Workbook

Sheet Ascendus DATA
A1: Customer Account: Name 1 | B1: Fiscal Year | C1: Posting Date | D1: Document Type | E1: Document Date | F1: Reference | G1: Document Currency Key | H1: Document Currency Value | I1: Company Code Currency Key | J1: Company Code Currency Value | K1: Text
A2: KUEHNE+NAGEL PVT. LTD. | B2: 2025 | C2: 45848 | D2: DG | E2: 45848 | F2: 256779421326 | G2: USD | H2: -70.8 | I2: INR | J2: -6088.85 | K2: Credit note raised against INV 256779414309
A3: KUEHNE+NAGEL PVT. LTD. | B3: 2025 | C3: 45848 | D3: DG | E3: 45848 | F3: 256779421327 | G3: USD | H3: -113.28 | I3: INR | J3: -9742.16 | K3: Credit note raised against INV 256779414309
A4: KUEHNE+NAGEL PVT. LTD. | B4: 2025 | C4: 45848 | D4: DG | E4: 45848 | F4: 256779421328 | G4: USD | H4: -242.75 | I4: INR | J4: -20876.66 | K4: Credit note raised against INV 256779414309
A5: KUEHNE+NAGEL PVT. LTD. | B5: 2025 | C5: 45904 | D5: DR | E5: 45904 | F5: 256779416909 | G5: USD | H5: 989.55 | I5: INR | J5: 86599.81 | K5: CODC Inbound chgs - 16-31 Aug 25
A6: KUEHNE+NAGEL PVT. LTD. | B6: 2025 | C6: 45904 | D6: DR | E6: 45904 | F6: 256779417134 | G6: USD | H6: 536.44 | I6: INR | J6: 46946.19 | K6: VAS - 16-31 Aug 25
A7: KUEHNE+NAGEL PVT. LTD. | B7: 2025 | C7: 45904 | D7: DR | E7: 45904 | F7: 256779417137 | G7: USD | H7: 409.79 | I7: INR | J7: 35862.5 | K7: WEIGHMENT - 16-31 Aug 25
A8: KUEHNE+NAGEL PVT. LTD. | B8: 2025 | C8: 45904 | D8: DR | E8: 45904 | F8: 256779417158 | G8: USD | H8: 110 | I8: INR | J8: 9626.58 | K8: Intra 16-31 Aug 25
A9: KUEHNE+NAGEL PVT. LTD. | B9: 2025 | C9: 45904 | D9: DR | E9: 45904 | F9: 256779417200 | G9: USD | H9: 100.74 | I9: INR | J9: 8816.19 | K9: Empty Lolo Chgs - 01 - 31 AUG 25
A10: KUEHNE+NAGEL PVT. LTD. | B10: 2025 | C10: 45904 | D10: DR | E10: 45904 | F10: 256779417238 | G10: USD | H10: 608.78 | I10: INR | J10: 53276.97 | K10: PORT SSR Chgs Aug 25
A11: KUEHNE+NAGEL PVT. LTD. | B11: 2025 | C11: 45904 | D11: DR | E11: 45904 | F11: 256779417250 | G11: USD | H11: 50 | I11: INR | J11: 4375.72 | K11: Scanning Chgs - 16 - 31 Aug 25
A12: KUEHNE+NAGEL PVT. LTD. | B12: 2025 | C12: 45904 | D12: DR | E12: 45904 | F12: 256779417257 | G12: USD | H12: 22.77 | I12: INR | J12: 1992.7 | K12: Bond Stamp Paper Chgs 01 - 31 Aug 25
A13: KUEHNE+NAGEL PVT. LTD. | B13: 2025 | C13: 45904 | D13: DR | E13: 45904 | F13: 256779417280 | G13: USD | H13: 249.98 | I13: INR | J13: 21876.83 | K13: LCL Chgs - 16 - 31 AUG 25
... A263: KUEHNE+NAGEL PVT. LTD. | B263: 2026 | C263: 46027 | D263: DR | E263: 46027 | F263: 256779440116 | G263: USD | H263: 498.28 | I263: INR | J263: 45215.49 | K263: LCL Chgs - 01 - 15 DEC 25
A264: KUEHNE+NAGEL PVT. LTD. | B264: 2026 | C264: 46030 | D264: DZ | E264: 46030 | G264: INR | H264: -719881.09 | I264: INR | J264: -719881.09
A265: KUEHNE+NAGEL PVT. LTD. | B265: 2026 | C265: 46031 | D265: DR | E265: 46031 | F265: 256779440126 | G265: USD | H265: 122.48 | I265: INR | J265: 11114.22 | K265: CODC Out chgs -1-15 Nov 25
A266: KUEHNE+NAGEL PVT. LTD. | B266: 2026 | C266: 46031 | D266: DR | E266: 46031 | F266: 256779440136 | G266: USD | H266: 27.81 | I266: INR | J266: 2523.57 | K266: Internet Activity Chgs - Dec 25
A267: KUEHNE+NAGEL PVT. LTD. | B267: 2026 | C267: 46028 | D267: DR | E267: 46028 | F267: 256779440150 | G267: USD | H267: 112.85 | I267: INR | J267: 10240.36 | K267: Empty Lolo Chgs - 01 - 31 DEC 25
A268: KUEHNE+NAGEL PVT. LTD. | B268: 2026 | C268: 46028 | D268: DR | E268: 46028 | F268: 256779440159 | G268: USD | H268: 160.22 | I268: INR | J268: 14538.87 | K268: PORT SSR Chgs Dec 25
A269: KUEHNE+NAGEL PVT. LTD. | B269: 2026 | C269: 46028 | D269: DR | E269: 46028 | F269: 256779440208 | G269: USD | H269: 650.12 | I269: INR | J269: 58993.93 | K269: LCL Chgs - 16 - 31 DEC 25
A270: KUEHNE+NAGEL PVT. LTD. | B270: 2026 | C270: 46034 | D270: DR | E270: 46034 | F270: 256779440227 | G270: USD | H270: 304.07 | I270: INR | J270: 27592.27 | K270: Outbound chgs - 16 - 31 Dec 25
A271: KUEHNE+NAGEL PVT. LTD. | B271: 2026 | C271: 46028 | D271: DR | E271: 46028 | F271: 256779440238 | G271: USD | H271: 1083.58 | I271: INR | J271: 98327.45 | K271: Unit Storage - 1-31 DEC 2025
A272: KUEHNE+NAGEL PVT. LTD. | B272: 2026 | C272: 46034 | D272: DR | E272: 46034 | F272: 256779440285 | G272: USD | H272: 535.29 | I272: INR | J272: 48573.9 | K272: VAS-Dec 25 - 16-31
A273: KUEHNE+NAGEL PVT. LTD. | B273: 2026 | C273: 46028 | D273: DR | E273: 46028 | F273: 256779440309 | G273: INR | H273: 200000 | I273: INR | J273: 200000 | K273: Fixed Storage Charges for January 2026
A274: KUEHNE+NAGEL PVT. LTD. | B274: 2026 | C274: 46028 | D274: DR | E274: 46028 | F274: 256779440310 | G274: INR | H274: 8000 | I274: INR | J274: 8000 | K274: Fixed Storage Charges for January 2026
A275: KUEHNE+NAGEL PVT. LTD. | B275: 2026 | C275: 46028 | D275: DR | E275: 46028 | F275: 256779440311 | G275: INR | H275: 4400 | I275: INR | J275: 4400 | K275: Fixed Storage Charges for January 2026
A276: KUEHNE+NAGEL PVT. LTD. | B276: 2026 | C276: 46035 | D276: DR | E276: 46035 | F276: 256779440363 | G276: USD | H276: 937.45 | I276: INR | J276: 85067.16 | K276: VAS - NOV 25,16-30
... A565: KUEHNE+NAGEL PVT. LTD. | B565: 2025 | C565: 45848 | D565: DR | E565: 45848 | F565: 256779415363 | G565: USD | H565: 3 | I565: INR | J565: 258 | K565: Outbound Handling for Aug 2024
A566: KUEHNE+NAGEL PVT. LTD. | B566: 2025 | C566: 45861 | D566: DZ | E566: 45861 | G566: USD | H566: 0 | I566: INR | J566: 0
A567: KUEHNE+NAGEL PVT. LTD. | B567: 2025 | C567: 45861 | D567: DZ | E567: 45861 | G567: USD | H567: 0 | I567: INR | J567: 0
A568: KUEHNE+NAGEL PVT. LTD. | B568: 2025 | C568: 45861 | D568: DZ | E568: 45861 | G568: USD | H568: 0 | I568: INR | J568: 0
A569: KUEHNE+NAGEL PVT. LTD. | B569: 2025 | C569: 45861 | D569: DZ | E569: 45861 | G569: USD | H569: 0 | I569: INR | J569: 0
A570: KUEHNE+NAGEL PVT. LTD. | B570: 2025 | C570: 45861 | D570: DZ | E570: 45861 | G570: USD | H570: 0 | I570: INR | J570: 0
A571: KUEHNE+NAGEL PVT. LTD. | B571: 2025 | C571: 45861 | D571: DZ | E571: 45861 | G571: USD | H571: 0 | I571: INR | J571: 0
A572: KUEHNE+NAGEL PVT. LTD. | B572: 2025 | C572: 45861 | D572: DZ | E572: 45861 | G572: USD | H572: 0 | I572: INR | J572: 0
A573: KUEHNE+NAGEL PVT. LTD. | B573: 2025 | C573: 45758 | D573: DA | E573: 45758 | G573: INR | H573: 1 | I573: INR | J573: 1 | K573: Overpayment
A574: KUEHNE+NAGEL PVT. LTD. | B574: 2025 | C574: 45758 | D574: DA | E574: 45758 | G574: INR | H574: -1 | I574: INR | J574: -1 | K574: Overpayment
A575: KUEHNE+NAGEL PVT. LTD. | B575: 2025 | C575: 45902 | D575: DY | E575: 45902 | G575: INR | H575: 212521.54 | I575: INR | J575: 208845.74
A576: KUEHNE+NAGEL PVT. LTD. | B576: 2025 | C576: 45902 | D576: DY | E576: 45902 | G576: INR | H576: -212521.54 | I576: INR | J576: -207607.52
A577: KUEHNE+NAGEL PVT. LTD. | B577: 2025 | C577: 45974 | D577: DZ | E577: 45974 | G577: USD | H577: 4603.48 | I577: INR | J577: 396450.85
...

Sheet Summary 
A2: Reconciliation of Ledger as on 31st January 2026
A3: Particulars | B3: Amount
A4: Balance as per Kuehne Nagel Pvt Ltd | B4: =-[1]A023951!$H$1116 -> 1386783.8
A5: Add: TDS recorded by customer but not in our books | B5: 233116.04
A6: Less: Amount recorded by customer, but not in our books | B6: -165435.46 | C6: This is Foreign Exchange Gain/loss in customers books confirmed by Customer team in Meeting
A7: Add: Difference in INR amounts in both books due to exchange rate | B7: 51209.63 | C7: This is Foreign Exchange Gain/loss in customers books confirmed by Customer team in Meeting
A8: Add: Invoices / CN not recorded in customer books | B8: ='Invoices not in customer''s Book'!I142+'CN Not in Customer''s Books'!G147 -> 2942083.2 | C8: To be discussed with customer
A9: Less: Exchange gain loss recorded by customer | B9: -7126.86
A10: Add: Diffrence in Payment recorded in both books due to exchange gain/loss | B10: =SUM('Payment Reco'!E3:E20) -> 2110.18
A11: Add: Payments recorded in Feb by Ascendus | B11: =('Payment Reco'!E21+'Payment Reco'!E22) -> 1878132.8 | C11: Confirmed by Sushil over call
A12: Derived balance | B12: =SUM(B4:B11) -> 6320873.3
A13: Balance as per Ascendus | B13: =[2]Sheet1!$T$709 -> 6321328.8
A15: Difference | B15: =B12-B13-B14 -> -455.44

Sheet Biling Reco
A1: As per Customer | G1: As per Ascendus
A2: Years | B2: Item Date | C2: Debit Note | D2: Expense | E2: Foreign Exchange Diffrence | F2: Net Amount | G2: Years | H2: Document Date | I2: Credit | J2: Expense | K2: Net Amount | L2: Diffrence
A3: 2025 | B3: Jan | D3: -217492.45 | F3: =SUM(C3:E3) -> -217492.45 | G3: 2025 | H3: Jan | K3: =SUM(I3:J3) -> 0 | L3: =K3+F3 -> -217492.45
A4: 2025 | B4: Feb | D4: -1520432.9 | F4: =SUM(C4:E4) -> -1520432.9 | G4: 2025 | H4: Feb | J4: 1514515.3 | K4: =SUM(I4:J4) -> 1514515.3 | L4: =K4+F4 -> -5917.55
A5: 2025 | B5: Mar | C5: 21719.38 | D5: -1191118 | F5: =SUM(C5:E5) -> -1169398.7 | G5: 2025 | H5: Mar | J5: 1933380.6 | K5: =SUM(I5:J5) -> 1933380.6 | L5: =K5+F5 -> 763981.97
A6: 2025 | B6: Apr | D6: -2932698.5 | F6: =SUM(C6:E6) -> -2932698.5 | G6: 2025 | H6: Apr | J6: 2087965.7 | K6: =SUM(I6:J6) -> 2087965.7 | L6: =K6+F6 -> -844732.75
A7: 2025 | B7: May | D7: -1341898.7 | F7: =SUM(C7:E7) -> -1341898.7 | G7: 2025 | H7: May | I7: -595574.41 | J7: 1044919.9 | K7: =SUM(I7:J7) -> 449345.53 | L7: =K7+F7 -> -892553.19
A8: 2025 | B8: Jun | D8: -796400.32 | F8: =SUM(C8:E8) -> -796400.32 | G8: 2025 | H8: Jun | J8: 1761603.8 | K8: =SUM(I8:J8) -> 1761603.8 | L8: =K8+F8 -> 965203.51
A9: 2025 | B9: Jul | D9: -266105.72 | F9: =SUM(C9:E9) -> -266105.72 | G9: 2025 | H9: Jul | I9: -1464659.3 | J9: 2492881.5 | K9: =SUM(I9:J9) -> 1028222.2 | L9: =K9+F9 -> 762116.44
A10: 2025 | B10: Aug | D10: -937708 | F10: =SUM(C10:E10) -> -937708 | G10: 2025 | H10: Aug | I10: -170239.97 | J10: 1305423 | K10: =SUM(I10:J10) -> 1135183.1 | L10: =K10+F10 -> 197475.05
A11: 2025 | B11: Sep | C11: 16556.76 | D11: -673577.15 | F11: =SUM(C11:E11) -> -657020.39 | G11: 2025 | H11: Sep | J11: =1564779.07+1238.22 -> 1566017.3 | K11: =SUM(I11:J11) -> 1566017.3 | L11: =K11+F11 -> 908996.9
A12: 2025 | B12: Oct | D12: -1793002.9 | F12: =SUM(C12:E12) -> -1793002.9 | G12: 2025 | H12: Oct | I12: -8361.37 | J12: 1113806.7 | K12: =SUM(I12:J12) -> 1105445.3 | L12: =K12+F12 -> -687557.56
A13: 2025 | B13: Nov | D13: -80394.56 | F13: =SUM(C13:E13) -> -80394.56 | G13: 2025 | H13: Nov | I13: -405590.02 | J13: 1574052.7 | K13: =SUM(I13:J13) -> 1168462.7 | L13: =K13+F13 -> 1088068.1
A14: 2025 | B14: Dec | F14: =SUM(C14:E14) -> 0 | G14: 2025 | H14: Dec | J14: 282835.01 | K14: =SUM(I14:J14) -> 282835.01 | L14: =K14+F14 -> 282835.01
A15: 2026 | B15: Jan | E15: -45403 | F15: =SUM(C15:E15) -> -45403 | G15: 2026 | H15: Jan | I15: -52265.33 | J15: 831546.81 | K15: =SUM(I15:J15) -> 779281.48 | L15: =K15+F15 -> 733878.48
A16: Total | C16: =SUM(C3:C15) -> 38276.14 | D16: =SUM(D3:D15) -> -11750829 | E16: =SUM(E3:E15) -> -45403 | F16: =SUM(C16:E16) -> -11757956 | G16: Total | I16: =SUM(I3:I15) -> -2696690.4 | J16: =SUM(J3:J15) -> 17508948 | K16: =SUM(I16:J16) -> 14812258 | L16: =K16+F16 -> 3054302
D18: =J16+D16 -> 5758119.3

Sheet Payment Reco
A1: As per Customer ledger | C1: As per Ascendus | E1: Amount
A2: Date | B2: Amount | C2: Date | D2: Amount | J2: As per Customer ledger | K2: As per Ascendus
A3: 45827 | B3: 1760137.8 | C3: 45940 | D3: -1746430.2 | E3: =B3+D3 -> 13707.54 | F3: >>Exchange diffrence | H3: 2025 | I3: Jan
A4: 45859 | B4: 2396201.3 | C4: 45940 | D4: -2385234 | E4: =B4+D4 -> 10967.32 | F4: >>Exchange diffrence | H4: 2025 | I4: Feb
A5: 45859 | B5: 2396201.3 | E5: =B5+D5 -> 2396201.3 | H5: 2025 | I5: May
A6: 45869 | B6: -2396201.3 | E6: =B6+D6 -> -2396201.3 | H6: 2025 | I6: June | J6: =B3 -> 1760137.8
A7: 45954 | B7: 1721315.8 | C7: 45958 | D7: -1719090.9 | E7: =B7+D7 -> 2224.91 | F7: >>Exchange diffrence | H7: 2025 | I7: July | J7: =B4 -> 2396201.3
C8: 45974 | D8: 396450.85 | E8: =B8+D8 -> 396450.85 | H8: 2025 | I8: Aug
C9: 45974 | D9: 262.21 | E9: =B9+D9 -> 262.21 | H9: 2025 | I9: Sep
C10: 45974 | D10: -262.21 | E10: =B10+D10 -> -262.21 | H10: 2025 | I10: Oct | J10: 1721315.8 | K10: -5850755.1
C11: 45974 | D11: 478086.37 | E11: =B11+D11 -> 478086.37 | H11: 2025 | I11: Nov | J11: 1899719.6 | K11: -1920293.1
C12: 45974 | D12: -338298.81 | E12: =B12+D12 -> -338298.81 | H12: 2025 | I12: Dec | J12: 715665.04
C13: 45974 | D13: -536832.3 | E13: =B13+D13 -> -536832.3 | H13: 2026 | I13: Jan | J13: 1878132.8 | K13: -719881.09
C14: 45974 | D14: 75771.03 | E14: =B14+D14 -> 75771.03 | H14: Total | J14: =SUM(J3:J13) -> 10371172 | K14: =SUM(K3:K13) -> -8490929.3 | L14: =SUM(J14:K14) -> 1880243
C15: 45974 | D15: -20130.78 | E15: =B15+D15 -> -20130.78
C16: 45974 | D16: -746.27 | E16: =B16+D16 -> -746.27
C17: 45974 | D17: -24772.95 | E17: =B17+D17 -> -24772.95
C18: 45974 | D18: -31858.99 | E18: =B18+D18 -> -31858.99
A19: 45982 | B19: 1899719.6 | C19: 45987 | D19: -1917961.2 | E19: =B19+D19 -> -18241.69 | F19: >>Exchange diffrence
A20: 46014 | B20: 715665.04 | C20: 46030 | D20: -719881.09 | E20: =B20+D20 -> -4216.05 | F20: >>Exchange diffrence
A21: 46052 | B21: 1869680.8 | E21: =B21+D21 -> 1869680.8 | F21: >>payment not recorded in books
A22: 46053 | B22: 8452 | E22: =B22+D22 -> 8452 | F22: >>payment not recorded in books
B23: =SUM(B3:B22) -> 10371172 | D23: =SUM(D3:D21) -> -8490929.3 | E23: =SUM(E3:E22) -> 1880243

Sheet Pivot data
A3: Sum of LC Amount | D3: Ty
A4: Years | B4: Quarters | C4: Item Date | D4: A | E4: C | F4: I | G4: S
A5: 2025 | B5: Qtr1 | C5: Jan | F5: -217492.45
C6: Feb | F6: -1520432.9
C7: Mar | E7: 21719.38 | F7: -1191118
B8: Qtr2 | C8: Apr | F8: -2932698.5
C9: May | F9: -1341898.7
C10: Jun | D10: 1760137.8 | F10: -796400.32
B11: Qtr3 | C11: Jul | D11: 2396201.3 | F11: -266105.72
C12: Aug | F12: -937708
C13: Sep | E13: 16556.76 | F13: -673577.15
B14: Qtr4 | C14: Oct | D14: 1721315.8 | F14: -1793002.9
C15: Nov | D15: 1899719.6 | F15: -80394.56
C16: Dec | D16: 715665.04
A17: 2026 | B17: Qtr1 | C17: Jan | D17: 1878132.8 | G17: -45403

Sheet Invoices not in customer's Book
A1: Customer Account: Name 1 | B1: Fiscal Year | C1: Document Type | D1: Document Date | E1: Reference | F1: Document Currency Key | G1: Document Currency Value | H1: Company Code Currency Key | I1: Company Code Currency Value | J1: Text | K1: Amount In USD | L1: Amount In INR | M1: Diffrecnce
A2: KUEHNE+NAGEL PVT. LTD. | B2: 2025 | C2: DR | D2: 45719 | E2: 246779410482 | F2: USD | G2: 3.54 | H2: INR | I2: 306.89 | J2: Outbound Handling for Aug 2024 | K2: #N/A
A3: KUEHNE+NAGEL PVT. LTD. | B3: 2025 | C3: DR | D3: 45719 | E3: 246779410483 | F3: USD | G3: 3.54 | H3: INR | I3: 306.89 | J3: Outbound Handling for Aug 2024 | K3: #N/A
A4: KUEHNE+NAGEL PVT. LTD. | B4: 2025 | C4: DR | D4: 45730 | E4: 246779412207 | F4: USD | G4: 312.5 | H4: INR | I4: 27091.02 | J4: VAS Activity Charges for the month of August, 24 | K4: #N/A
A5: KUEHNE+NAGEL PVT. LTD. | B5: 2025 | C5: DR | D5: 45730 | E5: 246779412208 | F5: USD | G5: 23.35 | H5: INR | I5: 2024.24 | J5: VAS Activity Charges for the month of August, 24 | K5: #N/A
A6: KUEHNE+NAGEL PVT. LTD. | B6: 2025 | C6: DR | D6: 45730 | E6: 246779412197 | F6: USD | G6: 40.06 | H6: INR | I6: 3472.85 | J6: VAS Activity Charges for the month of August, 24 | K6: #N/A
A7: KUEHNE+NAGEL PVT. LTD. | B7: 2025 | C7: DR | D7: 45730 | E7: 246779412198 | F7: USD | G7: 249.55 | H7: INR | I7: 21633.8 | J7: VAS Activity Charges for the month of August, 24 | K7: #N/A
A8: KUEHNE+NAGEL PVT. LTD. | B8: 2025 | C8: DR | D8: 45730 | E8: 246779412199 | F8: USD | G8: 40.06 | H8: INR | I8: 3472.85 | J8: VAS Activity Charges for the month of August, 24 | K8: #N/A
A9: KUEHNE+NAGEL PVT. LTD. | B9: 2025 | C9: DR | D9: 45730 | E9: 246779412200 | F9: USD | G9: 45.79 | H9: INR | I9: 3969.59 | J9: VAS Activity Charges for the month of August, 24 | K9: #N/A
A10: KUEHNE+NAGEL PVT. LTD. | B10: 2025 | C10: DR | D10: 45730 | E10: 246779412202 | F10: USD | G10: 40.06 | H10: INR | I10: 3472.85 | J10: VAS Activity Charges for the month of August, 24 | K10: #N/A
A11: KUEHNE+NAGEL PVT. LTD. | B11: 2025 | C11: DR | D11: 45730 | E11: 246779412203 | F11: USD | G11: 28.62 | H11: INR | I11: 2481.1 | J11: VAS Activity Charges for the month of August, 24 | K11: #N/A
A12: KUEHNE+NAGEL PVT. LTD. | B12: 2025 | C12: DR | D12: 45730 | E12: 246779412204 | F12: USD | G12: 22.89 | H12: INR | I12: 1984.36 | J12: VAS Activity Charges for the month of August, 24 | K12: #N/A
A13: KUEHNE+NAGEL PVT. LTD. | B13: 2025 | C13: DR | D13: 45730 | E13: 246779412205 | F13: USD | G13: 114.46 | H13: INR | I13: 9922.68 | J13: VAS Activity Charges for the month of August, 24 | K13: #N/A
... A141: KUEHNE+NAGEL PVT. LTD. | B141: 2026 | C141: DR | D141: 46049 | E141: 256779440443 | F141: USD | G141: 18.41 | H141: INR | I141: 1670.58 | J141: VAS-1-15 Jan 2026 | K141: #N/A
I142: =SUM(I2:I141) -> 5638773.6
I143: -2696690.4
I144: =I142+I143 -> 2942083.2
I145: 3054302
I146: =I145-I144 -> 112218.79

Sheet CN Not in Customer's Books
A1: Document Type | B1: Document Date | C1: Reference | D1: Document Currency Key | E1: Document Currency Value | F1: Company Code Currency Key | G1: Company Code Currency Value | H1: Text
A2: DG | B2: 45848 | C2: 256779421326 | D2: USD | E2: -70.8 | F2: INR | G2: -6088.85 | H2: Credit note raised against INV 256779414309 | I2: =MID(H2,32,15) -> 256779414309 | J2: 256779414309
A3: DG | B3: 45848 | C3: 256779421327 | D3: USD | E3: -113.28 | F3: INR | G3: -9742.16 | H3: Credit note raised against INV 256779414309 | I3: =MID(H3,32,15) -> 256779414309 | J3: 256779414309
A4: DG | B4: 45848 | C4: 256779421328 | D4: USD | E4: -242.75 | F4: INR | G4: -20876.66 | H4: Credit note raised against INV 256779414309 | I4: =MID(H4,32,15) -> 256779414309 | J4: 256779414309
A5: DG | B5: 45964 | C5: 256779422067 | D5: USD | E5: -4608.8 | F5: INR | G5: -405590.02 | H5: CN issued against 256779417093 | I5: =MID(H5,18,15) -> 256779417093 | J5: 256779417093
A6: DG | B6: 45791 | C6: 256779420272 | D6: USD | E6: -40.06 | F6: INR | G6: -3472.85 | H6: Credit note against 246779412202 | I6: =MID(H6,20,15) -> 246779412202 | J6: 246779412202
A7: DG | B7: 45791 | C7: 256779420273 | D7: USD | E7: -28.62 | F7: INR | G7: -2481.1 | H7: Credit note against 246779412203 | I7: =MID(H7,20,15) -> 246779412203 | J7: 246779412203
A8: DG | B8: 45791 | C8: 256779420275 | D8: USD | E8: -114.46 | F8: INR | G8: -9922.68 | H8: Credit note against 246779412205 | I8: =MID(H8,20,15) -> 246779412205 | J8: 246779412205
A9: DG | B9: 45791 | C9: 256779420276 | D9: USD | E9: -68.68 | F9: INR | G9: -5953.96 | H9: Credit note against 246779412206 | I9: =MID(H9,20,15) -> 246779412206 | J9: 246779412206
A10: DG | B10: 45791 | C10: 256779420268 | D10: USD | E10: -249.55 | F10: INR | G10: -21633.8 | H10: Credit note against 246779412198 | I10: =MID(H10,20,15) -> 246779412198 | J10: 246779412198
A11: DG | B11: 45791 | C11: 256779420269 | D11: USD | E11: -40.06 | F11: INR | G11: -3472.85 | H11: Credit note against 246779412199 | I11: =MID(H11,20,15) -> 246779412199 | J11: 246779412199
A12: DG | B12: 45791 | C12: 256779420274 | D12: USD | E12: -22.89 | F12: INR | G12: -1984.36 | H12: Credit note against 246779412204 | I12: =MID(H12,20,15) -> 246779412204 | J12: 246779412204
A13: DG | B13: 45791 | C13: 256779420277 | D13: USD | E13: -312.5 | F13: INR | G13: -27091.02 | H13: Credit note against 246779412207 | I13: =MID(H13,20,15) -> 246779412207 | J13: 246779412207
A14: DG | B14: 45791 | C14: 256779420278 | D14: USD | E14: -23.35 | F14: INR | G14: -2024.24 | H14: Credit note against 246779412208 | I14: =MID(H14,20,15) -> 246779412208 | J14: 246779412208
A15: DG | B15: 45791 | C15: 256779420266 | D15: USD | E15: -57.23 | F15: INR | G15: -4961.34 | H15: Credit note against 246779412196 | I15: =MID(H15,20,15) -> 246779412196 | J15: 246779412196
A16: DG | B16: 45791 | C16: 256779420267 | D16: USD | E16: -40.06 | F16: INR | G16: -3472.85 | H16: Credit note against 246779412197 | I16: =MID(H16,20,15) -> 246779412197 | J16: 246779412197
A17: DG | B17: 45791 | C17: 256779420270 | D17: USD | E17: -45.79 | F17: INR | G17: -3969.59 | H17: Credit note against 246779412200 | I17: =MID(H17,20,15) -> 246779412200 | J17: 246779412200
... A20: DG | B20: 45791 | C20: 256779420526 | D20: USD | E20: -2286.24 | F20: INR | G20: -198724.14 | H20: Credit note against 256779410272 | I20: =MID(H20,20,15) -> 256779410272 | J20: 256779410272
A21: DG | B21: 45873 | C21: 256779421623 | D21: USD | E21: -608.41 | F21: INR | G21: -52323.67 | H21: Credit note raised against 256779415792 | I21: =MID(H21,28,15) -> 256779415792 | J21: 256779415792
A22: DG | B22: 45862 | C22: 256779421498 | D22: USD | E22: -95.24 | F22: INR | G22: -8190.7 | H22: Credit note raised against 256779414430 | I22: =MID(H22,28,15) -> 256779414430 | J22: 256779414430
A23: DG | B23: 45862 | C23: 256779421512 | D23: USD | E23: -2333.18 | F23: INR | G23: -200655.04 | H23: Credit note raised against 256779414445 | I23: =MID(H23,28,15) -> 256779414445 | J23: 256779414445
A24: DG | B24: 45800 | C24: 256779421106 | D24: USD | E24: -707.71 | F24: INR | G24: -60851.52 | H24: Credit Note against 256779413161 | I24: =MID(H24,20,15) -> 256779413161 | J24: 256779413161
A25: DG | B25: 45800 | C25: 256779421109 | D25: USD | E25: -3.78 | F25: INR | G25: -325.02 | H25: Credit Note against 256779413169 | I25: =MID(H25,20,15) -> 256779413169 | J25: 256779413169
A26: DG | B26: 45890 | C26: 256779421698 | D26: USD | E26: -30 | F26: INR | G26: -2580.9 | H26: CN ISSUED TOWARDS BILL NO.256779415304 | I26: =MID(H26,27,15) -> 256779415304 | J26: 256779415304
A27: DG | B27: 45890 | C27: 256779421699 | D27: USD | E27: -30 | F27: INR | G27: -2580.9 | H27: CN ISSUED TOWARDS BILL NO.256779415305 | I27: =MID(H27,27,15) -> 256779415305 | J27: 256779415305
A28: DG | B28: 45890 | C28: 256779421700 | D28: USD | E28: -30 | F28: INR | G28: -2580.9 | H28: CN ISSUED TOWARDS BILL NO.256779415306 | I28: =MID(H28,27,15) -> 256779415306 | J28: 256779415306
A29: DG | B29: 45890 | C29: 256779421701 | D29: USD | E29: -30 | F29: INR | G29: -2580.9 | H29: CN ISSUED TOWARDS BILL NO.256779415307 | I29: =MID(H29,27,15) -> 256779415307 | J29: 256779415307
A30: DG | B30: 45890 | C30: 256779421702 | D30: USD | E30: -30 | F30: INR | G30: -2580.9 | H30: CN ISSUED TOWARDS BILL NO.256779415308 | I30: =MID(H30,27,15) -> 256779415308 | J30: 256779415308
A31: DG | B31: 45890 | C31: 256779421703 | D31: USD | E31: -27.39 | F31: INR | G31: -2356.36 | H31: CN ISSUED TOWARDS BILL NO.256779415339 | I31: =MID(H31,27,15) -> 256779415339 | J31: 256779415339
A32: DG | B32: 45890 | C32: 256779421705 | D32: USD | E32: -212.5 | F32: INR | G32: -18281.4 | H32: CN ISSUED TOWARDS BILL NO.256779415321 | I32: =MID(H32,27,15) -> 256779415321 | J32: 256779415321
A33: DG | B33: 45890 | C33: 256779421706 | D33: USD | E33: -362.02 | F33: INR | G33: -31144.62 | H33: CN ISSUED TOWARDS BILL NO.256779415374 | I33: =MID(H33,27,15) -> 256779415374 | J33: 256779415374
A34: DG | B34: 45890 | C34: 256779421707 | D34: USD | E34: -228.75 | F34: INR | G34: -19679.39 | H34: CN ISSUED TOWARDS BILL NO.246779414662 | I34: =MID(H34,27,15) -> 246779414662 | J34: 246779414662
A35: DG | B35: 45890 | C35: 256779421708 | D35: USD | E35: -281.5 | F35: INR | G35: -24217.48 | H35: CN ISSUED TOWARDS BILL NO.256779415365 | I35: =MID(H35,27,15) -> 256779415365 | J35: 256779415365
A36: DG | B36: 45799 | C36: 256779420844 | D36: INR | E36: -262.21 | F36: INR | G36: -262.21 | H36: Credit Note against 256779412140 | I36: =MID(H36,20,15) -> 256779412140 | J36: 256779412140
A37: DG | B37: 45799 | C37: 256779420845 | D37: USD | E37: -466.37 | F37: INR | G37: -40430.2 | H37: Credit Note against 246779413076 | I37: =MID(H37,20,15) -> 246779413076 | J37: 246779413076
A38: DG | B38: 46027 | C38: 256779422164 | D38: USD | E38: -562.38 | F38: INR | G38: -51032.13 | H38: Credit note for Duplicate invoice -256779418489 | I38: =MID(H38,36,15) -> 256779418489 | J38: 256779418489
A39: DG | B39: 46027 | C39: 256779422170 | D39: USD | E39: -13.59 | F39: INR | G39: -1233.2 | H39: Credit note for Duplicate invoice -256779418495 | I39: =MID(H39,36,15) -> 256779418495 | J39: 256779418495
A40: DG | B40: 45848 | C40: 256779421222 | D40: USD | E40: -295 | F40: INR | G40: -25370.2 | H40: Credit note raised against INV 256779411867 | I40: =MID(H40,32,15) -> 256779411867 | J40: 256779411867
A41: DG | B41: 45848 | C41: 256779421223 | D41: USD | E41: -28.32 | F41: INR | G41: -2435.54 | H41: Credit note raised against INV 246779414057 | I41: =MID(H41,32,15) -> 246779414057 | J41: 246779414057
A42: DG | B42: 45848 | C42: 256779421224 | D42: USD | E42: -28.32 | F42: INR | G42: -2435.54 | H42: Credit note raised against INV 256779411091 | I42: =MID(H42,32,15) -> 256779411091 | J42: 256779411091
...

Sheet Foreign Exchange difference
A1: Ty | B1: Item# | C1: Item Date | D1: FC Amount | E1: LC Amount | F1: Particular | G1: Due Date | H1: CCY | I1: VC Period | J1: VC Seq | K1: VC Date | L1: Tx. Type | M1: Company Code
A2: C | B2: 246779411409_R | C2: 45730 | D2: 249.55 | E2: 21721.43 | F2: NO EXCHANGE RATE | H2: USD | I2: 45839 | M2: 53826350
A3: C | B3: 246779411409_R | C3: 45730 | D3: 0 | E3: -2.05 | F3: C: ASCENDAS27 P: Matching | H3: USD | I3: 45839 | M3: 54969548
A4: C | B4: 256779417580_R | C4: 45918 | D4: 184.38 | E4: 184.38 | H4: USD | I4: 46023 | M4: 68208016
A5: S | B5: 2830735 | C5: 46053 | D5: 0 | E5: -7756 | F5: Exchange rate diference for JUN'25 USD 20175.95 | H5: INR | I5: 46023 | M5: 68369723
A6: S | B6: 2830736 | C6: 46053 | D6: 0 | E6: -15004 | F6: Exchange rate diference for JUL'25 USD 27632.46 | H6: INR | I6: 46023 | M6: 68369723
A7: S | B7: 2830738 | C7: 46053 | D7: 0 | E7: -17437 | F7: Exchange rate diference for NOV'25 USD 21525.94 | H7: INR | I7: 46023 | M7: 68369723
A8: S | B8: 2830739 | C8: 46053 | D8: 0 | E8: -5206 | F8: Exchange rate diference for DEC'25 USD 8027.22 | H8: INR | I8: 46023 | M8: 68369723
A9: C | B9: 256779417580_R | C9: 45918 | D9: -3.69 | E9: -3.69 | F9: C: ASCENDAS27 P: A023951 C 256779 | H9: USD | I9: 46023 | M9: 68389624
A10: C | B10: 256779417580_R | C10: 45918 | D10: 0 | E10: 16376.07 | F10: C: ASCENDAS27 P: Matching | H10: USD | I10: 46023 | M10: 68459189
E11: =SUM(E2:E10) -> -7126.86

Sheet Ascendus
A1: Customer Account: Name 1 | B1: Fiscal Year | C1: Document Type | D1: Document Date | E1: Reference | F1: Document Currency Key | G1: Document Currency Value | H1: Company Code Currency Key | I1: Company Code Currency Value | J1: Text | K1: Amount In USD | L1: Amount In INR | M1: Diffrecnce
A2: KUEHNE+NAGEL PVT. LTD. | B2: 2025 | C2: DG | D2: 45848 | E2: 256779421326 | F2: USD | G2: -70.8 | H2: INR | I2: -6088.85 | J2: Credit note raised against INV 256779414309 | K2: {=VLOOKUP(E2,[1]A023951!D$1:H$1114,{3,5},0)} -> #N/A
A3: KUEHNE+NAGEL PVT. LTD. | B3: 2025 | C3: DG | D3: 45848 | E3: 256779421327 | F3: USD | G3: -113.28 | H3: INR | I3: -9742.16 | J3: Credit note raised against INV 256779414309 | K3: {=VLOOKUP(E3,[1]A023951!D$1:H$1114,{3,5},0)} -> #N/A
A4: KUEHNE+NAGEL PVT. LTD. | B4: 2025 | C4: DG | D4: 45848 | E4: 256779421328 | F4: USD | G4: -242.75 | H4: INR | I4: -20876.66 | J4: Credit note raised against INV 256779414309 | K4: {=VLOOKUP(E4,[1]A023951!D$1:H$1114,{3,5},0)} -> #N/A
A5: KUEHNE+NAGEL PVT. LTD. | B5: 2025 | C5: DR | D5: 45904 | E5: 256779416909 | F5: USD | G5: 989.55 | H5: INR | I5: 86599.81 | J5: CODC Inbound chgs - 16-31 Aug 25 | K5: {=VLOOKUP(E5,[1]A023951!D$1:H$1114,{3,5},0)} -> -989.55 | L5: -87733 | M5: =I5+L5 -> -1133.19
A6: KUEHNE+NAGEL PVT. LTD. | B6: 2025 | C6: DR | D6: 45904 | E6: 256779417134 | F6: USD | G6: 536.44 | H6: INR | I6: 46946.19 | J6: VAS - 16-31 Aug 25 | K6: {=VLOOKUP(E6,[1]A023951!D$1:H$1114,{3,5},0)} -> -536.44 | L6: -47020 | M6: =I6+L6 -> -73.81
A7: KUEHNE+NAGEL PVT. LTD. | B7: 2025 | C7: DR | D7: 45904 | E7: 256779417137 | F7: USD | G7: 409.79 | H7: INR | I7: 35862.5 | J7: WEIGHMENT - 16-31 Aug 25 | K7: {=VLOOKUP(E7,[1]A023951!D$1:H$1114,{3,5},0)} -> -409.79 | L7: -35918.88 | M7: =I7+L7 -> -56.38
A8: KUEHNE+NAGEL PVT. LTD. | B8: 2025 | C8: DR | D8: 45904 | E8: 256779417158 | F8: USD | G8: 110 | H8: INR | I8: 9626.58 | J8: Intra 16-31 Aug 25 | K8: {=VLOOKUP(E8,[1]A023951!D$1:H$1114,{3,5},0)} -> -110 | L8: -9641.71 | M8: =I8+L8 -> -15.13
A9: KUEHNE+NAGEL PVT. LTD. | B9: 2025 | C9: DR | D9: 45904 | E9: 256779417200 | F9: USD | G9: 100.74 | H9: INR | I9: 8816.19 | J9: Empty Lolo Chgs - 01 - 31 AUG 25 | K9: {=VLOOKUP(E9,[1]A023951!D$1:H$1114,{3,5},0)} -> -100.74 | L9: -8830.05 | M9: =I9+L9 -> -13.86
A10: KUEHNE+NAGEL PVT. LTD. | B10: 2025 | C10: DR | D10: 45904 | E10: 256779417238 | F10: USD | G10: 608.78 | H10: INR | I10: 53276.97 | J10: PORT SSR Chgs Aug 25 | K10: {=VLOOKUP(E10,[1]A023951!D$1:H$1114,{3,5},0)} -> -608.78 | L10: -53360.74 | M10: =I10+L10 -> -83.77
A11: KUEHNE+NAGEL PVT. LTD. | B11: 2025 | C11: DR | D11: 45904 | E11: 256779417250 | F11: USD | G11: 50 | H11: INR | I11: 4375.72 | J11: Scanning Chgs - 16 - 31 Aug 25 | K11: {=VLOOKUP(E11,[1]A023951!D$1:H$1114,{3,5},0)} -> #N/A
A12: KUEHNE+NAGEL PVT. LTD. | B12: 2025 | C12: DR | D12: 45904 | E12: 256779417257 | F12: USD | G12: 22.77 | H12: INR | I12: 1992.7 | J12: Bond Stamp Paper Chgs 01 - 31 Aug 25 | K12: {=VLOOKUP(E12,[1]A023951!D$1:H$1114,{3,5},0)} -> -22.77 | L12: -1995.83 | M12: =I12+L12 -> -3.13
A13: KUEHNE+NAGEL PVT. LTD. | B13: 2025 | C13: DR | D13: 45904 | E13: 256779417280 | F13: USD | G13: 249.98 | H13: INR | I13: 21876.83 | J13: LCL Chgs - 16 - 31 AUG 25 | K13: {=VLOOKUP(E13,[1]A023951!D$1:H$1114,{3,5},0)} -> -249.98 | L13: -21911.23 | M13: =I13+L13 -> -34.4
A14: KUEHNE+NAGEL PVT. LTD. | B14: 2025 | C14: DR | D14: 45904 | E14: 256779417317 | F14: USD | G14: 170.85 | H14: INR | I14: 14951.82 | J14: Outbound chgs - 16 - 31 Aug 25 | K14: {=VLOOKUP(E14,[1]A023951!D$1:H$1114,{3,5},0)} -> -170.85 | L14: -14975.33 | M14: =I14+L14 -> -23.51
A15: KUEHNE+NAGEL PVT. LTD. | B15: 2025 | C15: DR | D15: 45842 | E15: 256779414859 | F15: USD | G15: 318.47 | H15: INR | I15: 27388.63 | J15: LCL Chgs - 16 - 30 JUN 25 | K15: {=VLOOKUP(E15,[1]A023951!D$1:H$1114,{3,5},0)} -> -318.47 | L15: -27385.08 | M15: =I15+L15 -> 3.55
A16: KUEHNE+NAGEL PVT. LTD. | B16: 2025 | C16: DR | D16: 45842 | E16: 256779415012 | F16: USD | G16: 184.3 | H16: INR | I16: 15849.92 | J16: Outbound chgs - 16 - 30 Jun 25 | K16: {=VLOOKUP(E16,[1]A023951!D$1:H$1114,{3,5},0)} -> -184 | L16: -15822.07 | M16: =I16+L16 -> 27.85
A17: KUEHNE+NAGEL PVT. LTD. | B17: 2025 | C17: DR | D17: 45842 | E17: 256779415208 | F17: USD | G17: 183.43 | H17: INR | I17: 15775.1 | J17: Unit Storage - 1-30 June 25 | K17: {=VLOOKUP(E17,[1]A023951!D$1:H$1114,{3,5},0)} -> -183.43 | L17: -16228.05 | M17: =I17+L17 -> -452.95
A18: KUEHNE+NAGEL PVT. LTD. | B18: 2025 | C18: DR | D18: 45842 | E18: 256779415209 | F18: USD | G18: 63.26 | H18: INR | I18: 5440.4 | J18: Unit Storage - 1-30 June 25 | K18: {=VLOOKUP(E18,[1]A023951!D$1:H$1114,{3,5},0)} -> -63.26 | L18: -5596.61 | M18: =I18+L18 -> -156.21
A19: KUEHNE+NAGEL PVT. LTD. | B19: 2025 | C19: DR | D19: 45842 | E19: 256779415210 | F19: USD | G19: 9629.63 | H19: INR | I19: 828154.63 | J19: Unit Storage - 1-30 June 25 | K19: {=VLOOKUP(E19,[1]A023951!D$1:H$1114,{3,5},0)} -> -9629.63 | L19: -851933.37 | M19: =I19+L19 -> -23778.74
A20: KUEHNE+NAGEL PVT. LTD. | B20: 2025 | C20: DR | D20: 45842 | E20: 256779415261 | F20: USD | G20: 292.96 | H20: INR | I20: 25194.76 | J20: VAS - 16-30 June 25 | K20: {=VLOOKUP(E20,[1]A023951!D$1:H$1114,{3,5},0)} -> -292.26 | L20: -25131.29 | M20: =I20+L20 -> 63.47
A21: KUEHNE+NAGEL PVT. LTD. | B21: 2025 | C21: DR | D21: 45842 | E21: 256779415270 | F21: USD | G21: 420.86 | H21: INR | I21: 36194.24 | J21: Weighment- 16-30 June 25 | K21: {=VLOOKUP(E21,[1]A023951!D$1:H$1114,{3,5},0)} -> -420.86 | L21: -37233.48 | M21: =I21+L21 -> -1039.24
A22: KUEHNE+NAGEL PVT. LTD. | B22: 2025 | C22: DR | D22: 45966 | E22: 256779418816 | F22: USD | G22: 891 | H22: INR | I22: 78411.02 | J22: VAS-16 -31 Oct 25 | K22: {=VLOOKUP(E22,[1]A023951!D$1:H$1114,{3,5},0)} -> #N/A
A23: KUEHNE+NAGEL PVT. LTD. | B23: 2025 | C23: DR | D23: 45966 | E23: 256779418872 | F23: USD | G23: 5939.04 | H23: INR | I23: 522655.65 | J23: Unit Storage - 1-31 Oct 2025 | K23: {=VLOOKUP(E23,[1]A023951!D$1:H$1114,{3,5},0)} -> #N/A
A24: KUEHNE+NAGEL PVT. LTD. | B24: 2025 | C24: DR | D24: 45966 | E24: 256779418892 | F24: USD | G24: 1683.97 | H24: INR | I24: 148195.07 | J24: CODC Inbound chgs - 16-31 Oct 25 | K24: {=VLOOKUP(E24,[1]A023951!D$1:H$1114,{3,5},0)} -> -1683.97 | L24: -148614.68 | M24: =I24+L24 -> -419.61
A25: KUEHNE+NAGEL PVT. LTD. | B25: 2025 | C25: DR | D25: 45966 | E25: 256779418904 | F25: USD | G25: 1273.92 | H25: INR | I25: 112109.28 | J25: CODC Out chgs -16-31 Oct 25 | K25: {=VLOOKUP(E25,[1]A023951!D$1:H$1114,{3,5},0)} -> -1273.92 | L25: -112426.72 | M25: =I25+L25 -> -317.44
A26: KUEHNE+NAGEL PVT. LTD. | B26: 2025 | C26: DR | D26: 45966 | E26: 256779419165 | F26: USD | G26: 191.57 | H26: INR | I26: 16858.81 | J26: Outbound chgs - 16 - 31 Oct 25 | K26: {=VLOOKUP(E26,[1]A023951!D$1:H$1114,{3,5},0)} -> -191.57 | L26: -16906.55 | M26: =I26+L26 -> -47.74
A27: KUEHNE+NAGEL PVT. LTD. | B27: 2025 | C27: DR | D27: 45966 | E27: 256779419192 | F27: USD | G27: 171.87 | H27: INR | I27: 15125.14 | J27: Empty Lolo Chgs - 01 - 31 OCT 25 | K27: {=VLOOKUP(E27,[1]A023951!D$1:H$1114,{3,5},0)} -> -171.87 | L27: -15167.97 | M27: =I27+L27 -> -42.83
A28: KUEHNE+NAGEL PVT. LTD. | B28: 2025 | C28: DR | D28: 45966 | E28: 256779419211 | F28: USD | G28: 28.18 | H28: INR | I28: 2479.94 | J28: Internet Activity Chgs - Oct 25 | K28: {=VLOOKUP(E28,[1]A023951!D$1:H$1114,{3,5},0)} -> -28.18 | L28: -2486.96 | M28: =I28+L28 -> -7.02
A29: KUEHNE+NAGEL PVT. LTD. | B29: 2025 | C29: DR | D29: 45966 | E29: 256779419222 | F29: USD | G29: 3537 | H29: INR | I29: 311267.99 | J29: PORT SSR Chgs Oct 25 | K29: {=VLOOKUP(E29,[1]A023951!D$1:H$1114,{3,5},0)} -> #N/A
A30: KUEHNE+NAGEL PVT. LTD. | B30: 2025 | C30: DR | D30: 45964 | E30: 256779419122 | F30: USD | G30: 670.42 | H30: INR | I30: 58999.23 | J30: LCL Chgs - 16 - 31 OCT 25 | K30: {=VLOOKUP(E30,[1]A023951!D$1:H$1114,{3,5},0)} -> -670.42 | L30: -59439.1 | M30: =I30+L30 -> -439.87
A31: KUEHNE+NAGEL PVT. LTD. | B31: 2025 | C31: DG | D31: 45964 | E31: 256779422067 | F31: USD | G31: -4608.8 | H31: INR | I31: -405590.02 | J31: CN issued against 256779417093 | K31: {=VLOOKUP(E31,[1]A023951!D$1:H$1114,{3,5},0)} -> #N/A
A32: KUEHNE+NAGEL PVT. LTD. | B32: 2025 | C32: DR | D32: 45877 | E32: 256779416096 | F32: USD | G32: 7386.34 | H32: INR | I32: 635447.72 | J32: Unit Storage - 1-31 July 25 | K32: {=VLOOKUP(E32,[1]A023951!D$1:H$1114,{3,5},0)} -> -7386.34 | L32: -639885.33 | M32: =I32+L32 -> -4437.61
A33: KUEHNE+NAGEL PVT. LTD. | B33: 2025 | C33: DR | D33: 45877 | E33: 256779416137 | F33: USD | G33: 55.28 | H33: INR | I33: 4755.75 | J33: Empty Lolo Chgs - 01 - 31 JUL 25 | K33: {=VLOOKUP(E33,[1]A023951!D$1:H$1114,{3,5},0)} -> -55 | L33: -4764.7 | M33: =I33+L33 -> -8.95
A34: KUEHNE+NAGEL PVT. LTD. | B34: 2025 | C34: DR | D34: 45877 | E34: 256779416169 | F34: USD | G34: 256.97 | H34: INR | I34: 22107.16 | J34: LCL Chgs - 16 - 31 JUL 25 | K34: {=VLOOKUP(E34,[1]A023951!D$1:H$1114,{3,5},0)} -> -257 | L34: -22264.14 | M34: =I34+L34 -> -156.98
A35: KUEHNE+NAGEL PVT. LTD. | B35: 2025 | C35: DR | D35: 45877 | E35: 256779416214 | F35: USD | G35: 212.34 | H35: INR | I35: 18267.64 | J35: Outbound chgs - 16 - 31 Jul 25 | K35: {=VLOOKUP(E35,[1]A023951!D$1:H$1114,{3,5},0)} -> -212 | L35: -18365.75 | M35: =I35+L35 -> -98.11
A36: KUEHNE+NAGEL PVT. LTD. | B36: 2025 | C36: DR | D36: 45877 | E36: 256779416255 | F36: USD | G36: 392.28 | H36: INR | I36: 33747.9 | J36: CODC Out chgs - 16 - 31 Jul 25 | K36: {=VLOOKUP(E36,[1]A023951!D$1:H$1114,{3,5},0)} -> -392 | L36: -33959.32 | M36: =I36+L36 -> -211.42
A37: KUEHNE+NAGEL PVT. LTD. | B37: 2025 | C37: DR | D37: 45877 | E37: 256779416442 | F37: USD | G37: 1053.34 | H37: INR | I37: 90618.97 | J37: VAS 16-31 July 25 | K37: {=VLOOKUP(E37,[1]A023951!D$1:H$1114,{3,5},0)} -> -1053 | L37: -91222.35 | M37: =I37+L37 -> -603.38
A38: KUEHNE+NAGEL PVT. LTD. | B38: 2025 | C38: DR | D38: 45877 | E38: 256779416454 | F38: USD | G38: 411.19 | H38: INR | I38: 35374.73 | J38: Weighment - 16-31 July 25 | K38: {=VLOOKUP(E38,[1]A023951!D$1:H$1114,{3,5},0)} -> -411 | L38: -35605.3 | M38: =I38+L38 -> -230.57
A39: KUEHNE+NAGEL PVT. LTD. | B39: 2025 | C39: DR | D39: 45812 | E39: 256779414156 | F39: USD | G39: 83.66 | H39: INR | I39: 7152.16 | J39: CODC Inbound chgs - 16 - 31 May 25 | K39: {=VLOOKUP(E39,[1]A023951!D$1:H$1114,{3,5},0)} -> #N/A
A40: KUEHNE+NAGEL PVT. LTD. | B40: 2025 | C40: DR | D40: 45812 | E40: 256779414173 | F40: USD | G40: 2668.72 | H40: INR | I40: 228150.95 | J40: PORT SSR Chgs - 16 - 31 May 25 | K40: {=VLOOKUP(E40,[1]A023951!D$1:H$1114,{3,5},0)} -> #N/A
...

Sheet Sheet12
A1: Customer Account: Name 1 | B1: Fiscal Year | C1: Document Type | D1: Document Date | E1: Entry Date | F1: Reference | G1: Document Currency Key | H1: Document Currency Value | I1: Company Code Currency Key | J1: Company Code Currency Value | K1: Text
A2: KUEHNE+NAGEL PVT. LTD. | B2: 2025 | C2: DR | D2: 45904 | E2: 45909 | F2: 256779417250 | G2: USD | H2: 50 | I2: INR | J2: 4375.72 | K2: Scanning Chgs - 16 - 31 Aug 25
A3: KUEHNE+NAGEL PVT. LTD. | B3: 2025 | C3: DR | D3: 45966 | E3: 45967 | F3: 256779418816 | G3: USD | H3: 891 | I3: INR | J3: 78411.02 | K3: VAS-16 -31 Oct 25
A4: KUEHNE+NAGEL PVT. LTD. | B4: 2025 | C4: DR | D4: 45966 | E4: 45967 | F4: 256779418872 | G4: USD | H4: 5939.04 | I4: INR | J4: 522655.65 | K4: Unit Storage - 1-31 Oct 2025
A5: KUEHNE+NAGEL PVT. LTD. | B5: 2025 | C5: DR | D5: 45966 | E5: 45968 | F5: 256779419222 | G5: USD | H5: 3537 | I5: INR | J5: 311267.99 | K5: PORT SSR Chgs Oct 25
A6: KUEHNE+NAGEL PVT. LTD. | B6: 2025 | C6: DR | D6: 45812 | E6: 45817 | F6: 256779414156 | G6: USD | H6: 83.66 | I6: INR | J6: 7152.16 | K6: CODC Inbound chgs - 16 - 31 May 25
A7: KUEHNE+NAGEL PVT. LTD. | B7: 2025 | C7: DR | D7: 45812 | E7: 45817 | F7: 256779414173 | G7: USD | H7: 2668.72 | I7: INR | J7: 228150.95 | K7: PORT SSR Chgs - 16 - 31 May 25
A8: KUEHNE+NAGEL PVT. LTD. | B8: 2025 | C8: DR | D8: 45812 | E8: 45817 | F8: 256779414206 | G8: USD | H8: 201.33 | I8: INR | J8: 17211.86 | K8: Outbound chgs - 16 - 31 MAY 25
A9: KUEHNE+NAGEL PVT. LTD. | B9: 2025 | C9: DR | D9: 45812 | E9: 45817 | F9: 256779414260 | G9: USD | H9: 130.93 | I9: INR | J9: 11193.31 | K9: Detention Chgs - 01 - 15 MAY 25
A10: KUEHNE+NAGEL PVT. LTD. | B10: 2025 | C10: DR | D10: 45812 | E10: 45817 | F10: 256779414271 | G10: USD | H10: 967.68 | I10: INR | J10: 82727.72 | K10: Empty Lolo Chgs - 01 - 31 MAY 25
A11: KUEHNE+NAGEL PVT. LTD. | B11: 2025 | C11: DR | D11: 45812 | E11: 45817 | F11: 256779414309 | G11: USD | H11: 662.83 | I11: INR | J11: 56665.85 | K11: Transportation In Chgs - 16-31 MAY 25
A12: KUEHNE+NAGEL PVT. LTD. | B12: 2025 | C12: DR | D12: 45793 | E12: 45800 | F12: 256779413280 | G12: USD | H12: 59 | I12: INR | J12: 5073.04 | K12: Scanning Chgs - 16 - 31 Apr 25
A13: KUEHNE+NAGEL PVT. LTD. | B13: 2025 | C13: DR | D13: 45793 | E13: 45800 | F13: 256779413308 | G13: USD | H13: 723.47 | I13: INR | J13: 62206.63 | K13: LCL Chgs - 16 - 30 Apr 25
... A141: KUEHNE+NAGEL PVT. LTD. | B141: 2025 | C141: DR | D141: 45719 | E141: 45719 | F141: 246779410483 | G141: USD | H141: 3.54 | I141: INR | J141: 306.89 | K141: Outbound Handling for Aug 2024

Sheet Sheet4

Sheet CUSTOMER DATA
E1: =SUBTOTAL(9,E3:E732) -> -11983945 | O1: =SUBTOTAL(9,O3:O732) -> 233116.04 | P1: =SUBTOTAL(9,P3:P732) -> -11750829 | R1: =SUBTOTAL(9,R3:R732) -> #N/A
A2: Ty | B2: Item# | C2: Item Date | D2: FC Amount | E2: LC Amount | F2: Particular | G2: Due Date | H2: CCY | I2: VC Period | J2: VC Seq | K2: VC Date | L2: Tx. Type | M2: Company Code | O2: TDS as per customer | P2: Customer balance | Q2: Vlookup | S2: Remarks
A3: I | B3: 256779413908 | C3: 45805 | D3: -3200.83 | E3: -273269.16 | G3: 27/06/2025 | H3: USD | I3: 45962 | J3: 1 | K3: 45991 | L3: 210 | M3: IN89 | N3: =O3/E3 -> -0.02000105 | O3: =VLOOKUP(B3,'Customer TDS'!A:D,4,0) -> 5465.67 | P3: =E3+O3 -> -267803.49 | Q3: =VLOOKUP(B3,Ascendus!E:I,5,0) -> 275219.21 | R3: =E3+Q3 -> 1950.05 | S3: Difference due to exchange rate
A4: I | B4: 256779413908 | C4: 45805 | D4: 0 | E4: -11858.12 | F4: C: ASCENDAS27 P: Matching | G4: 27/06/2025 | H4: USD | I4: 45962 | J4: 66 | K4: 45991 | L4: 271 | M4: IN89 | P4: =E4+O4 -> -11858.12 | S4: Amount recorded by customer but not in our books
A5: I | B5: 256779415989 | C5: 45863 | D5: -299.84 | E5: -25783.09 | G5: 24/08/2025 | H5: USD | I5: 45931 | J5: 1 | K5: 45959 | L5: 210 | M5: IN89 | N5: =O5/E5 -> -0.02001079 | O5: =VLOOKUP(B5,'Customer TDS'!A:D,4,0) -> 515.94 | P5: =E5+O5 -> -25267.15 | Q5: =VLOOKUP(B5,Ascendus!E:I,5,0) -> 25786.44 | R5: =E5+Q5 -> 3.35 | S5: Difference due to exchange rate
A6: I | B6: 256779416007 | C6: 45863 | D6: -421.15 | E6: -36214.48 | G6: 24/08/2025 | H6: USD | I6: 45931 | J6: 1 | K6: 45959 | L6: 210 | M6: IN89 | N6: =O6/E6 -> -0.019992832 | O6: =VLOOKUP(B6,'Customer TDS'!A:D,4,0) -> 724.03 | P6: =E6+O6 -> -35490.45 | Q6: =VLOOKUP(B6,Ascendus!E:I,5,0) -> 36219.18 | R6: =E6+Q6 -> 4.7 | S6: Difference due to exchange rate
A7: I | B7: 256779415989 | C7: 45863 | D7: 0 | E7: -664.99 | F7: C: ASCENDAS27 P: Matching | G7: 24/08/2025 | H7: USD | I7: 45931 | J7: 82 | K7: 45961 | L7: 271 | M7: IN89 | P7: =E7+O7 -> -664.99 | S7: Amount recorded by customer but not in our books
A8: I | B8: 256779416007 | C8: 45863 | D8: 0 | E8: -934.03 | F8: C: ASCENDAS27 P: Matching | G8: 24/08/2025 | H8: USD | I8: 45931 | J8: 84 | K8: 45961 | L8: 271 | M8: IN89 | P8: =E8+O8 -> -934.03 | S8: Amount recorded by customer but not in our books
A9: I | B9: 256779412776 | C9: 45771 | D9: -632.46 | E9: -54218.88 | G9: 24/05/2025 | H9: USD | I9: 45962 | J9: 1 | K9: 45991 | L9: 210 | M9: IN89 | N9: =O9/E9 -> -0.020001335 | O9: =VLOOKUP(B9,'Customer TDS'!A:D,4,0) -> 1084.45 | P9: =E9+O9 -> -53134.43 | Q9: =VLOOKUP(B9,Ascendus!E:I,5,0) -> 54974.57 | R9: =E9+Q9 -> 755.69 | S9: Difference due to exchange rate
A10: I | B10: 256779412776 | C10: 45771 | D10: 0 | E10: -2124.59 | F10: C: ASCENDAS27 P: Matching | G10: 24/05/2025 | H10: USD | I10: 45962 | J10: 58 | K10: 45991 | L10: 271 | M10: IN89 | P10: =E10+O10 -> -2124.59 | S10: Amount recorded by customer but not in our books
A11: I | B11: 256779417801 | C11: 45922 | D11: -4755.47 | E11: -416826.08 | G11: 22/10/2025 | H11: USD | I11: 45931 | J11: 1 | K11: 45959 | L11: 210 | M11: IN89 | N11: =O11/E11 -> -0.020000116 | O11: =VLOOKUP(B11,'Customer TDS'!A:D,4,0) -> 8336.57 | P11: =E11+O11 -> -408489.51 | Q11: =VLOOKUP(B11,Ascendus!E:I,5,0) -> 416171.77 | R11: =E11+Q11 -> -654.31 | S11: Difference due to exchange rate
A12: I | B12: 256779417801 | C12: 45922 | D12: 0 | E12: -2799.24 | F12: C: ASCENDAS27 P: Matching | G12: 22/10/2025 | H12: USD | I12: 45931 | J12: 64 | K12: 45961 | L12: 271 | M12: IN89 | P12: =E12+O12 -> -2799.24 | S12: Amount recorded by customer but not in our books
A13: I | B13: 256779417744 | C13: 45922 | D13: -870 | E13: -76257.17 | G13: 22/10/2025 | H13: USD | I13: 45962 | J13: 1 | K13: 45972 | L13: 210 | M13: IN89 | N13: =O13/E13 -> -0.019999955 | O13: =VLOOKUP(B13,'Customer TDS'!A:D,4,0) -> 1525.14 | P13: =E13+O13 -> -74732.03 | Q13: =VLOOKUP(B13,Ascendus!E:I,5,0) -> 76137.47 | R13: =E13+Q13 -> -119.7 | S13: Difference due to exchange rate
A14: I | B14: 256779412524 | C14: 45769 | D14: -36.5 | E14: -3129.03 | G14: 22/05/2025 | H14: USD | I14: 45809 | J14: 1 | K14: 45838 | L14: 210 | M14: IN89 | N14: =O14/E14 -> -0.019999808 | O14: =VLOOKUP(B14,'Customer TDS'!A:D,4,0) -> 62.58 | P14: =E14+O14 -> -3066.45 | Q14: =VLOOKUP(B14,Ascendus!E:I,5,0) -> 3172.65 | R14: =E14+Q14 -> 43.62 | S14: Difference due to exchange rate
A15: I | B15: 256779412529 | C15: 45769 | D15: -29.57 | E15: -2534.95 | G15: 22/05/2025 | H15: USD | I15: 45809 | J15: 1 | K15: 45838 | L15: 210 | M15: IN89 | N15: =O15/E15 -> -0.019953056 | O15: =VLOOKUP(B15,'Customer TDS'!A:D,4,0) -> 50.58 | P15: =E15+O15 -> -2484.37 | Q15: =VLOOKUP(B15,Ascendus!E:I,5,0) -> 2570.28 | R15: =E15+Q15 -> 35.33 | S15: Difference due to exchange rate
A16: I | B16: 256779412536 | C16: 45769 | D16: -37.02 | E16: -3173.61 | G16: 22/05/2025 | H16: USD | I16: 45809 | J16: 1 | K16: 45838 | L16: 210 | M16: IN89 | N16: =O16/E16 -> -0.019989854 | O16: =VLOOKUP(B16,'Customer TDS'!A:D,4,0) -> 63.44 | P16: =E16+O16 -> -3110.17 | Q16: =VLOOKUP(B16,Ascendus!E:I,5,0) -> 3217.85 | R16: =E16+Q16 -> 44.24 | S16: Difference due to exchange rate
A17: I | B17: 256779412537 | C17: 45769 | D17: -407.58 | E17: -34940.6 | G17: 22/05/2025 | H17: USD | I17: 45809 | J17: 1 | K17: 45838 | L17: 210 | M17: IN89 | N17: =O17/E17 -> -0.019995936 | O17: =VLOOKUP(B17,'Customer TDS'!A:D,4,0) -> 698.67 | P17: =E17+O17 -> -34241.93 | Q17: =VLOOKUP(B17,Ascendus!E:I,5,0) -> 35427.6 | R17: =E17+Q17 -> 487 | S17: Difference due to exchange rate
A18: I | B18: 256779412579 | C18: 45769 | D18: -57.6 | E18: -4937.87 | G18: 22/05/2025 | H18: USD | I18: 45809 | J18: 1 | K18: 45838 | L18: 210 | M18: IN89 | N18: =O18/E18 -> -0.019966099 | O18: =VLOOKUP(B18,'Customer TDS'!A:D,4,0) -> 98.59 | P18: =E18+O18 -> -4839.28 | Q18: =VLOOKUP(B18,Ascendus!E:I,5,0) -> 5006.7 | R18: =E18+Q18 -> 68.83 | S18: Difference due to exchange rate
A19: I | B19: 256779412586 | C19: 45769 | D19: -51.5 | E19: -4414.94 | G19: 22/05/2025 | H19: USD | I19: 45809 | J19: 1 | K19: 45838 | L19: 210 | M19: IN89 | N19: =O19/E19 -> -0.020000272 | O19: =VLOOKUP(B19,'Customer TDS'!A:D,4,0) -> 88.3 | P19: =E19+O19 -> -4326.64 | Q19: =VLOOKUP(B19,Ascendus!E:I,5,0) -> 4476.47 | R19: =E19+Q19 -> 61.53 | S19: Difference due to exchange rate
A20: I | B20: 256779412563 | C20: 45769 | D20: -27 | E20: -2314.63 | G20: 22/05/2025 | H20: USD | I20: 45809 | J20: 1 | K20: 45838 | L20: 210 | M20: IN89 | N20: =O20/E20 -> -0.019998877 | O20: =VLOOKUP(B20,'Customer TDS'!A:D,4,0) -> 46.29 | P20: =E20+O20 -> -2268.34 | Q20: =VLOOKUP(B20,Ascendus!E:I,5,0) -> 2346.89 | R20: =E20+Q20 -> 32.26 | S20: Difference due to exchange rate
A21: I | B21: 256779412576 | C21: 45769 | D21: -46 | E21: -3943.44 | G21: 22/05/2025 | H21: USD | I21: 45809 | J21: 1 | K21: 45838 | L21: 210 | M21: IN89 | N21: =O21/E21 -> -0.020000304 | O21: =VLOOKUP(B21,'Customer TDS'!A:D,4,0) -> 78.87 | P21: =E21+O21 -> -3864.57 | Q21: =VLOOKUP(B21,Ascendus!E:I,5,0) -> 3998.4 | R21: =E21+Q21 -> 54.96 | S21: Difference due to exchange rate
A22: I | B22: 256779412577 | C22: 45769 | D22: -46 | E22: -3943.44 | G22: 22/05/2025 | H22: USD | I22: 45809 | J22: 1 | K22: 45838 | L22: 210 | M22: IN89 | N22: =O22/E22 -> -0.020000304 | O22: =VLOOKUP(B22,'Customer TDS'!A:D,4,0) -> 78.87 | P22: =E22+O22 -> -3864.57 | Q22: =VLOOKUP(B22,Ascendus!E:I,5,0) -> 3998.4 | R22: =E22+Q22 -> 54.96 | S22: Difference due to exchange rate
A23: I | B23: 256779412580 | C23: 45769 | D23: -40.5 | E23: -3471.94 | G23: 22/05/2025 | H23: USD | I23: 45809 | J23: 1 | K23: 45838 | L23: 210 | M23: IN89 | N23: =O23/E23 -> -0.020000346 | O23: =VLOOKUP(B23,'Customer TDS'!A:D,4,0) -> 69.44 | P23: =E23+O23 -> -3402.5 | Q23: =VLOOKUP(B23,Ascendus!E:I,5,0) -> 3520.33 | R23: =E23+Q23 -> 48.39 | S23: Difference due to exchange rate
A24: I | B24: 256779412562 | C24: 45769 | D24: -54.65 | E24: -4684.98 | G24: 22/05/2025 | H24: USD | I24: 45809 | J24: 1 | K24: 45838 | L24: 210 | M24: IN89 | N24: =O24/E24 -> -0.019944589 | O24: =VLOOKUP(B24,'Customer TDS'!A:D,4,0) -> 93.44 | P24: =E24+O24 -> -4591.54 | Q24: =VLOOKUP(B24,Ascendus!E:I,5,0) -> 4750.28 | R24: =E24+Q24 -> 65.3 | S24: Difference due to exchange rate
... A28: I | B28: 256779412585 | C28: 45769 | D28: -48.75 | E28: -4179.19 | G28: 22/05/2025 | H28: USD | I28: 45809 | J28: 1 | K28: 45838 | L28: 210 | M28: IN89 | N28: =O28/E28 -> -0.020101981 | O28: =VLOOKUP(B28,'Customer TDS'!A:D,4,0) -> 84.01 | P28: =E28+O28 -> -4095.18 | Q28: =VLOOKUP(B28,Ascendus!E:I,5,0) -> 4237.44 | R28: =E28+Q28 -> 58.25 | S28: Difference due to exchange rate
A29: I | B29: 256779412583 | C29: 45769 | D29: -51.75 | E29: -4436.37 | G29: 22/05/2025 | H29: USD | I29: 45809 | J29: 1 | K29: 45838 | L29: 210 | M29: IN89 | P29: =E29+O29 -> -4436.37 | Q29: =VLOOKUP(B29,Ascendus!E:I,5,0) -> 4498.2 | R29: =E29+Q29 -> 61.83 | S29: Difference due to exchange rate
A30: I | B30: 256779412524 | C30: 45769 | D30: 0 | E30: -9.39 | F30: C: ASCENDAS27 P: Matching | G30: 22/05/2025 | H30: USD | I30: 45809 | J30: 14 | K30: 45838 | L30: 271 | M30: IN89 | P30: =E30+O30 -> -9.39 | S30: Amount recorded by customer but not in our books
A31: I | B31: 256779412529 | C31: 45769 | D31: 0 | E31: -7.61 | F31: C: ASCENDAS27 P: Matching | G31: 22/05/2025 | H31: USD | I31: 45809 | J31: 16 | K31: 45838 | L31: 271 | M31: IN89 | P31: =E31+O31 -> -7.61 | S31: Amount recorded by customer but not in our books
A32: I | B32: 256779412536 | C32: 45769 | D32: 0 | E32: -9.53 | F32: C: ASCENDAS27 P: Matching | G32: 22/05/2025 | H32: USD | I32: 45809 | J32: 18 | K32: 45838 | L32: 271 | M32: IN89 | P32: =E32+O32 -> -9.53 | S32: Amount recorded by customer but not in our books
A33: I | B33: 256779412537 | C33: 45769 | D33: 0 | E33: -104.86 | F33: C: ASCENDAS27 P: Matching | G33: 22/05/2025 | H33: USD | I33: 45809 | J33: 20 | K33: 45838 | L33: 271 | M33: IN89 | P33: =E33+O33 -> -104.86 | S33: Amount recorded by customer but not in our books
A34: I | B34: 256779412579 | C34: 45769 | D34: 0 | E34: -14.83 | F34: C: ASCENDAS27 P: Matching | G34: 22/05/2025 | H34: USD | I34: 45809 | J34: 22 | K34: 45838 | L34: 271 | M34: IN89 | P34: =E34+O34 -> -14.83 | S34: Amount recorded by customer but not in our books
A35: I | B35: 256779412586 | C35: 45769 | D35: 0 | E35: -13.25 | F35: C: ASCENDAS27 P: Matching | G35: 22/05/2025 | H35: USD | I35: 45809 | J35: 24 | K35: 45838 | L35: 271 | M35: IN89 | P35: =E35+O35 -> -13.25 | S35: Amount recorded by customer but not in our books
A36: I | B36: 256779412563 | C36: 45769 | D36: 0 | E36: -6.94 | F36: C: ASCENDAS27 P: Matching | G36: 22/05/2025 | H36: USD | I36: 45809 | J36: 48 | K36: 45838 | L36: 271 | M36: IN89 | P36: =E36+O36 -> -6.94 | S36: Amount recorded by customer but not in our books
A37: I | B37: 256779412576 | C37: 45769 | D37: 0 | E37: -11.84 | F37: C: ASCENDAS27 P: Matching | G37: 22/05/2025 | H37: USD | I37: 45809 | J37: 52 | K37: 45838 | L37: 271 | M37: IN89 | P37: =E37+O37 -> -11.84 | S37: Amount recorded by customer but not in our books
A38: I | B38: 256779412577 | C38: 45769 | D38: 0 | E38: -11.84 | F38: C: ASCENDAS27 P: Matching | G38: 22/05/2025 | H38: USD | I38: 45809 | J38: 54 | K38: 45838 | L38: 271 | M38: IN89 | P38: =E38+O38 -> -11.84 | S38: Amount recorded by customer but not in our books
A39: I | B39: 256779412580 | C39: 45769 | D39: 0 | E39: -10.42 | F39: C: ASCENDAS27 P: Matching | G39: 22/05/2025 | H39: USD | I39: 45809 | J39: 56 | K39: 45838 | L39: 271 | M39: IN89 | P39: =E39+O39 -> -10.42 | S39: Amount recorded by customer but not in our books
A40: I | B40: 256779412562 | C40: 45769 | D40: 0 | E40: -14.06 | F40: C: ASCENDAS27 P: Matching | G40: 22/05/2025 | H40: USD | I40: 45809 | J40: 66 | K40: 45838 | L40: 271 | M40: IN89 | P40: =E40+O40 -> -14.06 | S40: Amount recorded by customer but not in our books
A41: I | B41: 256779412564 | C41: 45769 | D41: 0 | E41: -14.2 | F41: C: ASCENDAS27 P: Matching | G41: 22/05/2025 | H41: USD | I41: 45809 | J41: 70 | K41: 45838 | L41: 271 | M41: IN89 | P41: =E41+O41 -> -14.2 | S41: Amount recorded by customer but not in our books
... A45: I | B45: 256779412583 | C45: 45769 | D45: 0 | E45: -13.59 | F45: C: ASCENDAS27 P: Matching | G45: 22/05/2025 | H45: USD | I45: 45809 | J45: 104 | K45: 45838 | L45: 271 | M45: IN89 | P45: =E45+O45 -> -13.59 | S45: Amount recorded by customer but not in our books
A46: I | B46: 256779418480 | C46: 45951 | D46: -13.59 | E46: -1204.88 | F46: USD CURRENCY | G46: 20/11/2025 | H46: USD | I46: 45992 | J46: 1 | K46: 46006 | L46: 210 | M46: IN89 | N46: =O46/E46 -> -0.019869199 | O46: =VLOOKUP(B46,'Customer TDS'!A:D,4,0) -> 23.94 | P46: =E46+O46 -> -1180.94 | Q46: =VLOOKUP(B46,Ascendus!E:I,5,0) -> 1198.51 | R46: =E46+Q46 -> -6.37 | S46: Difference due to exchange rate
...

Sheet Customer TDS
A2: Item# | B2: Item Date | C2: FC Amount | D2: LC Amount | E2: Particular | F2: Due Date | G2: CCY | H2: VC Period | I2: VC Seq | J2: VC Date | K2: Tx. Type | L2: Company Code
A3: 256779413908 | B3: 45805 | C3: 64.02 | D3: 5465.67 | E3: C: ASCENDAS27 P: A023951 I 256779413908 | F3: 27/06/2025 | G3: USD | H3: 45962 | I3: 1 | J3: 30/11/2025 | K3: 230 | L3: IN89
A4: 256779416007 | B4: 45863 | C4: 8.42 | D4: 724.03 | E4: C: ASCENDAS27 P: A023951 I 256779416007 | F4: 24/08/2025 | G4: USD | H4: 45931 | I4: 1 | J4: 29/10/2025 | K4: 230 | L4: IN89
A5: 256779415989 | B5: 45863 | C5: 6 | D5: 515.94 | E5: C: ASCENDAS27 P: A023951 I 256779415989 | F5: 24/08/2025 | G5: USD | H5: 45931 | I5: 1 | J5: 29/10/2025 | K5: 230 | L5: IN89
A6: 256779412776 | B6: 45771 | C6: 12.65 | D6: 1084.45 | E6: C: ASCENDAS27 P: A023951 I 256779412776 | F6: 24/05/2025 | G6: USD | H6: 45962 | I6: 1 | J6: 30/11/2025 | K6: 230 | L6: IN89
A7: 256779417801 | B7: 45922 | C7: 95.11 | D7: 8336.57 | E7: C: ASCENDAS27 P: A023951 I 256779417801 | F7: 22/10/2025 | G7: USD | H7: 45931 | I7: 1 | J7: 29/10/2025 | K7: 230 | L7: IN89
A8: 256779417744 | B8: 45922 | C8: 17.4 | D8: 1525.14 | E8: C: ASCENDAS27 P: A023951 I 256779417744 | F8: 22/10/2025 | G8: USD | H8: 45962 | I8: 1 | J8: 45972 | K8: 230 | L8: IN89
A9: 256779412577 | B9: 45769 | C9: 0.92 | D9: 78.87 | E9: C: ASCENDAS27 P: A023951 I 256779412577 | F9: 22/05/2025 | G9: USD | H9: 45809 | I9: 1 | J9: 30/06/2025 | K9: 230 | L9: IN89
A10: 256779412564 | B10: 45769 | C10: 1.1 | D10: 94.3 | E10: C: ASCENDAS27 P: A023951 I 256779412564 | F10: 22/05/2025 | G10: USD | H10: 45809 | I10: 1 | J10: 30/06/2025 | K10: 230 | L10: IN89
A11: 256779412529 | B11: 45769 | C11: 0.59 | D11: 50.58 | E11: C: ASCENDAS27 P: A023951 I 256779412529 | F11: 22/05/2025 | G11: USD | H11: 45809 | I11: 1 | J11: 30/06/2025 | K11: 230 | L11: IN89
A12: 256779412563 | B12: 45769 | C12: 0.54 | D12: 46.29 | E12: C: ASCENDAS27 P: A023951 I 256779412563 | F12: 22/05/2025 | G12: USD | H12: 45809 | I12: 1 | J12: 30/06/2025 | K12: 230 | L12: IN89
A13: 256779412570 | B13: 45769 | C13: 0.87 | D13: 74.58 | E13: C: ASCENDAS27 P: A023951 I 256779412570 | F13: 22/05/2025 | G13: USD | H13: 45809 | I13: 1 | J13: 30/06/2025 | K13: 230 | L13: IN89
A14: 256779412580 | B14: 45769 | C14: 0.81 | D14: 69.44 | E14: C: ASCENDAS27 P: A023951 I 256779412580 | F14: 22/05/2025 | G14: USD | H14: 45809 | I14: 1 | J14: 30/06/2025 | K14: 230 | L14: IN89
A15: 256779412581 | B15: 45769 | C15: 1.03 | D15: 88.3 | E15: C: ASCENDAS27 P: A023951 I 256779412581 | F15: 22/05/2025 | G15: USD | H15: 45809 | I15: 1 | J15: 30/06/2025 | K15: 230 | L15: IN89
A16: 256779412536 | B16: 45769 | C16: 0.74 | D16: 63.44 | E16: C: ASCENDAS27 P: A023951 I 256779412536 | F16: 22/05/2025 | G16: USD | H16: 45809 | I16: 1 | J16: 30/06/2025 | K16: 230 | L16: IN89
A17: 256779412576 | B17: 45769 | C17: 0.92 | D17: 78.87 | E17: C: ASCENDAS27 P: A023951 I 256779412576 | F17: 22/05/2025 | G17: USD | H17: 45809 | I17: 1 | J17: 30/06/2025 | K17: 230 | L17: IN89
A18: 256779412524 | B18: 45769 | C18: 0.73 | D18: 62.58 | E18: C: ASCENDAS27 P: A023951 I 256779412524 | F18: 22/05/2025 | G18: USD | H18: 45809 | I18: 1 | J18: 30/06/2025 | K18: 230 | L18: IN89
A19: 256779412537 | B19: 45769 | C19: 8.15 | D19: 698.67 | E19: C: ASCENDAS27 P: A023951 I 256779412537 | F19: 22/05/2025 | G19: USD | H19: 45809 | I19: 1 | J19: 30/06/2025 | K19: 230 | L19: IN89
A20: 256779412585 | B20: 45769 | C20: 0.98 | D20: 84.01 | E20: C: ASCENDAS27 P: A023951 I 256779412585 | F20: 22/05/2025 | G20: USD | H20: 45809 | I20: 1 | J20: 30/06/2025 | K20: 230 | L20: IN89
... A25: 256779418474 | B25: 45951 | C25: 11.25 | D25: 997.42 | E25: C: ASCENDAS27 P: A023951 I 256779418474 | F25: 20/11/2025 | G25: USD | H25: 46023 | I25: 1 | J25: 28/01/2026 | K25: 230 | L25: IN89
A26: 256779413396 | B26: 45798 | C26: 4.36 | D26: 372.23 | E26: C: ASCENDAS27 P: A023951 I 256779413396 | F26: 20/06/2025 | G26: USD | H26: 45839 | I26: 1 | J26: 45968 | K26: 230 | L26: IN89
A27: 256779413401 | B27: 45798 | C27: 4.6 | D27: 392.72 | E27: C: ASCENDAS27 P: A023951 I 256779413401 | F27: 20/06/2025 | G27: USD | H27: 45839 | I27: 1 | J27: 45968 | K27: 230 | L27: IN89
A28: 256779413395 | B28: 45798 | C28: 5.3 | D28: 452.48 | E28: C: ASCENDAS27 P: A023951 I 256779413395 | F28: 20/06/2025 | G28: USD | H28: 45839 | I28: 1 | J28: 45968 | K28: 230 | L28: IN89
A29: 256779413399 | B29: 45798 | C29: 4.6 | D29: 392.72 | E29: C: ASCENDAS27 P: A023951 I 256779413399 | F29: 20/06/2025 | G29: USD | H29: 45839 | I29: 1 | J29: 45968 | K29: 230 | L29: IN89
A30: 256779413391 | B30: 45798 | C30: 5.07 | D30: 432.85 | E30: C: ASCENDAS27 P: A023951 I 256779413391 | F30: 20/06/2025 | G30: USD | H30: 45901 | I30: 1 | J30: 30/09/2025 | K30: 230 | L30: IN89
A31: 256779413392 | B31: 45798 | C31: 4.36 | D31: 372.23 | E31: C: ASCENDAS27 P: A023951 I 256779413392 | F31: 20/06/2025 | G31: USD | H31: 45901 | I31: 1 | J31: 30/09/2025 | K31: 230 | L31: IN89
A32: 256779412189 | B32: 45768 | C32: 0 | D32: 6 | E32: C: ASCENDAS27 P: A023951 I 256779412189 | F32: 21/05/2025 | G32: INR | H32: 45809 | I32: 1 | J32: 30/06/2025 | K32: 230 | L32: IN89
A33: 256779412185 | B33: 45768 | C33: 1.03 | D33: 88.3 | E33: C: ASCENDAS27 P: A023951 I 256779412185 | F33: 21/05/2025 | G33: USD | H33: 45809 | I33: 1 | J33: 30/06/2025 | K33: 230 | L33: IN89
A34: 256779412184 | B34: 45768 | C34: 1.86 | D34: 159.45 | E34: C: ASCENDAS27 P: A023951 I 256779412184 | F34: 21/05/2025 | G34: USD | H34: 45809 | I34: 1 | J34: 30/06/2025 | K34: 230 | L34: IN89
A35: 256779412155 | B35: 45768 | C35: 46.61 | D35: 3995.73 | E35: C: ASCENDAS27 P: A023951 I 256779412155 | F35: 21/05/2025 | G35: USD | H35: 45809 | I35: 1 | J35: 30/06/2025 | K35: 230 | L35: IN89
A36: 256779419542 | B36: 45981 | C36: 8.19 | D36: 722.79 | E36: C: ASCENDAS27 P: A023951 I 256779419542 | F36: 20/12/2025 | G36: USD | H36: 45992 | I36: 1 | J36: 15/12/2025 | K36: 230 | L36: IN89
A37: 256779419620 | B37: 45981 | C37: 2.05 | D37: 180.92 | E37: C: ASCENDAS27 P: A023951 I 256779419620 | F37: 20/12/2025 | G37: USD | H37: 46023 | I37: 1 | J37: 27/01/2026 | K37: 230 | L37: IN89
A38: 256779419531 | B38: 45981 | C38: 8.36 | D38: 737.79 | E38: C: ASCENDAS27 P: A023951 I 256779419531 | F38: 20/12/2025 | G38: USD | H38: 46023 | I38: 1 | J38: 27/01/2026 | K38: 230 | L38: IN89
A39: 256779418653 | B39: 45950 | C39: 3.41 | D39: 302.33 | E39: C: ASCENDAS27 P: A023951 I 256779418653 | F39: 19/11/2025 | G39: USD | H39: 46023 | I39: 1 | J39: 28/01/2026 | K39: 230 | L39: IN89
A40: 256779416838 | B40: 45889 | C40: 13.7 | D40: 1186.84 | E40: C: ASCENDAS27 P: A023951 I 256779416838 | F40: 19/09/2025 | G40: USD | H40: 46023 | I40: 1 | J40: 28/01/2026 | K40: 230 | L40: IN89
A41: 256779416869 | B41: 45889 | C41: 2.32 | D41: 200.98 | E41: C: ASCENDAS27 P: A023951 I 256779416869 | F41: 19/09/2025 | G41: USD | H41: 46023 | I41: 1 | J41: 28/01/2026 | K41: 230 | L41: IN89
A42: 246779414663 | B42: 45736 | C42: 0.9 | D42: 78.34 | E42: C: ASCENDAS27 P: A023951 I 246779414663 | F42: 19/04/2025 | G42: USD | H42: 45809 | I42: 1 | J42: 45997 | K42: 230 | L42: IN89
A43: 246779414662 | B43: 45736 | C43: 5.5 | D43: 478.73 | E43: C: ASCENDAS27 P: A023951 I 246779414662 | F43: 19/04/2025 | G43: USD | H43: 45809 | I43: 1 | J43: 45997 | K43: 230 | L43: IN89
A44: 246779414385 | B44: 45736 | C44: 4.8 | D44: 417.8 | E44: C: ASCENDAS27 P: A023951 I 246779414385 | F44: 19/04/2025 | G44: USD | H44: 45809 | I44: 1 | J44: 45997 | K44: 230 | L44: IN89
A45: 246779413730 | B45: 45736 | C45: 0.06 | D45: 5.22 | E45: C: ASCENDAS27 P: A023951 I 246779413730 | F45: 19/04/2025 | G45: USD | H45: 45809 | I45: 1 | J45: 45997 | K45: 230 | L45: IN89
...

Sheet Customer P matching
B2: Item# | C2: Item Date | D2: FC Amount | E2: LC Amount | F2: Particular | G2: Due Date | H2: CCY | I2: VC Period | J2: VC Seq | K2: VC Date | L2: Tx. Type | M2: Company Code
