Workbook

Sheet Summary
A1: Reconciliation of Ledger as on 31st January 2026
A2: Particulars | B2: Amount
A3: Balance as per Shah TC Exim LLP | B3: =-'Customer Data'!L279 -> 13295.313
A4: Add: TDS recorded by customer but not in our books | B4: ='TDS Deducted'!O1-'Payment Reco Updated'!M19 -> 4115.9928 | C4: >> to be knocked against Payment
A5: Add: Invoices / CN not recorded in customer books | B5: ='Invoice not in Customer books'!I1 -> 7523.3641 | C5: >> to be confirmed by customer
A6: Add: Bank Charges and Foreign Exchange gain/loss | B6: =-('Payment Reco Updated'!L19+'Payment Reco Updated'!N19) -> 226.32 | C6: >> to be confirmed by CL team
A7: Less: Invoices under recorded in Ascendus books | B7: ='Difference in Invoice Amount'!M4 -> -96.0148 | C7: >> to be confirmed by CL team
A8: Less: Invoices in Customers books and not in Ascendus books | B8: =-'Customer Data Vlookup'!S11 -> -131.5718 | C8: >> to be confirmed by CL team
A9: Derived balance | B9: =SUM(B3:B8) -> 24933.403
A10: Balance as per Ascendus | B10: ='Ascendus Data'!G1 -> 25229.422
A12: Difference | B12: =B9-B10-B11 -> -296.0188

Sheet Payment Reco Updated
A1: Document Date | B1: Remarks | C1: Ref No | D1: Debit (FC) | E1: Payment Date | F1: Currency | G1: Recd Amount | H1: UTR Details | I1: Clearing Document | J1: Document Header Text | K1: Document Currency Value | L1: Bank Charges | M1: TDS | N1: Foreign Exchange Gain/Loss | O1: Remark
A2: 45876 | B2: Outgoing Payments - VD0304,Being payment done against USD 1007 | C2: 003MISC252190104 | D2: 1007.818 | E2: 45877 | F2: USD | G2: 986.32 | H2: 8681446219FS | I2: 1400000864 | J2: 8681446219FS | K2: -1102.02 | L2: =D2-G2 -> 21.498 | M2: 94.2 | N2: =-(K2+G2+M2) -> 21.5
A3: 45959 | B3: Outgoing Payments - VD0304,Being payment done against USD 1752 | C3: 003MISC253020092 | D3: 1752.7656 | E3: 45960 | F3: USD | G3: 1731.27 | H3: 2169049302JS | I3: Not Yet Cleared | J3: T54SWIC278972 | K3: -1731.27 | L3: =D3-G3 -> 21.4956 | M3: =K3+G3 -> 0 | N3: =-(K3+G3+M3) -> 0 | O3: To Be Cleared
A4: 45961 | B4: Outgoing Payments - VD0304,Being $1989 | C4: 003MISC253040153 | D4: 1989.9404 | E4: 45964 | F4: USD | G4: 1968.44 | H4: 2225660304JS | I4: Not Yet Cleared | J4: T54SWIC279192 | K4: -1968.44 | L4: =D4-G4 -> 21.5004 | M4: =K4+G4 -> 0 | N4: =-(K4+G4+M4) -> 0 | O4: To Be Cleared
A5: 46022 | B5: Outgoing Payments - VD0304,Being $2328 | C5: 003MISC253650039 | D5: 2368.203 | E5: 46024 | F5: USD | G5: 2346.7 | H5: T54SWIC285279 | I5: 1400002372 | J5: T54SWIC285279 | K5: -2517.26 | L5: =D5-G5 -> 21.503 | M5: 184.34 | N5: =-(K5+G5+M5) -> -13.78
A6: 45910 | B6: Outgoing Payments - VD0304,Being payment done against USD 2954 | C6: 003MISC252530130 | D6: 2954.3362 | E6: 45911 | F6: USD | G6: 2932.84 | H6: 4568362253FS | I6: Not Yet Cleared | J6: 4568362253FS | K6: -2932.84 | L6: =D6-G6 -> 21.4962 | M6: =K6+G6 -> 0 | N6: =-(K6+G6+M6) -> 0 | O6: To Be Cleared
A7: 45813 | B7: Outgoing Payments - VD0304,Being Amount paid to ascendas against bank ref | C7: 003MISC251560102 | D7: 3167.4752 | E7: 45814 | F7: USD | G7: 3145.98 | H7: 8113643156FS | I7: Not Yet Cleared | J7: 8113643156FS | K7: -3145.98 | L7: =D7-G7 -> 21.4952 | M7: =K7+G7 -> 0 | N7: =-(K7+G7+M7) -> 0 | O7: To Be Cleared
A8: 45813 | B8: Outgoing Payments - VD0304, Being Amount paid to ascendas against bank ref | C8: 003MISC251560088 | D8: 3529.5558 | E8: 45814 | F8: USD | G8: 3508.06 | H8: 9422978156FS | I8: Not Yet Cleared | J8: 9422978156FS | K8: -3508.06 | L8: =D8-G8 -> 21.4958 | M8: =K8+G8 -> 0 | N8: =-(K8+G8+M8) -> 0 | O8: To Be Cleared
A9: 45813 | B9: Outgoing Payments - VD0304,Being Amount paid to ascendas against bank ref | C9: 003MISC251560090 | D9: 3685.2032 | E9: 45814 | F9: USD | G9: 3663.7 | H9: 1810304156FS | I9: Not Yet Cleared | J9: T54SWIC264904 | K9: -3663.7 | L9: =D9-G9 -> 21.5032 | M9: =K9+G9 -> 0 | N9: =-(K9+G9+M9) -> 0 | O9: To Be Cleared
A10: 45856 | B10: Outgoing Payments - VD0304,Being payment done against USD 3798 | C10: 003MISC251990131 | D10: 3742.0478 | E10: 45859 | F10: USD | G10: 3777.49 | H10: 1984476199FS | I10: Not Yet Cleared | J10: T54SWIC268990 | K10: -3777.49 | L10: =D10-G10 -> -35.4422 | M10: =K10+G10 -> 0 | N10: =-(K10+G10+M10) -> 0 | O10: To Be Cleared
A11: 45821 | B11: Outgoing Payments - VD0304,Being Amount paid to ascendas against bank ref | C11: 003FT01251640038 | D11: 4224.8172 | E11: 45824 | F11: USD | G11: 4228.22 | H11: 4989824164FS | I11: Not Yet Cleared | J11: 4989824164FS | K11: -4228.22 | L11: =D11+D12-G11 -> -0.002 | M11: =K11+G11 -> 0 | N11: =-(K11+G11+M11) -> 0 | O11: To Be Cleared
A12: 45821 | B12: Being $3.4008 less paid in this bill because in summary sheet 2% tds deduscted instead of 10% | C12: HDFC Bank - INR | D12: 3.4008 | L12: 0 | N12: =-(K12+G12+M12) -> 0
A13: 45910 | B13: Outgoing Payments - VD0304,Being payment done against USD 4740 | C13: 003MISC252530128 | D13: 4740.77 | E13: 45911 | F13: USD | G13: 4719.25 | H13: 0758767253FS | I13: Not Yet Cleared | J13: 0758767253FS | K13: -4719.25 | L13: =D13-G13 -> 21.52 | M13: =K13+G13 -> 0 | N13: =-(K13+G13+M13) -> 0 | O13: To Be Cleared
A14: 45877 | B14: Outgoing Payments - VD0304,Being payment done against USD 4800 | C14: 003MISC252200121 | D14: 4800.3366 | E14: 45880 | F14: USD | G14: 4778.84 | H14: 0798436220FS | I14: 1400000854 | K14: -5138.35 | L14: =D14-G14 -> 21.4966 | M14: 338 | N14: =-(K14+G14+M14) -> 21.51
A15: 45916 | B15: Outgoing Payments - VD0304,Being payment done against USD 5041 | C15: 003MISC252590125 | D15: 5041.56 | E15: 45918 | F15: USD | G15: 8339.84 | H15: 5940256259FS | I15: Not Yet Cleared | J15: 5940256259FS | K15: -8339.84 | L15: =D15+D16-G15 -> 29.488 | M15: =K15+G15 -> 0 | N15: =-(K15+G15+M15) -> 0 | O15: To Be Cleared
A16: 45916 | B16: Outgoing Payments - VD0304,Being payment done against USD 3327 | C16: 003MISC252590125 | D16: 3327.768 | L16: 0 | N16: =-(K16+G16+M16) -> 0
A17: 45961 | B17: Outgoing Payments - VD0304,Being $10502 | C17: 003MISC253040148 | D17: 10502.163 | E17: 45964 | F17: USD | G17: 10455.66 | H17: 2220942304JS | I17: Not Yet Cleared | J17: T54SWIC279194 | K17: -10455.66 | L17: =D17-G17 -> 46.5028 | M17: =K17+G17 -> 0 | N17: =-(K17+G17+M17) -> 0 | O17: To Be Cleared
A18: 45821 | B18: Outgoing Payments - VD0304,Being Amount paid to ascendas against bank ref | C18: 003FT01251640051 | D18: 12549.359 | E18: 45824 | F18: USD | G18: 12549.36 | H18: 1171852164FS | I18: Not Yet Cleared | J18: 1171852164FS | K18: -12549.36 | L18: =D18-G18 -> -0.0006 | M18: =K18+G18 -> 0 | N18: =-(K18+G18+M18) -> 0 | O18: To Be Cleared
D19: =SUM(D2:D18) -> 69387.52 | G19: =SUM(G2:G18) -> 69131.97 | K19: =SUM(K2:K18) -> -69777.74 | L19: =-SUM(L2:L18) -> -255.55 | M19: =SUM(M2:M18) -> 616.54 | N19: =SUM(N2:N18) -> 29.23
G23: =K19+D19 -> -390.22

Sheet Ascendus Data
F1: 25229.422 | G1: =SUBTOTAL(9,G3:G317) -> 25229.422 | I1: =SUBTOTAL(9,I3:I317) -> 4171298.9
A2: Document Number | B2: Document Type | C2: Document Date | D2: Reference | E2: Document Currency Key | F2: Document Currency Value | G2: USD Value | H2: Company Code Currency Key | I2: Company Code Currency Value | K2: Gross Amount | L2: Net Amount | M2: Diffrence | N2: Rate | O2: Text
A3: 1400001110 | B3: DY | C3: 45902 | E3: INR | F3: 603848.88 | G3: =F3/87 -> 6940.7917 | H3: INR | I3: 595243.31 | J3: {=_xlfn.XLOOKUP(D3,'Customer Data Vlookup'!$L:$L,'Customer Data Vlookup'!$M:$N,,0)} -> #N/A
A4: 1400001110 | B4: DY | C4: 45902 | E4: INR | F4: -603848.88 | G4: =F4/87 -> -6940.7917 | H4: INR | I4: -599760.56 | J4: {=_xlfn.XLOOKUP(D4,'Customer Data Vlookup'!$L:$L,'Customer Data Vlookup'!$M:$N,,0)} -> #N/A
A5: 1400000854 | B5: DZ | C5: 45887 | E5: USD | F5: -700.45 | G5: =F5 -> -700.45 | H5: INR | I5: -60884.42 | J5: {=_xlfn.XLOOKUP(D5,'Customer Data Vlookup'!$L:$L,'Customer Data Vlookup'!$M:$N,,0)} -> #N/A
A6: 1400001231 | B6: DZ | C6: 45931 | E6: USD | F6: -4719.25 | G6: =F6 -> -4719.25 | H6: INR | I6: -413002 | J6: {=_xlfn.XLOOKUP(D6,'Customer Data Vlookup'!$L:$L,'Customer Data Vlookup'!$M:$N,,0)} -> #N/A
A7: 1400000977 | B7: DZ | C7: 45890 | E7: USD | F7: -3663.7 | G7: =F7 -> -3663.7 | H7: INR | I7: -313212.57 | J7: {=_xlfn.XLOOKUP(D7,'Customer Data Vlookup'!$L:$L,'Customer Data Vlookup'!$M:$N,,0)} -> #N/A
A8: 1400000990 | B8: DZ | C8: 45890 | E8: USD | F8: -3777.49 | G8: =F8 -> -3777.49 | H8: INR | I8: -324866.67 | J8: {=_xlfn.XLOOKUP(D8,'Customer Data Vlookup'!$L:$L,'Customer Data Vlookup'!$M:$N,,0)} -> #N/A
A9: 1400000126 | B9: DZ | C9: 45832 | E9: USD | F9: -3663.7 | G9: =F9 -> -3663.7 | H9: INR | I9: -3663.7 | J9: {=_xlfn.XLOOKUP(D9,'Customer Data Vlookup'!$L:$L,'Customer Data Vlookup'!$M:$N,,0)} -> #N/A
A10: 1400000127 | B10: DZ | C10: 45832 | E10: USD | F10: -3508.06 | G10: =F10 -> -3508.06 | H10: INR | I10: -3508.06 | J10: {=_xlfn.XLOOKUP(D10,'Customer Data Vlookup'!$L:$L,'Customer Data Vlookup'!$M:$N,,0)} -> #N/A
A11: 1400000128 | B11: DZ | C11: 45832 | E11: USD | F11: -3145.98 | G11: =F11 -> -3145.98 | H11: INR | I11: -3145.98 | J11: {=_xlfn.XLOOKUP(D11,'Customer Data Vlookup'!$L:$L,'Customer Data Vlookup'!$M:$N,,0)} -> #N/A
A12: 1400000133 | B12: DZ | C12: 45832 | E12: USD | F12: -12549.36 | G12: =F12 -> -12549.36 | H12: INR | I12: -12549.36 | J12: {=_xlfn.XLOOKUP(D12,'Customer Data Vlookup'!$L:$L,'Customer Data Vlookup'!$M:$N,,0)} -> #N/A
A13: 1400000134 | B13: DZ | C13: 45832 | E13: USD | F13: -4228.22 | G13: =F13 -> -4228.22 | H13: INR | I13: -4228.22 | J13: {=_xlfn.XLOOKUP(D13,'Customer Data Vlookup'!$L:$L,'Customer Data Vlookup'!$M:$N,,0)} -> #N/A
A14: 1400000149 | B14: DZ | C14: 45832 | E14: USD | F14: 3663.7 | G14: =F14 -> 3663.7 | H14: INR | I14: 3663.7 | J14: {=_xlfn.XLOOKUP(D14,'Customer Data Vlookup'!$L:$L,'Customer Data Vlookup'!$M:$N,,0)} -> #N/A
A15: 1400000854 | B15: DZ | C15: 45887 | E15: USD | F15: -4437.9 | G15: =F15 -> -4437.9 | H15: INR | I15: -383425.92 | J15: {=_xlfn.XLOOKUP(D15,'Customer Data Vlookup'!$L:$L,'Customer Data Vlookup'!$M:$N,,0)} -> #N/A
A16: 1400000864 | B16: DZ | C16: 45888 | E16: USD | F16: -1102.02 | G16: =F16 -> -1102.02 | H16: INR | I16: -94695.18 | J16: {=_xlfn.XLOOKUP(D16,'Customer Data Vlookup'!$L:$L,'Customer Data Vlookup'!$M:$N,,0)} -> #N/A | O16: 8681446219FS
A17: 1400001221 | B17: DZ | C17: 45924 | E17: USD | F17: -2932.84 | G17: =F17 -> -2932.84 | H17: INR | I17: -256665.53 | J17: {=_xlfn.XLOOKUP(D17,'Customer Data Vlookup'!$L:$L,'Customer Data Vlookup'!$M:$N,,0)} -> #N/A
A18: 1400001598 | B18: DZ | C18: 45964 | E18: USD | F18: -1731.27 | G18: =F18 -> -1731.27 | H18: INR | I18: -152682.03 | J18: {=_xlfn.XLOOKUP(D18,'Customer Data Vlookup'!$L:$L,'Customer Data Vlookup'!$M:$N,,0)} -> #N/A
A19: 1400001618 | B19: DZ | C19: 45972 | E19: USD | F19: -1968.44 | G19: =F19 -> -1968.44 | H19: INR | I19: -173229.39 | J19: {=_xlfn.XLOOKUP(D19,'Customer Data Vlookup'!$L:$L,'Customer Data Vlookup'!$M:$N,,0)} -> #N/A
A20: 1400001620 | B20: DZ | C20: 45972 | E20: USD | F20: -8339.84 | G20: =F20 -> -8339.84 | H20: INR | I20: -729855.51 | J20: {=_xlfn.XLOOKUP(D20,'Customer Data Vlookup'!$L:$L,'Customer Data Vlookup'!$M:$N,,0)} -> #N/A
A21: 1400001622 | B21: DZ | C21: 45972 | E21: USD | F21: -10455.66 | G21: =F21 -> -10455.66 | H21: INR | I21: -920133.52 | J21: {=_xlfn.XLOOKUP(D21,'Customer Data Vlookup'!$L:$L,'Customer Data Vlookup'!$M:$N,,0)} -> #N/A
A22: 1400000213 | B22: DY | C22: 45842 | D22: KNOCK OFF ENTRY | E22: USD | F22: 0 | G22: =F22 -> 0 | H22: INR | I22: 0 | J22: {=_xlfn.XLOOKUP(D22,'Customer Data Vlookup'!$L:$L,'Customer Data Vlookup'!$M:$N,,0)} -> #N/A
A23: 1400000214 | B23: DY | C23: 45842 | D23: KNOCK OFF ENTRY | E23: USD | F23: 1166.59 | G23: =F23 -> 1166.59 | H23: INR | I23: 101402.13 | J23: {=_xlfn.XLOOKUP(D23,'Customer Data Vlookup'!$L:$L,'Customer Data Vlookup'!$M:$N,,0)} -> #N/A
A24: 1400000214 | B24: DY | C24: 45842 | D24: KNOCK OFF ENTRY | E24: USD | F24: -1166.59 | G24: =F24 -> -1166.59 | H24: INR | I24: -101402.13 | J24: {=_xlfn.XLOOKUP(D24,'Customer Data Vlookup'!$L:$L,'Customer Data Vlookup'!$M:$N,,0)} -> #N/A
A25: 1400000215 | B25: DY | C25: 45842 | D25: KNOCK OFF ENTRY | E25: USD | F25: 1143.12 | G25: =F25 -> 1143.12 | H25: INR | I25: 99362.07 | J25: {=_xlfn.XLOOKUP(D25,'Customer Data Vlookup'!$L:$L,'Customer Data Vlookup'!$M:$N,,0)} -> #N/A
A26: 1400000215 | B26: DY | C26: 45842 | D26: KNOCK OFF ENTRY | E26: USD | F26: -1143.12 | G26: =F26 -> -1143.12 | H26: INR | I26: -99362.07 | J26: {=_xlfn.XLOOKUP(D26,'Customer Data Vlookup'!$L:$L,'Customer Data Vlookup'!$M:$N,,0)} -> #N/A
A27: 1800008260 | B27: DR | C27: 45787 | D27: 256779413144 | E27: INR | F27: 100000 | G27: =L27/0.9 -> 1163.0111 | H27: INR | I27: 100000 | J27: {=_xlfn.XLOOKUP(D27,'Customer Data Vlookup'!$L:$L,'Customer Data Vlookup'!$M:$N,,0)} -> 0 | K27: 1046.71 | L27: =K27-J27 -> 1046.71 | M27: =G27-L27 -> 116.30111 | N27: =M27/G27 -> 0.1 | O27: Fixed Storage Charges fo MAY 2025
A28: 1800009592 | B28: DR | C28: 45818 | D28: 256779414356 | E28: INR | F28: 100000 | G28: =L28/0.9 -> 1169.72 | H28: INR | I28: 100000 | J28: {=_xlfn.XLOOKUP(D28,'Customer Data Vlookup'!$L:$L,'Customer Data Vlookup'!$M:$N,,0)} -> 0 | K28: 1052.748 | L28: =K28-J28 -> 1052.748 | M28: =G28-L28 -> 116.972 | N28: =M28/G28 -> 0.1 | O28: Fixed Storage Charges fo JUNE 2025
A29: 1800010154 | B29: DR | C29: 45842 | D29: 256779414914 | E29: INR | F29: 100000 | G29: =L29/0.9 -> 1162.78 | H29: INR | I29: 100000 | J29: {=_xlfn.XLOOKUP(D29,'Customer Data Vlookup'!$L:$L,'Customer Data Vlookup'!$M:$N,,0)} -> 0 | K29: 1046.502 | L29: =K29-J29 -> 1046.502 | M29: =G29-L29 -> 116.278 | N29: =M29/G29 -> 0.1 | O29: Fixed Storage Charges fo JULY 2025
A30: 1800011360 | B30: DR | C30: 45870 | D30: 256779416026 | E30: INR | F30: 100000 | G30: =L30/0.9 -> 1162.3778 | H30: INR | I30: 100000 | J30: {=_xlfn.XLOOKUP(D30,'Customer Data Vlookup'!$L:$L,'Customer Data Vlookup'!$M:$N,,0)} -> 0 | K30: 1046.14 | L30: =K30-J30 -> 1046.14 | M30: =G30-L30 -> 116.23778 | N30: =M30/G30 -> 0.1 | O30: Fixed Storage Charges for August 2025
A31: 1800012712 | B31: DR | C31: 45904 | D31: 256779417346 | E31: INR | F31: 100000 | G31: =L31/0.9 -> 1142.67 | H31: INR | I31: 100000 | J31: {=_xlfn.XLOOKUP(D31,'Customer Data Vlookup'!$L:$L,'Customer Data Vlookup'!$M:$N,,0)} -> 0 | K31: 1028.403 | L31: =K31-J31 -> 1028.403 | M31: =G31-L31 -> 114.267 | N31: =M31/G31 -> 0.1 | O31: Fixed Storage Charges for September 2025
A32: 1800014235 | B32: DR | C32: 45966 | D32: 256779418775 | E32: INR | F32: 100000 | G32: =L32/0.9 -> 1136.32 | H32: INR | I32: 100000 | J32: {=_xlfn.XLOOKUP(D32,'Customer Data Vlookup'!$L:$L,'Customer Data Vlookup'!$M:$N,,0)} -> 0 | K32: 1022.688 | L32: =K32-J32 -> 1022.688 | M32: =G32-L32 -> 113.632 | N32: =M32/G32 -> 0.1 | O32: Fixed Storage Charges for November 2025
A33: 1800015484 | B33: DR | C33: 45995 | D33: 256779419968 | E33: INR | F33: 100000 | G33: =L33/0.9 -> 1127.39 | H33: INR | I33: 100000 | J33: {=_xlfn.XLOOKUP(D33,'Customer Data Vlookup'!$L:$L,'Customer Data Vlookup'!$M:$N,,0)} -> 0 | K33: 1014.651 | L33: =K33-J33 -> 1014.651 | M33: =G33-L33 -> 112.739 | N33: =M33/G33 -> 0.1 | O33: Fixed Storage Charges for December 2025
A34: 1800008261 | B34: DR | C34: 45787 | D34: 256779413145 | E34: INR | F34: 35000 | G34: =L34/0.9 -> 407.05 | H34: INR | I34: 35000 | J34: {=_xlfn.XLOOKUP(D34,'Customer Data Vlookup'!$L:$L,'Customer Data Vlookup'!$M:$N,,0)} -> 0 | K34: 366.345 | L34: =K34-J34 -> 366.345 | M34: =G34-L34 -> 40.705 | N34: =M34/G34 -> 0.1 | O34: Fixed Storage Charges fo MAY 2025
A35: 1800009593 | B35: DR | C35: 45818 | D35: 256779414357 | E35: INR | F35: 35000 | G35: =L35/0.9 -> 409.4 | H35: INR | I35: 35000 | J35: {=_xlfn.XLOOKUP(D35,'Customer Data Vlookup'!$L:$L,'Customer Data Vlookup'!$M:$N,,0)} -> 0 | K35: 368.46 | L35: =K35-J35 -> 368.46 | M35: =G35-L35 -> 40.94 | N35: =M35/G35 -> 0.1 | O35: Fixed Storage Charges fo JUNE 2025
A36: 1800010155 | B36: DR | C36: 45842 | D36: 256779414915 | E36: INR | F36: 35000 | G36: =L36/0.9 -> 443.14511 | H36: INR | I36: 35000 | J36: {=_xlfn.XLOOKUP(D36,'Customer Data Vlookup'!$L:$L,'Customer Data Vlookup'!$M:$N,,0)} -> 0 | K36: 398.8306 | L36: =K36-J36 -> 398.8306 | M36: =G36-L36 -> 44.314511 | N36: =M36/G36 -> 0.1 | O36: Fixed Storage Charges fo JULY 2025
A37: 1800011361 | B37: DR | C37: 45870 | D37: 256779416027 | E37: INR | F37: 35000 | G37: =L37/0.9 -> 442.98889 | H37: INR | I37: 35000 | J37: {=_xlfn.XLOOKUP(D37,'Customer Data Vlookup'!$L:$L,'Customer Data Vlookup'!$M:$N,,0)} -> 0 | K37: 398.69 | L37: =K37-J37 -> 398.69 | M37: =G37-L37 -> 44.298889 | N37: =M37/G37 -> 0.1 | O37: Fixed Storage Charges for August 2025
A38: 1800012713 | B38: DR | C38: 45904 | D38: 256779417347 | E38: INR | F38: 35000 | G38: =L38/0.9 -> 399.93 | H38: INR | I38: 35000 | J38: {=_xlfn.XLOOKUP(D38,'Customer Data Vlookup'!$L:$L,'Customer Data Vlookup'!$M:$N,,0)} -> 0 | K38: 359.937 | L38: =K38-J38 -> 359.937 | M38: =G38-L38 -> 39.993 | N38: =M38/G38 -> 0.1 | O38: Fixed Storage Charges for September 2025
... A40: 1800015485 | B40: DR | C40: 45995 | D40: 256779419969 | E40: INR | F40: 35000 | G40: =L40/0.9 -> 429.66467 | H40: INR | I40: 35000 | J40: {=_xlfn.XLOOKUP(D40,'Customer Data Vlookup'!$L:$L,'Customer Data Vlookup'!$M:$N,,0)} -> 0 | K40: 386.6982 | L40: =K40-J40 -> 386.6982 | M40: =G40-L40 -> 42.966467 | N40: =M40/G40 -> 0.1 | O40: Fixed Mangement FEE for December 2025
A41: 1600002145 | B41: DG | C41: 45890 | D41: 256779421709 | E41: INR | F41: -200000 | G41: =F41/87 -> -2298.8506 | H41: INR | I41: -200000 | J41: {=_xlfn.XLOOKUP(D41,'Customer Data Vlookup'!$L:$L,'Customer Data Vlookup'!$M:$N,,0)} -> #N/A | O41: CN issued towards D & D
...

Sheet Payment Reco
A2: As per Customer | E2: As per Ascendus
A3: Document Date | B3: Remarks | C3: Offset Acct Name | D3: Amount | E3: Document Type | F3: Document Date | G3: Document Currency Key | H3: Document Currency Value
A4: 45813 | B4: Outgoing Payments - VD0304, Being Amount paid to ascendas against bank ref. no-003MISC251560088 dated 5-6-2025. | C4: YES BANK - 038784600000486 - CC A/c(SGE) | D4: 3529.5558 | E4: DZ | F4: 45832 | G4: USD | H4: 3663.7
A5: 45813 | B5: Outgoing Payments - VD0304,Being Amount paid to ascendas against bank ref. no-003MISC251560102 dated 5-6-2025. | C5: YES BANK - 038784600000486 - CC A/c(SGE) | D5: 3167.4752 | E5: DZ | F5: 45832 | G5: USD | H5: 3508.06
A6: 45813 | B6: Outgoing Payments - VD0304,Being Amount paid to ascendas against bank ref. no-003MISC251560090 dated 5-6-2025. | C6: YES BANK - 038784600000486 - CC A/c(SGE) | D6: 3685.2032 | E6: DZ | F6: 45832 | G6: USD | H6: 3145.98
A7: 45821 | B7: Outgoing Payments - VD0304,Being Amount paid to ascendas against bank ref. no-003FT01251640051 dated 13-6-2025. | C7: HDFC Bank - INR | D7: 12549.359 | E7: DZ | F7: 45832 | G7: USD | H7: 12549.36
A8: 45821 | B8: Outgoing Payments - VD0304,Being Amount paid to ascendas against bank ref. no-003FT01251640038 dated 13-6-2025. | C8: HDFC Bank - INR | E8: DZ | F8: 45832 | G8: USD | H8: 4228.22
A9: 45821 | B9: Reverse Entry for Payment No. 7360143 | C9: HDFC Bank - INR | E9: DZ | F9: 45887 | G9: USD | H9: 700.45
A10: 45821 | B10: Outgoing Payments - VD0304,Being Amount paid to ascendas against bank ref. no-003FT01251640038 dated 13-6-2025. | C10: HDFC Bank - INR | D10: 4127.955 | E10: DZ | F10: 45887 | G10: USD | H10: 4437.9
A11: 45821 | B11: Being $3.4008 less paid in this bill because in summary sheet 2% tds deduscted instead of 10% | C11: HDFC Bank - INR | D11: 3.4008 | E11: DZ | F11: 45888 | G11: USD | H11: 1102.02
A12: 45821 | B12: Reverse Entry for Payment No. 7360144 | C12: HDFC Bank - INR | D12: -4127.955 | E12: DZ | F12: 45890 | G12: USD | H12: 3777.49
A13: 45821 | B13: Outgoing Payments - VD0304,Being Amount paid to ascendas against bank ref. no-003FT01251640038 dated 13-6-2025. | C13: HDFC Bank - INR | D13: 4224.8172 | E13: DZ | F13: 46029 | G13: USD | H13: 986.48
A14: 45856 | B14: Outgoing Payments - VD0304,Being payment done against USD 3798.9858 ASCENDAS PANVEL FTWZ PRIVATE LIMITED, Bank ref no.- 003MISC251990131 dated-18-07-2025. | C14: YES BANK - USD | D14: 3742.0478 | E14: DZ | F14: 45924 | G14: USD | H14: 2932.84
A15: 45876 | B15: Outgoing Payments - VD0304,Being payment done against USD 1007.82 ASCENDAS PANVEL FTWZ PRIVATE LIMITED, Bank ref no.- 003MISC252190104 dated-07-08-2025. | C15: YES BANK - USD | D15: 1007.818 | H15: 0
A16: 45877 | B16: Outgoing Payments - VD0304,Being payment done against USD 4800.34 ASCENDAS PANVEL FTWZ PRIVATE LIMITED, Bank ref no.- 003MISC252200121 dated-08-08-2025. | C16: YES BANK - USD | D16: 4800.3366 | E16: DZ | F16: 45931 | G16: USD | H16: 4719.25
A17: 45910 | B17: Outgoing Payments - VD0304,Being payment done against USD 2954.34 ASCENDAS PANVEL FTWZ PRIVATE LIMITED, Bank ref no.- 003MISC252530130 dated-10-09-2025. | C17: YES BANK - USD | D17: 2954.3362 | E17: DZ | F17: 45964 | G17: USD | H17: 1731.27
A18: 45910 | B18: Outgoing Payments - VD0304,Being payment done against USD 4740.75 ASCENDAS PANVEL FTWZ PRIVATE LIMITED, Bank ref no.- 003MISC252530128 dated-10-09-2025. | C18: YES BANK - USD | D18: 4740.77 | E18: DZ | F18: 45972 | G18: USD | H18: 1968.44
A19: 45916 | B19: Outgoing Payments - VD0304,Being payment done against USD 5041.57 ASCENDAS PANVEL FTWZ PRIVATE LIMITED, Bank ref no.- 003MISC252590125 dated-16-09-2025. | C19: YES BANK - USD | D19: 5041.56 | E19: DZ | F19: 45972 | G19: USD | H19: 8339.84
A20: 45916 | B20: Outgoing Payments - VD0304,Being payment done against USD 3327.77 ASCENDAS PANVEL FTWZ PRIVATE LIMITED, Bank ref no.- 003MISC252590125 dated-16-09-2025. | C20: YES BANK - USD | D20: 3327.768 | E20: DZ | F20: 45972 | G20: USD | H20: 10455.66
A21: 45959 | B21: Outgoing Payments - VD0304,Being payment done against USD 1752.77 ASCENDAS PANVEL FTWZ PRIVATE LIMITED, Bank ref no.- 003MISC253020092 dated-29-10-2025. | C21: YES BANK - USD | D21: 1752.7656 | H21: 0
A22: 45961 | B22: Outgoing Payments - VD0304,Being $1989.94 paid to ASCENDAS PANVEL FTWZ PRIVATE LIMITED against bank ref. no.-003MISC253040153 dated-31-10-2025. | C22: YES BANK - USD | D22: 1989.9404 | H22: 0
A23: 45961 | B23: Outgoing Payments - VD0304,Being $10502.1628 paid to ASCENDAS PANVEL FTWZ PRIVATE LIMITED against bank ref. no.-003MISC253040148 dated-31-10-2025. | C23: YES BANK - USD | D23: 10502.163 | E23: DZ | F23: 46029 | G23: USD | H23: 1530.78
A24: 46022 | B24: Outgoing Payments - VD0304,Being $2328.2000 paid to ASCENDAS PANVEL FTWZ PRIVATE LIMITED against bank ref. no.-003MISC253650039 dated-31-12-2025. | C24: Yes Bank (Dollar) | D24: 2368.203 | H24: 0
D25: =SUM(D4:D24) -> 69387.52 | H25: =SUM(H4:H24) -> 69777.74 | I25: =D25-H25 -> -390.22

Sheet Difference in Invoice Amount
A1: Document Number | B1: Document Type | C1: Document Date | D1: Reference | E1: Document Currency Key | F1: Document Currency Value | G1: USD Value | H1: Company Code Currency Key | I1: Company Code Currency Value | J1: Vlookup | K1: Gross Amount | L1: Net Amount | M1: Diffrence | N1: Rate | O1: Text
A2: 1800001581 | B2: DR | C2: 45730 | D2: 246779412238 | E2: USD | F2: 945.75 | G2: 945.75 | H2: INR | I2: 81988.26 | J2: 0 | K2: 0 | L2: 0 | M2: 945.75 | N2: 1 | O2: VAS Activity Charges for the month of August, 24
A3: 1800000282 | B3: DR | C3: 45708 | D3: 246779410209 | E3: USD | F3: 408.31 | G3: 408.31 | H3: INR | I3: 35238.65 | J3: 0 | K3: 1450.0748 | L3: 1450.0748 | M3: -1041.7648 | N3: -2.5514065 | O3: Management Fees for Jan 2025
M4: =SUM(M2:M3) -> -96.0148

Sheet Invoice not in Customer books
G1: =SUBTOTAL(9,G3:G38) -> 23952.404 | H1: ='CN not in Customer Books'!G21 -> -16429.04 | I1: =G1+H1 -> 7523.3641
A2: Document Number | B2: Document Type | C2: Document Date | D2: Reference | E2: Document Currency Key | F2: Document Currency Value | G2: USD Value | H2: Company Code Currency Key | I2: Company Code Currency Value | J2: Text
A3: 1800009967 | B3: DR | C3: 45827 | D3: 256779414731 | E3: USD | F3: 100 | G3: 100 | H3: INR | I3: 8549.08 | J3: Unit to Unit 1-15 June 25 | K3: =_xlfn.XLOOKUP(D3,'CN not in Customer Books'!$K:$K,'CN not in Customer Books'!$G:$G,,0) -> #N/A
A4: 1800009968 | B4: DR | C4: 45827 | D4: 256779414732 | E4: USD | F4: 100 | G4: 100 | H4: INR | I4: 8549.08 | J4: Unit to Unit 1-15 June 25 | K4: =_xlfn.XLOOKUP(D4,'CN not in Customer Books'!$K:$K,'CN not in Customer Books'!$G:$G,,0) -> #N/A
A5: 1800009969 | B5: DR | C5: 45827 | D5: 256779414733 | E5: USD | F5: 100 | G5: 100 | H5: INR | I5: 8549.08 | J5: Unit to Unit 1-15 June 25 | K5: =_xlfn.XLOOKUP(D5,'CN not in Customer Books'!$K:$K,'CN not in Customer Books'!$G:$G,,0) -> #N/A
A6: 1800009970 | B6: DR | C6: 45827 | D6: 256779414734 | E6: USD | F6: 100 | G6: 100 | H6: INR | I6: 8549.08 | J6: Unit to Unit 1-15 June 25 | K6: =_xlfn.XLOOKUP(D6,'CN not in Customer Books'!$K:$K,'CN not in Customer Books'!$G:$G,,0) -> #N/A
A7: 1800013748 | B7: DR | C7: 45937 | D7: 256779418169 | E7: USD | F7: 100 | G7: 100 | H7: INR | I7: 8819.08 | J7: Intra - SEZ-16-30 Sept 25 | K7: =_xlfn.XLOOKUP(D7,'CN not in Customer Books'!$K:$K,'CN not in Customer Books'!$G:$G,,0) -> #N/A
A8: 1800000374 | B8: DR | C8: 45716 | D8: 246779410343 | E8: USD | F8: 1700 | G8: 1700 | H8: INR | I8: 146716.22 | J8: CY Longstanding container Ground Rent charges for | K8: =_xlfn.XLOOKUP(D8,'CN not in Customer Books'!$K:$K,'CN not in Customer Books'!$G:$G,,0) -> #N/A
A9: 1800000381 | B9: DR | C9: 45716 | D9: 246779410350 | E9: USD | F9: 1750 | G9: 1750 | H9: INR | I9: 151031.41 | J9: CY Longstanding container Ground Rent charges for | K9: =_xlfn.XLOOKUP(D9,'CN not in Customer Books'!$K:$K,'CN not in Customer Books'!$G:$G,,0) -> #N/A
A10: 1800000387 | B10: DR | C10: 45716 | D10: 246779410356 | E10: USD | F10: 1750 | G10: 1750 | H10: INR | I10: 151031.41 | J10: CY Longstanding container Ground Rent charges for | K10: =_xlfn.XLOOKUP(D10,'CN not in Customer Books'!$K:$K,'CN not in Customer Books'!$G:$G,,0) -> #N/A
A11: 1800000393 | B11: DR | C11: 45716 | D11: 246779410362 | E11: USD | F11: 1700 | G11: 1700 | H11: INR | I11: 146716.22 | J11: CY Longstanding container Ground Rent charges for | K11: =_xlfn.XLOOKUP(D11,'CN not in Customer Books'!$K:$K,'CN not in Customer Books'!$G:$G,,0) -> #N/A
A12: 1800011800 | B12: DR | C12: 45877 | D12: 256779416103 | E12: USD | F12: 50 | G12: 50 | H12: INR | I12: 4301.51 | J12: Scanning Chgs - 16 - 31 Jul 25 | K12: =_xlfn.XLOOKUP(D12,'CN not in Customer Books'!$K:$K,'CN not in Customer Books'!$G:$G,,0) -> #N/A
A13: 1800011042 | B13: DR | C13: 45856 | D13: 256779415802 | E13: USD | F13: 860.97 | G13: 860.97 | H13: INR | I13: 74044 | J13: Transportation In Chgs - 01 - 15 JUL 25 | K13: =_xlfn.XLOOKUP(D13,'CN not in Customer Books'!$K:$K,'CN not in Customer Books'!$G:$G,,0) -> #N/A
A14: 1800005020 | B14: DR | C14: 45736 | D14: 246779414888 | E14: USD | F14: 10.91 | G14: 10.91 | H14: INR | I14: 945.8 | J14: Outbound Handling charges for Jan 2025 | K14: =_xlfn.XLOOKUP(D14,'CN not in Customer Books'!$K:$K,'CN not in Customer Books'!$G:$G,,0) -> #N/A
... A38: 1800017178 | B38: DR | C38: 46055 | D38: 256779440457 | E38: USD | F38: 938.8 | G38: 938.8 | H38: INR | I38: 84806.69 | J38: Unit Storage - 1-30 Sept 2025 | K38: =_xlfn.XLOOKUP(D38,'CN not in Customer Books'!$K:$K,'CN not in Customer Books'!$G:$G,,0) -> #N/A

Sheet CN not in Customer Books
A2: Document Number | B2: Document Type | C2: Document Date | D2: Reference | E2: Document Currency Key | F2: Document Currency Value | G2: USD Value | H2: Company Code Currency Key | I2: Company Code Currency Value | J2: Text
A3: 1600002439 | B3: DG | C3: 45943 | D3: 256779421983 | E3: USD | F3: -930.14 | G3: -930.14 | H3: INR | I3: -82029.76 | J3: CN issued against 256779418011 | K3: 256779418011 | L3: =_xlfn.XLOOKUP(K3,'Invoice not in Customer books'!$D:$D,'Invoice not in Customer books'!$G:$G,,0) -> #N/A
A4: 1600002212 | B4: DG | C4: 45904 | D4: 256779421767 | E4: USD | F4: -60 | G4: -60 | H4: INR | I4: -5250.86 | J4: CN Issued towards bill no. 256779417178 | K4: 256779417178 | L4: =_xlfn.XLOOKUP(K4,'Invoice not in Customer books'!$D:$D,'Invoice not in Customer books'!$G:$G,,0) -> #N/A
A5: 1600002213 | B5: DG | C5: 45904 | D5: 256779421768 | E5: USD | F5: -60 | G5: -60 | H5: INR | I5: -5250.86 | J5: CN Issued towards bill no. 256779417179 | K5: 256779417179 | L5: =_xlfn.XLOOKUP(K5,'Invoice not in Customer books'!$D:$D,'Invoice not in Customer books'!$G:$G,,0) -> #N/A
A6: 1600002214 | B6: DG | C6: 45904 | D6: 256779421769 | E6: USD | F6: -62 | G6: -62 | H6: INR | I6: -5425.89 | J6: CN Issued towards bill no. 256779417180 | K6: 256779417180 | L6: =_xlfn.XLOOKUP(K6,'Invoice not in Customer books'!$D:$D,'Invoice not in Customer books'!$G:$G,,0) -> #N/A
A7: 1600002215 | B7: DG | C7: 45904 | D7: 256779421770 | E7: USD | F7: -62 | G7: -62 | H7: INR | I7: -5425.89 | J7: CN Issued towards bill no. 256779417181 | K7: 256779417181 | L7: =_xlfn.XLOOKUP(K7,'Invoice not in Customer books'!$D:$D,'Invoice not in Customer books'!$G:$G,,0) -> #N/A
A8: 1600001539 | B8: DG | C8: 45842 | D8: 256779421172 | E8: USD | F8: -1700 | G8: -1700 | H8: INR | I8: -146201.14 | J8: CN against 256779410006 | K8: 256779410006 | L8: =_xlfn.XLOOKUP(K8,'Invoice not in Customer books'!$D:$D,'Invoice not in Customer books'!$G:$G,,0) -> #N/A
A9: 1600001540 | B9: DG | C9: 45842 | D9: 256779421173 | E9: USD | F9: -1750 | G9: -1750 | H9: INR | I9: -150501.17 | J9: CN against 256779410012 | K9: 256779410012 | L9: =_xlfn.XLOOKUP(K9,'Invoice not in Customer books'!$D:$D,'Invoice not in Customer books'!$G:$G,,0) -> #N/A
A10: 1600001541 | B10: DG | C10: 45842 | D10: 256779421174 | E10: USD | F10: -1700 | G10: -1700 | H10: INR | I10: -146201.14 | J10: CN against 256779410015 | K10: 256779410015 | L10: =_xlfn.XLOOKUP(K10,'Invoice not in Customer books'!$D:$D,'Invoice not in Customer books'!$G:$G,,0) -> #N/A
A11: 1600001542 | B11: DG | C11: 45842 | D11: 256779421175 | E11: USD | F11: -1750 | G11: -1750 | H11: INR | I11: -150501.17 | J11: CN against 256779410224 | K11: 256779410224 | L11: =_xlfn.XLOOKUP(K11,'Invoice not in Customer books'!$D:$D,'Invoice not in Customer books'!$G:$G,,0) -> #N/A
A12: 1600000596 | B12: DG | C12: 45791 | D12: 256779420305 | E12: USD | F12: -945.75 | G12: -945.75 | H12: INR | I12: -81988.26 | J12: Credit note against 246779412238 | K12: 246779412238 | L12: =_xlfn.XLOOKUP(K12,'Invoice not in Customer books'!$D:$D,'Invoice not in Customer books'!$G:$G,,0) -> #N/A
A13: 1600001839 | B13: DG | C13: 45862 | D13: 256779421459 | E13: USD | F13: -1700 | G13: -1700 | H13: INR | I13: -146201.14 | J13: Credit note raised against 256779410006 | K13: 256779410006 | L13: =_xlfn.XLOOKUP(K13,'Invoice not in Customer books'!$D:$D,'Invoice not in Customer books'!$G:$G,,0) -> #N/A
A14: 1600001840 | B14: DG | C14: 45862 | D14: 256779421460 | E14: USD | F14: -1750 | G14: -1750 | H14: INR | I14: -150501.17 | J14: Credit note raised against 256779410012 | K14: 256779410012 | L14: =_xlfn.XLOOKUP(K14,'Invoice not in Customer books'!$D:$D,'Invoice not in Customer books'!$G:$G,,0) -> #N/A
... A20: 1600002771 | B20: DG | C20: 46055 | D20: 256779422241 | E20: USD | F20: -87.28 | G20: -87.28 | H20: INR | I20: -7884.46 | J20: CN issued against - 256779417082 | K20: 256779417082 | L20: =_xlfn.XLOOKUP(K20,'Invoice not in Customer books'!$D:$D,'Invoice not in Customer books'!$G:$G,,0) -> #N/A
G21: =SUM(G3:G20) -> -16429.04

Sheet TDS Deducted
M1: =SUM(M3:M211) -> 4692.5328 | N1: =SUBTOTAL(9,N3:N211) -> 40 | O1: =M1+N1 -> 4732.5328
A2: Document Number | B2: Document Type | C2: Document Date | D2: Reference | E2: Document Currency Key | F2: Document Currency Value | G2: USD Value | H2: Company Code Currency Key | I2: Company Code Currency Value | J2: Vlookup | K2: Gross Amount | L2: Net Amount | M2: Diffrence | N2: Additional TDS | O2: Rate | P2: Text | R2: Ref. 2 (Header) | S2: Document Date | T2: Remarks | U2: Offset Acct Name | V2: Debit (FC) | W2: Credit (FC)
A3: 1800008260 | B3: DR | C3: 45787 | D3: 256779413144 | E3: INR | F3: 100000 | G3: 1163.0111 | H3: INR | I3: 100000 | J3: 0 | K3: 1046.71 | L3: 1046.71 | M3: 116.30111 | N3: =_xlfn.XLOOKUP(D3,$R:$R,$V:$V,0,0) -> 0 | O3: 0.1 | P3: Fixed Storage Charges fo MAY 2025 | R3: 246779413797 | S3: 45736 | T3: Being TDS deduction on 246779413797 ascendas | U3: Tds Payable- 94Ib - Rent | V3: 20
A4: 1800009592 | B4: DR | C4: 45818 | D4: 256779414356 | E4: INR | F4: 100000 | G4: 1169.72 | H4: INR | I4: 100000 | J4: 0 | K4: 1052.748 | L4: 1052.748 | M4: 116.972 | N4: =_xlfn.XLOOKUP(D4,$R:$R,$V:$V,0,0) -> 0 | O4: 0.1 | P4: Fixed Storage Charges fo JUNE 2025 | S4: 45736 | T4: Being TDS deduction on 246779413797 ascendas | U4: Tds Payable- 94Ib - Rent | W4: 20
A5: 1800010154 | B5: DR | C5: 45842 | D5: 256779414914 | E5: INR | F5: 100000 | G5: 1162.78 | H5: INR | I5: 100000 | J5: 0 | K5: 1046.502 | L5: 1046.502 | M5: 116.278 | N5: =_xlfn.XLOOKUP(D5,$R:$R,$V:$V,0,0) -> 0 | O5: 0.1 | P5: Fixed Storage Charges fo JULY 2025 | S5: 45736 | T5: Being TDS deduction on 246779413797 ascendas(Reversal) - 7619 | U5: Tds Payable- 94Ib - Rent | V5: -20
A6: 1800011360 | B6: DR | C6: 45870 | D6: 256779416026 | E6: INR | F6: 100000 | G6: 1162.3778 | H6: INR | I6: 100000 | J6: 0 | K6: 1046.14 | L6: 1046.14 | M6: 116.23778 | N6: =_xlfn.XLOOKUP(D6,$R:$R,$V:$V,0,0) -> 0 | O6: 0.1 | P6: Fixed Storage Charges for August 2025 | R6: 246779413808 | S6: 45736 | T6: Being TDS deduction on 246779413808 ascendas | U6: Tds Payable- 94Ib - Rent | V6: 20
A7: 1800012712 | B7: DR | C7: 45904 | D7: 256779417346 | E7: INR | F7: 100000 | G7: 1142.67 | H7: INR | I7: 100000 | J7: 0 | K7: 1028.403 | L7: 1028.403 | M7: 114.267 | N7: =_xlfn.XLOOKUP(D7,$R:$R,$V:$V,0,0) -> 0 | O7: 0.1 | P7: Fixed Storage Charges for September 2025 | S7: 45736 | T7: Being TDS deduction on 246779413797 ascendas | U7: Tds Payable- 94Ib - Rent | V7: 20
A8: 1800014235 | B8: DR | C8: 45966 | D8: 256779418775 | E8: INR | F8: 100000 | G8: 1136.32 | H8: INR | I8: 100000 | J8: 0 | K8: 1022.688 | L8: 1022.688 | M8: 113.632 | N8: =_xlfn.XLOOKUP(D8,$R:$R,$V:$V,0,0) -> 0 | O8: 0.1 | P8: Fixed Storage Charges for November 2025 | S8: 45736 | T8: Being TDS deduction on 246779413797 ascendas(Reversal) - 7646 | U8: Tds Payable- 94Ib - Rent | W8: -20
A9: 1800015484 | B9: DR | C9: 45995 | D9: 256779419968 | E9: INR | F9: 100000 | G9: 1127.39 | H9: INR | I9: 100000 | J9: 0 | K9: 1014.651 | L9: 1014.651 | M9: 112.739 | N9: =_xlfn.XLOOKUP(D9,$R:$R,$V:$V,0,0) -> 0 | O9: 0.1 | P9: Fixed Storage Charges for December 2025
A10: 1800008261 | B10: DR | C10: 45787 | D10: 256779413145 | E10: INR | F10: 35000 | G10: 407.05 | H10: INR | I10: 35000 | J10: 0 | K10: 366.345 | L10: 366.345 | M10: 40.705 | N10: =_xlfn.XLOOKUP(D10,$R:$R,$V:$V,0,0) -> 0 | O10: 0.1 | P10: Fixed Storage Charges fo MAY 2025
A11: 1800009593 | B11: DR | C11: 45818 | D11: 256779414357 | E11: INR | F11: 35000 | G11: 409.4 | H11: INR | I11: 35000 | J11: 0 | K11: 368.46 | L11: 368.46 | M11: 40.94 | N11: =_xlfn.XLOOKUP(D11,$R:$R,$V:$V,0,0) -> 0 | O11: 0.1 | P11: Fixed Storage Charges fo JUNE 2025
A12: 1800010155 | B12: DR | C12: 45842 | D12: 256779414915 | E12: INR | F12: 35000 | G12: 443.14511 | H12: INR | I12: 35000 | J12: 0 | K12: 398.8306 | L12: 398.8306 | M12: 44.314511 | N12: =_xlfn.XLOOKUP(D12,$R:$R,$V:$V,0,0) -> 0 | O12: 0.1 | P12: Fixed Storage Charges fo JULY 2025
A13: 1800011361 | B13: DR | C13: 45870 | D13: 256779416027 | E13: INR | F13: 35000 | G13: 442.98889 | H13: INR | I13: 35000 | J13: 0 | K13: 398.69 | L13: 398.69 | M13: 44.298889 | N13: =_xlfn.XLOOKUP(D13,$R:$R,$V:$V,0,0) -> 0 | O13: 0.1 | P13: Fixed Storage Charges for August 2025
A14: 1800012713 | B14: DR | C14: 45904 | D14: 256779417347 | E14: INR | F14: 35000 | G14: 399.93 | H14: INR | I14: 35000 | J14: 0 | K14: 359.937 | L14: 359.937 | M14: 39.993 | N14: =_xlfn.XLOOKUP(D14,$R:$R,$V:$V,0,0) -> 0 | O14: 0.1 | P14: Fixed Storage Charges for September 2025
A15: 1800014236 | B15: DR | C15: 45966 | D15: 256779418776 | E15: INR | F15: 35000 | G15: 433.062 | H15: INR | I15: 35000 | J15: 0 | K15: 389.7558 | L15: 389.7558 | M15: 43.3062 | N15: =_xlfn.XLOOKUP(D15,$R:$R,$V:$V,0,0) -> 0 | O15: 0.1 | P15: Fixed Storage Charges for November 2025
A16: 1800015485 | B16: DR | C16: 45995 | D16: 256779419969 | E16: INR | F16: 35000 | G16: 429.66467 | H16: INR | I16: 35000 | J16: 0 | K16: 386.6982 | L16: 386.6982 | M16: 42.966467 | N16: =_xlfn.XLOOKUP(D16,$R:$R,$V:$V,0,0) -> 0 | O16: 0.1 | P16: Fixed Mangement FEE for December 2025
A17: 1800002451 | B17: DR | C17: 45733 | D17: 246779412116 | E17: USD | F17: 100 | G17: 100 | H17: INR | I17: 8669.13 | J17: 0 | K17: 98 | L17: 98 | M17: 2 | N17: =_xlfn.XLOOKUP(D17,$R:$R,$V:$V,0,0) -> 0 | O17: 0.02 | P17: Intra Unit Transfer Charges Month Of December,2024
A18: 1800002454 | B18: DR | C18: 45733 | D18: 246779412119 | E18: USD | F18: 100 | G18: 100 | H18: INR | I18: 8669.13 | J18: 0 | K18: 98 | L18: 98 | M18: 2 | N18: =_xlfn.XLOOKUP(D18,$R:$R,$V:$V,0,0) -> 0 | O18: 0.02 | P18: Intra Unit Transfer Charges Month Of December,2024
A19: 1800002456 | B19: DR | C19: 45733 | D19: 246779412121 | E19: USD | F19: 100 | G19: 100 | H19: INR | I19: 8669.13 | J19: 0 | K19: 98 | L19: 98 | M19: 2 | N19: =_xlfn.XLOOKUP(D19,$R:$R,$V:$V,0,0) -> 0 | O19: 0.02 | P19: Intra Unit Transfer Charges Month Of December,2024
A20: 1800008348 | B20: DR | C20: 45787 | D20: 256779413231 | E20: USD | F20: 100 | G20: 100 | H20: INR | I20: 8598.37 | J20: 0 | K20: 98 | L20: 98 | M20: 2 | N20: =_xlfn.XLOOKUP(D20,$R:$R,$V:$V,0,0) -> 0 | O20: 0.02 | P20: Intra Unit Transfer 16-30 April 25
... A75: 1800001784 | B75: DR | C75: 45730 | D75: 246779411449 | E75: USD | F75: 945.75 | G75: 945.75 | H75: INR | I75: 81988.26 | J75: 0 | K75: 926.835 | L75: 926.835 | M75: 18.915 | N75: =_xlfn.XLOOKUP(D75,$R:$R,$V:$V,0,0) -> 0 | O75: 0.02 | P75: VAS Activity Charges for the month of August, 24
A76: 1600002155 | B76: DG | C76: 45883 | D76: 256779421715 | E76: USD | F76: -2324.77 | G76: -2324.77 | H76: INR | I76: -200000.24 | J76: 2092.293 | K76: 0 | L76: 2092.293 | M76: =G76+L76 -> -232.477 | O76: 0.1 | P76: CN issued towards D & D
A77: 1800012461 | B77: DR | C77: 45904 | D77: 256779417161 | E77: USD | F77: 787.95 | G77: 787.95 | H77: INR | I77: 68956.92 | J77: 0 | K77: 772.191 | L77: 772.191 | M77: 15.759 | N77: =_xlfn.XLOOKUP(D77,$R:$R,$V:$V,0,0) -> 0 | O77: 0.02 | P77: VAS -16-31 Aug 25
A78: 1800012559 | B78: DR | C78: 45904 | D78: 256779417178 | E78: USD | F78: 1560 | G78: 1560 | H78: INR | I78: 136522.35 | J78: 0 | K78: 1528.8 | L78: 1528.8 | M78: 31.2 | N78: =_xlfn.XLOOKUP(D78,$R:$R,$V:$V,0,0) -> 0 | O78: 0.02 | P78: CY Refer Pluging Chgs - 01 - 31 May 25
A79: 1800012560 | B79: DR | C79: 45904 | D79: 256779417179 | E79: USD | F79: 1560 | G79: 1560 | H79: INR | I79: 136522.35 | J79: 0 | K79: 1528.8 | L79: 1528.8 | M79: 31.2 | N79: =_xlfn.XLOOKUP(D79,$R:$R,$V:$V,0,0) -> 0 | O79: 0.02 | P79: CY Refer Pluging Chgs - 01 - 30 Jun 25
A80: 1800012561 | B80: DR | C80: 45904 | D80: 256779417180 | E80: USD | F80: 1799.1 | G80: 1799.1 | H80: INR | I80: 157447.03 | J80: 0 | K80: 1748.15 | L80: 1748.15 | M80: 50.95 | N80: =_xlfn.XLOOKUP(D80,$R:$R,$V:$V,0,0) -> 0 | O80: 0.028319715 | P80: CY Ground rent Chgs - 01 - 31 July 25
A81: 1800012562 | B81: DR | C81: 45904 | D81: 256779417181 | E81: USD | F81: 1812 | G81: 1812 | H81: INR | I81: 158575.97 | J81: 0 | K81: 1759.76 | L81: 1759.76 | M81: 52.24 | N81: =_xlfn.XLOOKUP(D81,$R:$R,$V:$V,0,0) -> 0 | O81: 0.028830022 | P81: CY Ground rent Chgs - 01 - 31 Aug 25
A82: 1800012619 | B82: DR | C82: 45904 | D82: 256779417206 | E82: USD | F82: 152.28 | G82: 152.28 | H82: INR | I82: 13326.68 | J82: 0 | K82: 149.2344 | L82: 149.2344 | M82: 3.0456 | N82: =_xlfn.XLOOKUP(D82,$R:$R,$V:$V,0,0) -> 0 | O82: 0.02 | P82: Empty Lolo Chgs - 01 - 31 AUG 25
A83: 1800012587 | B83: DR | C83: 45904 | D83: 256779417245 | E83: USD | F83: 83.89 | G83: 83.89 | H83: INR | I83: 7341.58 | J83: 0 | K83: 82.2122 | L83: 82.2122 | M83: 1.6778 | N83: =_xlfn.XLOOKUP(D83,$R:$R,$V:$V,0,0) -> 0 | O83: 0.02 | P83: PORT SSR Chgs Aug 25
A84: 1800012647 | B84: DR | C84: 45904 | D84: 256779417287 | E84: USD | F84: 410.58 | G84: 410.58 | H84: INR | I84: 35931.63 | J84: 0 | K84: 402.3684 | L84: 402.3684 | M84: 8.2116 | N84: =_xlfn.XLOOKUP(D84,$R:$R,$V:$V,0,0) -> 0 | O84: 0.02 | P84: Transportation In Chgs - 16 - 31 AUG 25
A85: 1800012685 | B85: DR | C85: 45904 | D85: 256779417325 | E85: USD | F85: 97.84 | G85: 97.84 | H85: INR | I85: 8562.4 | J85: 0 | K85: 95.8832 | L85: 95.8832 | M85: 1.9568 | N85: =_xlfn.XLOOKUP(D85,$R:$R,$V:$V,0,0) -> 0 | O85: 0.02 | P85: Outbound chgs - 16 - 31 Aug 25
A86: 1800010008 | B86: DR | C86: 45842 | D86: 256779414772 | E86: USD | F86: 220 | G86: 220 | H86: INR | I86: 18920.15 | J86: 0 | K86: 215.6 | L86: 215.6 | M86: 4.4 | N86: =_xlfn.XLOOKUP(D86,$R:$R,$V:$V,0,0) -> 0 | O86: 0.02 | P86: Transportation In Chgs - 01 - 15 Jun 25
A87: 1800010066 | B87: DR | C87: 45842 | D87: 256779414830 | E87: USD | F87: 142.32 | G87: 142.32 | H87: INR | I87: 12239.62 | J87: 0 | K87: 139.4736 | L87: 139.4736 | M87: 2.8464 | N87: =_xlfn.XLOOKUP(D87,$R:$R,$V:$V,0,0) -> 0 | O87: 0.02 | P87: Outbound chgs - 01 - 15 Jun 25
A88: 1800010119 | B88: DR | C88: 45842 | D88: 256779414879 | E88: USD | F88: 1663.92 | G88: 1663.92 | H88: INR | I88: 143098.23 | J88: 0 | K88: 1627.5448 | L88: 1627.5448 | M88: 36.3752 | N88: =_xlfn.XLOOKUP(D88,$R:$R,$V:$V,0,0) -> 0 | O88: 0.021861147 | P88: Transportation In Chgs - 16 - 30 JUN 25
... A211: 1800013479 | B211: DR | C211: 45935 | D211: 256779418095 | E211: USD | F211: 850 | G211: 850 | H211: INR | I211: 74962.15 | J211: 0 | K211: 825 | L211: 825 | M211: 25 | N211: =_xlfn.XLOOKUP(D211,$R:$R,$V:$V,0,0) -> 0 | O211: 0.029411765 | P211: CY Ground rent Chgs - 16 - 30 Sep 25

Sheet Sheet2
A3: Sum of USD Value | D3: Document Type | I3: Sum of USD Value | K3: Document Type
A4: Years | B4: Quarters | C4: Document Date | D4: DG | E4: DR | F4: DY | G4: DZ | I4: Years | J4: Document Date | K4: DG | L4: DR | M4: DZ | O4: Years | P4: Document Date | Q4: Sum of Debit (FC) | R4: Sum of Credit (FC)
A5: 2025 | B5: Qtr1 | C5: Feb | E5: 19803.86 | I5: 2025 | J5: Feb | L5: 19803.86 | O5: 2025 | P5: Feb | R5: 12293.713
C6: Mar | E6: 14823.47 | I6: 2025 | J6: Mar | L6: 14823.47 | O6: 2025 | P6: Mar | Q6: 40 | R6: 12720.29
B7: Qtr2 | C7: Apr | E7: 13418.32 | I7: 2025 | J7: Apr | L7: 13418.32 | O7: 2025 | P7: Apr | Q7: 80 | R7: 9784.916
C8: May | D8: -3255.46 | E8: 3894.3411 | I8: 2025 | J8: May | K8: -3255.46 | L8: 3894.3411 | O8: 2025 | P8: May | R8: 3363.296
C9: Jun | E9: 8129.42 | G9: -23431.62 | I9: 2025 | J9: Jun | L9: 8129.42 | M9: -23431.62 | O9: 2025 | P9: Jun | Q9: 27159.812 | R9: 4339.4726
B10: Qtr3 | C10: Jul | D10: -17406.03 | E10: 9114.5951 | F10: 0 | I10: 2025 | J10: Jul | K10: -17406.03 | L10: 9114.5951 | O10: 2025 | P10: Jul | Q10: 3742.0478 | R10: 7944.713
C11: Aug | D11: -4623.6206 | E11: 20154.677 | G11: -13681.56 | I11: 2025 | J11: Aug | K11: -4623.6206 | L11: 20154.677 | M11: -13681.56 | O11: 2025 | P11: Aug | Q11: 7900.4476 | R11: 9099.6876
C12: Sep | D12: -504.79 | E12: 13032.36 | F12: 0 | G12: -2932.84 | I12: 2025 | J12: Sep | K12: -504.79 | L12: 13032.36 | M12: -2932.84 | O12: 2025 | P12: Sep | Q12: 16064.434 | R12: 10508.427
B13: Qtr4 | C13: Oct | D13: -1066.62 | E13: 5834.0484 | G13: -4719.25 | I13: 2025 | J13: Oct | K13: -1066.62 | L13: 5834.0484 | M13: -4719.25 | O13: 2025 | P13: Oct | Q13: 14244.869 | R13: 6997.0412
C14: Nov | E14: 5099.432 | G14: -22495.21 | I14: 2025 | J14: Nov | L14: 5099.432 | M14: -22495.21 | O14: 2025 | P14: Nov | R14: 4796.2152
C15: Dec | E15: 2704.5547 | I15: 2025 | J15: Dec | L15: 2704.5547 | O15: 2025 | P15: Dec | Q15: 2368.203 | R15: 2517.8992
A16: 2026 | B16: Qtr1 | C16: Jan | E16: 5424.9541 | G16: -2517.26 | I16: 2026 | J16: Jan | L16: 5424.9541 | M16: -2517.26 | O16: 2026 | P16: Jan | R16: 825.474
C17: Feb | D17: -509.15 | E17: 938.8 | I17: 2026 | J17: Feb | K17: -509.15 | L17: 938.8 | Q17: =SUM(Q5:Q16) -> 71599.813 | R17: =SUM(R5:R16) -> 85191.145
K18: =SUM(K5:K17) -> -27365.671 | L18: =SUM(L5:L17) -> 122372.83 | M18: =SUM(M5:M17) -> -69777.74

Sheet Customer Data Vlookup
A1: Ref. 2 (Header) | B1: Document Date | C1: Remarks | D1: Offset Acct Name | E1: Debit (LC) | F1: Credit (LC) | G1: Cumulative Balance (LC) | H1: Debit (FC) | I1: Credit (FC) | J1: Cumulative Balance (FC) | L1: Ref. 2 (Header) | M1: Sum of Debit (FC) | N1: Sum of Credit (FC) | O1: vlookup | R1: Ref. 2 (Header) | S1: Sum of Credit (FC) | T1: vlookup
A2: 1002 | B2: 45940 | C2: A/P Credit Memo - Cancellation - VD0304 | D2: Reefer Plug In | F2: 2520.8598 | G2: -1156227.5 | I2: 28.8 | J2: -2529.6996 | L2: 1002 | N2: 28.8 | O2: =VLOOKUP(L2,'Ascendus Data'!$D$3:$F$317,3,0) -> #N/A | R2: 7360257 | S2: -58.8 | T2: #N/A
A3: 1003 | B3: 45940 | C3: A/P Credit Memo - Cancellation - VD0304 | D3: Reefer Plug In | F3: 2520.8598 | G3: -1158748.3 | I3: 28.8 | J3: -3579.6306 | L3: 1003 | N3: 28.8 | O3: =VLOOKUP(L3,'Ascendus Data'!$D$3:$F$317,3,0) -> #N/A | R3: 7360258 | S3: -58.8 | T3: #N/A
A4: 1004 | B4: 45940 | C4: A/P Credit Memo - Cancellation - VD0304 | D4: Reefer Plug In | F4: 2604.8885 | G4: -1161353.2 | I4: 29.76 | J4: -2978.5984 | L4: 1004 | N4: 29.76 | O4: =VLOOKUP(L4,'Ascendus Data'!$D$3:$F$317,3,0) -> #N/A | R4: 7360259 | S4: -60.76 | T4: #N/A
A5: 1005 | B5: 45940 | C5: A/P Credit Memo - Cancellation - VD0304 | D5: Reefer Plug In | F5: 138252.1 | G5: -1153706.6 | I5: 1579.76 | J5: -2970.4056 | L5: 1005 | N5: 1579.76 | O5: =VLOOKUP(L5,'Ascendus Data'!$D$3:$F$317,3,0) -> #N/A | R5: 7360262 | S5: -60.76 | T5: #N/A
A6: 1008 | B6: 45941 | C6: A/P Credit Memo - Cancellation - VD0304 | D6: Reefer Plug In | F6: 5250.8598 | G6: -1261566.9 | I6: 60 | J6: -3378.7422 | L6: 1008 | N6: 60 | O6: =VLOOKUP(L6,'Ascendus Data'!$D$3:$F$317,3,0) -> #N/A | R6: 246779414731 | S6: 90 | T6: #N/A
A7: 7360257 | B7: 45904 | C7: A/P Credit Memos - VD0304 | D7: Reefer Plug In | F7: -2520.8598 | G7: -1108837.9 | I7: -28.8 | J7: -4450.1742 | L7: 7360257 | N7: -87.6 | O7: =VLOOKUP(L7,'Ascendus Data'!$D$3:$F$317,3,0) -> #N/A | R7: 246779414732 | S7: 90 | T7: #N/A
A8: 7360257 | B8: 45904 | C8: A/P Credit Memos - VD0304 | D8: Reefer Plug In | F8: -5145.8598 | G8: -1251275.1 | I8: -58.8 | J8: -4526.7318 | L8: 7360258 | N8: -147.6 | O8: =VLOOKUP(L8,'Ascendus Data'!$D$3:$F$317,3,0) -> #N/A | R8: 246779414733 | S8: 90 | T8: #N/A
A9: 7360258 | B9: 45904 | C9: A/P Credit Memos - VD0304 | D9: Reefer Plug In | F9: -2520.8598 | G9: -1111358.8 | I9: -28.8 | J9: -4935.0684 | L9: 7360259 | N9: -90.52 | O9: =VLOOKUP(L9,'Ascendus Data'!$D$3:$F$317,3,0) -> #N/A | R9: 246779414734 | S9: 90 | T9: #N/A
A10: 7360258 | B10: 45904 | C10: A/P Credit Memos - VD0304 | D10: Reefer Plug In | F10: -5250.8598 | G10: -1256316 | I10: -60 | J10: -4986.7438 | L10: 7360262 | N10: -1640.52 | O10: =VLOOKUP(L10,'Ascendus Data'!$D$3:$F$317,3,0) -> #N/A | R10: 256779414888 | S10: 10.6918 | T10: #N/A
A11: 7360258 | B11: 45904 | C11: A/P Credit Memos - VD0304 | D11: Reefer Plug In | F11: -5145.8598 | G11: -1256421 | I11: -58.8 | J11: -6705.7438 | L11: 7360566 | M11: 1752.7656 | O11: =VLOOKUP(L11,'Ascendus Data'!$D$3:$F$317,3,0) -> #N/A | S11: =SUM(S2:S10) -> 131.5718 | T11: #N/A
A12: 7360259 | B12: 45904 | C12: A/P Credit Memos - VD0304 | D12: Reefer Plug In | F12: -2604.8885 | G12: -1106233 | I12: -29.76 | J12: -6780.2434 | L12: 246779410055 | N12: 408.3366 | O12: =VLOOKUP(L12,'Ascendus Data'!$D$3:$F$317,3,0) -> 416.67
A13: 7360259 | B13: 45904 | C13: A/P Credit Memos - VD0304 | D13: Reefer Plug In | F13: -5316.8885 | G13: -1245958.3 | I13: -60.76 | J13: -6760.2434 | L13: 246779410009 | N13: 1071.432 | O13: =VLOOKUP(L13,'Ascendus Data'!$D$3:$F$317,3,0) -> 1190.48
A14: 7360262 | B14: 45904 | C14: A/P Credit Memos - VD0304 | D14: Reefer Plug In | F14: -138252.1 | G14: -967980.94 | I14: -1579.76 | J14: -6809.2434 | L14: 246779410029 | N14: 1071.432 | O14: =VLOOKUP(L14,'Ascendus Data'!$D$3:$F$317,3,0) -> 1190.48
A15: 7360262 | B15: 45904 | C15: A/P Credit Memos - VD0304 | D15: Reefer Plug In | F15: -5316.8885 | G15: -1261566.9 | I15: -60.76 | J15: -6861.4382 | L15: 246779410077 | N15: 408.3366 | O15: =VLOOKUP(L15,'Ascendus Data'!$D$3:$F$317,3,0) -> 416.67
B16: 45959 | C16: Outgoing Payments - VD0304,Being payment done against USD 1752.77 ASCENDAS PANVEL FTWZ PRIVATE LIMITED, Bank ref no.- 003MISC253020092 dated-29-10-2025. | D16: YES BANK - USD | E16: 153004.1 | G16: -1092954.2 | H16: 1752.7656 | J16: -6917.5628 | L16: 246779410097 | N16: 1071.432 | O16: =VLOOKUP(L16,'Ascendus Data'!$D$3:$F$317,3,0) -> 1190.48
A17: 246779410009 | B17: 45707 | C17: A/P Invoices - VD0304 | D17: Rent - Ascendas | F17: 91693.278 | G17: -1027809.8 | I17: 1071.432 | J17: -6940.1812 | L17: 246779410123 | N17: 408.3366 | O17: =VLOOKUP(L17,'Ascendus Data'!$D$3:$F$317,3,0) -> 416.67
A18: 246779410029 | B18: 45708 | C18: A/P Invoices - VD0304 | D18: Rent - Ascendas | F18: 91693.278 | G18: -1575456.3 | I18: 1071.432 | J18: -6981.5568 | L18: 246779410140 | N18: 1071.432 | O18: =VLOOKUP(L18,'Ascendus Data'!$D$3:$F$317,3,0) -> 1190.48
A19: 246779410055 | B19: 45708 | C19: A/P Invoices - VD0304 | D19: Management Fees (Ascendas) | F19: 34945.619 | G19: -1610402 | I19: 408.3366 | J19: -7070.5996 | L19: 246779410166 | N19: 408.3366 | O19: =VLOOKUP(L19,'Ascendus Data'!$D$3:$F$317,3,0) -> 416.67
A20: 246779410077 | B20: 45708 | C20: A/P Invoices - VD0304 | D20: Management Fees (Ascendas) | F20: 34945.619 | G20: -1062755.5 | I20: 408.3366 | J20: -7166.0516 | L20: 246779410209 | N20: 1450.0748 | O20: =VLOOKUP(L20,'Ascendus Data'!$D$3:$F$317,3,0) -> 408.31
A21: 246779410097 | B21: 45708 | C21: A/P Invoices - VD0304 | D21: Rent - Ascendas | F21: 91693.278 | G21: -380845.89 | I21: 1071.432 | J21: -7196.2356 | L21: 246779410226 | N21: 1028.808 | O21: =VLOOKUP(L21,'Ascendus Data'!$D$3:$F$317,3,0) -> 1143.12
A22: 246779410123 | B22: 45708 | C22: A/P Invoices - VD0304 | D22: Management Fees (Ascendas) | F22: 34945.619 | G22: -422343.02 | I22: 408.3366 | J22: -7203.125 | L22: 246779410252 | N22: 392.0882 | O22: =VLOOKUP(L22,'Ascendus Data'!$D$3:$F$317,3,0) -> 400.09
A23: 246779410140 | B23: 45708 | C23: A/P Invoices - VD0304 | D23: Rent - Ascendas | F23: 91693.278 | G23: -797615.56 | I23: 1071.432 | J23: -7210.2496 | L23: 246779410276 | N23: 1071.432 | O23: =VLOOKUP(L23,'Ascendus Data'!$D$3:$F$317,3,0) -> 1190.48
A24: 246779410166 | B24: 45708 | C24: A/P Invoices - VD0304 | D24: Management Fees (Ascendas) | F24: 34945.619 | G24: -705922.29 | I24: 408.3366 | J24: -7220.9414 | L24: 246779410308 | N24: 408.3366 | O24: =VLOOKUP(L24,'Ascendus Data'!$D$3:$F$317,3,0) -> 416.67
A25: 246779410209 | B25: 45708 | C25: A/P Invoices - VD0304 | D25: Rent - Ascendas | F25: 89852.772 | G25: -306344.44 | I25: 1049.931 | J25: -7223.411 | L25: 246779410324 | N25: 1575 | O25: =VLOOKUP(L25,'Ascendus Data'!$D$3:$F$317,3,0) -> 1750
A26: 246779410209 | B26: 45708 | C26: A/P Invoices - VD0304 | D26: Management Fees (Ascendas) | F26: 34244.17 | G26: -254207 | I26: 400.1438 | J26: -7255.1434 | L26: 246779410376 | N26: 640.215 | O26: =VLOOKUP(L26,'Ascendus Data'!$D$3:$F$317,3,0) -> 711.35
A27: 246779410226 | B27: 45708 | C27: A/P Invoices - VD0304 | D27: Rent - Ascendas | F27: 88045.21 | G27: -885660.77 | I27: 1028.808 | J27: -7298.2634 | L27: 246779410401 | N27: 1169.064 | O27: =VLOOKUP(L27,'Ascendus Data'!$D$3:$F$317,3,0) -> 1298.96
A28: 246779410252 | B28: 45708 | C28: A/P Invoices - VD0304 | D28: Management Fees (Ascendas) | F28: 33554.702 | G28: -670976.67 | I28: 392.0882 | J28: -7363.4334 | L28: 246779410425 | N28: 1518.489 | O28: =VLOOKUP(L28,'Ascendus Data'!$D$3:$F$317,3,0) -> 1687.21
... A35: 246779410871 | B35: 45722 | C35: A/P Invoices - VD0304 | D35: Rent - Ascendas | F35: 3274.0058 | G35: -1778306.5 | I35: 38.259 | J35: -10348.923 | L35: 246779411515 | N35: 98 | O35: =VLOOKUP(L35,'Ascendus Data'!$D$3:$F$317,3,0) -> 100
A36: 246779410871 | B36: 45821 | C36: Being $3.4008 less paid in this bill because in summary sheet 2% tds deduscted instead of 10% | D36: HDFC Bank - INR | E36: 290.9044 | G36: -675841.21 | H36: 3.4008 | J36: -10858.69 | L36: 246779411621 | N36: 435.1592 | O36: =VLOOKUP(L36,'Ascendus Data'!$D$3:$F$317,3,0) -> 444.04
A37: 246779410893 | B37: 45722 | C37: A/P Invoices - VD0304 | D37: Rent - Ascendas | F37: 13647.064 | G37: -1775032.5 | I37: 159.462 | J37: -10863.002 | L37: 246779411760 | N37: 509.7666 | O37: =VLOOKUP(L37,'Ascendus Data'!$D$3:$F$317,3,0) -> 520.17
A38: 246779411279 | B38: 45729 | C38: A/P Invoices - VD0304 | D38: Vos Miscellaneous Charges | F38: 2935.3 | G38: -1613337.3 | I38: 34.3 | J38: -10938.501 | L38: 246779411937 | N38: 7.1246 | O38: =VLOOKUP(L38,'Ascendus Data'!$D$3:$F$317,3,0) -> 7.27
A39: 246779411301 | B39: 45729 | C39: A/P Invoices - VD0304 | D39: Vos Miscellaneous Charges | F39: 7129.3 | G39: -1329744.4 | I39: 83.3 | J39: -12009.933 | L39: 246779411938 | N39: 52.1948 | O39: =VLOOKUP(L39,'Ascendus Data'!$D$3:$F$317,3,0) -> 53.26
A40: 246779411315 | B40: 45729 | C40: A/P Invoices - VD0304 | D40: Vos Miscellaneous Charges | F40: 2935.3 | G40: -1332679.7 | I40: 34.3 | J40: -12418.27 | L40: 246779411939 | N40: 22.6184 | O40: =VLOOKUP(L40,'Ascendus Data'!$D$3:$F$317,3,0) -> 23.08
A41: 246779411449 | B41: 45730 | C41: A/P Invoices - VD0304 | D41: Vos Miscellaneous Charges | F41: 79318.285 | G41: -1142073.7 | I41: 926.835 | J41: -13345.105 | L41: 246779411940 | N41: 51.6754 | O41: =VLOOKUP(L41,'Ascendus Data'!$D$3:$F$317,3,0) -> 52.73
A42: 246779411515 | B42: 45730 | C42: A/P Invoices - VD0304 | D42: Vos Miscellaneous Charges | F42: 8387 | G42: -1815791.5 | I42: 98 | J42: -14271.94 | L42: 246779411941 | N42: 74.4996 | O42: =VLOOKUP(L42,'Ascendus Data'!$D$3:$F$317,3,0) -> 76.02
A43: 246779411621 | B43: 45733 | C43: A/P Invoices - VD0304 | D43: Vos Miscellaneous Charges | F43: 37240.943 | G43: -1322615.1 | I43: 435.1592 | J43: -14464.784 | L43: 246779412066 | N43: 65.17 | O43: =VLOOKUP(L43,'Ascendus Data'!$D$3:$F$317,3,0) -> 66.5
A44: 246779411760 | B44: 45733 | C44: A/P Invoices - VD0304 | D44: Vos Miscellaneous Charges | F44: 43626.149 | G44: -929286.92 | I44: 509.7666 | J44: -15019.572 | L44: 246779412116 | N44: 98 | O44: =VLOOKUP(L44,'Ascendus Data'!$D$3:$F$317,3,0) -> 100
A45: 246779411937 | B45: 45733 | C45: A/P Invoices - VD0304 | D45: Vos Miscellaneous Charges | F45: 610.1666 | G45: -592005 | I45: 7.1246 | J45: -15454.731 | L45: 246779412119 | N45: 98 | O45: =VLOOKUP(L45,'Ascendus Data'!$D$3:$F$317,3,0) -> 100
A46: 246779411938 | B46: 45733 | C46: A/P Invoices - VD0304 | D46: Vos Miscellaneous Charges | F46: 4466.9908 | G46: -587201.84 | I46: 52.1948 | J46: -15538.031 | L46: 246779412121 | N46: 98 | O46: =VLOOKUP(L46,'Ascendus Data'!$D$3:$F$317,3,0) -> 100
...

Sheet Sheet3
A3: Years | B3: Quarters | C3: Document Date | D3: Sum of Debit (FC) | E3: Sum of Credit (FC)
A4: 2025 | B4: Qtr1 | C4: Feb | E4: 12293.713
C5: Mar | D5: 40 | E5: 12720.29
B6: Qtr2 | C6: Apr | D6: 80 | E6: 9784.916
C7: May | E7: 3363.296
C8: Jun | D8: 27159.812 | E8: 4339.4726
B9: Qtr3 | C9: Jul | D9: 3742.0478 | E9: 7944.713
C10: Aug | D10: 7900.4476 | E10: 9099.6876
C11: Sep | D11: 16064.434 | E11: 10508.427
B12: Qtr4 | C12: Oct | D12: 14244.869 | E12: 6997.0412
C13: Nov | E13: 4796.2152
C14: Dec | D14: 2368.203 | E14: 2517.8992
A15: 2026 | B15: Qtr1 | C15: Jan | E15: 825.474

Sheet Updated Ascendus ledger
A1: Cleared Item | B1: Company Code | C1: Customer | D1: Customer Account: Name 1 | E1: Fiscal Year | F1: Posting period | G1: Posting Date | H1: Document Number | I1: Document Type | J1: Document Date | K1: Entry Date | L1: Document Header Text | M1: Reference | N1: G/L Account | O1: G/L Account: Short Text | P1: Special G/L Ind. | Q1: Posting Key | R1: Document Currency Key | S1: Document Currency Value | T1: Company Code Currency Key | U1: Company Code Currency Value | V1: Tax Code | W1: Profit Center | X1: Trading Partner No. | Y1: Assignment | Z1: Item | AG1: Text | AH1: Reference Key 1 | AI1: Reference Key 2 | AJ1: Reference Key 3 | AK1: Baseline Payment Dte | AL1: Clearing Date | AM1: Clearing Document
A2: Selected | B2: 6779 | C2: 100222372 | D2: SHAH TC GLOBAL EXIM LLP | E2: 2025 | F2: 9 | G2: 45902 | H2: 1400001110 | I2: DY | J2: 45902 | K2: 45902 | N2: 212100 | O2: Trade Debtors (Ctrl) | Q2: 08 | R2: INR | S2: 6940.7917 | T2: INR | U2: 595243.31 | W2: 6779224500 | Z2: 1 | AD2: =_xlfn.XLOOKUP(M2,'Customer Data Vlookup'!$R:$R,'Customer Data Vlookup'!$S:$S,,0) -> #N/A | AK2: 45902 | AL2: 45902 | AM2: 1400001110
A3: Selected | B3: 6779 | C3: 100222372 | D3: SHAH TC GLOBAL EXIM LLP | E3: 2025 | F3: 9 | G3: 45902 | H3: 1400001110 | I3: DY | J3: 45902 | K3: 45902 | N3: 212100 | O3: Trade Debtors (Ctrl) | Q3: 15 | R3: INR | S3: -6940.7917 | T3: INR | U3: -599760.56 | W3: 6779224500 | Z3: 2 | AD3: =_xlfn.XLOOKUP(M3,'Customer Data Vlookup'!$R:$R,'Customer Data Vlookup'!$S:$S,,0) -> #N/A | AK3: 45902 | AL3: 45902 | AM3: 1400001110
A4: Selected | B4: 6779 | C4: 100222372 | D4: SHAH TC GLOBAL EXIM LLP | E4: 2025 | F4: 8 | G4: 45887 | H4: 1400000854 | I4: DZ | J4: 45887 | K4: 45887 | N4: 212100 | O4: Trade Debtors (Ctrl) | Q4: 15 | R4: USD | S4: -700.45 | T4: INR | U4: -60884.42 | Z4: 4 | AD4: =_xlfn.XLOOKUP(M4,'Customer Data Vlookup'!$R:$R,'Customer Data Vlookup'!$S:$S,,0) -> #N/A | AK4: 45887 | AL4: 45887 | AM4: 1400000854
A5: Not Selected | B5: 6779 | C5: 100222372 | D5: SHAH TC GLOBAL EXIM LLP | E5: 2025 | F5: 10 | G5: 45931 | H5: 1400001231 | I5: DZ | J5: 45931 | K5: 45925 | L5: 0758767253FS | N5: 212100 | O5: Trade Debtors (Ctrl) | Q5: 15 | R5: USD | S5: -4719.25 | T5: INR | U5: -413002 | W5: 6779220000 | Z5: 2 | AD5: =_xlfn.XLOOKUP(M5,'Customer Data Vlookup'!$R:$R,'Customer Data Vlookup'!$S:$S,,0) -> #N/A | AK5: 45931
A6: Not Selected | B6: 6779 | C6: 100222372 | D6: SHAH TC GLOBAL EXIM LLP | E6: 2025 | F6: 8 | G6: 45890 | H6: 1400000977 | I6: DZ | J6: 45890 | K6: 45890 | L6: T54SWIC264904 | N6: 212100 | O6: Trade Debtors (Ctrl) | Q6: 15 | R6: USD | S6: -3663.7 | T6: INR | U6: -313212.57 | W6: 6779220000 | Z6: 2 | AD6: =_xlfn.XLOOKUP(M6,'Customer Data Vlookup'!$R:$R,'Customer Data Vlookup'!$S:$S,,0) -> #N/A | AK6: 45890
A7: Selected | B7: 6779 | C7: 100222372 | D7: SHAH TC GLOBAL EXIM LLP | E7: 2025 | F7: 7 | G7: 45839 | H7: 1400000126 | I7: DZ | J7: 45832 | K7: 45832 | L7: 1810304156FS | N7: 212100 | O7: Trade Debtors (Ctrl) | Q7: 15 | R7: USD | S7: -3663.7 | T7: INR | U7: -3663.7 | W7: 6779220000 | Z7: 2 | AD7: =_xlfn.XLOOKUP(M7,'Customer Data Vlookup'!$R:$R,'Customer Data Vlookup'!$S:$S,,0) -> #N/A | AK7: 45832 | AL7: 45839 | AM7: 1400000149
A8: Not Selected | B8: 6779 | C8: 100222372 | D8: SHAH TC GLOBAL EXIM LLP | E8: 2025 | F8: 7 | G8: 45839 | H8: 1400000128 | I8: DZ | J8: 45832 | K8: 45832 | L8: 8113643156FS | N8: 212100 | O8: Trade Debtors (Ctrl) | Q8: 15 | R8: USD | S8: -3145.98 | T8: INR | U8: -3145.98 | W8: 6779220000 | Z8: 2 | AD8: =_xlfn.XLOOKUP(M8,'Customer Data Vlookup'!$R:$R,'Customer Data Vlookup'!$S:$S,,0) -> #N/A | AK8: 45832
A9: Not Selected | B9: 6779 | C9: 100222372 | D9: SHAH TC GLOBAL EXIM LLP | E9: 2025 | F9: 7 | G9: 45839 | H9: 1400000133 | I9: DZ | J9: 45832 | K9: 45832 | L9: 1171852164FS | N9: 212100 | O9: Trade Debtors (Ctrl) | Q9: 15 | R9: USD | S9: -12549.36 | T9: INR | U9: -12549.36 | W9: 6779220000 | Z9: 2 | AD9: =_xlfn.XLOOKUP(M9,'Customer Data Vlookup'!$R:$R,'Customer Data Vlookup'!$S:$S,,0) -> #N/A | AK9: 45832
A10: Not Selected | B10: 6779 | C10: 100222372 | D10: SHAH TC GLOBAL EXIM LLP | E10: 2025 | F10: 7 | G10: 45839 | H10: 1400000134 | I10: DZ | J10: 45832 | K10: 45832 | L10: 4989824164FS | N10: 212100 | O10: Trade Debtors (Ctrl) | Q10: 15 | R10: USD | S10: -4228.22 | T10: INR | U10: -4228.22 | W10: 6779220000 | Z10: 2 | AD10: =_xlfn.XLOOKUP(M10,'Customer Data Vlookup'!$R:$R,'Customer Data Vlookup'!$S:$S,,0) -> #N/A | AK10: 45832
A11: Selected | B11: 6779 | C11: 100222372 | D11: SHAH TC GLOBAL EXIM LLP | E11: 2025 | F11: 7 | G11: 45839 | H11: 1400000149 | I11: DZ | J11: 45832 | K11: 45835 | L11: 1810304156FS | N11: 212100 | O11: Trade Debtors (Ctrl) | Q11: 05 | R11: USD | S11: 3663.7 | T11: INR | U11: 3663.7 | W11: 6779220000 | Z11: 2 | AD11: =_xlfn.XLOOKUP(M11,'Customer Data Vlookup'!$R:$R,'Customer Data Vlookup'!$S:$S,,0) -> #N/A | AK11: 45832 | AL11: 45839 | AM11: 1400000149
