Workbook

Sheet Summary
A2: Reconciliation of Ledger as on 31st January 2026
A3: Particulars | B3: Amount
A4: Balance as per Barnet India Pvt Ltd | B4: ='Customer data'!P188 -> 1917316.7
A5: Add: TDS recorded by customer but not in our books | B5: ='TDS data'!J1 -> 298205
A6: Add: Credit Note in Customer's Books | B6: ='Credit Note in customers books'!L5 -> 397146.74
A7: Less: Difference in Invoice value in customers books | B7: =-'Difference in Invoice value '!L8 -> -5055.6602
A8: Less: Duplicate CN in Ascendus Books | B8: ='Duplicate CN in Ascenudes Books'!H3 -> -7510.05
A9: less: Difference in Payment recorded in Ascendus books | B9: =Sheet5!G15 -> -464928.21
A10: Derived balance | B10: =SUM(B4:B9) -> 2135174.6
A11: Balance as per Ascendus | B11: ='Ascendus Data'!U337 -> 2135174.6
A13: Difference | B13: =B10-B11-B12 -> -0.006391603

Sheet Sheet5
A2: Years | B2: Date | C2: Company Code Currency Value | D2: Years | E2: Date | F2: Sum of AMOUNT PAID
A3: 2025 | B3: Mar | C3: 0 | D3: 2025 | E3: Mar | F3: 267943.73 | G3: =C3+F3 -> 267943.73
A4: 2025 | B4: Apr | C4: -291173.73 | D4: 2025 | E4: Apr | F4: 0 | G4: =C4+F4 -> -291173.73
A5: 2025 | B5: May | C5: 0 | D5: 2025 | E5: May | F5: 112111.95 | G5: =C5+F5 -> 112111.95
A6: 2025 | B6: Jun | C6: -341000 | D6: 2025 | E6: Jun | F6: 905889.53 | G6: =C6+F6 -> 564889.53
A7: 2025 | B7: Jul | C7: 0 | D7: 2025 | E7: Jul | F7: 475086.94 | G7: =C7+F7 -> 475086.94
A8: 2025 | B8: Aug | C8: 0 | D8: 2025 | E8: Aug | F8: 602275.11 | G8: =C8+F8 -> 602275.11
A9: 2025 | B9: Sep | C9: 0 | D9: 2025 | E9: Sep | F9: 124189.23 | G9: =C9+F9 -> 124189.23
A10: 2025 | B10: Oct | C10: -1805272.2 | D10: 2025 | E10: Oct | F10: 663652.5 | G10: =C10+F10 -> -1141619.7
A11: 2025 | B11: Nov | C11: -1129444.9 | D11: 2025 | E11: Nov | F11: 0 | G11: =C11+F11 -> -1129444.9
A12: 2025 | B12: Dec | C12: -422946.17 | D12: 2025 | E12: Dec | F12: 375012.8 | G12: =C12+F12 -> -47933.368
A13: 2026 | B13: Jan | C13: -1253.01 | D13: 2026 | E13: Jan | F13: 0 | G13: =C13+F13 -> -1253.01
A14: 2026 | B14: Feb | C14: -31395.72 | D14: 2026 | E14: Feb | F14: 31395.717 | G14: =C14+F14 -> -0.0034348
C15: =SUM(C3:C14) -> -4022485.7 | F15: =SUM(F3:F14) -> 3557557.5 | G15: =SUM(G3:G14) -> -464928.21

Sheet Sheet3
A1: As per Customer
A2: Date | B2: AMOUNT PAID | C2: UTR NO/REMARK | E2: Years | F2: Quarters | G2: Date | H2: Sum of AMOUNT PAID
A3: 45728 | B3: 69973.16 | C3: HDFCN52025031215974606 | E3: 2025 | F3: Qtr1 | G3: Mar | H3: 267943.73
A4: 45728 | B4: 28756.3 | C4: HDFCN52025031215976413 | F4: Qtr2 | G4: May | H4: 112111.95
A5: 45728 | B5: 97112.2 | C5: HDFCN52025031215974609 | G5: Jun | H5: 905889.53
A6: 45740 | B6: 11330.33 | C6: HDFCN52025032433793860 | F6: Qtr3 | G6: Jul | H6: 475086.94
A7: 45740 | B7: 18128.12 | C7: HDFCN52025032433793867 | G7: Aug | H7: 602275.11
A8: 45740 | B8: 18128.12 | C8: HDFCN52025032433793886 | G8: Sep | H8: 124189.23
A9: 45740 | B9: 4532.53 | C9: HDFCN52025032433793875 | F9: Qtr4 | G9: Oct | H9: 663652.5
A10: 45740 | B10: 15450.44 | C10: HDFCN52025032433791996 | G10: Dec | H10: 375012.8
A11: 45740 | B11: 4532.53 | C11: HDFCN52025032433791993 | E11: 2026 | F11: Qtr1 | G11: Feb | H11: 31395.717
A12: 45791 | B12: 28538.08 | C12: HDFCN52025051435275414
A13: 45791 | B13: 24143.251 | C13: HDFCN52025051435275414
A14: 45791 | B14: 6746.2081 | C14: HDFCN52025051435275414 | E14: Years | F14: Quarters | G14: Date | H14: Sum of AMOUNT PAID
A15: 45791 | B15: 11040.068 | C15: HDFCN52025051435275414 | E15: 2025 | F15: Qtr1 | G15: Mar | H15: 267943.73
A16: 45791 | B16: 24143.251 | C16: HDFCN52025051435275414 | F16: Qtr2 | G16: May | H16: 112111.95
A17: 45791 | B17: 11040.068 | C17: HDFCN52025051435275414 | G17: Jun | H17: 905889.53
A18: 45791 | B18: 6461.02 | C18: HDFCN52025051435275414 | F18: Qtr3 | G18: Jul | H18: 475086.94
A19: 45813 | B19: 2186.2831 | C19: HDFCN52025060575568983 | G19: Aug | H19: 602275.11
A20: 45813 | B20: 3566.69 | C20: HDFCN52025060575568983 | G20: Sep | H20: 124189.23
A21: 45813 | B21: 8026.5902 | C21: HDFCN52025060575568983 | F21: Qtr4 | G21: Oct | H21: 663652.5
A22: 45813 | B22: 2293.664 | C22: HDFCN52025060575568983 | G22: Dec | H22: 375012.8
A23: 45813 | B23: 3670.0624 | C23: HDFCN52025060575568983 | E23: 2026 | F23: Qtr1 | G23: Feb | H23: 31395.717
A24: 45813 | B24: 8026.5902 | C24: HDFCN52025060575568983
A25: 45813 | B25: 2293.664 | C25: HDFCN52025060575568983
A26: 45813 | B26: 3670.0624 | C26: HDFCN52025060575568983
A27: 45813 | B27: 16052.314 | C27: HDFCN52025060575568983
A28: 45813 | B28: 4587.328 | C28: HDFCN52025060575568983
A29: 45813 | B29: 7340.1249 | C29: HDFCN52025060575568983
A30: 45813 | B30: 15921.62 | C30: HDFCN52025060575568983
A31: 45813 | B31: 15921.62 | C31: HDFCN52025060575568983
A32: 45813 | B32: 57739.158 | C32: HDFCN52025060575568983
A33: 45813 | B33: 4339.1605 | C33: HDFCN52025060575568983
A34: 45813 | B34: 3551.3531 | C34: HDFCN52025060575568983
A35: 45813 | B35: 341000 | C35: HDFCN52025060575565670
... A92: 46067 | B92: 971.66757 | C92: HDFCH00806112854

Sheet Sheet4
A1: Document Type | B1: Document Date | C1: Company Code Currency Value | D1: Text | I1: Years | J1: Quarters | K1: Document Date | L1: Sum of Company Code Currency Value
A2: DZ | B2: 45772 | C2: -77748.16 | D2: HDFCN52025031215974606 | I2: 2025 | J2: Qtr2 | K2: Apr | L2: -291173.73
A3: DZ | B3: 45772 | C3: -31951.3 | D3: HDFCN52025031215976413 | K3: Jun | L3: -341000
A4: DZ | B4: 45772 | C4: -107902.2 | D4: HDFCN52025031215974609 | J4: Qtr3 | K4: Aug | L4: 0
A5: DZ | B5: 45772 | C5: -11561.33 | D5: HDFCN52025032433793860 | K5: Sep | L5: 0
A6: DZ | B6: 45772 | C6: -18498.12 | D6: HDFCN52025032433793867 | J6: Qtr4 | K6: Oct | L6: -1805272.2
A7: DZ | B7: 45772 | C7: -18498.12 | D7: HDFCN52025032433793886 | K7: Nov | L7: -1129444.9
A8: DZ | B8: 45772 | C8: -4624.53 | D8: HDFCN52025032433793875 | K8: Dec | L8: -422946.17
A9: DZ | B9: 45772 | C9: -15765.44 | D9: HDFCN52025032433791996 | I9: 2026 | J9: Qtr1 | K9: Jan | L9: -1253.01
A10: DZ | B10: 45772 | C10: -4624.53 | D10: HDFCN52025032433791993 | K10: Feb | L10: -31395.72
A11: DZ | B11: 45832 | C11: -341000
A12: DZ | B12: 45832 | C12: -112111.95
A13: DZ | B13: 45832 | C13: 112111.95
A14: DZ | B14: 45832 | C14: 159186.29
A15: DZ | B15: 45832 | C15: -159186.29
A16: DZ | B16: 45890 | C16: 179293.83
A17: DZ | B17: 45890 | C17: -179293.83
A18: DZ | B18: 45890 | C18: 475086.94
A19: DZ | B19: 45890 | C19: -475086.94
A20: DZ | B20: 45908 | C20: 495157.4
A21: DZ | B21: 45908 | C21: -495157.4
A22: DZ | B22: 45908 | C22: 107117.71
... A28: DZ | B28: 45938 | C28: -339060.54
A29: DZ | B29: 45946 | C29: 2932.62 | D29: HDFCH00465695692
A30: DZ | B30: 45946 | C30: -492209.06 | D30: HDFCN52025082227307462
A31: DZ | B31: 45946 | C31: -139776.58 | D31: HDFCH00465695692
A32: DZ | B32: 45946 | C32: -2932.62
A33: DZ | B33: 45946 | C33: -116988.95 | D33: HDFCN52025051435275414
A34: DZ | B34: 45946 | C34: -646935.77 | D34: HDFCN52025100205721894
A35: DZ | B35: 45946 | C35: -182952.83 | D35: HDFCN52025062512710909
A36: DZ | B36: 45972 | C36: -324591.96
A37: DZ | B37: 45979 | C37: -8051.51 | D37: HDFCN52025060575568983
A38: DZ | B38: 45979 | C38: -109304.71 | D38: HDFCN52025082733046460
A39: DZ | B39: 45979 | C39: -159622.78 | D39: HDFCN52025060575568983
A40: DZ | B40: 45979 | C40: -50734.53 | D40: HDFCN52025072369906032
A41: DZ | B41: 45979 | C41: -477139.41 | D41: HDFCN52025072369906032
A42: DZ | B42: 46007 | C42: -66620.79 | D42: G15K40FCKGJH
A43: DZ | B43: 46007 | C43: -296024
A44: DZ | B44: 46007 | C44: -30866.77 | D44: G15K40FCKGJH
A45: DZ | B45: 46007 | C45: -14531.11
...

Sheet Payment Reco Updated
A2: As Per Bank Details | D2: As per Ascendus ledger | G2: Reco
A3: Payment Date | B3: Recd Amount | C3: Bank Reference | D3: Clearing Documents | E3: Document Header Text | F3: Sum of Company Code Currency Value | G3: TDS | H3: Difference | I3: Reasons
A4: 45933 | B4: 324591.96 | C4: HDFCN52025100308494407 | D4: Not Yet Cleared | E4: HDFCN52025100308494407 | F4: -324591.96 | G4: =_xlfn.XLOOKUP(D4,Sheet8!$D:$D,Sheet8!$E:$E,0,0) -> 0 | H4: =B4+F4+G4 -> 0 | I4: Documents Not Yet Cleared
A5: 45933 | B5: 339060.54 | C5: HDFCN52025100205721894 | D5: 1400001455 | E5: HDFCN52025100205721894 | F5: -646935.77 | G5: =_xlfn.XLOOKUP(D5,Sheet8!$D:$D,Sheet8!$E:$E,0,0) -> 57796 | H5: =B5+F5+G5 -> -250079.23 | I5: Part Payment Cleared
A6: 45896 | B6: 107117.71 | C6: HDFCN52025082733046460 | D6: 1400001956 | E6: HDFCN52025082733046460 | F6: -109304.71 | G6: =_xlfn.XLOOKUP(D6,Sheet8!$D:$D,Sheet8!$E:$E,0,0) -> 2187 | H6: =B6+F6+G6 -> 0
A7: 45891 | B7: 495157.4 | C7: HDFCN52025082227307462 | D7: 1400001452 | E7: HDFCN52025082227307462 | F7: -492209.06 | G7: =_xlfn.XLOOKUP(D7,Sheet8!$D:$D,Sheet8!$E:$E,0,0) -> 9843 | H7: =B7+F7+G7 -> 12791.34 | I7: Foreign exchange Gain/Loss
D8: 1400001453 | F8: -2932.62 | H8: =B8+F8+G8 -> -2932.62 | I8: Not In Bank
D9: 1400001453 | E9: HDFCH00465695692 | F9: -136843.96 | G9: =_xlfn.XLOOKUP(D9,Sheet8!$D:$D,Sheet8!$E:$E,0,0) -> 2796 | H9: =B9+F9+G9 -> -134047.96 | I9: Not In Bank
A10: 45861 | B10: 475086.94 | C10: HDFCN52025072369906032 | D10: 1400001972 | E10: HDFCN52025072369906032 | F10: -477139.41 | G10: =_xlfn.XLOOKUP(D10,Sheet8!$D:$D,Sheet8!$E:$E,0,0) -> 47714 | H10: =B10+F10+G10 -> 45661.53
D11: 1400001971 | E11: HDFCN52025072369906032 | F11: -50734.53 | G11: =_xlfn.XLOOKUP(D11,Sheet8!$D:$D,Sheet8!$E:$E,0,0) -> 5073 | H11: =B11+F11+G11 -> -45661.53
A12: 45833 | B12: 179293.83 | C12: HDFCN52025062512710909 | D12: 1400001456 | E12: HDFCN52025062512710909 | F12: -182952.83 | G12: =_xlfn.XLOOKUP(D12,Sheet8!$D:$D,Sheet8!$E:$E,0,0) -> 3659 | H12: =B12+F12+G12 -> 0
A13: 45822 | B13: 226409 | C13: HDFCN52025061495304800 | D13: Not Yet Cleared | E13: HDFCN52025061495304800 | F13: -226409 | G13: =_xlfn.XLOOKUP(D13,Sheet8!$D:$D,Sheet8!$E:$E,0,0) -> 0 | H13: =B13+F13+G13 -> 0 | I13: Documents Not Yet Cleared
A14: 45813 | B14: 159186.29 | C14: HDFCN52025060575568983 | D14: 1400001961 | E14: HDFCN52025060575568983 | F14: -167674.29 | G14: =_xlfn.XLOOKUP(D14,Sheet8!$D:$D,Sheet8!$E:$E,0,0) -> 8488 | H14: =B14+F14+G14 -> 0
A15: 45813 | B15: 341000 | C15: HDFCN52025060575565670 | D15: Not Yet Cleared | E15: HDFCN52025060575565670 | F15: -341000 | G15: =_xlfn.XLOOKUP(D15,Sheet8!$D:$D,Sheet8!$E:$E,0,0) -> 0 | H15: =B15+F15+G15 -> 0 | I15: Documents Not Yet Cleared
A16: 45791 | B16: 112111.95 | C16: HDFCN52025051435275414 | D16: 1400001454 | E16: HDFCN52025051435275414 | F16: -116988.95 | G16: =_xlfn.XLOOKUP(D16,Sheet8!$D:$D,Sheet8!$E:$E,0,0) -> 4877 | H16: =B16+F16+G16 -> 0
A17: 45740 | B17: 18128.12 | C17: HDFCN52025032433793886 | D17: 1400000012 | E17: HDFCN52025032433793886 | F17: -18498.12 | G17: =_xlfn.XLOOKUP(D17,Sheet8!$D:$D,Sheet8!$E:$E,0,0) -> 370 | H17: =B17+F17+G17 -> 0
A18: 45740 | B18: 4532.53 | C18: HDFCN52025032433793875 | D18: 1400000013 | E18: HDFCN52025032433793875 | F18: -4624.53 | G18: =_xlfn.XLOOKUP(D18,Sheet8!$D:$D,Sheet8!$E:$E,0,0) -> 92 | H18: =B18+F18+G18 -> 0
A19: 45740 | B19: 18128.12 | C19: HDFCN52025032433793867 | D19: 1400000011 | E19: HDFCN52025032433793867 | F19: -18498.12 | G19: =_xlfn.XLOOKUP(D19,Sheet8!$D:$D,Sheet8!$E:$E,0,0) -> 370 | H19: =B19+F19+G19 -> 0
A20: 45740 | B20: 11330.33 | C20: HDFCN52025032433793860 | D20: 1400000010 | E20: HDFCN52025032433793860 | F20: -11561.33 | G20: =_xlfn.XLOOKUP(D20,Sheet8!$D:$D,Sheet8!$E:$E,0,0) -> 231 | H20: =B20+F20+G20 -> 0
A21: 45740 | B21: 15450.44 | C21: HDFCN52025032433791996 | D21: 1400000014 | E21: HDFCN52025032433791996 | F21: -15765.44 | G21: =_xlfn.XLOOKUP(D21,Sheet8!$D:$D,Sheet8!$E:$E,0,0) -> 315 | H21: =B21+F21+G21 -> 0
A22: 45740 | B22: 4532.53 | C22: HDFCN52025032433791993 | D22: 1400000015 | E22: HDFCN52025032433791993 | F22: -4624.53 | G22: =_xlfn.XLOOKUP(D22,Sheet8!$D:$D,Sheet8!$E:$E,0,0) -> 92 | H22: =B22+F22+G22 -> 0
A23: 45728 | B23: 28756.3 | C23: HDFCN52025031215976413 | D23: 1400000008 | E23: HDFCN52025031215976413 | F23: -31951.3 | G23: =_xlfn.XLOOKUP(D23,Sheet8!$D:$D,Sheet8!$E:$E,0,0) -> 3195 | H23: =B23+F23+G23 -> 0
A24: 45728 | B24: 97112.2 | C24: HDFCN52025031215974609 | D24: 1400000009 | E24: HDFCN52025031215974609 | F24: -107902.2 | G24: =_xlfn.XLOOKUP(D24,Sheet8!$D:$D,Sheet8!$E:$E,0,0) -> 10790 | H24: =B24+F24+G24 -> 0
A25: 45728 | B25: 69973.16 | C25: HDFCN52025031215974606 | D25: 1400000007 | E25: HDFCN52025031215974606 | F25: -77748.16 | G25: =_xlfn.XLOOKUP(D25,Sheet8!$D:$D,Sheet8!$E:$E,0,0) -> 7775 | H25: =B25+F25+G25 -> 0
A26: 46069 | B26: 30424.05 | C26: H3YKFZWVB0GN | D26: Not Yet Cleared | E26: H3YKFZWVB0GN | F26: -30424.05 | G26: =_xlfn.XLOOKUP(D26,Sheet8!$D:$D,Sheet8!$E:$E,0,0) -> 0 | H26: =B26+F26+G26 -> 0 | I26: Documents Not Yet Cleared
A27: 46069 | B27: 971.67 | C27: H2PMXC728CY0 | D27: Not Yet Cleared | E27: H2PMXC728CY0 | F27: -971.67 | G27: =_xlfn.XLOOKUP(D27,Sheet8!$D:$D,Sheet8!$E:$E,0,0) -> 0 | H27: =B27+F27+G27 -> 0 | I27: Documents Not Yet Cleared
A28: 46006 | B28: 14903.5 | C28: G90RGJ9HVGZQ | D28: Not Yet Cleared | E28: G15K40FCKGJH | F28: -296024 | G28: =_xlfn.XLOOKUP(D29,Sheet8!$D:$D,Sheet8!$E:$E,0,0) -> 0 | H28: =B29+F28+G28 -> 64085.3 | I28: Documents Not Yet Cleared
A29: 45993 | B29: 360109.3 | C29: G15K40FCKGJH | D29: Not Yet Cleared | E29: G15K40FCKGJH | F29: -97487.56 | G29: =_xlfn.XLOOKUP(D30,Sheet8!$D:$D,Sheet8!$E:$E,0,0) -> 4539 | H29: =B30+F29+G29 -> -92948.56 | I29: =G29/F29 -> -0.046559787
D30: 1400002197 | E30: G15K40FCKGJH+G90RGJ9HVGZQ | F30: =-14531.11-16156.51 -> -30687.62 | G30: =_xlfn.XLOOKUP(D31,Sheet8!$D:$D,Sheet8!$E:$E,0,0) -> 614 | H30: =B31+F30+G30 -> -30073.62 | I30: =G30/F30 -> -0.020008068
D31: 1400002389

Sheet Sheet8
A3: Row Labels | B3: Sum of TDS | D3: Row Labels | E3: Sum of TDS
A4: 1400000007 | B4: 7775 | D4: 1400000007 | E4: 7775
A5: 1400000008 | B5: 3195 | D5: 1400000008 | E5: 3195
A6: 1400000009 | B6: 10790 | D6: 1400000009 | E6: 10790
A7: 1400000010 | B7: 231 | D7: 1400000010 | E7: 231
A8: 1400000011 | B8: 370 | D8: 1400000011 | E8: 370
A9: 1400000012 | B9: 370 | D9: 1400000012 | E9: 370
A10: 1400000013 | B10: 92 | D10: 1400000013 | E10: 92
A11: 1400000014 | B11: 315 | D11: 1400000014 | E11: 315
A12: 1400000015 | B12: 92 | D12: 1400000015 | E12: 92
A13: 1400000293 | D13: 1400000293
A14: 1400000294 | D14: 1400000294
A15: 1400000295 | D15: 1400000295
A16: 1400000296 | D16: 1400000296
A17: 1400000297 | D17: 1400000297
A18: 1400000298 | D18: 1400000298
A19: 1400000299 | D19: 1400000299
A20: 1400000300 | D20: 1400000300
A21: 1400000301 | D21: 1400000301
A22: 1400000302 | D22: 1400000302
A23: 1400000303 | D23: 1400000303
A24: 1400000304 | D24: 1400000304
... A65: 1400001451 | D65: 1400001451
A66: 1400001452 | B66: 9843 | D66: 1400001452 | E66: 9843
A67: 1400001453 | B67: 2796 | D67: 1400001453 | E67: 2796
A68: 1400001454 | B68: 4877 | D68: 1400001454 | E68: 4877
A69: 1400001455 | B69: 57796 | D69: 1400001455 | E69: 57796
A70: 1400001456 | B70: 3659 | D70: 1400001456 | E70: 3659
A71: 1400001458 | D71: 1400001458
A72: 1400001468 | D72: 1400001468
A73: 1400001956 | B73: 2187 | D73: 1400001956 | E73: 2187
A74: 1400001961 | B74: 8488 | D74: 1400001961 | E74: 8488
A75: 1400001971 | B75: 5073 | D75: 1400001971 | E75: 5073
A76: 1400001972 | B76: 47714 | D76: 1400001972 | E76: 47714
A77: 1400001988 | D77: 1400001988
A78: 1400001989 | D78: 1400001989
A79: 1400001993 | D79: 1400001993
A80: 1400002197 | B80: 4539 | D80: 1400002197 | E80: 4539
A81: 1400002388 | D81: 1400002388
A82: 1400002389 | B82: 614 | D82: 1400002389 | E82: 614
...

Sheet Ascendus Data
AK1: =SUBTOTAL(9,AK148:AK334) -> 0.005074
A2: Cleared Item | B2: Company Code | C2: Customer | D2: Customer Account: Name 1 | E2: Fiscal Year | F2: Posting period | G2: Posting Date | H2: Document Number | I2: Document Type | J2: Document Date | K2: Entry Date | L2: Document Header Text | M2: Reference | N2: G/L Account | O2: G/L Account: Short Text | P2: Special G/L Ind. | Q2: Posting Key | R2: Document Currency Key | S2: Document Currency Value | T2: Company Code Currency Key | U2: Company Code Currency Value | V2: Tax Code | W2: Profit Center | X2: Trading Partner No. | Y2: Assignment | Z2: Item | AA2: Text | AB2: Reference Key 1 | AC2: Reference Key 2 | AD2: Reference Key 3 | AE2: Baseline Payment Dte | AF2: Clearing Date | AG2: Clearing Documents | AH2: Gross Amount | AI2: TDS | AJ2: Net Amount | AK2: Difference | AL2: Rate | AO2: Payment reference as per customer
A3: Selected | B3: 6779 | C3: 100222397 | D3: BARNET INDIA PRIVATE LIMITED | E3: 2025 | F3: 9 | G3: 46070 | H3: 1400002720 | I3: DZ | J3: 46070 | K3: 46070 | L3: H3YKFZWVB0GN | M3: 2173609 | N3: 212100 | O3: Trade Debtors (Ctrl) | Q3: 15 | R3: INR | S3: -30424.05 | T3: INR | U3: -30424.05 | W3: 6779220000 | Z3: 2 | AE3: 46070 | AH3: {=VLOOKUP(M3,'Customer data Vlookup'!$B$3:$H$127,{2,3},0)} -> #N/A | AO3: =VLOOKUP(M3,'Customer data'!F:P,11,0) -> #N/A
A4: Selected | B4: 6779 | C4: 100222397 | D4: BARNET INDIA PRIVATE LIMITED | E4: 2025 | F4: 12 | G4: 46070 | H4: 1400002721 | I4: DZ | J4: 46070 | K4: 46070 | L4: H2PMXC728CY0 | M4: 2173609 | N4: 212100 | O4: Trade Debtors (Ctrl) | Q4: 15 | R4: INR | S4: -971.67 | T4: INR | U4: -971.67 | W4: 6779220000 | Z4: 2 | AE4: 46070 | AH4: {=VLOOKUP(M4,'Customer data Vlookup'!$B$3:$H$127,{2,3},0)} -> #N/A | AO4: =VLOOKUP(M4,'Customer data'!F:P,11,0) -> #N/A
A5: Selected | B5: 6779 | C5: 100222397 | D5: BARNET INDIA PRIVATE LIMITED | E5: 2025 | F5: 10 | G5: 46065 | H5: 1800017510 | I5: DR | J5: 46065 | K5: 46069 | L5: NA | M5: 256779451324 | N5: 212100 | O5: Trade Debtors (Ctrl) | Q5: 01 | R5: USD | S5: 384.56 | T5: INR | U5: 34739.3 | V5: O0 | W5: 6779224501 | Y5: 2172711 | Z5: 1 | AA5: Unit Storage 1-31 Jan 2026 | AE5: 46065 | AH5: {=VLOOKUP(M5,'Customer data Vlookup'!$B$3:$H$127,{2,3},0)} -> 34739.305 | AI5: 3474 | AJ5: =AH5-AI5 -> 31265.305 | AK5: =U5-AH5 -> -0.004512 | AL5: =AI5/U5 -> 0.10000202 | AO5: =VLOOKUP(M5,'Customer data'!F:P,11,0) -> Not Approved
A6: Selected | B6: 6779 | C6: 100222397 | D6: BARNET INDIA PRIVATE LIMITED | E6: 2025 | F6: 11 | G6: 46064 | H6: 1800017704 | I6: DR | J6: 46064 | K6: 46069 | L6: 2173095 | M6: 256779451520 | N6: 212100 | O6: Trade Debtors (Ctrl) | Q6: 01 | R6: USD | S6: 61.04 | T6: INR | U6: 5514.06 | V6: O0 | W6: 6779224501 | Y6: NA | Z6: 1 | AA6: LCL Chgs - 16 - 31 JAN 26 | AE6: 46064 | AH6: {=VLOOKUP(M6,'Customer data Vlookup'!$B$3:$H$127,{2,3},0)} -> 5514.0606 | AI6: 111 | AJ6: =AH6-AI6 -> 5403.0606 | AK6: =U6-AH6 -> -0.000608 | AL6: =AI6/U6 -> 0.020130358 | AO6: =VLOOKUP(M6,'Customer data'!F:P,11,0) -> Not Approved
A7: Not Selected | B7: 6779 | C7: 100222397 | D7: BARNET INDIA PRIVATE LIMITED | E7: 2025 | F7: 10 | G7: 46030 | H7: 1400002388 | I7: DZ | J7: 46030 | K7: 46030 | L7: G15K40FCKGJH | N7: 212100 | O7: Trade Debtors (Ctrl) | Q7: 08 | R7: INR | S7: 14531.11 | T7: INR | U7: 14531.11 | W7: 6779220000 | Z7: 2 | AE7: 46030 | AF7: 46030 | AG7: 1400002388 | AH7: {=VLOOKUP(M7,'Customer data Vlookup'!$B$3:$H$127,{2,3},0)} -> #N/A | AO7: =VLOOKUP(M7,'Customer data'!F:P,11,0) -> #N/A
A8: Selected | B8: 6779 | C8: 100222397 | D8: BARNET INDIA PRIVATE LIMITED | E8: 2025 | F8: 11 | G8: 46030 | H8: 1400002389 | I8: DZ | J8: 46030 | K8: 46030 | L8: G90RGJ9HVGZQ | N8: 212100 | O8: Trade Debtors (Ctrl) | Q8: 08 | R8: INR | S8: 14903.5 | T8: INR | U8: 14903.5 | W8: 6779220000 | Z8: 3 | AE8: 46030 | AF8: 46030 | AG8: 1400002389 | AH8: {=VLOOKUP(M8,'Customer data Vlookup'!$B$3:$H$127,{2,3},0)} -> #N/A | AO8: =VLOOKUP(M8,'Customer data'!F:P,11,0) -> #N/A
A9: Selected | B9: 6779 | C9: 100222397 | D9: BARNET INDIA PRIVATE LIMITED | E9: 2025 | F9: 11 | G9: 46030 | H9: 1400002389 | I9: DZ | J9: 46030 | K9: 46030 | L9: G90RGJ9HVGZQ | N9: 212100 | O9: Trade Debtors (Ctrl) | Q9: 08 | R9: INR | S9: 14531.11 | T9: INR | U9: 14531.11 | W9: 6779224500 | Z9: 4 | AE9: 46030 | AF9: 46030 | AG9: 1400002389 | AH9: {=VLOOKUP(M9,'Customer data Vlookup'!$B$3:$H$127,{2,3},0)} -> #N/A | AO9: =VLOOKUP(M9,'Customer data'!F:P,11,0) -> #N/A
A10: Selected | B10: 6779 | C10: 100222397 | D10: BARNET INDIA PRIVATE LIMITED | E10: 2025 | F10: 11 | G10: 46030 | H10: 1400002389 | I10: DZ | J10: 46030 | K10: 46030 | L10: G90RGJ9HVGZQ | N10: 212100 | O10: Trade Debtors (Ctrl) | Q10: 15 | R10: INR | S10: -31650.87 | T10: INR | U10: -30687.62 | W10: 6779224500 | Z10: 5 | AE10: 46030 | AF10: 46030 | AG10: 1400002389 | AH10: {=VLOOKUP(M10,'Customer data Vlookup'!$B$3:$H$127,{2,3},0)} -> #N/A | AO10: =VLOOKUP(M10,'Customer data'!F:P,11,0) -> #N/A
A11: Selected | B11: 6779 | C11: 100222397 | D11: BARNET INDIA PRIVATE LIMITED | E11: 2025 | F11: 11 | G11: 46030 | H11: 1400002388 | I11: DZ | J11: 46030 | K11: 46030 | L11: G15K40FCKGJH | N11: 212100 | O11: Trade Debtors (Ctrl) | Q11: 15 | R11: INR | S11: -14531.11 | T11: INR | U11: -14531.11 | W11: 6779224500 | Y11: NA | Z11: 1 | AE11: 46030 | AF11: 46030 | AG11: 1400002389 | AH11: {=VLOOKUP(M11,'Customer data Vlookup'!$B$3:$H$127,{2,3},0)} -> #N/A | AO11: =VLOOKUP(M11,'Customer data'!F:P,11,0) -> #N/A
A12: Selected | B12: 6779 | C12: 100222397 | D12: BARNET INDIA PRIVATE LIMITED | E12: 2025 | F12: 10 | G12: 46028 | H12: 1800016266 | I12: DR | J12: 46028 | K12: 46031 | L12: 2158342 | M12: 256779440152 | N12: 212100 | O12: Trade Debtors (Ctrl) | Q12: 01 | R12: USD | S12: 246.17 | T12: INR | U12: 22338.24 | V12: O0 | W12: 6779224500 | Y12: NA | Z12: 1 | AA12: PORT SSR Chgs Dec 25 | AE12: 46028 | AH12: {=VLOOKUP(M12,'Customer data Vlookup'!$B$3:$H$127,{2,3},0)} -> 22338.239 | AI12: 447 | AJ12: =AH12-AI12 -> 21891.239 | AK12: =U12-AH12 -> 0.0012262 | AL12: =AI12/U12 -> 0.020010529 | AO12: =VLOOKUP(M12,'Customer data'!F:P,11,0) -> Not Approved
A13: Selected | B13: 6779 | C13: 100222397 | D13: BARNET INDIA PRIVATE LIMITED | E13: 2025 | F13: 8 | G13: 46028 | H13: 1800016352 | I13: DR | J13: 46028 | K13: 46034 | L13: 2158411 | M13: 256779440242 | N13: 212100 | O13: Trade Debtors (Ctrl) | Q13: 01 | R13: USD | S13: 881.6 | T13: INR | U13: 79999.15 | V13: O0 | W13: 6779224500 | Y13: NA | Z13: 1 | AA13: Unit Storage - 1-31 DEC 2025 | AE13: 46028 | AH13: {=VLOOKUP(M13,'Customer data Vlookup'!$B$3:$H$127,{2,3},0)} -> 79999.152 | AI13: 8000 | AJ13: =AH13-AI13 -> 71999.152 | AK13: =U13-AH13 -> -0.002224 | AL13: =AI13/U13 -> 0.10000106 | AO13: =VLOOKUP(M13,'Customer data'!F:P,11,0) -> Not Approved
A14: Selected | B14: 6779 | C14: 100222397 | D14: BARNET INDIA PRIVATE LIMITED | E14: 2025 | F14: 11 | G14: 46027 | H14: 1800016064 | I14: DR | J14: 46027 | K14: 46027 | L14: 2156406 | M14: 256779440106 | N14: 212100 | O14: Trade Debtors (Ctrl) | Q14: 01 | R14: USD | S14: 700 | T14: INR | U14: 63520.2 | V14: O0 | W14: 6779224500 | Y14: NA | Z14: 1 | AA14: Transportation IN Chgs - 01 - 15 DEC 25 | AE14: 46027 | AH14: {=VLOOKUP(M14,'Customer data Vlookup'!$B$3:$H$127,{2,3},0)} -> 63520.198 | AI14: 1270 | AJ14: =AH14-AI14 -> 62250.198 | AK14: =U14-AH14 -> 0.002 | AL14: =AI14/U14 -> 0.01999364 | AO14: =VLOOKUP(M14,'Customer data'!F:P,11,0) -> Not Approved
A15: Selected | B15: 6779 | C15: 100222397 | D15: BARNET INDIA PRIVATE LIMITED | E15: 2025 | F15: 8 | G15: 46024 | H15: 1800015679 | I15: DR | J15: 46024 | K15: 46024 | L15: NA | M15: 256779440012 | N15: 212100 | O15: Trade Debtors (Ctrl) | Q15: 01 | R15: USD | S15: 182.78 | T15: INR | U15: 16586.03 | V15: O0 | W15: 6779224500 | Y15: 2139799 | Z15: 1 | AA15: Unit Storage - 1-30 Nov 2025 | AE15: 46024 | AH15: {=VLOOKUP(M15,'Customer data Vlookup'!$B$3:$H$127,{2,3},0)} -> 33172.062 | AI15: 3318 | AJ15: =AH15-AI15 -> 29854.062 | AK15: =U15-AH15 -> -16586.032 | AL15: =AI15/U15 -> 0.20004787 | AO15: =VLOOKUP(M15,'Customer data'!F:P,11,0) -> Not Approved
A16: Selected | B16: 6779 | C16: 100222397 | D16: BARNET INDIA PRIVATE LIMITED | E16: 2025 | F16: 10 | G16: 46024 | H16: 1800015717 | I16: DR | J16: 46024 | K16: 46024 | L16: NA | M16: 256779440046 | N16: 212100 | O16: Trade Debtors (Ctrl) | Q16: 01 | R16: USD | S16: 50 | T16: INR | U16: 4537.16 | V16: O0 | W16: 6779224500 | Y16: 2139808 | Z16: 1 | AA16: Scanning Chgs - 16 - 30 Nov 25 | AE16: 46024 | AH16: {=VLOOKUP(M16,'Customer data Vlookup'!$B$3:$H$127,{2,3},0)} -> 9074.314 | AI16: 182 | AJ16: =AH16-AI16 -> 8892.314 | AK16: =U16-AH16 -> -4537.154 | AL16: =AI16/U16 -> 0.040113199 | AO16: =VLOOKUP(M16,'Customer data'!F:P,11,0) -> Not Approved
A17: Selected | B17: 6779 | C17: 100222397 | D17: BARNET INDIA PRIVATE LIMITED | E17: 2025 | F17: 9 | G17: 46011 | H17: 1400002237 | I17: DZ | J17: 46011 | K17: 46011 | L17: G90RGJ9HVGZQ | N17: 212100 | O17: Trade Debtors (Ctrl) | Q17: 15 | R17: INR | S17: -14903.5 | T17: INR | U17: -14903.5 | W17: 6779220000 | Z17: 2 | AE17: 46011 | AF17: 46030 | AG17: 1400002389 | AH17: {=VLOOKUP(M17,'Customer data Vlookup'!$B$3:$H$127,{2,3},0)} -> #N/A | AO17: =VLOOKUP(M17,'Customer data'!F:P,11,0) -> #N/A
A18: Selected | B18: 6779 | C18: 100222397 | D18: BARNET INDIA PRIVATE LIMITED | E18: 2025 | F18: 10 | G18: 46007 | H18: 1400002197 | I18: DZ | J18: 46007 | K18: 46007 | L18: G15K40FCKGJH | N18: 212100 | O18: Trade Debtors (Ctrl) | Q18: 15 | R18: INR | S18: -67082.14 | T18: INR | U18: -66620.79 | W18: 6779224500 | Z18: 5 | AA18: G15K40FCKGJH | AE18: 46007 | AF18: 46007 | AG18: 1400002197 | AH18: {=VLOOKUP(M18,'Customer data Vlookup'!$B$3:$H$127,{2,3},0)} -> #N/A | AO18: =VLOOKUP(M18,'Customer data'!F:P,11,0) -> #N/A
A19: Selected | B19: 6779 | C19: 100222397 | D19: BARNET INDIA PRIVATE LIMITED | E19: 2025 | F19: 10 | G19: 46007 | H19: 1400002197 | I19: DZ | J19: 46007 | K19: 46007 | L19: G15K40FCKGJH | N19: 212100 | O19: Trade Debtors (Ctrl) | Q19: 15 | R19: INR | S19: -31045.05 | T19: INR | U19: -30866.77 | W19: 6779224501 | Z19: 4 | AA19: G15K40FCKGJH | AE19: 46007 | AF19: 46007 | AG19: 1400002197 | AH19: {=VLOOKUP(M19,'Customer data Vlookup'!$B$3:$H$127,{2,3},0)} -> #N/A | AO19: =VLOOKUP(M19,'Customer data'!F:P,11,0) -> #N/A
A20: Selected | B20: 6779 | C20: 100222397 | D20: BARNET INDIA PRIVATE LIMITED | E20: 2025 | F20: 10 | G20: 46007 | H20: 1400002198 | I20: DZ | J20: 46007 | K20: 46007 | L20: G15K40FCKGJH | N20: 212100 | O20: Trade Debtors (Ctrl) | Q20: 15 | R20: INR | S20: -14531.11 | T20: INR | U20: -14531.11 | W20: 6779220000 | Z20: 2 | AE20: 46007 | AF20: 46030 | AG20: 1400002388 | AH20: {=VLOOKUP(M20,'Customer data Vlookup'!$B$3:$H$127,{2,3},0)} -> #N/A | AO20: =VLOOKUP(M20,'Customer data'!F:P,11,0) -> #N/A
A21: Selected | B21: 6779 | C21: 100222397 | D21: BARNET INDIA PRIVATE LIMITED | E21: 2025 | F21: 10 | G21: 46007 | H21: 1400002197 | I21: DZ | J21: 46007 | K21: 46007 | L21: G15K40FCKGJH | N21: 212100 | O21: Trade Debtors (Ctrl) | Q21: 15 | R21: INR | S21: -296024 | T21: INR | U21: -296024 | W21: 6779224500 | Y21: NA | Z21: 3 | AE21: 46007 | AH21: {=VLOOKUP(M21,'Customer data Vlookup'!$B$3:$H$127,{2,3},0)} -> #N/A | AO21: =VLOOKUP(M21,'Customer data'!F:P,11,0) -> #N/A
A22: Selected | B22: 6779 | C22: 100222397 | D22: BARNET INDIA PRIVATE LIMITED | E22: 2025 | F22: 10 | G22: 45999 | H22: 1800015381 | I22: DR | J22: 45999 | K22: 46000 | L22: NA | M22: 256779419830 | N22: 212100 | O22: Trade Debtors (Ctrl) | Q22: 01 | R22: USD | S22: 11.18 | T22: INR | U22: 991.67 | V22: O0 | W22: 6779224500 | Y22: 2140080 | Z22: 1 | AA22: Bond Stamp Paper Chgs Nov 25 | AE22: 45999 | AH22: {=VLOOKUP(M22,'Customer data Vlookup'!$B$3:$H$127,{2,3},0)} -> 991.66757 | AI22: 20 | AJ22: =AH22-AI22 -> 971.66757 | AK22: =U22-AH22 -> 0.0024348 | AL22: =AI22/U22 -> 0.020167999 | AO22: =VLOOKUP(M22,'Customer data'!F:P,11,0) -> HDFCH00806112854
A23: Selected | B23: 6779 | C23: 100222397 | D23: BARNET INDIA PRIVATE LIMITED | E23: 2025 | F23: 10 | G23: 45996 | H23: 1800015349 | I23: DR | J23: 45996 | K23: 46000 | L23: NA | M23: 256779419798 | N23: 212100 | O23: Trade Debtors (Ctrl) | Q23: 01 | R23: USD | S23: 350 | T23: INR | U23: 31045.05 | V23: O0 | W23: 6779224500 | Y23: 2140069 | Z23: 1 | AA23: Transportation In Chgs - 16 - 30 Nov 25 | AE23: 45996 | AH23: {=VLOOKUP(M23,'Customer data Vlookup'!$B$3:$H$127,{2,3},0)} -> 31045.049 | AI23: 621 | AJ23: =AH23-AI23 -> 30424.049 | AK23: =U23-AH23 -> 0.001 | AL23: =AI23/U23 -> 0.020003189 | AO23: =VLOOKUP(M23,'Customer data'!F:P,11,0) -> HDFCH00806112855
A24: Selected | B24: 6779 | C24: 100222397 | D24: BARNET INDIA PRIVATE LIMITED | E24: 2025 | F24: 10 | G24: 45979 | H24: 1400001956 | I24: DZ | J24: 45979 | K24: 45979 | L24: HDFCN52025082733046460 | N24: 212100 | O24: Trade Debtors (Ctrl) | Q24: 15 | R24: INR | S24: -109304.71 | T24: INR | U24: -109304.71 | W24: 6779224500 | Z24: 3 | AA24: HDFCN52025082733046460 | AE24: 45979 | AF24: 45979 | AG24: 1400001956 | AH24: {=VLOOKUP(M24,'Customer data Vlookup'!$B$3:$H$127,{2,3},0)} -> #N/A | AO24: =VLOOKUP(M24,'Customer data'!F:P,11,0) -> #N/A
A25: Selected | B25: 6779 | C25: 100222397 | D25: BARNET INDIA PRIVATE LIMITED | E25: 2025 | F25: 9 | G25: 45979 | H25: 1400001961 | I25: DZ | J25: 45979 | K25: 45979 | L25: HDFCN52025060575568983 | N25: 212100 | O25: Trade Debtors (Ctrl) | Q25: 15 | R25: INR | S25: -8051.51 | T25: INR | U25: -8051.51 | W25: 6779224500 | Z25: 5 | AA25: HDFCN52025060575568983 | AE25: 45979 | AF25: 45979 | AG25: 1400001961 | AH25: {=VLOOKUP(M25,'Customer data Vlookup'!$B$3:$H$127,{2,3},0)} -> #N/A | AO25: =VLOOKUP(M25,'Customer data'!F:P,11,0) -> #N/A
A26: Selected | B26: 6779 | C26: 100222397 | D26: BARNET INDIA PRIVATE LIMITED | E26: 2025 | F26: 11 | G26: 45979 | H26: 1400001961 | I26: DZ | J26: 45979 | K26: 45979 | L26: HDFCN52025060575568983 | N26: 212100 | O26: Trade Debtors (Ctrl) | Q26: 15 | R26: INR | S26: -159132.62 | T26: INR | U26: -159622.78 | W26: 6779224500 | Z26: 4 | AA26: HDFCN52025060575568983 | AE26: 45979 | AF26: 45979 | AG26: 1400001961 | AH26: {=VLOOKUP(M26,'Customer data Vlookup'!$B$3:$H$127,{2,3},0)} -> #N/A | AO26: =VLOOKUP(M26,'Customer data'!F:P,11,0) -> #N/A
A27: Selected | B27: 6779 | C27: 100222397 | D27: BARNET INDIA PRIVATE LIMITED | E27: 2025 | F27: 9 | G27: 45979 | H27: 1400001971 | I27: DZ | J27: 45979 | K27: 45979 | L27: HDFCN52025072369906032 | N27: 212100 | O27: Trade Debtors (Ctrl) | Q27: 15 | R27: INR | S27: -50196.87 | T27: INR | U27: -50734.53 | W27: 6779224500 | Z27: 4 | AA27: HDFCN52025072369906032 | AE27: 45979 | AF27: 45979 | AG27: 1400001971 | AH27: {=VLOOKUP(M27,'Customer data Vlookup'!$B$3:$H$127,{2,3},0)} -> #N/A | AO27: =VLOOKUP(M27,'Customer data'!F:P,11,0) -> #N/A
A28: Not Selected | B28: 6779 | C28: 100222397 | D28: BARNET INDIA PRIVATE LIMITED | E28: 2025 | F28: 7 | G28: 45979 | H28: 1400001972 | I28: DZ | J28: 45979 | K28: 45979 | L28: HDFCN52025072369906032 | N28: 212100 | O28: Trade Debtors (Ctrl) | Q28: 15 | R28: INR | S28: -477139.41 | T28: INR | U28: -477139.41 | W28: 6779224500 | Z28: 3 | AA28: HDFCN52025072369906032 | AE28: 45979 | AF28: 45979 | AG28: 1400001972 | AH28: {=VLOOKUP(M28,'Customer data Vlookup'!$B$3:$H$127,{2,3},0)} -> #N/A | AO28: =VLOOKUP(M28,'Customer data'!F:P,11,0) -> #N/A
A29: Selected | B29: 6779 | C29: 100222397 | D29: BARNET INDIA PRIVATE LIMITED | E29: 2025 | F29: 7 | G29: 45972 | H29: 1400001627 | I29: DZ | J29: 45972 | K29: 45972 | L29: HDFCN52025100308494407 | N29: 212100 | O29: Trade Debtors (Ctrl) | Q29: 15 | R29: INR | S29: -324591.96 | T29: INR | U29: -324591.96 | W29: 6779220000 | Z29: 2 | AE29: 45972 | AH29: {=VLOOKUP(M29,'Customer data Vlookup'!$B$3:$H$127,{2,3},0)} -> #N/A | AO29: =VLOOKUP(M29,'Customer data'!F:P,11,0) -> #N/A
A30: Selected | B30: 6779 | C30: 100222397 | D30: BARNET INDIA PRIVATE LIMITED | E30: 2025 | F30: 10 | G30: 45966 | H30: 1800014545 | I30: DR | J30: 45966 | K30: 45967 | L30: NA | M30: 256779418877 | N30: 212100 | O30: Trade Debtors (Ctrl) | Q30: 01 | R30: USD | S30: 367.84 | T30: INR | U30: 32371.17 | V30: O0 | W30: 6779224500 | Y30: 2123390 | Z30: 1 | AA30: Unit Storage - 1-31 Oct 2025 | AE30: 45966 | AF30: 46007 | AG30: 1400002197 | AH30: {=VLOOKUP(M30,'Customer data Vlookup'!$B$3:$H$127,{2,3},0)} -> 32371.167 | AI30: 3237 | AJ30: =AH30-AI30 -> 29134.167 | AK30: =U30-AH30 -> 0.0030224 | AL30: =AI30/U30 -> 0.099996386 | AO30: =VLOOKUP(M30,'Customer data'!F:P,11,0) -> HDFCH00646925098
A31: Selected | B31: 6779 | C31: 100222397 | D31: BARNET INDIA PRIVATE LIMITED | E31: 2025 | F31: 11 | G31: 45966 | H31: 1800014715 | I31: DR | J31: 45966 | K31: 45968 | L31: 2123630 | M31: 256779419216 | N31: 212100 | O31: Trade Debtors (Ctrl) | Q31: 01 | R31: USD | S31: 27.17 | T31: INR | U31: 2391.05 | V31: O0 | W31: 6779224500 | Y31: NA | Z31: 1 | AA31: PORT SSR Chgs Oct 25 | AE31: 45966 | AF31: 46007 | AG31: 1400002197 | AH31: {=VLOOKUP(M31,'Customer data Vlookup'!$B$3:$H$127,{2,3},0)} -> 2391.0521 | AI31: 48 | AJ31: =AH31-AI31 -> 2343.0521 | AK31: =U31-AH31 -> -0.0021063 | AL31: =AI31/U31 -> 0.020074863 | AO31: =VLOOKUP(M31,'Customer data'!F:P,11,0) -> HDFCH00646925098
A32: Selected | B32: 6779 | C32: 100222397 | D32: BARNET INDIA PRIVATE LIMITED | E32: 2025 | F32: 7 | G32: 45966 | H32: 1800014737 | I32: DR | J32: 45966 | K32: 45968 | L32: NA | M32: 256779419240 | N32: 212100 | O32: Trade Debtors (Ctrl) | Q32: 01 | R32: USD | S32: 11.27 | T32: INR | U32: 991.8 | V32: O0 | W32: 6779224500 | Y32: 2123648 | Z32: 1 | AA32: Bond Stamp Paper Chgs Oct 25 | AE32: 45966 | AF32: 46007 | AG32: 1400002197 | AH32: {=VLOOKUP(M32,'Customer data Vlookup'!$B$3:$H$127,{2,3},0)} -> 991.79821 | AI32: 20 | AJ32: =AH32-AI32 -> 971.79821 | AK32: =U32-AH32 -> 0.0017947 | AL32: =AI32/U32 -> 0.020165356 | AO32: =VLOOKUP(M32,'Customer data'!F:P,11,0) -> HDFCH00646925098
A33: Selected | B33: 6779 | C33: 100222397 | D33: BARNET INDIA PRIVATE LIMITED | E33: 2025 | F33: 10 | G33: 45950 | H33: 1800013820 | I33: DR | J33: 45950 | K33: 45951 | L33: NA | M33: 256779418638 | N33: 212100 | O33: Trade Debtors (Ctrl) | Q33: 01 | R33: USD | S33: 350 | T33: INR | U33: 30866.77 | V33: O0 | W33: 6779224500 | Y33: 2114881 | Z33: 1 | AA33: Transportation In Chgs - 01 - 15 OCT 25 | AE33: 45950 | AF33: 46007 | AG33: 1400002197 | AH33: {=VLOOKUP(M33,'Customer data Vlookup'!$B$3:$H$127,{2,3},0)} -> 30866.769 | AI33: 617 | AJ33: =AH33-AI33 -> 30249.769 | AK33: =U33-AH33 -> 0.0005 | AL33: =AI33/U33 -> 0.019989134 | AO33: =VLOOKUP(M33,'Customer data'!F:P,11,0) -> HDFCH00646925098
A34: Selected | B34: 6779 | C34: 100222397 | D34: BARNET INDIA PRIVATE LIMITED | E34: 2025 | F34: 10 | G34: 45946 | H34: 1400001452 | I34: DZ | J34: 45946 | K34: 45946 | L34: HDFCN52025082227307462 | N34: 212100 | O34: Trade Debtors (Ctrl) | Q34: 15 | R34: INR | S34: -492224.78 | T34: INR | U34: -492209.06 | W34: 6779224500 | Z34: 3 | AA34: HDFCN52025082227307462 | AE34: 45946 | AF34: 45946 | AG34: 1400001452 | AH34: {=VLOOKUP(M34,'Customer data Vlookup'!$B$3:$H$127,{2,3},0)} -> #N/A | AO34: =VLOOKUP(M34,'Customer data'!F:P,11,0) -> #N/A
A35: Selected | B35: 6779 | C35: 100222397 | D35: BARNET INDIA PRIVATE LIMITED | E35: 2025 | F35: 4 | G35: 45946 | H35: 1400001453 | I35: DZ | J35: 45946 | K35: 45946 | L35: HDFCH00465695692 | N35: 212100 | O35: Trade Debtors (Ctrl) | Q35: 08 | R35: INR | S35: 2932.62 | T35: INR | U35: 2932.62 | W35: 6779224500 | Z35: 4 | AA35: HDFCH00465695692 | AE35: 45946 | AF35: 45946 | AG35: 1400001453 | AH35: {=VLOOKUP(M35,'Customer data Vlookup'!$B$3:$H$127,{2,3},0)} -> #N/A | AO35: =VLOOKUP(M35,'Customer data'!F:P,11,0) -> #N/A
A36: Selected | B36: 6779 | C36: 100222397 | D36: BARNET INDIA PRIVATE LIMITED | E36: 2025 | F36: 4 | G36: 45946 | H36: 1400001453 | I36: DZ | J36: 45946 | K36: 45946 | L36: HDFCH00465695692 | N36: 212100 | O36: Trade Debtors (Ctrl) | Q36: 15 | R36: INR | S36: -142188.03 | T36: INR | U36: -139776.58 | W36: 6779224500 | Z36: 5 | AA36: HDFCH00465695692 | AE36: 45946 | AF36: 45946 | AG36: 1400001453 | AH36: {=VLOOKUP(M36,'Customer data Vlookup'!$B$3:$H$127,{2,3},0)} -> #N/A | AO36: =VLOOKUP(M36,'Customer data'!F:P,11,0) -> #N/A
A37: Selected | B37: 6779 | C37: 100222397 | D37: BARNET INDIA PRIVATE LIMITED | E37: 2025 | F37: 4 | G37: 45946 | H37: 1400001452 | I37: DZ | J37: 45946 | K37: 45946 | L37: HDFCN52025082227307462 | N37: 212100 | O37: Trade Debtors (Ctrl) | Q37: 15 | R37: INR | S37: -2932.62 | T37: INR | U37: -2932.62 | W37: 6779224500 | Y37: NA | Z37: 2 | AE37: 45946 | AF37: 45946 | AG37: 1400001453 | AH37: {=VLOOKUP(M37,'Customer data Vlookup'!$B$3:$H$127,{2,3},0)} -> #N/A | AO37: =VLOOKUP(M37,'Customer data'!F:P,11,0) -> #N/A
A38: Selected | B38: 6779 | C38: 100222397 | D38: BARNET INDIA PRIVATE LIMITED | E38: 2025 | F38: 4 | G38: 45946 | H38: 1400001454 | I38: DZ | J38: 45946 | K38: 45946 | L38: HDFCN52025051435275414 | N38: 212100 | O38: Trade Debtors (Ctrl) | Q38: 15 | R38: INR | S38: -115726.32 | T38: INR | U38: -116988.95 | Z38: 4 | AA38: HDFCN52025051435275414 | AE38: 45946 | AF38: 45946 | AG38: 1400001454 | AH38: {=VLOOKUP(M38,'Customer data Vlookup'!$B$3:$H$127,{2,3},0)} -> #N/A | AO38: =VLOOKUP(M38,'Customer data'!F:P,11,0) -> #N/A
A39: Selected | B39: 6779 | C39: 100222397 | D39: BARNET INDIA PRIVATE LIMITED | E39: 2025 | F39: 4 | G39: 45946 | H39: 1400001455 | I39: DZ | J39: 45946 | K39: 45946 | L39: HDFCN52025100205721894 | N39: 212100 | O39: Trade Debtors (Ctrl) | Q39: 15 | R39: INR | S39: -659505.58 | T39: INR | U39: -646935.77 | W39: 6779224500 | Z39: 4 | AA39: HDFCN52025100205721894 | AE39: 45946 | AF39: 45946 | AG39: 1400001455 | AH39: {=VLOOKUP(M39,'Customer data Vlookup'!$B$3:$H$127,{2,3},0)} -> #N/A | AO39: =VLOOKUP(M39,'Customer data'!F:P,11,0) -> #N/A
A40: Selected | B40: 6779 | C40: 100222397 | D40: BARNET INDIA PRIVATE LIMITED | E40: 2025 | F40: 4 | G40: 45946 | H40: 1400001456 | I40: DZ | J40: 45946 | K40: 45946 | L40: HDFCN52025062512710909 | N40: 212100 | O40: Trade Debtors (Ctrl) | Q40: 15 | R40: USD | S40: -2140.03 | T40: INR | U40: -182952.83 | W40: 6779224500 | Z40: 3 | AA40: HDFCN52025062512710909 | AE40: 45946 | AF40: 45946 | AG40: 1400001456 | AH40: {=VLOOKUP(M40,'Customer data Vlookup'!$B$3:$H$127,{2,3},0)} -> #N/A | AO40: =VLOOKUP(M40,'Customer data'!F:P,11,0) -> #N/A
...

Sheet Customer data
A1: Sr.No. | B1: Particulars | C1: Bill Amt in USD | D1: Month- service Received | E1: Date | F1: INV NO | G1: EX.RATE | H1: INVOICE AMT | I1: TDS | J1: TDS AMOUNT | K1: AMT PAYABLE | L1: AMOUNT DEDUCTED | M1: AMOUNT PAID | O1: Date | P1: UTR NO/REMARK | Q1: MONTH-INV Received &BOOKED | R1: REMARK
A2: 1 | B2: Storage Charges 1st Aug to 31st Aug 2024 | C2: 960.64 | D2: August, 2024 | E2: 45698 | F2: 6779IV124000167 | G2: 87.5858 | H2: 84138.423 | I2: 0.1 | J2: =ROUND(H2*I2,0) -> 8414 | K2: =H2-J2 -> 75724.423 | M2: =K2 -> 75724.423 | N2: =SUM(L2:M2) -> 75724.423 | O2: 45861 | P2: HDFCN52025072369906032 | Q2: 45717
A3: 2 | B3: LCL Charges | C3: 132 | D3: August, 2024 | E3: 45698 | F3: 6779IV124000168 | G3: 87.5858 | H3: 11561.326 | I3: 0.02 | J3: =ROUND(H3*I3,0) -> 231 | K3: =H3-J3 -> 11330.326 | M3: 11330.33 | N3: =SUM(L3:M3) -> 11330.33 | O3: 45740 | P3: HDFCN52025032433793860 | Q3: 45717
A4: 3 | B4: Inbound Handling Charges | C4: 472.38 | D4: August, 2024 | E4: 45698 | F4: 6779IV124000169 | G4: 87.5858 | H4: 41373.78 | I4: 0.02 | J4: =ROUND(H4*I4,0) -> 827 | K4: =H4-J4 -> 40546.78 | N4: =SUM(L4:M4) -> 0 | P4: Not Approved | Q4: 45717
A5: 4 | B5: Lolo Charges | C5: 432 | D5: August, 2024 | E5: 45698 | F5: 6779IV124000170 | G5: 87.5858 | H5: 37837.066 | I5: 0.02 | J5: =ROUND(H5*I5,0) -> 757 | K5: =H5-J5 -> 37080.066 | N5: =SUM(L5:M5) -> 0 | P5: Not Approved | Q5: 45717
A6: 5 | B6: Outbound Handling Charges | C6: 472.38 | D6: August, 2024 | E6: 45698 | F6: 6779IV124000171 | G6: 87.5858 | H6: 41373.78 | I6: 0.02 | J6: =ROUND(H6*I6,0) -> 827 | K6: =H6-J6 -> 40546.78 | N6: =SUM(L6:M6) -> 0 | P6: Not Approved | Q6: 45717
A7: 6 | B7: VAS Activity Charges | C7: 125.59113 | D7: August, 2024 | E7: 45698 | F7: 6779IV124000172 | G7: 87.5858 | H7: 11000 | I7: 0.02 | J7: =ROUND(H7*I7,0) -> 220 | K7: =H7-J7 -> 10780 | M7: =K7 -> 10780 | N7: =SUM(L7:M7) -> 10780 | O7: 45822 | P7: HDFCN52025061495304800 | Q7: 45717
A8: 7 | B8: Storage Charges 1st Sep to 30th Sep 2024 | C8: 1495.68 | D8: September, 2024 | E8: 45698 | F8: 6779IV124000173 | G8: 87.5858 | H8: 131000.33 | I8: 0.1 | J8: =ROUND(H8*I8,0) -> 13100 | K8: =H8-J8 -> 117900.33 | M8: =K8 -> 117900.33 | N8: =SUM(L8:M8) -> 117900.33 | O8: 45861 | P8: HDFCN52025072369906032 | Q8: 45717
A9: 8 | B9: LCL Charges | C9: 211.2 | D9: September, 2024 | E9: 45698 | F9: 6779IV124000174 | G9: 87.5858 | H9: 18498.121 | I9: 0.02 | J9: =ROUND(H9*I9,0) -> 370 | K9: =H9-J9 -> 18128.121 | M9: 18128.12 | N9: =SUM(L9:M9) -> 18128.12 | O9: 45740 | P9: HDFCN52025032433793867 | Q9: 45717
A10: 9 | B10: Inbound Handling Charges | C10: 755.808 | D10: September, 2024 | E10: 45698 | F10: 6779IV124000175 | G10: 87.5858 | H10: 66198.048 | I10: 0.02 | J10: =ROUND(H10*I10,0) -> 1324 | K10: =H10-J10 -> 64874.048 | N10: =SUM(L10:M10) -> 0 | P10: Not Approved | Q10: 45717
A11: 10 | B11: Lolo Charges | C11: 475.2 | D11: September, 2024 | E11: 45698 | F11: 6779IV124000176 | G11: 87.5858 | H11: 41620.772 | I11: 0.02 | J11: =ROUND(H11*I11,0) -> 832 | K11: =H11-J11 -> 40788.772 | N11: =SUM(L11:M11) -> 0 | P11: Not Approved | Q11: 45717
A12: 11 | B12: Outbound Handling Charges | C12: 283.428 | D12: September, 2024 | E12: 45698 | F12: 6779IV124000177 | G12: 87.5858 | H12: 24824.268 | I12: 0.02 | J12: =ROUND(H12*I12,0) -> 496 | K12: =H12-J12 -> 24328.268 | N12: =SUM(L12:M12) -> 0 | P12: Not Approved | Q12: 45717
A13: 12 | B13: CY Movement Charges | C13: 81 | D13: September, 2024 | E13: 45698 | F13: 6779IV124000178 | G13: 87.5858 | H13: 7094.4498 | I13: 0.02 | J13: =ROUND(H13*I13,0) -> 142 | K13: =H13-J13 -> 6952.4498 | N13: =SUM(L13:M13) -> 0 | P13: Not Approved | Q13: 45717
A14: 13 | B14: VAS Activity Charges | C14: 150.70936 | D14: September, 2024 | E14: 45698 | F14: 6779IV124000179 | G14: 87.5858 | H14: 13200 | I14: 0.02 | J14: =ROUND(H14*I14,0) -> 264 | K14: =H14-J14 -> 12936 | L14: 6468 | M14: 6468 | N14: =SUM(L14:M14) -> 12936 | O14: 45822 | P14: HDFCN52025061495304800 | Q14: 45717 | R14: CREDIT NOTE AWAITED
A15: 14 | B15: Storage Charges 1st Oct to 31st Oct 2024 | C15: 2991.36 | D15: October, 2024 | E15: 45698 | F15: 6779IV124000180 | G15: 87.5858 | H15: 262000.66 | I15: 0.1 | J15: =ROUND(H15*I15,0) -> 26200 | K15: =H15-J15 -> 235800.66 | M15: =K15 -> 235800.66 | N15: =SUM(L15:M15) -> 235800.66 | O15: 45861 | P15: HDFCN52025072369906032 | Q15: 45717
A16: 15 | B16: LCL Charges | C16: 211.2 | D16: October, 2024 | E16: 45698 | F16: 6779IV124000181 | G16: 87.5858 | H16: 18498.121 | I16: 0.02 | J16: =ROUND(H16*I16,0) -> 370 | K16: =H16-J16 -> 18128.121 | M16: 18128.12 | N16: =SUM(L16:M16) -> 18128.12 | O16: 45740 | P16: HDFCN52025032433793886 | Q16: 45717
A17: 16 | B17: Inbound Handling Charges | C17: 755.808 | D17: October, 2024 | E17: 45698 | F17: 6779IV124000182 | G17: 87.5858 | H17: 66198.048 | I17: 0.02 | J17: =ROUND(H17*I17,0) -> 1324 | K17: =H17-J17 -> 64874.048 | N17: =SUM(L17:M17) -> 0 | P17: Not Approved | Q17: 45717
A18: 17 | B18: Lolo Charges | C18: 691.2 | D18: October, 2024 | E18: 45698 | F18: 6779IV124000183 | G18: 87.5858 | H18: 60539.305 | I18: 0.02 | J18: =ROUND(H18*I18,0) -> 1211 | K18: =H18-J18 -> 59328.305 | N18: =SUM(L18:M18) -> 0 | P18: Not Approved | Q18: 45717
A19: 18 | B19: CY Movement Charges | C19: 216 | D19: October, 2024 | E19: 45698 | F19: 6779IV124000184 | G19: 87.5858 | H19: 18918.533 | I19: 0.02 | J19: =ROUND(H19*I19,0) -> 378 | K19: =H19-J19 -> 18540.533 | N19: =SUM(L19:M19) -> 0 | P19: Not Approved | Q19: 45717
A20: 19 | B20: Outbound Handling Charges | C20: 755.808 | D20: October, 2024 | E20: 45698 | F20: 6779IV124000185 | G20: 87.5858 | H20: 66198.048 | I20: 0.02 | J20: =ROUND(H20*I20,0) -> 1324 | K20: =H20-J20 -> 64874.048 | N20: =SUM(L20:M20) -> 0 | P20: Not Approved | Q20: 45717
A21: 20 | B21: Storage Charges 1st Nov to 30th Nov 2024 | C21: 887.68 | D21: November, 2024 | E21: 45698 | F21: 6779IV124000186 | G21: 87.5858 | H21: 77748.163 | I21: 0.1 | J21: =ROUND(H21*I21,0) -> 7775 | K21: =H21-J21 -> 69973.163 | M21: 69973.16 | N21: =SUM(L21:M21) -> 69973.16 | O21: 45728 | P21: HDFCN52025031215974606 | Q21: 45717
A22: 21 | B22: CY Movement Charges | C22: 162 | D22: November, 2024 | E22: 45698 | F22: 6779IV124000187 | G22: 87.5858 | H22: 14188.9 | I22: 0.02 | J22: =ROUND(H22*I22,0) -> 284 | K22: =H22-J22 -> 13904.9 | N22: =SUM(L22:M22) -> 0 | P22: Not Approved | Q22: 45717
A23: 22 | B23: Outbound Handling Charges | C23: 566.856 | D23: November, 2024 | E23: 45698 | F23: 6779IV124000188 | G23: 87.5858 | H23: 49648.536 | I23: 0.02 | J23: =ROUND(H23*I23,0) -> 993 | K23: =H23-J23 -> 48655.536 | N23: =SUM(L23:M23) -> 0 | P23: Not Approved | Q23: 45717
A24: 23 | B24: Lolo Charges | C24: 259.2 | D24: November, 2024 | E24: 45698 | F24: 6779IV124000189 | G24: 87.5858 | H24: 22702.239 | I24: 0.02 | J24: =ROUND(H24*I24,0) -> 454 | K24: =H24-J24 -> 22248.239 | N24: =SUM(L24:M24) -> 0 | P24: Not Approved | Q24: 45717
A25: 24 | B25: Storage Charges 1st Dec to 31st Dec 2024 | C25: 364.8 | D25: December, 2024 | E25: 45698 | F25: 6779IV124000190 | G25: 87.5858 | H25: 31951.3 | I25: 0.1 | J25: =ROUND(H25*I25,0) -> 3195 | K25: =H25-J25 -> 28756.3 | M25: 28756.3 | N25: =SUM(L25:M25) -> 28756.3 | O25: 45728 | P25: HDFCN52025031215976413 | Q25: 45717
A26: 25 | B26: LCL Charges | C26: 52.8 | D26: December, 2024 | E26: 45698 | F26: 6779IV124000191 | G26: 87.5858 | H26: 4624.5302 | I26: 0.02 | J26: =ROUND(H26*I26,0) -> 92 | K26: =H26-J26 -> 4532.5302 | M26: 4532.53 | N26: =SUM(L26:M26) -> 4532.53 | O26: 45740 | P26: HDFCN52025032433793875 | Q26: 45717
A27: 26 | B27: Inbound Handling Charges | C27: 188.952 | D27: December, 2024 | E27: 45698 | F27: 6779IV124000192 | G27: 87.5858 | H27: 16549.512 | I27: 0.02 | J27: =ROUND(H27*I27,0) -> 331 | K27: =H27-J27 -> 16218.512 | N27: =SUM(L27:M27) -> 0 | P27: Not Approved | Q27: 45717
A28: 27 | B28: Lolo Charges | C28: 172.8 | D28: December, 2024 | E28: 45698 | F28: 6779IV124000193 | G28: 87.5858 | H28: 15134.826 | I28: 0.02 | J28: =ROUND(H28*I28,0) -> 303 | K28: =H28-J28 -> 14831.826 | N28: =SUM(L28:M28) -> 0 | P28: Not Approved | Q28: 45717
A29: 28 | B29: CY Movement Charges | C29: 54 | D29: December, 2024 | E29: 45698 | F29: 6779IV124000194 | G29: 87.5858 | H29: 4729.6332 | I29: 0.02 | J29: =ROUND(H29*I29,0) -> 95 | K29: =H29-J29 -> 4634.6332 | N29: =SUM(L29:M29) -> 0 | P29: Not Approved | Q29: 45717
A30: 29 | B30: Outbound Handling Charges | C30: 188.952 | D30: December, 2024 | E30: 45698 | F30: 6779IV124000195 | G30: 87.5858 | H30: 16549.512 | I30: 0.02 | J30: =ROUND(H30*I30,0) -> 331 | K30: =H30-J30 -> 16218.512 | N30: =SUM(L30:M30) -> 0 | P30: Not Approved | Q30: 45717
A31: 30 | B31: Storage Charges 1st Jan to 31st Jan 2025 | C31: 1231.96 | D31: January, 2025 | E31: 45698 | F31: 6779IV124000196 | G31: 87.5858 | H31: 107902.2 | I31: 0.1 | J31: =ROUND(H31*I31,0) -> 10790 | K31: =H31-J31 -> 97112.202 | M31: 97112.2 | N31: =SUM(L31:M31) -> 97112.2 | O31: 45728 | P31: HDFCN52025031215974609 | Q31: 45717
A32: 31 | B32: Transportation Inbound | C32: 180 | D32: January, 2025 | E32: 45698 | F32: 6779IV124000197 | G32: 87.5858 | H32: 15765.444 | I32: 0.02 | J32: =ROUND(H32*I32,0) -> 315 | K32: =H32-J32 -> 15450.444 | M32: 15450.44 | N32: =SUM(L32:M32) -> 15450.44 | O32: 45740 | P32: HDFCN52025032433791996 | Q32: 45717
A33: 32 | B33: CY Destuff Charges | C33: 27 | D33: January, 2025 | E33: 45698 | F33: 6779IV124000198 | G33: 87.5858 | H33: 2364.8166 | I33: 0.02 | J33: =ROUND(H33*I33,0) -> 47 | K33: =H33-J33 -> 2317.8166 | N33: =SUM(L33:M33) -> 0 | P33: Not Approved | Q33: 45717
A34: 33 | B34: Empty Movement Charges | C34: 180 | D34: January, 2025 | E34: 45698 | F34: 6779IV124000199 | G34: 87.5858 | H34: 15765.444 | I34: 0.02 | J34: =ROUND(H34*I34,0) -> 315 | K34: =H34-J34 -> 15450.444 | N34: =SUM(L34:M34) -> 0 | P34: Not Approved | Q34: 45717
A35: 34 | B35: LCL Charges | C35: 52.8 | D35: January, 2025 | E35: 45698 | F35: 6779IV124000200 | G35: 87.5858 | H35: 4624.5302 | I35: 0.02 | J35: =ROUND(H35*I35,0) -> 92 | K35: =H35-J35 -> 4532.5302 | M35: 4532.53 | N35: =SUM(L35:M35) -> 4532.53 | O35: 45740 | P35: HDFCN52025032433791993 | Q35: 45717
A36: 35 | B36: Inbound Handling Charges | C36: 252.932 | D36: January, 2025 | E36: 45698 | F36: 6779IV124000201 | G36: 87.5858 | H36: 22153.252 | I36: 0.02 | J36: =ROUND(H36*I36,0) -> 443 | K36: =H36-J36 -> 21710.252 | N36: =SUM(L36:M36) -> 0 | P36: Not Approved | Q36: 45717
A37: 36 | B37: Loose Unloading Charges | C37: 31.99 | D37: January, 2025 | E37: 45698 | F37: 6779IV124000202 | G37: 87.5858 | H37: 2801.8697 | I37: 0.02 | J37: =ROUND(H37*I37,0) -> 56 | K37: =H37-J37 -> 2745.8697 | N37: =SUM(L37:M37) -> 0 | P37: Not Approved | Q37: 45717
A38: 37 | B38: Lolo Charges | C38: 129.6 | D38: January, 2025 | E38: 45698 | F38: 6779IV124000203 | G38: 87.5858 | H38: 11351.12 | I38: 0.02 | J38: =ROUND(H38*I38,0) -> 227 | K38: =H38-J38 -> 11124.12 | N38: =SUM(L38:M38) -> 0 | P38: Not Approved | Q38: 45717
A39: 38 | B39: Outbound Handling Charges | C39: 63.98 | D39: January, 2025 | E39: 45698 | F39: 6779IV124000204 | G39: 87.5858 | H39: 5603.7395 | I39: 0.02 | J39: =ROUND(H39*I39,0) -> 112 | K39: =H39-J39 -> 5491.7395 | N39: =SUM(L39:M39) -> 0 | P39: Not Approved | Q39: 45717
A40: 39 | B40: Loose Loading Charges | C40: 31.99 | D40: January, 2025 | E40: 45698 | F40: 6779IV124000205 | G40: 87.5858 | H40: 2801.8697 | I40: 0.02 | J40: =ROUND(H40*I40,0) -> 56 | K40: =H40-J40 -> 2745.8697 | N40: =SUM(L40:M40) -> 0 | P40: Not Approved | Q40: 45717
...

Sheet Paym Updated
A1: Document Number | B1: Document Type | C1: Document Date | D1: Document Header Text | E1: Company Code Currency Key | F1: Company Code Currency Value | G1: Text | H1: Clearing Documents | J1: Clearing Documents | K1: Document Header Text | L1: Sum of Company Code Currency Value
A2: 1400000007 | B2: DZ | C2: 45772 | D2: HDFCN52025031215974606 | E2: INR | F2: -77748.16 | G2: HDFCN52025031215974606 | H2: 1400000007 | J2: 1400000007 | K2: HDFCN52025031215974606 | L2: -77748.16
A3: 1400000008 | B3: DZ | C3: 45772 | D3: HDFCN52025031215976413 | E3: INR | F3: -31951.3 | G3: HDFCN52025031215976413 | H3: 1400000008 | J3: 1400000008 | K3: HDFCN52025031215976413 | L3: -31951.3
A4: 1400000009 | B4: DZ | C4: 45772 | D4: HDFCN52025031215974609 | E4: INR | F4: -107902.2 | G4: HDFCN52025031215974609 | H4: 1400000009 | J4: 1400000009 | K4: HDFCN52025031215974609 | L4: -107902.2
A5: 1400000010 | B5: DZ | C5: 45772 | D5: HDFCN52025032433793860 | E5: INR | F5: -11561.33 | G5: HDFCN52025032433793860 | H5: 1400000010 | J5: 1400000010 | K5: HDFCN52025032433793860 | L5: -11561.33
A6: 1400000011 | B6: DZ | C6: 45772 | D6: HDFCN52025032433793867 | E6: INR | F6: -18498.12 | G6: HDFCN52025032433793867 | H6: 1400000011 | J6: 1400000011 | K6: HDFCN52025032433793867 | L6: -18498.12
A7: 1400000012 | B7: DZ | C7: 45772 | D7: HDFCN52025032433793886 | E7: INR | F7: -18498.12 | G7: HDFCN52025032433793886 | H7: 1400000012 | J7: 1400000012 | K7: HDFCN52025032433793886 | L7: -18498.12
A8: 1400000013 | B8: DZ | C8: 45772 | D8: HDFCN52025032433793875 | E8: INR | F8: -4624.53 | G8: HDFCN52025032433793875 | H8: 1400000013 | J8: 1400000013 | K8: HDFCN52025032433793875 | L8: -4624.53
A9: 1400000014 | B9: DZ | C9: 45772 | D9: HDFCN52025032433791996 | E9: INR | F9: -15765.44 | G9: HDFCN52025032433791996 | H9: 1400000014 | J9: 1400000014 | K9: HDFCN52025032433791996 | L9: -15765.44
A10: 1400000015 | B10: DZ | C10: 45772 | D10: HDFCN52025032433791993 | E10: INR | F10: -4624.53 | G10: HDFCN52025032433791993 | H10: 1400000015 | J10: 1400000015 | K10: HDFCN52025032433791993 | L10: -4624.53
A11: 1400001449 | B11: DZ | C11: 45912 | D11: HDFCN52025090553870975 | E11: INR | F11: 124189.23 | H11: 1400001449 | J11: 1400001449 | K11: HDFCN52025090553870975 | L11: 0
A12: 1400001173 | B12: DZ | C12: 45912 | D12: HDFCN52025090553870975 | E12: INR | F12: -124189.23 | H12: 1400001449 | J12: 1400001450 | L12: 0
A13: 1400001450 | B13: DZ | C13: 45908 | E13: INR | F13: 495157.4 | H13: 1400001450 | J13: 1400001451 | K13: HDFCN52025051435275414 | L13: 0
A14: 1400001142 | B14: DZ | C14: 45908 | E14: INR | F14: -495157.4 | H14: 1400001450 | J14: 1400001452 | K14: HDFCN52025082227307462 | L14: -492209.06
A15: 1400000063 | B15: DZ | C15: 45832 | D15: HDFCN52025051435275414 | E15: INR | F15: -112111.95 | H15: 1400001451 | J15: 1400001453 | K15: HDFCN52025082227307462 | L15: -2932.62
A16: 1400001451 | B16: DZ | C16: 45832 | D16: HDFCN52025051435275414 | E16: INR | F16: 112111.95 | H16: 1400001451 | K16: HDFCH00465695692 | L16: -136843.96
A17: 1400001452 | B17: DZ | C17: 45946 | D17: HDFCN52025082227307462 | E17: INR | F17: -492209.06 | G17: HDFCN52025082227307462 | H17: 1400001452 | J17: 1400001454 | K17: HDFCN52025051435275414 | L17: -116988.95
A18: 1400001453 | B18: DZ | C18: 45946 | D18: HDFCH00465695692 | E18: INR | F18: 2932.62 | G18: HDFCH00465695692 | H18: 1400001453 | J18: 1400001455 | K18: HDFCN52025100205721894 | L18: -646935.77
A19: 1400001453 | B19: DZ | C19: 45946 | D19: HDFCH00465695692 | E19: INR | F19: -139776.58 | G19: HDFCH00465695692 | H19: 1400001453 | J19: 1400001456 | K19: HDFCN52025062512710909 | L19: -182952.83
A20: 1400001452 | B20: DZ | C20: 45946 | D20: HDFCN52025082227307462 | E20: INR | F20: -2932.62 | H20: 1400001453 | J20: 1400001458 | K20: CT68PKL3P93Q | L20: 0
A21: 1400001454 | B21: DZ | C21: 45946 | D21: HDFCN52025051435275414 | E21: INR | F21: -116988.95 | G21: HDFCN52025051435275414 | H21: 1400001454 | J21: 1400001468 | K21: HDFCN52025100205721894 | L21: 0
A22: 1400001455 | B22: DZ | C22: 45946 | D22: HDFCN52025100205721894 | E22: INR | F22: -646935.77 | G22: HDFCN52025100205721894 | H22: 1400001455 | J22: 1400001956 | K22: HDFCN52025082733046460 | L22: -109304.71
A23: 1400001456 | B23: DZ | C23: 45946 | D23: HDFCN52025062512710909 | E23: INR | F23: -182952.83 | G23: HDFCN52025062512710909 | H23: 1400001456 | J23: 1400001961 | K23: HDFCN52025060575568983 | L23: -167674.29
A24: 1400001458 | B24: DZ | C24: 45890 | D24: CT68PKL3P93Q | E24: INR | F24: 179293.83 | H24: 1400001458 | J24: 1400001971 | K24: HDFCN52025072369906032 | L24: -50734.53
A25: 1400000898 | B25: DZ | C25: 45890 | D25: CT68PKL3P93Q | E25: INR | F25: -179293.83 | H25: 1400001458 | J25: 1400001972 | K25: HDFCN52025072369906032 | L25: -477139.41
A26: 1400001468 | B26: DZ | C26: 45938 | D26: HDFCN52025100205721894 | E26: INR | F26: 339060.54 | H26: 1400001468 | J26: 1400001988 | K26: HDFCN52025082733046460 | L26: 0
A27: 1400001367 | B27: DZ | C27: 45938 | D27: HDFCN52025100205721894 | E27: INR | F27: -339060.54 | H27: 1400001468 | J27: 1400001989 | K27: D2WMGTC7VB6Y | L27: 0
A28: 1400001956 | B28: DZ | C28: 45979 | D28: HDFCN52025082733046460 | E28: INR | F28: -109304.71 | G28: HDFCN52025082733046460 | H28: 1400001956 | J28: 1400001993 | K28: HDFCN52025060575568983 | L28: 0
A29: 1400001961 | B29: DZ | C29: 45979 | D29: HDFCN52025060575568983 | E29: INR | F29: -8051.51 | G29: HDFCN52025060575568983 | H29: 1400001961 | J29: 1400002197 | K29: G15K40FCKGJH | L29: -97487.56
A30: 1400001961 | B30: DZ | C30: 45979 | D30: HDFCN52025060575568983 | E30: INR | F30: -159622.78 | G30: HDFCN52025060575568983 | H30: 1400001961 | J30: 1400002388 | K30: G15K40FCKGJH | L30: 0
A31: 1400001971 | B31: DZ | C31: 45979 | D31: HDFCN52025072369906032 | E31: INR | F31: -50734.53 | G31: HDFCN52025072369906032 | H31: 1400001971 | J31: 1400002389 | K31: G90RGJ9HVGZQ | L31: -16156.51
A32: 1400001972 | B32: DZ | C32: 45979 | D32: HDFCN52025072369906032 | E32: INR | F32: -477139.41 | G32: HDFCN52025072369906032 | H32: 1400001972 | K32: G15K40FCKGJH | L32: -14531.11
A33: 1400001988 | B33: DZ | C33: 45908 | D33: HDFCN52025082733046460 | E33: INR | F33: 107117.71 | H33: 1400001988 | K33: HDFCN52025100308494407 | L33: -324591.96
A34: 1400001145 | B34: DZ | C34: 45908 | D34: HDFCN52025082733046460 | E34: INR | F34: -107117.71 | H34: 1400001988 | K34: HDFCN52025061495304800 | L34: -226409
A35: 1400001989 | B35: DZ | C35: 45890 | D35: D2WMGTC7VB6Y | E35: INR | F35: 475086.94 | H35: 1400001989 | K35: HDFCN52025060575565670 | L35: -341000
A36: 1400000962 | B36: DZ | C36: 45890 | D36: D2WMGTC7VB6Y | E36: INR | F36: -475086.94 | H36: 1400001989 | K36: H3YKFZWVB0GN | L36: -30424.05
A37: 1400001993 | B37: DZ | C37: 45832 | D37: HDFCN52025060575568983 | E37: INR | F37: 159186.29 | H37: 1400001993 | K37: H2PMXC728CY0 | L37: -971.67
A38: 1400000115 | B38: DZ | C38: 45832 | D38: HDFCN52025060575568983 | E38: INR | F38: -159186.29 | H38: 1400001993 | K38: G15K40FCKGJH | L38: -296024
A39: 1400002197 | B39: DZ | C39: 46007 | D39: G15K40FCKGJH | E39: INR | F39: -66620.79 | G39: G15K40FCKGJH | H39: 1400002197
A40: 1400002197 | B40: DZ | C40: 46007 | D40: G15K40FCKGJH | E40: INR | F40: -30866.77 | G40: G15K40FCKGJH | H40: 1400002197
...

Sheet Payment Reco
B1: =SUBTOTAL(9,B4:B93) -> 3557557.5 | D1: =B1+G1 -> -464928.21 | G1: =SUBTOTAL(9,G4:G55) -> -4022485.7 | M1: =SUM(M4:M31) -> 3557557.1
A2: As per Customer | E2: As per Ascendus Ledger | J2: As per Ascendus Bank Details
A3: Date | B3: AMOUNT PAID | C3: UTR NO/REMARK | E3: Document Type | F3: Document Date | G3: Company Code Currency Value | H3: Text | J3: Payment Date | K3: Customer Name | L3: Currency | M3: Recd Amount | N3: Bank Reference
A4: 45728 | B4: 69973.16 | C4: HDFCN52025031215974606 | E4: DZ | F4: 45772 | G4: -77748.16 | H4: HDFCN52025031215974606 | J4: 45728 | K4: BARNET INDIA PRIVATE LIMITED | L4: INR | M4: 97112.2 | N4: HDFCN52025031215974609
A5: 45728 | B5: 28756.3 | C5: HDFCN52025031215976413 | E5: DZ | F5: 45772 | G5: -31951.3 | H5: HDFCN52025031215976413 | J5: 45728 | K5: BARNET INDIA PRIVATE LIMITED | L5: INR | M5: 28756.3 | N5: HDFCN52025031215976413
A6: 45728 | B6: 97112.2 | C6: HDFCN52025031215974609 | E6: DZ | F6: 45772 | G6: -107902.2 | H6: HDFCN52025031215974609 | J6: 45728 | K6: BARNET INDIA PRIVATE LIMITED | L6: INR | M6: 69973.16 | N6: HDFCN52025031215974606
A7: 45740 | B7: 11330.33 | C7: HDFCN52025032433793860 | E7: DZ | F7: 45772 | G7: -11561.33 | H7: HDFCN52025032433793860 | J7: 45740 | K7: BARNET INDIA PRIVATE LIMITED | L7: INR | M7: 18128.12 | N7: HDFCN52025032433793867
A8: 45740 | B8: 18128.12 | C8: HDFCN52025032433793867 | E8: DZ | F8: 45772 | G8: -18498.12 | H8: HDFCN52025032433793867 | J8: 45740 | K8: BARNET INDIA PRIVATE LIMITED | L8: INR | M8: 15450.44 | N8: HDFCN52025032433791996
A9: 45740 | B9: 18128.12 | C9: HDFCN52025032433793886 | E9: DZ | F9: 45772 | G9: -18498.12 | H9: HDFCN52025032433793886 | J9: 45740 | K9: BARNET INDIA PRIVATE LIMITED | L9: INR | M9: 11330.33 | N9: HDFCN52025032433793860
A10: 45740 | B10: 4532.53 | C10: HDFCN52025032433793875 | E10: DZ | F10: 45772 | G10: -4624.53 | H10: HDFCN52025032433793875 | J10: 45740 | K10: BARNET INDIA PRIVATE LIMITED | L10: INR | M10: 4532.53 | N10: HDFCN52025032433791993
A11: 45740 | B11: 15450.44 | C11: HDFCN52025032433791996 | E11: DZ | F11: 45772 | G11: -15765.44 | H11: HDFCN52025032433791996 | J11: 45740 | K11: BARNET INDIA PRIVATE LIMITED | L11: INR | M11: 18128.12 | N11: HDFCN52025032433793886
A12: 45740 | B12: 4532.53 | C12: HDFCN52025032433791993 | E12: DZ | F12: 45772 | G12: -4624.53 | H12: HDFCN52025032433791993 | J12: 45740 | K12: BARNET INDIA PRIVATE LIMITED | L12: INR | M12: 4532.53 | N12: HDFCN52025032433793875
A13: 45791 | B13: 28538.08 | C13: HDFCN52025051435275414 | E13: DZ | F13: 45832 | G13: -341000 | J13: 45813 | K13: BARNET INDIA PRIVATE LIMITED | L13: INR | M13: 341000 | N13: HDFCN52025060575565670
A14: 45791 | B14: 24143.251 | C14: HDFCN52025051435275414 | E14: DZ | F14: 45931 | G14: -226409 | J14: 45822 | K14: BARNET INDIA PRIVATE LIMITED | L14: INR | M14: 226409 | N14: HDFCN52025061495304800
A15: 45791 | B15: 6746.2081 | C15: HDFCN52025051435275414 | E15: DZ | F15: 45946 | G15: -492209.06 | H15: HDFCN52025082227307462 | J15: 45791 | K15: BARNET INDIA PRIVATE LIMITED | L15: INR | M15: 112111.95 | N15: HDFCN52025051435275414
A16: 45791 | B16: 11040.068 | C16: HDFCN52025051435275414 | E16: DZ | F16: 45946 | G16: -139776.58 | H16: HDFCH00465695692
A17: 45791 | B17: 24143.251 | C17: HDFCN52025051435275414 | E17: DZ | F17: 45946 | G17: -116988.95 | H17: HDFCN52025051435275414 | J17: 45813 | K17: BARNET INDIA PRIVATE LIMITED | L17: INR | M17: 159186.29 | N17: HDFCN52025060575568983
