Workbook

Sheet Sheet4

Sheet Invoice & CN Not in Customer
A1: Document Number | B1: Document Type | C1: Document Date | D1: Reference | E1: Document Currency Key | F1: Document Currency Value | G1: Company Code Currency Key | H1: Company Code Currency Value | I1: Text
A2: 1800005707 | B2: DR | C2: 45751 | D2: 256779410599 | E2: USD | F2: 2.55 | G2: INR | H2: 221.65 | I2: Storage charges for Jan 2025
A3: 1800002328 | B3: DR | C3: 45733 | D3: 246779411993 | E3: USD | F3: 18.69 | G3: INR | H3: 1620.26 | I3: VAS Activity Charges for the month of December, 24
A4: 1800002329 | B4: DR | C4: 45733 | D4: 246779411994 | E4: USD | F4: 18.69 | G4: INR | H4: 1620.26 | I4: VAS Activity Charges for the month of December, 24
A5: 1800002330 | B5: DR | C5: 45733 | D5: 246779411995 | E5: USD | F5: 18.69 | G5: INR | H5: 1620.26 | I5: VAS Activity Charges for the month of December, 24
A6: 1800002331 | B6: DR | C6: 45733 | D6: 246779411996 | E6: USD | F6: 18.69 | G6: INR | H6: 1620.26 | I6: VAS Activity Charges for the month of December, 24
A7: 1800006091 | B7: DR | C7: 45762 | D7: 256779410982 | E7: USD | F7: 31.27 | G7: INR | H7: 2718.05 | I7: LCL Charges August 2024
A8: 1800006938 | B8: DR | C8: 45763 | D8: 256779411829 | E8: USD | F8: 2.95 | G8: INR | H8: 256.42 | I8: Outbound Handling charges for Dec 2024
A9: 1800004208 | B9: DR | C9: 45736 | D9: 246779414076 | E9: USD | F9: 4.87 | G9: INR | H9: 422.19 | I9: Inbound Handling charges for Sep 2024
A10: 1800004209 | B10: DR | C10: 45736 | D10: 246779414077 | E10: USD | F10: 28.32 | G10: INR | H10: 2455.1 | I10: LCL charges for Sep 2024
A11: 1800004471 | B11: DR | C11: 45736 | D11: 246779414339 | E11: USD | F11: 7.43 | G11: INR | H11: 644.12 | I11: Inbound Handling charges for Nov 2024
A12: 1800004472 | B12: DR | C12: 45736 | D12: 246779414340 | E12: USD | F12: 28.32 | G12: INR | H12: 2455.1 | I12: LCL Movement Charges for Nov 2024
A13: 1800004305 | B13: DR | C13: 45736 | D13: 246779414173 | E13: USD | F13: 2.95 | G13: INR | H13: 255.74 | I13: Outbound Handling charges for Sep 2024
... A101: 1600002237 | B101: DG | C101: 45919 | D101: 256779421792 | E101: USD | F101: -26.77 | G101: INR | H101: -2342.76 | I101: Credit note against -246779413885
F102: =SUM(F2:F101) -> 346.05

Sheet Ascendus Data
A1: Document Number | B1: Document Type | C1: Document Date | D1: Document Header Text | E1: Reference | F1: Document Currency Key | G1: Document Currency Value | H1: Company Code Currency Key | I1: Company Code Currency Value | J1: Xlookup | L1: TDS | M1: Text | N1: Clearing Document
A2: 1400000032 | B2: DZ | C2: 45811 | D2: 2.0250327e+15 | F2: USD | G2: -33.82 | H2: INR | I2: -2939.7 | J2: =_xlfn.XLOOKUP(E2,'Customer Data'!$A:$A,'Customer Data'!$C:$C,,0) -> #N/A | M2: 2025032700149723 | N2: 1400000032
A3: 1400000032 | B3: DZ | C3: 45811 | D3: 2.0250327e+15 | F3: USD | G3: -194.93 | H3: INR | I3: -16904.64 | J3: =_xlfn.XLOOKUP(E3,'Customer Data'!$A:$A,'Customer Data'!$C:$C,,0) -> #N/A | M3: 2025032700149723 | N3: 1400000032
A4: 1800005707 | B4: DR | C4: 45751 | D4: NA | E4: 256779410599 | F4: USD | G4: 2.55 | H4: INR | I4: 221.65 | J4: =_xlfn.XLOOKUP(E4,'Customer Data'!$A:$A,'Customer Data'!$C:$C,,0) -> #N/A | M4: Storage charges for Jan 2025 | N4: 1400000032
A5: 1800002328 | B5: DR | C5: 45733 | D5: NA | E5: 246779411993 | F5: USD | G5: 18.69 | H5: INR | I5: 1620.26 | J5: =_xlfn.XLOOKUP(E5,'Customer Data'!$A:$A,'Customer Data'!$C:$C,,0) -> #N/A | M5: VAS Activity Charges for the month of December, 24 | N5: 1400000032
A6: 1800002329 | B6: DR | C6: 45733 | D6: NA | E6: 246779411994 | F6: USD | G6: 18.69 | H6: INR | I6: 1620.26 | J6: =_xlfn.XLOOKUP(E6,'Customer Data'!$A:$A,'Customer Data'!$C:$C,,0) -> #N/A | M6: VAS Activity Charges for the month of December, 24 | N6: 1400000032
A7: 1800002330 | B7: DR | C7: 45733 | D7: NA | E7: 246779411995 | F7: USD | G7: 18.69 | H7: INR | I7: 1620.26 | J7: =_xlfn.XLOOKUP(E7,'Customer Data'!$A:$A,'Customer Data'!$C:$C,,0) -> #N/A | M7: VAS Activity Charges for the month of December, 24 | N7: 1400000032
A8: 1800002331 | B8: DR | C8: 45733 | D8: NA | E8: 246779411996 | F8: USD | G8: 18.69 | H8: INR | I8: 1620.26 | J8: =_xlfn.XLOOKUP(E8,'Customer Data'!$A:$A,'Customer Data'!$C:$C,,0) -> #N/A | M8: VAS Activity Charges for the month of December, 24 | N8: 1400000032
A9: 1800006091 | B9: DR | C9: 45762 | D9: NA | E9: 256779410982 | F9: USD | G9: 31.27 | H9: INR | I9: 2718.05 | J9: =_xlfn.XLOOKUP(E9,'Customer Data'!$A:$A,'Customer Data'!$C:$C,,0) -> #N/A | M9: LCL Charges August 2024 | N9: 1400000032
A10: 1800006938 | B10: DR | C10: 45763 | D10: NA | E10: 256779411829 | F10: USD | G10: 2.95 | H10: INR | I10: 256.42 | J10: =_xlfn.XLOOKUP(E10,'Customer Data'!$A:$A,'Customer Data'!$C:$C,,0) -> #N/A | M10: Outbound Handling charges for Dec 2024 | N10: 1400000032
A11: 1800004208 | B11: DR | C11: 45736 | D11: NA | E11: 246779414076 | F11: USD | G11: 4.87 | H11: INR | I11: 422.19 | J11: =_xlfn.XLOOKUP(E11,'Customer Data'!$A:$A,'Customer Data'!$C:$C,,0) -> #N/A | M11: Inbound Handling charges for Sep 2024 | N11: 1400000032
A12: 1800004209 | B12: DR | C12: 45736 | D12: NA | E12: 246779414077 | F12: USD | G12: 28.32 | H12: INR | I12: 2455.1 | J12: =_xlfn.XLOOKUP(E12,'Customer Data'!$A:$A,'Customer Data'!$C:$C,,0) -> #N/A | M12: LCL charges for Sep 2024 | N12: 1400000032
A13: 1800004471 | B13: DR | C13: 45736 | D13: NA | E13: 246779414339 | F13: USD | G13: 7.43 | H13: INR | I13: 644.12 | J13: =_xlfn.XLOOKUP(E13,'Customer Data'!$A:$A,'Customer Data'!$C:$C,,0) -> #N/A | M13: Inbound Handling charges for Nov 2024 | N13: 1400000032
A14: 1800004472 | B14: DR | C14: 45736 | D14: NA | E14: 246779414340 | F14: USD | G14: 28.32 | H14: INR | I14: 2455.1 | J14: =_xlfn.XLOOKUP(E14,'Customer Data'!$A:$A,'Customer Data'!$C:$C,,0) -> #N/A | M14: LCL Movement Charges for Nov 2024 | N14: 1400000032
A15: 1800004305 | B15: DR | C15: 45736 | D15: NA | E15: 246779414173 | F15: USD | G15: 2.95 | H15: INR | I15: 255.74 | J15: =_xlfn.XLOOKUP(E15,'Customer Data'!$A:$A,'Customer Data'!$C:$C,,0) -> #N/A | M15: Outbound Handling charges for Sep 2024 | N15: 1400000032
... A21: 1800002538 | B21: DR | C21: 45734 | D21: NA | E21: 246779412405 | F21: USD | G21: 9.56 | H21: INR | I21: 828.77 | J21: =_xlfn.XLOOKUP(E21,'Customer Data'!$A:$A,'Customer Data'!$C:$C,,0) -> #N/A | M21: Storage charges for Sept 2024 | N21: 1400000032
A22: 1400000503 | B22: DZ | C22: 45861 | D22: NA | F22: USD | G22: 0 | H22: INR | I22: 0 | J22: =_xlfn.XLOOKUP(E22,'Customer Data'!$A:$A,'Customer Data'!$C:$C,,0) -> #N/A | N22: 1400000503
A23: 1800001491 | B23: DR | C23: 45730 | D23: NA | E23: 246779412148 | F23: USD | G23: 11.92 | H23: INR | I23: 1033.36 | J23: =_xlfn.XLOOKUP(E23,'Customer Data'!$A:$A,'Customer Data'!$C:$C,,0) -> #N/A | M23: VAS Activity Charges for the month of August, 24 | N23: 1400000503
A24: 1600000502 | B24: DG | C24: 45791 | D24: NA | E24: 256779420211 | F24: USD | G24: -11.92 | H24: INR | I24: -1033.36 | J24: =_xlfn.XLOOKUP(E24,'Customer Data'!$A:$A,'Customer Data'!$C:$C,,0) -> #N/A | M24: Credit note against 246779412148 | N24: 1400000503
A25: 1400000504 | B25: DZ | C25: 45861 | D25: NA | F25: USD | G25: 0 | H25: INR | I25: 0 | J25: =_xlfn.XLOOKUP(E25,'Customer Data'!$A:$A,'Customer Data'!$C:$C,,0) -> #N/A | N25: 1400000504
A26: 1800001492 | B26: DR | C26: 45730 | D26: NA | E26: 246779412149 | F26: USD | G26: 35.77 | H26: INR | I26: 3100.95 | J26: =_xlfn.XLOOKUP(E26,'Customer Data'!$A:$A,'Customer Data'!$C:$C,,0) -> #N/A | M26: VAS Activity Charges for the month of August, 24 | N26: 1400000504
A27: 1600000503 | B27: DG | C27: 45791 | D27: NA | E27: 256779420212 | F27: USD | G27: -35.77 | H27: INR | I27: -3100.95 | J27: =_xlfn.XLOOKUP(E27,'Customer Data'!$A:$A,'Customer Data'!$C:$C,,0) -> #N/A | M27: Credit note against 246779412149 | N27: 1400000504
A28: 1400000505 | B28: DZ | C28: 45861 | D28: NA | F28: USD | G28: 0 | H28: INR | I28: 0 | J28: =_xlfn.XLOOKUP(E28,'Customer Data'!$A:$A,'Customer Data'!$C:$C,,0) -> #N/A | N28: 1400000505
A29: 1800001493 | B29: DR | C29: 45730 | D29: NA | E29: 246779412150 | F29: USD | G29: 75.12 | H29: INR | I29: 6512.25 | J29: =_xlfn.XLOOKUP(E29,'Customer Data'!$A:$A,'Customer Data'!$C:$C,,0) -> #N/A | M29: VAS Activity Charges for the month of August, 24 | N29: 1400000505
A30: 1600000504 | B30: DG | C30: 45791 | D30: NA | E30: 256779420213 | F30: USD | G30: -75.12 | H30: INR | I30: -6512.25 | J30: =_xlfn.XLOOKUP(E30,'Customer Data'!$A:$A,'Customer Data'!$C:$C,,0) -> #N/A | M30: Credit note against 246779412150 | N30: 1400000505
A31: 1400000506 | B31: DZ | C31: 45861 | D31: NA | F31: USD | G31: 0 | H31: INR | I31: 0 | J31: =_xlfn.XLOOKUP(E31,'Customer Data'!$A:$A,'Customer Data'!$C:$C,,0) -> #N/A | N31: 1400000506
A32: 1800001494 | B32: DR | C32: 45730 | D32: NA | E32: 246779412151 | F32: USD | G32: 17.88 | H32: INR | I32: 1550.04 | J32: =_xlfn.XLOOKUP(E32,'Customer Data'!$A:$A,'Customer Data'!$C:$C,,0) -> #N/A | M32: VAS Activity Charges for the month of August, 24 | N32: 1400000506
A33: 1600000505 | B33: DG | C33: 45791 | D33: NA | E33: 256779420214 | F33: USD | G33: -17.88 | H33: INR | I33: -1550.04 | J33: =_xlfn.XLOOKUP(E33,'Customer Data'!$A:$A,'Customer Data'!$C:$C,,0) -> #N/A | M33: Credit note against 246779412151 | N33: 1400000506
A34: 1400000507 | B34: DZ | C34: 45861 | D34: NA | F34: USD | G34: 0 | H34: INR | I34: 0 | J34: =_xlfn.XLOOKUP(E34,'Customer Data'!$A:$A,'Customer Data'!$C:$C,,0) -> #N/A | N34: 1400000507
A35: 1800001495 | B35: DR | C35: 45730 | D35: NA | E35: 246779412152 | F35: USD | G35: 6.56 | H35: INR | I35: 568.69 | J35: =_xlfn.XLOOKUP(E35,'Customer Data'!$A:$A,'Customer Data'!$C:$C,,0) -> #N/A | M35: VAS Activity Charges for the month of August, 24 | N35: 1400000507
A36: 1600000506 | B36: DG | C36: 45791 | D36: NA | E36: 256779420215 | F36: USD | G36: -6.56 | H36: INR | I36: -568.69 | J36: =_xlfn.XLOOKUP(E36,'Customer Data'!$A:$A,'Customer Data'!$C:$C,,0) -> #N/A | M36: Credit note against 246779412152 | N36: 1400000507
A37: 1400000508 | B37: DZ | C37: 45861 | D37: NA | F37: USD | G37: 0 | H37: INR | I37: 0 | J37: =_xlfn.XLOOKUP(E37,'Customer Data'!$A:$A,'Customer Data'!$C:$C,,0) -> #N/A | N37: 1400000508
A38: 1800001496 | B38: DR | C38: 45730 | D38: NA | E38: 246779412153 | F38: USD | G38: 23.85 | H38: INR | I38: 2067.59 | J38: =_xlfn.XLOOKUP(E38,'Customer Data'!$A:$A,'Customer Data'!$C:$C,,0) -> #N/A | M38: VAS Activity Charges for the month of August, 24 | N38: 1400000508
A39: 1600000507 | B39: DG | C39: 45791 | D39: NA | E39: 256779420216 | F39: USD | G39: -23.85 | H39: INR | I39: -2067.59 | J39: =_xlfn.XLOOKUP(E39,'Customer Data'!$A:$A,'Customer Data'!$C:$C,,0) -> #N/A | M39: Credit note against 246779412153 | N39: 1400000508
A40: 1400000509 | B40: DZ | C40: 45861 | D40: NA | F40: USD | G40: 0 | H40: INR | I40: 0 | J40: =_xlfn.XLOOKUP(E40,'Customer Data'!$A:$A,'Customer Data'!$C:$C,,0) -> #N/A | N40: 1400000509
A41: 1800001639 | B41: DR | C41: 45730 | D41: NA | E41: 246779412296 | F41: USD | G41: 11.92 | H41: INR | I41: 1033.36 | J41: =_xlfn.XLOOKUP(E41,'Customer Data'!$A:$A,'Customer Data'!$C:$C,,0) -> #N/A | M41: VAS Activity Charges for the month of August, 24 | N41: 1400000509
A42: 1600000638 | B42: DG | C42: 45791 | D42: NA | E42: 256779420347 | F42: USD | G42: -11.92 | H42: INR | I42: -1033.36 | J42: =_xlfn.XLOOKUP(E42,'Customer Data'!$A:$A,'Customer Data'!$C:$C,,0) -> #N/A | M42: Credit note against 246779412296 | N42: 1400000509
A43: 1400000510 | B43: DZ | C43: 45861 | D43: NA | F43: USD | G43: 0 | H43: INR | I43: 0 | J43: =_xlfn.XLOOKUP(E43,'Customer Data'!$A:$A,'Customer Data'!$C:$C,,0) -> #N/A | N43: 1400000510
A44: 1800001640 | B44: DR | C44: 45730 | D44: NA | E44: 246779412297 | F44: USD | G44: 35.77 | H44: INR | I44: 3100.95 | J44: =_xlfn.XLOOKUP(E44,'Customer Data'!$A:$A,'Customer Data'!$C:$C,,0) -> #N/A | M44: VAS Activity Charges for the month of August, 24 | N44: 1400000510
A45: 1600000639 | B45: DG | C45: 45791 | D45: NA | E45: 256779420348 | F45: USD | G45: -35.77 | H45: INR | I45: -3100.95 | J45: =_xlfn.XLOOKUP(E45,'Customer Data'!$A:$A,'Customer Data'!$C:$C,,0) -> #N/A | M45: Credit note against 246779412297 | N45: 1400000510
...

Sheet Customer Data
A1: Invoice Number | B1: Invoice date | C1: Invoice amount | D1: Paid amount | E1: Payment date | F1: Payment reference
A2: 256779419880 | B2: 45996 | C2: 3.73 | D2: 3.73 | E2: 46087 | F2: 2000016339
A3: 256779419838 | B3: 45999 | C3: 39.58 | D3: 39.58 | E3: 46087 | F3: 2000016339
A4: 256779418939 | B4: 45966 | C4: 0.83 | D4: 0.83 | E4: 46006 | F4: 2000016247
A5: 256779419102 | B5: 45964 | C5: 40.38 | D5: 40.38 | E5: 46006 | F5: 2000016247
A6: 256779416300 | B6: 45877 | C6: 18.42 | D6: 18.42 | E6: 45925 | F6: 2000016149
A7: 256779416188 | B7: 45877 | C7: 15.35 | D7: 15.35 | E7: 45925 | F7: 2000016149
A8: 256779416150 | B8: 45877 | C8: 88.09 | D8: 88.09 | E8: 45925 | F8: 2000016149
A9: 256779414993 | B9: 45842 | C9: 40.09 | D9: 40.09 | E9: 45894 | F9: 2000016095
A10: 256779415151 | B10: 45843 | C10: 49.13 | D10: 49.13 | E10: 45894 | F10: 2000016095
A11: 256779413571 | B11: 45785 | C11: 4.5 | D11: 4.5 | E11: 45880 | F11: 2000016066
A12: 256779412870 | B12: 45770 | C12: 40.21 | D12: 40.21 | E12: 45880 | F12: 2000016066
A13: 256779412899 | B13: 45770 | C13: 3.79 | D13: 3.79 | E13: 45880 | F13: 2000016066
... A21: 256779412593 | B21: 45769 | C21: 40.18 | D21: 40.18 | E21: 45876 | F21: 2000016065
A22: 6779IV124000228 | B22: 45702 | C22: 37.82 | D22: 37.82 | E22: 45743 | F22: 2000015822
A23: 6779IV124000226 | B23: 45702 | C23: 6.5 | D23: 6.5 | E23: 45743 | F23: 2000015822
A24: 6779IV124000231 | B24: 45702 | C24: 3.94 | D24: 3.94 | E24: 45743 | F24: 2000015822
A25: 6779IV124000233 | B25: 45702 | C25: 3.41 | D25: 3.41 | E25: 45743 | F25: 2000015822
A26: 6779IV124000218 | B26: 45702 | C26: 2.55 | D26: 2.55 | E26: 45743 | F26: 2000015822
A27: 6779IV124000225 | B27: 45702 | C27: 11.06 | D27: 11.06 | E27: 45743 | F27: 2000015822
A28: 6779IV124000227 | B28: 45702 | C28: 12.77 | D28: 12.77 | E28: 45743 | F28: 2000015822
A29: 6779IV124000230 | B29: 45702 | C29: 15.75 | D29: 15.75 | E29: 45743 | F29: 2000015822
A30: 6779IV124000224 | B30: 45702 | C30: 3.94 | D30: 3.94 | E30: 45743 | F30: 2000015822
A31: 6779IV124000219 | B31: 45702 | C31: 37.82 | D31: 37.82 | E31: 45743 | F31: 2000015822
A32: 6779IV124000220 | B32: 45702 | C32: 3.94 | D32: 3.94 | E32: 45743 | F32: 2000015822
A33: 6779IV124000221 | B33: 45702 | C33: 11.91 | D33: 11.91 | E33: 45743 | F33: 2000015822
... A37: 6779IV124000232 | B37: 45702 | C37: 98.25 | D37: 98.25 | E37: 45743 | F37: 2000015822
C38: =SUM(C2:C37) -> 866.44 | D38: =SUM(D2:D37) -> 866.44

Sheet Summary
A1: Reconciliation of Ledger as on 31st January 2026
A2: Particulars | B2: Amount in USD
A3: Balance as per Ashland Singapore Ltd | B3: 0
A4: Add: TDS to be booked in Ascendus books
A5: Add: Invoices & CN not recorded in customer books
A6: Less: Difference in Payment recorded in both books
A7: Less: Invoice not recorded in Ascendus Books
A8: Derived balance
A9: Balance as per Ascent | B9: ='Ascendus Data'!G171 -> 151.52
A11: Difference | B11: =B8-B9-B10 -> -151.52
