Workbook

Sheet Summary
A2: Reconciliation of Ledger as on 31st January 2026
A3: Particulars | B3: Amount in USD
A4: Balance as per Siddhartha Logistics | B4: ='Customer ledger'!E158 -> 6201.493
A5: Add: TDS to be booked in Ascendus books | B5: =TDS!F154+'Payment Reco'!H8 -> 2559.2659
A6: Less: Difference in Payment recorded in both books | B6: ='Payment Reco'!I8 -> 50
A7: Add: CN and Invoices not in customer Books | B7: ='Invoices not in Customer books'!G8 -> 163.76
A8: Derived balance | B8: =SUM(B4:B7) -> 8974.5189
A9: Balance as per Ascent | B9: ='Ascendus Ledger'!K202 -> 8974.5146
A10: Difference | B10: =B8-B9 -> 0.0042622589

Sheet Invoices not in Customer books
A1: Document Number | B1: Document Type | C1: Document Date | D1: Reference | E1: Document Currency Value | F1: Company Code Currency Value | G1: Converted Value | H1: Text | I1: Remarks | J1: Status
A2: 1800001617 | B2: DR | C2: 45730 | D2: 246779412274 | E2: 100 | F2: 8669.13 | G2: 100 | H2: Intra Unit Transfer Charges Month Of August,2024 | I2: =_xlfn.XLOOKUP(D2,'Invoice Not in Customer Book'!$F:$F,'Invoice Not in Customer Book'!$N:$N,,0) -> Credit Note to be passed as discussed with CL team | J2: Done
A3: 1800013511 | B3: DR | C3: 45935 | D3: 256779418401 | E3: 62.52 | F3: 5513.69 | G3: 62.52 | H3: PORT SSR Chgs Sep 25 | I3: =_xlfn.XLOOKUP(D3,'Invoice Not in Customer Book'!$F:$F,'Invoice Not in Customer Book'!$N:$N,,0) -> to be accounted by siddhartha | J3: Pending
A4: 1800014290 | B4: DR | C4: 45966 | D4: 256779418827 | E4: 60.86 | F4: 5355.89 | G4: 60.86 | H4: WEIGHTMENT-16 -31 Oct 25 | I4: =_xlfn.XLOOKUP(D4,'Invoice Not in Customer Book'!$F:$F,'Invoice Not in Customer Book'!$N:$N,,0) -> Credit Note to be passed as discussed with CL team | J4: Done
A5: 1800013760 | B5: DR | C5: 45937 | D5: 256779418181 | E5: 49.33 | F5: 4350.45 | G5: 49.33 | H5: VAS-16-30 Sept 25 | I5: =_xlfn.XLOOKUP(D5,'Invoice Not in Customer Book'!$F:$F,'Invoice Not in Customer Book'!$N:$N,,0) -> Credit Note to be passed as discussed with CL team | J5: Done
A6: 1600002686 | B6: DG | C6: 46027 | D6: 256779422156 | E6: =G6 -> -59.62 | F6: -5410.11 | G6: -59.62 | H6: 256779418354 | I6: =_xlfn.XLOOKUP(D6,'Invoice Not in Customer Book'!$F:$F,'Invoice Not in Customer Book'!$N:$N,,0) -> #N/A | J6: Pending
A7: 1600002687 | B7: DG | C7: 46027 | D7: 256779422157 | E7: =G7 -> -49.33 | F7: -4476.36 | G7: -49.33 | H7: 256779418354 | I7: =_xlfn.XLOOKUP(D7,'Invoice Not in Customer Book'!$F:$F,'Invoice Not in Customer Book'!$N:$N,,0) -> #N/A | J7: Pending
G8: =SUM(G2:G7) -> 163.76

Sheet Ascendus Ledger
A1: Document Number | B1: Document Type | C1: Document Date | D1: Entry Date | E1: Document Header Text | F1: Reference | G1: Document Currency Key | H1: Document Currency Value | I1: Company Code Currency Key | J1: Company Code Currency Value | K1: Converted Value | L1: Xlookup | M1: TDS | N1: Text | O1: Clearing Document
A2: 1800000035 | B2: DR | C2: 45708 | D2: 45708 | E2: NA | F2: 246779410007 | G2: USD | H2: 1190.48 | I2: INR | J2: 102742.78 | K2: =_xlfn.XLOOKUP(F2,'[1]Ascendus data working'!$B:$B,'[1]Ascendus data working'!$F:$F,,0) -> 1190.48 | L2: =_xlfn.XLOOKUP(F2,'Customer ledger'!$A:$A,'Customer ledger'!$D:$D,,0) -> 1071.43 | M2: =K2-L2 -> 119.05 | N2: Fixed Rental charges for Aug 2024 | O2: 1400000805
A3: 1800000079 | B3: DR | C3: 45708 | D3: 45709 | E3: NA | F3: 246779410274 | G3: USD | H3: 1190.48 | I3: INR | J3: 102742.78 | K3: =_xlfn.XLOOKUP(F3,'[1]Ascendus data working'!$B:$B,'[1]Ascendus data working'!$F:$F,,0) -> 1190.48 | L3: =_xlfn.XLOOKUP(F3,'Customer ledger'!$A:$A,'Customer ledger'!$D:$D,,0) -> 1071.43 | M3: =K3-L3 -> 119.05 | N3: Fixed Rental charges for Oct 2024 | O3: 1400000805
A4: 1800000099 | B4: DR | C4: 45708 | D4: 45708 | E4: NA | F4: 246779410027 | G4: USD | H4: 1190.48 | I4: INR | J4: 102742.78 | K4: =_xlfn.XLOOKUP(F4,'[1]Ascendus data working'!$B:$B,'[1]Ascendus data working'!$F:$F,,0) -> 1190.48 | L4: =_xlfn.XLOOKUP(F4,'Customer ledger'!$A:$A,'Customer ledger'!$D:$D,,0) -> 1071.43 | M4: =K4-L4 -> 119.05 | N4: Fixed Rental charges for Sept 2024 | O4: 1400000805
A5: 1800000168 | B5: DR | C5: 45708 | D5: 45708 | E5: NA | F5: 246779410095 | G5: USD | H5: 1190.48 | I5: INR | J5: 102742.78 | K5: =_xlfn.XLOOKUP(F5,'[1]Ascendus data working'!$B:$B,'[1]Ascendus data working'!$F:$F,,0) -> 1190.48 | L5: =_xlfn.XLOOKUP(F5,'Customer ledger'!$A:$A,'Customer ledger'!$D:$D,,0) -> 1071.43 | M5: =K5-L5 -> 119.05 | N5: Fixed Rental charges for Nov 2024 | O5: 1400000805
A6: 1800000211 | B6: DR | C6: 45708 | D6: 45708 | E6: NA | F6: 246779410138 | G6: USD | H6: 1190.48 | I6: INR | J6: 102742.78 | K6: =_xlfn.XLOOKUP(F6,'[1]Ascendus data working'!$B:$B,'[1]Ascendus data working'!$F:$F,,0) -> 1190.48 | L6: =_xlfn.XLOOKUP(F6,'Customer ledger'!$A:$A,'Customer ledger'!$D:$D,,0) -> 1071.43 | M6: =K6-L6 -> 119.05 | N6: Fixed Rental charges for Dec 2024 | O6: 1400000805
A7: 1800000254 | B7: DR | C7: 45708 | D7: 45708 | E7: NA | F7: 246779410181 | G7: USD | H7: 1166.59 | I7: INR | J7: 100680.99 | K7: =_xlfn.XLOOKUP(F7,'[1]Ascendus data working'!$B:$B,'[1]Ascendus data working'!$F:$F,,0) -> 1166.59 | L7: =_xlfn.XLOOKUP(F7,'Customer ledger'!$A:$A,'Customer ledger'!$D:$D,,0) -> 1049.93 | M7: =K7-L7 -> 116.66 | N7: Fixed Rental charges for Jan 2025 | O7: 1400000805
A8: 1800000297 | B8: DR | C8: 45708 | D8: 45708 | E8: NA | F8: 246779410224 | G8: USD | H8: 1143.12 | I8: INR | J8: 98655.44 | K8: =_xlfn.XLOOKUP(F8,'[1]Ascendus data working'!$B:$B,'[1]Ascendus data working'!$F:$F,,0) -> 1143.12 | L8: =_xlfn.XLOOKUP(F8,'Customer ledger'!$A:$A,'Customer ledger'!$D:$D,,0) -> 1028.81 | M8: =K8-L8 -> 114.31 | N8: Fixed Rental charges for Feb 2025 | O8: 1400000805
A9: 1800000406 | B9: DR | C9: 45719 | D9: 45719 | E9: NA | F9: 246779410368 | G9: USD | H9: 356.43 | I9: INR | J9: 30899.37 | K9: =_xlfn.XLOOKUP(F9,'[1]Ascendus data working'!$B:$B,'[1]Ascendus data working'!$F:$F,,0) -> 356.43 | L9: =_xlfn.XLOOKUP(F9,'Customer ledger'!$A:$A,'Customer ledger'!$D:$D,,0) -> 320.78 | M9: =K9-L9 -> 35.65 | N9: Storage Charges for the month of August, 2024
A10: 1800000675 | B10: DR | C10: 45719 | D10: 45720 | E10: NA | F10: 246779410615 | G10: USD | H10: 9 | I10: INR | J10: 780.22 | K10: =_xlfn.XLOOKUP(F10,'[1]Ascendus data working'!$B:$B,'[1]Ascendus data working'!$F:$F,,0) -> 9 | L10: =_xlfn.XLOOKUP(F10,'Customer ledger'!$A:$A,'Customer ledger'!$D:$D,,0) -> 8.81 | M10: =K10-L10 -> 0.19 | N10: Outbound Handling for Sep 2024
A11: 1800000432 | B11: DR | C11: 45719 | D11: 45719 | E11: NA | F11: 246779410394 | G11: USD | H11: 505.86 | I11: INR | J11: 43853.64 | K11: =_xlfn.XLOOKUP(F11,'[1]Ascendus data working'!$B:$B,'[1]Ascendus data working'!$F:$F,,0) -> 505.86 | L11: =_xlfn.XLOOKUP(F11,'Customer ledger'!$A:$A,'Customer ledger'!$D:$D,,0) -> 455.27 | M11: =K11-L11 -> 50.59 | N11: Storage for the month of Sep 2024 Exch Rate 83.79
A12: 1800000456 | B12: DR | C12: 45719 | D12: 45719 | E12: NA | F12: 246779410418 | G12: USD | H12: 562.6 | I12: INR | J12: 48772.5 | K12: =_xlfn.XLOOKUP(F12,'[1]Ascendus data working'!$B:$B,'[1]Ascendus data working'!$F:$F,,0) -> 562.6 | L12: =_xlfn.XLOOKUP(F12,'Customer ledger'!$A:$A,'Customer ledger'!$D:$D,,0) -> 506.34 | M12: =K12-L12 -> 56.26 | N12: Storage for the month of Oct 2024
A13: 1800000559 | B13: DR | C13: 45719 | D13: 45719 | E13: NA | F13: 246779410509 | G13: USD | H13: 29.25 | I13: INR | J13: 2535.72 | K13: =_xlfn.XLOOKUP(F13,'[1]Ascendus data working'!$B:$B,'[1]Ascendus data working'!$F:$F,,0) -> 29.25 | L13: =_xlfn.XLOOKUP(F13,'Customer ledger'!$A:$A,'Customer ledger'!$D:$D,,0) -> 28.66 | M13: =K13-L13 -> 0.59 | N13: Outbound Handling for Aug 2024
A14: 1800000560 | B14: DR | C14: 45719 | D14: 45719 | E14: NA | F14: 246779410510 | G14: USD | H14: 194.9 | I14: INR | J14: 16896.13 | K14: =_xlfn.XLOOKUP(F14,'[1]Ascendus data working'!$B:$B,'[1]Ascendus data working'!$F:$F,,0) -> 194.9 | L14: =_xlfn.XLOOKUP(F14,'Customer ledger'!$A:$A,'Customer ledger'!$D:$D,,0) -> 191 | M14: =K14-L14 -> 3.9 | N14: Outbound Handling for Aug 2024
A15: 1800000561 | B15: DR | C15: 45719 | D15: 45719 | E15: NA | F15: 246779410511 | G15: USD | H15: 13.91 | I15: INR | J15: 1205.88 | K15: =_xlfn.XLOOKUP(F15,'[1]Ascendus data working'!$B:$B,'[1]Ascendus data working'!$F:$F,,0) -> 13.91 | L15: =_xlfn.XLOOKUP(F15,'Customer ledger'!$A:$A,'Customer ledger'!$D:$D,,0) -> 13.63 | M15: =K15-L15 -> 0.28 | N15: Outbound Handling for Aug 2024
A16: 1800000674 | B16: DR | C16: 45719 | D16: 45720 | E16: NA | F16: 246779410614 | G16: USD | H16: 2.25 | I16: INR | J16: 195.06 | K16: =_xlfn.XLOOKUP(F16,'[1]Ascendus data working'!$B:$B,'[1]Ascendus data working'!$F:$F,,0) -> 2.25 | L16: =_xlfn.XLOOKUP(F16,'Customer ledger'!$A:$A,'Customer ledger'!$D:$D,,0) -> 2.2 | M16: =K16-L16 -> 0.05 | N16: Outbound Handling for Sep 2024
A17: 1800000754 | B17: DR | C17: 45720 | D17: 45720 | E17: NA | F17: 246779410694 | G17: USD | H17: 59.36 | I17: INR | J17: 5145.99 | K17: =_xlfn.XLOOKUP(F17,'[1]Ascendus data working'!$B:$B,'[1]Ascendus data working'!$F:$F,,0) -> 59.36 | L17: =_xlfn.XLOOKUP(F17,'Customer ledger'!$A:$A,'Customer ledger'!$D:$D,,0) -> 58.17 | M17: =K17-L17 -> 1.19 | N17: Outbound Handling for Oct 2024
A18: 1800000915 | B18: DR | C18: 45720 | D18: 45721 | E18: NA | F18: 246779410856 | G18: USD | H18: 18.32 | I18: INR | J18: 1588.18 | K18: =_xlfn.XLOOKUP(F18,'[1]Ascendus data working'!$B:$B,'[1]Ascendus data working'!$F:$F,,0) -> 18.32 | L18: =_xlfn.XLOOKUP(F18,'Customer ledger'!$A:$A,'Customer ledger'!$D:$D,,0) -> 17.95 | M18: =K18-L18 -> 0.37 | N18: Outbound Handling for Dec 2024
A19: 1800000948 | B19: DR | C19: 45722 | D19: 45722 | E19: NA | F19: 246779410888 | G19: USD | H19: 446.38 | I19: INR | J19: 38697.24 | K19: =_xlfn.XLOOKUP(F19,'[1]Ascendus data working'!$B:$B,'[1]Ascendus data working'!$F:$F,,0) -> 446.38 | L19: =_xlfn.XLOOKUP(F19,'Customer ledger'!$A:$A,'Customer ledger'!$D:$D,,0) -> 401.74 | M19: =K19-L19 -> 44.64 | N19: Storage Charges for the month of December, 2024 Ex
A20: 1800000925 | B20: DR | C20: 45722 | D20: 45722 | E20: NA | F20: 246779410865 | G20: USD | H20: 412.11 | I20: INR | J20: 35726.34 | K20: =_xlfn.XLOOKUP(F20,'[1]Ascendus data working'!$B:$B,'[1]Ascendus data working'!$F:$F,,0) -> 412.11 | L20: =_xlfn.XLOOKUP(F20,'Customer ledger'!$A:$A,'Customer ledger'!$D:$D,,0) -> 370.9 | M20: =K20-L20 -> 41.21 | N20: Storage Charges for the month of November, 2024 Ex
... A35: 1800001791 | B35: DR | C35: 45730 | D35: 45733 | E35: NA | F35: 246779411456 | G35: USD | H35: 4.77 | I35: INR | J35: 413.52 | K35: =_xlfn.XLOOKUP(F35,'[1]Ascendus data working'!$B:$B,'[1]Ascendus data working'!$F:$F,,0) -> 4.77 | L35: =_xlfn.XLOOKUP(F35,'Customer ledger'!$A:$A,'Customer ledger'!$D:$D,,0) -> #N/A | M35: =K35-L35 -> #N/A | N35: VAS Activity Charges for the month of August, 24
A36: 1800001583 | B36: DR | C36: 45730 | D36: 45735 | E36: NA | F36: 246779412240 | G36: USD | H36: 2.86 | I36: INR | J36: 247.94 | K36: =_xlfn.XLOOKUP(F36,'[1]Ascendus data working'!$B:$B,'[1]Ascendus data working'!$F:$F,,0) -> 2.86 | L36: =_xlfn.XLOOKUP(F36,'Customer ledger'!$A:$A,'Customer ledger'!$D:$D,,0) -> 2.8 | M36: =K36-L36 -> 0.06 | N36: VAS Activity Charges for the month of August, 24 | O36: 1400000797
A37: 1800001584 | B37: DR | C37: 45730 | D37: 45735 | E37: NA | F37: 246779412241 | G37: USD | H37: 0.95 | I37: INR | J37: 82.36 | K37: =_xlfn.XLOOKUP(F37,'[1]Ascendus data working'!$B:$B,'[1]Ascendus data working'!$F:$F,,0) -> 0.95 | L37: =_xlfn.XLOOKUP(F37,'Customer ledger'!$A:$A,'Customer ledger'!$D:$D,,0) -> #N/A | M37: =K37-L37 -> #N/A | N37: VAS Activity Charges for the month of August, 24 | O37: 1400000797
A38: 1800001585 | B38: DR | C38: 45730 | D38: 45735 | E38: NA | F38: 246779412242 | G38: USD | H38: 4.77 | I38: INR | J38: 413.52 | K38: =_xlfn.XLOOKUP(F38,'[1]Ascendus data working'!$B:$B,'[1]Ascendus data working'!$F:$F,,0) -> 4.77 | L38: =_xlfn.XLOOKUP(F38,'Customer ledger'!$A:$A,'Customer ledger'!$D:$D,,0) -> 4.67 | M38: =K38-L38 -> 0.1 | N38: VAS Activity Charges for the month of August, 24 | O38: 1400000797
A39: 1800001586 | B39: DR | C39: 45730 | D39: 45735 | E39: NA | F39: 246779412243 | G39: USD | H39: 1.91 | I39: INR | J39: 165.58 | K39: =_xlfn.XLOOKUP(F39,'[1]Ascendus data working'!$B:$B,'[1]Ascendus data working'!$F:$F,,0) -> 1.91 | L39: =_xlfn.XLOOKUP(F39,'Customer ledger'!$A:$A,'Customer ledger'!$D:$D,,0) -> 1.87 | M39: =K39-L39 -> 0.04 | N39: VAS Activity Charges for the month of August, 24 | O39: 1400000797
A40: 1800001587 | B40: DR | C40: 45730 | D40: 45735 | E40: NA | F40: 246779412244 | G40: USD | H40: 1.91 | I40: INR | J40: 165.58 | K40: =_xlfn.XLOOKUP(F40,'[1]Ascendus data working'!$B:$B,'[1]Ascendus data working'!$F:$F,,0) -> 1.91 | L40: =_xlfn.XLOOKUP(F40,'Customer ledger'!$A:$A,'Customer ledger'!$D:$D,,0) -> 1.87 | M40: =K40-L40 -> 0.04 | N40: VAS Activity Charges for the month of August, 24 | O40: 1400000797
A41: 1800001588 | B41: DR | C41: 45730 | D41: 45735 | E41: NA | F41: 246779412245 | G41: USD | H41: 4.77 | I41: INR | J41: 413.52 | K41: =_xlfn.XLOOKUP(F41,'[1]Ascendus data working'!$B:$B,'[1]Ascendus data working'!$F:$F,,0) -> 4.77 | L41: =_xlfn.XLOOKUP(F41,'Customer ledger'!$A:$A,'Customer ledger'!$D:$D,,0) -> 4.68 | M41: =K41-L41 -> 0.09 | N41: VAS Activity Charges for the month of August, 24 | O41: 1400000797
A42: 1800001957 | B42: DR | C42: 45733 | D42: 45733 | E42: NA | F42: 246779411622 | G42: USD | H42: 3.82 | I42: INR | J42: 331.16 | K42: =_xlfn.XLOOKUP(F42,'[1]Ascendus data working'!$B:$B,'[1]Ascendus data working'!$F:$F,,0) -> 3.82 | L42: =_xlfn.XLOOKUP(F42,'Customer ledger'!$A:$A,'Customer ledger'!$D:$D,,0) -> 3.74 | M42: =K42-L42 -> 0.08 | N42: VAS Activity Charges for the month of September, 2
A43: 1800001958 | B43: DR | C43: 45733 | D43: 45733 | E43: NA | F43: 246779411623 | G43: USD | H43: 1.91 | I43: INR | J43: 165.58 | K43: =_xlfn.XLOOKUP(F43,'[1]Ascendus data working'!$B:$B,'[1]Ascendus data working'!$F:$F,,0) -> 1.91 | L43: =_xlfn.XLOOKUP(F43,'Customer ledger'!$A:$A,'Customer ledger'!$D:$D,,0) -> 1.87 | M43: =K43-L43 -> 0.04 | N43: VAS Activity Charges for the month of September, 2
A44: 1800003125 | B44: DR | C44: 45735 | D44: 45736 | E44: NA | F44: 246779412992 | G44: USD | H44: 1148.63 | I44: INR | J44: 99576.18 | K44: =_xlfn.XLOOKUP(F44,'[1]Ascendus data working'!$B:$B,'[1]Ascendus data working'!$F:$F,,0) -> 1148.63 | L44: =_xlfn.XLOOKUP(F44,'Customer ledger'!$A:$A,'Customer ledger'!$D:$D,,0) -> 1033.77 | M44: =K44-L44 -> 114.86 | N44: Fixed Storage Charges for Mar 2025
A45: 1800004097 | B45: DR | C45: 45736 | D45: 45737 | E45: NA | F45: 246779413953 | G45: USD | H45: 3 | I45: INR | J45: 260.07 | K45: =_xlfn.XLOOKUP(F45,'[1]Ascendus data working'!$B:$B,'[1]Ascendus data working'!$F:$F,,0) -> 3 | L45: =_xlfn.XLOOKUP(F45,'Customer ledger'!$A:$A,'Customer ledger'!$D:$D,,0) -> 2.94 | M45: =K45-L45 -> 0.06 | N45: Outbound Handling charges for Feb 2025
A46: 1800004357 | B46: DR | C46: 45736 | D46: 45737 | E46: NA | F46: 246779414225 | G46: USD | H46: 13.5 | I46: INR | J46: 1170.33 | K46: =_xlfn.XLOOKUP(F46,'[1]Ascendus data working'!$B:$B,'[1]Ascendus data working'!$F:$F,,0) -> 13.5 | L46: =_xlfn.XLOOKUP(F46,'Customer ledger'!$A:$A,'Customer ledger'!$D:$D,,0) -> 13.23 | M46: =K46-L46 -> 0.27 | N46: Outbound Handling charges for Sep 2024
A47: 1800004532 | B47: DR | C47: 45736 | D47: 45737 | E47: NA | F47: 246779414400 | G47: USD | H47: 80.95 | I47: INR | J47: 7017.66 | K47: =_xlfn.XLOOKUP(F47,'[1]Ascendus data working'!$B:$B,'[1]Ascendus data working'!$F:$F,,0) -> 80.95 | L47: =_xlfn.XLOOKUP(F47,'Customer ledger'!$A:$A,'Customer ledger'!$D:$D,,0) -> 79.33 | M47: =K47-L47 -> 1.62 | N47: Inbound Handling charges for Nov 2024
A48: 1800004533 | B48: DR | C48: 45736 | D48: 45737 | E48: NA | F48: 246779414401 | G48: USD | H48: 15 | I48: INR | J48: 1300.37 | K48: =_xlfn.XLOOKUP(F48,'[1]Ascendus data working'!$B:$B,'[1]Ascendus data working'!$F:$F,,0) -> 15 | L48: =_xlfn.XLOOKUP(F48,'Customer ledger'!$A:$A,'Customer ledger'!$D:$D,,0) -> 14.7 | M48: =K48-L48 -> 0.3 | N48: LCL Movement Charges for Nov 2024
A49: 1800004870 | B49: DR | C49: 45736 | D49: 45737 | E49: NA | F49: 246779414738 | G49: USD | H49: 2.25 | I49: INR | J49: 195.06 | K49: =_xlfn.XLOOKUP(F49,'[1]Ascendus data working'!$B:$B,'[1]Ascendus data working'!$F:$F,,0) -> 2.25 | L49: =_xlfn.XLOOKUP(F49,'Customer ledger'!$A:$A,'Customer ledger'!$D:$D,,0) -> 2.2 | M49: =K49-L49 -> 0.05 | N49: Outbound Handling charges for Jan 2025
A50: 1800004871 | B50: DR | C50: 45736 | D50: 45737 | E50: NA | F50: 246779414739 | G50: USD | H50: 0.75 | I50: INR | J50: 65.02 | K50: =_xlfn.XLOOKUP(F50,'[1]Ascendus data working'!$B:$B,'[1]Ascendus data working'!$F:$F,,0) -> 0.75 | L50: =_xlfn.XLOOKUP(F50,'Customer ledger'!$A:$A,'Customer ledger'!$D:$D,,0) -> 0.73 | M50: =K50-L50 -> 0.02 | N50: Loose Loading Handling charges for Jan 2025
A51: 1800004926 | B51: DR | C51: 45736 | D51: 45737 | E51: NA | F51: 246779414794 | G51: USD | H51: 2.25 | I51: INR | J51: 195.06 | K51: =_xlfn.XLOOKUP(F51,'[1]Ascendus data working'!$B:$B,'[1]Ascendus data working'!$F:$F,,0) -> 2.25 | L51: =_xlfn.XLOOKUP(F51,'Customer ledger'!$A:$A,'Customer ledger'!$D:$D,,0) -> 2.2 | M51: =K51-L51 -> 0.05 | N51: Outbound Handling charges for Feb 2025
A52: 1800004927 | B52: DR | C52: 45736 | D52: 45737 | E52: NA | F52: 246779414795 | G52: USD | H52: 0.75 | I52: INR | J52: 65.02 | K52: =_xlfn.XLOOKUP(F52,'[1]Ascendus data working'!$B:$B,'[1]Ascendus data working'!$F:$F,,0) -> 0.75 | L52: =_xlfn.XLOOKUP(F52,'Customer ledger'!$A:$A,'Customer ledger'!$D:$D,,0) -> 0.73 | M52: =K52-L52 -> 0.02 | N52: Loose handling Charges for Feb 2025
A53: 1800004739 | B53: DR | C53: 45736 | D53: 45737 | E53: NA | F53: 246779414607 | G53: USD | H53: 2.25 | I53: INR | J53: 195.06 | K53: =_xlfn.XLOOKUP(F53,'[1]Ascendus data working'!$B:$B,'[1]Ascendus data working'!$F:$F,,0) -> 2.25 | L53: =_xlfn.XLOOKUP(F53,'Customer ledger'!$A:$A,'Customer ledger'!$D:$D,,0) -> 2.2 | M53: =K53-L53 -> 0.05 | N53: Outbound Handling charges for Oct 2024
... A56: 1800005192 | B56: DR | C56: 45750 | D56: 45752 | E56: NA | F56: 256779410138 | G56: USD | H56: 1.5 | I56: INR | J56: 130.38 | K56: =_xlfn.XLOOKUP(F56,'[1]Ascendus data working'!$B:$B,'[1]Ascendus data working'!$F:$F,,0) -> 1.5 | L56: =_xlfn.XLOOKUP(F56,'Customer ledger'!$A:$A,'Customer ledger'!$D:$D,,0) -> 1.47 | M56: =K56-L56 -> 0.03 | N56: Loose loading Handling charges for Mar 25
...

Sheet CL Ledger
A1: Cleared Item | B1: Company Code | C1: Customer | D1: Customer Account: Name 1 | E1: Fiscal Year | F1: Posting period | G1: Posting Date | H1: Document Number | I1: Document Type | J1: Document Date | K1: Entry Date | L1: Document Header Text | M1: Reference | N1: G/L Account | O1: G/L Account: Short Text | P1: Special G/L Ind. | Q1: Posting Key | R1: Document Currency Key | S1: Document Currency Value | T1: Company Code Currency Key | U1: Company Code Currency Value | V1: Tax Code | W1: Profit Center | X1: Trading Partner No. | Y1: Assignment | Z1: Item | AB1: Text | AC1: Reference Key 1 | AD1: Reference Key 2 | AE1: Reference Key 3 | AF1: Baseline Payment Dte | AG1: Clearing Date | AH1: Clearing Document
A2: Selected | B2: 6779 | C2: 100222345 | D2: SIDDHARTHA LOGISTICS FTWZ PRIVATE | E2: 2025 | F2: 9 | G2: 45902 | H2: 1400001107 | I2: DY | J2: 45902 | K2: 45902 | N2: 212100 | O2: Trade Debtors (Ctrl) | Q2: 08 | R2: USD | S2: 104184.06 | T2: INR | U2: 102382.08 | W2: 6779224500 | Z2: 1 | AA2: =U2 -> 102382.08 | AF2: 45902 | AG2: 45902 | AH2: 1400001107
A3: Selected | B3: 6779 | C3: 100222345 | D3: SIDDHARTHA LOGISTICS FTWZ PRIVATE | E3: 2025 | F3: 9 | G3: 45902 | H3: 1400001107 | I3: DY | J3: 45902 | K3: 45902 | N3: 212100 | O3: Trade Debtors (Ctrl) | Q3: 15 | R3: USD | S3: -104184.06 | T3: INR | U3: -101775.06 | W3: 6779224500 | Z3: 2 | AA3: =U3 -> -101775.06 | AF3: 45902 | AG3: 45902 | AH3: 1400001107
A4: Selected | B4: 6779 | C4: 100222345 | D4: SIDDHARTHA LOGISTICS FTWZ PRIVATE | E4: 2025 | F4: 7 | G4: 45861 | H4: 1400000797 | I4: DY | J4: 45861 | K4: 45861 | N4: 212100 | O4: Trade Debtors (Ctrl) | Q4: 08 | R4: USD | S4: 198636.61 | T4: INR | U4: 200764.2 | W4: 6779224500 | Z4: 1 | AA4: =U4 -> 200764.2 | AF4: 45861 | AG4: 45861 | AH4: 1400000797
A5: Selected | B5: 6779 | C5: 100222345 | D5: SIDDHARTHA LOGISTICS FTWZ PRIVATE | E5: 2025 | F5: 7 | G5: 45861 | H5: 1400000797 | I5: DY | J5: 45861 | K5: 45861 | N5: 212100 | O5: Trade Debtors (Ctrl) | Q5: 15 | R5: USD | S5: -198636.61 | T5: INR | U5: -200764.2 | W5: 6779224500 | Z5: 2 | AA5: =U5 -> -200764.2 | AF5: 45861 | AG5: 45861 | AH5: 1400000797
A6: Not Selected | B6: 6779 | C6: 100222345 | D6: SIDDHARTHA LOGISTICS FTWZ PRIVATE | E6: 2025 | F6: 8 | G6: 45891 | H6: 1400001003 | I6: DZ | J6: 45891 | K6: 45891 | L6: 0099542199FC | N6: 212100 | O6: Trade Debtors (Ctrl) | Q6: 15 | R6: USD | S6: -4582.99 | T6: INR | U6: -394140.21 | W6: 6779220000 | Z6: 2 | AA6: =S6 -> -4582.99 | AF6: 45891
A7: Selected | B7: 6779 | C7: 100222345 | D7: SIDDHARTHA LOGISTICS FTWZ PRIVATE | E7: 2025 | F7: 7 | G7: 45862 | H7: 1400000805 | I7: DZ | J7: 45862 | K7: 45862 | L7: 0105357143FC | N7: 212100 | O7: Trade Debtors (Ctrl) | Q7: 15 | R7: USD | S7: -8262.11 | T7: INR | U7: -713050.33 | W7: 6779224500 | Z7: 3 | AA7: =S7 -> -8262.11 | AB7: 0105357143FC | AF7: 45862 | AG7: 45862 | AH7: 1400000805
A8: Not Selected | B8: 6779 | C8: 100222345 | D8: SIDDHARTHA LOGISTICS FTWZ PRIVATE | E8: 2025 | F8: 10 | G8: 45955 | H8: 1400001512 | I8: DZ | J8: 45955 | K8: 45955 | L8: T54SWIC277314 | N8: 212100 | O8: Trade Debtors (Ctrl) | Q8: 15 | R8: USD | S8: -4875.15 | T8: INR | U8: -429943.23 | W8: 6779220000 | Z8: 2 | AA8: =S8 -> -4875.15 | AF8: 45955
A9: Selected | B9: 6779 | C9: 100222345 | D9: SIDDHARTHA LOGISTICS FTWZ PRIVATE | E9: 2025 | F9: 11 | G9: 45976 | H9: 1400001904 | I9: DY | J9: 45976 | K9: 45976 | L9: NA | M9: KNOCK OFF ENTRY | N9: 212100 | O9: Trade Debtors (Ctrl) | Q9: 08 | R9: USD | S9: 0 | T9: INR | U9: 0 | W9: 6779224500 | Z9: 1 | AA9: =S9 -> 0 | AF9: 45976 | AG9: 45976 | AH9: 1400001904
A10: Selected | B10: 6779 | C10: 100222345 | D10: SIDDHARTHA LOGISTICS FTWZ PRIVATE | E10: 2025 | F10: 11 | G10: 45976 | H10: 1400001905 | I10: DY | J10: 45976 | K10: 45976 | L10: NA | M10: KNOCK OFF ENTRY | N10: 212100 | O10: Trade Debtors (Ctrl) | Q10: 08 | R10: USD | S10: 879.2 | T10: INR | U10: 77537.33 | W10: 6779224500 | Z10: 4 | AA10: =S10 -> 879.2 | AF10: 45976 | AG10: 45976 | AH10: 1400001905
A11: Not Selected | B11: 6779 | C11: 100222345 | D11: SIDDHARTHA LOGISTICS FTWZ PRIVATE | E11: 2025 | F11: 11 | G11: 45976 | H11: 1400001905 | I11: DY | J11: 45976 | K11: 45976 | L11: NA | M11: KNOCK OFF ENTRY | N11: 212100 | O11: Trade Debtors (Ctrl) | Q11: 15 | R11: USD | S11: -111.25 | T11: INR | U11: -9790.38 | W11: 6779224500 | Y11: NA | Z11: 1 | AA11: =S11 -> -111.25 | AF11: 45976
A12: Not Selected | B12: 6779 | C12: 100222345 | D12: SIDDHARTHA LOGISTICS FTWZ PRIVATE | E12: 2025 | F12: 11 | G12: 45976 | H12: 1400001905 | I12: DY | J12: 45976 | K12: 45976 | L12: NA | M12: KNOCK OFF ENTRY | N12: 212100 | O12: Trade Debtors (Ctrl) | Q12: 15 | R12: USD | S12: -376.4 | T12: INR | U12: -33124.48 | W12: 6779224500 | Y12: NA | Z12: 2 | AA12: =S12 -> -376.4 | AF12: 45976
A13: Not Selected | B13: 6779 | C13: 100222345 | D13: SIDDHARTHA LOGISTICS FTWZ PRIVATE | E13: 2025 | F13: 11 | G13: 45976 | H13: 1400001905 | I13: DY | J13: 45976 | K13: 45976 | L13: NA | M13: KNOCK OFF ENTRY | N13: 212100 | O13: Trade Debtors (Ctrl) | Q13: 15 | R13: USD | S13: -391.55 | T13: INR | U13: -34457.73 | W13: 6779224500 | Y13: NA | Z13: 3 | AA13: =S13 -> -391.55 | AF13: 45976
A14: Not Selected | B14: 6779 | C14: 100222345 | D14: SIDDHARTHA LOGISTICS FTWZ PRIVATE | E14: 2025 | F14: 5 | G14: 45787 | H14: 1800008258 | I14: DR | J14: 45787 | K14: 45791 | L14: NA | M14: 256779413142 | N14: 212100 | O14: Trade Debtors (Ctrl) | Q14: 01 | R14: USD | S14: 100000 | T14: INR | U14: 100000 | V14: O0 | W14: 6779224500 | Y14: NA | Z14: 1 | AA14: =_xlfn.XLOOKUP(M14,'[1]TDS To Be Booked'!$D:$D,'[1]TDS To Be Booked'!$K:$K,,0) -> 1163.0111 | AB14: Fixed Storage Charges fo MAY 2025 | AF14: 45787
A15: Not Selected | B15: 6779 | C15: 100222345 | D15: SIDDHARTHA LOGISTICS FTWZ PRIVATE | E15: 2025 | F15: 6 | G15: 45818 | H15: 1800009590 | I15: DR | J15: 45818 | K15: 45825 | L15: NA | M15: 256779414354 | N15: 212100 | O15: Trade Debtors (Ctrl) | Q15: 01 | R15: USD | S15: 100000 | T15: INR | U15: 100000 | V15: O0 | W15: 6779224500 | Y15: NA | Z15: 1 | AA15: =_xlfn.XLOOKUP(M15,'[1]TDS To Be Booked'!$D:$D,'[1]TDS To Be Booked'!$K:$K,,0) -> 1169.7222 | AB15: Fixed Storage Charges fo JUNE 2025 | AF15: 45818
A16: Not Selected | B16: 6779 | C16: 100222345 | D16: SIDDHARTHA LOGISTICS FTWZ PRIVATE | E16: 2025 | F16: 7 | G16: 45842 | H16: 1800010152 | I16: DR | J16: 45842 | K16: 45847 | L16: NA | M16: 256779414912 | N16: 212100 | O16: Trade Debtors (Ctrl) | Q16: 01 | R16: USD | S16: 100000 | T16: INR | U16: 100000 | V16: O0 | W16: 6779224500 | Y16: NA | Z16: 1 | AA16: =_xlfn.XLOOKUP(M16,'[1]TDS To Be Booked'!$D:$D,'[1]TDS To Be Booked'!$K:$K,,0) -> 1162.7778 | AB16: Fixed Storage Charges fo JULY 2025 | AF16: 45842
A17: Not Selected | B17: 6779 | C17: 100222345 | D17: SIDDHARTHA LOGISTICS FTWZ PRIVATE | E17: 2025 | F17: 8 | G17: 45870 | H17: 1800011358 | I17: DR | J17: 45870 | K17: 45873 | L17: NA | M17: 256779416024 | N17: 212100 | O17: Trade Debtors (Ctrl) | Q17: 01 | R17: USD | S17: 100000 | T17: INR | U17: 100000 | V17: O0 | W17: 6779224500 | Y17: NA | Z17: 1 | AA17: =_xlfn.XLOOKUP(M17,'[1]TDS To Be Booked'!$D:$D,'[1]TDS To Be Booked'!$K:$K,,0) -> 1162.3778 | AB17: Fixed Storage Charges for August 2025 | AF17: 45870
A18: Not Selected | B18: 6779 | C18: 100222345 | D18: SIDDHARTHA LOGISTICS FTWZ PRIVATE | E18: 2025 | F18: 9 | G18: 45904 | H18: 1800012710 | I18: DR | J18: 45904 | K18: 45909 | L18: NA | M18: 256779417344 | N18: 212100 | O18: Trade Debtors (Ctrl) | Q18: 01 | R18: USD | S18: 100000 | T18: INR | U18: 100000 | V18: O0 | W18: 6779224500 | Y18: 2097261 | Z18: 1 | AA18: =_xlfn.XLOOKUP(M18,'[1]TDS To Be Booked'!$D:$D,'[1]TDS To Be Booked'!$K:$K,,0) -> 1142.6667 | AB18: Fixed Storage Charges for September 2025 | AF18: 45904
A19: Not Selected | B19: 6779 | C19: 100222345 | D19: SIDDHARTHA LOGISTICS FTWZ PRIVATE | E19: 2025 | F19: 10 | G19: 45935 | H19: 1800013251 | I19: DR | J19: 45935 | K19: 45937 | L19: NA | M19: 256779417871 | N19: 212100 | O19: Trade Debtors (Ctrl) | Q19: 01 | R19: USD | S19: 100000 | T19: INR | U19: 100000 | V19: O0 | W19: 6779224500 | Y19: 2110507 | Z19: 1 | AA19: =_xlfn.XLOOKUP(M19,'[1]TDS To Be Booked'!$D:$D,'[1]TDS To Be Booked'!$K:$K,,0) -> 1133.9111 | AB19: Fixed Storage Charges for October 2025 | AF19: 45935
A20: Not Selected | B20: 6779 | C20: 100222345 | D20: SIDDHARTHA LOGISTICS FTWZ PRIVATE | E20: 2025 | F20: 11 | G20: 45966 | H20: 1800014233 | I20: DR | J20: 45966 | K20: 45966 | L20: NA | M20: 256779418773 | N20: 212100 | O20: Trade Debtors (Ctrl) | Q20: 01 | R20: USD | S20: 100000 | T20: INR | U20: 100000 | V20: O0 | W20: 6779224500 | Y20: 2123158 | Z20: 1 | AA20: =_xlfn.XLOOKUP(M20,'[1]TDS To Be Booked'!$D:$D,'[1]TDS To Be Booked'!$K:$K,,0) -> 1136.3222 | AB20: Fixed Storage Charges for November 2025 | AF20: 45966
A21: Not Selected | B21: 6779 | C21: 100222345 | D21: SIDDHARTHA LOGISTICS FTWZ PRIVATE | E21: 2025 | F21: 12 | G21: 45995 | H21: 1800015482 | I21: DR | J21: 45995 | K21: 46000 | L21: NA | M21: 256779419966 | N21: 212100 | O21: Trade Debtors (Ctrl) | Q21: 01 | R21: USD | S21: 100000 | T21: INR | U21: 100000 | V21: O0 | W21: 6779224500 | Y21: 2139804 | Z21: 1 | AA21: =_xlfn.XLOOKUP(M21,'[1]TDS To Be Booked'!$D:$D,'[1]TDS To Be Booked'!$K:$K,,0) -> 1127.3889 | AB21: Fixed Storage Charges for December 2025 | AF21: 45995
A22: Not Selected | B22: 6779 | C22: 100222345 | D22: SIDDHARTHA LOGISTICS FTWZ PRIVATE | E22: 2025 | F22: 3 | G22: 45730 | H22: 1800001820 | I22: DR | J22: 45730 | K22: 45733 | L22: NA | M22: 246779411485 | N22: 212100 | O22: Trade Debtors (Ctrl) | Q22: 01 | R22: USD | S22: 100 | T22: INR | U22: 8669.13 | V22: O0 | W22: 6779224500 | Y22: NA | Z22: 1 | AA22: =S22 -> 100 | AB22: Intra Unit Transfer Charges Month Of August,2024 | AF22: 45730
A23: Not Selected | B23: 6779 | C23: 100222345 | D23: SIDDHARTHA LOGISTICS FTWZ PRIVATE | E23: 2025 | F23: 3 | G23: 45730 | H23: 1800001617 | I23: DR | J23: 45730 | K23: 45735 | L23: NA | M23: 246779412274 | N23: 212100 | O23: Trade Debtors (Ctrl) | Q23: 01 | R23: USD | S23: 100 | T23: INR | U23: 8669.13 | V23: O0 | W23: 6779224500 | Y23: NA | Z23: 1 | AA23: =S23 -> 100 | AB23: Intra Unit Transfer Charges Month Of August,2024 | AF23: 45730
A24: Not Selected | B24: 6779 | C24: 100222345 | D24: SIDDHARTHA LOGISTICS FTWZ PRIVATE | E24: 2025 | F24: 3 | G24: 45720 | H24: 1800000754 | I24: DR | J24: 45720 | K24: 45720 | L24: NA | M24: 246779410694 | N24: 212100 | O24: Trade Debtors (Ctrl) | Q24: 01 | R24: USD | S24: 59.36 | T24: INR | U24: 5145.99 | V24: O0 | W24: 6779224500 | Y24: NA | Z24: 1 | AA24: =S24 -> 59.36 | AB24: Outbound Handling for Oct 2024 | AF24: 45720
A25: Not Selected | B25: 6779 | C25: 100222345 | D25: SIDDHARTHA LOGISTICS FTWZ PRIVATE | E25: 2025 | F25: 3 | G25: 45720 | H25: 1800000915 | I25: DR | J25: 45720 | K25: 45721 | L25: NA | M25: 246779410856 | N25: 212100 | O25: Trade Debtors (Ctrl) | Q25: 01 | R25: USD | S25: 18.32 | T25: INR | U25: 1588.18 | V25: O0 | W25: 6779224500 | Y25: NA | Z25: 1 | AA25: =S25 -> 18.32 | AB25: Outbound Handling for Dec 2024 | AF25: 45720
A26: Not Selected | B26: 6779 | C26: 100222345 | D26: SIDDHARTHA LOGISTICS FTWZ PRIVATE | E26: 2025 | F26: 4 | G26: 45751 | H26: 1800005899 | I26: DR | J26: 45751 | K26: 45752 | L26: NA | M26: 256779410791 | N26: 212100 | O26: Trade Debtors (Ctrl) | Q26: 01 | R26: USD | S26: 441.2 | T26: INR | U26: 38349.91 | V26: O0 | Y26: NA | Z26: 1 | AA26: =S26 -> 441.2 | AB26: Storage Charges Feb, 25 Exch Rate 87.4 | AF26: 45751
A27: Not Selected | B27: 6779 | C27: 100222345 | D27: SIDDHARTHA LOGISTICS FTWZ PRIVATE | E27: 2025 | F27: 4 | G27: 45751 | H27: 1800005916 | I27: DR | J27: 45751 | K27: 45752 | L27: NA | M27: 256779410807 | N27: 212100 | O27: Trade Debtors (Ctrl) | Q27: 01 | R27: USD | S27: 742.7 | T27: INR | U27: 64556.84 | V27: O0 | Y27: NA | Z27: 1 | AA27: =S27 -> 742.7 | AB27: Storage Charges Jan, 25 Exch Rate 86.64 | AF27: 45751
A28: Not Selected | B28: 6779 | C28: 100222345 | D28: SIDDHARTHA LOGISTICS FTWZ PRIVATE | E28: 2025 | F28: 3 | G28: 45722 | H28: 1800000948 | I28: DR | J28: 45722 | K28: 45722 | L28: NA | M28: 246779410888 | N28: 212100 | O28: Trade Debtors (Ctrl) | Q28: 01 | R28: USD | S28: 446.38 | T28: INR | U28: 38697.24 | V28: O0 | W28: 6779224500 | Y28: NA | Z28: 1 | AA28: =S28 -> 446.38 | AB28: Storage Charges for the month of December, 2024 Ex | AF28: 45722
A29: Not Selected | B29: 6779 | C29: 100222345 | D29: SIDDHARTHA LOGISTICS FTWZ PRIVATE | E29: 2025 | F29: 3 | G29: 45722 | H29: 1800000925 | I29: DR | J29: 45722 | K29: 45722 | L29: NA | M29: 246779410865 | N29: 212100 | O29: Trade Debtors (Ctrl) | Q29: 01 | R29: USD | S29: 412.11 | T29: INR | U29: 35726.34 | V29: O0 | W29: 6779224500 | Y29: NA | Z29: 1 | AA29: =S29 -> 412.11 | AB29: Storage Charges for the month of November, 2024 Ex | AF29: 45722
A30: Not Selected | B30: 6779 | C30: 100222345 | D30: SIDDHARTHA LOGISTICS FTWZ PRIVATE | E30: 2025 | F30: 3 | G30: 45722 | H30: 1800001035 | I30: DR | J30: 45722 | K30: 45722 | L30: NA | M30: 246779410975 | N30: 212100 | O30: Trade Debtors (Ctrl) | Q30: 01 | R30: USD | S30: 28.91 | T30: INR | U30: 2506.24 | V30: O0 | W30: 6779224500 | Y30: NA | Z30: 1 | AA30: =S30 -> 28.91 | AB30: Inbound Handling charges for Aug 2024 | AF30: 45722
A31: Not Selected | B31: 6779 | C31: 100222345 | D31: SIDDHARTHA LOGISTICS FTWZ PRIVATE | E31: 2025 | F31: 3 | G31: 45722 | H31: 1800001036 | I31: DR | J31: 45722 | K31: 45722 | L31: NA | M31: 246779410976 | N31: 212100 | O31: Trade Debtors (Ctrl) | Q31: 01 | R31: USD | S31: 24 | T31: INR | U31: 2080.59 | V31: O0 | W31: 6779224500 | Y31: NA | Z31: 1 | AA31: =S31 -> 24 | AB31: Inbound Handling charges for Aug 2024 | AF31: 45722
A32: Not Selected | B32: 6779 | C32: 100222345 | D32: SIDDHARTHA LOGISTICS FTWZ PRIVATE | E32: 2025 | F32: 3 | G32: 45722 | H32: 1800001120 | I32: DR | J32: 45722 | K32: 45723 | L32: NA | M32: 246779411056 | N32: 212100 | O32: Trade Debtors (Ctrl) | Q32: 01 | R32: USD | S32: 59.36 | T32: INR | U32: 5145.99 | V32: O0 | W32: 6779224500 | Y32: NA | Z32: 1 | AA32: =S32 -> 59.36 | AB32: Inbound Handling charges for Sep 2024 | AF32: 45722
A33: Not Selected | B33: 6779 | C33: 100222345 | D33: SIDDHARTHA LOGISTICS FTWZ PRIVATE | E33: 2025 | F33: 3 | G33: 45722 | H33: 1800001121 | I33: DR | J33: 45722 | K33: 45723 | L33: NA | M33: 246779411057 | N33: 212100 | O33: Trade Debtors (Ctrl) | Q33: 01 | R33: USD | S33: 67.67 | T33: INR | U33: 5866.4 | V33: O0 | W33: 6779224500 | Y33: NA | Z33: 1 | AA33: =S33 -> 67.67 | AB33: Inbound Handling charges for Sep 2024 | AF33: 45722
A34: Not Selected | B34: 6779 | C34: 100222345 | D34: SIDDHARTHA LOGISTICS FTWZ PRIVATE | E34: 2025 | F34: 3 | G34: 45722 | H34: 1800001321 | I34: DR | J34: 45722 | K34: 45723 | L34: NA | M34: 246779411190 | N34: 212100 | O34: Trade Debtors (Ctrl) | Q34: 01 | R34: USD | S34: 17.25 | T34: INR | U34: 1495.42 | V34: O0 | W34: 6779224500 | Y34: NA | Z34: 1 | AA34: =S34 -> 17.25 | AB34: Inbound Handling charges for Nov 2024 | AF34: 45722
A35: Not Selected | B35: 6779 | C35: 100222345 | D35: SIDDHARTHA LOGISTICS FTWZ PRIVATE | E35: 2025 | F35: 3 | G35: 45722 | H35: 1800001322 | I35: DR | J35: 45722 | K35: 45723 | L35: NA | M35: 246779411191 | N35: 212100 | O35: Trade Debtors (Ctrl) | Q35: 01 | R35: USD | S35: 26.15 | T35: INR | U35: 2266.98 | V35: O0 | W35: 6779224500 | Y35: NA | Z35: 1 | AA35: =S35 -> 26.15 | AB35: Inbound Handling charges for Nov 2024 | AF35: 45722
A36: Not Selected | B36: 6779 | C36: 100222345 | D36: SIDDHARTHA LOGISTICS FTWZ PRIVATE | E36: 2025 | F36: 3 | G36: 45722 | H36: 1800001384 | I36: DR | J36: 45722 | K36: 45723 | L36: NA | M36: 246779411253 | N36: 212100 | O36: Trade Debtors (Ctrl) | Q36: 01 | R36: USD | S36: 20 | T36: INR | U36: 1733.83 | V36: O0 | W36: 6779224500 | Y36: NA | Z36: 1 | AA36: =S36 -> 20 | AB36: Inbound Handling charges for Dec 2024 | AF36: 45722
A37: Not Selected | B37: 6779 | C37: 100222345 | D37: SIDDHARTHA LOGISTICS FTWZ PRIVATE | E37: 2025 | F37: 10 | G37: 45943 | H37: 1600002430 | I37: DG | J37: 45943 | K37: 45944 | L37: NA | M37: 256779421974 | N37: 212100 | O37: Trade Debtors (Ctrl) | Q37: 11 | R37: USD | S37: -435.91 | T37: INR | U37: -38443.24 | V37: O0 | W37: 6779224500 | Y37: 2112576 | Z37: 1 | AA37: =S37 -> -435.91 | AB37: CN issued against 246779410865 | AF37: 45943
A38: Not Selected | B38: 6779 | C38: 100222345 | D38: SIDDHARTHA LOGISTICS FTWZ PRIVATE | E38: 2025 | F38: 10 | G38: 45943 | H38: 1600002431 | I38: DG | J38: 45943 | K38: 45944 | L38: NA | M38: 256779421975 | N38: 212100 | O38: Trade Debtors (Ctrl) | Q38: 11 | R38: USD | S38: -447.05 | T38: INR | U38: -39425.68 | V38: O0 | W38: 6779224500 | Y38: 2112576 | Z38: 1 | AA38: =S38 -> -447.05 | AB38: CN issued against 246779410888 | AF38: 45943
A39: Selected | B39: 6779 | C39: 100222345 | D39: SIDDHARTHA LOGISTICS FTWZ PRIVATE | E39: 2025 | F39: 10 | G39: 45943 | H39: 1600002438 | I39: DG | J39: 45943 | K39: 45944 | L39: NA | M39: 256779421982 | N39: 212100 | O39: Trade Debtors (Ctrl) | Q39: 11 | R39: USD | S39: -480.02 | T39: INR | U39: -42333.33 | V39: O0 | W39: 6779224500 | Y39: 2112591 | Z39: 1 | AA39: =S39 -> -480.02 | AB39: CN issued against 256779418012 | AF39: 45943 | AG39: 45976 | AH39: 1400001904
A40: Selected | B40: 6779 | C40: 100222345 | D40: SIDDHARTHA LOGISTICS FTWZ PRIVATE | E40: 2025 | F40: 10 | G40: 45943 | H40: 1600002432 | I40: DG | J40: 45943 | K40: 45944 | L40: NA | M40: 256779421976 | N40: 212100 | O40: Trade Debtors (Ctrl) | Q40: 11 | R40: USD | S40: -111.25 | T40: INR | U40: -9811.22 | V40: O0 | W40: 6779224500 | Y40: 2112576 | Z40: 1 | AA40: =S40 -> -111.25 | AB40: CN issued against 246779410368 | AF40: 45943 | AG40: 45976 | AH40: 1400001905
...

Sheet TDS
F1: =SUM(F3:F153) -> 3385.1759
A2: Invoice No | B2: Invoice Date | C2: Debit (USD) | D2: Credit (USD) | E2: Xlookup | F2: TDS | G2: Rate
A3: 246779410007 | B3: 45708 | D3: 1071.43 | E3: =_xlfn.XLOOKUP(A3,'CL Ledger'!$M:$M,'CL Ledger'!$AA:$AA,,0) -> 1190.48 | F3: =E3-D3 -> 119.05 | G3: =F3/E3 -> 0.10000168
A4: 246779410138 | B4: 45708 | D4: 1071.43 | E4: =_xlfn.XLOOKUP(A4,'CL Ledger'!$M:$M,'CL Ledger'!$AA:$AA,,0) -> 1190.48 | F4: =E4-D4 -> 119.05 | G4: =F4/E4 -> 0.10000168
A5: 246779410095 | B5: 45708 | D5: 1071.43 | E5: =_xlfn.XLOOKUP(A5,'CL Ledger'!$M:$M,'CL Ledger'!$AA:$AA,,0) -> 1190.48 | F5: =E5-D5 -> 119.05 | G5: =F5/E5 -> 0.10000168
A6: 246779410274 | B6: 45708 | D6: 1071.43 | E6: =_xlfn.XLOOKUP(A6,'CL Ledger'!$M:$M,'CL Ledger'!$AA:$AA,,0) -> 1190.48 | F6: =E6-D6 -> 119.05 | G6: =F6/E6 -> 0.10000168
A7: 246779410027 | B7: 45708 | D7: 1071.43 | E7: =_xlfn.XLOOKUP(A7,'CL Ledger'!$M:$M,'CL Ledger'!$AA:$AA,,0) -> 1190.48 | F7: =E7-D7 -> 119.05 | G7: =F7/E7 -> 0.10000168
A8: 246779410181 | B8: 45708 | D8: 1049.93 | E8: =_xlfn.XLOOKUP(A8,'CL Ledger'!$M:$M,'CL Ledger'!$AA:$AA,,0) -> 1166.59 | F8: =E8-D8 -> 116.66 | G8: =F8/E8 -> 0.10000086
A9: 246779410224 | B9: 45708 | D9: 1028.81 | E9: =_xlfn.XLOOKUP(A9,'CL Ledger'!$M:$M,'CL Ledger'!$AA:$AA,,0) -> 1143.12 | F9: =E9-D9 -> 114.31 | G9: =F9/E9 -> 0.09999825
A10: 246779410614 | B10: 45719 | D10: 2.2 | E10: =_xlfn.XLOOKUP(A10,'CL Ledger'!$M:$M,'CL Ledger'!$AA:$AA,,0) -> 2.25 | F10: =E10-D10 -> 0.05 | G10: =F10/E10 -> 0.022222222
A11: 246779410615 | B11: 45719 | D11: 8.81 | E11: =_xlfn.XLOOKUP(A11,'CL Ledger'!$M:$M,'CL Ledger'!$AA:$AA,,0) -> 9 | F11: =E11-D11 -> 0.19 | G11: =F11/E11 -> 0.021111111
A12: 246779410511 | B12: 45719 | D12: 13.63 | E12: =_xlfn.XLOOKUP(A12,'CL Ledger'!$M:$M,'CL Ledger'!$AA:$AA,,0) -> 13.91 | F12: =E12-D12 -> 0.28 | G12: =F12/E12 -> 0.020129403
A13: 246779410510 | B13: 45719 | D13: 191 | E13: =_xlfn.XLOOKUP(A13,'CL Ledger'!$M:$M,'CL Ledger'!$AA:$AA,,0) -> 194.9 | F13: =E13-D13 -> 3.9 | G13: =F13/E13 -> 0.020010262
A14: 246779410368 | B14: 45719 | D14: 320.78 | E14: =_xlfn.XLOOKUP(A14,'CL Ledger'!$M:$M,'CL Ledger'!$AA:$AA,,0) -> 356.43 | F14: =E14-D14 -> 35.65 | G14: =F14/E14 -> 0.10001964
... A153: 256779422210 | B153: 46053 | D153: -22.64 | E153: =_xlfn.XLOOKUP(A153,'CL Ledger'!$M:$M,'CL Ledger'!$AA:$AA,,0) -> -22.64 | F153: =E153-D153 -> 0 | G153: =F153/E153 -> 0
D154: =SUM(D3:D153) -> 33836.943 | E154: =SUM(E3:E153) -> 37222.119 | F154: =SUM(F3:F153)+0.31 -> 3385.4859

Sheet Customer ledger
A2: Invoice No | B2: Invoice Dt | C2: Debit (USD) | D2: Credit (USD) | E2: Xlookup | F2: TDS | G2: Rate
A3: 246779410007 | B3: 45708 | D3: 1071.43 | E3: =_xlfn.XLOOKUP(A3,'CL Ledger'!$M:$M,'CL Ledger'!$AA:$AA,,0) -> 1190.48 | F3: =E3-D3 -> 119.05 | G3: =F3/E3 -> 0.10000168
A4: 246779410138 | B4: 45708 | D4: 1071.43 | E4: =_xlfn.XLOOKUP(A4,'CL Ledger'!$M:$M,'CL Ledger'!$AA:$AA,,0) -> 1190.48 | F4: =E4-D4 -> 119.05 | G4: =F4/E4 -> 0.10000168
A5: 246779410095 | B5: 45708 | D5: 1071.43 | E5: =_xlfn.XLOOKUP(A5,'CL Ledger'!$M:$M,'CL Ledger'!$AA:$AA,,0) -> 1190.48 | F5: =E5-D5 -> 119.05 | G5: =F5/E5 -> 0.10000168
A6: 246779410274 | B6: 45708 | D6: 1071.43 | E6: =_xlfn.XLOOKUP(A6,'CL Ledger'!$M:$M,'CL Ledger'!$AA:$AA,,0) -> 1190.48 | F6: =E6-D6 -> 119.05 | G6: =F6/E6 -> 0.10000168
A7: 246779410027 | B7: 45708 | D7: 1071.43 | E7: =_xlfn.XLOOKUP(A7,'CL Ledger'!$M:$M,'CL Ledger'!$AA:$AA,,0) -> 1190.48 | F7: =E7-D7 -> 119.05 | G7: =F7/E7 -> 0.10000168
A8: 246779410181 | B8: 45708 | D8: 1049.93 | E8: =_xlfn.XLOOKUP(A8,'CL Ledger'!$M:$M,'CL Ledger'!$AA:$AA,,0) -> 1166.59 | F8: =E8-D8 -> 116.66 | G8: =F8/E8 -> 0.10000086
A9: 246779410224 | B9: 45708 | D9: 1028.81 | E9: =_xlfn.XLOOKUP(A9,'CL Ledger'!$M:$M,'CL Ledger'!$AA:$AA,,0) -> 1143.12 | F9: =E9-D9 -> 114.31 | G9: =F9/E9 -> 0.09999825
A10: 246779410614 | B10: 45719 | D10: 2.2 | E10: =_xlfn.XLOOKUP(A10,'CL Ledger'!$M:$M,'CL Ledger'!$AA:$AA,,0) -> 2.25 | F10: =E10-D10 -> 0.05 | G10: =F10/E10 -> 0.022222222
A11: 246779410615 | B11: 45719 | D11: 8.81 | E11: =_xlfn.XLOOKUP(A11,'CL Ledger'!$M:$M,'CL Ledger'!$AA:$AA,,0) -> 9 | F11: =E11-D11 -> 0.19 | G11: =F11/E11 -> 0.021111111
A12: 246779410511 | B12: 45719 | D12: 13.63 | E12: =_xlfn.XLOOKUP(A12,'CL Ledger'!$M:$M,'CL Ledger'!$AA:$AA,,0) -> 13.91 | F12: =E12-D12 -> 0.28 | G12: =F12/E12 -> 0.020129403
A13: 246779410510 | B13: 45719 | D13: 191 | E13: =_xlfn.XLOOKUP(A13,'CL Ledger'!$M:$M,'CL Ledger'!$AA:$AA,,0) -> 194.9 | F13: =E13-D13 -> 3.9 | G13: =F13/E13 -> 0.020010262
A14: 246779410368 | B14: 45719 | D14: 320.78 | E14: =_xlfn.XLOOKUP(A14,'CL Ledger'!$M:$M,'CL Ledger'!$AA:$AA,,0) -> 356.43 | F14: =E14-D14 -> 35.65 | G14: =F14/E14 -> 0.10001964
... A153: 256779422210 | B153: 46053 | D153: -22.64 | E153: =_xlfn.XLOOKUP(A153,'CL Ledger'!$M:$M,'CL Ledger'!$AA:$AA,,0) -> -22.64 | F153: =E153-D153 -> 0 | G153: =F153/E153 -> 0
A154: Outgoing payment | B154: 45800 | C154: 7435.89
A155: Outgoing payment | B155: 45856 | C155: 4602.99
A156: Outgoing payment | B156: 45945 | C156: 4875.15
A157: Outgoing payment | B157: 46053 | C157: 10721.42
C158: =SUM(C3:C157) -> 27635.45 | D158: =SUM(D3:D157) -> 33836.943 | E158: =D158-C158 -> 6201.493

Sheet Invoice Not in Customer Book
A1: Document Number | B1: Document Type | C1: Document Date | D1: Entry Date | E1: Document Header Text | F1: Reference | G1: Document Currency Key | H1: Document Currency Value | I1: Company Code Currency Key | J1: Company Code Currency Value | K1: Text | L1: Remark | M1: Remarks | N1: Action Points
A2: 1800001617 | B2: DR | C2: 45730 | D2: 45735 | E2: NA | F2: 246779412274 | G2: USD | H2: 100 | I2: INR | J2: 8669.13 | K2: Intra Unit Transfer Charges Month Of August,2024 | L2: We had given 2 invoices against BOE No. 7000274, and we accepted invoice 246779411485. | M2: Credit Note to be passed after verification by billing team | N2: Credit Note to be passed as discussed with CL team
A3: 1800000559 | B3: DR | C3: 45719 | D3: 45719 | E3: NA | F3: 246779410509 | G3: USD | H3: 29.25 | I3: INR | J3: 2535.72 | K3: Outbound Handling for Aug 2024 | L3: you have made an Invoice of Handling Charges 13 Plt instead of 4 Plt. | M3: CRM team will handle | N3: to be accounted by siddhartha
A4: 1800006698 | B4: DR | C4: 45762 | D4: 45763 | E4: NA | F4: 256779411589 | G4: USD | H4: 3.38 | I4: INR | J4: 293.8 | K4: Outbound Handling Charges Aug 2024 | L4: Handling Charges CBM Rate is 2.25 but you have Handling Charges CBM Rate is 3.24 | M4: CRM team will handle | N4: To be discussed with customer that the rate is charged as per agreemant for HAZ goods
A5: 1800001791 | B5: DR | C5: 45730 | D5: 45733 | E5: NA | F5: 246779411456 | G5: USD | H5: 4.77 | I5: INR | J5: 413.52 | K5: VAS Activity Charges for the month of August, 24 | L5: Duplicated invoice | M5: Credit Note to be passed after verification by billing team | N5: Credit Note to be passed as discussed with CL team
A6: 1800012462 | B6: DR | C6: 45904 | D6: 45909 | E6: NA | F6: 256779417162 | G6: USD | H6: 44.74 | I6: INR | J6: 3915.39 | K6: VAS -16-31 Aug 25 | L6: The VAS charges are incorrect. | M6: Invoice to changed by CRM team | N6: Credit Note to be passed as discussed with CL team
A7: 1800014290 | B7: DR | C7: 45966 | D7: 45967 | E7: NA | F7: 256779418827 | G7: USD | H7: 60.86 | I7: INR | J7: 5355.89 | K7: WEIGHTMENT-16 -31 Oct 25 | L7: These specific charges are not included in our existing contract. | N7: Credit Note to be passed as discussed with CL team
A8: 1800004532 | B8: DR | C8: 45736 | D8: 45737 | E8: NA | F8: 246779414400 | G8: USD | H8: 80.95 | I8: INR | J8: 7017.66 | K8: Inbound Handling charges for Nov 2024 | L8: Handling Charges CBM Rate is 2.25 but you have Handling Charges CBM Rate is 3.24 | M8: CRM team will handle | N8: To be discussed with customer that the rate is charged as per agreemant for HAZ goods
A9: 1800004533 | B9: DR | C9: 45736 | D9: 45737 | E9: NA | F9: 246779414401 | G9: USD | H9: 15 | I9: INR | J9: 1300.37 | K9: LCL Movement Charges for Nov 2024 | M9: Amount in Invoice to be verified by biling team | N9: to be accounted by siddhartha
A10: 1800013760 | B10: DR | C10: 45937 | D10: 45939 | E10: NA | F10: 256779418181 | G10: USD | H10: 49.33 | I10: INR | J10: 4350.45 | K10: VAS-16-30 Sept 25 | L10: This is to inform you that MHE charges have already been applied in Invoice Nos. 256779418354 and 256779418342. However, the same MHE charges have been included again in Invoice No. 256779418181. | M10: to be accounted by siddhartha after CBM rate issue is solved | N10: Credit Note to be passed as discussed with CL team
A11: 1800009470 | B11: DR | C11: 45815 | D11: 45817 | E11: NA | F11: 256779414234 | G11: USD | H11: 925.23 | I11: INR | J11: 79098.63 | K11: Unit storage -1-31 May 25 | L11: Credit Note Pending | M11: mail summary will be sent by Siddhartha team ,Credit Note to be passed after verification by billing team | N11: Credit Note to be passed as discussed with CL team | O11: 149 | P11: 22.64
A12: 1800013511 | B12: DR | C12: 45935 | D12: 45940 | E12: NA | F12: 256779418401 | G12: USD | H12: 62.52 | I12: INR | J12: 5513.69 | K12: PORT SSR Chgs Sep 25 | L12: These specific charges are not included in our existing contract. | M12: to be accounted by siddhartha | N12: to be accounted by siddhartha
H13: =SUM(H2:H12) -> 1376.03 | J13: =SUBTOTAL(9,J2:J12) -> 118464.25

Sheet Payment Reco
A2: As per Customer | D2: As per Ascendus
A3: Payment Date | B3: Particulars | C3: Amount | D3: Particulars | E3: Date | G3: Amount | H3: TDS | I3: Bank Charges
A4: 45800 | B4: Outgoing payment | C4: 7435.89 | D4: DZ | E4: 45862 | F4: USD | G4: -8262.11 | H4: =C4+G4 -> -826.22
A5: 45856 | B5: Outgoing payment | C5: 4602.99 | D5: DZ | E5: 45891 | F5: USD | G5: -4582.99 | I5: =C5+G5 -> 20
A6: 45945 | B6: Outgoing payment | C6: 4875.15 | D6: DZ | E6: 45955 | F6: USD | G6: -4875.15 | I6: =C6+G6 -> 0
B7: Outgoing payment | C7: 10721.42 | D7: DZ | E7: 46050 | F7: USD | G7: -10691.42 | I7: =C7+G7 -> 30
C8: =SUM(C4:C7) -> 27635.45 | G8: =SUM(G4:G7) -> -28411.67 | H8: =SUM(H4:H7) -> -826.22 | I8: =SUM(I5:I7) -> 50
