Workbook

Sheet Ascendus DATA
A1: Customer Account: Name 1 | B1: Fiscal Year | C1: Posting Date | D1: Document Type | E1: Document Date | F1: Reference | G1: Document Currency Key | H1: Document Currency Value | I1: Company Code Currency Key | J1: Company Code Currency Value | K1: Text
A2: KUEHNE+NAGEL PVT. LTD. | B2: 2025 | C2: 45848 | D2: DG | E2: 45848 | F2: 256779421326 | G2: USD | H2: -70.8 | I2: INR | J2: -6088.85 | K2: Credit note raised against INV 256779414309
A3: KUEHNE+NAGEL PVT. LTD. | B3: 2025 | C3: 45848 | D3: DG | E3: 45848 | F3: 256779421327 | G3: USD | H3: -113.28 | I3: INR | J3: -9742.16 | K3: Credit note raised against INV 256779414309
A4: KUEHNE+NAGEL PVT. LTD. | B4: 2025 | C4: 45848 | D4: DG | E4: 45848 | F4: 256779421328 | G4: USD | H4: -242.75 | I4: INR | J4: -20876.66 | K4: Credit note raised against INV 256779414309
A5: KUEHNE+NAGEL PVT. LTD. | B5: 2025 | C5: 45904 | D5: DR | E5: 45904 | F5: 256779416909 | G5: USD | H5: 989.55 | I5: INR | J5: 86599.81 | K5: CODC Inbound chgs - 16-31 Aug 25
A6: KUEHNE+NAGEL PVT. LTD. | B6: 2025 | C6: 45904 | D6: DR | E6: 45904 | F6: 256779417134 | G6: USD | H6: 536.44 | I6: INR | J6: 46946.19 | K6: VAS - 16-31 Aug 25
A7: KUEHNE+NAGEL PVT. LTD. | B7: 2025 | C7: 45904 | D7: DR | E7: 45904 | F7: 256779417137 | G7: USD | H7: 409.79 | I7: INR | J7: 35862.5 | K7: WEIGHMENT - 16-31 Aug 25
A8: KUEHNE+NAGEL PVT. LTD. | B8: 2025 | C8: 45904 | D8: DR | E8: 45904 | F8: 256779417158 | G8: USD | H8: 110 | I8: INR | J8: 9626.58 | K8: Intra 16-31 Aug 25
A9: KUEHNE+NAGEL PVT. LTD. | B9: 2025 | C9: 45904 | D9: DR | E9: 45904 | F9: 256779417200 | G9: USD | H9: 100.74 | I9: INR | J9: 8816.19 | K9: Empty Lolo Chgs - 01 - 31 AUG 25
A10: KUEHNE+NAGEL PVT. LTD. | B10: 2025 | C10: 45904 | D10: DR | E10: 45904 | F10: 256779417238 | G10: USD | H10: 608.78 | I10: INR | J10: 53276.97 | K10: PORT SSR Chgs Aug 25
A11: KUEHNE+NAGEL PVT. LTD. | B11: 2025 | C11: 45904 | D11: DR | E11: 45904 | F11: 256779417250 | G11: USD | H11: 50 | I11: INR | J11: 4375.72 | K11: Scanning Chgs - 16 - 31 Aug 25
A12: KUEHNE+NAGEL PVT. LTD. | B12: 2025 | C12: 45904 | D12: DR | E12: 45904 | F12: 256779417257 | G12: USD | H12: 22.77 | I12: INR | J12: 1992.7 | K12: Bond Stamp Paper Chgs 01 - 31 Aug 25
A13: KUEHNE+NAGEL PVT. LTD. | B13: 2025 | C13: 45904 | D13: DR | E13: 45904 | F13: 256779417280 | G13: USD | H13: 249.98 | I13: INR | J13: 21876.83 | K13: LCL Chgs - 16 - 31 AUG 25
... A263: KUEHNE+NAGEL PVT. LTD. | B263: 2026 | C263: 46027 | D263: DR | E263: 46027 | F263: 256779440116 | G263: USD | H263: 498.28 | I263: INR | J263: 45215.49 | K263: LCL Chgs - 01 - 15 DEC 25
A264: KUEHNE+NAGEL PVT. LTD. | B264: 2026 | C264: 46030 | D264: DZ | E264: 46030 | G264: INR | H264: -719881.09 | I264: INR | J264: -719881.09
A265: KUEHNE+NAGEL PVT. LTD. | B265: 2026 | C265: 46031 | D265: DR | E265: 46031 | F265: 256779440126 | G265: USD | H265: 122.48 | I265: INR | J265: 11114.22 | K265: CODC Out chgs -1-15 Nov 25
A266: KUEHNE+NAGEL PVT. LTD. | B266: 2026 | C266: 46031 | D266: DR | E266: 46031 | F266: 256779440136 | G266: USD | H266: 27.81 | I266: INR | J266: 2523.57 | K266: Internet Activity Chgs - Dec 25
A267: KUEHNE+NAGEL PVT. LTD. | B267: 2026 | C267: 46028 | D267: DR | E267: 46028 | F267: 256779440150 | G267: USD | H267: 112.85 | I267: INR | J267: 10240.36 | K267: Empty Lolo Chgs - 01 - 31 DEC 25
A268: KUEHNE+NAGEL PVT. LTD. | B268: 2026 | C268: 46028 | D268: DR | E268: 46028 | F268: 256779440159 | G268: USD | H268: 160.22 | I268: INR | J268: 14538.87 | K268: PORT SSR Chgs Dec 25
A269: KUEHNE+NAGEL PVT. LTD. | B269: 2026 | C269: 46028 | D269: DR | E269: 46028 | F269: 256779440208 | G269: USD | H269: 650.12 | I269: INR | J269: 58993.93 | K269: LCL Chgs - 16 - 31 DEC 25
A270: KUEHNE+NAGEL PVT. LTD. | B270: 2026 | C270: 46034 | D270: DR | E270: 46034 | F270: 256779440227 | G270: USD | H270: 304.07 | I270: INR | J270: 27592.27 | K270: Outbound chgs - 16 - 31 Dec 25
A271: KUEHNE+NAGEL PVT. LTD. | B271: 2026 | C271: 46028 | D271: DR | E271: 46028 | F271: 256779440238 | G271: USD | H271: 1083.58 | I271: INR | J271: 98327.45 | K271: Unit Storage - 1-31 DEC 2025
A272: KUEHNE+NAGEL PVT. LTD. | B272: 2026 | C272: 46034 | D272: DR | E272: 46034 | F272: 256779440285 | G272: USD | H272: 535.29 | I272: INR | J272: 48573.9 | K272: VAS-Dec 25 - 16-31
A273: KUEHNE+NAGEL PVT. LTD. | B273: 2026 | C273: 46028 | D273: DR | E273: 46028 | F273: 256779440309 | G273: INR | H273: 200000 | I273: INR | J273: 200000 | K273: Fixed Storage Charges for January 2026
A274: KUEHNE+NAGEL PVT. LTD. | B274: 2026 | C274: 46028 | D274: DR | E274: 46028 | F274: 256779440310 | G274: INR | H274: 8000 | I274: INR | J274: 8000 | K274: Fixed Storage Charges for January 2026
A275: KUEHNE+NAGEL PVT. LTD. | B275: 2026 | C275: 46028 | D275: DR | E275: 46028 | F275: 256779440311 | G275: INR | H275: 4400 | I275: INR | J275: 4400 | K275: Fixed Storage Charges for January 2026
A276: KUEHNE+NAGEL PVT. LTD. | B276: 2026 | C276: 46035 | D276: DR | E276: 46035 | F276: 256779440363 | G276: USD | H276: 937.45 | I276: INR | J276: 85067.16 | K276: VAS - NOV 25,16-30
... A565: KUEHNE+NAGEL PVT. LTD. | B565: 2025 | C565: 45848 | D565: DR | E565: 45848 | F565: 256779415363 | G565: USD | H565: 3 | I565: INR | J565: 258 | K565: Outbound Handling for Aug 2024
A566: KUEHNE+NAGEL PVT. LTD. | B566: 2025 | C566: 45861 | D566: DZ | E566: 45861 | G566: USD | H566: 0 | I566: INR | J566: 0
A567: KUEHNE+NAGEL PVT. LTD. | B567: 2025 | C567: 45861 | D567: DZ | E567: 45861 | G567: USD | H567: 0 | I567: INR | J567: 0
A568: KUEHNE+NAGEL PVT. LTD. | B568: 2025 | C568: 45861 | D568: DZ | E568: 45861 | G568: USD | H568: 0 | I568: INR | J568: 0
A569: KUEHNE+NAGEL PVT. LTD. | B569: 2025 | C569: 45861 | D569: DZ | E569: 45861 | G569: USD | H569: 0 | I569: INR | J569: 0
A570: KUEHNE+NAGEL PVT. LTD. | B570: 2025 | C570: 45861 | D570: DZ | E570: 45861 | G570: USD | H570: 0 | I570: INR | J570: 0
A571: KUEHNE+NAGEL PVT. LTD. | B571: 2025 | C571: 45861 | D571: DZ | E571: 45861 | G571: USD | H571: 0 | I571: INR | J571: 0
A572: KUEHNE+NAGEL PVT. LTD. | B572: 2025 | C572: 45861 | D572: DZ | E572: 45861 | G572: USD | H572: 0 | I572: INR | J572: 0
A573: KUEHNE+NAGEL PVT. LTD. | B573: 2025 | C573: 45758 | D573: DA | E573: 45758 | G573: INR | H573: 1 | I573: INR | J573: 1 | K573: Overpayment
A574: KUEHNE+NAGEL PVT. LTD. | B574: 2025 | C574: 45758 | D574: DA | E574: 45758 | G574: INR | H574: -1 | I574: INR | J574: -1 | K574: Overpayment
A575: KUEHNE+NAGEL PVT. LTD. | B575: 2025 | C575: 45902 | D575: DY | E575: 45902 | G575: INR | H575: 212521.54 | I575: INR | J575: 208845.74
A576: KUEHNE+NAGEL PVT. LTD. | B576: 2025 | C576: 45902 | D576: DY | E576: 45902 | G576: INR | H576: -212521.54 | I576: INR | J576: -207607.52
A577: KUEHNE+NAGEL PVT. LTD. | B577: 2025 | C577: 45974 | D577: DZ | E577: 45974 | G577: USD | H577: 4603.48 | I577: INR | J577: 396450.85
...

Sheet Summary 
A2: Reconciliation of Ledger as on 31st January 2026
A3: Particulars | B3: Amount
A4: Balance as per Kuehne Nagel Pvt Ltd | B4: =-'CUSTOMER DATA'!Y1 -> -10371172
A5: Add: TDS recorded by customer but not in our books | B5: ='CUSTOMER DATA'!X1 -> 0
A6: Add: Corrections to be done by customer | B6: ='Corrections to be done by custo'!AB1 -> 102752.19
A7: Less: Amount recorded by customer, but not in our books due to exchange gain | B7: -111936.53
A8: Less: Difference in INR amounts in both books due to exchange rate | B8: =-63698.83-45403 -> -109101.83
A9: Add: Invoices / CN not recorded in customer books | B9: ='Invoices not in customer''s Book'!H20 -> 1181419.2 | C9: To be discussed with customer
A10: Add: Payments recorded in Feb by Ascendus | B10: =('Payment Reco'!E21+'Payment Reco'!E22) -> 1878132.8 | C10: Confirmed by Sushil over call
A11: Derived balance | B11: =SUM(B4:B10) -> -7429906.4
A12: Balance as per Ascendus | B12: =[1]Sheet1!$T$709 -> 6321328.8
A14: Difference | B14: =B11-B12-B13 -> -13751235

Sheet Corrections to be done by custo
AB1: =SUM(AB3:AB5) -> 102752.19
A2: Creditor Code | B2: Creditor | C2: Ty | D2: Item# | E2: Item Date | F2: CCY | G2: FC Amount | H2: Settled FC Amount | I2: LC Amount | J2: Particular | K2: Due Date | L2: Last Sett. Date | M2: Job# | N2: VC Period | O2: VC# | P2: VC Seq | Q2: VC Date | R2: Tx. Type | S2: Reference | T2: Full Name | U2: Settled LC Amount | X2: TDS | Y2: Net balance | Z2: Remarks | AA2: vlookup | AB2: Difference
A3: A023951 | B3: A023951 | C3: I | D3: 256779410262 | E3: 45750 | F3: INR | G3: - | H3: - | I3: -93.33 | J3: NO EXCHANGE RATE | K3: 45780 | L3: 45939 | M3: - | N3: 45809 | O3: 51171858 | P3: 1 | Q3: 45820 | R3: 210 | S3: 1.55e+16 | T3: Ascendas Panvel FTWZ Private Limited | U3: 2 | W3: -0.021429337 | X3: 2 | Y3: -91.33 | Z3: Customer recorded USD amount in INR amount. Customer needs to correct | AA3: 8112.41 | AB3: 8019.08
A4: A023951 | B4: A023951 | C4: I | D4: 256779410263 | E4: 45750 | F4: INR | G4: - | H4: - | I4: -51.33 | J4: NO EXCHANGE RATE | K4: 45780 | L4: 45939 | M4: - | N4: 45809 | O4: 51171949 | P4: 1 | Q4: 45820 | R4: 210 | S4: 1.55e+16 | T4: Ascendas Panvel FTWZ Private Limited | U4: 2 | W4: -0.038963569 | X4: 2 | Y4: -49.33 | Z4: Customer recorded USD amount in INR amount. Customer needs to correct | AA4: 4461.7 | AB4: 4410.37
A5: A023951 | B5: A023951 | C5: I | D5: 256779412012 | E5: 45763 | F5: INR | G5: - | H5: - | I5: -1051.22 | J5: NO EXCHANGE RATE | K5: 45793 | L5: 45820 | M5: - | N5: 45809 | O5: 51171953 | P5: 1 | Q5: 45820 | R5: 210 | S5: 1.55e+16 | T5: Ascendas Panvel FTWZ Private Limited | U5: 22 | W5: -0.020928065 | X5: 22 | Y5: -1029.22 | Z5: Customer recorded USD amount in INR amount. Customer needs to correct | AA5: 91373.96 | AB5: 90322.74

Sheet Biling Reco
A1: As per Customer | G1: As per Ascendus
A2: Years | B2: Item Date | C2: Debit Note | D2: Expense | E2: Foreign Exchange Diffrence | F2: Net Amount | G2: Years | H2: Document Date | I2: Credit | J2: Expense | K2: Net Amount | L2: Diffrence
A3: 2025 | B3: Jan | D3: -217492.45 | F3: =SUM(C3:E3) -> -217492.45 | G3: 2025 | H3: Jan | K3: =SUM(I3:J3) -> 0 | L3: =K3+F3 -> -217492.45
A4: 2025 | B4: Feb | D4: -1520432.9 | F4: =SUM(C4:E4) -> -1520432.9 | G4: 2025 | H4: Feb | J4: 1514515.3 | K4: =SUM(I4:J4) -> 1514515.3 | L4: =K4+F4 -> -5917.55
A5: 2025 | B5: Mar | C5: 21719.38 | D5: -1191118 | F5: =SUM(C5:E5) -> -1169398.7 | G5: 2025 | H5: Mar | J5: 1933380.6 | K5: =SUM(I5:J5) -> 1933380.6 | L5: =K5+F5 -> 763981.97
A6: 2025 | B6: Apr | D6: -2932698.5 | F6: =SUM(C6:E6) -> -2932698.5 | G6: 2025 | H6: Apr | J6: 2087965.7 | K6: =SUM(I6:J6) -> 2087965.7 | L6: =K6+F6 -> -844732.75
A7: 2025 | B7: May | D7: -1341898.7 | F7: =SUM(C7:E7) -> -1341898.7 | G7: 2025 | H7: May | I7: -595574.41 | J7: 1044919.9 | K7: =SUM(I7:J7) -> 449345.53 | L7: =K7+F7 -> -892553.19
A8: 2025 | B8: Jun | D8: -796400.32 | F8: =SUM(C8:E8) -> -796400.32 | G8: 2025 | H8: Jun | J8: 1761603.8 | K8: =SUM(I8:J8) -> 1761603.8 | L8: =K8+F8 -> 965203.51
A9: 2025 | B9: Jul | D9: -266105.72 | F9: =SUM(C9:E9) -> -266105.72 | G9: 2025 | H9: Jul | I9: -1464659.3 | J9: 2492881.5 | K9: =SUM(I9:J9) -> 1028222.2 | L9: =K9+F9 -> 762116.44
A10: 2025 | B10: Aug | D10: -937708 | F10: =SUM(C10:E10) -> -937708 | G10: 2025 | H10: Aug | I10: -170239.97 | J10: 1305423 | K10: =SUM(I10:J10) -> 1135183.1 | L10: =K10+F10 -> 197475.05
A11: 2025 | B11: Sep | C11: 16556.76 | D11: -673577.15 | F11: =SUM(C11:E11) -> -657020.39 | G11: 2025 | H11: Sep | J11: =1564779.07+1238.22 -> 1566017.3 | K11: =SUM(I11:J11) -> 1566017.3 | L11: =K11+F11 -> 908996.9
A12: 2025 | B12: Oct | D12: -1793002.9 | F12: =SUM(C12:E12) -> -1793002.9 | G12: 2025 | H12: Oct | I12: -8361.37 | J12: 1113806.7 | K12: =SUM(I12:J12) -> 1105445.3 | L12: =K12+F12 -> -687557.56
A13: 2025 | B13: Nov | D13: -80394.56 | F13: =SUM(C13:E13) -> -80394.56 | G13: 2025 | H13: Nov | I13: -405590.02 | J13: 1574052.7 | K13: =SUM(I13:J13) -> 1168462.7 | L13: =K13+F13 -> 1088068.1
A14: 2025 | B14: Dec | F14: =SUM(C14:E14) -> 0 | G14: 2025 | H14: Dec | J14: 282835.01 | K14: =SUM(I14:J14) -> 282835.01 | L14: =K14+F14 -> 282835.01
A15: 2026 | B15: Jan | E15: -45403 | F15: =SUM(C15:E15) -> -45403 | G15: 2026 | H15: Jan | I15: -52265.33 | J15: 831546.81 | K15: =SUM(I15:J15) -> 779281.48 | L15: =K15+F15 -> 733878.48
A16: Total | C16: =SUM(C3:C15) -> 38276.14 | D16: =SUM(D3:D15) -> -11750829 | E16: =SUM(E3:E15) -> -45403 | F16: =SUM(C16:E16) -> -11757956 | G16: Total | I16: =SUM(I3:I15) -> -2696690.4 | J16: =SUM(J3:J15) -> 17508948 | K16: =SUM(I16:J16) -> 14812258 | L16: =K16+F16 -> 3054302
D18: =J16+D16 -> 5758119.3

Sheet Payment Reco
A1: As per Customer ledger | C1: As per Ascendus | E1: Amount
A2: Date | B2: Amount | C2: Date | D2: Amount | J2: As per Customer ledger | K2: As per Ascendus
A3: 45827 | B3: 1760137.8 | C3: 45940 | D3: -1746430.2 | E3: =B3+D3 -> 13707.54 | F3: >>Exchange diffrence | H3: 2025 | I3: Jan
A4: 45859 | B4: 2396201.3 | C4: 45940 | D4: -2385234 | E4: =B4+D4 -> 10967.32 | F4: >>Exchange diffrence | H4: 2025 | I4: Feb
A5: 45859 | B5: 2396201.3 | E5: =B5+D5 -> 2396201.3 | H5: 2025 | I5: May
A6: 45869 | B6: -2396201.3 | E6: =B6+D6 -> -2396201.3 | H6: 2025 | I6: June | J6: =B3 -> 1760137.8
A7: 45954 | B7: 1721315.8 | C7: 45958 | D7: -1719090.9 | E7: =B7+D7 -> 2224.91 | F7: >>Exchange diffrence | H7: 2025 | I7: July | J7: =B4 -> 2396201.3
C8: 45974 | D8: 396450.85 | E8: =B8+D8 -> 396450.85 | H8: 2025 | I8: Aug
C9: 45974 | D9: 262.21 | E9: =B9+D9 -> 262.21 | H9: 2025 | I9: Sep
C10: 45974 | D10: -262.21 | E10: =B10+D10 -> -262.21 | H10: 2025 | I10: Oct | J10: 1721315.8 | K10: -5850755.1
C11: 45974 | D11: 478086.37 | E11: =B11+D11 -> 478086.37 | H11: 2025 | I11: Nov | J11: 1899719.6 | K11: -1920293.1
C12: 45974 | D12: -338298.81 | E12: =B12+D12 -> -338298.81 | H12: 2025 | I12: Dec | J12: 715665.04
C13: 45974 | D13: -536832.3 | E13: =B13+D13 -> -536832.3 | H13: 2026 | I13: Jan | J13: 1878132.8 | K13: -719881.09
C14: 45974 | D14: 75771.03 | E14: =B14+D14 -> 75771.03 | H14: Total | J14: =SUM(J3:J13) -> 10371172 | K14: =SUM(K3:K13) -> -8490929.3 | L14: =SUM(J14:K14) -> 1880243
C15: 45974 | D15: -20130.78 | E15: =B15+D15 -> -20130.78
C16: 45974 | D16: -746.27 | E16: =B16+D16 -> -746.27
C17: 45974 | D17: -24772.95 | E17: =B17+D17 -> -24772.95
C18: 45974 | D18: -31858.99 | E18: =B18+D18 -> -31858.99
A19: 45982 | B19: 1899719.6 | C19: 45987 | D19: -1917961.2 | E19: =B19+D19 -> -18241.69 | F19: >>Exchange diffrence
A20: 46014 | B20: 715665.04 | C20: 46030 | D20: -719881.09 | E20: =B20+D20 -> -4216.05 | F20: >>Exchange diffrence
A21: 46052 | B21: 1869680.8 | E21: =B21+D21 -> 1869680.8 | F21: >>payment not recorded in books
A22: 46053 | B22: 8452 | E22: =B22+D22 -> 8452 | F22: >>payment not recorded in books
B23: =SUM(B3:B22) -> 10371172 | D23: =SUM(D3:D21) -> -8490929.3 | E23: =SUM(E3:E22) -> 1880243

Sheet Pivot data
A3: Sum of LC Amount | D3: Ty
A4: Years | B4: Quarters | C4: Item Date | D4: A | E4: C | F4: I | G4: S
A5: 2025 | B5: Qtr1 | C5: Jan | F5: -217492.45
C6: Feb | F6: -1520432.9
C7: Mar | E7: 21719.38 | F7: -1191118
B8: Qtr2 | C8: Apr | F8: -2932698.5
C9: May | F9: -1341898.7
C10: Jun | D10: 1760137.8 | F10: -796400.32
B11: Qtr3 | C11: Jul | D11: 2396201.3 | F11: -266105.72
C12: Aug | F12: -937708
C13: Sep | E13: 16556.76 | F13: -673577.15
B14: Qtr4 | C14: Oct | D14: 1721315.8 | F14: -1793002.9
C15: Nov | D15: 1899719.6 | F15: -80394.56
C16: Dec | D16: 715665.04
A17: 2026 | B17: Qtr1 | C17: Jan | D17: 1878132.8 | G17: -45403

Sheet Invoices not in customer's Book
A1: Document Number | B1: Document Type | C1: Document Date | D1: Reference | E1: Document Currency Key | F1: Document Currency Value | G1: Company Code Currency Key | H1: Company Code Currency Value | I1: Assignment | J1: Item | K1: Text | L1: Clearing Document | N1: Remarks from customers
A2: 1800013764 | B2: DR | C2: 45937 | D2: 256779418185 | E2: USD | F2: 405.44 | G2: INR | H2: 35756.07 | I2: 2110802 | J2: 1 | K2: Weighment-16-30 Sept 25 | N2: Invoice under booking
A3: 1800009489 | B3: DR | C3: 45815 | D3: 256779414253 | E3: USD | F3: 9947.26 | G3: INR | H3: 850399.02 | I3: NA | J3: 1 | K3: Unit storage -1-31 May 25 | N3: Invoice under booking
A4: 1800015955 | B4: DR | C4: 46027 | D4: 256779440078 | E4: USD | F4: 78.75 | G4: INR | H4: 7146.02 | I4: NA | J4: 1 | K4: Outbound chgs - 01 - 15 Dec 25 | N4: Invoice not received
A5: 1800016933 | B5: DR | C5: 46043 | D5: 256779440381 | E5: USD | F5: 6.79 | G5: INR | H5: 616.15 | I5: NA | J5: 1 | K5: CODC Out chgs -1-15 JAN 26 | N5: Invoice not received
A6: 1800016874 | B6: DR | C6: 46043 | D6: 256779440388 | E6: USD | F6: 57.29 | G6: INR | H6: 5198.67 | I6: 2163060 | J6: 1 | K6: CODC LCL Chgs -1-15 JAN 26 | N6: Invoice not received
A7: 1800017058 | B7: DR | C7: 46045 | D7: 256779440411 | E7: USD | F7: 554.49 | G7: INR | H7: 50316.16 | I7: NA | J7: 1 | K7: LCL Chgs - 01 - 15 JAN 26 | N7: Invoice not received
A8: 1800017100 | B8: DR | C8: 46045 | D8: 256779440427 | E8: USD | F8: 44.06 | G8: INR | H8: 3998.14 | I8: NA | J8: 1 | K8: Outbound chgs - 01 - 15 JAN 26 | N8: Invoice not received
A9: 1800017150 | B9: DR | C9: 46049 | D9: 256779440443 | E9: USD | F9: 18.41 | G9: INR | H9: 1670.58 | I9: NA | J9: 1 | K9: VAS-1-15 Jan 2026 | N9: Invoice not received
A10: 1800014279 | B10: DR | C10: 45966 | D10: 256779418816 | E10: USD | F10: 891 | G10: INR | H10: 78411.02 | I10: 2123387 | J10: 1 | K10: VAS-16 -31 Oct 25 | N10: Invoice under booking
A11: 1800010603 | B11: DR | C11: 45848 | D11: 256779415363 | E11: USD | F11: 3 | G11: INR | H11: 258 | I11: NA | J11: 1 | K11: Outbound Handling for Aug 2024 | N11: Invoice under booking
A12: 1800011944 | B12: DR | C12: 45889 | D12: 256779416593 | E12: USD | F12: 810 | G12: INR | H12: 69684.4 | I12: NA | J12: 1 | K12: Empty Cont Out Chgs - 16 - 31 Jul 25 | N12: Invoice under booking
A13: 1800012156 | B13: DR | C13: 45889 | D13: 256779416801 | E13: USD | F13: 110 | G13: INR | H13: 9463.31 | I13: NA | J13: 1 | K13: INTRA-Aug 25- 1-15 | N13: Invoice under booking
... A15: 1800012182 | B15: DR | C15: 45889 | D15: 256779416814 | E15: USD | F15: 230 | G15: INR | H15: 19786.93 | I15: NA | J15: 1 | K15: Transportation In Chgs - 01 - 15 Aug 25 | N15: Invoice under booking
A16: 1800009071 | B16: DR | C16: 45797 | D16: 256779413835 | E16: USD | F16: 206.02 | G16: INR | H16: 17714.36 | J16: 1 | K16: VAS -1-15 May 25, Ex.rate 85.43 | N16: Invoice not received
A17: 1800005928 | B17: DR | C17: 45751 | D17: 256779410819 | E17: USD | F17: 1913.97 | G17: INR | H17: 166365.76 | I17: NA | J17: 1 | K17: Storage Charges Jan, 25 | N17: Invoice under booking
H18: =SUM(H2:H17) -> 1338202.7
H19: -156783.44
H20: =H18+H19 -> 1181419.2

Sheet CN Not in Customer's Books
A1: Document Number | B1: Document Type | C1: Document Date | D1: Reference | E1: Document Currency Key | F1: Document Currency Value | G1: Company Code Currency Key | H1: Company Code Currency Value | I1: Assignment | J1: Item | K1: Text | L1: Clearing Document | N1: Remarks from customers
A2: 1600001670 | B2: DG | C2: 45848 | D2: 256779421302 | E2: USD | F2: -3.54 | G2: INR | H2: -304.44 | I2: NA | J2: 1 | K2: Credit note raised against INV 246779410665 | L2: 1400001815 | N2: CN not received
A3: 1600001590 | B3: DG | C3: 45848 | D3: 256779421222 | E3: USD | F3: -295 | G3: INR | H3: -25370.2 | I3: NA | J3: 1 | K3: Credit note raised against INV 256779411867 | L3: 1400001815 | N3: CN not received
A4: 1600001607 | B4: DG | C4: 45848 | D4: 256779421239 | E4: USD | F4: -35.4 | G4: INR | H4: -3044.42 | I4: NA | J4: 1 | K4: Credit note raised against INV 256779411466 | L4: 1400001815 | N4: CN not received
A5: 1600001608 | B5: DG | C5: 45848 | D5: 256779421240 | E5: USD | F5: -35.4 | G5: INR | H5: -3044.42 | I5: NA | J5: 1 | K5: Credit note raised against INV 256779411467 | L5: 1400001815 | N5: CN not received
A6: 1600001648 | B6: DG | C6: 45848 | D6: 256779421280 | E6: USD | F6: -23.6 | G6: INR | H6: -2029.62 | I6: NA | J6: 1 | K6: Credit note raised against INV 256779411463 | L6: 1400001815 | N6: CN not received
A7: 1600001650 | B7: DG | C7: 45848 | D7: 256779421282 | E7: USD | F7: -32.45 | G7: INR | H7: -2790.72 | I7: NA | J7: 1 | K7: Credit note raised against INV 256779411465 | L7: 1400001815 | N7: CN not received
A8: 1600001651 | B8: DG | C8: 45848 | D8: 256779421283 | E8: USD | F8: -26.55 | G8: INR | H8: -2283.32 | I8: NA | J8: 1 | K8: Credit note raised against INV 256779411468 | L8: 1400001815 | N8: CN not received
A9: 1600002133 | B9: DG | C9: 45890 | D9: 256779421698 | E9: USD | F9: -30 | G9: INR | H9: -2580.9 | I9: NA | J9: 1 | K9: CN ISSUED TOWARDS BILL NO.256779415304 | L9: 1400001815 | N9: CN under booking
A10: 1600002134 | B10: DG | C10: 45890 | D10: 256779421699 | E10: USD | F10: -30 | G10: INR | H10: -2580.9 | I10: NA | J10: 1 | K10: CN ISSUED TOWARDS BILL NO.256779415305 | L10: 1400001815 | N10: CN under booking
A11: 1600002135 | B11: DG | C11: 45890 | D11: 256779421700 | E11: USD | F11: -30 | G11: INR | H11: -2580.9 | I11: NA | J11: 1 | K11: CN ISSUED TOWARDS BILL NO.256779415306 | L11: 1400001815 | N11: CN under booking
A12: 1600002136 | B12: DG | C12: 45890 | D12: 256779421701 | E12: USD | F12: -30 | G12: INR | H12: -2580.9 | I12: NA | J12: 1 | K12: CN ISSUED TOWARDS BILL NO.256779415307 | L12: 1400001815 | N12: CN under booking
A13: 1600002137 | B13: DG | C13: 45890 | D13: 256779421702 | E13: USD | F13: -30 | G13: INR | H13: -2580.9 | I13: NA | J13: 1 | K13: CN ISSUED TOWARDS BILL NO.256779415308 | L13: 1400001815 | N13: CN under booking
... A20: 1600002139 | B20: DG | C20: 45890 | D20: 256779421704 | E20: USD | F20: -8.48 | G20: INR | H20: -729.54 | I20: NA | J20: 1 | K20: CN ISSUED TOWARDS BILL NO.256779415349 | L20: 1400001816 | N20: CN under booking
H21: =SUM(H2:H20) -> -156783.44 | I21: =MID(H21,28,15)
I22: =MID(H22,28,15)
I23: =MID(H23,28,15)
I24: =MID(H24,20,15)
I25: =MID(H25,20,15)
I26: =MID(H26,27,15)
I27: =MID(H27,27,15)
I28: =MID(H28,27,15)
I29: =MID(H29,27,15)
I30: =MID(H30,27,15)
I31: =MID(H31,27,15)
I32: =MID(H32,27,15)
I33: =MID(H33,27,15)
I34: =MID(H34,27,15)
I35: =MID(H35,27,15)
I36: =MID(H36,20,15)
I37: =MID(H37,20,15)
I38: =MID(H38,36,15)
I39: =MID(H39,36,15)
I40: =MID(H40,32,15)
I41: =MID(H41,32,15)
I42: =MID(H42,32,15)
I43: =MID(H43,32,15)
I44: =MID(H44,32,15)
I45: =MID(H45,32,15)
I46: =MID(H46,32,15)
...

Sheet Foreign Exchange difference
A1: Ty | B1: Item# | C1: Item Date | D1: FC Amount | E1: LC Amount | F1: Particular | G1: Due Date | H1: CCY | I1: VC Period | J1: VC Seq | K1: VC Date | L1: Tx. Type | M1: Company Code
A2: C | B2: 246779411409_R | C2: 45730 | D2: 249.55 | E2: 21721.43 | F2: NO EXCHANGE RATE | H2: USD | I2: 45839 | M2: 53826350
A3: C | B3: 246779411409_R | C3: 45730 | D3: 0 | E3: -2.05 | F3: C: ASCENDAS27 P: Matching | H3: USD | I3: 45839 | M3: 54969548
A4: C | B4: 256779417580_R | C4: 45918 | D4: 184.38 | E4: 184.38 | H4: USD | I4: 46023 | M4: 68208016
A5: S | B5: 2830735 | C5: 46053 | D5: 0 | E5: -7756 | F5: Exchange rate diference for JUN'25 USD 20175.95 | H5: INR | I5: 46023 | M5: 68369723
A6: S | B6: 2830736 | C6: 46053 | D6: 0 | E6: -15004 | F6: Exchange rate diference for JUL'25 USD 27632.46 | H6: INR | I6: 46023 | M6: 68369723
A7: S | B7: 2830738 | C7: 46053 | D7: 0 | E7: -17437 | F7: Exchange rate diference for NOV'25 USD 21525.94 | H7: INR | I7: 46023 | M7: 68369723
A8: S | B8: 2830739 | C8: 46053 | D8: 0 | E8: -5206 | F8: Exchange rate diference for DEC'25 USD 8027.22 | H8: INR | I8: 46023 | M8: 68369723
A9: C | B9: 256779417580_R | C9: 45918 | D9: -3.69 | E9: -3.69 | F9: C: ASCENDAS27 P: A023951 C 256779 | H9: USD | I9: 46023 | M9: 68389624
A10: C | B10: 256779417580_R | C10: 45918 | D10: 0 | E10: 16376.07 | F10: C: ASCENDAS27 P: Matching | H10: USD | I10: 46023 | M10: 68459189
E11: =SUM(E2:E10) -> -7126.86

Sheet Ascendus
A1: Customer Account: Name 1 | B1: Fiscal Year | C1: Document Type | D1: Document Date | E1: Reference | F1: Document Currency Key | G1: Document Currency Value | H1: Company Code Currency Key | I1: Company Code Currency Value | J1: Text | K1: Amount In USD | L1: Amount In INR | M1: Diffrecnce
A2: KUEHNE+NAGEL PVT. LTD. | B2: 2025 | C2: DG | D2: 45848 | E2: 256779421326 | F2: USD | G2: -70.8 | H2: INR | I2: -6088.85 | J2: Credit note raised against INV 256779414309 | K2: {=VLOOKUP(E2,[2]A023951!D$1:H$1114,{3,5},0)} -> #N/A
A3: KUEHNE+NAGEL PVT. LTD. | B3: 2025 | C3: DG | D3: 45848 | E3: 256779421327 | F3: USD | G3: -113.28 | H3: INR | I3: -9742.16 | J3: Credit note raised against INV 256779414309 | K3: {=VLOOKUP(E3,[2]A023951!D$1:H$1114,{3,5},0)} -> #N/A
A4: KUEHNE+NAGEL PVT. LTD. | B4: 2025 | C4: DG | D4: 45848 | E4: 256779421328 | F4: USD | G4: -242.75 | H4: INR | I4: -20876.66 | J4: Credit note raised against INV 256779414309 | K4: {=VLOOKUP(E4,[2]A023951!D$1:H$1114,{3,5},0)} -> #N/A
A5: KUEHNE+NAGEL PVT. LTD. | B5: 2025 | C5: DR | D5: 45904 | E5: 256779416909 | F5: USD | G5: 989.55 | H5: INR | I5: 86599.81 | J5: CODC Inbound chgs - 16-31 Aug 25 | K5: {=VLOOKUP(E5,[2]A023951!D$1:H$1114,{3,5},0)} -> -989.55 | L5: -87733 | M5: =I5+L5 -> -1133.19
A6: KUEHNE+NAGEL PVT. LTD. | B6: 2025 | C6: DR | D6: 45904 | E6: 256779417134 | F6: USD | G6: 536.44 | H6: INR | I6: 46946.19 | J6: VAS - 16-31 Aug 25 | K6: {=VLOOKUP(E6,[2]A023951!D$1:H$1114,{3,5},0)} -> -536.44 | L6: -47020 | M6: =I6+L6 -> -73.81
A7: KUEHNE+NAGEL PVT. LTD. | B7: 2025 | C7: DR | D7: 45904 | E7: 256779417137 | F7: USD | G7: 409.79 | H7: INR | I7: 35862.5 | J7: WEIGHMENT - 16-31 Aug 25 | K7: {=VLOOKUP(E7,[2]A023951!D$1:H$1114,{3,5},0)} -> -409.79 | L7: -35918.88 | M7: =I7+L7 -> -56.38
A8: KUEHNE+NAGEL PVT. LTD. | B8: 2025 | C8: DR | D8: 45904 | E8: 256779417158 | F8: USD | G8: 110 | H8: INR | I8: 9626.58 | J8: Intra 16-31 Aug 25 | K8: {=VLOOKUP(E8,[2]A023951!D$1:H$1114,{3,5},0)} -> -110 | L8: -9641.71 | M8: =I8+L8 -> -15.13
A9: KUEHNE+NAGEL PVT. LTD. | B9: 2025 | C9: DR | D9: 45904 | E9: 256779417200 | F9: USD | G9: 100.74 | H9: INR | I9: 8816.19 | J9: Empty Lolo Chgs - 01 - 31 AUG 25 | K9: {=VLOOKUP(E9,[2]A023951!D$1:H$1114,{3,5},0)} -> -100.74 | L9: -8830.05 | M9: =I9+L9 -> -13.86
A10: KUEHNE+NAGEL PVT. LTD. | B10: 2025 | C10: DR | D10: 45904 | E10: 256779417238 | F10: USD | G10: 608.78 | H10: INR | I10: 53276.97 | J10: PORT SSR Chgs Aug 25 | K10: {=VLOOKUP(E10,[2]A023951!D$1:H$1114,{3,5},0)} -> -608.78 | L10: -53360.74 | M10: =I10+L10 -> -83.77
A11: KUEHNE+NAGEL PVT. LTD. | B11: 2025 | C11: DR | D11: 45904 | E11: 256779417250 | F11: USD | G11: 50 | H11: INR | I11: 4375.72 | J11: Scanning Chgs - 16 - 31 Aug 25 | K11: {=VLOOKUP(E11,[2]A023951!D$1:H$1114,{3,5},0)} -> #N/A
A12: KUEHNE+NAGEL PVT. LTD. | B12: 2025 | C12: DR | D12: 45904 | E12: 256779417257 | F12: USD | G12: 22.77 | H12: INR | I12: 1992.7 | J12: Bond Stamp Paper Chgs 01 - 31 Aug 25 | K12: {=VLOOKUP(E12,[2]A023951!D$1:H$1114,{3,5},0)} -> -22.77 | L12: -1995.83 | M12: =I12+L12 -> -3.13
A13: KUEHNE+NAGEL PVT. LTD. | B13: 2025 | C13: DR | D13: 45904 | E13: 256779417280 | F13: USD | G13: 249.98 | H13: INR | I13: 21876.83 | J13: LCL Chgs - 16 - 31 AUG 25 | K13: {=VLOOKUP(E13,[2]A023951!D$1:H$1114,{3,5},0)} -> -249.98 | L13: -21911.23 | M13: =I13+L13 -> -34.4
A14: KUEHNE+NAGEL PVT. LTD. | B14: 2025 | C14: DR | D14: 45904 | E14: 256779417317 | F14: USD | G14: 170.85 | H14: INR | I14: 14951.82 | J14: Outbound chgs - 16 - 31 Aug 25 | K14: {=VLOOKUP(E14,[2]A023951!D$1:H$1114,{3,5},0)} -> -170.85 | L14: -14975.33 | M14: =I14+L14 -> -23.51
A15: KUEHNE+NAGEL PVT. LTD. | B15: 2025 | C15: DR | D15: 45842 | E15: 256779414859 | F15: USD | G15: 318.47 | H15: INR | I15: 27388.63 | J15: LCL Chgs - 16 - 30 JUN 25 | K15: {=VLOOKUP(E15,[2]A023951!D$1:H$1114,{3,5},0)} -> -318.47 | L15: -27385.08 | M15: =I15+L15 -> 3.55
A16: KUEHNE+NAGEL PVT. LTD. | B16: 2025 | C16: DR | D16: 45842 | E16: 256779415012 | F16: USD | G16: 184.3 | H16: INR | I16: 15849.92 | J16: Outbound chgs - 16 - 30 Jun 25 | K16: {=VLOOKUP(E16,[2]A023951!D$1:H$1114,{3,5},0)} -> -184 | L16: -15822.07 | M16: =I16+L16 -> 27.85
A17: KUEHNE+NAGEL PVT. LTD. | B17: 2025 | C17: DR | D17: 45842 | E17: 256779415208 | F17: USD | G17: 183.43 | H17: INR | I17: 15775.1 | J17: Unit Storage - 1-30 June 25 | K17: {=VLOOKUP(E17,[2]A023951!D$1:H$1114,{3,5},0)} -> -183.43 | L17: -16228.05 | M17: =I17+L17 -> -452.95
A18: KUEHNE+NAGEL PVT. LTD. | B18: 2025 | C18: DR | D18: 45842 | E18: 256779415209 | F18: USD | G18: 63.26 | H18: INR | I18: 5440.4 | J18: Unit Storage - 1-30 June 25 | K18: {=VLOOKUP(E18,[2]A023951!D$1:H$1114,{3,5},0)} -> -63.26 | L18: -5596.61 | M18: =I18+L18 -> -156.21
A19: KUEHNE+NAGEL PVT. LTD. | B19: 2025 | C19: DR | D19: 45842 | E19: 256779415210 | F19: USD | G19: 9629.63 | H19: INR | I19: 828154.63 | J19: Unit Storage - 1-30 June 25 | K19: {=VLOOKUP(E19,[2]A023951!D$1:H$1114,{3,5},0)} -> -9629.63 | L19: -851933.37 | M19: =I19+L19 -> -23778.74
A20: KUEHNE+NAGEL PVT. LTD. | B20: 2025 | C20: DR | D20: 45842 | E20: 256779415261 | F20: USD | G20: 292.96 | H20: INR | I20: 25194.76 | J20: VAS - 16-30 June 25 | K20: {=VLOOKUP(E20,[2]A023951!D$1:H$1114,{3,5},0)} -> -292.26 | L20: -25131.29 | M20: =I20+L20 -> 63.47
A21: KUEHNE+NAGEL PVT. LTD. | B21: 2025 | C21: DR | D21: 45842 | E21: 256779415270 | F21: USD | G21: 420.86 | H21: INR | I21: 36194.24 | J21: Weighment- 16-30 June 25 | K21: {=VLOOKUP(E21,[2]A023951!D$1:H$1114,{3,5},0)} -> -420.86 | L21: -37233.48 | M21: =I21+L21 -> -1039.24
A22: KUEHNE+NAGEL PVT. LTD. | B22: 2025 | C22: DR | D22: 45966 | E22: 256779418816 | F22: USD | G22: 891 | H22: INR | I22: 78411.02 | J22: VAS-16 -31 Oct 25 | K22: {=VLOOKUP(E22,[2]A023951!D$1:H$1114,{3,5},0)} -> #N/A
A23: KUEHNE+NAGEL PVT. LTD. | B23: 2025 | C23: DR | D23: 45966 | E23: 256779418872 | F23: USD | G23: 5939.04 | H23: INR | I23: 522655.65 | J23: Unit Storage - 1-31 Oct 2025 | K23: {=VLOOKUP(E23,[2]A023951!D$1:H$1114,{3,5},0)} -> #N/A
A24: KUEHNE+NAGEL PVT. LTD. | B24: 2025 | C24: DR | D24: 45966 | E24: 256779418892 | F24: USD | G24: 1683.97 | H24: INR | I24: 148195.07 | J24: CODC Inbound chgs - 16-31 Oct 25 | K24: {=VLOOKUP(E24,[2]A023951!D$1:H$1114,{3,5},0)} -> -1683.97 | L24: -148614.68 | M24: =I24+L24 -> -419.61
A25: KUEHNE+NAGEL PVT. LTD. | B25: 2025 | C25: DR | D25: 45966 | E25: 256779418904 | F25: USD | G25: 1273.92 | H25: INR | I25: 112109.28 | J25: CODC Out chgs -16-31 Oct 25 | K25: {=VLOOKUP(E25,[2]A023951!D$1:H$1114,{3,5},0)} -> -1273.92 | L25: -112426.72 | M25: =I25+L25 -> -317.44
A26: KUEHNE+NAGEL PVT. LTD. | B26: 2025 | C26: DR | D26: 45966 | E26: 256779419165 | F26: USD | G26: 191.57 | H26: INR | I26: 16858.81 | J26: Outbound chgs - 16 - 31 Oct 25 | K26: {=VLOOKUP(E26,[2]A023951!D$1:H$1114,{3,5},0)} -> -191.57 | L26: -16906.55 | M26: =I26+L26 -> -47.74
A27: KUEHNE+NAGEL PVT. LTD. | B27: 2025 | C27: DR | D27: 45966 | E27: 256779419192 | F27: USD | G27: 171.87 | H27: INR | I27: 15125.14 | J27: Empty Lolo Chgs - 01 - 31 OCT 25 | K27: {=VLOOKUP(E27,[2]A023951!D$1:H$1114,{3,5},0)} -> -171.87 | L27: -15167.97 | M27: =I27+L27 -> -42.83
A28: KUEHNE+NAGEL PVT. LTD. | B28: 2025 | C28: DR | D28: 45966 | E28: 256779419211 | F28: USD | G28: 28.18 | H28: INR | I28: 2479.94 | J28: Internet Activity Chgs - Oct 25 | K28: {=VLOOKUP(E28,[2]A023951!D$1:H$1114,{3,5},0)} -> -28.18 | L28: -2486.96 | M28: =I28+L28 -> -7.02
A29: KUEHNE+NAGEL PVT. LTD. | B29: 2025 | C29: DR | D29: 45966 | E29: 256779419222 | F29: USD | G29: 3537 | H29: INR | I29: 311267.99 | J29: PORT SSR Chgs Oct 25 | K29: {=VLOOKUP(E29,[2]A023951!D$1:H$1114,{3,5},0)} -> #N/A
A30: KUEHNE+NAGEL PVT. LTD. | B30: 2025 | C30: DR | D30: 45964 | E30: 256779419122 | F30: USD | G30: 670.42 | H30: INR | I30: 58999.23 | J30: LCL Chgs - 16 - 31 OCT 25 | K30: {=VLOOKUP(E30,[2]A023951!D$1:H$1114,{3,5},0)} -> -670.42 | L30: -59439.1 | M30: =I30+L30 -> -439.87
A31: KUEHNE+NAGEL PVT. LTD. | B31: 2025 | C31: DG | D31: 45964 | E31: 256779422067 | F31: USD | G31: -4608.8 | H31: INR | I31: -405590.02 | J31: CN issued against 256779417093 | K31: {=VLOOKUP(E31,[2]A023951!D$1:H$1114,{3,5},0)} -> #N/A
A32: KUEHNE+NAGEL PVT. LTD. | B32: 2025 | C32: DR | D32: 45877 | E32: 256779416096 | F32: USD | G32: 7386.34 | H32: INR | I32: 635447.72 | J32: Unit Storage - 1-31 July 25 | K32: {=VLOOKUP(E32,[2]A023951!D$1:H$1114,{3,5},0)} -> -7386.34 | L32: -639885.33 | M32: =I32+L32 -> -4437.61
A33: KUEHNE+NAGEL PVT. LTD. | B33: 2025 | C33: DR | D33: 45877 | E33: 256779416137 | F33: USD | G33: 55.28 | H33: INR | I33: 4755.75 | J33: Empty Lolo Chgs - 01 - 31 JUL 25 | K33: {=VLOOKUP(E33,[2]A023951!D$1:H$1114,{3,5},0)} -> -55 | L33: -4764.7 | M33: =I33+L33 -> -8.95
A34: KUEHNE+NAGEL PVT. LTD. | B34: 2025 | C34: DR | D34: 45877 | E34: 256779416169 | F34: USD | G34: 256.97 | H34: INR | I34: 22107.16 | J34: LCL Chgs - 16 - 31 JUL 25 | K34: {=VLOOKUP(E34,[2]A023951!D$1:H$1114,{3,5},0)} -> -257 | L34: -22264.14 | M34: =I34+L34 -> -156.98
A35: KUEHNE+NAGEL PVT. LTD. | B35: 2025 | C35: DR | D35: 45877 | E35: 256779416214 | F35: USD | G35: 212.34 | H35: INR | I35: 18267.64 | J35: Outbound chgs - 16 - 31 Jul 25 | K35: {=VLOOKUP(E35,[2]A023951!D$1:H$1114,{3,5},0)} -> -212 | L35: -18365.75 | M35: =I35+L35 -> -98.11
A36: KUEHNE+NAGEL PVT. LTD. | B36: 2025 | C36: DR | D36: 45877 | E36: 256779416255 | F36: USD | G36: 392.28 | H36: INR | I36: 33747.9 | J36: CODC Out chgs - 16 - 31 Jul 25 | K36: {=VLOOKUP(E36,[2]A023951!D$1:H$1114,{3,5},0)} -> -392 | L36: -33959.32 | M36: =I36+L36 -> -211.42
A37: KUEHNE+NAGEL PVT. LTD. | B37: 2025 | C37: DR | D37: 45877 | E37: 256779416442 | F37: USD | G37: 1053.34 | H37: INR | I37: 90618.97 | J37: VAS 16-31 July 25 | K37: {=VLOOKUP(E37,[2]A023951!D$1:H$1114,{3,5},0)} -> -1053 | L37: -91222.35 | M37: =I37+L37 -> -603.38
A38: KUEHNE+NAGEL PVT. LTD. | B38: 2025 | C38: DR | D38: 45877 | E38: 256779416454 | F38: USD | G38: 411.19 | H38: INR | I38: 35374.73 | J38: Weighment - 16-31 July 25 | K38: {=VLOOKUP(E38,[2]A023951!D$1:H$1114,{3,5},0)} -> -411 | L38: -35605.3 | M38: =I38+L38 -> -230.57
A39: KUEHNE+NAGEL PVT. LTD. | B39: 2025 | C39: DR | D39: 45812 | E39: 256779414156 | F39: USD | G39: 83.66 | H39: INR | I39: 7152.16 | J39: CODC Inbound chgs - 16 - 31 May 25 | K39: {=VLOOKUP(E39,[2]A023951!D$1:H$1114,{3,5},0)} -> #N/A
A40: KUEHNE+NAGEL PVT. LTD. | B40: 2025 | C40: DR | D40: 45812 | E40: 256779414173 | F40: USD | G40: 2668.72 | H40: INR | I40: 228150.95 | J40: PORT SSR Chgs - 16 - 31 May 25 | K40: {=VLOOKUP(E40,[2]A023951!D$1:H$1114,{3,5},0)} -> #N/A
...

Sheet Sheet12
A1: Customer Account: Name 1 | B1: Fiscal Year | C1: Document Type | D1: Document Date | E1: Entry Date | F1: Reference | G1: Document Currency Key | H1: Document Currency Value | I1: Company Code Currency Key | J1: Company Code Currency Value | K1: Text
A2: KUEHNE+NAGEL PVT. LTD. | B2: 2025 | C2: DR | D2: 45904 | E2: 45909 | F2: 256779417250 | G2: USD | H2: 50 | I2: INR | J2: 4375.72 | K2: Scanning Chgs - 16 - 31 Aug 25
A3: KUEHNE+NAGEL PVT. LTD. | B3: 2025 | C3: DR | D3: 45966 | E3: 45967 | F3: 256779418816 | G3: USD | H3: 891 | I3: INR | J3: 78411.02 | K3: VAS-16 -31 Oct 25
A4: KUEHNE+NAGEL PVT. LTD. | B4: 2025 | C4: DR | D4: 45966 | E4: 45967 | F4: 256779418872 | G4: USD | H4: 5939.04 | I4: INR | J4: 522655.65 | K4: Unit Storage - 1-31 Oct 2025
A5: KUEHNE+NAGEL PVT. LTD. | B5: 2025 | C5: DR | D5: 45966 | E5: 45968 | F5: 256779419222 | G5: USD | H5: 3537 | I5: INR | J5: 311267.99 | K5: PORT SSR Chgs Oct 25
A6: KUEHNE+NAGEL PVT. LTD. | B6: 2025 | C6: DR | D6: 45812 | E6: 45817 | F6: 256779414156 | G6: USD | H6: 83.66 | I6: INR | J6: 7152.16 | K6: CODC Inbound chgs - 16 - 31 May 25
A7: KUEHNE+NAGEL PVT. LTD. | B7: 2025 | C7: DR | D7: 45812 | E7: 45817 | F7: 256779414173 | G7: USD | H7: 2668.72 | I7: INR | J7: 228150.95 | K7: PORT SSR Chgs - 16 - 31 May 25
A8: KUEHNE+NAGEL PVT. LTD. | B8: 2025 | C8: DR | D8: 45812 | E8: 45817 | F8: 256779414206 | G8: USD | H8: 201.33 | I8: INR | J8: 17211.86 | K8: Outbound chgs - 16 - 31 MAY 25
A9: KUEHNE+NAGEL PVT. LTD. | B9: 2025 | C9: DR | D9: 45812 | E9: 45817 | F9: 256779414260 | G9: USD | H9: 130.93 | I9: INR | J9: 11193.31 | K9: Detention Chgs - 01 - 15 MAY 25
A10: KUEHNE+NAGEL PVT. LTD. | B10: 2025 | C10: DR | D10: 45812 | E10: 45817 | F10: 256779414271 | G10: USD | H10: 967.68 | I10: INR | J10: 82727.72 | K10: Empty Lolo Chgs - 01 - 31 MAY 25
A11: KUEHNE+NAGEL PVT. LTD. | B11: 2025 | C11: DR | D11: 45812 | E11: 45817 | F11: 256779414309 | G11: USD | H11: 662.83 | I11: INR | J11: 56665.85 | K11: Transportation In Chgs - 16-31 MAY 25
A12: KUEHNE+NAGEL PVT. LTD. | B12: 2025 | C12: DR | D12: 45793 | E12: 45800 | F12: 256779413280 | G12: USD | H12: 59 | I12: INR | J12: 5073.04 | K12: Scanning Chgs - 16 - 31 Apr 25
A13: KUEHNE+NAGEL PVT. LTD. | B13: 2025 | C13: DR | D13: 45793 | E13: 45800 | F13: 256779413308 | G13: USD | H13: 723.47 | I13: INR | J13: 62206.63 | K13: LCL Chgs - 16 - 30 Apr 25
... A141: KUEHNE+NAGEL PVT. LTD. | B141: 2025 | C141: DR | D141: 45719 | E141: 45719 | F141: 246779410483 | G141: USD | H141: 3.54 | I141: INR | J141: 306.89 | K141: Outbound Handling for Aug 2024

Sheet Sheet4

Sheet CUSTOMER DATA
I1: =SUBTOTAL(9,I3:I751) -> 10371172 | X1: =SUBTOTAL(9,X3:X751) -> 0 | Y1: =SUBTOTAL(9,Y3:Y751) -> 10371172 | AB1: =SUBTOTAL(9,AB3:AB751) -> 0
A2: Creditor Code | B2: Creditor | C2: Ty | D2: Item# | E2: Item Date | F2: CCY | G2: FC Amount | H2: Settled FC Amount | I2: LC Amount | J2: Particular | K2: Due Date | L2: Last Sett. Date | M2: Job# | N2: VC Period | O2: VC# | P2: VC Seq | Q2: VC Date | R2: Tx. Type | S2: Reference | T2: Full Name | U2: Settled LC Amount | X2: TDS | Y2: Net balance | Z2: Remarks | AA2: vlookup | AB2: Difference
A3: A023951 | B3: A023951 | C3: I | D3: 246779411742 | E3: 45733 | F3: USD | G3: -23.27 | H3: 23.27 | I3: -2025.48 | J3: NO EXCHANGE RATE | K3: 45763 | L3: 45838 | M3: - | N3: 45809 | O3: 51127398 | P3: 1 | Q3: 45819 | R3: 210 | S3: 1.55e+16 | T3: Ascendas Panvel FTWZ Private Limited | U3: 2025.48 | W3: =X3/I3 -> -0.020197682 | X3: =VLOOKUP(D3,'[3]Customer TDS'!D:I,6,0) -> 40.91 | Y3: =I3+X3 -> -1984.57 | Z3: Diff due to exchange gain/loss | AA3: =VLOOKUP(D3,'Ascendus DATA'!$F:$J,5,0) -> 2017.31 | AB3: =I3+AA3 -> -8.17
A4: A023951 | B4: A023951 | C4: I | D4: 246779411737 | E4: 45733 | F4: USD | G4: -28.54 | H4: 28.54 | I4: -2484.19 | K4: 45763 | L4: 45838 | M4: - | N4: 45809 | O4: 51158463 | P4: 1 | Q4: 45820 | R4: 210 | S4: 1.55e+16 | T4: Ascendas Panvel FTWZ Private Limited | U4: 2484.19 | W4: =X4/I4 -> -0.019970292 | X4: =VLOOKUP(D4,'[3]Customer TDS'!D:I,6,0) -> 49.61 | Y4: =I4+X4 -> -2434.58 | Z4: Diff due to exchange gain/loss | AA4: =VLOOKUP(D4,'Ascendus DATA'!$F:$J,5,0) -> 2474.17 | AB4: =I4+AA4 -> -10.02
A5: A023951 | B5: A023951 | C5: I | D5: 246779411734 | E5: 45733 | F5: USD | G5: -22.83 | H5: 22.83 | I5: -1987.18 | K5: 45763 | L5: 45838 | M5: - | N5: 45809 | O5: 51158465 | P5: 1 | Q5: 45820 | R5: 210 | S5: 1.55e+16 | T5: Ascendas Panvel FTWZ Private Limited | U5: 1987.18 | W5: =X5/I5 -> -0.020149156 | X5: =VLOOKUP(D5,'[3]Customer TDS'!D:I,6,0) -> 40.04 | Y5: =I5+X5 -> -1947.14 | Z5: Diff due to exchange gain/loss | AA5: =VLOOKUP(D5,'Ascendus DATA'!$F:$J,5,0) -> 1979.16 | AB5: =I5+AA5 -> -8.02
A6: A023951 | B6: A023951 | C6: I | D6: 246779411732 | E6: 45733 | F6: USD | G6: -28.54 | H6: 28.54 | I6: -2484.19 | K6: 45763 | L6: 45838 | M6: - | N6: 45809 | O6: 51158468 | P6: 1 | Q6: 45820 | R6: 210 | S6: 1.55e+16 | T6: Ascendas Panvel FTWZ Private Limited | U6: 2484.19 | W6: =X6/I6 -> -0.019970292 | X6: =VLOOKUP(D6,'[3]Customer TDS'!D:I,6,0) -> 49.61 | Y6: =I6+X6 -> -2434.58 | Z6: Diff due to exchange gain/loss | AA6: =VLOOKUP(D6,'Ascendus DATA'!$F:$J,5,0) -> 2474.17 | AB6: =I6+AA6 -> -10.02
A7: A023951 | B7: A023951 | C7: I | D7: 246779411729 | E7: 45733 | F7: USD | G7: -34.25 | H7: 34.25 | I7: -2981.2 | J7: NO EXCHANGE RATE | K7: 45763 | L7: 45838 | M7: - | N7: 45809 | O7: 51158469 | P7: 1 | Q7: 45820 | R7: 210 | S7: 1.55e+16 | T7: Ascendas Panvel FTWZ Private Limited | U7: 2981.2 | W7: =X7/I7 -> -0.02014625 | X7: =VLOOKUP(D7,'[3]Customer TDS'!D:I,6,0) -> 60.06 | Y7: =I7+X7 -> -2921.14 | Z7: Diff due to exchange gain/loss | AA7: =VLOOKUP(D7,'Ascendus DATA'!$F:$J,5,0) -> 2969.18 | AB7: =I7+AA7 -> -12.02
A8: A023951 | B8: A023951 | C8: I | D8: 246779411724 | E8: 45733 | F8: USD | G8: -68.5 | H8: 68.5 | I8: -5962.41 | K8: 45763 | L8: 45838 | M8: - | N8: 45809 | O8: 51158473 | P8: 1 | Q8: 45820 | R8: 210 | S8: 1.55e+16 | T8: Ascendas Panvel FTWZ Private Limited | U8: 5962.41 | W8: =X8/I8 -> -0.020000302 | X8: =VLOOKUP(D8,'[3]Customer TDS'!D:I,6,0) -> 119.25 | Y8: =I8+X8 -> -5843.16 | Z8: Diff due to exchange gain/loss | AA8: =VLOOKUP(D8,'Ascendus DATA'!$F:$J,5,0) -> 5938.35 | AB8: =I8+AA8 -> -24.06
A9: A023951 | B9: A023951 | C9: I | D9: 246779411721 | E9: 45733 | F9: USD | G9: -525.63 | H9: 525.63 | I9: -45752.1 | K9: 45763 | L9: 45838 | M9: - | N9: 45809 | O9: 51158475 | P9: 1 | Q9: 45820 | R9: 210 | S9: 1.55e+16 | T9: Ascendas Panvel FTWZ Private Limited | U9: 45752.1 | W9: =X9/I9 -> -0.019995148 | X9: =VLOOKUP(D9,'[3]Customer TDS'!D:I,6,0) -> 914.82 | Y9: =I9+X9 -> -44837.28 | Z9: Diff due to exchange gain/loss | AA9: =VLOOKUP(D9,'Ascendus DATA'!$F:$J,5,0) -> 45567.53 | AB9: =I9+AA9 -> -184.57
A10: A023951 | B10: A023951 | C10: I | D10: 246779411741 | E10: 45733 | F10: USD | G10: -240 | H10: 240 | I10: -20890.18 | K10: 45763 | L10: 45838 | M10: - | N10: 45809 | O10: 51158478 | P10: 1 | Q10: 45820 | R10: 210 | S10: 1.55e+16 | T10: Ascendas Panvel FTWZ Private Limited | U10: 20890.18 | W10: =X10/I10 -> -0.019999828 | X10: =VLOOKUP(D10,'[3]Customer TDS'!D:I,6,0) -> 417.8 | Y10: =I10+X10 -> -20472.38 | Z10: Diff due to exchange gain/loss | AA10: =VLOOKUP(D10,'Ascendus DATA'!$F:$J,5,0) -> 20805.9 | AB10: =I10+AA10 -> -84.28
A11: A023951 | B11: A023951 | C11: I | D11: 246779410315 | E11: 45708 | F11: USD | G11: -2380.95 | H11: 2380.95 | I11: -207243.64 | K11: 45738 | L11: 45838 | M11: - | N11: 45809 | O11: 51158482 | P11: 1 | Q11: 45820 | R11: 210 | S11: 1.55e+16 | T11: Ascendas Panvel FTWZ Private Limited | U11: 207243.64 | W11: =X11/I11 -> -0.020000421 | X11: =VLOOKUP(D11,'[3]Customer TDS'!D:I,6,0) -> 4144.96 | Y11: =I11+X11 -> -203098.68 | Z11: Diff due to exchange gain/loss | AA11: =VLOOKUP(D11,'Ascendus DATA'!$F:$J,5,0) -> 205484.7 | AB11: =I11+AA11 -> -1758.94
A12: A023951 | B12: A023951 | C12: I | D12: 246779411735 | E12: 45733 | F12: USD | G12: -479.25 | H12: 479.25 | I12: -41715.08 | K12: 45763 | L12: 45838 | M12: - | N12: 45809 | O12: 51158483 | P12: 1 | Q12: 45820 | R12: 210 | S12: 1.55e+16 | T12: Ascendas Panvel FTWZ Private Limited | U12: 41715.08 | W12: =X12/I12 -> -0.020010509 | X12: =VLOOKUP(D12,'[3]Customer TDS'!D:I,6,0) -> 834.74 | Y12: =I12+X12 -> -40880.34 | Z12: Diff due to exchange gain/loss | AA12: =VLOOKUP(D12,'Ascendus DATA'!$F:$J,5,0) -> 41546.79 | AB12: =I12+AA12 -> -168.29
A13: A023951 | B13: A023951 | C13: I | D13: 246779411733 | E13: 45733 | F13: USD | G13: -17.12 | H13: 17.12 | I13: -1490.17 | K13: 45763 | L13: 45838 | M13: - | N13: 45809 | O13: 51158487 | P13: 1 | Q13: 45820 | R13: 210 | S13: 1.55e+16 | T13: Ascendas Panvel FTWZ Private Limited | U13: 1490.17 | W13: =X13/I13 -> -0.019856795 | X13: =VLOOKUP(D13,'[3]Customer TDS'!D:I,6,0) -> 29.59 | Y13: =I13+X13 -> -1460.58 | Z13: Diff due to exchange gain/loss | AA13: =VLOOKUP(D13,'Ascendus DATA'!$F:$J,5,0) -> 1484.15 | AB13: =I13+AA13 -> -6.02
A14: A023951 | B14: A023951 | C14: I | D14: 246779411727 | E14: 45733 | F14: USD | G14: -17.12 | H14: 17.12 | I14: -1490.17 | K14: 45763 | L14: 45838 | M14: - | N14: 45809 | O14: 51158492 | P14: 1 | Q14: 45820 | R14: 210 | S14: 1.55e+16 | T14: Ascendas Panvel FTWZ Private Limited | U14: 1490.17 | W14: =X14/I14 -> -0.019856795 | X14: =VLOOKUP(D14,'[3]Customer TDS'!D:I,6,0) -> 29.59 | Y14: =I14+X14 -> -1460.58 | Z14: Diff due to exchange gain/loss | AA14: =VLOOKUP(D14,'Ascendus DATA'!$F:$J,5,0) -> 1484.15 | AB14: =I14+AA14 -> -6.02
A15: A023951 | B15: A023951 | C15: I | D15: 246779411726 | E15: 45733 | F15: USD | G15: -28.54 | H15: 28.54 | I15: -2484.19 | K15: 45763 | L15: 45838 | M15: - | N15: 45809 | O15: 51158494 | P15: 1 | Q15: 45820 | R15: 210 | S15: 1.55e+16 | T15: Ascendas Panvel FTWZ Private Limited | U15: 2484.19 | W15: =X15/I15 -> -0.019970292 | X15: =VLOOKUP(D15,'[3]Customer TDS'!D:I,6,0) -> 49.61 | Y15: =I15+X15 -> -2434.58 | Z15: Diff due to exchange gain/loss | AA15: =VLOOKUP(D15,'Ascendus DATA'!$F:$J,5,0) -> 2474.17 | AB15: =I15+AA15 -> -10.02
A16: A023951 | B16: A023951 | C16: I | D16: 246779411720 | E16: 45733 | F16: USD | G16: -17.12 | H16: 17.12 | I16: -1490.17 | K16: 45763 | L16: 45838 | M16: - | N16: 45809 | O16: 51158497 | P16: 1 | Q16: 45820 | R16: 210 | S16: 1.55e+16 | T16: Ascendas Panvel FTWZ Private Limited | U16: 1490.17 | W16: =X16/I16 -> -0.019856795 | X16: =VLOOKUP(D16,'[3]Customer TDS'!D:I,6,0) -> 29.59 | Y16: =I16+X16 -> -1460.58 | Z16: Diff due to exchange gain/loss | AA16: =VLOOKUP(D16,'Ascendus DATA'!$F:$J,5,0) -> 1484.15 | AB16: =I16+AA16 -> -6.02
A17: A023951 | B17: A023951 | C17: I | D17: 246779411718 | E17: 45733 | F17: USD | G17: -22.95 | H17: 22.95 | I17: -1997.62 | K17: 45763 | L17: 45838 | M17: - | N17: 45809 | O17: 51158499 | P17: 1 | Q17: 45820 | R17: 210 | S17: 1.55e+16 | T17: Ascendas Panvel FTWZ Private Limited | U17: 1997.62 | W17: =X17/I17 -> -0.020043852 | X17: =VLOOKUP(D17,'[3]Customer TDS'!D:I,6,0) -> 40.04 | Y17: =I17+X17 -> -1957.58 | Z17: Diff due to exchange gain/loss | AA17: =VLOOKUP(D17,'Ascendus DATA'!$F:$J,5,0) -> 1989.56 | AB17: =I17+AA17 -> -8.06
A18: A023951 | B18: A023951 | C18: I | D18: 246779411637 | E18: 45733 | F18: USD | G18: -429.65 | H18: 429.65 | I18: -37397.77 | K18: 45763 | L18: 45838 | M18: - | N18: 45809 | O18: 51158500 | P18: 1 | Q18: 45820 | R18: 210 | S18: 1.55e+16 | T18: Ascendas Panvel FTWZ Private Limited | U18: 37397.77 | W18: =X18/I18 -> -0.019992903 | X18: =VLOOKUP(D18,'[3]Customer TDS'!D:I,6,0) -> 747.69 | Y18: =I18+X18 -> -36650.08 | Z18: Diff due to exchange gain/loss | AA18: =VLOOKUP(D18,'Ascendus DATA'!$F:$J,5,0) -> 37246.9 | AB18: =I18+AA18 -> -150.87
A19: A023951 | B19: A023951 | C19: I | D19: 246779411717 | E19: 45733 | F19: USD | G19: -45.67 | H19: 45.67 | I19: -3975.23 | K19: 45763 | L19: 45838 | M19: - | N19: 45809 | O19: 51158502 | P19: 1 | Q19: 45820 | R19: 210 | S19: 1.55e+16 | T19: Ascendas Panvel FTWZ Private Limited | U19: 3975.23 | W19: =X19/I19 -> -0.019925891 | X19: =VLOOKUP(D19,'[3]Customer TDS'!D:I,6,0) -> 79.21 | Y19: =I19+X19 -> -3896.02 | Z19: Diff due to exchange gain/loss | AA19: =VLOOKUP(D19,'Ascendus DATA'!$F:$J,5,0) -> 3959.19 | AB19: =I19+AA19 -> -16.04
... A23: A023951 | B23: A023951 | C23: I | D23: 246779411597 | E23: 45733 | F23: USD | G23: -57.29 | H23: 57.29 | I23: -4986.66 | K23: 45763 | L23: 45838 | M23: - | N23: 45809 | O23: 51158507 | P23: 1 | Q23: 45820 | R23: 210 | S23: 1.55e+16 | T23: Ascendas Panvel FTWZ Private Limited | U23: 4986.66 | W23: =X23/I23 -> -0.020073556 | X23: =VLOOKUP(D23,'[3]Customer TDS'!D:I,6,0) -> 100.1 | Y23: =I23+X23 -> -4886.56 | Z23: Diff due to exchange gain/loss | AA23: =VLOOKUP(D23,'Ascendus DATA'!$F:$J,5,0) -> 4966.54 | AB23: =I23+AA23 -> -20.12
A24: A023951 | B24: A023951 | C24: I | D24: 246779411739 | E24: 45733 | F24: USD | G24: -34.25 | H24: 34.25 | I24: -2981.2 | J24: NO EXCHANGE RATE | K24: 45763 | L24: 45838 | M24: - | N24: 45809 | O24: 51158508 | P24: 1 | Q24: 45820 | R24: 210 | S24: 1.55e+16 | T24: Ascendas Panvel FTWZ Private Limited | U24: 2981.2 | W24: =X24/I24 -> -0.02014625 | X24: =VLOOKUP(D24,'[3]Customer TDS'!D:I,6,0) -> 60.06 | Y24: =I24+X24 -> -2921.14 | Z24: Diff due to exchange gain/loss | AA24: =VLOOKUP(D24,'Ascendus DATA'!$F:$J,5,0) -> 2969.18 | AB24: =I24+AA24 -> -12.02
A25: A023951 | B25: A023951 | C25: I | D25: 246779411914 | E25: 45733 | F25: USD | G25: -260 | H25: 260 | I25: -22631.03 | K25: 45763 | L25: 45838 | M25: - | N25: 45809 | O25: 51158509 | P25: 1 | Q25: 45820 | R25: 210 | S25: 1.55e+16 | T25: Ascendas Panvel FTWZ Private Limited | U25: 22631.03 | W25: =X25/I25 -> -0.019999973 | X25: =VLOOKUP(D25,'[3]Customer TDS'!D:I,6,0) -> 452.62 | Y25: =I25+X25 -> -22178.41 | Z25: Diff due to exchange gain/loss | AA25: =VLOOKUP(D25,'Ascendus DATA'!$F:$J,5,0) -> 22539.73 | AB25: =I25+AA25 -> -91.3
A26: A023951 | B26: A023951 | C26: I | D26: 246779411596 | E26: 45733 | F26: USD | G26: -74.47 | H26: 74.47 | I26: -6482.05 | K26: 45763 | L26: 45838 | M26: - | N26: 45809 | O26: 51158510 | P26: 1 | Q26: 45820 | R26: 210 | S26: 1.55e+16 | T26: Ascendas Panvel FTWZ Private Limited | U26: 6482.05 | W26: =X26/I26 -> -0.020007559 | X26: =VLOOKUP(D26,'[3]Customer TDS'!D:I,6,0) -> 129.69 | Y26: =I26+X26 -> -6352.36 | Z26: Diff due to exchange gain/loss | AA26: =VLOOKUP(D26,'Ascendus DATA'!$F:$J,5,0) -> 6455.9 | AB26: =I26+AA26 -> -26.15
A27: A023951 | B27: A023951 | C27: I | D27: 246779411738 | E27: 45733 | F27: USD | G27: -28.54 | H27: 28.54 | I27: -2484.19 | K27: 45763 | L27: 45838 | M27: - | N27: 45809 | O27: 51158511 | P27: 1 | Q27: 45820 | R27: 210 | S27: 1.55e+16 | T27: Ascendas Panvel FTWZ Private Limited | U27: 2484.19 | W27: =X27/I27 -> -0.019970292 | X27: =VLOOKUP(D27,'[3]Customer TDS'!D:I,6,0) -> 49.61 | Y27: =I27+X27 -> -2434.58 | Z27: Diff due to exchange gain/loss | AA27: =VLOOKUP(D27,'Ascendus DATA'!$F:$J,5,0) -> 2474.17 | AB27: =I27+AA27 -> -10.02
A28: A023951 | B28: A023951 | C28: I | D28: 246779412040 | E28: 45733 | F28: USD | G28: -16.82 | H28: 16.82 | I28: -1464.05 | J28: NO EXCHANGE RATE / 14 DAYS OLDER | K28: 45763 | L28: 45838 | M28: - | N28: 45809 | O28: 51158513 | P28: 1 | Q28: 45820 | R28: 210 | S28: 1.55e+16 | T28: Ascendas Panvel FTWZ Private Limited | U28: 1464.05 | W28: =X28/I28 -> -0.020211058 | X28: =VLOOKUP(D28,'[3]Customer TDS'!D:I,6,0) -> 29.59 | Y28: =I28+X28 -> -1434.46 | Z28: Diff due to exchange gain/loss | AA28: =VLOOKUP(D28,'Ascendus DATA'!$F:$J,5,0) -> 1458.15 | AB28: =I28+AA28 -> -5.9
A29: A023951 | B29: A023951 | C29: I | D29: 246779411736 | E29: 45733 | F29: USD | G29: -22.83 | H29: 22.83 | I29: -1987.18 | K29: 45763 | L29: 45838 | M29: - | N29: 45809 | O29: 51158514 | P29: 1 | Q29: 45820 | R29: 210 | S29: 1.55e+16 | T29: Ascendas Panvel FTWZ Private Limited | U29: 1987.18 | W29: =X29/I29 -> -0.020149156 | X29: =VLOOKUP(D29,'[3]Customer TDS'!D:I,6,0) -> 40.04 | Y29: =I29+X29 -> -1947.14 | Z29: Diff due to exchange gain/loss | AA29: =VLOOKUP(D29,'Ascendus DATA'!$F:$J,5,0) -> 1979.16 | AB29: =I29+AA29 -> -8.02
A30: A023951 | B30: A023951 | C30: I | D30: 246779411899 | E30: 45733 | F30: USD | G30: -62.49 | H30: 62.49 | I30: -5439.28 | K30: 45763 | L30: 45838 | M30: - | N30: 45809 | O30: 51158516 | P30: 1 | Q30: 45820 | R30: 210 | S30: 1.55e+16 | T30: Ascendas Panvel FTWZ Private Limited | U30: 5439.28 | W30: =X30/I30 -> -0.020002647 | X30: =VLOOKUP(D30,'[3]Customer TDS'!D:I,6,0) -> 108.8 | Y30: =I30+X30 -> -5330.48 | Z30: Diff due to exchange gain/loss | AA30: =VLOOKUP(D30,'Ascendus DATA'!$F:$J,5,0) -> 5417.34 | AB30: =I30+AA30 -> -21.94
A31: A023951 | B31: A023951 | C31: I | D31: 246779411896 | E31: 45733 | F31: USD | G31: -39.77 | H31: 39.77 | I31: -3461.68 | K31: 45763 | L31: 45838 | M31: - | N31: 45809 | O31: 51158519 | P31: 1 | Q31: 45820 | R31: 210 | S31: 1.55e+16 | T31: Ascendas Panvel FTWZ Private Limited | U31: 3461.68 | W31: =X31/I31 -> -0.020114511 | X31: =VLOOKUP(D31,'[3]Customer TDS'!D:I,6,0) -> 69.63 | Y31: =I31+X31 -> -3392.05 | Z31: Diff due to exchange gain/loss | AA31: =VLOOKUP(D31,'Ascendus DATA'!$F:$J,5,0) -> 3447.71 | AB31: =I31+AA31 -> -13.97
A32: A023951 | B32: A023951 | C32: I | D32: 246779411902 | E32: 45733 | F32: USD | G32: -2.13 | H32: 2.13 | I32: -185.4 | K32: 45763 | L32: 45838 | M32: - | N32: 45809 | O32: 51158521 | P32: 1 | Q32: 45820 | R32: 210 | S32: 1.55e+16 | T32: Ascendas Panvel FTWZ Private Limited | U32: 185.4 | W32: =X32/I32 -> -0.018770227 | X32: =VLOOKUP(D32,'[3]Customer TDS'!D:I,6,0) -> 3.48 | Y32: =I32+X32 -> -181.92 | Z32: Diff due to exchange gain/loss | AA32: =VLOOKUP(D32,'Ascendus DATA'!$F:$J,5,0) -> 184.65 | AB32: =I32+AA32 -> -0.75
A33: A023951 | B33: A023951 | C33: I | D33: 246779411723 | E33: 45733 | F33: USD | G33: -45.67 | H33: 45.67 | I33: -3975.23 | J33: NO EXCHANGE RATE | K33: 45763 | L33: 45838 | M33: - | N33: 45809 | O33: 51158523 | P33: 1 | Q33: 45820 | R33: 210 | S33: 1.55e+16 | T33: Ascendas Panvel FTWZ Private Limited | U33: 3975.23 | W33: =X33/I33 -> -0.019925891 | X33: =VLOOKUP(D33,'[3]Customer TDS'!D:I,6,0) -> 79.21 | Y33: =I33+X33 -> -3896.02 | Z33: Diff due to exchange gain/loss | AA33: =VLOOKUP(D33,'Ascendus DATA'!$F:$J,5,0) -> 3959.19 | AB33: =I33+AA33 -> -16.04
A34: A023951 | B34: A023951 | C34: I | D34: 246779411722 | E34: 45733 | F34: USD | G34: -39.96 | H34: 39.96 | I34: -3478.21 | K34: 45763 | L34: 45838 | M34: - | N34: 45809 | O34: 51158526 | P34: 1 | Q34: 45820 | R34: 210 | S34: 1.55e+16 | T34: Ascendas Panvel FTWZ Private Limited | U34: 3478.21 | W34: =X34/I34 -> -0.020018918 | X34: =VLOOKUP(D34,'[3]Customer TDS'!D:I,6,0) -> 69.63 | Y34: =I34+X34 -> -3408.58 | Z34: Diff due to exchange gain/loss | AA34: =VLOOKUP(D34,'Ascendus DATA'!$F:$J,5,0) -> 3464.18 | AB34: =I34+AA34 -> -14.03
A35: A023951 | B35: A023951 | C35: I | D35: 246779411907 | E35: 45733 | F35: USD | G35: -17.04 | H35: 17.04 | I35: -1483.2 | K35: 45763 | L35: 45838 | M35: - | N35: 45809 | O35: 51158529 | P35: 1 | Q35: 45820 | R35: 210 | S35: 1.55e+16 | T35: Ascendas Panvel FTWZ Private Limited | U35: 1483.2 | W35: =X35/I35 -> -0.019950108 | X35: =VLOOKUP(D35,'[3]Customer TDS'!D:I,6,0) -> 29.59 | Y35: =I35+X35 -> -1453.61 | Z35: Diff due to exchange gain/loss | AA35: =VLOOKUP(D35,'Ascendus DATA'!$F:$J,5,0) -> 1477.22 | AB35: =I35+AA35 -> -5.98
A36: A023951 | B36: A023951 | C36: I | D36: 246779411909 | E36: 45733 | F36: USD | G36: -28.41 | H36: 28.41 | I36: -2472.88 | K36: 45763 | L36: 45838 | M36: - | N36: 45809 | O36: 51158531 | P36: 1 | Q36: 45820 | R36: 210 | S36: 1.55e+16 | T36: Ascendas Panvel FTWZ Private Limited | U36: 2472.88 | W36: =X36/I36 -> -0.020061629 | X36: =VLOOKUP(D36,'[3]Customer TDS'!D:I,6,0) -> 49.61 | Y36: =I36+X36 -> -2423.27 | Z36: Diff due to exchange gain/loss | AA36: =VLOOKUP(D36,'Ascendus DATA'!$F:$J,5,0) -> 2462.9 | AB36: =I36+AA36 -> -9.98
A37: A023951 | B37: A023951 | C37: I | D37: 246779411600 | E37: 45733 | F37: USD | G37: -2.6 | H37: 2.6 | I37: -226.31 | K37: 45763 | L37: 45838 | M37: - | N37: 45809 | O37: 51158533 | P37: 1 | Q37: 45820 | R37: 210 | S37: 1.55e+16 | T37: Ascendas Panvel FTWZ Private Limited | U37: 226.31 | W37: =X37/I37 -> -0.019221422 | X37: =VLOOKUP(D37,'[3]Customer TDS'!D:I,6,0) -> 4.35 | Y37: =I37+X37 -> -221.96 | Z37: Diff due to exchange gain/loss | AA37: =VLOOKUP(D37,'Ascendus DATA'!$F:$J,5,0) -> 225.4 | AB37: =I37+AA37 -> -0.91
A38: A023951 | B38: A023951 | C38: I | D38: 246779410436 | E38: 45719 | F38: USD | G38: -1332.41 | H38: 1332.41 | I38: -115976.18 | K38: 45749 | L38: 45838 | M38: - | N38: 45809 | O38: 51158534 | P38: 1 | Q38: 45820 | R38: 210 | S38: 1.55e+16 | T38: Ascendas Panvel FTWZ Private Limited | U38: 115976.18 | W38: =X38/I38 -> -0.020001349 | X38: =VLOOKUP(D38,'[3]Customer TDS'!D:I,6,0) -> 2319.68 | Y38: =I38+X38 -> -113656.5 | Z38: Diff due to exchange gain/loss | AA38: =VLOOKUP(D38,'Ascendus DATA'!$F:$J,5,0) -> 115508.3 | AB38: =I38+AA38 -> -467.88
A39: A023951 | B39: A023951 | C39: I | D39: 246779411595 | E39: 45733 | F39: USD | G39: -51.56 | H39: 51.56 | I39: -4487.91 | K39: 45763 | L39: 45838 | M39: - | N39: 45809 | O39: 51158535 | P39: 1 | Q39: 45820 | R39: 210 | S39: 1.55e+16 | T39: Ascendas Panvel FTWZ Private Limited | U39: 4487.91 | W39: =X39/I39 -> -0.019975891 | X39: =VLOOKUP(D39,'[3]Customer TDS'!D:I,6,0) -> 89.65 | Y39: =I39+X39 -> -4398.26 | Z39: Diff due to exchange gain/loss | AA39: =VLOOKUP(D39,'Ascendus DATA'!$F:$J,5,0) -> 4469.8 | AB39: =I39+AA39 -> -18.11
A40: A023951 | B40: A023951 | C40: I | D40: 246779414663 | E40: 45736 | F40: USD | G40: -45 | H40: 45 | I40: -3916.91 | K40: 45766 | L40: 45838 | M40: - | N40: 45809 | O40: 51158536 | P40: 1 | Q40: 45820 | R40: 210 | S40: 1.55e+16 | T40: Ascendas Panvel FTWZ Private Limited | U40: 3916.91 | W40: =X40/I40 -> -0.02000046 | X40: =VLOOKUP(D40,'[3]Customer TDS'!D:I,6,0) -> 78.34 | Y40: =I40+X40 -> -3838.57 | Z40: Diff due to exchange gain/loss | AA40: =VLOOKUP(D40,'Ascendus DATA'!$F:$J,5,0) -> 3901.11 | AB40: =I40+AA40 -> -15.8
A41: A023951 | B41: A023951 | C41: I | D41: 246779411594 | E41: 45733 | F41: USD | G41: -17.19 | H41: 17.19 | I41: -1496.26 | K41: 45763 | L41: 45838 | M41: - | N41: 45809 | O41: 51158537 | P41: 1 | Q41: 45820 | R41: 210 | S41: 1.55e+16 | T41: Ascendas Panvel FTWZ Private Limited | U41: 1496.26 | W41: =X41/I41 -> -0.019775975 | X41: =VLOOKUP(D41,'[3]Customer TDS'!D:I,6,0) -> 29.59 | Y41: =I41+X41 -> -1466.67 | Z41: Diff due to exchange gain/loss | AA41: =VLOOKUP(D41,'Ascendus DATA'!$F:$J,5,0) -> 1490.22 | AB41: =I41+AA41 -> -6.04
A42: A023951 | B42: A023951 | C42: I | D42: 246779410098 | E42: 45708 | F42: USD | G42: -2380.95 | H42: 2380.95 | I42: -206046.42 | K42: 45738 | L42: 45838 | M42: - | N42: 45809 | O42: 51158538 | P42: 1 | Q42: 45820 | R42: 210 | S42: 1.55e+16 | T42: Ascendas Panvel FTWZ Private Limited | U42: 206046.42 | W42: =X42/I42 -> -0.020000396 | X42: =VLOOKUP(D42,'[3]Customer TDS'!D:I,6,0) -> 4121.01 | Y42: =I42+X42 -> -201925.41 | Z42: Diff due to exchange gain/loss | AA42: =VLOOKUP(D42,'Ascendus DATA'!$F:$J,5,0) -> 205484.7 | AB42: =I42+AA42 -> -561.72
A43: A023951 | B43: A023951 | C43: I | D43: 246779411599 | E43: 45733 | F43: USD | G43: -37.95 | H43: 37.95 | I43: -3303.26 | K43: 45763 | L43: 45838 | M43: - | N43: 45809 | O43: 51158539 | P43: 1 | Q43: 45820 | R43: 210 | S43: 1.55e+16 | T43: Ascendas Panvel FTWZ Private Limited | U43: 3303.26 | W43: =X43/I43 -> -0.020025672 | X43: =VLOOKUP(D43,'[3]Customer TDS'!D:I,6,0) -> 66.15 | Y43: =I43+X43 -> -3237.11 | Z43: Diff due to exchange gain/loss | AA43: =VLOOKUP(D43,'Ascendus DATA'!$F:$J,5,0) -> 3289.93 | AB43: =I43+AA43 -> -13.33
...

Sheet Customer TDS
A2: Creditor Code | B2: Creditor | C2: Ty | D2: Item# | E2: Item Date | F2: CCY | G2: FC Amount | H2: Settled FC Amount | I2: LC Amount | J2: Particular | K2: Due Date | L2: Last Sett. Date | M2: Job# | N2: VC Period | O2: VC# | P2: VC Seq | Q2: VC Date | R2: Tx. Type | S2: Reference | T2: Full Name | U2: Settled LC Amount
A3: A023951 | B3: A023951 | C3: I | D3: 246779411742 | E3: 45733 | F3: USD | G3: 0.47 | H3: - | I3: 40.91 | J3: C: ASCENDAS27 P: A023951 I 246779411742 | K3: 45763 | M3: - | N3: 45809 | O3: 51127447 | P3: 1 | Q3: 45819 | R3: 230 | T3: Ascendas Panvel FTWZ Private Limited | U3: 0
A4: A023951 | B4: A023951 | C4: I | D4: 246779411601 | E4: 45733 | F4: USD | G4: 0.47 | H4: - | I4: 40.91 | J4: C: ASCENDAS27 P: A023951 I 246779411601 | K4: 45763 | M4: - | N4: 45809 | O4: 51162689 | P4: 1 | Q4: 45820 | R4: 230 | T4: Ascendas Panvel FTWZ Private Limited | U4: 0
A5: A023951 | B5: A023951 | C5: I | D5: 246779411717 | E5: 45733 | F5: USD | G5: 0.91 | H5: - | I5: 79.21 | J5: C: ASCENDAS27 P: A023951 I 246779411717 | K5: 45763 | M5: - | N5: 45809 | O5: 51162692 | P5: 1 | Q5: 45820 | R5: 230 | T5: Ascendas Panvel FTWZ Private Limited | U5: 0
A6: A023951 | B6: A023951 | C6: I | D6: 246779411913 | E6: 45733 | F6: USD | G6: 0.57 | H6: - | I6: 49.61 | J6: C: ASCENDAS27 P: A023951 I 246779411913 | K6: 45763 | M6: - | N6: 45809 | O6: 51162693 | P6: 1 | Q6: 45820 | R6: 230 | T6: Ascendas Panvel FTWZ Private Limited | U6: 0
A7: A023951 | B7: A023951 | C7: I | D7: 246779411740 | E7: 45733 | F7: USD | G7: 0.46 | H7: - | I7: 40.04 | J7: C: ASCENDAS27 P: A023951 I 246779411740 | K7: 45763 | M7: - | N7: 45809 | O7: 51162694 | P7: 1 | Q7: 45820 | R7: 230 | T7: Ascendas Panvel FTWZ Private Limited | U7: 0
A8: A023951 | B8: A023951 | C8: I | D8: 246779412111 | E8: 45733 | F8: USD | G8: 8.41 | H8: - | I8: 732.03 | J8: C: ASCENDAS27 P: A023951 I 246779412111 | K8: 45763 | M8: - | N8: 45809 | O8: 51162695 | P8: 1 | Q8: 45820 | R8: 230 | T8: Ascendas Panvel FTWZ Private Limited | U8: 0
