Workbook

Sheet LEDGER FINAL
N1: =SUBTOTAL(9,N2:N223) -> 8848605.4
A2: Customer | B2: Customer Account: Name 1 | C2: Fiscal Year | D2: Posting period | E2: Posting Date | F2: Document Type | G2: Document Header Text | H2: Invoice No | I2: G/L Account | J2: Document Number | K2: Document Currency Key | L2: Document Currency Value | M2: Company Code Currency Key | N2: Company Code Currency Value | O2: Text | P2: Baseline Payment Dte | Q2: Clearing Date | R2: Clearing Document | S2: TDS | T2: Section
A3: 100222362 | B3: ONNSYNEX VENTURES PRIVATE LIMITED | C3: 2025 | D3: 4 | E3: 45758 | F3: DA | I3: 212100 | J3: 1600000012 | K3: INR | L3: 1 | M3: INR | N3: 1 | O3: Overpayment | P3: 45758 | Q3: 45758 | R3: 1600000012
A4: 100222362 | B4: ONNSYNEX VENTURES PRIVATE LIMITED | C4: 2025 | D4: 4 | E4: 45758 | F4: DA | I4: 212100 | J4: 1600000012 | K4: INR | L4: -1 | M4: INR | N4: -1 | O4: Overpayment | P4: 45758 | Q4: 45758 | R4: 1600000012
A5: 100222362 | B5: ONNSYNEX VENTURES PRIVATE LIMITED | C5: 2025 | D5: 2 | E5: 45705 | F5: DY | G5: Na | I5: 212100 | J5: 1400000001 | K5: USD | L5: 75 | M5: INR | N5: 6472.77 | P5: 45705 | Q5: 45707 | R5: 1400000001
A6: 100222362 | B6: ONNSYNEX VENTURES PRIVATE LIMITED | C6: 2025 | D6: 2 | E6: 45705 | F6: DY | G6: Na | I6: 212100 | J6: 1400000001 | K6: USD | L6: -75 | M6: INR | N6: -6472.77 | P6: 45705 | Q6: 45707 | R6: 1400000001
A7: 100222362 | B7: ONNSYNEX VENTURES PRIVATE LIMITED | C7: 2025 | D7: 8 | E7: 45889 | F7: DZ | G7: RBINR52025071152142380 | I7: 212100 | J7: 1400000026 | K7: INR | L7: -500000 | M7: INR | N7: -500000 | P7: 45889
A8: 100222362 | B8: ONNSYNEX VENTURES PRIVATE LIMITED | C8: 2025 | D8: 8 | E8: 45889 | F8: DZ | G8: RBINR52025071152144290 | I8: 212100 | J8: 1400000027 | K8: INR | L8: -500000 | M8: INR | N8: -500000 | P8: 45889
A9: 100222362 | B9: ONNSYNEX VENTURES PRIVATE LIMITED | C9: 2025 | D9: 10 | E9: 45931 | F9: DZ | G9: HDFCR52025091059694776 | I9: 212100 | J9: 1400000043 | K9: INR | L9: -500000 | M9: INR | N9: -500000 | P9: 45931
A10: 100222362 | B10: ONNSYNEX VENTURES PRIVATE LIMITED | C10: 2025 | D10: 10 | E10: 45931 | F10: DZ | G10: HDFCR52025091059714564 | I10: 212100 | J10: 1400000044 | K10: INR | L10: -500000 | M10: INR | N10: -500000 | P10: 45931
A11: 100222362 | B11: ONNSYNEX VENTURES PRIVATE LIMITED | C11: 2025 | D11: 10 | E11: 45931 | F11: DZ | G11: HDFCR52025091059694771 | I11: 212100 | J11: 1400000045 | K11: INR | L11: -500000 | M11: INR | N11: -500000 | P11: 45931
A12: 100222362 | B12: ONNSYNEX VENTURES PRIVATE LIMITED | C12: 2025 | D12: 10 | E12: 45931 | F12: DZ | G12: RBINR52025091011436663 | I12: 212100 | J12: 1400000046 | K12: INR | L12: -500000 | M12: INR | N12: -500000 | P12: 45931
A13: 100222362 | B13: ONNSYNEX VENTURES PRIVATE LIMITED | C13: 2025 | D13: 10 | E13: 45959 | F13: DZ | G13: FDX3H9MYLVYP | I13: 212100 | J13: 1400000055 | K13: INR | L13: -5000000 | M13: INR | N13: -5000000 | P13: 45959
A14: 100222362 | B14: ONNSYNEX VENTURES PRIVATE LIMITED | C14: 2025 | D14: 2 | E14: 45701 | F14: XC | G14: 6788ZP25000006 | H14: 6788ZP25000006 | I14: 212100 | J14: 7000000036 | K14: INR | L14: -1 | M14: INR | N14: -1 | O14: Overpayment | P14: 45701 | Q14: 45758 | R14: 1600000012
A15: 100222362 | B15: ONNSYNEX VENTURES PRIVATE LIMITED | C15: 2025 | D15: 3 | E15: 45744 | F15: XC | G15: 6788ZR25000006 | H15: 6788ZR25000006 | I15: 212100 | J15: 7000000128 | K15: INR | L15: 1 | M15: INR | N15: 1 | O15: Overpayment | P15: 45701 | Q15: 45758 | R15: 1600000012
A16: 100222362 | B16: ONNSYNEX VENTURES PRIVATE LIMITED | C16: 2025 | D16: 4 | E16: 45748 | F16: XC | G16: 6788ZP25000117 | H16: 6788ZP25000117 | I16: 212100 | J16: 7000000131 | K16: INR | L16: -1500000 | M16: INR | N16: -1500000 | O16: as per SME conformation parked as overpayment | P16: 45743
A17: 100222362 | B17: ONNSYNEX VENTURES PRIVATE LIMITED | C17: 2025 | D17: 11 | E17: 45976 | F17: DY | G17: NA | H17: KNOCK OFF ENTRY | I17: 212100 | J17: 1400000084 | K17: USD | L17: 150 | M17: INR | N17: 12897.56 | P17: 45976 | Q17: 45976 | R17: 1400000084
A18: 100222362 | B18: ONNSYNEX VENTURES PRIVATE LIMITED | C18: 2025 | D18: 11 | E18: 45976 | F18: DY | G18: NA | H18: KNOCK OFF ENTRY | I18: 212100 | J18: 1400000084 | K18: USD | L18: -150 | M18: INR | N18: -13038.28 | P18: 45976 | Q18: 45976 | R18: 1400000084
A19: 100222362 | B19: ONNSYNEX VENTURES PRIVATE LIMITED | C19: 2025 | D19: 8 | E19: 45889 | F19: DR | G19: NA | H19: 256788410349 | I19: 212100 | J19: 1800000477 | K19: USD | L19: 100 | M19: INR | N19: 8603.01 | O19: INTRA 1-15 Aug 25 | P19: 45889 | S19: =VLOOKUP(H19,TDS!$B$2:$C$70,2,0) -> #N/A | T19: =VLOOKUP(H19,TDS!$B$2:$D$70,3,0) -> #N/A
A20: 100222362 | B20: ONNSYNEX VENTURES PRIVATE LIMITED | C20: 2025 | D20: 9 | E20: 45904 | F20: DR | G20: NA | H20: 256788410353 | I20: 212100 | J20: 1800000479 | K20: USD | L20: 100 | M20: INR | N20: 8751.43 | O20: Intra 16-31 Aug 25 | P20: 45904 | S20: =VLOOKUP(H20,TDS!$B$2:$C$70,2,0) -> 175.03 | T20: =VLOOKUP(H20,TDS!$B$2:$D$70,3,0) -> 194C
A21: 100222362 | B21: ONNSYNEX VENTURES PRIVATE LIMITED | C21: 2025 | D21: 4 | E21: 45751 | F21: DR | G21: NA | H21: 256788410027 | I21: 212100 | J21: 1800000152 | K21: USD | L21: 170 | M21: INR | N21: 14776.71 | O21: Transportation Inbound charges for Jan 25 | P21: 45755 | S21: =VLOOKUP(H21,TDS!$B$2:$C$70,2,0) -> 296 | T21: =VLOOKUP(H21,TDS!$B$2:$D$70,3,0) -> 194C
A22: 100222362 | B22: ONNSYNEX VENTURES PRIVATE LIMITED | C22: 2025 | D22: 3 | E22: 45722 | F22: DR | G22: NA | H22: 246788410045 | I22: 212100 | J22: 1800000050 | K22: USD | L22: 841.24 | M22: INR | N22: 72928.16 | O22: Storage Charges for the month of November 2024 | P22: 45722 | S22: =VLOOKUP(H22,TDS!$B$2:$C$70,2,0) -> 7151 | T22: =VLOOKUP(H22,TDS!$B$2:$D$70,3,0) -> 194I
A23: 100222362 | B23: ONNSYNEX VENTURES PRIVATE LIMITED | C23: 2025 | D23: 3 | E23: 45722 | F23: DR | G23: NA | H23: 246788410046 | I23: 212100 | J23: 1800000051 | K23: USD | L23: 4169.66 | M23: INR | N23: 361473.08 | O23: Storage Charges for the month of December 2024 | P23: 45722 | S23: =VLOOKUP(H23,TDS!$B$2:$C$70,2,0) -> 35442 | T23: =VLOOKUP(H23,TDS!$B$2:$D$70,3,0) -> 194I
A24: 100222362 | B24: ONNSYNEX VENTURES PRIVATE LIMITED | C24: 2025 | D24: 3 | E24: 45719 | F24: DR | G24: NA | H24: 246788410039 | I24: 212100 | J24: 1800000045 | K24: USD | L24: 1044.69 | M24: INR | N24: 90565.49 | O24: CY-CY Ground Rent charges for Oct 2024. Exchange c | P24: 45719 | S24: =VLOOKUP(H24,TDS!$B$2:$C$70,2,0) -> 9072 | T24: =VLOOKUP(H24,TDS!$B$2:$D$70,3,0) -> 194I
A25: 100222362 | B25: ONNSYNEX VENTURES PRIVATE LIMITED | C25: 2025 | D25: 3 | E25: 45719 | F25: DR | G25: NA | H25: 246788410040 | I25: 212100 | J25: 1800000046 | K25: USD | L25: 129.98 | M25: INR | N25: 11268.13 | O25: CY-CY Ground Rent charges for Dec 2024. Exchange c | P25: 45719 | S25: =VLOOKUP(H25,TDS!$B$2:$C$70,2,0) -> 1129 | T25: =VLOOKUP(H25,TDS!$B$2:$D$70,3,0) -> 194I
A26: 100222362 | B26: ONNSYNEX VENTURES PRIVATE LIMITED | C26: 2025 | D26: 3 | E26: 45719 | F26: DR | G26: NA | H26: 246788410042 | I26: 212100 | J26: 1800000047 | K26: USD | L26: 4421.13 | M26: INR | N26: 383273.33 | O26: Storage Charges for the month of August, 2024 | P26: 45719 | S26: =VLOOKUP(H26,TDS!$B$2:$C$70,2,0) -> 38022 | T26: =VLOOKUP(H26,TDS!$B$2:$D$70,3,0) -> 194I
A27: 100222362 | B27: ONNSYNEX VENTURES PRIVATE LIMITED | C27: 2025 | D27: 3 | E27: 45719 | F27: DR | G27: NA | H27: 246788410043 | I27: 212100 | J27: 1800000048 | K27: USD | L27: 2730.01 | M27: INR | N27: 236668.01 | O27: Storage Charges for the month of September, 2024 | P27: 45719 | S27: =VLOOKUP(H27,TDS!$B$2:$C$70,2,0) -> 23478 | T27: =VLOOKUP(H27,TDS!$B$2:$D$70,3,0) -> 194I
A28: 100222362 | B28: ONNSYNEX VENTURES PRIVATE LIMITED | C28: 2025 | D28: 3 | E28: 45719 | F28: DR | G28: NA | H28: 246788410044 | I28: 212100 | J28: 1800000049 | K28: USD | L28: 474.24 | M28: INR | N28: 41112.46 | O28: Storage Charges for the month of October, 2024 | P28: 45719 | S28: =VLOOKUP(H28,TDS!$B$2:$C$70,2,0) -> 4061 | T28: =VLOOKUP(H28,TDS!$B$2:$D$70,3,0) -> 194I
A29: 100222362 | B29: ONNSYNEX VENTURES PRIVATE LIMITED | C29: 2025 | D29: 8 | E29: 45870 | F29: DR | G29: NA | H29: 256788410322 | I29: 212100 | J29: 1800000447 | K29: USD | L29: 75 | M29: INR | N29: 6452.26 | O29: Fixed Storage Charges for August 2025 | P29: 45870 | S29: =VLOOKUP(H29,TDS!$B$2:$C$70,2,0) -> #N/A | T29: =VLOOKUP(H29,TDS!$B$2:$D$70,3,0) -> #N/A
A30: 100222362 | B30: ONNSYNEX VENTURES PRIVATE LIMITED | C30: 2025 | D30: 6 | E30: 45818 | F30: DR | G30: NA | H30: 256788410228 | I30: 212100 | J30: 1800000353 | K30: USD | L30: 75 | M30: INR | N30: 6411.81 | O30: Fixed Storage Charges fo JUNE 2025 | P30: 45818 | S30: =VLOOKUP(H30,TDS!$B$2:$C$70,2,0) -> #N/A | T30: =VLOOKUP(H30,TDS!$B$2:$D$70,3,0) -> #N/A
... A35: 100222362 | B35: ONNSYNEX VENTURES PRIVATE LIMITED | C35: 2025 | D35: 5 | E35: 45785 | F35: DR | G35: NA | H35: 256788410218 | I35: 212100 | J35: 1800000343 | K35: USD | L35: 13.18 | M35: INR | N35: 1133.27 | O35: Outbound chgs - 16 - 30 Apr 25 | P35: 45785 | S35: =VLOOKUP(H35,TDS!$B$2:$C$70,2,0) -> #N/A | T35: =VLOOKUP(H35,TDS!$B$2:$D$70,3,0) -> #N/A
A36: 100222362 | B36: ONNSYNEX VENTURES PRIVATE LIMITED | C36: 2025 | D36: 10 | E36: 45947 | F36: DG | G36: NA | H36: 256788420141 | I36: 212100 | J36: 1600000261 | K36: USD | L36: -1211.9 | M36: INR | N36: -106878.39 | O36: Credit note raised against 256788410417 | P36: 45947 | Q36: 45976 | R36: 1400000084 | S36: =VLOOKUP(H36,TDS!$B$2:$C$70,2,0) -> #N/A | T36: =VLOOKUP(H36,TDS!$B$2:$D$70,3,0) -> #N/A
A37: 100222362 | B37: ONNSYNEX VENTURES PRIVATE LIMITED | C37: 2025 | D37: 10 | E37: 45947 | F37: DG | G37: NA | H37: 256788420142 | I37: 212100 | J37: 1600000262 | K37: USD | L37: -40 | M37: INR | N37: -3527.63 | O37: Credit note raised against 256788410418 | P37: 45947 | Q37: 45976 | R37: 1400000084 | S37: =VLOOKUP(H37,TDS!$B$2:$C$70,2,0) -> #N/A | T37: =VLOOKUP(H37,TDS!$B$2:$D$70,3,0) -> #N/A
A38: 100222362 | B38: ONNSYNEX VENTURES PRIVATE LIMITED | C38: 2025 | D38: 10 | E38: 45947 | F38: DG | G38: NA | H38: 256788420143 | I38: 212100 | J38: 1600000263 | K38: USD | L38: -11.26 | M38: INR | N38: -993.03 | O38: Credit note raised against 256788410419 | P38: 45947 | Q38: 45976 | R38: 1400000084 | S38: =VLOOKUP(H38,TDS!$B$2:$C$70,2,0) -> #N/A | T38: =VLOOKUP(H38,TDS!$B$2:$D$70,3,0) -> #N/A
A39: 100222362 | B39: ONNSYNEX VENTURES PRIVATE LIMITED | C39: 2025 | D39: 4 | E39: 45763 | F39: DR | G39: NA | H39: 256779412015 | I39: 212100 | J39: 1800007124 | K39: USD | L39: 86.56 | M39: INR | N39: 7523.95 | O39: VAS Activity - Jan 25, Ex Rate. 86.64 | P39: 45763 | S39: =VLOOKUP(H39,TDS!$B$2:$C$70,2,0) -> 150 | T39: =VLOOKUP(H39,TDS!$B$2:$D$70,3,0) -> 194C
A40: 100222362 | B40: ONNSYNEX VENTURES PRIVATE LIMITED | C40: 2025 | D40: 4 | E40: 45763 | F40: DR | G40: NA | H40: 256779412058 | I40: 212100 | J40: 1800007167 | K40: USD | L40: 188.84 | M40: INR | N40: 16414.32 | O40: VAS Activity - Feb 25, Ex Rate. 87.40 | P40: 45763 | S40: =VLOOKUP(H40,TDS!$B$2:$C$70,2,0) -> 328 | T40: =VLOOKUP(H40,TDS!$B$2:$D$70,3,0) -> 194C
A41: 100222362 | B41: ONNSYNEX VENTURES PRIVATE LIMITED | C41: 2025 | D41: 4 | E41: 45763 | F41: DR | G41: NA | H41: 256779412096 | I41: 212100 | J41: 1800007205 | K41: USD | L41: 16.83 | M41: INR | N41: 1462.89 | O41: VAS Activity - Mar 25, 16-31, Ex Rate. 85.58 | P41: 45763 | S41: =VLOOKUP(H41,TDS!$B$2:$C$70,2,0) -> 29 | T41: =VLOOKUP(H41,TDS!$B$2:$D$70,3,0) -> 194C
A42: 100222362 | B42: ONNSYNEX VENTURES PRIVATE LIMITED | C42: 2025 | D42: 7 | E42: 45847 | F42: DR | G42: NA | H42: 256788410243 | I42: 212100 | J42: 1800000368 | K42: USD | L42: 30 | M42: INR | N42: 2580.02 | O42: CY - WH Destuff Charges fo MAY 2025 | P42: 45847 | S42: =VLOOKUP(H42,TDS!$B$2:$C$70,2,0) -> #N/A | T42: =VLOOKUP(H42,TDS!$B$2:$D$70,3,0) -> #N/A
A43: 100222362 | B43: ONNSYNEX VENTURES PRIVATE LIMITED | C43: 2025 | D43: 7 | E43: 45847 | F43: DR | G43: NA | H43: 256788410259 | I43: 212100 | J43: 1800000384 | K43: USD | L43: 75 | M43: INR | N43: 6450.05 | O43: Fixed Rental charges for April 2025 | P43: 45847 | S43: =VLOOKUP(H43,TDS!$B$2:$C$70,2,0) -> 129 | T43: =VLOOKUP(H43,TDS!$B$2:$D$70,3,0) -> 194C
A44: 100222362 | B44: ONNSYNEX VENTURES PRIVATE LIMITED | C44: 2025 | D44: 9 | E44: 45904 | F44: DR | G44: NA | H44: 256779416953 | I44: 212100 | J44: 1800012496 | K44: USD | L44: 2.14 | M44: INR | N44: 187.28 | O44: CODC Out chgs -16-31 Aug 25 | P44: 45904 | S44: =VLOOKUP(H44,TDS!$B$2:$C$70,2,0) -> 3.75 | T44: =VLOOKUP(H44,TDS!$B$2:$D$70,3,0) -> 194C
...

Sheet LEDGER
A1: Customer | B1: Customer Account: Name 1 | C1: Fiscal Year | D1: Posting period | E1: Posting Date | F1: Document Number | G1: Document Type | H1: Document Header Text | I1: Invoice No | J1: G/L Account | K1: Document Currency Key | L1: Document Currency Value | M1: Company Code Currency Key | N1: Company Code Currency Value | O1: Text | P1: Baseline Payment Dte | Q1: Clearing Date | R1: Clearing Document | S1: TDS
A2: 100222362 | B2: ONNSYNEX VENTURES PRIVATE LIMITED | C2: 2025 | D2: 4 | E2: 45758 | F2: 1600000012 | G2: DA | J2: 212100 | K2: INR | L2: 1 | M2: INR | N2: 1 | O2: Overpayment | P2: 45758 | Q2: 45758 | R2: 1600000012 | S2: =VLOOKUP(I2,TDS!$A$1:$C$70,4,FALSE) -> #N/A
A3: 100222362 | B3: ONNSYNEX VENTURES PRIVATE LIMITED | C3: 2025 | D3: 4 | E3: 45758 | F3: 1600000012 | G3: DA | J3: 212100 | K3: INR | L3: -1 | M3: INR | N3: -1 | O3: Overpayment | P3: 45758 | Q3: 45758 | R3: 1600000012 | S3: =VLOOKUP(I3,TDS!$A$1:$C$70,4,FALSE) -> #N/A
A4: 100222362 | B4: ONNSYNEX VENTURES PRIVATE LIMITED | C4: 2025 | D4: 2 | E4: 45705 | F4: 1400000001 | G4: DY | H4: Na | J4: 212100 | K4: USD | L4: 75 | M4: INR | N4: 6472.77 | P4: 45705 | Q4: 45707 | R4: 1400000001 | S4: =VLOOKUP(I4,TDS!$A$1:$C$70,4,FALSE) -> #N/A
A5: 100222362 | B5: ONNSYNEX VENTURES PRIVATE LIMITED | C5: 2025 | D5: 2 | E5: 45705 | F5: 1400000001 | G5: DY | H5: Na | J5: 212100 | K5: USD | L5: -75 | M5: INR | N5: -6472.77 | P5: 45705 | Q5: 45707 | R5: 1400000001 | S5: =VLOOKUP(I5,TDS!$A$1:$C$70,4,FALSE) -> #N/A
A6: 100222362 | B6: ONNSYNEX VENTURES PRIVATE LIMITED | C6: 2025 | D6: 8 | E6: 45889 | F6: 1400000026 | G6: DZ | H6: RBINR52025071152142380 | J6: 212100 | K6: INR | L6: -500000 | M6: INR | N6: -500000 | P6: 45889 | S6: =VLOOKUP(I6,TDS!$A$1:$C$70,4,FALSE) -> #N/A
A7: 100222362 | B7: ONNSYNEX VENTURES PRIVATE LIMITED | C7: 2025 | D7: 8 | E7: 45889 | F7: 1400000027 | G7: DZ | H7: RBINR52025071152144290 | J7: 212100 | K7: INR | L7: -500000 | M7: INR | N7: -500000 | P7: 45889 | S7: =VLOOKUP(I7,TDS!$A$1:$C$70,4,FALSE) -> #N/A
A8: 100222362 | B8: ONNSYNEX VENTURES PRIVATE LIMITED | C8: 2025 | D8: 10 | E8: 45931 | F8: 1400000043 | G8: DZ | H8: HDFCR52025091059694776 | J8: 212100 | K8: INR | L8: -500000 | M8: INR | N8: -500000 | P8: 45931 | S8: =VLOOKUP(I8,TDS!$A$1:$C$70,4,FALSE) -> #N/A
A9: 100222362 | B9: ONNSYNEX VENTURES PRIVATE LIMITED | C9: 2025 | D9: 10 | E9: 45931 | F9: 1400000044 | G9: DZ | H9: HDFCR52025091059714564 | J9: 212100 | K9: INR | L9: -500000 | M9: INR | N9: -500000 | P9: 45931 | S9: =VLOOKUP(I9,TDS!$A$1:$C$70,4,FALSE) -> #N/A
A10: 100222362 | B10: ONNSYNEX VENTURES PRIVATE LIMITED | C10: 2025 | D10: 10 | E10: 45931 | F10: 1400000045 | G10: DZ | H10: HDFCR52025091059694771 | J10: 212100 | K10: INR | L10: -500000 | M10: INR | N10: -500000 | P10: 45931 | S10: =VLOOKUP(I10,TDS!$A$1:$C$70,4,FALSE) -> #N/A
A11: 100222362 | B11: ONNSYNEX VENTURES PRIVATE LIMITED | C11: 2025 | D11: 10 | E11: 45931 | F11: 1400000046 | G11: DZ | H11: RBINR52025091011436663 | J11: 212100 | K11: INR | L11: -500000 | M11: INR | N11: -500000 | P11: 45931 | S11: =VLOOKUP(I11,TDS!$A$1:$C$70,4,FALSE) -> #N/A
A12: 100222362 | B12: ONNSYNEX VENTURES PRIVATE LIMITED | C12: 2025 | D12: 10 | E12: 45959 | F12: 1400000055 | G12: DZ | H12: FDX3H9MYLVYP | J12: 212100 | K12: INR | L12: -5000000 | M12: INR | N12: -5000000 | P12: 45959 | S12: =VLOOKUP(I12,TDS!$A$1:$C$70,4,FALSE) -> #N/A
A13: 100222362 | B13: ONNSYNEX VENTURES PRIVATE LIMITED | C13: 2025 | D13: 2 | E13: 45701 | F13: 7000000036 | G13: XC | H13: 6788ZP25000006 | I13: 6788ZP25000006 | J13: 212100 | K13: INR | L13: -1 | M13: INR | N13: -1 | O13: Overpayment | P13: 45701 | Q13: 45758 | R13: 1600000012 | S13: =VLOOKUP(I13,TDS!$A$1:$C$70,4,FALSE) -> #N/A
A14: 100222362 | B14: ONNSYNEX VENTURES PRIVATE LIMITED | C14: 2025 | D14: 3 | E14: 45744 | F14: 7000000128 | G14: XC | H14: 6788ZR25000006 | I14: 6788ZR25000006 | J14: 212100 | K14: INR | L14: 1 | M14: INR | N14: 1 | O14: Overpayment | P14: 45701 | Q14: 45758 | R14: 1600000012 | S14: =VLOOKUP(I14,TDS!$A$1:$C$70,4,FALSE) -> #N/A
A15: 100222362 | B15: ONNSYNEX VENTURES PRIVATE LIMITED | C15: 2025 | D15: 4 | E15: 45748 | F15: 7000000131 | G15: XC | H15: 6788ZP25000117 | I15: 6788ZP25000117 | J15: 212100 | K15: INR | L15: -1500000 | M15: INR | N15: -1500000 | O15: as per SME conformation parked as overpayment | P15: 45743 | S15: =VLOOKUP(I15,TDS!$A$1:$C$70,4,FALSE) -> #N/A
A16: 100222362 | B16: ONNSYNEX VENTURES PRIVATE LIMITED | C16: 2025 | D16: 11 | E16: 45976 | F16: 1400000084 | G16: DY | H16: NA | I16: KNOCK OFF ENTRY | J16: 212100 | K16: USD | L16: 150 | M16: INR | N16: 12897.56 | P16: 45976 | Q16: 45976 | R16: 1400000084 | S16: =VLOOKUP(I16,TDS!$A$1:$C$70,4,FALSE) -> #N/A
A17: 100222362 | B17: ONNSYNEX VENTURES PRIVATE LIMITED | C17: 2025 | D17: 11 | E17: 45976 | F17: 1400000084 | G17: DY | H17: NA | I17: KNOCK OFF ENTRY | J17: 212100 | K17: USD | L17: -150 | M17: INR | N17: -13038.28 | P17: 45976 | Q17: 45976 | R17: 1400000084 | S17: =VLOOKUP(I17,TDS!$A$1:$C$70,4,FALSE) -> #N/A
A18: 100222362 | B18: ONNSYNEX VENTURES PRIVATE LIMITED | C18: 2025 | D18: 8 | E18: 45889 | F18: 1800000477 | G18: DR | H18: NA | I18: 256788410349 | J18: 212100 | K18: USD | L18: 100 | M18: INR | N18: 8603.01 | O18: INTRA 1-15 Aug 25 | P18: 45889 | S18: =VLOOKUP(I18,TDS!$A$1:$C$70,4,FALSE) -> #N/A
A19: 100222362 | B19: ONNSYNEX VENTURES PRIVATE LIMITED | C19: 2025 | D19: 9 | E19: 45904 | F19: 1800000479 | G19: DR | H19: NA | I19: 256788410353 | J19: 212100 | K19: USD | L19: 100 | M19: INR | N19: 8751.43 | O19: Intra 16-31 Aug 25 | P19: 45904 | S19: =VLOOKUP(I19,TDS!$A$1:$C$70,4,FALSE) -> #N/A
A20: 100222362 | B20: ONNSYNEX VENTURES PRIVATE LIMITED | C20: 2025 | D20: 4 | E20: 45751 | F20: 1800000152 | G20: DR | H20: NA | I20: 256788410027 | J20: 212100 | K20: USD | L20: 170 | M20: INR | N20: 14776.71 | O20: Transportation Inbound charges for Jan 25 | P20: 45755 | S20: =VLOOKUP(I20,TDS!$A$1:$C$70,4,FALSE) -> #N/A
A21: 100222362 | B21: ONNSYNEX VENTURES PRIVATE LIMITED | C21: 2025 | D21: 3 | E21: 45722 | F21: 1800000050 | G21: DR | H21: NA | I21: 246788410045 | J21: 212100 | K21: USD | L21: 841.24 | M21: INR | N21: 72928.16 | O21: Storage Charges for the month of November 2024 | P21: 45722 | S21: =VLOOKUP(I21,TDS!$A$1:$C$70,4,FALSE) -> #N/A
A22: 100222362 | B22: ONNSYNEX VENTURES PRIVATE LIMITED | C22: 2025 | D22: 3 | E22: 45722 | F22: 1800000051 | G22: DR | H22: NA | I22: 246788410046 | J22: 212100 | K22: USD | L22: 4169.66 | M22: INR | N22: 361473.08 | O22: Storage Charges for the month of December 2024 | P22: 45722 | S22: =VLOOKUP(I22,TDS!$A$1:$C$70,4,FALSE) -> #N/A
A23: 100222362 | B23: ONNSYNEX VENTURES PRIVATE LIMITED | C23: 2025 | D23: 3 | E23: 45719 | F23: 1800000045 | G23: DR | H23: NA | I23: 246788410039 | J23: 212100 | K23: USD | L23: 1044.69 | M23: INR | N23: 90565.49 | O23: CY-CY Ground Rent charges for Oct 2024. Exchange c | P23: 45719 | S23: =VLOOKUP(I23,TDS!$A$1:$C$70,4,FALSE) -> #N/A
A24: 100222362 | B24: ONNSYNEX VENTURES PRIVATE LIMITED | C24: 2025 | D24: 3 | E24: 45719 | F24: 1800000046 | G24: DR | H24: NA | I24: 246788410040 | J24: 212100 | K24: USD | L24: 129.98 | M24: INR | N24: 11268.13 | O24: CY-CY Ground Rent charges for Dec 2024. Exchange c | P24: 45719 | S24: =VLOOKUP(I24,TDS!$A$1:$C$70,4,FALSE) -> #N/A
A25: 100222362 | B25: ONNSYNEX VENTURES PRIVATE LIMITED | C25: 2025 | D25: 3 | E25: 45719 | F25: 1800000047 | G25: DR | H25: NA | I25: 246788410042 | J25: 212100 | K25: USD | L25: 4421.13 | M25: INR | N25: 383273.33 | O25: Storage Charges for the month of August, 2024 | P25: 45719 | S25: =VLOOKUP(I25,TDS!$A$1:$C$70,4,FALSE) -> #N/A
A26: 100222362 | B26: ONNSYNEX VENTURES PRIVATE LIMITED | C26: 2025 | D26: 3 | E26: 45719 | F26: 1800000048 | G26: DR | H26: NA | I26: 246788410043 | J26: 212100 | K26: USD | L26: 2730.01 | M26: INR | N26: 236668.01 | O26: Storage Charges for the month of September, 2024 | P26: 45719 | S26: =VLOOKUP(I26,TDS!$A$1:$C$70,4,FALSE) -> #N/A
A27: 100222362 | B27: ONNSYNEX VENTURES PRIVATE LIMITED | C27: 2025 | D27: 3 | E27: 45719 | F27: 1800000049 | G27: DR | H27: NA | I27: 246788410044 | J27: 212100 | K27: USD | L27: 474.24 | M27: INR | N27: 41112.46 | O27: Storage Charges for the month of October, 2024 | P27: 45719 | S27: =VLOOKUP(I27,TDS!$A$1:$C$70,4,FALSE) -> #N/A
A28: 100222362 | B28: ONNSYNEX VENTURES PRIVATE LIMITED | C28: 2025 | D28: 8 | E28: 45870 | F28: 1800000447 | G28: DR | H28: NA | I28: 256788410322 | J28: 212100 | K28: USD | L28: 75 | M28: INR | N28: 6452.26 | O28: Fixed Storage Charges for August 2025 | P28: 45870 | S28: =VLOOKUP(I28,TDS!$A$1:$C$70,4,FALSE) -> #N/A
A29: 100222362 | B29: ONNSYNEX VENTURES PRIVATE LIMITED | C29: 2025 | D29: 6 | E29: 45818 | F29: 1800000353 | G29: DR | H29: NA | I29: 256788410228 | J29: 212100 | K29: USD | L29: 75 | M29: INR | N29: 6411.81 | O29: Fixed Storage Charges fo JUNE 2025 | P29: 45818 | S29: =VLOOKUP(I29,TDS!$A$1:$C$70,4,FALSE) -> #N/A
... A34: 100222362 | B34: ONNSYNEX VENTURES PRIVATE LIMITED | C34: 2025 | D34: 5 | E34: 45785 | F34: 1800000343 | G34: DR | H34: NA | I34: 256788410218 | J34: 212100 | K34: USD | L34: 13.18 | M34: INR | N34: 1133.27 | O34: Outbound chgs - 16 - 30 Apr 25 | P34: 45785 | S34: =VLOOKUP(I34,TDS!$A$1:$C$70,4,FALSE) -> #N/A
A35: 100222362 | B35: ONNSYNEX VENTURES PRIVATE LIMITED | C35: 2025 | D35: 10 | E35: 45947 | F35: 1600000261 | G35: DG | H35: NA | I35: 256788420141 | J35: 212100 | K35: USD | L35: -1211.9 | M35: INR | N35: -106878.39 | O35: Credit note raised against 256788410417 | P35: 45947 | Q35: 45976 | R35: 1400000084 | S35: =VLOOKUP(I35,TDS!$A$1:$C$70,4,FALSE) -> #N/A
A36: 100222362 | B36: ONNSYNEX VENTURES PRIVATE LIMITED | C36: 2025 | D36: 10 | E36: 45947 | F36: 1600000262 | G36: DG | H36: NA | I36: 256788420142 | J36: 212100 | K36: USD | L36: -40 | M36: INR | N36: -3527.63 | O36: Credit note raised against 256788410418 | P36: 45947 | Q36: 45976 | R36: 1400000084 | S36: =VLOOKUP(I36,TDS!$A$1:$C$70,4,FALSE) -> #N/A
A37: 100222362 | B37: ONNSYNEX VENTURES PRIVATE LIMITED | C37: 2025 | D37: 10 | E37: 45947 | F37: 1600000263 | G37: DG | H37: NA | I37: 256788420143 | J37: 212100 | K37: USD | L37: -11.26 | M37: INR | N37: -993.03 | O37: Credit note raised against 256788410419 | P37: 45947 | Q37: 45976 | R37: 1400000084 | S37: =VLOOKUP(I37,TDS!$A$1:$C$70,4,FALSE) -> #N/A
A38: 100222362 | B38: ONNSYNEX VENTURES PRIVATE LIMITED | C38: 2025 | D38: 4 | E38: 45763 | F38: 1800007124 | G38: DR | H38: NA | I38: 256779412015 | J38: 212100 | K38: USD | L38: 86.56 | M38: INR | N38: 7523.95 | O38: VAS Activity - Jan 25, Ex Rate. 86.64 | P38: 45763 | S38: =VLOOKUP(I38,TDS!$A$1:$C$70,4,FALSE) -> #N/A
A39: 100222362 | B39: ONNSYNEX VENTURES PRIVATE LIMITED | C39: 2025 | D39: 4 | E39: 45763 | F39: 1800007167 | G39: DR | H39: NA | I39: 256779412058 | J39: 212100 | K39: USD | L39: 188.84 | M39: INR | N39: 16414.32 | O39: VAS Activity - Feb 25, Ex Rate. 87.40 | P39: 45763 | S39: =VLOOKUP(I39,TDS!$A$1:$C$70,4,FALSE) -> #N/A
A40: 100222362 | B40: ONNSYNEX VENTURES PRIVATE LIMITED | C40: 2025 | D40: 4 | E40: 45763 | F40: 1800007205 | G40: DR | H40: NA | I40: 256779412096 | J40: 212100 | K40: USD | L40: 16.83 | M40: INR | N40: 1462.89 | O40: VAS Activity - Mar 25, 16-31, Ex Rate. 85.58 | P40: 45763 | S40: =VLOOKUP(I40,TDS!$A$1:$C$70,4,FALSE) -> #N/A
A41: 100222362 | B41: ONNSYNEX VENTURES PRIVATE LIMITED | C41: 2025 | D41: 7 | E41: 45847 | F41: 1800000368 | G41: DR | H41: NA | I41: 256788410243 | J41: 212100 | K41: USD | L41: 30 | M41: INR | N41: 2580.02 | O41: CY - WH Destuff Charges fo MAY 2025 | P41: 45847 | S41: =VLOOKUP(I41,TDS!$A$1:$C$70,4,FALSE) -> #N/A
A42: 100222362 | B42: ONNSYNEX VENTURES PRIVATE LIMITED | C42: 2025 | D42: 7 | E42: 45847 | F42: 1800000384 | G42: DR | H42: NA | I42: 256788410259 | J42: 212100 | K42: USD | L42: 75 | M42: INR | N42: 6450.05 | O42: Fixed Rental charges for April 2025 | P42: 45847 | S42: =VLOOKUP(I42,TDS!$A$1:$C$70,4,FALSE) -> #N/A
A43: 100222362 | B43: ONNSYNEX VENTURES PRIVATE LIMITED | C43: 2025 | D43: 9 | E43: 45904 | F43: 1800012496 | G43: DR | H43: NA | I43: 256779416953 | J43: 212100 | K43: USD | L43: 2.14 | M43: INR | N43: 187.28 | O43: CODC Out chgs -16-31 Aug 25 | P43: 45904 | S43: =VLOOKUP(I43,TDS!$A$1:$C$70,4,FALSE) -> #N/A
A44: 100222362 | B44: ONNSYNEX VENTURES PRIVATE LIMITED | C44: 2025 | D44: 9 | E44: 45904 | F44: 1800000480 | G44: DR | H44: NA | I44: 256788410354 | J44: 212100 | K44: USD | L44: 12.52 | M44: INR | N44: 1095.68 | O44: VAS -16-31 Aug 25 | P44: 45904 | S44: =VLOOKUP(I44,TDS!$A$1:$C$70,4,FALSE) -> #N/A
...

Sheet Sheet3
A1: Section | B1: Particulars | C1: Type | D1: TDS
A2: 194I | B2: By ANOMALOUS INFRA PRIVATE LIMITED | C2: 246788410024 | D2: 34560
A3: 194I | B3: By ANOMALOUS INFRA PRIVATE LIMITED | C3: 246788410005 | D3: 638
A4: 194I | B4: By ANOMALOUS INFRA PRIVATE LIMITED | C4: 246788410009 | D4: 638
A5: 194I | B5: By ANOMALOUS INFRA PRIVATE LIMITED | C5: 246788410013 | D5: 638
A6: 194I | B6: By ANOMALOUS INFRA PRIVATE LIMITED | C6: 246788410015 | D6: 638
A7: 194I | B7: By ANOMALOUS INFRA PRIVATE LIMITED | C7: 246788410017 | D7: 638
A8: 194I | B8: By ANOMALOUS INFRA PRIVATE LIMITED | C8: 246788410019 | D8: 638
A9: 194I | B9: By ANOMALOUS INFRA PRIVATE LIMITED | C9: 246788410021 | D9: 638
A10: 194I | B10: By ANOMALOUS INFRA PRIVATE LIMITED | C10: 246788410044 | D10: 4061
A11: 194I | B11: By ANOMALOUS INFRA PRIVATE LIMITED | C11: 246788410039 | D11: 9072
A12: 194I | B12: By ANOMALOUS INFRA PRIVATE LIMITED | C12: 246788410040 | D12: 1129
A13: 194I | B13: By ANOMALOUS INFRA PRIVATE LIMITED | C13: 246788410042 | D13: 38022
... A70: 194C | B70: By AGENCY CHARGES Journal | C70: 256788410166 | D70: 20.17

Sheet TDS
A1: Particulars | B1: Type | C1: TDS | D1: Section
A2: By ANOMALOUS INFRA PRIVATE LIMITED | B2: 246788410024 | C2: 34560 | D2: 194I | E2: {=VLOOKUP(B2,'LEDGER FINAL'!H3:$R$221,{3,7},0)} -> 1800000041 | F2: 343523.09
A3: By ANOMALOUS INFRA PRIVATE LIMITED | B3: 246788410005 | C3: 638 | D3: 194I | E3: {=VLOOKUP(B3,'LEDGER FINAL'!H4:$R$221,{3,7},0)} -> 1800000006 | F3: 6472.77
A4: By ANOMALOUS INFRA PRIVATE LIMITED | B4: 246788410009 | C4: 638 | D4: 194I | E4: {=VLOOKUP(B4,'LEDGER FINAL'!H5:$R$221,{3,7},0)} -> 1800000022 | F4: 6472.77
A5: By ANOMALOUS INFRA PRIVATE LIMITED | B5: 246788410013 | C5: 638 | D5: 194I | E5: {=VLOOKUP(B5,'LEDGER FINAL'!H6:$R$221,{3,7},0)} -> 1800000018 | F5: 6472.77
A6: By ANOMALOUS INFRA PRIVATE LIMITED | B6: 246788410015 | C6: 638 | D6: 194I | E6: {=VLOOKUP(B6,'LEDGER FINAL'!H7:$R$221,{3,7},0)} -> 1800000010 | F6: 6472.77
A7: By ANOMALOUS INFRA PRIVATE LIMITED | B7: 246788410017 | C7: 638 | D7: 194I | E7: {=VLOOKUP(B7,'LEDGER FINAL'!H8:$R$221,{3,7},0)} -> 1800000012 | F7: 6472.77
A8: By ANOMALOUS INFRA PRIVATE LIMITED | B8: 246788410019 | C8: 638 | D8: 194I | E8: {=VLOOKUP(B8,'LEDGER FINAL'!H9:$R$221,{3,7},0)} -> 1800000029 | F8: 6472.77
A9: By ANOMALOUS INFRA PRIVATE LIMITED | B9: 246788410021 | C9: 638 | D9: 194I | E9: {=VLOOKUP(B9,'LEDGER FINAL'!H10:$R$221,{3,7},0)} -> 1800000033 | F9: 6472.77
A10: By ANOMALOUS INFRA PRIVATE LIMITED | B10: 246788410044 | C10: 4061 | D10: 194I | E10: {=VLOOKUP(B10,'LEDGER FINAL'!H11:$R$221,{3,7},0)} -> 1800000049 | F10: 41112.46
A11: By ANOMALOUS INFRA PRIVATE LIMITED | B11: 246788410039 | C11: 9072 | D11: 194I | E11: {=VLOOKUP(B11,'LEDGER FINAL'!H12:$R$221,{3,7},0)} -> 1800000045 | F11: 90565.49
A12: By ANOMALOUS INFRA PRIVATE LIMITED | B12: 246788410040 | C12: 1129 | D12: 194I | E12: {=VLOOKUP(B12,'LEDGER FINAL'!H13:$R$221,{3,7},0)} -> 1800000046 | F12: 11268.13
A13: By ANOMALOUS INFRA PRIVATE LIMITED | B13: 246788410042 | C13: 38022 | D13: 194I | E13: {=VLOOKUP(B13,'LEDGER FINAL'!H14:$R$221,{3,7},0)} -> 1800000047 | F13: 383273.33
... A45: By ANOMALOUS INFRA PRIVATE LIMITED | B45: 256779412498 | C45: 44 | D45: 194C | E45: {=VLOOKUP(B45,'LEDGER FINAL'!H46:$R$221,{3,7},0)} -> 1800007607 | F45: 2200.86
A46: By ANOMALOUS INFRA PRIVATE LIMITED | B46: 256779412015 | C46: 150 | D46: 194C | E46: {=VLOOKUP(B46,'LEDGER FINAL'!H47:$R$221,{3,7},0)} -> #N/A
A47: By ANOMALOUS INFRA PRIVATE LIMITED | B47: 256779412058 | C47: 328 | D47: 194C | E47: {=VLOOKUP(B47,'LEDGER FINAL'!H48:$R$221,{3,7},0)} -> #N/A
A48: By ANOMALOUS INFRA PRIVATE LIMITED | B48: 256779412096 | C48: 29 | D48: 194C | E48: {=VLOOKUP(B48,'LEDGER FINAL'!H49:$R$221,{3,7},0)} -> #N/A
A49: By ANOMALOUS INFRA PRIVATE LIMITED | B49: 256779413241 | C49: 1814 | D49: 194C | E49: {=VLOOKUP(B49,'LEDGER FINAL'!H50:$R$221,{3,7},0)} -> 1800008358 | F49: 90694.75
A50: By ANOMALOUS INFRA PRIVATE LIMITED | B50: 246788410109 | C50: 4062 | D50: 194C | E50: {=VLOOKUP(B50,'LEDGER FINAL'!H51:$R$221,{3,7},0)} -> 1800000115 | F50: 203100.28
A51: By ANOMALOUS INFRA PRIVATE LIMITED | B51: 246788410085 | C51: 2296 | D51: 194C | E51: {=VLOOKUP(B51,'LEDGER FINAL'!H52:$R$221,{3,7},0)} -> 1800000090 | F51: 114779.23
A52: By ANOMALOUS INFRA PRIVATE LIMITED | B52: 256788410027 | C52: 296 | D52: 194C | E52: {=VLOOKUP(B52,'LEDGER FINAL'!H53:$R$221,{3,7},0)} -> #N/A
A53: By AGENCY CHARGES | B53: 256788410259 | C53: 129 | D53: 194C | E53: {=VLOOKUP(B53,'LEDGER FINAL'!H54:$R$221,{3,7},0)} -> #N/A
A54: By AGENCY CHARGES | B54: 256788410264 | C54: 7.98 | D54: 194C | E54: {=VLOOKUP(B54,'LEDGER FINAL'!H55:$R$221,{3,7},0)} -> 1800000388 | F54: 399.04
A55: By AGENCY CHARGES | B55: 256788410265 | C55: 2597.25 | D55: 194C | E55: {=VLOOKUP(B55,'LEDGER FINAL'!H56:$R$221,{3,7},0)} -> 1800000389 | F55: 129862.73
A56: By AGENCY CHARGES | B56: 256779416953 | C56: 3.75 | D56: 194C | E56: {=VLOOKUP(B56,'LEDGER FINAL'!H57:$R$221,{3,7},0)} -> #N/A
A57: By AGENCY CHARGES | B57: 256788410353 | C57: 175.03 | D57: 194C | E57: {=VLOOKUP(B57,'LEDGER FINAL'!H58:$R$221,{3,7},0)} -> #N/A
A58: By AGENCY CHARGES | B58: 256788410354 | C58: 21.91 | D58: 194C | E58: {=VLOOKUP(B58,'LEDGER FINAL'!H59:$R$221,{3,7},0)} -> #N/A
A59: By AGENCY CHARGES | B59: 256788410355 | C59: 23.91 | D59: 194C | E59: {=VLOOKUP(B59,'LEDGER FINAL'!H60:$R$221,{3,7},0)} -> #N/A
A60: By AGENCY CHARGES | B60: 256788410358 | C60: 19796.09 | D60: 194C | E60: {=VLOOKUP(B60,'LEDGER FINAL'!H61:$R$221,{3,7},0)} -> #N/A
A61: By AGENCY CHARGES | B61: 256788410359 | C61: 221.55 | D61: 194C | E61: {=VLOOKUP(B61,'LEDGER FINAL'!H62:$R$221,{3,7},0)} -> #N/A
A62: By AGENCY CHARGES | B62: 256788410360 | C62: 609.47 | D62: 194C | E62: {=VLOOKUP(B62,'LEDGER FINAL'!H63:$R$221,{3,7},0)} -> #N/A
A63: By AGENCY CHARGES | B63: 256788410361 | C63: 45.51 | D63: 194C | E63: {=VLOOKUP(B63,'LEDGER FINAL'!H64:$R$221,{3,7},0)} -> #N/A
A64: By AGENCY CHARGES | B64: 256788410363 | C64: 398.61 | D64: 194C | E64: {=VLOOKUP(B64,'LEDGER FINAL'!H65:$R$221,{3,7},0)} -> #N/A
A65: By AGENCY CHARGES | B65: 256788410364 | C65: 656.36 | D65: 194C | E65: {=VLOOKUP(B65,'LEDGER FINAL'!H66:$R$221,{3,7},0)} -> #N/A
A66: By AGENCY CHARGES | B66: 256788410162 | C66: 9.49 | D66: 194C | E66: {=VLOOKUP(B66,'LEDGER FINAL'!H67:$R$221,{3,7},0)} -> 1800000287 | F66: 474.59
A67: By AGENCY CHARGES | B67: 256788410163 | C67: 6.08 | D67: 194C | E67: {=VLOOKUP(B67,'LEDGER FINAL'!H68:$R$221,{3,7},0)} -> 1800000288 | F67: 304.23
A68: By AGENCY CHARGES | B68: 256788410164 | C68: 9.74 | D68: 194C | E68: {=VLOOKUP(B68,'LEDGER FINAL'!H69:$R$221,{3,7},0)} -> 1800000289 | F68: 486.76
A69: By AGENCY CHARGES | B69: 256788410165 | C69: 9.74 | D69: 194C | E69: {=VLOOKUP(B69,'LEDGER FINAL'!H70:$R$221,{3,7},0)} -> 1800000290 | F69: 486.76
A70: By AGENCY CHARGES Journal | B70: 256788410166 | C70: 20.17 | D70: 194C | E70: {=VLOOKUP(B70,'LEDGER FINAL'!H71:$R$221,{3,7},0)} -> 1800000291 | F70: 1008.29

Sheet Summary
A1: Not in the books of Onnsynex | J1: Not in the books of Anomolus & ascendus
A2: Document Type | B2: Invoice No | C2: Document Number | D2: Document Currency Key | E2: Document Currency Value | F2: Company Code Currency Value | G2: Text | H2: Baseline Payment Dte | J2: Particulars | K2: Invoice No | L2: Amount | M2: Section
A3: DR | B3: 256788410349 | C3: 1800000477 | D3: USD | E3: 100 | F3: 8603.01 | G3: INTRA 1-15 Aug 25 | H3: 45889 | J3: By ANOMALOUS INFRA PRIVATE LIMITED | K3: 256779412015 | L3: 150 | M3: 194C
A4: DR | B4: 256788410322 | C4: 1800000447 | D4: USD | E4: 75 | F4: 6452.26 | G4: Fixed Storage Charges for August 2025 | H4: 45870 | J4: By ANOMALOUS INFRA PRIVATE LIMITED | K4: 256779412058 | L4: 328 | M4: 194C
A5: DR | B5: 256788410228 | C5: 1800000353 | D5: USD | E5: 75 | F5: 6411.81 | G5: Fixed Storage Charges fo JUNE 2025 | H5: 45818 | J5: By ANOMALOUS INFRA PRIVATE LIMITED | K5: 256779412096 | L5: 29 | M5: 194C
A6: DR | B6: 256788410379 | C6: 1800000504 | D6: USD | E6: 53.78 | F6: 4706.52 | G6: VAS Activity - Feb 25, Ex Rate. 87.40 | H6: 45917 | J6: By ANOMALOUS INFRA PRIVATE LIMITED | K6: 256788410027 | L6: 296 | M6: 194C
A7: DR | B7: 256788410382 | C7: 1800000507 | D7: USD | E7: 102.14 | F7: 8938.71 | G7: VAS -1-15 Sept-25 | H7: 45917 | J7: By AGENCY CHARGES | K7: 256788410259 | L7: 129 | M7: 194C
A8: DR | B8: 256788410216 | C8: 1800000341 | D8: USD | E8: 8.45 | F8: 726.56 | G8: Inbound chgs - 01 - 15 Apr 25 | H8: 45785 | J8: By AGENCY CHARGES | K8: 256779416953 | L8: 3.75 | M8: 194C
A9: DR | B9: 256788410217 | C9: 1800000342 | D9: USD | E9: 37.66 | F9: 3238.15 | G9: Outbound chgs - 01 - 15 Apr 25 | H9: 45785 | J9: By AGENCY CHARGES | K9: 256788410353 | L9: 175.03 | M9: 194C
A10: DR | B10: 256788410218 | C10: 1800000343 | D10: USD | E10: 13.18 | F10: 1133.27 | G10: Outbound chgs - 16 - 30 Apr 25 | H10: 45785 | J10: By AGENCY CHARGES | K10: 256788410354 | L10: 21.91 | M10: 194C
A11: DG | B11: 256788420141 | C11: 1600000261 | D11: USD | E11: -1211.9 | F11: -106878.39 | G11: Credit note raised against 256788410417 | H11: 45947 | J11: By AGENCY CHARGES | K11: 256788410355 | L11: 23.91 | M11: 194C
A12: DG | B12: 256788420142 | C12: 1600000262 | D12: USD | E12: -40 | F12: -3527.63 | G12: Credit note raised against 256788410418 | H12: 45947 | J12: By AGENCY CHARGES | K12: 256788410358 | L12: 19796.09 | M12: 194C
A13: DG | B13: 256788420143 | C13: 1600000263 | D13: USD | E13: -11.26 | F13: -993.03 | G13: Credit note raised against 256788410419 | H13: 45947 | J13: By AGENCY CHARGES | K13: 256788410359 | L13: 221.55 | M13: 194C
A14: DR | B14: 256788410243 | C14: 1800000368 | D14: USD | E14: 30 | F14: 2580.02 | G14: CY - WH Destuff Charges fo MAY 2025 | H14: 45847 | J14: By AGENCY CHARGES | K14: 256788410360 | L14: 609.47 | M14: 194C
... A17: DR | B17: 256788410235 | C17: 1800000360 | D17: USD | E17: 2323.12 | F17: 199789.88 | G17: CY Ground rent Chgs - 01 - 30 June 25 | H17: 45842 | J17: By AGENCY CHARGES | K17: 256788410364 | L17: 656.36 | M17: 194C
A18: DR | B18: 256788410237 | C18: 1800000362 | D18: USD | E18: 75 | F18: 6450.05 | G18: Fixed Storage Charges fo JULY 2025 | H18: 45842
A19: DR | B19: 256788410255 | C19: 1800000380 | D19: USD | E19: 14 | F19: 1204.01 | G19: LCL Chgs - 01 - 15 JUN 25 | H19: 45842
A20: DR | B20: 256788410257 | C20: 1800000382 | D20: USD | E20: 67.76 | F20: 5827.41 | G20: Outbound chgs - 01 - 15 JUN 25 | H20: 45842
A21: DR | B21: 256788410258 | C21: 1800000383 | D21: USD | E21: 17 | F21: 1462.01 | G21: Outbound chgs - 16 - 30 JUN 25 | H21: 45842
A22: DR | B22: 256788410267 | C22: 1800000391 | D22: USD | E22: 9 | F22: 774.01 | G22: Outbound chgs - 01 - 15 JUL 25 | H22: 45842
A23: DR | B23: 256788410441 | C23: 1800000576 | D23: USD | E23: 75 | F23: 6600.25 | G23: Fixed Storage Charges for November 2025 | H23: 45966
A24: DR | B24: 256788410448 | C24: 1800000587 | D24: USD | E24: 70 | F24: 6160.24 | G24: Intra SEZ-Transfer-16 -31 Oct 25 | H24: 45966
A25: DR | B25: 256788410449 | C25: 1800000588 | D25: USD | E25: 70 | F25: 6160.24 | G25: Intra SEZ-Transfer-16 -31 Oct 25 | H25: 45966
A26: DR | B26: 256788410450 | C26: 1800000589 | D26: USD | E26: 70 | F26: 6160.24 | G26: Intra SEZ-Transfer-16 -31 Oct 25 | H26: 45966
A27: DR | B27: 256788410451 | C27: 1800000590 | D27: USD | E27: 70 | F27: 6160.24 | G27: Intra SEZ-Transfer-16 -31 Oct 25 | H27: 45966
A28: DR | B28: 256788410452 | C28: 1800000591 | D28: USD | E28: 65.31 | F28: 5747.5 | G28: VAS-16 -31 Oct 25 | H28: 45966
A29: DR | B29: 256788410453 | C29: 1800000592 | D29: USD | E29: 31.56 | F29: 2777.39 | G29: WEIGHTMENT-16 -31 Oct 25 | H29: 45966
... A136: DG | B136: 256788420150 | C136: 1600000274 | D136: USD | E136: -53 | F136: -4809.39 | G136: CN Against LCL & Inbound chgs - 16 -31 DEC 25 | H136: 46028
