Workbook

Sheet Summary
A3: Reconciliation of Ledger as on 31st January 2026
A4: Particulars | B4: Amount in USD
A5: Balance as per Ashland | B5: ='Customer Data'!F192 -> 0
A6: Add: Invoices not recorded in customer books | B6: ='Invoices Not in customer books'!F30 -> 34851.14
A7: Less: Invoice not recorded in Ascendus Books | B7: ='invoice not in Ascendus Books'!E41 -> 0
A8: Add: CN not recorded in Ascendus Books | B8: ='CN not in Ascendus Books'!F2 -> 16009
A9: Add: Diffrence in Payment recorded in both books | B9: ='Payment Reco'!L14 -> 44897.47
A10: Add: Diffrence in Invoice Amount in both Books | B10: ='Diffrence in Customer Books'!Q11 -> 49.5
A11: Less: Duplicate CN in Ascendus Books | B11: ='Duplicate CN in Ascendus Books'!F2 -> -131.74
A12: Derived balance | B12: =SUM(B5:B11) -> 95675.37
A13: Balance as per Ascent | B13: ='Ascendus data'!T296 -> 95447.7
A15: Difference | B15: =B12-B13 -> 227.67

Sheet Invoice No Ref
A1: Ascendus Ledger | F1: Customer Ledger
A2: Document Type | B2: Document Date | C2: Reference | D2: Document Currency Value | E2: Text | F2: Document Type | G2: Document Number | H2: Document Date | I2: Reference | J2: Amount in doc. curr. | K2: Text
A3: DR | B3: 45763 | C3: 256779411831 | D3: 23.6 | E3: CY - CY charges for Dec 2024 | F3: KR | G3: 1900008140 | H3: 45702 | I3: 6779IV124000270 | J3: -23.6 | K3: CY Movement Charges-Dec24
A4: DR | B4: 45736 | C4: 246779414629 | D4: 23.6 | E4: CY-MOVEMENT CHARGES for Nov 2024 | F4: KR | G4: 1900008127 | H4: 45702 | I4: 6779IV124000261 | J4: -23.6 | K4: CY Movement Charges-Nov24
A5: DR | B5: 45737 | C5: 246779414251 | D5: 28.32 | E5: LCL Movement Charges for Oct 2024 | F5: KR | G5: 1900008134 | H5: 45702 | I5: 6779IV124000251 | J5: -28.32 | K5: LCL Charges-Oct24
A6: DR | B6: 45737 | C6: 246779414252 | D6: 70.8 | E6: CY-MOVEMENT CHARGES for Oct 2024 | F6: KR | G6: 1900008133 | H6: 45702 | I6: 6779IV124000250 | J6: -70.8 | K6: CY Destuff Charges-Oct24
A7: DR | B7: 45729 | C7: 246779411330 | D7: 85 | E7: Scanning Charges for the month of December, 2024 | F7: KR | G7: 1900008142 | H7: 45702 | I7: 6779IV124000273 | J7: -85 | K7: Scanning Charges- Dec24
A8: DR | B8: 45736 | C8: 246779414554 | D8: 94.4 | E8: CY-MOVEMENT CHARGES for Oct 2024 | F8: KR | G8: 1900008136 | H8: 45702 | I8: 6779IV124000253 | J8: -94.4 | K8: CY Movement Charges-oct24
A9: DR | B9: 45736 | C9: 246779414343 | D9: 118 | E9: CY-MOVEMENT CHARGES for Nov 2024 | F9: KR | G9: 1900008125 | H9: 45702 | I9: 6779IV124000258 | J9: -118 | K9: CY Destuff Charges-Nov24
A10: DR | B10: 45736 | C10: 246779414424 | D10: 118 | E10: Cy-WH Destuff charges for Jan 2025 | F10: KR | G10: 1900008144 | H10: 45702 | I10: 6779IV124000276 | J10: -118 | K10: CY Destuff Charges-Jan25
A11: DR | B11: 45729 | C11: 246779411319 | D11: 120 | E11: Scanning Charges for the month of November, 2024 | F11: KR | G11: 1900008129 | H11: 45702 | I11: 6779IV124000264 | J11: -120 | K11: Scanning Charges-Nov24
A12: DR | B12: 45729 | C12: 246779411305 | D12: 135 | E12: Scanning Charges for the month of October, 2024 | F12: KR | G12: 1900008124 | H12: 45702 | I12: 6779IV124000256 | J12: -135 | K12: Scanning Charges-Oct24
A13: DR | B13: 45763 | C13: 256779411746 | D13: 141.6 | E13: Cy-WH Destuff charges for Dec 2024 | F13: KR | G13: 1900008130 | H13: 45702 | I13: 6779IV124000267 | J13: -141.6 | K13: CY Destuff Charges-Dec24
A14: DR | B14: 45736 | C14: 246779414079 | D14: 169.92 | E14: LCL charges for Sep 2024 | F14: KR | G14: 1900008117 | H14: 45702 | I14: 6779IV124000244 | J14: -169.92 | K14: LCL Charges-Sep24
... A38: DR | B38: 45734 | C38: 246779412401 | D38: 23761.19 | E38: Storage charges for OCT 2024 | F38: RE | G38: 5100012795 | H38: 45702 | I38: 6779IV124000249 | J38: -23761.19 | K38: Storage Charges Oct24
A39: DR | B39: 45736 | C39: 246779413820 | D39: 354 | E39: Scanning Charges for the month of Jan 2025 | F39: KR | H39: 45702 | I39: 6779IV124000285 | J39: -200 | K39: Scanning Charges-Jan25

Sheet Payment Reco
A1: As Per Customer ledger | E1: As Per Bank Details | J1: As per Ascendus Ledger
A2: Document Date | B2: Reference | C2: Document currency | D2: Amount in doc. curr. | E2: Customer Code | F2: Payment Date | G2: Currency | H2: Recd Amount | I2: UTR Details | J2: Clearing Doc No | K2: Amount | L2: Difference | M2: Remarks
A3: 45751 | B3: Payment | C3: USD | D3: 123978.28 | E3: 100222426 | F3: 45751 | G3: USD | H3: 123953.28 | I3: 2.0250403e+15 | K3: -123953.28 | L3: =K3+D3 -> 25 | M3: Difference Due to Bank Charges
A4: 46097 | B4: Payment | C4: USD | D4: 44872.17 | E4: 100222426 | F4: 46097 | G4: USD | H4: 44847.17 | I4: T54SWIC292175 | L4: =K4+D4 -> 44872.17 | M4: Payment Not in Books
A5: 46015 | B5: Payment | C5: USD | D5: 37332.98 | E5: 100222426 | F5: 46015 | G5: USD | H5: 37307.98 | I5: T54SWIC284726 | J5: 1400002336 | K5: -37332.98 | L5: =K5+D5 -> 0
A6: 45884 | B6: Payment | C6: USD | D6: 34635.14 | E6: 100222426 | F6: 45887 | G6: USD | H6: 34610.14 | I6: 2.0250814e+15 | J6: 1400002466 | K6: -34635.14 | L6: =K6+D6 -> 0
A7: 45925 | B7: Payment | C7: USD | D7: 29536.15 | E7: 100222426 | F7: 45925 | G7: USD | H7: 29511.15 | I7: 2.0250924e+15 | J7: 1400002445 | K7: -29535.85 | L7: =K7+D7 -> 0.3
A8: 45975 | B8: Payment | C8: USD | D8: 22973.48 | E8: 100222426 | F8: 45975 | G8: USD | H8: 22948.48 | I8: 2.0251113e+15 | J8: 1400002448 | K8: -22973.48 | L8: =K8+D8 -> 0
A9: 45833 | B9: Payment | C9: USD | D9: 19783.53 | E9: 100222426 | F9: 45833 | G9: USD | H9: 19758.53 | I9: 2.0250624e+15 | J9: 1400000284 | K9: -19783.53 | L9: =K9+D9 -> 0
A10: 45824 | B10: Payment | C10: USD | D10: 19172.47 | E10: 100222426 | F10: 45824 | G10: USD | H10: 19147.47 | I10: 2.0250616e+15 | J10: 1400002443 | K10: -19172.47 | L10: =K10+D10 -> 0
A11: 45945 | B11: Payment | C11: USD | D11: 8309.99 | E11: 100222426 | F11: 45945 | G11: USD | H11: 8284.99 | I11: 2.0251014e+15 | J11: 1400002446 | K11: -8309.99 | L11: =K11+D11 -> 0
A12: 45915 | B12: Payment | C12: USD | D12: 6750.14 | E12: 100222426 | F12: 45915 | G12: USD | H12: 6725.14 | I12: 2.0250915e+15 | J12: 1400002444 | K12: -6750.14 | L12: =K12+D12 -> 0
A13: 45954 | B13: Payment | C13: USD | D13: 79.94 | E13: 100222426 | F13: 45954 | G13: USD | H13: 79.94 | I13: 2.0251023e+15 | J13: 1400002447 | K13: -79.94 | L13: =K13+D13 -> 0
L14: =SUM(L3:L13) -> 44897.47

Sheet Invoices Not in customer books
A3: Document Number | B3: Document Type | C3: Document Date | D3: Reference | E3: Document Currency Key | F3: Document Currency Value | G3: Text
A4: 1800012797 | B4: DR | C4: 45920 | D4: 256779417478 | E4: USD | F4: 1002.2 | G4: BOE handling charges
A5: 1800003244 | B5: DR | C5: 45735 | D5: 246779413111 | E5: USD | F5: 13.77 | G5: CMAU8274168-Port SSR Storage Jan 2025. Exch rate -
A6: 1800006828 | B6: DR | C6: 45763 | D6: 256779411719 | E6: USD | F6: 488.03 | G6: CY Longstanding Transportation chgs for 31 MAR 202
A7: 1800003944 | B7: DR | C7: 45736 | D7: 246779413973 | E7: USD | F7: 123.56 | G7: Detention Charges for JAN 2025 Exch. Rate 86.60
A8: 1800016238 | B8: DR | C8: 46028 | D8: 256779450410 | E8: USD | F8: 833.03 | G8: Empty Lolo Chgs - 01 - 31 DEC 25
A9: 1800003245 | B9: DR | C9: 45735 | D9: 246779413112 | E9: USD | F9: 13.77 | G9: GATU4442400-Port SSR Storage Jan 2025. Exch rate -
A10: 1800006854 | B10: DR | C10: 45763 | D10: 256779411745 | E10: USD | F10: 169.92 | G10: Loose Unloading charges for Dec 2024
A11: 1800003241 | B11: DR | C11: 45735 | D11: 246779413108 | E11: USD | F11: 78.12 | G11: ONEU1598927-Port SSR Shifting Jan 2025. Exch rate
A12: 1800003242 | B12: DR | C12: 45735 | D12: 246779413109 | E12: USD | F12: 166.09 | G12: ONEU1598927-Port SSR Storage Jan 2025. Exch rate -
A13: 1800003243 | B13: DR | C13: 45735 | D13: 246779413110 | E13: USD | F13: 76.72 | G13: ONEU1598927-Port SSR Storage Jan 2025. Exch rate -
A14: 1800016374 | B14: DR | C14: 46034 | D14: 256779450541 | E14: USD | F14: 1568.64 | G14: Outbound chgs - 16 - 31 Dec 25
A15: 1800013204 | B15: DR | C15: 45924 | D15: 256779417820 | E15: USD | F15: 131.74 | G15: Port SSR Charges - Shifting for Aug to Dec,24. Exc
... A29: 1800017223 | B29: DR | C29: 46059 | D29: 256779451053 | E29: USD | F29: 27.18 | G29: Weighment -1-15 Oct 2025
F30: =SUM(F4:F29) -> 34851.14

Sheet CN not in Ascendus Books
A1: Document Type | B1: Document Number | C1: Document Date | D1: Reference | E1: Document currency | F1: Amount in doc. curr. | G1: Text
A2: KG | B2: 1700001171 | C2: 45729 | D2: ASCEN20250102 | E2: USD | F2: 16009 | G2: CN against detention-Aug24-Dec24

Sheet Sheet1
A1: Text | B1: Reference | C1: Sum of Document Currency Value
A2: BOE handling charges | B2: 256779417478 | C2: 1002.2
A3: CMAU8274168-Port SSR Storage Jan 2025. Exch rate - | B3: 246779413111 | C3: 13.77
A4: CY Destuff Charges August 2024 | B4: 256779410983 | C4: 392.35
B5: 256779410984 | C5: 200.6
B6: 256779410985 | C6: 106.2
B7: 256779410986 | C7: 82.6
B8: 256779410988 | C8: 330.4
B9: 256779410989 | C9: 82.6
B10: 256779410990 | C10: 194.7
A11: CY Longstanding Transportation chgs for 31 MAR 202 | B11: 256779411719 | C11: 488.03
A12: Detention Charges for JAN 2025 Exch. Rate 86.60 | B12: 246779413973 | C12: 123.56
A13: Empty Lolo Chgs - 01 - 31 DEC 25 | B13: 256779450410 | C13: 833.03
A14: GATU4442400-Port SSR Storage Jan 2025. Exch rate - | B14: 246779413112 | C14: 13.77
A15: Inbound Handling charges for Jan 2025 | B15: 246779414012 | C15: 72.89
B16: 246779414013 | C16: 81.04
B17: 246779414419 | C17: 1003.1
A18: Loose Unloading charges for Dec 2024 | B18: 256779411745 | C18: 169.92
A19: ONEU1598927-Port SSR Shifting Jan 2025. Exch rate | B19: 246779413108 | C19: 78.12
A20: ONEU1598927-Port SSR Storage Jan 2025. Exch rate - | B20: 246779413109 | C20: 166.09
B21: 246779413110 | C21: 76.72
A22: Outbound chgs - 16 - 31 Dec 25 | B22: 256779450541 | C22: 1568.64
A23: Outbound Handling Charges Aug 2024 | B23: 256779411213 | C23: 66.08
B24: 256779411214 | C24: 11.8
B25: 256779411215 | C25: 46.87
B26: 256779411216 | C26: 91.45
B27: 256779411217 | C27: 91.45
B28: 256779411218 | C28: 110.7
B29: 256779411219 | C29: 35.4
B30: 256779411220 | C30: 44.25
B31: 256779411221 | C31: 2.95
B32: 256779411222 | C32: 105.43
B33: 256779411223 | C33: 85.55
B34: 256779411224 | C34: 54.47
B35: 256779411225 | C35: 66
... B43: 256779411233 | C43: 20.96
A44: Outbound Handling charges for Jan 2025 | B44: 246779414704 | C44: 768.32
B45: 246779414803 | C45: 17.7
B46: 246779414804 | C46: 109.15
B47: 246779414805 | C47: 8.85
...

Sheet Sheet2
A1: As Per Customer | G1: As per CL
A2: Document Type | B2: Document Number | C2: Document Date | D2: Reference | E2: Amount in doc. curr. | F2: Text | G2: Text | H2: Reference | I2: Sum of Document Currency Value
A3: KR | B3: 1900008119 | C3: 45702 | D3: 6779IV124000236 | E3: -236 | F3: CY Destuff Charges-Aug24 | G3: CY Destuff Charges August 2024 | H3: 256779410983 to 256779410990 | I3: 1389.45 | J3: =I3+E3 -> 1153.45 | K3: =J3/E3 -> -4.8875
A4: KR | B4: 1900008161 | C4: 45702 | D4: 6779IV124000279 | E4: -1100.39 | F4: Inbound Handling Charges-Jan25 | G4: Inbound Handling charges for Jan 2025 | H4: 246779414012/246779414013/246779414019 | I4: 1157.03 | J4: =I4+E4 -> 56.64 | K4: =J4/E4 -> -0.05147266
A5: KR | B5: 1900008165 | C5: 45702 | D5: 6779IV124000239 | E5: -1142.99 | F5: Outbound Handling Charges-Aug24 | G5: Outbound Handling Charges Aug 2024 | H5: 256779411213 To 256779411233 | I5: 1166.59 | J5: =I5+E5 -> 23.6 | K5: =J5/E5 -> -0.0206476
A6: KR | B6: 1900008160 | C6: 45702 | D6: 6779IV124000282 | E6: -1093.36 | F6: Outbound Handling Charges-Jan25 | G6: Outbound Handling charges for Jan 2025 | I6: 1116.97 | J6: =I6+E6 -> 23.61 | K6: =J6/E6 -> -0.021593986
A7: KR | B7: 1900008118 | C7: 45702 | D7: 6779IV124000235 | E7: -141.07 | F7: Transportation Inbound charges-Aug24 | G7: Transportation In Charges August 2024 | I7: 223.67 | J7: =I7+E7 -> 82.6 | K7: =J7/E7 -> -0.58552492
A8: KR | B8: 1900008150 | C8: 45702 | D8: 6779IV124000284 | E8: -219.71 | F8: VAS Activity Charges -Jan25 | G8: VAS Activity - Jan 25, Ex Rate. 86.64 | I8: 146.81 | J8: =I8+E8 -> -72.9 | K8: =J8/E8 -> 0.33180101
A9: KR | B9: 1900008141 | C9: 45702 | D9: 6779IV124000272 | E9: -54.67 | F9: VAS Activity Charges-Dec24 | G9: VAS Activity Charges for the month of December, 24 | I9: 55.47 | J9: =I9+E9 -> 0.8 | K9: =J9/E9 -> -0.014633254
A10: KR | B10: 1900008128 | C10: 45702 | D10: 6779IV124000263 | E10: -135.81 | F10: VAS Activity Charges-Nov24 | G10: VAS Activity Charges for the month of November, 24 | I10: 139.65 | J10: =I10+E10 -> 3.84 | K10: =J10/E10 -> -0.028274796
A11: KR | B11: 1900008137 | C11: 45702 | D11: 6779IV124000255 | E11: -245.49 | F11: VAS Activity Charges-Oct24 | G11: VAS Activity Charges for the month of October, 24 | I11: 253.66 | J11: =I11+E11 -> 8.17 | K11: =J11/E11 -> -0.033280378
A12: KR | B12: 1900008131 | C12: 45702 | D12: 6779IV124000247 | E12: -71.36 | F12: VAS Activity Charges-Sep24 | G12: VAS Activity Charges for the month of September, 2 | I12: 73.99 | J12: =I12+E12 -> 2.63 | K12: =J12/E12 -> -0.036855381
A13: KR | B13: 1900008121 | C13: 45702 | D13: 6779IV124000240 | E13: -165.16 | F13: VAS Activity Charges-Aug24 | G13: VAS- 1-31 Aug-24, | I13: 165.16 | J13: =I13+E13 -> 0 | K13: =J13/E13 -> 0

Sheet invoice not in Ascendus Books
A1: Document Type | B1: Document Number | C1: Document Date | D1: Reference | E1: Amount in doc. curr. | F1: Text
A2: KR | B2: 1900008146 | C2: 45702 | D2: 6779IV124000278 | E2: -226.56 | F2: LCL Charges-Jan25
A3: KR | B3: 1900008159 | C3: 45702 | D3: 6779IV124000237 | E3: -1236.05 | F3: Inbound Handling Charges-Aug24
A4: KR | B4: 1900008148 | C4: 45702 | D4: 6779IV124000281 | E4: -23.6 | F4: CY Movement Charges-Jan25
A5: KR | B5: 1900008120 | C5: 45702 | D5: 6779IV124000238 | E5: -23.6 | F5: CY Movement Charges-Aug24
E41: =SUM(E23:E40) -> 0

Sheet Duplicate CN in Ascendus Books
A1: Document Number | B1: Document Type | C1: Document Date | D1: Reference | E1: Document Currency Key | F1: Document Currency Value | G1: Company Code Currency Key | H1: Company Code Currency Value | I1: Text | J1: Clearing Document
A2: 1600002320 | B2: DG | C2: 45923 | D2: 246779413054 | E2: USD | F2: -131.74 | G2: INR | H2: -11420.71 | I2: Credit Note Raised against INV_246779413054

Sheet Diffrence in Customer Books
A1: Document Number | B1: Document Type | C1: Document Date | D1: Reference | E1: New Ref | F1: Document Currency Key | G1: Document Currency Value | H1: Vlookup | I1: Difference | J1: Text | K1: Document No | L1: Doc Type | M1: Date | N1: Difference invoice raised in Ascendus books | O1: Amount | P1: Particulars | Q1: Net Diffrence | R1: Remarks
A2: 1800003964 | B2: DR | C2: 45736 | D2: 246779413820 | E2: 6779IV124000285 | F2: USD | G2: 354 | H2: =_xlfn.XLOOKUP(E2,'Customer Data'!$D:$D,'Customer Data'!$H:$H,,0) -> -200 | I2: =G2+H2 -> 154 | J2: Scanning Charges for the month of Jan 2025 | Q2: =O2+I2 -> 154 | R2: UnderBooked in customer's Books
A3: 1800007300 | B3: DR | C3: 45768 | D3: 256779412191 | E3: 6779IV124000234 | F3: USD | G3: 19567.14 | H3: =_xlfn.XLOOKUP(E3,'Customer Data'!$D:$D,'Customer Data'!$H:$H,,0) -> -19671.64 | I3: =G3+H3 -> -104.5 | J3: Storage Charges for Aug 2024 | Q3: =O3+I3 -> -104.5 | R3: OverBooked in customer's Books
A4: 1800012322 | B4: DR | C4: 45904 | D4: 256779416958 | F4: USD | G4: 3624.71 | H4: =_xlfn.XLOOKUP(D4,'Customer Data'!$D:$D,'Customer Data'!$H:$H,,0) -> -6712.26 | I4: =G4+H4 -> -3087.55 | J4: WH 09- Storage - 16-31 Aug 25 | K4: 1800011946 | L4: DR | M4: 45889 | N4: 256779416698 | O4: 3087.55 | P4: Storage 1-15 Aug-25,WH-9 | Q4: =O4+I4 -> 0 | R4: Different invoice no in Ascendus books
A5: 1800012323 | B5: DR | C5: 45904 | D5: 256779416959 | F5: USD | G5: 2779.47 | H5: =_xlfn.XLOOKUP(D5,'Customer Data'!$D:$D,'Customer Data'!$H:$H,,0) -> -5587.13 | I5: =G5+H5 -> -2807.66 | J5: WH 09- Storage - 16-31 Aug 25 | K5: 1800011947 | L5: DR | M5: 45889 | N5: 256779416699 | O5: 2807.66 | P5: Storage 1-15 Aug-25,WH-9 | Q5: =O5+I5 -> 0 | R5: Different invoice no in Ascendus books
A6: 1800013655 | B6: DR | C6: 45936 | D6: 256779418216 | F6: USD | G6: 3984.09 | H6: =_xlfn.XLOOKUP(D6,'Customer Data'!$D:$D,'Customer Data'!$H:$H,,0) -> -8093.39 | I6: =G6+H6 -> -4109.3 | J6: Storage -WH 09- 16-30 Sep 25 | K6: 1800013001 | L6: DR | M6: 45918 | N6: 256779417627 | O6: 4109.3 | P6: Storage -WH 09- 1-15 Sep 25 | Q6: =O6+I6 -> 0 | R6: Different invoice no in Ascendus books
A7: 1800013656 | B7: DR | C7: 45936 | D7: 256779418217 | F7: USD | G7: 3863.82 | H7: =_xlfn.XLOOKUP(D7,'Customer Data'!$D:$D,'Customer Data'!$H:$H,,0) -> -6196.45 | I7: =G7+H7 -> -2332.63 | J7: Storage -WH 09- 16-30 Sep 25 | K7: 1800013002 | L7: DR | M7: 45918 | N7: 256779417628 | O7: 2332.63 | P7: Storage -WH 09- 1-15 Sep 25 | Q7: =O7+I7 -> 0 | R7: Different invoice no in Ascendus books
A8: 1800012498 | B8: DR | C8: 45904 | D8: 256779417102 | F8: USD | G8: 17.07 | H8: =_xlfn.XLOOKUP(D8,'Customer Data'!$D:$D,'Customer Data'!$H:$H,,0) -> -66.22 | I8: =G8+H8 -> -49.15 | J8: VAS -16-31 Aug 25 | K8: 1800012098 | L8: DR | M8: 45889 | N8: 256779416789 | O8: 49.15 | P8: VAS-Aug 25, 1-15 | Q8: =O8+I8 -> 0 | R8: Different invoice no in Ascendus books
A9: 1800013605 | B9: DR | C9: 45937 | D9: 256779418129 | F9: USD | G9: 82.72 | H9: =_xlfn.XLOOKUP(D9,'Customer Data'!$D:$D,'Customer Data'!$H:$H,,0) -> -122.94 | I9: =G9+H9 -> -40.22 | J9: VAS-16-30 Sept 25 | K9: 1800012828 | L9: DR | M9: 45917 | N9: 256779417462 | O9: 40.22 | P9: VAS -1-15 Sept-25 | Q9: =O9+I9 -> 0 | R9: Different invoice no in Ascendus books
A10: 1800008808 | B10: DR | C10: 45785 | D10: 256779413572 | F10: USD | G10: 5969.61 | H10: =_xlfn.XLOOKUP(D10,'Customer Data'!$D:$D,'Customer Data'!$H:$H,,0) -> -6237.23 | I10: =G10+H10 -> -267.62 | J10: Storage 16-30 April-25-WH09 | K10: 1800016812 | L10: DR | M10: 46036 | N10: 256779450748 | O10: 267.62 | P10: Storage -WH 09- 16-30 Apr 25 | Q10: =O10+I10 -> 0 | R10: Different invoice no in Ascendus books
Q11: =SUM(Q2:Q10) -> 49.5

Sheet Ascendus data
A1: Cleared Item | B1: Company Code | C1: Customer | D1: Customer Account: Name 1 | E1: Fiscal Year | F1: Posting period | G1: Posting Date | H1: Document Number | I1: Document Type | J1: Document Date | K1: Entry Date | L1: Document Header Text | M1: Reference | N1: G/L Account | O1: G/L Account: Short Text | P1: Special G/L Ind. | Q1: Posting Key | R1: New Ref | S1: Document Currency Key | T1: Document Currency Value | U1: Company Code Currency Key | V1: Company Code Currency Value | X1: Profit Center | Y1: Trading Partner No. | Z1: Assignment | AA1: Item | AB1: Vlookup | AC1: Difference | AD1: Text | AE1: Reference Key 1 | AF1: Reference Key 2 | AG1: Reference Key 3 | AH1: Baseline Payment Dte | AI1: Clearing Date | AJ1: Clearing Document
A2: Selected | B2: 6779 | C2: 100222426 | D2: ASHLAND SPECIALITY CHEMICAL | E2: 2025 | F2: 7 | G2: 45855 | H2: 1400000284 | I2: DZ | J2: 45855 | K2: 45855 | L2: 2025062400636248 | N2: 212100 | O2: Trade Debtors (Ctrl) | Q2: 15 | R2: =_xlfn.XLOOKUP(M2,'Invoice No Ref'!$C:$C,'Invoice No Ref'!$I:$I,,0) -> #N/A | S2: USD | T2: -3814.84 | U2: INR | V2: -331592.82 | W2: =V2/T2 -> 86.921816 | X2: 6779224500 | AA2: 4 | AB2: =_xlfn.XLOOKUP(R2,'Customer Data'!$D:$D,'Customer Data'!$F:$F,,0) -> #N/A | AD2: 2025062400636248 | AH2: 45855 | AI2: 45855 | AJ2: 1400000284
A3: Not Selected | B3: 6779 | C3: 100222426 | D3: ASHLAND SPECIALITY CHEMICAL | E3: 2025 | F3: 8 | G3: 45891 | H3: 1400000999 | I3: DZ | J3: 45891 | K3: 45891 | N3: 212100 | O3: Trade Debtors (Ctrl) | Q3: 15 | R3: =_xlfn.XLOOKUP(M3,'Invoice No Ref'!$C:$C,'Invoice No Ref'!$I:$I,,0) -> #N/A | S3: USD | T3: -123953.28 | U3: INR | V3: -10774245 | W3: =V3/T3 -> 86.92182 | X3: 6779220000 | AA3: 2 | AB3: =_xlfn.XLOOKUP(R3,'Customer Data'!$D:$D,'Customer Data'!$F:$F,,0) -> #N/A | AH3: 45891
A4: Selected | B4: 6779 | C4: 100222426 | D4: ASHLAND SPECIALITY CHEMICAL | E4: 2025 | F4: 7 | G4: 45855 | H4: 1400000284 | I4: DZ | J4: 45855 | K4: 45855 | L4: 2025062400636248 | N4: 212100 | O4: Trade Debtors (Ctrl) | Q4: 15 | R4: =_xlfn.XLOOKUP(M4,'Invoice No Ref'!$C:$C,'Invoice No Ref'!$I:$I,,0) -> #N/A | S4: USD | T4: -15968.69 | U4: INR | V4: -1388027.6 | W4: =V4/T4 -> 86.92182 | AA4: 3 | AB4: =_xlfn.XLOOKUP(R4,'Customer Data'!$D:$D,'Customer Data'!$F:$F,,0) -> #N/A | AD4: 2025062400636248 | AH4: 45855 | AI4: 45855 | AJ4: 1400000284
A5: Selected | B5: 6779 | C5: 100222426 | D5: ASHLAND SPECIALITY CHEMICAL | E5: 2025 | F5: 7 | G5: 45842 | H5: 1400000158 | I5: DY | J5: 45842 | K5: 45842 | L5: NA | M5: KNOCK OFF ENTRY | N5: 212100 | O5: Trade Debtors (Ctrl) | Q5: 15 | R5: =_xlfn.XLOOKUP(M5,'Invoice No Ref'!$C:$C,'Invoice No Ref'!$I:$I,,0) -> #N/A | S5: USD | T5: 0 | U5: INR | V5: 0 | W5: =V5/T5 -> #DIV/0! | X5: 6779224500 | AA5: 1 | AB5: =_xlfn.XLOOKUP(R5,'Customer Data'!$D:$D,'Customer Data'!$F:$F,,0) -> #N/A | AH5: 45842 | AI5: 45842 | AJ5: 1400000158
A6: Selected | B6: 6779 | C6: 100222426 | D6: ASHLAND SPECIALITY CHEMICAL | E6: 2025 | F6: 3 | G6: 45735 | H6: 1800003187 | I6: DR | J6: 45735 | K6: 45736 | L6: NA | M6: 246779413054 | N6: 212100 | O6: Trade Debtors (Ctrl) | Q6: 01 | R6: =_xlfn.XLOOKUP(M6,'Invoice No Ref'!$C:$C,'Invoice No Ref'!$I:$I,,0) -> #N/A | S6: USD | T6: 131.74 | U6: INR | V6: 11420.71 | W6: =V6/T6 -> 86.691286 | X6: 6779224500 | Z6: NA | AA6: 1 | AB6: =_xlfn.XLOOKUP(R6,'Customer Data'!$D:$D,'Customer Data'!$F:$F,,0) -> #N/A | AD6: Port SSR Charges - Shifting for Aug to Dec,24. | AH6: 45735 | AI6: 45842 | AJ6: 1400000158
A7: Selected | B7: 6779 | C7: 100222426 | D7: ASHLAND SPECIALITY CHEMICAL | E7: 2025 | F7: 11 | G7: 45976 | H7: 1400001878 | I7: DY | J7: 45976 | K7: 45976 | L7: NA | M7: KNOCK OFF ENTRY | N7: 212100 | O7: Trade Debtors (Ctrl) | Q7: 08 | R7: =_xlfn.XLOOKUP(M7,'Invoice No Ref'!$C:$C,'Invoice No Ref'!$I:$I,,0) -> #N/A | S7: USD | T7: 3981.8 | U7: INR | V7: 351158.01 | W7: =V7/T7 -> 88.190771 | X7: 6779224501 | AA7: 1 | AB7: =_xlfn.XLOOKUP(R7,'Customer Data'!$D:$D,'Customer Data'!$F:$F,,0) -> #N/A | AH7: 45976 | AI7: 45976 | AJ7: 1400001878
A8: Selected | B8: 6779 | C8: 100222426 | D8: ASHLAND SPECIALITY CHEMICAL | E8: 2025 | F8: 11 | G8: 45976 | H8: 1400001878 | I8: DY | J8: 45976 | K8: 45976 | L8: NA | M8: KNOCK OFF ENTRY | N8: 212100 | O8: Trade Debtors (Ctrl) | Q8: 15 | R8: =_xlfn.XLOOKUP(M8,'Invoice No Ref'!$C:$C,'Invoice No Ref'!$I:$I,,0) -> #N/A | S8: USD | T8: -3981.8 | U8: INR | V8: -351158.01 | W8: =V8/T8 -> 88.190771 | X8: 6779224501 | AA8: 2 | AB8: =_xlfn.XLOOKUP(R8,'Customer Data'!$D:$D,'Customer Data'!$F:$F,,0) -> #N/A | AH8: 45976 | AI8: 45976 | AJ8: 1400001878
A9: Not Selected | B9: 6779 | C9: 100222426 | D9: ASHLAND SPECIALITY CHEMICAL | E9: 2025 | F9: 3 | G9: 45736 | H9: 1800004475 | I9: DR | J9: 45736 | K9: 45737 | L9: NA | M9: 246779414343 | N9: 212100 | O9: Trade Debtors (Ctrl) | Q9: 01 | R9: =_xlfn.XLOOKUP(M9,'Invoice No Ref'!$C:$C,'Invoice No Ref'!$I:$I,,0) -> 6779IV124000258 | S9: USD | T9: 118 | U9: INR | V9: 10229.57 | W9: =V9/T9 -> 86.691271 | X9: 6779224500 | Z9: NA | AA9: 1 | AB9: =_xlfn.XLOOKUP(R9,'Customer Data'!$D:$D,'Customer Data'!$F:$F,,0) -> -118 | AC9: =AB9+T9 -> 0 | AD9: CY-MOVEMENT CHARGES for Nov 2024 | AH9: 45736
A10: Not Selected | B10: 6779 | C10: 100222426 | D10: ASHLAND SPECIALITY CHEMICAL | E10: 2025 | F10: 3 | G10: 45736 | H10: 1800004556 | I10: DR | J10: 45736 | K10: 45737 | L10: NA | M10: 246779414424 | N10: 212100 | O10: Trade Debtors (Ctrl) | Q10: 01 | R10: =_xlfn.XLOOKUP(M10,'Invoice No Ref'!$C:$C,'Invoice No Ref'!$I:$I,,0) -> 6779IV124000276 | S10: USD | T10: 118 | U10: INR | V10: 10229.57 | W10: =V10/T10 -> 86.691271 | X10: 6779224500 | Z10: NA | AA10: 1 | AB10: =_xlfn.XLOOKUP(R10,'Customer Data'!$D:$D,'Customer Data'!$F:$F,,0) -> -118 | AC10: =AB10+T10 -> 0 | AD10: Cy-WH Destuff charges for Jan 2025 | AH10: 45736
A11: Not Selected | B11: 6779 | C11: 100222426 | D11: ASHLAND SPECIALITY CHEMICAL | E11: 2025 | F11: 4 | G11: 45763 | H11: 1800006323 | I11: DR | J11: 45763 | K11: 45763 | L11: NA | M11: 256779411214 | N11: 212100 | O11: Trade Debtors (Ctrl) | Q11: 01 | R11: =_xlfn.XLOOKUP(M11,'Invoice No Ref'!$C:$C,'Invoice No Ref'!$I:$I,,0) -> #N/A | S11: USD | T11: 11.8 | U11: INR | V11: 1025.68 | W11: =V11/T11 -> 86.922034 | Z11: NA | AA11: 1 | AB11: =_xlfn.XLOOKUP(R11,'Customer Data'!$D:$D,'Customer Data'!$F:$F,,0) -> #N/A | AD11: Outbound Handling Charges Aug 2024 | AH11: 45763
A12: Not Selected | B12: 6779 | C12: 100222426 | D12: ASHLAND SPECIALITY CHEMICAL | E12: 2025 | F12: 3 | G12: 45736 | H12: 1800003964 | I12: DR | J12: 45736 | K12: 45737 | L12: NA | M12: 246779413820 | N12: 212100 | O12: Trade Debtors (Ctrl) | Q12: 01 | R12: =_xlfn.XLOOKUP(M12,'Invoice No Ref'!$C:$C,'Invoice No Ref'!$I:$I,,0) -> 6779IV124000285 | S12: USD | T12: 354 | U12: INR | V12: 30688.71 | W12: =V12/T12 -> 86.691271 | X12: 6779224500 | Z12: NA | AA12: 1 | AB12: =_xlfn.XLOOKUP(R12,'Customer Data'!$D:$D,'Customer Data'!$F:$F,,0) -> -200 | AC12: =AB12+T12 -> 154 | AD12: Scanning Charges for the month of Jan 2025 | AH12: 45736
A13: Not Selected | B13: 6779 | C13: 100222426 | D13: ASHLAND SPECIALITY CHEMICAL | E13: 2025 | F13: 4 | G13: 45751 | H13: 1800005708 | I13: DR | J13: 45751 | K13: 45752 | L13: NA | M13: 256779410600 | N13: 212100 | O13: Trade Debtors (Ctrl) | Q13: 01 | R13: =_xlfn.XLOOKUP(M13,'Invoice No Ref'!$C:$C,'Invoice No Ref'!$I:$I,,0) -> 6779IV124000274 | S13: USD | T13: 15887.63 | U13: INR | V13: 1380981.7 | W13: =V13/T13 -> 86.92182 | Z13: NA | AA13: 1 | AB13: =_xlfn.XLOOKUP(R13,'Customer Data'!$D:$D,'Customer Data'!$F:$F,,0) -> -15887.63 | AC13: =AB13+T13 -> 0 | AD13: Storage charges for Jan 2025 | AH13: 45751
A14: Not Selected | B14: 6779 | C14: 100222426 | D14: ASHLAND SPECIALITY CHEMICAL | E14: 2025 | F14: 3 | G14: 45733 | H14: 1800001878 | I14: DR | J14: 45733 | K14: 45733 | L14: NA | M14: 246779411543 | N14: 212100 | O14: Trade Debtors (Ctrl) | Q14: 01 | R14: =_xlfn.XLOOKUP(M14,'Invoice No Ref'!$C:$C,'Invoice No Ref'!$I:$I,,0) -> #N/A | S14: USD | T14: 17.9 | U14: INR | V14: 1551.77 | W14: =V14/T14 -> 86.691061 | X14: 6779224500 | Z14: NA | AA14: 1 | AB14: =_xlfn.XLOOKUP(R14,'Customer Data'!$D:$D,'Customer Data'!$F:$F,,0) -> #N/A | AD14: VAS Activity Charges for the month of September, 2 | AH14: 45733
A15: Not Selected | B15: 6779 | C15: 100222426 | D15: ASHLAND SPECIALITY CHEMICAL | E15: 2025 | F15: 3 | G15: 45733 | H15: 1800001879 | I15: DR | J15: 45733 | K15: 45733 | L15: NA | M15: 246779411544 | N15: 212100 | O15: Trade Debtors (Ctrl) | Q15: 01 | R15: =_xlfn.XLOOKUP(M15,'Invoice No Ref'!$C:$C,'Invoice No Ref'!$I:$I,,0) -> #N/A | S15: USD | T15: 17.9 | U15: INR | V15: 1551.77 | W15: =V15/T15 -> 86.691061 | X15: 6779224500 | Z15: NA | AA15: 1 | AB15: =_xlfn.XLOOKUP(R15,'Customer Data'!$D:$D,'Customer Data'!$F:$F,,0) -> #N/A | AD15: VAS Activity Charges for the month of September, 2 | AH15: 45733
A16: Not Selected | B16: 6779 | C16: 100222426 | D16: ASHLAND SPECIALITY CHEMICAL | E16: 2025 | F16: 3 | G16: 45733 | H16: 1800001880 | I16: DR | J16: 45733 | K16: 45733 | L16: NA | M16: 246779411545 | N16: 212100 | O16: Trade Debtors (Ctrl) | Q16: 01 | R16: =_xlfn.XLOOKUP(M16,'Invoice No Ref'!$C:$C,'Invoice No Ref'!$I:$I,,0) -> #N/A | S16: USD | T16: 38.19 | U16: INR | V16: 3310.74 | W16: =V16/T16 -> 86.69128 | X16: 6779224500 | Z16: NA | AA16: 1 | AB16: =_xlfn.XLOOKUP(R16,'Customer Data'!$D:$D,'Customer Data'!$F:$F,,0) -> #N/A | AD16: VAS Activity Charges for the month of September, 2 | AH16: 45733
A17: Not Selected | B17: 6779 | C17: 100222426 | D17: ASHLAND SPECIALITY CHEMICAL | E17: 2025 | F17: 3 | G17: 45733 | H17: 1800001993 | I17: DR | J17: 45733 | K17: 45734 | L17: NA | M17: 246779411658 | N17: 212100 | O17: Trade Debtors (Ctrl) | Q17: 01 | R17: =_xlfn.XLOOKUP(M17,'Invoice No Ref'!$C:$C,'Invoice No Ref'!$I:$I,,0) -> #N/A | S17: USD | T17: 149.84 | U17: INR | V17: 12989.82 | W17: =V17/T17 -> 86.691271 | X17: 6779224500 | Z17: NA | AA17: 1 | AB17: =_xlfn.XLOOKUP(R17,'Customer Data'!$D:$D,'Customer Data'!$F:$F,,0) -> #N/A | AD17: VAS Activity Charges for the month of October, 24 | AH17: 45733
A18: Not Selected | B18: 6779 | C18: 100222426 | D18: ASHLAND SPECIALITY CHEMICAL | E18: 2025 | F18: 3 | G18: 45733 | H18: 1800001994 | I18: DR | J18: 45733 | K18: 45734 | L18: NA | M18: 246779411659 | N18: 212100 | O18: Trade Debtors (Ctrl) | Q18: 01 | R18: =_xlfn.XLOOKUP(M18,'Invoice No Ref'!$C:$C,'Invoice No Ref'!$I:$I,,0) -> #N/A | S18: USD | T18: 17.84 | U18: INR | V18: 1546.57 | W18: =V18/T18 -> 86.691143 | X18: 6779224500 | Z18: NA | AA18: 1 | AB18: =_xlfn.XLOOKUP(R18,'Customer Data'!$D:$D,'Customer Data'!$F:$F,,0) -> #N/A | AD18: VAS Activity Charges for the month of October, 24 | AH18: 45733
A19: Not Selected | B19: 6779 | C19: 100222426 | D19: ASHLAND SPECIALITY CHEMICAL | E19: 2025 | F19: 3 | G19: 45733 | H19: 1800001995 | I19: DR | J19: 45733 | K19: 45734 | L19: NA | M19: 246779411660 | N19: 212100 | O19: Trade Debtors (Ctrl) | Q19: 01 | R19: =_xlfn.XLOOKUP(M19,'Invoice No Ref'!$C:$C,'Invoice No Ref'!$I:$I,,0) -> #N/A | S19: USD | T19: 11.89 | U19: INR | V19: 1030.76 | W19: =V19/T19 -> 86.691337 | X19: 6779224500 | Z19: NA | AA19: 1 | AB19: =_xlfn.XLOOKUP(R19,'Customer Data'!$D:$D,'Customer Data'!$F:$F,,0) -> #N/A | AD19: VAS Activity Charges for the month of October, 24 | AH19: 45733
A20: Not Selected | B20: 6779 | C20: 100222426 | D20: ASHLAND SPECIALITY CHEMICAL | E20: 2025 | F20: 3 | G20: 45733 | H20: 1800001996 | I20: DR | J20: 45733 | K20: 45734 | L20: NA | M20: 246779411661 | N20: 212100 | O20: Trade Debtors (Ctrl) | Q20: 01 | R20: =_xlfn.XLOOKUP(M20,'Invoice No Ref'!$C:$C,'Invoice No Ref'!$I:$I,,0) -> #N/A | S20: USD | T20: 0.95 | U20: INR | V20: 82.36 | W20: =V20/T20 -> 86.694737 | X20: 6779224500 | Z20: NA | AA20: 1 | AB20: =_xlfn.XLOOKUP(R20,'Customer Data'!$D:$D,'Customer Data'!$F:$F,,0) -> #N/A | AD20: VAS Activity Charges for the month of October, 24 | AH20: 45733
A21: Not Selected | B21: 6779 | C21: 100222426 | D21: ASHLAND SPECIALITY CHEMICAL | E21: 2025 | F21: 3 | G21: 45733 | H21: 1800001997 | I21: DR | J21: 45733 | K21: 45734 | L21: NA | M21: 246779411662 | N21: 212100 | O21: Trade Debtors (Ctrl) | Q21: 01 | R21: =_xlfn.XLOOKUP(M21,'Invoice No Ref'!$C:$C,'Invoice No Ref'!$I:$I,,0) -> #N/A | S21: USD | T21: 6.54 | U21: INR | V21: 566.96 | W21: =V21/T21 -> 86.691131 | X21: 6779224500 | Z21: NA | AA21: 1 | AB21: =_xlfn.XLOOKUP(R21,'Customer Data'!$D:$D,'Customer Data'!$F:$F,,0) -> #N/A | AD21: VAS Activity Charges for the month of October, 24 | AH21: 45733
A22: Not Selected | B22: 6779 | C22: 100222426 | D22: ASHLAND SPECIALITY CHEMICAL | E22: 2025 | F22: 3 | G22: 45733 | H22: 1800001998 | I22: DR | J22: 45733 | K22: 45734 | L22: NA | M22: 246779411663 | N22: 212100 | O22: Trade Debtors (Ctrl) | Q22: 01 | R22: =_xlfn.XLOOKUP(M22,'Invoice No Ref'!$C:$C,'Invoice No Ref'!$I:$I,,0) -> #N/A | S22: USD | T22: 66.6 | U22: INR | V22: 5773.64 | W22: =V22/T22 -> 86.691291 | X22: 6779224500 | Z22: NA | AA22: 1 | AB22: =_xlfn.XLOOKUP(R22,'Customer Data'!$D:$D,'Customer Data'!$F:$F,,0) -> #N/A | AD22: VAS Activity Charges for the month of October, 24 | AH22: 45733
A23: Not Selected | B23: 6779 | C23: 100222426 | D23: ASHLAND SPECIALITY CHEMICAL | E23: 2025 | F23: 3 | G23: 45733 | H23: 1800002200 | I23: DR | J23: 45733 | K23: 45734 | L23: NA | M23: 246779411865 | N23: 212100 | O23: Trade Debtors (Ctrl) | Q23: 01 | R23: =_xlfn.XLOOKUP(M23,'Invoice No Ref'!$C:$C,'Invoice No Ref'!$I:$I,,0) -> #N/A | S23: USD | T23: 17.75 | U23: INR | V23: 1538.77 | W23: =V23/T23 -> 86.691268 | X23: 6779224500 | Z23: NA | AA23: 1 | AB23: =_xlfn.XLOOKUP(R23,'Customer Data'!$D:$D,'Customer Data'!$F:$F,,0) -> #N/A | AD23: VAS Activity Charges for the month of November, 24 | AH23: 45733
A24: Not Selected | B24: 6779 | C24: 100222426 | D24: ASHLAND SPECIALITY CHEMICAL | E24: 2025 | F24: 3 | G24: 45733 | H24: 1800002201 | I24: DR | J24: 45733 | K24: 45734 | L24: NA | M24: 246779411866 | N24: 212100 | O24: Trade Debtors (Ctrl) | Q24: 01 | R24: =_xlfn.XLOOKUP(M24,'Invoice No Ref'!$C:$C,'Invoice No Ref'!$I:$I,,0) -> #N/A | S24: USD | T24: 17.75 | U24: INR | V24: 1538.77 | W24: =V24/T24 -> 86.691268 | X24: 6779224500 | Z24: NA | AA24: 1 | AB24: =_xlfn.XLOOKUP(R24,'Customer Data'!$D:$D,'Customer Data'!$F:$F,,0) -> #N/A | AD24: VAS Activity Charges for the month of November, 24 | AH24: 45733
A25: Not Selected | B25: 6779 | C25: 100222426 | D25: ASHLAND SPECIALITY CHEMICAL | E25: 2025 | F25: 3 | G25: 45733 | H25: 1800002206 | I25: DR | J25: 45733 | K25: 45734 | L25: NA | M25: 246779411871 | N25: 212100 | O25: Trade Debtors (Ctrl) | Q25: 01 | R25: =_xlfn.XLOOKUP(M25,'Invoice No Ref'!$C:$C,'Invoice No Ref'!$I:$I,,0) -> #N/A | S25: USD | T25: 17.75 | U25: INR | V25: 1538.77 | W25: =V25/T25 -> 86.691268 | X25: 6779224500 | Z25: NA | AA25: 1 | AB25: =_xlfn.XLOOKUP(R25,'Customer Data'!$D:$D,'Customer Data'!$F:$F,,0) -> #N/A | AD25: VAS Activity Charges for the month of November, 24 | AH25: 45733
... A34: Not Selected | B34: 6779 | C34: 100222426 | D34: ASHLAND SPECIALITY CHEMICAL | E34: 2025 | F34: 3 | G34: 45733 | H34: 1800002208 | I34: DR | J34: 45733 | K34: 45734 | L34: NA | M34: 246779411873 | N34: 212100 | O34: Trade Debtors (Ctrl) | Q34: 01 | R34: =_xlfn.XLOOKUP(M34,'Invoice No Ref'!$C:$C,'Invoice No Ref'!$I:$I,,0) -> #N/A | S34: USD | T34: 16.57 | U34: INR | V34: 1436.47 | W34: =V34/T34 -> 86.691008 | X34: 6779224500 | Z34: NA | AA34: 1 | AB34: =_xlfn.XLOOKUP(R34,'Customer Data'!$D:$D,'Customer Data'!$F:$F,,0) -> #N/A | AD34: VAS Activity Charges for the month of November, 24 | AH34: 45733
A35: Not Selected | B35: 6779 | C35: 100222426 | D35: ASHLAND SPECIALITY CHEMICAL | E35: 2025 | F35: 4 | G35: 45762 | H35: 1800006092 | I35: DR | J35: 45762 | K35: 45763 | L35: NA | M35: 256779410983 | N35: 212100 | O35: Trade Debtors (Ctrl) | Q35: 01 | R35: =_xlfn.XLOOKUP(M35,'Invoice No Ref'!$C:$C,'Invoice No Ref'!$I:$I,,0) -> #N/A | S35: USD | T35: 392.35 | U35: INR | V35: 34103.78 | W35: =V35/T35 -> 86.92183 | Z35: NA | AA35: 1 | AB35: =_xlfn.XLOOKUP(R35,'Customer Data'!$D:$D,'Customer Data'!$F:$F,,0) -> #N/A | AD35: CY Destuff Charges August 2024 | AH35: 45762
A36: Not Selected | B36: 6779 | C36: 100222426 | D36: ASHLAND SPECIALITY CHEMICAL | E36: 2025 | F36: 4 | G36: 45762 | H36: 1800006093 | I36: DR | J36: 45762 | K36: 45763 | L36: NA | M36: 256779410984 | N36: 212100 | O36: Trade Debtors (Ctrl) | Q36: 01 | R36: =_xlfn.XLOOKUP(M36,'Invoice No Ref'!$C:$C,'Invoice No Ref'!$I:$I,,0) -> #N/A | S36: USD | T36: 200.6 | U36: INR | V36: 17436.52 | W36: =V36/T36 -> 86.921834 | Z36: NA | AA36: 1 | AB36: =_xlfn.XLOOKUP(R36,'Customer Data'!$D:$D,'Customer Data'!$F:$F,,0) -> #N/A | AD36: CY Destuff Charges August 2024 | AH36: 45762
A37: Not Selected | B37: 6779 | C37: 100222426 | D37: ASHLAND SPECIALITY CHEMICAL | E37: 2025 | F37: 4 | G37: 45762 | H37: 1800006094 | I37: DR | J37: 45762 | K37: 45763 | L37: NA | M37: 256779410985 | N37: 212100 | O37: Trade Debtors (Ctrl) | Q37: 01 | R37: =_xlfn.XLOOKUP(M37,'Invoice No Ref'!$C:$C,'Invoice No Ref'!$I:$I,,0) -> #N/A | S37: USD | T37: 106.2 | U37: INR | V37: 9231.1 | W37: =V37/T37 -> 86.921846 | Z37: NA | AA37: 1 | AB37: =_xlfn.XLOOKUP(R37,'Customer Data'!$D:$D,'Customer Data'!$F:$F,,0) -> #N/A | AD37: CY Destuff Charges August 2024 | AH37: 45762
A38: Not Selected | B38: 6779 | C38: 100222426 | D38: ASHLAND SPECIALITY CHEMICAL | E38: 2025 | F38: 4 | G38: 45762 | H38: 1800006095 | I38: DR | J38: 45762 | K38: 45763 | L38: NA | M38: 256779410986 | N38: 212100 | O38: Trade Debtors (Ctrl) | Q38: 01 | R38: =_xlfn.XLOOKUP(M38,'Invoice No Ref'!$C:$C,'Invoice No Ref'!$I:$I,,0) -> #N/A | S38: USD | T38: 82.6 | U38: INR | V38: 7179.74 | W38: =V38/T38 -> 86.921792 | Z38: NA | AA38: 1 | AB38: =_xlfn.XLOOKUP(R38,'Customer Data'!$D:$D,'Customer Data'!$F:$F,,0) -> #N/A | AD38: CY Destuff Charges August 2024 | AH38: 45762
A39: Not Selected | B39: 6779 | C39: 100222426 | D39: ASHLAND SPECIALITY CHEMICAL | E39: 2025 | F39: 4 | G39: 45762 | H39: 1800006096 | I39: DR | J39: 45762 | K39: 45763 | L39: NA | M39: 256779410987 | N39: 212100 | O39: Trade Debtors (Ctrl) | Q39: 01 | R39: =_xlfn.XLOOKUP(M39,'Invoice No Ref'!$C:$C,'Invoice No Ref'!$I:$I,,0) -> #N/A | S39: USD | T39: 223.67 | U39: INR | V39: 19441.8 | W39: =V39/T39 -> 86.921804 | Z39: NA | AA39: 1 | AB39: =_xlfn.XLOOKUP(R39,'Customer Data'!$D:$D,'Customer Data'!$F:$F,,0) -> #N/A | AD39: Transportation In Charges August 2024 | AH39: 45762
A40: Not Selected | B40: 6779 | C40: 100222426 | D40: ASHLAND SPECIALITY CHEMICAL | E40: 2025 | F40: 4 | G40: 45762 | H40: 1800006097 | I40: DR | J40: 45762 | K40: 45763 | L40: NA | M40: 256779410988 | N40: 212100 | O40: Trade Debtors (Ctrl) | Q40: 01 | R40: =_xlfn.XLOOKUP(M40,'Invoice No Ref'!$C:$C,'Invoice No Ref'!$I:$I,,0) -> #N/A | S40: USD | T40: 330.4 | U40: INR | V40: 28718.97 | W40: =V40/T40 -> 86.921822 | Z40: NA | AA40: 1 | AB40: =_xlfn.XLOOKUP(R40,'Customer Data'!$D:$D,'Customer Data'!$F:$F,,0) -> #N/A | AD40: CY Destuff Charges August 2024 | AH40: 45762
A41: Not Selected | B41: 6779 | C41: 100222426 | D41: ASHLAND SPECIALITY CHEMICAL | E41: 2025 | F41: 4 | G41: 45762 | H41: 1800006098 | I41: DR | J41: 45762 | K41: 45763 | L41: NA | M41: 256779410989 | N41: 212100 | O41: Trade Debtors (Ctrl) | Q41: 01 | R41: =_xlfn.XLOOKUP(M41,'Invoice No Ref'!$C:$C,'Invoice No Ref'!$I:$I,,0) -> #N/A | S41: USD | T41: 82.6 | U41: INR | V41: 7179.74 | W41: =V41/T41 -> 86.921792 | Z41: NA | AA41: 1 | AB41: =_xlfn.XLOOKUP(R41,'Customer Data'!$D:$D,'Customer Data'!$F:$F,,0) -> #N/A | AD41: CY Destuff Charges August 2024 | AH41: 45762
A42: Not Selected | B42: 6779 | C42: 100222426 | D42: ASHLAND SPECIALITY CHEMICAL | E42: 2025 | F42: 4 | G42: 45762 | H42: 1800006099 | I42: DR | J42: 45762 | K42: 45763 | L42: NA | M42: 256779410990 | N42: 212100 | O42: Trade Debtors (Ctrl) | Q42: 01 | R42: =_xlfn.XLOOKUP(M42,'Invoice No Ref'!$C:$C,'Invoice No Ref'!$I:$I,,0) -> #N/A | S42: USD | T42: 194.7 | U42: INR | V42: 16923.68 | W42: =V42/T42 -> 86.921828 | Z42: NA | AA42: 1 | AB42: =_xlfn.XLOOKUP(R42,'Customer Data'!$D:$D,'Customer Data'!$F:$F,,0) -> #N/A | AD42: CY Destuff Charges August 2024 | AH42: 45762
A43: Selected | B43: 6779 | C43: 100222426 | D43: ASHLAND SPECIALITY CHEMICAL | E43: 2025 | F43: 10 | G43: 45947 | H43: 1600002447 | I43: DG | J43: 45947 | K43: 45953 | L43: NA | M43: 256779421989 | N43: 212100 | O43: Trade Debtors (Ctrl) | Q43: 11 | R43: =_xlfn.XLOOKUP(M43,'Invoice No Ref'!$C:$C,'Invoice No Ref'!$I:$I,,0) -> #N/A | S43: USD | T43: -3981.8 | U43: INR | V43: -351158.01 | W43: =V43/T43 -> 88.190771 | X43: 6779224501 | Z43: 2117487 | AA43: 1 | AB43: =_xlfn.XLOOKUP(R43,'Customer Data'!$D:$D,'Customer Data'!$F:$F,,0) -> #N/A | AD43: Credit note raised against 256779418050 | AH43: 45947 | AI43: 45976 | AJ43: 1400001878
A44: Not Selected | B44: 6779 | C44: 100222426 | D44: ASHLAND SPECIALITY CHEMICAL | E44: 2025 | F44: 4 | G44: 45763 | H44: 1800006828 | I44: DR | J44: 45763 | K44: 45764 | L44: NA | M44: 256779411719 | N44: 212100 | O44: Trade Debtors (Ctrl) | Q44: 01 | R44: =_xlfn.XLOOKUP(M44,'Invoice No Ref'!$C:$C,'Invoice No Ref'!$I:$I,,0) -> #N/A | S44: USD | T44: 488.03 | U44: INR | V44: 42420.46 | W44: =V44/T44 -> 86.921829 | X44: 6779224500 | Z44: NA | AA44: 1 | AB44: =_xlfn.XLOOKUP(R44,'Customer Data'!$D:$D,'Customer Data'!$F:$F,,0) -> #N/A | AD44: CY Longstanding Transportation chgs for 31 MAR 202 | AH44: 45763
A45: Not Selected | B45: 6779 | C45: 100222426 | D45: ASHLAND SPECIALITY CHEMICAL | E45: 2025 | F45: 4 | G45: 45763 | H45: 1800006853 | I45: DR | J45: 45763 | K45: 45764 | L45: NA | M45: 256779411744 | N45: 212100 | O45: Trade Debtors (Ctrl) | Q45: 01 | R45: =_xlfn.XLOOKUP(M45,'Invoice No Ref'!$C:$C,'Invoice No Ref'!$I:$I,,0) -> 6779IV124000269 | S45: USD | T45: 1015.85 | U45: INR | V45: 88299.53 | W45: =V45/T45 -> 86.921819 | X45: 6779224500 | Z45: NA | AA45: 1 | AB45: =_xlfn.XLOOKUP(R45,'Customer Data'!$D:$D,'Customer Data'!$F:$F,,0) -> -1015.85 | AC45: =AB45+T45 -> 0 | AD45: Inbound Handling charges for Dec 2024 | AH45: 45763
A46: Not Selected | B46: 6779 | C46: 100222426 | D46: ASHLAND SPECIALITY CHEMICAL | E46: 2025 | F46: 4 | G46: 45763 | H46: 1800006854 | I46: DR | J46: 45763 | K46: 45764 | L46: NA | M46: 256779411745 | N46: 212100 | O46: Trade Debtors (Ctrl) | Q46: 01 | R46: =_xlfn.XLOOKUP(M46,'Invoice No Ref'!$C:$C,'Invoice No Ref'!$I:$I,,0) -> #N/A | S46: USD | T46: 169.92 | U46: INR | V46: 14769.76 | W46: =V46/T46 -> 86.921846 | X46: 6779224500 | Z46: NA | AA46: 1 | AB46: =_xlfn.XLOOKUP(R46,'Customer Data'!$D:$D,'Customer Data'!$F:$F,,0) -> #N/A | AD46: Loose Unloading charges for Dec 2024 | AH46: 45763
A47: Not Selected | B47: 6779 | C47: 100222426 | D47: ASHLAND SPECIALITY CHEMICAL | E47: 2025 | F47: 4 | G47: 45763 | H47: 1800006855 | I47: DR | J47: 45763 | K47: 45764 | L47: NA | M47: 256779411746 | N47: 212100 | O47: Trade Debtors (Ctrl) | Q47: 01 | R47: =_xlfn.XLOOKUP(M47,'Invoice No Ref'!$C:$C,'Invoice No Ref'!$I:$I,,0) -> 6779IV124000267 | S47: USD | T47: 141.6 | U47: INR | V47: 12308.13 | W47: =V47/T47 -> 86.921822 | X47: 6779224500 | Z47: NA | AA47: 1 | AB47: =_xlfn.XLOOKUP(R47,'Customer Data'!$D:$D,'Customer Data'!$F:$F,,0) -> -141.6 | AC47: =AB47+T47 -> 0 | AD47: Cy-WH Destuff charges for Dec 2024 | AH47: 45763
A48: Not Selected | B48: 6779 | C48: 100222426 | D48: ASHLAND SPECIALITY CHEMICAL | E48: 2025 | F48: 4 | G48: 45763 | H48: 1800006939 | I48: DR | J48: 45763 | K48: 45764 | L48: NA | M48: 256779411830 | N48: 212100 | O48: Trade Debtors (Ctrl) | Q48: 01 | R48: =_xlfn.XLOOKUP(M48,'Invoice No Ref'!$C:$C,'Invoice No Ref'!$I:$I,,0) -> 6779IV124000271 | S48: USD | T48: 1362.36 | U48: INR | V48: 118418.81 | W48: =V48/T48 -> 86.921819 | X48: 6779224500 | Z48: NA | AA48: 1 | AB48: =_xlfn.XLOOKUP(R48,'Customer Data'!$D:$D,'Customer Data'!$F:$F,,0) -> -1362.36 | AC48: =AB48+T48 -> 0 | AD48: Outbound Handling charges for Dec 2024 | AH48: 45763
...

Sheet Customer Data
A1: Document Type | B1: Document Number | C1: Document Date | D1: Reference | E1: Document currency | F1: Amount in doc. curr. | G1: Local Currency | H1: Amount in local currency | I1: Vlookup | J1: Difference | K1: Clearing Document | L1: Clearing date | M1: Text
A2: KR | B2: 1900008116 | C2: 45702 | D2: 6779IV124000285 | E2: USD | F2: -200 | G2: USD | H2: -200 | I2: =_xlfn.XLOOKUP(D2,'Ascendus data'!$R:$R,'Ascendus data'!$T:$T,,0) -> 354 | J2: =H2+I2 -> 154 | K2: 2000002627 | L2: 45751 | M2: Scanning Charges-Jan25
A3: KR | B3: 1900008117 | C3: 45702 | D3: 6779IV124000244 | E3: USD | F3: -169.92 | G3: USD | H3: -169.92 | I3: =_xlfn.XLOOKUP(D3,'Ascendus data'!$R:$R,'Ascendus data'!$T:$T,,0) -> 169.92 | J3: =H3+I3 -> 0 | K3: 2000002627 | L3: 45751 | M3: LCL Charges-Sep24
A4: KR | B4: 1900008118 | C4: 45702 | D4: 6779IV124000235 | E4: USD | F4: -141.07 | G4: USD | H4: -141.07 | I4: =_xlfn.XLOOKUP(D4,'Ascendus data'!$R:$R,'Ascendus data'!$T:$T,,0) -> #N/A | J4: =H4+I4 -> #N/A | K4: 2000002627 | L4: 45751 | M4: Transportation Inbound charges-Aug24
A5: KR | B5: 1900008119 | C5: 45702 | D5: 6779IV124000236 | E5: USD | F5: -236 | G5: USD | H5: -236 | I5: =_xlfn.XLOOKUP(D5,'Ascendus data'!$R:$R,'Ascendus data'!$T:$T,,0) -> #N/A | J5: =H5+I5 -> #N/A | K5: 2000002627 | L5: 45751 | M5: CY Destuff Charges-Aug24
A6: KR | B6: 1900008120 | C6: 45702 | D6: 6779IV124000238 | E6: USD | F6: -23.6 | G6: USD | H6: -23.6 | I6: =_xlfn.XLOOKUP(D6,'Ascendus data'!$R:$R,'Ascendus data'!$T:$T,,0) -> #N/A | J6: =H6+I6 -> #N/A | K6: 2000002627 | L6: 45751 | M6: CY Movement Charges-Aug24
A7: KR | B7: 1900008121 | C7: 45702 | D7: 6779IV124000240 | E7: USD | F7: -165.16 | G7: USD | H7: -165.16 | I7: =_xlfn.XLOOKUP(D7,'Ascendus data'!$R:$R,'Ascendus data'!$T:$T,,0) -> #N/A | J7: =H7+I7 -> #N/A | K7: 2000002627 | L7: 45751 | M7: VAS Activity Charges-Aug24
A8: KR | B8: 1900008122 | C8: 45702 | D8: 6779IV124000241 | E8: USD | F8: -220 | G8: USD | H8: -220 | I8: =_xlfn.XLOOKUP(D8,'Ascendus data'!$R:$R,'Ascendus data'!$T:$T,,0) -> 220 | J8: =H8+I8 -> 0 | K8: 2000002627 | L8: 45751 | M8: Scanning Charges-Aug24
A9: KR | B9: 1900008123 | C9: 45702 | D9: 6779IV124000243 | E9: USD | F9: -519.2 | G9: USD | H9: -519.2 | I9: =_xlfn.XLOOKUP(D9,'Ascendus data'!$R:$R,'Ascendus data'!$T:$T,,0) -> 519.2 | J9: =H9+I9 -> 0 | K9: 2000002627 | L9: 45751 | M9: CY Destuff Charges-Sep24
A10: KR | B10: 1900008124 | C10: 45702 | D10: 6779IV124000256 | E10: USD | F10: -135 | G10: USD | H10: -135 | I10: =_xlfn.XLOOKUP(D10,'Ascendus data'!$R:$R,'Ascendus data'!$T:$T,,0) -> 135 | J10: =H10+I10 -> 0 | K10: 2000002627 | L10: 45751 | M10: Scanning Charges-Oct24
A11: KR | B11: 1900008125 | C11: 45702 | D11: 6779IV124000258 | E11: USD | F11: -118 | G11: USD | H11: -118 | I11: =_xlfn.XLOOKUP(D11,'Ascendus data'!$R:$R,'Ascendus data'!$T:$T,,0) -> 118 | J11: =H11+I11 -> 0 | K11: 2000002627 | L11: 45751 | M11: CY Destuff Charges-Nov24
A12: KR | B12: 1900008126 | C12: 45702 | D12: 6779IV124000260 | E12: USD | F12: -761.12 | G12: USD | H12: -761.12 | I12: =_xlfn.XLOOKUP(D12,'Ascendus data'!$R:$R,'Ascendus data'!$T:$T,,0) -> 761.12 | J12: =H12+I12 -> 0 | K12: 2000002627 | L12: 45751 | M12: Inbound Handling Charges-Nov24
A13: KR | B13: 1900008127 | C13: 45702 | D13: 6779IV124000261 | E13: USD | F13: -23.6 | G13: USD | H13: -23.6 | I13: =_xlfn.XLOOKUP(D13,'Ascendus data'!$R:$R,'Ascendus data'!$T:$T,,0) -> 23.6 | J13: =H13+I13 -> 0 | K13: 2000002627 | L13: 45751 | M13: CY Movement Charges-Nov24
... A54: KG | B54: 1700001171 | C54: 45729 | D54: ASCEN20250102 | E54: USD | F54: 16009 | G54: USD | H54: 16009 | I54: =_xlfn.XLOOKUP(D54,'Ascendus data'!$R:$R,'Ascendus data'!$T:$T,,0) -> #N/A | J54: =H54+I54 -> #N/A | K54: 2000002627 | L54: 45751 | M54: CN against detention-Aug24-Dec24
A55: ZP | B55: 2000002627 | C55: 45751 | D55: Payment | E55: USD | F55: 123978.28 | G55: USD | H55: 123978.28 | I55: =_xlfn.XLOOKUP(D55,'Ascendus data'!$R:$R,'Ascendus data'!$T:$T,,0) -> #N/A | J55: =H55+I55 -> #N/A
A56: KR | B56: 1900008240 | C56: 45735 | D56: 246779413236 | E56: USD | F56: -36.38 | G56: USD | H56: -36.38 | I56: =_xlfn.XLOOKUP(D56,'Ascendus data'!$M:$M,'Ascendus data'!$T:$T,,0) -> 36.38 | J56: =H56+I56 -> 0 | K56: 2000002693 | L56: 45824 | M56: SSR charges - Feb 25
A57: KR | B57: 1900008241 | C57: 45735 | D57: 246779413237 | E57: USD | F57: -27.3 | G57: USD | H57: -27.3 | I57: =_xlfn.XLOOKUP(D57,'Ascendus data'!$M:$M,'Ascendus data'!$T:$T,,0) -> 27.3 | J57: =H57+I57 -> 0 | K57: 2000002693 | L57: 45824 | M57: SSR charges - Feb 25
A58: KR | B58: 1900008242 | C58: 45735 | D58: 246779413238 | E58: USD | F58: -20.47 | G58: USD | H58: -20.47 | I58: =_xlfn.XLOOKUP(D58,'Ascendus data'!$M:$M,'Ascendus data'!$T:$T,,0) -> 20.47 | J58: =H58+I58 -> 0 | K58: 2000002693 | L58: 45824 | M58: SSR charges - Feb 25
A59: KR | B59: 1900008243 | C59: 45735 | D59: 246779413239 | E59: USD | F59: -68.24 | G59: USD | H59: -68.24 | I59: =_xlfn.XLOOKUP(D59,'Ascendus data'!$M:$M,'Ascendus data'!$T:$T,,0) -> 68.24 | J59: =H59+I59 -> 0 | K59: 2000002693 | L59: 45824 | M59: SSR charges - Feb 25
A60: KR | B60: 1900008244 | C60: 45736 | D60: 246779413638 | E60: USD | F60: -59.41 | G60: USD | H60: -59.41 | I60: =_xlfn.XLOOKUP(D60,'Ascendus data'!$M:$M,'Ascendus data'!$T:$T,,0) -> 59.41 | J60: =H60+I60 -> 0 | K60: 2000002693 | L60: 45824 | M60: Empty Lolo charges - Feb 25
A61: KR | B61: 1900008245 | C61: 45736 | D61: 246779413811 | E61: USD | F61: -200.6 | G61: USD | H61: -200.6 | I61: =_xlfn.XLOOKUP(D61,'Ascendus data'!$M:$M,'Ascendus data'!$T:$T,,0) -> 200.6 | J61: =H61+I61 -> 0 | K61: 2000002693 | L61: 45824 | M61: Scanning charges - Feb 25
A62: KR | B62: 1900008246 | C62: 45736 | D62: 246779414481 | E62: USD | F62: -42.48 | G62: USD | H62: -42.48 | I62: =_xlfn.XLOOKUP(D62,'Ascendus data'!$M:$M,'Ascendus data'!$T:$T,,0) -> 42.48 | J62: =H62+I62 -> 0 | K62: 2000002693 | L62: 45824 | M62: Handling charges- Feb 25
A63: KR | B63: 1900008247 | C63: 45736 | D63: 246779414482 | E63: USD | F63: -177 | G63: USD | H63: -177 | I63: =_xlfn.XLOOKUP(D63,'Ascendus data'!$M:$M,'Ascendus data'!$T:$T,,0) -> 177 | J63: =H63+I63 -> 0 | K63: 2000002693 | L63: 45824 | M63: Inbound Handling charges- Feb 25
A64: KR | B64: 1900008248 | C64: 45736 | D64: 246779414483 | E64: USD | F64: -23.6 | G64: USD | H64: -23.6 | I64: =_xlfn.XLOOKUP(D64,'Ascendus data'!$M:$M,'Ascendus data'!$T:$T,,0) -> 23.6 | J64: =H64+I64 -> 0 | K64: 2000002693 | L64: 45824 | M64: CY- Movement charges - Feb 25
A65: KR | B65: 1900008249 | C65: 45736 | D65: 246779414484 | E65: USD | F65: -173.48 | G65: USD | H65: -173.48 | I65: =_xlfn.XLOOKUP(D65,'Ascendus data'!$M:$M,'Ascendus data'!$T:$T,,0) -> 173.48 | J65: =H65+I65 -> 0 | K65: 2000002693 | L65: 45824 | M65: Transportation charges - Feb 25
A66: KR | B66: 1900008250 | C66: 45736 | D66: 246779414755 | E66: USD | F66: -419.36 | G66: USD | H66: -419.36 | I66: =_xlfn.XLOOKUP(D66,'Ascendus data'!$M:$M,'Ascendus data'!$T:$T,,0) -> 419.36 | J66: =H66+I66 -> 0 | K66: 2000002693 | L66: 45824 | M66: Outbound Handling charges- Feb 25
A67: KR | B67: 1900008251 | C67: 45736 | D67: 246779414756 | E67: USD | F67: -81.21 | G67: USD | H67: -81.21 | I67: =_xlfn.XLOOKUP(D67,'Ascendus data'!$M:$M,'Ascendus data'!$T:$T,,0) -> 81.21 | J67: =H67+I67 -> 0 | K67: 2000002693 | L67: 45824 | M67: Handling charges- Feb 25
... A78: KR | B78: 1900008262 | C78: 45736 | D78: 256779417737 | E78: USD | F78: -950.61 | G78: USD | H78: -950.61 | I78: =_xlfn.XLOOKUP(D78,'Ascendus data'!$M:$M,'Ascendus data'!$T:$T,,0) -> 950.61 | J78: =H78+I78 -> 0 | K78: 2000002693 | L78: 45824 | M78: Outbound Handling charges- Feb 25
A79: ZP | B79: 2000002693 | C79: 45824 | D79: Payment | E79: USD | F79: 19172.47 | G79: USD | H79: 19172.47 | I79: =_xlfn.XLOOKUP(D79,'Ascendus data'!$R:$R,'Ascendus data'!$T:$T,,0) -> #N/A | J79: =H79+I79 -> #N/A | K79: 2000002693 | L79: 45824
A80: KR | B80: 1900008270 | C80: 45763 | D80: 256779411925 | E80: USD | F80: -3.48 | G80: USD | H80: -3.48 | I80: =_xlfn.XLOOKUP(D80,'Ascendus data'!$M:$M,'Ascendus data'!$T:$T,,0) -> 3.48 | J80: =H80+I80 -> 0 | K80: 2000002708 | L80: 45833 | M80: HPCU2278439-Port SSR Shifting Mar 2025.
A81: KR | B81: 1900008271 | C81: 45763 | D81: 256779411926 | E81: USD | F81: -13.94 | G81: USD | H81: -13.94 | I81: =_xlfn.XLOOKUP(D81,'Ascendus data'!$M:$M,'Ascendus data'!$T:$T,,0) -> 13.94 | J81: =H81+I81 -> 0 | K81: 2000002708 | L81: 45833 | M81: TCNU6507209-Port SSR Shifting Mar 2025.
A82: KR | B82: 1900008272 | C82: 45763 | D82: 256779412079 | E82: USD | F82: -116.73 | G82: USD | H82: -116.73 | I82: =_xlfn.XLOOKUP(D82,'Ascendus data'!$M:$M,'Ascendus data'!$T:$T,,0) -> 116.73 | J82: =H82+I82 -> 0 | K82: 2000002708 | L82: 45833 | M82: VAS Activity
A83: KR | B83: 1900008273 | C83: 45750 | D83: 256779410026 | E83: USD | F83: -45.68 | G83: USD | H83: -45.68 | I83: =_xlfn.XLOOKUP(D83,'Ascendus data'!$M:$M,'Ascendus data'!$T:$T,,0) -> 45.68 | J83: =H83+I83 -> 0 | K83: 2000002708 | L83: 45833 | M83: Loose unloading charges Mar 2025
A84: KR | B84: 1900008274 | C84: 45750 | D84: 256779410027 | E84: USD | F84: -56.64 | G84: USD | H84: -56.64 | I84: =_xlfn.XLOOKUP(D84,'Ascendus data'!$M:$M,'Ascendus data'!$T:$T,,0) -> 56.64 | J84: =H84+I84 -> 0 | K84: 2000002708 | L84: 45833 | M84: LCL charges - March 2025
A85: KR | B85: 1900008275 | C85: 45750 | D85: 256779410028 | E85: USD | F85: -455.62 | G85: USD | H85: -455.62 | I85: =_xlfn.XLOOKUP(D85,'Ascendus data'!$M:$M,'Ascendus data'!$T:$T,,0) -> 455.62 | J85: =H85+I85 -> 0 | K85: 2000002708 | L85: 45833 | M85: Transportation Inbound charges- Mar 25
A86: KR | B86: 1900008276 | C86: 45750 | D86: 256779410029 | E86: USD | F86: -210 | G86: USD | H86: -210 | I86: =_xlfn.XLOOKUP(D86,'Ascendus data'!$M:$M,'Ascendus data'!$T:$T,,0) -> 210 | J86: =H86+I86 -> 0 | K86: 2000002708 | L86: 45833 | M86: Outbound charges- Mar 25
A87: KR | B87: 1900008277 | C87: 45750 | D87: 256779410030 | E87: USD | F87: -70.8 | G87: USD | H87: -70.8 | I87: =_xlfn.XLOOKUP(D87,'Ascendus data'!$M:$M,'Ascendus data'!$T:$T,,0) -> 70.8 | J87: =H87+I87 -> 0 | K87: 2000002708 | L87: 45833 | M87: CY - Destuff charges - March 2025
A88: KR | B88: 1900008278 | C88: 45750 | D88: 256779410097 | E88: USD | F88: -191.18 | G88: USD | H88: -191.18 | I88: =_xlfn.XLOOKUP(D88,'Ascendus data'!$M:$M,'Ascendus data'!$T:$T,,0) -> 191.18 | J88: =H88+I88 -> 0 | K88: 2000002708 | L88: 45833 | M88: Inbound Handling charges- Mar 25
A89: KR | B89: 1900008279 | C89: 45750 | D89: 256779410025 | E89: USD | F89: -407.28 | G89: USD | H89: -407.28 | I89: =_xlfn.XLOOKUP(D89,'Ascendus data'!$M:$M,'Ascendus data'!$T:$T,,0) -> 407.28 | J89: =H89+I89 -> 0 | K89: 2000002708 | L89: 45833 | M89: Inbound Handling charges- Mar 25
A90: KR | B90: 1900008280 | C90: 45750 | D90: 256779410180 | E90: USD | F90: -68.15 | G90: USD | H90: -68.15 | I90: =_xlfn.XLOOKUP(D90,'Ascendus data'!$M:$M,'Ascendus data'!$T:$T,,0) -> 68.15 | J90: =H90+I90 -> 0 | K90: 2000002708 | L90: 45833 | M90: VAS Activity Charges-Mar.25
...

Sheet Pivot - customer data
C4: Values | D4: Document Type
C5: Sum of Amount in doc. curr. | F5: Sum of Amount in local currency
A6: Months | B6: Document Date | C6: KG | D6: KR | E6: RE | F6: KG | G6: KR | H6: RE
A7: Feb | D7: -21923.99 | E7: -118063.29 | G7: -21923.99 | H7: -118063.29
A8: Mar | C8: 16009 | D8: -2280.14 | F8: 16009 | G8: -2280.14
A9: Apr | D9: -10761.47 | E9: -33703.42 | G9: -10761.47 | H9: -33703.42
A10: May | D10: -5481.61 | E10: -6237.23 | G10: -5481.61 | H10: -6237.23
A11: Jun | D11: -4841.19 | E11: -12657.66 | G11: -4841.19 | H11: -12657.66
A12: Jul | D12: -4378.56 | E12: -14259.89 | G12: -4378.56 | H12: -14259.89
A13: Aug | D13: -9590.65 | E13: -14009.32 | G13: -9590.65 | H13: -14009.32
A14: Sep | D14: -9538.38 | E14: -12299.39 | G14: -9538.38 | H14: -12299.39
A15: Oct | D15: -13501.32 | E15: -14289.84 | G15: -13501.32 | H15: -14289.84
A16: Nov | D16: -10743.75 | G16: -10743.75
B20: Sum of Amount in doc. curr.
A21: Months | B21: KG | C21: KR | D21: RE
A22: Feb | C22: -21923.99 | D22: -118063.29
A23: Mar | B23: 16009 | C23: -2280.14
A24: Apr | C24: -10761.47 | D24: -33703.42
A25: May | C25: -5481.61 | D25: -6237.23
A26: Jun | C26: -4841.19 | D26: -12657.66
A27: Jul | C27: -4378.56 | D27: -14259.89
A28: Aug | C28: -9590.65 | D28: -14009.32
A29: Sep | C29: -9538.38 | D29: -12299.39
A30: Oct | C30: -13501.32 | D30: -14289.84
A31: Nov | C31: -10743.75
A32: Total | B32: =SUM(B22:B31) -> 16009 | C32: =SUM(C22:C31) -> -93041.06 | D32: =SUM(D22:D31) -> -225520.04

Sheet Asendus Data
A1: Cleared/Open Items Symbol | B1: Document Number | C1: Invoice | D1: Document Type | E1: Document Date | F1: Special G/L Ind. | G1: Net Due Date Symbol | H1: Amount in Local Currency | I1: Local Currency | J1: Amount in USD | K1: Clearing Document | L1: Text | M1: Customer | N1: Posting Date | O1: Tax Code | P1: Processor | Q1: Contract Number | R1: G/L Account | S1: Vlookup
B2: 1400000999 | C2: #N/A | D2: DZ | E2: 45891 | H2: -10774245 | I2: INR | J2: #N/A | M2: 100222426 | N2: 45891 | R2: 212100
B3: 1800012797 | C3: 256779417478 | D3: DR | E3: 45920 | H3: 87706.86 | I3: INR | J3: 1002.2 | L3: BOE handling charges | M3: 100222426 | N3: 45920 | O3: O0 | R3: 212100
B4: 1600002320 | C4: 256779421875 | D4: DG | E4: 45923 | H4: -11420.71 | I4: INR | J4: -131.74 | L4: Credit Note Raised against INV_246779413054 | M4: 100222426 | N4: 45923 | O4: O0 | R4: 212100
B5: 1800013204 | C5: 256779417820 | D5: DR | E5: 45924 | H5: 11420.71 | I5: INR | J5: 131.74 | L5: Port SSR Charges - Shifting for Aug to Dec,24. Exc | M5: 100222426 | N5: 45924 | O5: O0 | R5: 212100
B6: 1800014423 | C6: 256779418940 | D6: DR | E6: 45966 | H6: 637020.46 | I6: INR | J6: 7238.59 | L6: Storage -WH 09- 16-31 OCT 25 | M6: 100222426 | N6: 45966 | O6: O0 | R6: 212100
B7: 1800014424 | C7: 256779418941 | D7: DR | E7: 45966 | H7: 674927.92 | I7: INR | J7: 7669.34 | L7: Storage -WH 09- 16-31 OCT 25 | M7: 100222426 | N7: 45966 | O7: O0 | R7: 212100
B8: 1800014902 | C8: 256779419451 | D8: DR | E8: 45981 | H8: 9074.03 | I8: INR | J8: 103.11 | L8: VAS-Nov 1-15, 2025 | M8: 100222426 | N8: 45981 | O8: O0 | R8: 212100
B9: 1800014910 | C9: 256779419459 | D9: DR | E9: 45981 | H9: 1189.81 | I9: INR | J9: 13.52 | L9: Weighment-Nov 1-15, 2025 | M9: 100222426 | N9: 45981 | O9: O0 | R9: 212100
B10: 1800015173 | C10: 256779419674 | D10: DR | E10: 45994 | H10: 790993.26 | I10: INR | J10: 8917.61 | L10: Storage -WH 09- 1-30 Nov 25 | M10: 100222426 | N10: 45994 | O10: O0 | R10: 212100
B11: 1800015174 | C11: 256779419675 | D11: DR | E11: 45994 | H11: 668445.14 | I11: INR | J11: 7536.01 | L11: Storage -WH 09- 1-30 Nov 25 | M11: 100222426 | N11: 45994 | O11: O0 | R11: 212100
B12: 1800015716 | C12: 256779450072 | D12: DR | E12: 46024 | H12: 10707.69 | I12: INR | J12: 118 | L12: Scanning Chgs - 16 - 30 Nov 25 | M12: 100222426 | N12: 46024 | O12: O0 | R12: 212100
B13: 1800015380 | C13: 256779419829 | D13: DR | E13: 45999 | H13: 4957.45 | I13: INR | J13: 55.89 | L13: Bond Stamp Paper Chgs Nov 25 | M13: 100222426 | N13: 45999 | O13: O0 | R13: 212100
B14: 1800015390 | C14: 256779419839 | D14: DR | E14: 45999 | H14: 726007.1 | I14: INR | J14: 3122.18 | L14: Transportation In Chgs - 16 - 30 NOV 25 | M14: 100222426 | N14: 45999 | O14: O0 | R14: 212100
... B137: 1800016811 | C137: 256779450747 | D137: DR | E137: 46034 | H137: 4260.39 | I137: INR | J137: 46.95 | L137: Weighment -NOV 25,16-30 | M137: 100222426 | N137: 46034 | O137: O0 | R137: 212100

Sheet Ascendus Pivot
C2: Sum of Document Currency Value | F2: Sum of Company Code Currency Value
A3: Years | B3: Document Date | C3: DG-Credit Note | D3: DR-Sales | E3: DZ-Payment | F3: DG-Credit Note | G3: DR-Sales | H3: DZ-Payment
A4: 2025 | B4: Feb
A5: 2025 | B5: Mar | D5: 63058.48 | G5: 5466619.1
A6: 2025 | B6: Apr | D6: 125751.78 | G6: 10930574
A7: 2025 | B7: May | C7: -473.94 | D7: 11457.67 | F7: -41086.47 | G7: 985172.85
A8: 2025 | B8: Jun | D8: 17599.15 | E8: -19376.22 | G8: 1504565.1 | H8: -1656776.5
A9: 2025 | B9: Jul | D9: 19661.85 | E9: -19783.53 | G9: 1690932.3 | H9: -1719620.4
A10: 2025 | B10: Aug | D10: 29638.91 | E10: -158563.42 | G10: 2549839 | H10: -13751759
A11: 2025 | B11: Sep | C11: -1082.33 | D11: 24505.42 | E11: -6725.14 | F11: -94610.97 | G11: 2144467 | H11: -588546.12
A12: 2025 | B12: Oct | C12: -3981.8 | D12: 25315.59 | E12: -38217.41 | F12: -351158.01 | G12: 2233401.4 | H12: -3349729
A13: 2025 | B13: Nov | C13: -171.1 | D13: 25800.22 | E13: -22948.48 | F13: -15057.37 | G13: 2270506.8 | H13: -2019544
A14: 2025 | B14: Dec | D14: 29373.84 | E14: -31.91 | G14: 2605463.7 | H14: -2830.42
A15: 2026 | B15: Jan | D15: 32187.51 | E15: -37482.68 | G15: 2920817.9 | H15: -3233319.9
A16: 2026 | B16: Feb | D16: 86.76 | G16: 7837.48
A17: Total | C17: =SUM(C4:C16) -> -5709.17 | D17: =SUM(D4:D16) -> 404437.18 | E17: =SUM(E4:E16) -> -303128.79 | F17: =SUM(F4:F16) -> -501912.82 | G17: =SUM(G5:G16) -> 35310196 | H17: =SUM(H5:H16) -> -26322126
