Workbook

Sheet Summary
A1: Reconciliation of Ledger as on 31st January 2026
A2: Particulars | B2: Amount
A3: Balance as per Scope Chemicals Pvt Ltd | B3: =-'Customer Data'!E390 -> 1489274.5
A4: Add: TDS to be booked in Ascendus books | B4: =TDS!L2 -> 961633.58
A5: Add: Invoices & CN not recorded in customer books | B5: ='Invoice & CN not in Customers'!H1 -> 2304711.4
A6: Less: Difference of invoice value in both Books | B6: =-'Difference in Invoice Value'!L2 -> -72025.131
A7: Less: Knock off entries difference | B7: ='Foreign Exchnage Gain loss'!H31 -> -1093.08
A8: Derived balance | B8: =SUM(B3:B7) -> 4682501.3
A9: Balance as per Ascent | B9: ='Ascendus Data'!J479 -> 4683369.6
A11: Difference due to Foreign Exchange gain/loss | B11: =B8-B9-B10 -> -868.3137

Sheet TDS
L2: =SUBTOTAL(9,L4:L264) -> 961633.58
A3: Document Number | B3: Document Type | C3: Document Date | D3: Reference | E3: Document Currency Key | F3: Document Currency Value | G3: Company Code Currency Key | H3: Company Code Currency Value | I3: Debit | J3: Credit | K3: Net Amount | L3: TDS | M3: Rate | N3: Text
A4: 1800012476 | B4: DR | C4: 45906 | D4: 256779417084 | E4: USD | F4: 8832.14 | G4: INR | H4: 772938.81 | I4: 0 | J4: 695663.66 | K4: 695663.66 | L4: 77275.149 | M4: 0.099975765 | N4: Unit-Storage-1-31 Aug 25
A5: 1800013274 | B5: DR | C5: 45936 | D5: 256779418010 | E5: USD | F5: 8566.5 | G5: INR | H5: 755486.23 | I5: 0 | J5: 679906.74 | K5: 679906.74 | L5: 75579.489 | M5: 0.10004086 | N5: Unit Storage - 1-30 Sept 2025
A6: 1800000442 | B6: DR | C6: 45719 | D6: 246779410404 | E6: USD | F6: 7394.09 | G6: INR | H6: 641002.98 | I6: 0 | J6: 580687 | K6: 580687 | L6: 60315.98 | M6: 0.094096255 | N6: Storage for the month of Sept 2024
A7: 1800014537 | B7: DR | C7: 45966 | D7: 256779418869 | E7: USD | F7: 6685.47 | G7: INR | H7: 588344.02 | I7: 0 | J7: 529469.76 | K7: 529469.76 | L7: 58874.264 | M7: 0.10006775 | N7: Unit Storage - 1-31 Oct 2025
A8: 1800011658 | B8: DR | C8: 45877 | D8: 256779416088 | E8: USD | F8: 5977.6 | G8: INR | H8: 514253.65 | I8: 0 | J8: 462828 | K8: 462828 | L8: 51425.65 | M8: 0.10000055 | N8: Unit Storage - 1-31 July 25
A9: 1800000417 | B9: DR | C9: 45719 | D9: 246779410379 | E9: USD | F9: 5862.04 | G9: INR | H9: 508187.63 | I9: 0 | J9: 460370 | K9: 460370 | L9: 47817.63 | M9: 0.094094439 | N9: Storage Charges for the month of August, 2024
A10: 1800007226 | B10: DR | C10: 45763 | D10: 256779412117 | E10: USD | F10: 5415.85 | G10: INR | H10: 470755.54 | I10: 0 | J10: 417286 | K10: 417286 | L10: 53469.54 | M10: 0.11358239 | N10: Storage Charges Mar, 25
A11: 1800005904 | B11: DR | C11: 45751 | D11: 256779410795 | E11: USD | F11: 5005.59 | G11: INR | H11: 435094.99 | I11: 0 | J11: 384955 | K11: 384955 | L11: 50139.99 | M11: 0.11523918 | N11: Storage Charges Feb, 25
A12: 1800000956 | B12: DR | C12: 45722 | D12: 246779410896 | E12: USD | F12: 4556.4 | G12: INR | H12: 395000.06 | I12: 0 | J12: 357094 | K12: 357094 | L12: 37906.06 | M12: 0.095964694 | N12: Storage for the month of Dec 2024
A13: 1800009478 | B13: DR | C13: 45815 | D13: 256779414242 | E13: USD | F13: 4585.18 | G13: INR | H13: 391990.61 | I13: 0 | J13: 352792 | K13: 352792 | L13: 39198.61 | M13: 0.099998849 | N13: Unit storage -1-31 May 25
A14: 1800000466 | B14: DR | C14: 45719 | D14: 246779410428 | E14: USD | F14: 4332.22 | G14: INR | H14: 375565.61 | I14: 0 | J14: 340227 | K14: 340227 | L14: 35338.61 | M14: 0.094094371 | N14: Storage for the month of Oct 2024
A15: 1800005921 | B15: DR | C15: 45751 | D15: 256779410812 | E15: USD | F15: 4311.37 | G15: INR | H15: 374752.13 | I15: 0 | J15: 331566 | K15: 331566 | L15: 43186.13 | M15: 0.11523918 | N15: Storage Charges Jan, 25
... A137: 1800004273 | B137: DR | C137: 45736 | D137: 246779414141 | E137: USD | F137: 55 | G137: INR | H137: 4768.02 | I137: 0 | J137: 4652 | K137: 4652 | L137: 116.02 | M137: 0.024332952 | N137: Inbound Handling charges for Sep 2024
A138: 1800010215 | B138: DR | C138: 45842 | D138: 256779414975 | E138: USD | F138: 54.05 | G138: INR | H138: 4648.34 | I138: 0 | J138: 4562.3355 | K138: 4562.3355 | L138: 86.0045 | M138: 0.018502196
A139: 1800012684 | B139: DR | C139: 45904 | D139: 256779417324 | E139: USD | F139: 49.35 | G139: INR | H139: 4318.83 | I139: 0 | J139: 4231.3179 | K139: 4231.3179 | L139: 87.5121 | M139: 0.020262918 | N139: Outbound chgs - 16 - 31 Aug 25
A140: 1800008641 | B140: DR | C140: 45798 | D140: 256779413405 | E140: USD | F140: 47 | G140: INR | H140: 4041.23 | I140: 0 | J140: 3960 | K140: 3960 | L140: 81.23 | M140: 0.020100316 | N140: InKPI-CODC-1-15 May 25-BOE9862672
A141: 1800003760 | B141: DR | C141: 45736 | D141: 246779413627 | E141: USD | F141: 42.3 | G141: INR | H141: 3667.04 | I141: 0 | J141: 3578 | K141: 3578 | L141: 89.04 | M141: 0.024281164 | N141: Outbound Handling charges for Jan 2025
A142: 1800003870 | B142: DR | C142: 45736 | D142: 246779413738 | E142: USD | F142: 42.3 | G142: INR | H142: 3667.04 | I142: 0 | J142: 3603 | K142: 3603 | L142: 64.04 | M142: 0.017463676 | N142: Outbound Handling charges for Jan 2025
A143: 1800000750 | B143: DR | C143: 45720 | D143: 246779410690 | E143: USD | F143: 42.3 | G143: INR | H143: 3667.04 | I143: 0 | J143: 3622 | K143: 3622 | L143: 45.04 | M143: 0.012282386 | N143: Outbound Handling for Oct 2024
A144: 1800000815 | B144: DR | C144: 45720 | D144: 246779410755 | E144: USD | F144: 42.3 | G144: INR | H144: 3667.04 | I144: 0 | J144: 3594 | K144: 3594 | L144: 73.04 | M144: 0.019917972 | N144: Outbound Handling for Nov 2024
A145: 1800008360 | B145: DR | C145: 45787 | D145: 256779413243 | E145: USD | F145: 42.53 | G145: INR | H145: 3656.89 | I145: 0 | J145: 3623 | K145: 3623 | L145: 33.89 | M145: 0.0092674376 | N145: VAS - 16-30 April 25, Ex.Rate-85.05
A146: 1800012275 | B146: DR | C146: 45904 | D146: 256779416911 | E146: USD | F146: 40.85 | G146: INR | H146: 3574.96 | I146: 0 | J146: 3487.4461 | K146: 3487.4461 | L146: 87.5139 | M146: 0.024479686 | N146: CODC LCL Chgs - 16-31 Aug 25
A147: 1800000818 | B147: DR | C147: 45720 | D147: 246779410758 | E147: USD | F147: 37.6 | G147: INR | H147: 3259.59 | I147: 0 | J147: 3219 | K147: 3219 | L147: 40.59 | M147: 0.012452486 | N147: Outbound Handling for Nov 2024
A148: 1800000669 | B148: DR | C148: 45719 | D148: 246779410609 | E148: USD | F148: 37.6 | G148: INR | H148: 3259.59 | I148: 0 | J148: 3203 | K148: 3203 | L148: 56.59 | M148: 0.017361079 | N148: Outbound Handling for Sep 2024
A149: 1800014641 | B149: DR | C149: 45966 | D149: 256779418906 | E149: USD | F149: 35.25 | G149: INR | H149: 3102.12 | I149: 0 | J149: 3014.1161 | K149: 3014.1161 | L149: 88.0039 | M149: 0.028368954 | N149: CODC Out chgs -16-31 Oct 25
A150: 1800005309 | B150: DR | C150: 45750 | D150: 256779410201 | E150: USD | F150: 34.48 | G150: INR | H150: 2997.06 | I150: 0 | J150: 2937 | K150: 2937 | L150: 60.06 | M150: 0.020039639 | N150: VAS Activity -1 -15 Mar 25, Ex Rate. 87.01
... A156: 1800010118 | B156: DR | C156: 45842 | D156: 256779414878 | E156: USD | F156: 31.73 | G156: INR | H156: 2728.8 | I156: 0 | J156: 2642.8006 | K156: 2642.8006 | L156: 85.9994 | M156: 0.031515465 | N156: Inbound chgs - 16 - 30 JUN 25
A157: 1800010208 | B157: DR | C157: 45845 | D157: 256779414968 | E157: USD | F157: 31.58 | G157: INR | H157: 2715.9 | I157: 0 | J157: 2629.9005 | K157: 2629.9005 | L157: 85.9995 | M157: 0.031665194
A158: 1800011011 | B158: DR | C158: 45857 | D158: 256779415771 | E158: USD | F158: 30.76 | G158: INR | H158: 2645.38 | I158: 0 | J158: 2559.3799 | K158: 2559.3799 | L158: 86.0001 | M158: 0.032509545 | N158: VAS - 1-15 July 25
A159: 1800001259 | B159: DR | C159: 45722 | D159: 246779411128 | E159: USD | F159: 28.2 | G159: INR | H159: 2444.69 | I159: 0 | J159: 2406 | K159: 2406 | L159: 38.69 | M159: 0.015826137 | N159: Inbound Handling charges for Oct 2024
A160: 1800004449 | B160: DR | C160: 45737 | D160: 246779414317 | E160: USD | F160: 25 | G160: INR | H160: 2167.28 | I160: 0 | J160: 1907 | K160: 1907 | L160: 260.28 | M160: 0.12009523 | N160: Inbound Handling charges for Oct 2024
A161: 1800001316 | B161: DR | C161: 45722 | D161: 246779411185 | E161: USD | F161: 23.5 | G161: INR | H161: 2037.24 | I161: 0 | J161: 2004 | K161: 2004 | L161: 33.24 | M161: 0.016316192 | N161: Inbound Handling charges for Nov 2024
A162: 1800001317 | B162: DR | C162: 45722 | D162: 246779411186 | E162: USD | F162: 23.5 | G162: INR | H162: 2037.24 | I162: 0 | J162: 2004 | K162: 2004 | L162: 33.24 | M162: 0.016316192 | N162: Inbound Handling charges for Nov 2024
A163: 1800001318 | B163: DR | C163: 45722 | D163: 246779411187 | E163: USD | F163: 23.5 | G163: INR | H163: 2037.24 | I163: 0 | J163: 2004 | K163: 2004 | L163: 33.24 | M163: 0.016316192 | N163: Inbound Handling charges for Nov 2024
A164: 1800001319 | B164: DR | C164: 45722 | D164: 246779411188 | E164: USD | F164: 23.5 | G164: INR | H164: 2037.24 | I164: 0 | J164: 2004 | K164: 2004 | L164: 33.24 | M164: 0.016316192 | N164: Inbound Handling charges for Nov 2024
A165: 1800001320 | B165: DR | C165: 45722 | D165: 246779411189 | E165: USD | F165: 23.5 | G165: INR | H165: 2037.24 | I165: 0 | J165: 2004 | K165: 2004 | L165: 33.24 | M165: 0.016316192 | N165: Inbound Handling charges for Nov 2024
A166: 1800000545 | B166: DR | C166: 45719 | D166: 246779410495 | E166: USD | F166: 23.5 | G166: INR | H166: 2037.24 | I166: 0 | J166: 2009 | K166: 2009 | L166: 28.24 | M166: 0.013861892 | N166: Outbound Handling for Aug 2024
A167: 1800000552 | B167: DR | C167: 45719 | D167: 246779410502 | E167: USD | F167: 23.5 | G167: INR | H167: 2037.24 | I167: 0 | J167: 2009 | K167: 2009 | L167: 28.24 | M167: 0.013861892 | N167: Outbound Handling for Aug 2024
...

Sheet Ascendus Data
A2: Document Number | B2: Document Type | C2: Document Date | D2: Entry Date | E2: Document Header Text | F2: Reference | G2: Document Currency Key | H2: Document Currency Value | I2: Company Code Currency Key | J2: Company Code Currency Value | K2: Profit Center | L2: Assignment | M2: Debit | N2: Credit | O2: Net Amount | P2: TDS | Q2: Rate | R2: Text | S2: Clearing Date | T2: Clearing Document | U2: Invoice Reversed in books
A3: 1800012476 | B3: DR | C3: 45906 | D3: 45909 | E3: NA | F3: 256779417084 | G3: USD | H3: 8832.14 | I3: INR | J3: 772938.81 | K3: 6779224500 | L3: NA | M3: {=_xlfn.XLOOKUP(F3,'Customer Data Vlookup'!$L:$L,'Customer Data Vlookup'!$M:$N,,0)} -> 0 | N3: 695663.66 | O3: =N3-M3 -> 695663.66 | P3: =J3-O3 -> 77275.149 | Q3: =P3/J3 -> 0.099975765 | R3: Unit-Storage-1-31 Aug 25
A4: 1800013274 | B4: DR | C4: 45936 | D4: 45937 | E4: NA | F4: 256779418010 | G4: USD | H4: 8566.5 | I4: INR | J4: 755486.23 | K4: 6779224500 | L4: 2110511 | M4: {=_xlfn.XLOOKUP(F4,'Customer Data Vlookup'!$L:$L,'Customer Data Vlookup'!$M:$N,,0)} -> 0 | N4: 679906.74 | O4: =N4-M4 -> 679906.74 | P4: =J4-O4 -> 75579.489 | Q4: =P4/J4 -> 0.10004086 | R4: Unit Storage - 1-30 Sept 2025
A5: 1800016345 | B5: DR | C5: 46028 | D5: 46034 | E5: 2158411 | F5: 256779440235 | G5: USD | H5: 7267.85 | I5: INR | J5: 659507.53 | K5: 6779224500 | L5: NA | M5: {=_xlfn.XLOOKUP(F5,'Customer Data Vlookup'!$L:$L,'Customer Data Vlookup'!$M:$N,,0)} -> #N/A | O5: =N5-M5 -> #N/A | P5: =J5-O5 -> #N/A | Q5: =P5/J5 -> #N/A | R5: Unit Storage - 1-31 DEC 2025
A6: 1800000442 | B6: DR | C6: 45719 | D6: 45719 | E6: NA | F6: 246779410404 | G6: USD | H6: 7394.09 | I6: INR | J6: 641002.98 | K6: 6779224500 | L6: NA | M6: {=_xlfn.XLOOKUP(F6,'Customer Data Vlookup'!$L:$L,'Customer Data Vlookup'!$M:$N,,0)} -> 0 | N6: 580687 | O6: =N6-M6 -> 580687 | P6: =J6-O6 -> 60315.98 | Q6: =P6/J6 -> 0.094096255 | R6: Storage for the month of Sept 2024
A7: 1800015671 | B7: DR | C7: 46024 | D7: 46024 | E7: NA | F7: 256779440004 | G7: USD | H7: 7039.11 | I7: INR | J7: 638750.94 | K7: 6779224500 | L7: 2139799 | M7: {=_xlfn.XLOOKUP(F7,'Customer Data Vlookup'!$L:$L,'Customer Data Vlookup'!$M:$N,,0)} -> #N/A | O7: =N7-M7 -> #N/A | P7: =J7-O7 -> #N/A | Q7: =P7/J7 -> #N/A | R7: Unit Storage - 1-30 Nov 2025
A8: 1800014537 | B8: DR | C8: 45966 | D8: 45967 | E8: NA | F8: 256779418869 | G8: USD | H8: 6685.47 | I8: INR | J8: 588344.02 | K8: 6779224500 | L8: 2123390 | M8: {=_xlfn.XLOOKUP(F8,'Customer Data Vlookup'!$L:$L,'Customer Data Vlookup'!$M:$N,,0)} -> 0 | N8: 529469.76 | O8: =N8-M8 -> 529469.76 | P8: =J8-O8 -> 58874.264 | Q8: =P8/J8 -> 0.10006775 | R8: Unit Storage - 1-31 Oct 2025
A9: 1800011658 | B9: DR | C9: 45877 | D9: 45877 | E9: NA | F9: 256779416088 | G9: USD | H9: 5977.6 | I9: INR | J9: 514253.65 | K9: 6779224500 | L9: NA | M9: {=_xlfn.XLOOKUP(F9,'Customer Data Vlookup'!$L:$L,'Customer Data Vlookup'!$M:$N,,0)} -> 0 | N9: 462828 | O9: =N9-M9 -> 462828 | P9: =J9-O9 -> 51425.65 | Q9: =P9/J9 -> 0.10000055 | R9: Unit Storage - 1-31 July 25
A10: 1800000417 | B10: DR | C10: 45719 | D10: 45719 | E10: NA | F10: 246779410379 | G10: USD | H10: 5862.04 | I10: INR | J10: 508187.63 | K10: 6779224500 | L10: NA | M10: {=_xlfn.XLOOKUP(F10,'Customer Data Vlookup'!$L:$L,'Customer Data Vlookup'!$M:$N,,0)} -> 0 | N10: 460370 | O10: =N10-M10 -> 460370 | P10: =J10-O10 -> 47817.63 | Q10: =P10/J10 -> 0.094094439 | R10: Storage Charges for the month of August, 2024
A11: 1400001985 | B11: DZ | C11: 45972 | D11: 45985 | E11: PUNBR52025110118746241 | G11: INR | H11: 500000 | I11: INR | J11: 500000 | K11: 6779220000 | M11: {=_xlfn.XLOOKUP(F11,'Customer Data Vlookup'!$L:$L,'Customer Data Vlookup'!$M:$N,,0)} -> #N/A | O11: =N11-M11 -> #N/A | P11: =J11-O11 -> #N/A | Q11: =P11/J11 -> #N/A | S11: 45972 | T11: 1400001985 | U11: Yes
A12: 1800007226 | B12: DR | C12: 45763 | D12: 45764 | E12: NA | F12: 256779412117 | G12: USD | H12: 5415.85 | I12: INR | J12: 470755.54 | K12: 6779224500 | L12: NA | M12: {=_xlfn.XLOOKUP(F12,'Customer Data Vlookup'!$L:$L,'Customer Data Vlookup'!$M:$N,,0)} -> 0 | N12: 417286 | O12: =N12-M12 -> 417286 | P12: =J12-O12 -> 53469.54 | Q12: =P12/J12 -> 0.11358239 | R12: Storage Charges Mar, 25
A13: 1800005904 | B13: DR | C13: 45751 | D13: 45752 | E13: NA | F13: 256779410795 | G13: USD | H13: 5005.59 | I13: INR | J13: 435094.99 | L13: NA | M13: {=_xlfn.XLOOKUP(F13,'Customer Data Vlookup'!$L:$L,'Customer Data Vlookup'!$M:$N,,0)} -> 0 | N13: 384955 | O13: =N13-M13 -> 384955 | P13: =J13-O13 -> 50139.99 | Q13: =P13/J13 -> 0.11523918 | R13: Storage Charges Feb, 25
A14: 1800000956 | B14: DR | C14: 45722 | D14: 45722 | E14: NA | F14: 246779410896 | G14: USD | H14: 4556.4 | I14: INR | J14: 395000.06 | K14: 6779224500 | L14: NA | M14: {=_xlfn.XLOOKUP(F14,'Customer Data Vlookup'!$L:$L,'Customer Data Vlookup'!$M:$N,,0)} -> 0 | N14: 357094 | O14: =N14-M14 -> 357094 | P14: =J14-O14 -> 37906.06 | Q14: =P14/J14 -> 0.095964694 | R14: Storage for the month of Dec 2024
A15: 1800009478 | B15: DR | C15: 45815 | D15: 45817 | E15: NA | F15: 256779414242 | G15: USD | H15: 4585.18 | I15: INR | J15: 391990.61 | K15: 6779224500 | L15: NA | M15: {=_xlfn.XLOOKUP(F15,'Customer Data Vlookup'!$L:$L,'Customer Data Vlookup'!$M:$N,,0)} -> 0 | N15: 352792 | O15: =N15-M15 -> 352792 | P15: =J15-O15 -> 39198.61 | Q15: =P15/J15 -> 0.099998849 | R15: Unit storage -1-31 May 25
A16: 1800000466 | B16: DR | C16: 45719 | D16: 45719 | E16: NA | F16: 246779410428 | G16: USD | H16: 4332.22 | I16: INR | J16: 375565.61 | K16: 6779224500 | L16: NA | M16: {=_xlfn.XLOOKUP(F16,'Customer Data Vlookup'!$L:$L,'Customer Data Vlookup'!$M:$N,,0)} -> 0 | N16: 340227 | O16: =N16-M16 -> 340227 | P16: =J16-O16 -> 35338.61 | Q16: =P16/J16 -> 0.094094371 | R16: Storage for the month of Oct 2024
A17: 1800005921 | B17: DR | C17: 45751 | D17: 45752 | E17: NA | F17: 256779410812 | G17: USD | H17: 4311.37 | I17: INR | J17: 374752.13 | L17: NA | M17: {=_xlfn.XLOOKUP(F17,'Customer Data Vlookup'!$L:$L,'Customer Data Vlookup'!$M:$N,,0)} -> 0 | N17: 331566 | O17: =N17-M17 -> 331566 | P17: =J17-O17 -> 43186.13 | Q17: =P17/J17 -> 0.11523918 | R17: Storage Charges Jan, 25
A18: 1800009135 | B18: DR | C18: 45805 | D18: 45805 | E18: NA | F18: 256779413899 | G18: USD | H18: 4312.12 | I18: INR | J18: 370772.03 | K18: 6779224500 | L18: NA | M18: {=_xlfn.XLOOKUP(F18,'Customer Data Vlookup'!$L:$L,'Customer Data Vlookup'!$M:$N,,0)} -> 0 | N18: 333696 | O18: =N18-M18 -> 333696 | P18: =J18-O18 -> 37076.03 | Q18: =P18/J18 -> 0.099996836 | R18: Storage Chgs - 01 - 31 Apr 25
A19: 1400001901 | B19: DY | C19: 45976 | D19: 45976 | E19: NA | F19: KNOCK OFF ENTRY | G19: USD | H19: 3813.11 | I19: INR | J19: 331442.46 | K19: 6779224500 | M19: {=_xlfn.XLOOKUP(F19,'Customer Data Vlookup'!$L:$L,'Customer Data Vlookup'!$M:$N,,0)} -> #N/A | O19: =N19-M19 -> #N/A | P19: =J19-O19 -> #N/A | Q19: =P19/J19 -> #N/A | S19: 45976 | T19: 1400001901 | U19: Yes
A20: 1800010438 | B20: DR | C20: 45842 | D20: 45847 | E20: NA | F20: 256779415198 | G20: USD | H20: 3330.8 | I20: INR | J20: 286451.03 | K20: 6779224500 | L20: NA | M20: {=_xlfn.XLOOKUP(F20,'Customer Data Vlookup'!$L:$L,'Customer Data Vlookup'!$M:$N,,0)} -> 0 | N20: 257812.81 | O20: =N20-M20 -> 257812.81 | P20: =J20-O20 -> 28638.222 | Q20: =P20/J20 -> 0.099975977 | R20: Unit Storage - 1-30 June 25
A21: 1800000934 | B21: DR | C21: 45722 | D21: 45722 | E21: NA | F21: 246779410874 | G21: USD | H21: 3080 | I21: INR | J21: 267009.08 | K21: 6779224500 | L21: NA | M21: {=_xlfn.XLOOKUP(F21,'Customer Data Vlookup'!$L:$L,'Customer Data Vlookup'!$M:$N,,0)} -> 0 | N21: 241385 | O21: =N21-M21 -> 241385 | P21: =J21-O21 -> 25624.08 | Q21: =P21/J21 -> 0.095967073 | R21: Storage for the month of Nov 2024
A22: 1800010649 | B22: DR | C22: 45854 | D22: 45855 | E22: NA | F22: 256779415409 | G22: USD | H22: 1926.06 | I22: INR | J22: 166972.57 | K22: 6779224500 | L22: NA | M22: {=_xlfn.XLOOKUP(F22,'Customer Data Vlookup'!$L:$L,'Customer Data Vlookup'!$M:$N,,0)} -> #N/A | O22: =N22-M22 -> #N/A | P22: =J22-O22 -> #N/A | Q22: =P22/J22 -> #N/A | R22: Debit note Note raised against CN_256779421363 | S22: 45854 | T22: 1400000288 | U22: Yes
A23: 1800003928 | B23: DR | C23: 45736 | D23: 45736 | E23: NA | F23: 246779413796 | G23: USD | H23: 1926.06 | I23: INR | J23: 166972.57 | K23: 6779224500 | L23: NA | M23: {=_xlfn.XLOOKUP(F23,'Customer Data Vlookup'!$L:$L,'Customer Data Vlookup'!$M:$N,,0)} -> 0 | N23: 163631 | O23: =N23-M23 -> 163631 | P23: =J23-O23 -> 3341.57 | Q23: =P23/J23 -> 0.020012688 | R23: Ground Rent Jan 25
A24: 1400000288 | B24: DY | C24: 45854 | D24: 45855 | E24: NA | G24: USD | H24: 1926.06 | I24: INR | J24: 166972.57 | K24: 6779224500 | M24: {=_xlfn.XLOOKUP(F24,'Customer Data Vlookup'!$L:$L,'Customer Data Vlookup'!$M:$N,,0)} -> #N/A | O24: =N24-M24 -> #N/A | P24: =J24-O24 -> #N/A | Q24: =P24/J24 -> #N/A | S24: 45854 | T24: 1400000288 | U24: Yes
A25: 1800000371 | B25: DR | C25: 45716 | D25: 45716 | E25: NA | F25: 246779410340 | G25: USD | H25: 1863.55 | I25: INR | J25: 160831.19 | K25: 6779224500 | L25: NA | M25: {=_xlfn.XLOOKUP(F25,'Customer Data Vlookup'!$L:$L,'Customer Data Vlookup'!$M:$N,,0)} -> 0 | N25: 144772.57 | O25: =N25-M25 -> 144772.57 | P25: =J25-O25 -> 16058.625 | Q25: =P25/J25 -> 0.099847704 | R25: CY-CY Ground Rent charges for Dec 2024
A26: 1800005064 | B26: DR | C26: 45750 | D26: 45752 | E26: NA | F26: 256779410010 | G26: USD | H26: 1793.99 | I26: INR | J26: 155936.88 | L26: NA | M26: {=_xlfn.XLOOKUP(F26,'Customer Data Vlookup'!$L:$L,'Customer Data Vlookup'!$M:$N,,0)} -> 0 | N26: 140649 | O26: =N26-M26 -> 140649 | P26: =J26-O26 -> 15287.88 | Q26: =P26/J26 -> 0.098038899 | R26: CY Longstanding container Ground Rent charges for | S26: 45976 | T26: 1400001901 | U26: Yes
A27: 1800011863 | B27: DR | C27: 45877 | D27: 45877 | E27: NA | F27: 256779416514 | G27: USD | H27: 1804.03 | I27: INR | J27: 155200.92 | K27: 6779224500 | L27: NA | M27: {=_xlfn.XLOOKUP(F27,'Customer Data Vlookup'!$L:$L,'Customer Data Vlookup'!$M:$N,,0)} -> #N/A | O27: =N27-M27 -> #N/A | P27: =J27-O27 -> #N/A | Q27: =P27/J27 -> #N/A | R27: PORT SSR Chgs July 25
A28: 1800010646 | B28: DR | C28: 45854 | D28: 45855 | E28: NA | F28: 256779415406 | G28: USD | H28: 1793.99 | I28: INR | J28: 154827.9 | K28: 6779224500 | L28: NA | M28: {=_xlfn.XLOOKUP(F28,'Customer Data Vlookup'!$L:$L,'Customer Data Vlookup'!$M:$N,,0)} -> #N/A | O28: =N28-M28 -> #N/A | P28: =J28-O28 -> #N/A | Q28: =P28/J28 -> #N/A | R28: Debit note Note raised against CN_256779421358 | S28: 45854 | T28: 1400000285 | U28: Yes
A29: 1400000285 | B29: DY | C29: 45854 | D29: 45855 | E29: NA | G29: USD | H29: 1793.99 | I29: INR | J29: 154827.9 | K29: 6779224500 | M29: {=_xlfn.XLOOKUP(F29,'Customer Data Vlookup'!$L:$L,'Customer Data Vlookup'!$M:$N,,0)} -> #N/A | O29: =N29-M29 -> #N/A | P29: =J29-O29 -> #N/A | Q29: =P29/J29 -> #N/A | S29: 45854 | T29: 1400000285 | U29: Yes
A30: 1800000379 | B30: DR | C30: 45716 | D30: 45716 | E30: NA | F30: 246779410348 | G30: USD | H30: 1793.99 | I30: INR | J30: 154827.9 | K30: 6779224500 | L30: NA | M30: {=_xlfn.XLOOKUP(F30,'Customer Data Vlookup'!$L:$L,'Customer Data Vlookup'!$M:$N,,0)} -> 0 | N30: 151725 | O30: =N30-M30 -> 151725 | P30: =J30-O30 -> 3102.9 | Q30: =P30/J30 -> 0.020040962 | R30: CY Longstanding container Ground Rent charges for
A31: 1800001954 | B31: DR | C31: 45733 | D31: 45733 | E31: NA | F31: 246779411619 | G31: USD | H31: 1765.65 | I31: INR | J31: 153066.42 | K31: 6779224500 | L31: NA | M31: {=_xlfn.XLOOKUP(F31,'Customer Data Vlookup'!$L:$L,'Customer Data Vlookup'!$M:$N,,0)} -> 0 | N31: 143412 | O31: =N31-M31 -> 143412 | P31: =J31-O31 -> 9654.42 | Q31: =P31/J31 -> 0.063073403 | R31: VAS Activity Charges for the month of September, 2
A32: 1800011041 | B32: DR | C32: 45856 | D32: 45859 | E32: NA | F32: 256779415801 | G32: USD | H32: 1762.2 | I32: INR | J32: 151550.38 | K32: 6779224500 | L32: NA | M32: {=_xlfn.XLOOKUP(F32,'Customer Data Vlookup'!$L:$L,'Customer Data Vlookup'!$M:$N,,0)} -> 0 | N32: 148540.36 | O32: =N32-M32 -> 148540.36 | P32: =J32-O32 -> 3010.0228 | Q32: =P32/J32 -> 0.019861533 | R32: Inbound chgs - 01 - 15 JUL 25
A33: 1800013509 | B33: DR | C33: 45935 | D33: 45940 | E33: NA | F33: 256779418399 | G33: USD | H33: 1432.98 | I33: INR | J33: 126375.61 | K33: 6779224500 | L33: 2110981 | M33: {=_xlfn.XLOOKUP(F33,'Customer Data Vlookup'!$L:$L,'Customer Data Vlookup'!$M:$N,,0)} -> #N/A | O33: =N33-M33 -> #N/A | P33: =J33-O33 -> #N/A | Q33: =P33/J33 -> #N/A | R33: PORT SSR Chgs Sep 25
A34: 1800005328 | B34: DR | C34: 45750 | D34: 45752 | E34: NA | F34: 256779410220 | G34: USD | H34: 1314.12 | I34: INR | J34: 114225.7 | L34: NA | M34: {=_xlfn.XLOOKUP(F34,'Customer Data Vlookup'!$L:$L,'Customer Data Vlookup'!$M:$N,,0)} -> 0 | N34: 114223 | O34: =N34-M34 -> 114223 | P34: =J34-O34 -> 2.7 | Q34: =P34/J34 -> 2.3637413e-05 | R34: CY Longstanding container Ground Rent charges for | S34: 45976 | T34: 1400001901 | U34: Yes
A35: 1800000383 | B35: DR | C35: 45716 | D35: 45716 | E35: NA | F35: 246779410352 | G35: USD | H35: 1314.12 | I35: INR | J35: 113413.37 | K35: 6779224500 | L35: NA | M35: {=_xlfn.XLOOKUP(F35,'Customer Data Vlookup'!$L:$L,'Customer Data Vlookup'!$M:$N,,0)} -> 0 | N35: 102103.26 | O35: =N35-M35 -> 102103.26 | P35: =J35-O35 -> 11310.114 | Q35: =P35/J35 -> 0.099724697 | R35: CY Longstanding container Ground Rent charges for
A36: 1800001031 | B36: DR | C36: 45722 | D36: 45722 | E36: NA | F36: 246779410971 | G36: USD | H36: 1205.2 | I36: INR | J36: 104480.31 | K36: 6779224500 | L36: NA | M36: {=_xlfn.XLOOKUP(F36,'Customer Data Vlookup'!$L:$L,'Customer Data Vlookup'!$M:$N,,0)} -> 0 | N36: 36538 | O36: =N36-M36 -> 36538 | P36: =J36-O36 -> 67942.31 | Q36: =P36/J36 -> 0.65028817 | R36: Inbound Handling charges for Aug 2024
A37: 1800010130 | B37: DR | C37: 45842 | D37: 45847 | E37: NA | F37: 256779414890 | G37: USD | H37: 1180.8 | I37: INR | J37: 101549.59 | K37: 6779224500 | L37: NA | M37: {=_xlfn.XLOOKUP(F37,'Customer Data Vlookup'!$L:$L,'Customer Data Vlookup'!$M:$N,,0)} -> 0 | N37: 91401.512 | O37: =N37-M37 -> 91401.512 | P37: =J37-O37 -> 10148.078 | Q37: =P37/J37 -> 0.099932239 | R37: CY Ground rent Chgs - 01 - 30 June 25
A38: 1400001902 | B38: DY | C38: 45976 | D38: 45976 | E38: NA | F38: KNOCK OFF ENTRY | G38: USD | H38: 1117.66 | I38: INR | J38: 96798.99 | K38: 6779224500 | M38: {=_xlfn.XLOOKUP(F38,'Customer Data Vlookup'!$L:$L,'Customer Data Vlookup'!$M:$N,,0)} -> #N/A | O38: =N38-M38 -> #N/A | P38: =J38-O38 -> #N/A | Q38: =P38/J38 -> #N/A | S38: 45976 | T38: 1400001902 | U38: Yes
A39: 1800012646 | B39: DR | C39: 45904 | D39: 45909 | E39: NA | F39: 256779417286 | G39: USD | H39: 1050.9 | I39: INR | J39: 91968.81 | K39: 6779224500 | L39: NA | M39: {=_xlfn.XLOOKUP(F39,'Customer Data Vlookup'!$L:$L,'Customer Data Vlookup'!$M:$N,,0)} -> 0 | N39: 90131.008 | O39: =N39-M39 -> 90131.008 | P39: =J39-O39 -> 1837.8015 | Q39: =P39/J39 -> 0.019982878 | R39: Inbound chgs - 16 - 31 AUG 25
A40: 1400001112 | B40: DY | C40: 45902 | D40: 45902 | G40: INR | H40: 79944.34 | I40: INR | J40: 78561.62 | K40: 6779224500 | M40: {=_xlfn.XLOOKUP(F40,'Customer Data Vlookup'!$L:$L,'Customer Data Vlookup'!$M:$N,,0)} -> #N/A | O40: =N40-M40 -> #N/A | P40: =J40-O40 -> #N/A | Q40: =P40/J40 -> #N/A | S40: 45902 | T40: 1400001112 | U40: Yes
A41: 1800014013 | B41: DR | C41: 45950 | D41: 45951 | E41: NA | F41: 256779418620 | G41: USD | H41: 830.96 | I41: INR | J41: 73283 | K41: 6779224500 | L41: 2114877 | M41: {=_xlfn.XLOOKUP(F41,'Customer Data Vlookup'!$L:$L,'Customer Data Vlookup'!$M:$N,,0)} -> #N/A | O41: =N41-M41 -> #N/A | P41: =J41-O41 -> #N/A | Q41: =P41/J41 -> #N/A | R41: CY Ground rent Chgs - 01 - 15 Oct 25
...

Sheet Difference in Invoice Value
L2: =SUBTOTAL(9,L4:L78) -> 72025.131
A3: Document Number | B3: Document Type | C3: Document Date | D3: Reference | E3: Document Currency Key | F3: Document Currency Value | G3: Company Code Currency Key | H3: Company Code Currency Value | I3: Debit | J3: Credit | K3: Net Amount | L3: Difference in Invoice Value | M3: Rate | N3: Text
A4: 1800001954 | B4: DR | C4: 45733 | D4: 246779411619 | E4: USD | F4: 1765.65 | G4: INR | H4: 153066.42 | I4: 0 | J4: 143412 | K4: 143412 | L4: 9654.42 | M4: 0.063073403 | N4: VAS Activity Charges for the month of September, 2
A5: 1800001031 | B5: DR | C5: 45722 | D5: 246779410971 | E5: USD | F5: 1205.2 | G5: INR | H5: 104480.31 | I5: 0 | J5: 36538 | K5: 36538 | L5: 67942.31 | M5: 0.65028817 | N5: Inbound Handling charges for Aug 2024
A6: 1800013428 | B6: DR | C6: 45935 | D6: 256779418075 | E6: USD | F6: 582.8 | G6: INR | H6: 51397.58 | I6: 0 | J6: 1972 | K6: 1972 | L6: 49425.58 | M6: 0.96163243 | N6: Outbound chgs - 16 - 30 Sep 25
A7: 1800007792 | B7: DR | C7: 45769 | D7: 256779412683 | E7: USD | F7: 517.64 | G7: INR | H7: 44994.21 | I7: 0 | J7: 43195 | K7: 43195 | L7: 1799.21 | M7: 0.03998759 | N7: Outbound Handling charges for 31 Mar 25
A8: 1800012739 | B8: DR | C8: 45904 | D8: 256779417373 | E8: USD | F8: 456.75 | G8: INR | H8: 39972.17 | I8: 0 | J8: 33482.011 | K8: 33482.011 | L8: 6490.159 | M8: 0.16236694 | N8: Fixed Storage Charges for September 2025
A9: 1800003783 | B9: DR | C9: 45736 | D9: 246779413705 | E9: USD | F9: 237.35 | G9: INR | H9: 20576.17 | I9: 0 | J9: 19429 | K9: 19429 | L9: 1147.17 | M9: 0.055752358 | N9: Ground Rent Feb 16-28
A10: 1800001426 | B10: DR | C10: 45729 | D10: 246779411339 | E10: USD | F10: 220 | G10: INR | H10: 19072.08 | I10: 0 | J10: 17857 | K10: 17857 | L10: 1215.08 | M10: 0.063709884 | N10: Scanning Charges for the month of December, 2024
A11: 1800009524 | B11: DR | C11: 45812 | D11: 256779414288 | E11: USD | F11: 190 | G11: INR | H11: 16243.25 | I11: 0 | J11: 17313 | K11: 17313 | L11: -1069.75 | M11: -0.065858126 | N11: Scanning Chgs - 16 - 31 May 25
A12: 1800007577 | B12: DR | C12: 45769 | D12: 256779412468 | E12: USD | F12: 169.2 | G12: INR | H12: 14707.17 | I12: 0 | J12: 14119 | K12: 14119 | L12: 588.17 | M12: 0.039992058 | N12: Inbound Handling charges for Feb 2025
A13: 1800001380 | B13: DR | C13: 45722 | D13: 246779411249 | E13: USD | F13: 169.2 | G13: INR | H13: 14668.16 | I13: 0 | J13: 13737 | K13: 13737 | L13: 931.16 | M13: 0.063481718 | N13: Inbound Handling charges for Dec 2024
A14: 1800001382 | B14: DR | C14: 45722 | D14: 246779411251 | E14: USD | F14: 126.9 | G14: INR | H14: 11001.12 | I14: 0 | J14: 1599 | K14: 1599 | L14: 9402.12 | M14: 0.85465116 | N14: Inbound Handling charges for Dec 2024
A15: 1800001450 | B15: DR | C15: 45729 | D15: 246779411314 | E15: USD | F15: 105 | G15: INR | H15: 9102.58 | I15: 0 | J15: 8522 | K15: 8522 | L15: 580.58 | M15: 0.063781917 | N15: Scanning Charges for the month of October, 2024
... A78: 1800000557 | B78: DR | C78: 45719 | D78: 246779410507 | E78: USD | F78: 2.35 | G78: INR | H78: 203.72 | I78: 0 | J78: 402 | K78: 402 | L78: -198.28 | M78: -0.97329668 | N78: Outbound Handling for Aug 2024

Sheet Invoice & CN not in Customers
H1: =SUBTOTAL(9,H3:H42) -> 2304711.4
A2: Document Number | B2: Document Type | C2: Document Date | D2: Reference | E2: Document Currency Key | F2: Document Currency Value | G2: Company Code Currency Key | H2: Company Code Currency Value | I2: Text
A3: 1800016345 | B3: DR | C3: 46028 | D3: 256779440235 | E3: USD | F3: 7267.85 | G3: INR | H3: 659507.53 | I3: Unit Storage - 1-31 DEC 2025
A4: 1800015671 | B4: DR | C4: 46024 | D4: 256779440004 | E4: USD | F4: 7039.11 | G4: INR | H4: 638750.94 | I4: Unit Storage - 1-30 Nov 2025
A5: 1800011863 | B5: DR | C5: 45877 | D5: 256779416514 | E5: USD | F5: 1804.03 | G5: INR | H5: 155200.92 | I5: PORT SSR Chgs July 25
A6: 1800013509 | B6: DR | C6: 45935 | D6: 256779418399 | E6: USD | F6: 1432.98 | G6: INR | H6: 126375.61 | I6: PORT SSR Chgs Sep 25
A7: 1800014013 | B7: DR | C7: 45950 | D7: 256779418620 | E7: USD | F7: 830.96 | G7: INR | H7: 73283 | I7: CY Ground rent Chgs - 01 - 15 Oct 25
A8: 1800012586 | B8: DR | C8: 45904 | D8: 256779417244 | E8: USD | F8: 685.41 | G8: INR | H8: 59983.2 | I8: PORT SSR Chgs Aug 25
A9: 1800009171 | B9: DR | C9: 45810 | D9: 256779413935 | E9: USD | F9: 590.74 | G9: INR | H9: 50502.82 | I9: Port SSR Charges - Shifting for Aug to D
A10: 1800013758 | B10: DR | C10: 45937 | D10: 256779418179 | E10: USD | F10: 528.99 | G10: INR | H10: 46652.04 | I10: VAS-16-30 Sept 25
A11: 1800016282 | B11: DR | C11: 46028 | D11: 256779440162 | E11: USD | F11: 505.46 | G11: INR | H11: 45867.03 | I11: PORT SSR Chgs Dec 25
A12: 1800016693 | B12: DR | C12: 46034 | D12: 256779440282 | E12: USD | F12: 498.5 | G12: INR | H12: 45235.46 | I12: VAS-Dec 25 - 16-31
A13: 1800016623 | B13: DR | C13: 46028 | D13: 256779440332 | E13: USD | F13: 456.75 | G13: INR | H13: 41446.93 | I13: Fixed Storage Charges for January 2026
A14: 1800009411 | B14: DR | C14: 45812 | D14: 256779414175 | E14: USD | F14: 472.4 | G14: INR | H14: 40385.84 | I14: PORT SSR Chgs - 16 - 31 May 25
... A42: 1600001816 | B42: DG | C42: 45862 | D42: 256779421436 | E42: USD | F42: -140 | G42: INR | H42: -12037.72 | I42: Credit Note raised against 256779413861

Sheet Foreign Exchnage Gain loss
A1: Document Number | B1: Document Type | C1: Document Date | D1: Reference | E1: Document Currency Key | F1: Document Currency Value | G1: Company Code Currency Key | H1: Company Code Currency Value | I1: Debit | J1: Credit | K1: Net Amount | L1: TDS | M1: Rate | N1: Text | O1: Clearing Document | P1: Invoice Reversed in books
A2: 1400001901 | B2: DY | C2: 45976 | D2: KNOCK OFF ENTRY | E2: USD | F2: 3813.11 | G2: INR | H2: 331442.46 | I2: #N/A | K2: #N/A | L2: #N/A | M2: #N/A | O2: 1400001901 | P2: Yes
A3: 1400000288 | B3: DY | C3: 45854 | E3: USD | F3: 1926.06 | G3: INR | H3: 166972.57 | I3: #N/A | K3: #N/A | L3: #N/A | M3: #N/A | O3: 1400000288 | P3: Yes
A4: 1400000285 | B4: DY | C4: 45854 | E4: USD | F4: 1793.99 | G4: INR | H4: 154827.9 | I4: #N/A | K4: #N/A | L4: #N/A | M4: #N/A | O4: 1400000285 | P4: Yes
A5: 1400001902 | B5: DY | C5: 45976 | D5: KNOCK OFF ENTRY | E5: USD | F5: 1117.66 | G5: INR | H5: 96798.99 | I5: #N/A | K5: #N/A | L5: #N/A | M5: #N/A | O5: 1400001902 | P5: Yes
A6: 1400001112 | B6: DY | C6: 45902 | E6: INR | F6: 79944.34 | G6: INR | H6: 78561.62 | I6: #N/A | K6: #N/A | L6: #N/A | M6: #N/A | O6: 1400001112 | P6: Yes
A7: 1400000286 | B7: DY | C7: 45854 | E7: USD | F7: 705 | G7: INR | H7: 60844.08 | I7: #N/A | K7: #N/A | L7: #N/A | M7: #N/A | O7: 1400000286 | P7: Yes
A8: 1400000289 | B8: DY | C8: 45854 | E8: USD | F8: 531.9 | G8: INR | H8: 46111.08 | I8: #N/A | K8: #N/A | L8: #N/A | M8: #N/A | O8: 1400000289 | P8: Yes
A9: 1400000290 | B9: DY | C9: 45854 | D9: KNOCK OFF ENTRY | E9: USD | F9: 525 | G9: INR | H9: 45512.91 | I9: #N/A | K9: #N/A | L9: #N/A | M9: #N/A | O9: 1400000290 | P9: Yes
A10: 1400000246 | B10: DY | C10: 45842 | D10: KNOCK OFF ENTRY | E10: USD | F10: 456.75 | G10: INR | H10: 39701.54 | I10: #N/A | K10: #N/A | L10: #N/A | M10: #N/A | O10: 1400000246 | P10: Yes
A11: 1400000247 | B11: DY | C11: 45842 | D11: KNOCK OFF ENTRY | E11: USD | F11: 456.75 | G11: INR | H11: 39701.54 | I11: #N/A | K11: #N/A | L11: #N/A | M11: #N/A | O11: 1400000247 | P11: Yes
A12: 1400000287 | B12: DY | C12: 45854 | E12: USD | F12: 216.2 | G12: INR | H12: 18742.65 | I12: #N/A | K12: #N/A | L12: #N/A | M12: #N/A | O12: 1400000287 | P12: Yes
A13: 1400000245 | B13: DY | C13: 45842 | D13: KNOCK OFF ENTRY | E13: USD | F13: 0 | G13: INR | H13: 0 | I13: #N/A | K13: #N/A | L13: #N/A | M13: #N/A | O13: 1400000245 | P13: Yes
A14: 1400000248 | B14: DY | C14: 45842 | D14: KNOCK OFF ENTRY | E14: USD | F14: 0 | G14: INR | H14: 0 | I14: #N/A | K14: #N/A | L14: #N/A | M14: #N/A | O14: 1400000248 | P14: Yes
A15: 1400001902 | B15: DY | C15: 45976 | D15: KNOCK OFF ENTRY | E15: USD | F15: -55.46 | G15: INR | H15: -4880.67 | I15: #N/A | K15: #N/A | L15: #N/A | M15: #N/A
A16: 1400001902 | B16: DY | C16: 45976 | D16: KNOCK OFF ENTRY | E16: USD | F16: -137.9 | G16: INR | H16: -12135.67 | I16: #N/A | K16: #N/A | L16: #N/A | M16: #N/A
A17: 1400001902 | B17: DY | C17: 45976 | D17: KNOCK OFF ENTRY | E17: USD | F17: -143.81 | G17: INR | H17: -12655.77 | I17: #N/A | K17: #N/A | L17: #N/A | M17: #N/A
A18: 1400001902 | B18: DY | C18: 45976 | D18: KNOCK OFF ENTRY | E18: USD | F18: -177.66 | G18: INR | H18: -15634.68 | I18: #N/A | K18: #N/A | L18: #N/A | M18: #N/A
A19: 1400001902 | B19: DY | C19: 45976 | D19: KNOCK OFF ENTRY | E19: USD | F19: -182.83 | G19: INR | H19: -16089.66 | I19: #N/A | K19: #N/A | L19: #N/A | M19: #N/A
A20: 1400000287 | B20: DY | C20: 45854 | E20: USD | F20: -216.2 | G20: INR | H20: -18742.65 | I20: #N/A | K20: #N/A | L20: #N/A | M20: #N/A | O20: 1400000287 | P20: Yes
A21: 1400001902 | B21: DY | C21: 45976 | D21: KNOCK OFF ENTRY | E21: USD | F21: -420 | G21: INR | H21: -36961.42 | I21: #N/A | K21: #N/A | L21: #N/A | M21: #N/A
A22: 1400000246 | B22: DY | C22: 45842 | D22: KNOCK OFF ENTRY | E22: USD | F22: -456.75 | G22: INR | H22: -39701.54 | I22: #N/A | K22: #N/A | L22: #N/A | M22: #N/A | O22: 1400000246 | P22: Yes
A23: 1400000247 | B23: DY | C23: 45842 | D23: KNOCK OFF ENTRY | E23: USD | F23: -456.75 | G23: INR | H23: -39701.54 | I23: #N/A | K23: #N/A | L23: #N/A | M23: #N/A | O23: 1400000247 | P23: Yes
A24: 1400000290 | B24: DY | C24: 45854 | D24: KNOCK OFF ENTRY | E24: USD | F24: -525 | G24: INR | H24: -45512.91 | I24: #N/A | K24: #N/A | L24: #N/A | M24: #N/A | O24: 1400000290 | P24: Yes
A25: 1400000289 | B25: DY | C25: 45854 | E25: USD | F25: -531.9 | G25: INR | H25: -46111.08 | I25: #N/A | K25: #N/A | L25: #N/A | M25: #N/A | O25: 1400000289 | P25: Yes
A26: 1400000286 | B26: DY | C26: 45854 | E26: USD | F26: -705 | G26: INR | H26: -60844.08 | I26: #N/A | K26: #N/A | L26: #N/A | M26: #N/A | O26: 1400000286 | P26: Yes
A27: 1400001112 | B27: DY | C27: 45902 | E27: INR | F27: -79944.34 | G27: INR | H27: -78095.82 | I27: #N/A | K27: #N/A | L27: #N/A | M27: #N/A | O27: 1400001112 | P27: Yes
A28: 1400000285 | B28: DY | C28: 45854 | E28: USD | F28: -1793.99 | G28: INR | H28: -154827.9 | I28: #N/A | K28: #N/A | L28: #N/A | M28: #N/A | O28: 1400000285 | P28: Yes
A29: 1400000288 | B29: DY | C29: 45854 | E29: USD | F29: -1926.06 | G29: INR | H29: -166972.57 | I29: #N/A | K29: #N/A | L29: #N/A | M29: #N/A | O29: 1400000288 | P29: Yes
A30: 1400001901 | B30: DY | C30: 45976 | D30: KNOCK OFF ENTRY | E30: USD | F30: -3813.11 | G30: INR | H30: -331442.46 | I30: #N/A | K30: #N/A | L30: #N/A | M30: #N/A | O30: 1400001901 | P30: Yes
H31: =SUM(H2:H30) -> -1093.08

Sheet Customer Data Vlookup
B1: =SUBTOTAL(9,B2:B360) -> 8842595.5 | C1: =SUBTOTAL(9,C2:C360) -> 10967816 | D1: =C1-B1 -> 2125220.5
A2: Posting Date | B2: Debit (INR) | C2: Credit (INR) | D2: Voucher Type | E2: Voucher Subtype | F2: Voucher No | G2: Against Account | H2: Against Voucher | I2: Supplier Invoice No | L2: Row Labels | M2: Sum of Debit (INR) | N2: Sum of Credit (INR)
A3: 2025-02-20 | B3: 0 | C3: 35554.52 | D3: Purchase Invoice | E3: Purchase Invoice | F3: PU/25/SLS/OT/1560 | G3: Fixed Storage Charges - ODC (Covered) - SLSIPL | H3: PU/25/SLS/OT/1560 | I3: 246779410049 | L3: 246779410049 | M3: 0 | N3: 35554.52
A4: 2025-02-20 | B4: 0 | C4: 35554.52 | D4: Purchase Invoice | E4: Purchase Invoice | F4: PU/25/SLS/OT/1561 | G4: Fixed Storage Charges - ODC (Covered) - SLSIPL | H4: PU/25/SLS/OT/1561 | I4: 246779410303 | L4: 246779410072 | M4: 0 | N4: 35477
A5: 2025-02-20 | B5: 0 | C5: 35554.52 | D5: Purchase Invoice | E5: Purchase Invoice | F5: PU/25/SLS/OT/1562 | G5: Fixed Storage Charges - ODC (Covered) - SLSIPL | H5: PU/25/SLS/OT/1562 | I5: 246779410117 | L5: 246779410117 | M5: 0 | N5: 35554.52
A6: 2025-02-20 | B6: 0 | C6: 35554.52 | D6: Purchase Invoice | E6: Purchase Invoice | F6: PU/25/SLS/OT/1563 | G6: Fixed Storage Charges - ODC (Covered) - SLSIPL | H6: PU/25/SLS/OT/1563 | I6: 246779410160 | L6: 246779410160 | M6: 0 | N6: 35554.52
A7: 2025-02-20 | B7: 0 | C7: 35554.52 | D7: Purchase Invoice | E7: Purchase Invoice | F7: PU/25/SLS/OT/1564 | G7: Fixed Storage Charges - ODC (Covered) - SLSIPL | H7: PU/25/SLS/OT/1564 | I7: 246779410203 | L7: 246779410203 | M7: 0 | N7: 35554.52
A8: 2025-02-20 | B8: 0 | C8: 35554.52 | D8: Purchase Invoice | E8: Purchase Invoice | F8: PU/25/SLS/OT/1565 | G8: Fixed Storage Charges - ODC (Covered) - SLSIPL | H8: PU/25/SLS/OT/1565 | I8: 246779410246 | L8: 246779410246 | M8: 0 | N8: 35554.52
A9: 2025-03-03 | B9: 0 | C9: 804 | D9: Purchase Invoice | E9: Purchase Invoice | F9: PU/25/SLS/OT/1672 | G9: Handling Charges - Outbound (Exp) - SLSIPL | H9: PU/25/SLS/OT/1672 | I9: 246779410613 | L9: 246779410303 | M9: 0 | N9: 35554.52
A10: 2025-03-03 | B10: 0 | C10: 1004 | D10: Purchase Invoice | E10: Purchase Invoice | F10: PU/25/SLS/OT/1673 | G10: Handling Charges - Outbound (Exp) - SLSIPL | H10: PU/25/SLS/OT/1673 | I10: 246779410612 | L10: 246779410327 | M10: 0 | N10: 16480.711
A11: 2025-03-03 | B11: 0 | C11: 402 | D11: Purchase Invoice | E11: Purchase Invoice | F11: PU/25/SLS/OT/1674 | G11: Handling Charges - Outbound (Exp) - SLSIPL | H11: PU/25/SLS/OT/1674 | I11: 246779410611 | L11: 246779410333 | M11: 0 | N11: 29975.442
A12: 2025-03-03 | B12: 0 | C12: 201 | D12: Purchase Invoice | E12: Purchase Invoice | F12: PU/25/SLS/OT/1675 | G12: Handling Charges - Outbound (Exp) - SLSIPL | H12: PU/25/SLS/OT/1675 | I12: 246779410610 | L12: 246779410338 | M12: 0 | N12: 13859.78
A13: 2025-03-03 | B13: 0 | C13: 804 | D13: Purchase Invoice | E13: Purchase Invoice | F13: PU/25/SLS/OT/1676 | G13: Handling Charges - Outbound (Exp) - SLSIPL | H13: PU/25/SLS/OT/1676 | I13: 246779410608 | L13: 246779410339 | M13: 0 | N13: 44681.825
A14: 2025-03-03 | B14: 0 | C14: 402 | D14: Purchase Invoice | E14: Purchase Invoice | F14: PU/25/SLS/OT/1677 | G14: Handling Charges - Outbound (Exp) - SLSIPL | H14: PU/25/SLS/OT/1677 | I14: 246779410607 | L14: 246779410340 | M14: 0 | N14: 144772.57
... A210: 2025-05-28 | B210: 0 | C210: 333696 | D210: Purchase Invoice | E210: Purchase Invoice | F210: PU/26/SLS/OT/0278 | G210: Storage Charges - Cargo - SLSIPL | H210: PU/26/SLS/OT/0278 | I210: 256779413899 | L210: 256779412468 | M210: 0 | N210: 14119
A211: 2025-05-30 | B211: 177773 | C211: 0 | D211: Payment Entry | E211: Pay | F211: BP/26/SLS/0192 | G211: 1395250393003 - Punjab National Bank - INR - SLSIPL | L211: 256779412613 | M211: 0 | N211: 3922
A212: 2025-06-04 | B212: 0 | C212: 9844 | D212: Purchase Invoice | E212: Purchase Invoice | F212: PU/26/SLS/OT/0358 | G212: Handling Charges - Outbound (Exp) - SLSIPL | H212: PU/26/SLS/OT/0358 | I212: 256779414165 | L212: 256779412655 | M212: 0 | N212: 2085
A213: 2025-06-04 | B213: 0 | C213: 8407 | D213: Purchase Invoice | E213: Purchase Invoice | F213: PU/26/SLS/OT/0360 | G213: Handling Charges - Outbound (Exp) - SLSIPL | H213: PU/26/SLS/OT/0360 | I213: 256779414216 | L213: 256779412675 | M213: 0 | N213: 1447
A214: 2025-06-04 | B214: 500946.52 | C214: 0 | D214: Payment Entry | E214: Pay | F214: BP/25/SLS/1225-1 | G214: 1395250393003 - Punjab National Bank - INR - SLSIPL | H214: PU/25/SLS/OT/1562, PU/25/SLS/OT/1720, PU/25/SLS/OT/1731, PU/25/SLS/OT/1721, PU/25/SLS/OT/1673 | L214: 256779412683 | M214: 0 | N214: 43195
A215: 2025-06-04 | B215: 0 | C215: 17313 | D215: Purchase Invoice | E215: Purchase Invoice | F215: PU/26/SLS/OT/0585 | G215: Scanning Charges - Inbound - SLSIPL | H215: PU/26/SLS/OT/0585 | I215: 256779414288 | L215: 256779412692 | M215: 0 | N215: 6084
A216: 2025-06-04 | B216: 0 | C216: 41769 | D216: Purchase Invoice | E216: Purchase Invoice | F216: PU/26/SLS/OT/0797 | G216: Handling Charges - Inbound (Exp) - SLSIPL,LCL Movment - Gate in Charge - SLSIPL,Transportation Charges Paid - SLSIPL,Eempty Container Return Charges Paid - SLSIPL | H216: PU/26/SLS/OT/0797 | I216: 256779414158 | L216: 256779412777 | M216: 0 | N216: 7981
A217: 2025-06-07 | B217: 0 | C217: 352792 | D217: Purchase Invoice | E217: Purchase Invoice | F217: PU/26/SLS/OT/0285 | G217: Storage Charges - Cargo - SLSIPL | H217: PU/26/SLS/OT/0285 | I217: 256779414242 | L217: 256779412926 | M217: 0 | N217: 1878
A218: 2025-06-10 | B218: 0 | C218: 35431 | D218: Purchase Invoice | E218: Purchase Invoice | F218: PU/26/SLS/OT/0357-1 | G218: Fixed Storage Charges - ODC (Covered) - SLSIPL | H218: PU/26/SLS/OT/0357-1 | I218: 256779414386 | L218: 256779412941 | M218: 0 | N218: 27408
A219: 2025-06-13 | B219: 700000 | C219: 0 | D219: Payment Entry | E219: Pay | F219: BP/26/SLS/0229 | G219: 1395250393003 - Punjab National Bank - INR - SLSIPL | L219: 256779412950 | M219: 0 | N219: 13211
A220: 2025-06-21 | B220: 700000 | C220: 0 | D220: Payment Entry | E220: Pay | F220: BP/26/SLS/0259 | G220: 1395250393003 - Punjab National Bank - INR - SLSIPL | L220: 256779413127 | M220: 0 | N220: 35097
A221: 2025-06-30 | B221: 700000 | C221: 0 | D221: Payment Entry | E221: Pay | F221: BP/26/SLS/0291 | G221: 1395250393003 - Punjab National Bank - INR - SLSIPL | L221: 256779413163 | M221: 0 | N221: 15927
A222: 2025-07-05 | B222: 700000 | C222: 0 | D222: Payment Entry | E222: Pay | F222: BP/26/SLS/0300 | G222: 1395250393003 - Punjab National Bank - INR - SLSIPL | L222: 256779413172 | M222: 0 | N222: 11810
A223: 2025-07-11 | B223: 700000 | C223: 0 | D223: Payment Entry | E223: Pay | F223: BP/26/SLS/0311 | G223: 1395250393003 - Punjab National Bank - INR - SLSIPL | L223: 256779413184 | M223: 0 | N223: 11723.018
A224: 2025-05-16 | B224: 0 | C224: 11797 | D224: Purchase Invoice | E224: Purchase Invoice | F224: PU/26/SLS/OT/0283 | G224: Container Scanning Paid - SLSIPL | H224: PU/26/SLS/OT/0283 | I224: 256779413283 | L224: 256779413243 | M224: 0 | N224: 3623
A225: 2025-04-23 | B225: 0 | C225: 6084 | D225: Purchase Invoice | E225: Purchase Invoice | F225: PU/26/SLS/OT/0586-1 | G225: Scanning Charges - Inbound - SLSIPL | H225: PU/26/SLS/OT/0586-1 | I225: 256779412692 | L225: 256779413283 | M225: 0 | N225: 11797
A226: 2025-04-16 | B226: 0 | C226: 12169 | D226: Purchase Invoice | E226: Purchase Invoice | F226: PU/26/SLS/OT/0587-1 | G226: Scanning Charges - Inbound - SLSIPL | H226: PU/26/SLS/OT/0587-1 | I226: 256779411917 | L226: 256779413357 | M226: 0 | N226: 1264
A227: 2025-04-03 | B227: 0 | C227: 114223 | D227: Purchase Invoice | E227: Purchase Invoice | F227: PU/26/SLS/OT/0611-1 | G227: Storage Charges - Cargo - SLSIPL | H227: PU/26/SLS/OT/0611-1 | I227: 256779410220 | L227: 256779413404 | M227: 0 | N227: 7129
A228: 2025-04-03 | B228: 0 | C228: 140649 | D228: Purchase Invoice | E228: Purchase Invoice | F228: PU/26/SLS/OT/0612 | G228: Storage Charges - Cargo - SLSIPL | H228: PU/26/SLS/OT/0612 | I228: 256779410010 | L228: 256779413405 | M228: 0 | N228: 3960
A229: 2025-04-03 | B229: 0 | C229: 55272 | D229: Purchase Invoice | E229: Purchase Invoice | F229: PU/26/SLS/OT/0613 | G229: Storage Charges - Cargo - SLSIPL | H229: PU/26/SLS/OT/0613 | I229: 256779410004 | L229: 256779413427 | M229: 0 | N229: 990
A230: 2025-04-01 | B230: 0 | C230: 45188 | D230: Purchase Invoice | E230: Purchase Invoice | F230: PU/26/SLS/OT/0588 | G230: Transportation Charges Paid - SLSIPL | H230: PU/26/SLS/OT/0588 | I230: 246779413845 | L230: 256779413428 | M230: 0 | N230: 990
A231: 2025-03-31 | B231: 0 | C231: 31723 | D231: Purchase Invoice | E231: Purchase Invoice | F231: PU/25/SLS/OT/1822 | G231: Container Scanning Paid - SLSIPL | H231: PU/25/SLS/OT/1822 | I231: 246779413827 | L231: 256779413429 | M231: 0 | N231: 601
A232: 2025-07-19 | B232: 700000 | C232: 0 | D232: Payment Entry | E232: Pay | F232: BP/26/SLS/0368 | G232: 1395250393003 - Punjab National Bank - INR - SLSIPL | L232: 256779413430 | M232: 0 | N232: 1201
A233: 2025-07-24 | B233: 0 | C233: 9368 | D233: Purchase Invoice | E233: Purchase Invoice | F233: PU/26/SLS/OT/0607 | G233: Handling Charges - Inbound (Exp) - SLSIPL | H233: PU/26/SLS/OT/0607 | I233: 256779415945 | L233: 256779413486 | M233: 0 | N233: 1054
A234: 2025-07-25 | B234: 350672 | C234: 0 | D234: Payment Entry | E234: Pay | F234: BP/26/SLS/0394 | G234: 1395250393003 - Punjab National Bank - INR - SLSIPL | L234: 256779413837 | M234: 0 | N234: 12177
A235: 2025-07-25 | B235: 0 | C235: 32007 | D235: Purchase Invoice | E235: Purchase Invoice | F235: PU/26/SLS/OT/0608 | G235: Storage Charges - Cargo - SLSIPL | H235: PU/26/SLS/OT/0608 | I235: 256779415967 | L235: 256779413899 | M235: 0 | N235: 333696
...

Sheet DN & CN in customer books
B1: 636449 | C1: 503
A2: Posting Date | B2: Debit (INR) | C2: Credit (INR) | D2: Voucher Subtype | E2: Voucher No | F2: Against Account | G2: Against Voucher | H2: Supplier Invoice No | I2: Supplier Invoice No
A3: 2025-07-16 | B3: 11798 | C3: 0 | D3: Credit Note | E3: SLS26/MF/DN/0013 | F3: Container Scanning Paid - SLSIPL | G3: PU/26/SLS/OT/0283 | H3: 256779413283 | J3: =_xlfn.XLOOKUP(H3,'Invoice & CN not in Customers'!$D:$D,'Invoice & CN not in Customers'!$H:$H,0,0) -> 0
A4: 2025-07-16 | B4: 140649 | C4: 0 | D4: Credit Note | E4: SLS26/MF/DN/0016 | F4: Storage Charges - Cargo - SLSIPL | G4: PU/26/SLS/OT/0612 | H4: 256779410010 | J4: =_xlfn.XLOOKUP(H4,'Invoice & CN not in Customers'!$D:$D,'Invoice & CN not in Customers'!$H:$H,0,0) -> 0
A5: 2025-07-16 | B5: 55272 | C5: 0 | D5: Credit Note | E5: SLS26/MF/DN/0017 | F5: Storage Charges - Cargo - SLSIPL | G5: PU/26/SLS/OT/0613 | H5: 256779410004 | J5: =_xlfn.XLOOKUP(H5,'Invoice & CN not in Customers'!$D:$D,'Invoice & CN not in Customers'!$H:$H,0,0) -> 0
A6: 2025-07-16 | B6: 4786 | C6: 0 | D6: Credit Note | E6: SLS26/MF/DN/0007-2 | F6: Storage Charges - Cargo - SLSIPL | G6: SLS26/MF/DN/0007-2 | H6: 256779421381 | J6: =_xlfn.XLOOKUP(H6,'Invoice & CN not in Customers'!$D:$D,'Invoice & CN not in Customers'!$H:$H,0,0) -> 0
A7: 2025-07-16 | B7: 11955 | C7: 0 | D7: Credit Note | E7: SLS26/MF/DN/0004-1 | F7: Transportation Charges Paid - SLSIPL | G7: PU/26/SLS/OT/0588 | H7: 246779413845 | J7: =_xlfn.XLOOKUP(H7,'Invoice & CN not in Customers'!$D:$D,'Invoice & CN not in Customers'!$H:$H,0,0) -> 0
A8: 2025-07-16 | B8: 12467 | C8: 0 | D8: Credit Note | E8: SLS26/MF/DN/0018-1 | F8: Storage Charges - Cargo - SLSIPL | G8: SLS26/MF/DN/0018-1 | H8: 256779421383 | J8: =_xlfn.XLOOKUP(H8,'Invoice & CN not in Customers'!$D:$D,'Invoice & CN not in Customers'!$H:$H,0,0) -> 0
A9: 2025-07-16 | B9: 6084 | C9: 0 | D9: Credit Note | E9: SLS26/MF/DN/0002-1 | F9: Scanning Charges - Inbound - SLSIPL | G9: SLS26/MF/DN/0002-1 | H9: 256779421376 | J9: =_xlfn.XLOOKUP(H9,'Invoice & CN not in Customers'!$D:$D,'Invoice & CN not in Customers'!$H:$H,0,0) -> 0
A10: 2025-07-16 | B10: 12169 | C10: 0 | D10: Credit Note | E10: SLS26/MF/DN/0003-1 | F10: Scanning Charges - Inbound - SLSIPL | G10: SLS26/MF/DN/0003-1 | H10: 256779421370 | J10: =_xlfn.XLOOKUP(H10,'Invoice & CN not in Customers'!$D:$D,'Invoice & CN not in Customers'!$H:$H,0,0) -> 0
A11: 2025-07-16 | B11: 114223 | C11: 0 | D11: Credit Note | E11: SLS26/MF/DN/0015-1 | F11: Storage Charges - Cargo - SLSIPL | G11: SLS26/MF/DN/0015-1 | H11: 256779421367 | J11: =_xlfn.XLOOKUP(H11,'Invoice & CN not in Customers'!$D:$D,'Invoice & CN not in Customers'!$H:$H,0,0) -> 0
A12: 2025-07-16 | B12: 31577 | C12: 0 | D12: Credit Note | E12: SLS26/MF/DN/0005-1 | F12: Storage Charges - Cargo - SLSIPL | G12: SLS26/MF/DN/0005-1 | H12: 256779421361 | J12: =_xlfn.XLOOKUP(H12,'Invoice & CN not in Customers'!$D:$D,'Invoice & CN not in Customers'!$H:$H,0,0) -> 0
A13: 2025-07-16 | B13: 17313 | C13: 330 | D13: Debit Note | E13: SLS26/MF/DN/0001-2 | F13: Scanning Charges - Inbound - SLSIPL | G13: SLS26/MF/DN/0001-2, SLS26/MF/DN/0001-2 | H13: 256779421379 | J13: =_xlfn.XLOOKUP(H13,'Invoice & CN not in Customers'!$D:$D,'Invoice & CN not in Customers'!$H:$H,0,0) -> 0
A14: 2025-07-16 | B14: 8696 | C14: 173 | D14: Debit Note | E14: SLS26/MF/DN/0010-1 | F14: Container Scanning Paid - SLSIPL | G14: SLS26/MF/DN/0010-1, SLS26/MF/DN/0010-1 | H14: 256779421373 | J14: =_xlfn.XLOOKUP(H14,'Invoice & CN not in Customers'!$D:$D,'Invoice & CN not in Customers'!$H:$H,0,0) -> 0
A15: 2025-07-16 | B15: 31723 | C15: 0 | D15: Credit Note | E15: SLS26/MF/DN/0009 | F15: Container Scanning Paid - SLSIPL | G15: PU/25/SLS/OT/1822 | H15: 246779413827 | J15: =_xlfn.XLOOKUP(H15,'Invoice & CN not in Customers'!$D:$D,'Invoice & CN not in Customers'!$H:$H,0,0) -> 0
A16: 2025-07-31 | B16: 15778 | C16: 0 | D16: Credit Note | E16: SLS26/MF/DN/0020-1 | F16: Storage Charges - Cargo - SLSIPL | G16: SLS26/MF/DN/0020-1 | H16: 246779410348 | I16: 256779421380 | J16: =_xlfn.XLOOKUP(H16,'Invoice & CN not in Customers'!$D:$D,'Invoice & CN not in Customers'!$H:$H,0,0) -> 0 | K16: =_xlfn.XLOOKUP(I16,'Invoice & CN not in Customers'!$D:$D,'Invoice & CN not in Customers'!$H:$H,0,0) -> 0
A17: 2025-07-31 | B17: 36410 | C17: 0 | D17: Credit Note | E17: SLS26/MF/DN/0022-1 | F17: Container Scanning Paid - SLSIPL | G17: SLS26/MF/DN/0022-1 | H17: 246779411278 | I17: 256779421385 | J17: =_xlfn.XLOOKUP(H17,'Invoice & CN not in Customers'!$D:$D,'Invoice & CN not in Customers'!$H:$H,0,0) -> 0 | K17: =_xlfn.XLOOKUP(I17,'Invoice & CN not in Customers'!$D:$D,'Invoice & CN not in Customers'!$H:$H,0,0) -> 0
A18: 2025-07-31 | B18: 15401 | C18: 0 | D18: Credit Note | E18: SLS26/MF/DN/0021-1 | F18: Fixed Storage Charges - ODC (Covered) - SLSIPL | G18: SLS26/MF/DN/0021-1 | H18: 256779421382 | I18: 246779413701 | J18: =_xlfn.XLOOKUP(H18,'Invoice & CN not in Customers'!$D:$D,'Invoice & CN not in Customers'!$H:$H,0,0) -> 0 | K18: =_xlfn.XLOOKUP(I18,'Invoice & CN not in Customers'!$D:$D,'Invoice & CN not in Customers'!$H:$H,0,0) -> 0
A19: 2025-07-16 | B19: 18611 | C19: 0 | D19: Credit Note | E19: SLS26/MF/DN/0008 | F19: Container Scanning Paid - SLSIPL | G19: PU/25/SLS/OT/1821 | H19: 246779413816 | J19: =_xlfn.XLOOKUP(H19,'Invoice & CN not in Customers'!$D:$D,'Invoice & CN not in Customers'!$H:$H,0,0) -> 0
A20: 2025-07-16 | B20: 19430 | C20: 0 | D20: Credit Note | E20: SLS26/MF/DN/0006 | F20: Storage Charges - Cargo - SLSIPL | G20: PU/26/SLS/OT/0590 | H20: 246779413705 | J20: =_xlfn.XLOOKUP(H20,'Invoice & CN not in Customers'!$D:$D,'Invoice & CN not in Customers'!$H:$H,0,0) -> 0
A21: 2025-07-16 | B21: 17857 | C21: 0 | D21: Credit Note | E21: SLS26/MF/DN/0011 | F21: Container Scanning Paid - SLSIPL | G21: PU/25/SLS/OT/1854 | H21: 246779411339 | J21: =_xlfn.XLOOKUP(H21,'Invoice & CN not in Customers'!$D:$D,'Invoice & CN not in Customers'!$H:$H,0,0) -> 0
A22: 2025-07-16 | B22: 20874 | C22: 0 | D22: Credit Note | E22: SLS26/MF/DN/0014 | F22: Container Scanning Paid - SLSIPL | G22: PU/25/SLS/OT/1820 | H22: 246779411326 | J22: =_xlfn.XLOOKUP(H22,'Invoice & CN not in Customers'!$D:$D,'Invoice & CN not in Customers'!$H:$H,0,0) -> 0
A23: 2025-07-31 | B23: 33376 | C23: 0 | D23: Credit Note | E23: SLS26/MF/DN/0019 | F23: Container Scanning Paid - SLSIPL | G23: PU/25/SLS/OT/1925 | H23: 246779411300 | J23: =_xlfn.XLOOKUP(H23,'Invoice & CN not in Customers'!$D:$D,'Invoice & CN not in Customers'!$H:$H,0,0) -> 0

Sheet DN Reversal with CN in customer
A1: Posting Date | B1: Debit (INR) | C1: Credit (INR) | D1: Voucher Type | E1: Voucher Subtype | F1: Voucher No | G1: Against Voucher | I1: Supplier Invoice No
A2: 2025-12-31 | B2: 453 | C2: 453 | D2: Journal Entry | E2: Debit Note | F2: SJ/25/GEA/1377 | G2: PU/26/SLS/OT/1422 | H2: SLS26/MF/DN/0001-2 | I2: 256779417084
A3: 2025-12-31 | B3: 16530 | C3: 16530 | D3: Journal Entry | E3: Debit Note | F3: SJ/25/GEA/1376 | G3: PU/26/SLS/OT/0585 | H3: SLS26/MF/DN/0001-2 | I3: 256779414288
A4: 2025-10-07 | B4: 6084 | C4: 6084 | D4: Journal Entry | E4: Debit Note | F4: SJ/25/GEA/1108 | G4: PU/26/SLS/OT/0586-1 | H4: SLS26/MF/DN/0002-1 | I4: 256779412692
A5: 2025-10-07 | B5: 12169 | C5: 12169 | D5: Journal Entry | E5: Debit Note | F5: SJ/25/GEA/1109 | G5: PU/26/SLS/OT/0587-1 | H5: SLS26/MF/DN/0003-1 | I5: 256779411917
A6: 2025-10-07 | B6: 114223 | C6: 114223 | D6: Journal Entry | E6: Debit Note | F6: SJ/25/GEA/1110 | G6: PU/26/SLS/OT/0611-1 | H6: SLS26/MF/DN/0015-1 | I6: 256779410220
A7: 2025-10-07 | B7: 12467 | C7: 12467 | D7: Journal Entry | E7: Debit Note | F7: SJ/25/GEA/1107 | G7: PU/26/SLS/OT/0614-1 | H7: SLS26/MF/DN/0018-1 | I7: 246779413796
A8: 2025-10-07 | B8: 31577 | C8: 31577 | D8: Journal Entry | E8: Debit Note | F8: SJ/25/GEA/1111 | G8: PU/26/SLS/OT/0589-2 | H8: SLS26/MF/DN/0005-1 | I8: 246779413702
A9: 2025-10-07 | B9: 15401 | C9: 15401 | D9: Journal Entry | E9: Debit Note | F9: SJ/25/GEA/1106 | G9: PU/26/SLS/OT/1008-1 | H9: SLS26/MF/DN/0021-1 | I9: 246779413701
A10: 2025-12-31 | B10: 8522 | C10: 8522 | D10: Journal Entry | E10: Debit Note | F10: SJ/25/GEA/1378 | G10: PU/25/SLS/OT/1856 | H10: SLS26/MF/DN/0010-1 | I10: 246779411314
A11: 2025-10-07 | B11: 36410 | C11: 36410 | D11: Journal Entry | E11: Debit Note | F11: SJ/25/GEA/1105 | G11: PU/26/SLS/OT/1009-1 | H11: SLS26/MF/DN/0022-1 | I11: 246779411278
A12: 2025-10-07 | B12: 4786 | C12: 4786 | D12: Journal Entry | E12: Debit Note | F12: SJ/25/GEA/1103 | G12: PU/26/SLS/OT/0591-1 | H12: SLS26/MF/DN/0007-2 | I12: 246779410360
A13: 2025-10-07 | B13: 15778 | C13: 15778 | D13: Journal Entry | E13: Debit Note | F13: SJ/25/GEA/1104 | G13: PU/26/SLS/OT/0415-1 | H13: SLS26/MF/DN/0020-1 | I13: 246779410348

Sheet Customer Data
A2: Posting Date | B2: Account | C2: Debit (INR) | D2: Credit (INR) | E2: Balance (INR) | F2: Voucher Type | G2: Voucher Subtype | H2: Voucher No | I2: Against Account | J2: Party Type | K2: Party | L2: Against Voucher | M2: Supplier Invoice No
A3: 2025-02-20 | B3: Sundry Creditors - SLSIPL | C3: 0 | D3: 35554.52 | E3: -35554.52 | F3: Purchase Invoice | G3: Purchase Invoice | H3: PU/25/SLS/OT/1560 | I3: Fixed Storage Charges - ODC (Covered) - SLSIPL | J3: Supplier | K3: Ascendas Panvel FTWZ Private Limited | L3: PU/25/SLS/OT/1560 | M3: 246779410049
A4: 2025-02-20 | B4: Sundry Creditors - SLSIPL | C4: 0 | D4: 35554.52 | E4: -71109.04 | F4: Purchase Invoice | G4: Purchase Invoice | H4: PU/25/SLS/OT/1561 | I4: Fixed Storage Charges - ODC (Covered) - SLSIPL | J4: Supplier | K4: Ascendas Panvel FTWZ Private Limited | L4: PU/25/SLS/OT/1561 | M4: 246779410303
A5: 2025-02-20 | B5: Sundry Creditors - SLSIPL | C5: 0 | D5: 35554.52 | E5: -106663.56 | F5: Purchase Invoice | G5: Purchase Invoice | H5: PU/25/SLS/OT/1562 | I5: Fixed Storage Charges - ODC (Covered) - SLSIPL | J5: Supplier | K5: Ascendas Panvel FTWZ Private Limited | L5: PU/25/SLS/OT/1562 | M5: 246779410117
A6: 2025-02-20 | B6: Sundry Creditors - SLSIPL | C6: 0 | D6: 35554.52 | E6: -142218.08 | F6: Purchase Invoice | G6: Purchase Invoice | H6: PU/25/SLS/OT/1563 | I6: Fixed Storage Charges - ODC (Covered) - SLSIPL | J6: Supplier | K6: Ascendas Panvel FTWZ Private Limited | L6: PU/25/SLS/OT/1563 | M6: 246779410160
A7: 2025-02-20 | B7: Sundry Creditors - SLSIPL | C7: 0 | D7: 35554.52 | E7: -177772.6 | F7: Purchase Invoice | G7: Purchase Invoice | H7: PU/25/SLS/OT/1564 | I7: Fixed Storage Charges - ODC (Covered) - SLSIPL | J7: Supplier | K7: Ascendas Panvel FTWZ Private Limited | L7: PU/25/SLS/OT/1564 | M7: 246779410203
A8: 2025-02-20 | B8: Sundry Creditors - SLSIPL | C8: 0 | D8: 35554.52 | E8: -213327.12 | F8: Purchase Invoice | G8: Purchase Invoice | H8: PU/25/SLS/OT/1565 | I8: Fixed Storage Charges - ODC (Covered) - SLSIPL | J8: Supplier | K8: Ascendas Panvel FTWZ Private Limited | L8: PU/25/SLS/OT/1565 | M8: 246779410246
A9: 2025-03-03 | B9: Sundry Creditors - SLSIPL | C9: 0 | D9: 804 | E9: -214131.12 | F9: Purchase Invoice | G9: Purchase Invoice | H9: PU/25/SLS/OT/1672 | I9: Handling Charges - Outbound (Exp) - SLSIPL | J9: Supplier | K9: Ascendas Panvel FTWZ Private Limited | L9: PU/25/SLS/OT/1672 | M9: 246779410613
A10: 2025-03-03 | B10: Sundry Creditors - SLSIPL | C10: 0 | D10: 1004 | E10: -215135.12 | F10: Purchase Invoice | G10: Purchase Invoice | H10: PU/25/SLS/OT/1673 | I10: Handling Charges - Outbound (Exp) - SLSIPL | J10: Supplier | K10: Ascendas Panvel FTWZ Private Limited | L10: PU/25/SLS/OT/1673 | M10: 246779410612
A11: 2025-03-03 | B11: Sundry Creditors - SLSIPL | C11: 0 | D11: 402 | E11: -215537.12 | F11: Purchase Invoice | G11: Purchase Invoice | H11: PU/25/SLS/OT/1674 | I11: Handling Charges - Outbound (Exp) - SLSIPL | J11: Supplier | K11: Ascendas Panvel FTWZ Private Limited | L11: PU/25/SLS/OT/1674 | M11: 246779410611
A12: 2025-03-03 | B12: Sundry Creditors - SLSIPL | C12: 0 | D12: 201 | E12: -215738.12 | F12: Purchase Invoice | G12: Purchase Invoice | H12: PU/25/SLS/OT/1675 | I12: Handling Charges - Outbound (Exp) - SLSIPL | J12: Supplier | K12: Ascendas Panvel FTWZ Private Limited | L12: PU/25/SLS/OT/1675 | M12: 246779410610
A13: 2025-03-03 | B13: Sundry Creditors - SLSIPL | C13: 0 | D13: 804 | E13: -216542.12 | F13: Purchase Invoice | G13: Purchase Invoice | H13: PU/25/SLS/OT/1676 | I13: Handling Charges - Outbound (Exp) - SLSIPL | J13: Supplier | K13: Ascendas Panvel FTWZ Private Limited | L13: PU/25/SLS/OT/1676 | M13: 246779410608
A14: 2025-03-03 | B14: Sundry Creditors - SLSIPL | C14: 0 | D14: 402 | E14: -216944.12 | F14: Purchase Invoice | G14: Purchase Invoice | H14: PU/25/SLS/OT/1677 | I14: Handling Charges - Outbound (Exp) - SLSIPL | J14: Supplier | K14: Ascendas Panvel FTWZ Private Limited | L14: PU/25/SLS/OT/1677 | M14: 246779410607
... A222: 2025-05-28 | B222: Sundry Creditors - SLSIPL | C222: 0 | D222: 333696 | E222: -5193789.1 | F222: Purchase Invoice | G222: Purchase Invoice | H222: PU/26/SLS/OT/0278 | I222: Storage Charges - Cargo - SLSIPL | J222: Supplier | K222: Ascendas Panvel FTWZ Private Limited | L222: PU/26/SLS/OT/0278 | M222: 256779413899
A223: 2025-05-30 | B223: Sundry Creditors - SLSIPL | C223: 177773 | D223: 0 | E223: -5016016.1 | F223: Payment Entry | G223: Pay | H223: BP/26/SLS/0192 | I223: 1395250393003 - Punjab National Bank - INR - SLSIPL | J223: Supplier | K223: Ascendas Panvel FTWZ Private Limited
A224: 2025-06-04 | B224: Sundry Creditors - SLSIPL | C224: 0 | D224: 9844 | E224: -5025860.1 | F224: Purchase Invoice | G224: Purchase Invoice | H224: PU/26/SLS/OT/0358 | I224: Handling Charges - Outbound (Exp) - SLSIPL | J224: Supplier | K224: Ascendas Panvel FTWZ Private Limited | L224: PU/26/SLS/OT/0358 | M224: 256779414165
A225: 2025-06-04 | B225: Sundry Creditors - SLSIPL | C225: 0 | D225: 8407 | E225: -5034267.1 | F225: Purchase Invoice | G225: Purchase Invoice | H225: PU/26/SLS/OT/0360 | I225: Handling Charges - Outbound (Exp) - SLSIPL | J225: Supplier | K225: Ascendas Panvel FTWZ Private Limited | L225: PU/26/SLS/OT/0360 | M225: 256779414216
