Workbook

Sheet Summary
A1: Reconciliation of Ledger as on 31st January 2026
A2: Particulars | B2: Amount in USD
A3: Balance as per Scope Chemicals Pvt Ltd | B3: =-'Customer Data'!F59 -> -2231.8015
A4: Add: TDS to be booked in Ascendus books | B4: ='TDS To be recorded'!N1 -> 258
A5: Add: Invoices & CN not recorded in customer books | B5: ='Invoices not in customers books'!G35 -> 14357.35 | C5: To be discussed with Customer
A6: Less: Difference in Payment recorded in both books | B6: ='Payment Reco'!M8 -> -25.10247 | C6: To be discussed with CL Team
A7: Less: Understatement of invoice value in the customer books | B7: ='Difference in Invoice value'!H5 -> 778.75 | C7: To be discussed with Customer
A8: Less: Duplicate Credit Note in the books of Ascendus | B8: ='Duplicate Invoice'!G2 -> -50.75 | C8: To be discussed with CL Team
A9: Derived balance | B9: =SUM(B3:B8) -> 13086.446
A10: Balance as per Ascent | B10: ='Ascendus Data'!G120 -> -2045.428
A12: Difference | B12: =B9-B10-B11 -> 15131.874

Sheet Payment Reco
A1: As Per Ascendus | J1: As per customer | M1: Diffrence
A2: Document Number | B2: Document Type | C2: Document Date | D2: Document Currency Key | E2: Document Currency Value | F2: Company Code Currency Key | G2: Company Code Currency Value | H2: Exchange Rate | I2: Converted Value | J2: Posting Date | K2: Debit (USD) | L2: Voucher Type | M2: Amount | N2: Remarks
A3: 1400000789 | B3: DZ | C3: 45861 | D3: INR | E3: 8729.06 | F3: INR | G3: 8822.56 | M3: =I3-K3 -> 0
A4: 1400000789 | B4: DZ | C4: 45861 | D4: INR | E4: -8729.06 | F4: INR | G4: -8822.56 | M4: =I4-K4 -> 0
A5: 1400001561 | B5: DZ | C5: 45959 | D5: INR | E5: -500000 | F5: INR | G5: -500000 | H5: =G5/K5 -> -86 | I5: =G5/H5 -> 5813.9535 | J5: 2025-10-24 | K5: 5813.9535 | L5: Payment Entry | M5: =I5-K5 -> 0
A6: 1400000004 | B6: DZ | C6: 45743 | D6: INR | E6: -26397.48 | F6: INR | G6: -26279.46 | H6: 86.543676 | I6: =G6/H6 -> -303.65546 | J6: 2025-03-26 | K6: 278.55299 | L6: Payment Entry | M6: =I6+K6 -> -25.10247 | N6: The amount as per Bank details is 24,107 and as per ledger is 26397.48
A7: 1400002476 | B7: DZ | C7: 46041 | D7: INR | E7: -500000 | F7: INR | G7: -500000 | H7: =G7/K7 -> -90.300009 | I7: =G7/H7 -> 5537.098 | J7: 2026-01-14 | K7: 5537.098 | L7: Payment Entry | M7: =I7-K7 -> 0
I8: =SUM(I5:I7) -> 11047.396 | K8: =SUM(K5:K7) -> 11629.604 | M8: =SUM(M3:M7) -> -25.10247

Sheet Duplicate Invoice
A1: Document Number | B1: Document Type | C1: Document Date | D1: Document Header Text | E1: Reference | F1: Document Currency Key | G1: Document Currency Value | H1: Company Code Currency Key | I1: Company Code Currency Value
A2: 1600000001 | B2: DG | C2: 45693 | D2: NA | E2: 246779420002 | F2: USD | G2: -50.75 | H2: INR | I2: -4299.63 | J2: Credit Note Against Inv. 1800000001

Sheet Invoices not in customers old
G1: =SUBTOTAL(9,G3:G46) -> 15890.1 | H1: ='CN not in customers book'!G15 -> -1532.29 | I1: =G1+H1 -> 14357.81
A2: Document Number | B2: Document Type | C2: Document Date | D2: Document Header Text | E2: Reference | F2: Document Currency Key | G2: Document Currency Value | H2: Company Code Currency Key | I2: Company Code Currency Value
A3: 1800000001 | B3: DR | C3: 45688 | D3: NA | E3: 246779410001 | F3: USD | G3: 50.75 | H3: INR | I3: 4299.63 | J3: Towards Fixed charges for the month of August2024
A4: 1800014973 | B4: DR | C4: 45981 | D4: NA | E4: 256779419474 | F4: USD | G4: 20.28 | H4: INR | I4: 1784.71 | J4: Weighment-Nov 1-15, 2025
A5: 1800000003 | B5: DR | C5: 45692 | D5: NA | E5: 246779410003 | F5: USD | G5: 50.75 | H5: INR | I5: 4379.91 | J5: Towards Fixed charges for the month of August2024
A6: 1800000002 | B6: DR | C6: 45692 | D6: NA | E6: 246779410002 | F6: USD | G6: 50.75 | H6: INR | I6: 4379.91 | J6: Towards Fixed charges for the month of August2024
A7: 1800010437 | B7: DR | C7: 45842 | D7: NA | E7: 256779415197 | F7: USD | G7: 492.25 | H7: INR | I7: 42333.83 | J7: Unit Storage - 1-30 June 25
A8: 1800010502 | B8: DR | C8: 45842 | D8: NA | E8: 256779415262 | F8: USD | G8: 476.32 | H8: INR | I8: 40963.84 | J8: VAS - 16-30 June 25
A9: 1800014289 | B9: DR | C9: 45966 | D9: NA | E9: 256779418826 | F9: USD | G9: 60.86 | H9: INR | I9: 5355.89 | J9: WEIGHTMENT-16 -31 Oct 25
A10: 1800014554 | B10: DR | C10: 45966 | D10: NA | E10: 256779418886 | F10: USD | G10: 1457.24 | H10: INR | I10: 128242.06 | J10: Unit Storage - 1-31 Oct 2025
A11: 1800014728 | B11: DR | C11: 45966 | D11: 2123630 | E11: 256779419229 | F11: USD | G11: 77.07 | H11: INR | I11: 6782.42 | J11: PORT SSR Chgs Oct 25
A12: 1800011657 | B12: DR | C12: 45877 | D12: NA | E12: 256779416087 | F12: USD | G12: 916.56 | H12: INR | I12: 78851.77 | J12: Unit Storage - 1-31 July 25
A13: 1800009134 | B13: DR | C13: 45805 | D13: NA | E13: 256779413898 | F13: USD | G13: 928.64 | H13: INR | I13: 79847.9 | J13: Storage Chgs - 01 - 31 Apr 25
A14: 1800000028 | B14: DR | C14: 45708 | D14: NA | E14: 246779410073 | F14: USD | G14: 50.75 | H14: INR | I14: 4379.91 | J14: Fixed Rental charges for Aug 2024
... A46: 1800016703 | B46: DR | C46: 46034 | D46: 2158638 | E46: 256779440292 | F46: USD | G46: 40.04 | H46: INR | I46: 3633.36 | J46: Weighment-Dec 25 - 16-31

Sheet CN not in customers book
A2: Document Number | B2: Document Type | C2: Document Date | D2: Document Header Text | E2: Reference | F2: Document Currency Key | G2: Document Currency Value | H2: Company Code Currency Key | I2: Company Code Currency Value
A3: 1600000000 | B3: DG | C3: 45693 | D3: NA | E3: 246779420001 | F3: USD | G3: -50.75 | H3: INR | I3: -4379.91 | J3: Credit Against Invoice #1800000002
A4: 1600000716 | B4: DG | C4: 45791 | D4: NA | E4: 256779420425 | F4: USD | G4: -50.75 | H4: INR | I4: -4411.28 | J4: Credit note against 256779410292
A5: 1600000803 | B5: DG | C5: 45791 | D5: NA | E5: 256779420512 | F5: USD | G5: -50.75 | H5: INR | I5: -4411.28 | J5: Credit note against 256779410251
A6: 1600002033 | B6: DG | C6: 45873 | D6: NA | E6: 256779421609 | F6: USD | G6: -83.9 | H6: INR | I6: -7215.46 | J6: Credit note raised against 256779415776
A7: 1600001873 | B7: DG | C7: 45862 | D7: NA | E7: 256779421493 | F7: USD | G7: -50.75 | H7: INR | I7: -4364.53 | J7: Credit note raised against 256779414425
A8: 1600001907 | B8: DG | C8: 45862 | D8: NA | E8: 256779421527 | F8: USD | G8: -50.75 | H8: INR | I8: -4364.53 | J8: Credit note raised against 256779414460
A9: 1600001924 | B9: DG | C9: 45862 | D9: NA | E9: 256779421544 | F9: USD | G9: -50.75 | H9: INR | I9: -4364.53 | J9: Credit note raised against 256779414477
A10: 1600001851 | B10: DG | C10: 45862 | D10: NA | E10: 256779421471 | F10: USD | G10: -50.75 | H10: INR | I10: -4364.53 | J10: Credit note raised against 256779414403
A11: 1600001070 | B11: DG | C11: 45799 | D11: NA | E11: 256779420758 | F11: USD | G11: -50.75 | H11: INR | I11: -4379.91 | J11: Credit Note against 246779410002
A12: 1600001069 | B12: DG | C12: 45799 | D12: NA | E12: 256779420757 | F12: USD | G12: -50.75 | H12: INR | I12: -4379.91 | J12: Credit Note against 246779410073
A13: 1600002696 | B13: DG | C13: 46027 | D13: NA | E13: 256779422166 | F13: USD | G13: -950.87 | H13: INR | I13: -86284.93 | J13: Credit note for Duplicate invoice -256779418491
A14: 1600002701 | B14: DG | C14: 46027 | D14: NA | E14: 256779422171 | F14: USD | G14: -40.77 | H14: INR | I14: -3699.6 | J14: Credit note for Duplicate invoice -256779418496
G15: =SUM(G3:G14) -> -1532.29

Sheet Difference in Invoice old
A1: Document Number | B1: Document Type | C1: Document Date | D1: Reference | E1: Document Currency Key | F1: Document Currency Value | G1: Company Code Currency Key | H1: Company Code Currency Value | K1: Gross Amount | L1: Net Amount | M1: Diffrence In invoice value
A2: 1800016772 | B2: DR | C2: 46035 | D2: 256779440359 | E2: USD | F2: 821.64 | G2: INR | H2: 74558.19 | I2: VAS - NOV 25,16-30 | J2: 1 | K2: 40.04 | L2: 39.04 | M2: =F2-K2 -> 781.6
A3: 1800016783 | B3: DR | C3: 46035 | D3: 256779440370 | E3: USD | F3: 60.36 | G3: INR | H3: 5477.26 | I3: Weighment -NOV 25,16-30 | J3: 1 | K3: 63.21 | L3: =K3-J3 -> 62.21 | M3: =F3-K3 -> -2.85
M4: =SUM(M2:M3) -> 778.75

Sheet TDS To be recorded
N1: =SUM(N3:N47) -> 258
A2: Document Number | B2: Document Type | C2: Document Date | D2: Document Header Text | E2: Reference | F2: Document Currency Key | G2: Document Currency Value | H2: Company Code Currency Key | I2: Company Code Currency Value | L2: Gross Amount | M2: Net Amount | N2: TDS | O2: Rate
A3: 1800011346 | B3: DR | C3: 45870 | D3: NA | E3: 256779416055 | F3: USD | G3: 50.75 | H3: INR | I3: 4366.03 | J3: Fixed Storage Charges for August 2025 | K3: 0 | L3: 45.75 | M3: =L3-K3 -> 45.75 | N3: =G3-M3 -> 5 | O3: =N3/G3 -> 0.098522167
A4: 1800009623 | B4: DR | C4: 45818 | D4: NA | E4: 256779414387 | F4: USD | G4: 50.75 | H4: INR | I4: 4338.66 | J4: Fixed Storage Charges fo JUNE 2025 | K4: 0 | L4: 45.75 | M4: =L4-K4 -> 45.75 | N4: =G4-M4 -> 5 | O4: =N4/G4 -> 0.098522167
A5: 1800012787 | B5: DR | C5: 45917 | D5: NA | E5: 256779417441 | F5: USD | G5: 1902.19 | H5: INR | I5: 166468.88 | J5: VAS -1-15 Sept-25 | K5: 38 | L5: 1902.19 | M5: =L5-K5 -> 1864.19 | N5: =G5-M5 -> 38 | O5: =N5/G5 -> 0.019976974
A6: 1800012796 | B6: DR | C6: 45917 | D6: NA | E6: 256779417450 | F6: USD | G6: 81.57 | H6: INR | I6: 7138.54 | J6: Weighment -1-15 Sept-25 | K6: 0 | L6: 79.57 | M6: =L6-K6 -> 79.57 | N6: =G6-M6 -> 2 | O6: =N6/G6 -> 0.024518818
A7: 1800010207 | B7: DR | C7: 45845 | D7: NA | E7: 256779414967 | F7: USD | G7: 216.2 | H7: INR | I7: 18593.34 | K7: 0 | L7: 212.2 | M7: =L7-K7 -> 212.2 | N7: =G7-M7 -> 4 | O7: =N7/G7 -> 0.018501388
A8: 1800012740 | B8: DR | C8: 45904 | D8: NA | E8: 256779417374 | F8: USD | G8: 50.75 | H8: INR | I8: 4441.35 | J8: Fixed Storage Charges for September 2025 | K8: 0 | L8: 45.75 | M8: =L8-K8 -> 45.75 | N8: =G8-M8 -> 5 | O8: =N8/G8 -> 0.098522167
A9: 1800010003 | B9: DR | C9: 45842 | D9: NA | E9: 256779414767 | F9: USD | G9: 19.7 | H9: INR | I9: 1694.21 | J9: CODC LCL Chgs - 01 - 15 Jun 25 | K9: 0 | L9: 19.7 | M9: =L9-K9 -> 19.7 | N9: =G9-M9 -> 0 | O9: =N9/G9 -> 0
A10: 1800010185 | B10: DR | C10: 45842 | D10: NA | E10: 256779414945 | F10: USD | G10: 50.75 | H10: INR | I10: 4364.53 | J10: Fixed Storage Charges fo JULY 2025 | K10: 0 | L10: 45.75 | M10: =L10-K10 -> 45.75 | N10: =G10-M10 -> 5 | O10: =N10/G10 -> 0.098522167
A11: 1800014264 | B11: DR | C11: 45966 | D11: NA | E11: 256779418803 | F11: USD | G11: 50.75 | H11: INR | I11: 4466.17 | J11: Fixed Storage Charges for November 2025 | K11: 5 | L11: 50.75 | M11: =L11-K11 -> 45.75 | N11: =G11-M11 -> 5 | O11: =N11/G11 -> 0.098522167
A12: 1800014281 | B12: DR | C12: 45966 | D12: NA | E12: 256779418818 | F12: USD | G12: 1468.91 | H12: INR | I12: 129269.06 | J12: VAS-16 -31 Oct 25 | K12: 29 | L12: 1468.91 | M12: =L12-K12 -> 1439.91 | N12: =G12-M12 -> 29 | O12: =N12/G12 -> 0.01974253
A13: 1800014587 | B13: DR | C13: 45966 | D13: NA | E13: 256779418894 | F13: USD | G13: 131.6 | H13: INR | I13: 11581.25 | J13: CODC Inbound chgs - 16-31 Oct 25 | K13: 0 | L13: 128.6 | M13: =L13-K13 -> 128.6 | N13: =G13-M13 -> 3 | O13: =N13/G13 -> 0.022796353
A14: 1800014642 | B14: DR | C14: 45966 | D14: NA | E14: 256779418907 | F14: USD | G14: 112.8 | H14: INR | I14: 9926.78 | J14: CODC Out chgs -16-31 Oct 25 | K14: 0 | L14: 110.8 | M14: =L14-K14 -> 110.8 | N14: =G14-M14 -> 2 | O14: =N14/G14 -> 0.017730496
A15: 1800010671 | B15: DR | C15: 45856 | D15: NA | E15: 256779415455 | F15: USD | G15: 490.4 | H15: INR | I15: 42174.73 | J15: CODC GATE Out chgs - 01 - 15 July 25 | K15: 0 | L15: 480.4 | M15: =L15-K15 -> 480.4 | N15: =G15-M15 -> 10 | O15: =N15/G15 -> 0.020391517
A16: 1800000091 | B16: DR | C16: 45708 | D16: NA | E16: 246779410304 | F16: USD | G16: 50.75 | H16: INR | I16: 4379.91 | J16: Fixed Rental charges for Oct 2024 | K16: 0 | L16: 45.75 | M16: =L16-K16 -> 45.75 | N16: =G16-M16 -> 5 | O16: =N16/G16 -> 0.098522167
A17: 1800000122 | B17: DR | C17: 45708 | D17: NA | E17: 246779410050 | F17: USD | G17: 50.75 | H17: INR | I17: 4379.91 | J17: Fixed Rental charges for Sept 2024 | K17: 0 | L17: 45.75 | M17: =L17-K17 -> 45.75 | N17: =G17-M17 -> 5 | O17: =N17/G17 -> 0.098522167
A18: 1800000191 | B18: DR | C18: 45708 | D18: NA | E18: 246779410118 | F18: USD | G18: 50.75 | H18: INR | I18: 4379.91 | J18: Fixed Rental charges for Nov 2024 | K18: 0 | L18: 45.75 | M18: =L18-K18 -> 45.75 | N18: =G18-M18 -> 5 | O18: =N18/G18 -> 0.098522167
A19: 1800000234 | B19: DR | C19: 45708 | D19: NA | E19: 246779410161 | F19: USD | G19: 50.75 | H19: INR | I19: 4379.91 | J19: Fixed Rental charges for Dec 2024 | K19: 0 | L19: 45.75 | M19: =L19-K19 -> 45.75 | N19: =G19-M19 -> 5 | O19: =N19/G19 -> 0.098522167
... A47: 1800016749 | B47: DR | C47: 46035 | D47: NA | E47: 256779440336 | F47: USD | G47: 70 | H47: INR | I47: 6352.02 | J47: INTRA -NOV 25,16-30 | K47: 1 | L47: 70 | M47: =L47-K47 -> 69 | N47: =G47-M47 -> 1 | O47: =N47/G47 -> 0.014285714

Sheet Sheet10
A2: As per Customer Data | F2: As per Ascendus Data
A3: Years | B3: Posting Date | C3: TDS and Payment | D3: Purchase | F3: Years | G3: Document Date | H3: CN | I3: Sales | J3: Net Sales | K3: Payment
F4: 2025 | G4: Jan | I4: 50.75 | J4: =SUM(H4:I4) -> 50.75
A5: 2025 | B5: Feb | C5: 0 | D5: 274.5 | F5: 2025 | G5: Feb | H5: -101.5 | I5: 456.75 | J5: =SUM(H5:I5) -> 355.25
A6: 2025 | B6: Mar | C6: -282.60599 | D6: 4.053 | F6: 2025 | G6: Mar | I6: 50.75 | J6: =SUM(H6:I6) -> 50.75 | K6: -302.06276
F7: 2025 | G7: Apr | I7: 152.25 | J7: =SUM(H7:I7) -> 152.25
F8: 2025 | G8: May | H8: -203 | I8: 3380.88 | J8: =SUM(H8:I8) -> 3177.88
F9: 2025 | G9: Jun | I9: 1438.33 | J9: =SUM(H9:I9) -> 1438.33
F10: 2025 | G10: Jul | H10: -203 | I10: 3356.79 | J10: =SUM(H10:I10) -> 3153.79 | K10: 0
F11: 2025 | G11: Aug | H11: -83.9 | I11: 967.31 | J11: =SUM(H11:I11) -> 883.41
A12: 2025 | B12: Sep | C12: 0 | D12: 45.75 | F12: 2025 | G12: Sep | I12: 3151.36 | J12: =SUM(H12:I12) -> 3151.36
A13: 2025 | B13: Oct | C13: -5813.9535 | D13: 274.5 | F13: 2025 | G13: Oct | I13: 4613.83 | J13: =SUM(H13:I13) -> 4613.83 | K13: -5813.9535
F14: 2025 | G14: Nov | I14: 4169.54 | J14: =SUM(H14:I14) -> 4169.54
A15: 2025 | B15: Dec | C15: -2 | D15: 3671.59 | F15: 2026 | G15: Jan | H15: -991.64 | I15: 4534.06 | J15: =SUM(H15:I15) -> 3542.42 | K15: -5537.098
A16: 2026 | B16: Jan | C16: -5639.098 | D16: 4738.41 | H16: =SUM(H4:H15) -> -1583.04 | I16: =SUM(I4:I15) -> 26322.6 | J16: =SUM(H16:I16) -> 24739.56 | K16: =SUM(K4:K15) -> -11653.114 | L16: =SUM(J16:K16) -> 13086.446
A17: 2026 | B17: Feb | C17: -13 | D17: 506
C18: =SUM(C4:C17) -> -11750.657 | D18: =SUM(D4:D17) -> 9514.803 | E18: =SUM(C18:D18) -> -2235.8545

Sheet Customer Data
A1: Posting Date | B1: Supplier Invoice No | C1: Account | D1: Debit (USD) | E1: Credit (USD) | F1: Balance (USD) | G1: Voucher Type | H1: Voucher Subtype | I1: Voucher No | J1: Against Account | K1: File No | L1: Against Voucher | O1: Years | P1: Quarters | Q1: Posting Date | R1: Sum of Debit (USD) | S1: Sum of Credit (USD)
A2: 45714 | B2: 246779410050 | C2: Sundry Creditors USD - SCPL | D2: 0 | E2: 45.75 | F2: -45.75 | G2: Purchase Invoice | H2: Purchase Invoice | I2: PU/25/SCP/OT/0867 | J2: Rent - Warehouse - SCPL | L2: PU/25/SCP/OT/0867 | O2: 2025 | P2: Qtr1 | Q2: Feb | R2: 0 | S2: 274.5
A3: 45714 | B3: 246779410304 | C3: Sundry Creditors USD - SCPL | D3: 0 | E3: 45.75 | F3: -91.5 | G3: Purchase Invoice | H3: Purchase Invoice | I3: PU/25/SCP/OT/0868 | J3: Rent - Warehouse - SCPL | L3: PU/25/SCP/OT/0868 | Q3: Mar | R3: 282.60599 | S3: 4.053
A4: 45714 | B4: 246779410118 | C4: Sundry Creditors USD - SCPL | D4: 0 | E4: 45.75 | F4: -137.25 | G4: Purchase Invoice | H4: Purchase Invoice | I4: PU/25/SCP/OT/0869 | J4: Rent - Warehouse - SCPL | L4: PU/25/SCP/OT/0869 | P4: Qtr3 | Q4: Sep | R4: 0 | S4: 45.75
A5: 45714 | B5: 246779410161 | C5: Sundry Creditors USD - SCPL | D5: 0 | E5: 45.75 | F5: -183 | G5: Purchase Invoice | H5: Purchase Invoice | I5: PU/25/SCP/OT/0870 | J5: Rent - Warehouse - SCPL | L5: PU/25/SCP/OT/0870 | P5: Qtr4 | Q5: Oct | R5: 5813.9535 | S5: 274.5
A6: 45714 | B6: 246779410247 | C6: Sundry Creditors USD - SCPL | D6: 0 | E6: 45.75 | F6: -228.75 | G6: Purchase Invoice | H6: Purchase Invoice | I6: PU/25/SCP/OT/0872 | J6: Rent - Warehouse - SCPL | L6: PU/25/SCP/OT/0872 | Q6: Dec | R6: 2 | S6: 3671.59
A7: 45714 | B7: 246779410204 | C7: Sundry Creditors USD - SCPL | D7: 0 | E7: 45.75 | F7: -274.5 | G7: Purchase Invoice | H7: Purchase Invoice | I7: PU/25/SCP/OT/0871-1 | J7: Rent - Warehouse - SCPL | L7: PU/25/SCP/OT/0871-1 | O7: 2026 | P7: Qtr1 | Q7: Jan | R7: 5639.098 | S7: 4738.41
A8: 45742 | B8: 246779410050 | C8: Sundry Creditors USD - SCPL | D8: 278.55299 | E8: 0 | F8: 4.0529947 | G8: Payment Entry | H8: Pay | I8: BP/25/SCP/0820 | J8: 650014134028 - IndusInd Bank Limited - SCPL | L8: PU/25/SCP/OT/0867, PU/25/SCP/OT/0868, PU/25/SCP/OT/0869, PU/25/SCP/OT/0870, PU/25/SCP/OT/0871-1, PU/25/SCP/OT/0872 | Q8: Feb | R8: 13 | S8: 506
A9: 45742 | B9: 246779410050 | C9: Sundry Creditors USD - SCPL | D9: 0 | E9: 0 | F9: 4.0529947 | G9: Journal Entry | H9: Exchange Gain Or Loss | I9: SJ/25/GEA/0611 | J9: Exchange Gain/Loss - SCPL | L9: PU/25/SCP/OT/0867
A10: 45742 | B10: 246779410304 | C10: Sundry Creditors USD - SCPL | D10: 0 | E10: 0 | F10: 4.0529947 | G10: Journal Entry | H10: Exchange Gain Or Loss | I10: SJ/25/GEA/0612 | J10: Exchange Gain/Loss - SCPL | L10: PU/25/SCP/OT/0868
A11: 45742 | B11: 246779410118 | C11: Sundry Creditors USD - SCPL | D11: 0 | E11: 0 | F11: 4.0529947 | G11: Journal Entry | H11: Exchange Gain Or Loss | I11: SJ/25/GEA/0613 | J11: Exchange Gain/Loss - SCPL | L11: PU/25/SCP/OT/0869
A12: 45742 | B12: 246779410161 | C12: Sundry Creditors USD - SCPL | D12: 0 | E12: 0 | F12: 4.0529947 | G12: Journal Entry | H12: Exchange Gain Or Loss | I12: SJ/25/GEA/0614 | J12: Exchange Gain/Loss - SCPL | L12: PU/25/SCP/OT/0870
A13: 45742 | B13: 246779410204 | C13: Sundry Creditors USD - SCPL | D13: 0 | E13: 0 | F13: 4.0529947 | G13: Journal Entry | H13: Exchange Gain Or Loss | I13: SJ/25/GEA/0615 | J13: Exchange Gain/Loss - SCPL | L13: PU/25/SCP/OT/0871-1
A14: 45742 | B14: 246779410247 | C14: Sundry Creditors USD - SCPL | D14: 0 | E14: 0 | F14: 4.0529947 | G14: Journal Entry | H14: Exchange Gain Or Loss | I14: SJ/25/GEA/0616 | J14: Exchange Gain/Loss - SCPL | L14: PU/25/SCP/OT/0872
A15: 45747 | C15: Sundry Creditors USD - SCPL | D15: 4.053 | E15: 4.053 | F15: 4.0529947 | G15: Journal Entry | H15: Exchange Rate Revaluation | I15: SJ/25/GEA/1247 | J15: Rhenocoll-Werk EK EURO, Welfull Group Co., Ltd., H2 Minerals And More GmbH - EUR, Limited Liability Company VOSTOK - RUB, Exchange Gain/Loss - SCPL, Kaustik Europe B. V., Thomas Brunner Hygiene GmbH - EURO, Ascendas Panvel FTWZ Private Limited, Rhenocoll-Werk Ek EUR, Indulor AG, Zhejiang Luba Traffic Technology Co Ltd | L15: ACC-ERR-2025-00004, ACC-ERR-2025-00004
A16: 45904 | B16: 256779417374 | C16: Sundry Creditors USD - SCPL | D16: 0 | E16: 45.75 | F16: -41.697005 | G16: Purchase Invoice | H16: Purchase Invoice | I16: PU/26/SCP/OT/0351 | J16: Rent - Warehouse - SCPL | L16: PU/26/SCP/OT/0351
A17: 45946 | B17: 246779413009 | C17: Sundry Creditors USD - SCPL | D17: 0 | E17: 45.75 | F17: -87.447005 | G17: Purchase Invoice | H17: Purchase Invoice | I17: PU/26/SCP/OT/0396 | J17: Rent - Warehouse - SCPL | L17: PU/26/SCP/OT/0396
A18: 45946 | B18: 256779412170 | C18: Sundry Creditors USD - SCPL | D18: 0 | E18: 45.75 | F18: -133.19701 | G18: Purchase Invoice | H18: Purchase Invoice | I18: PU/26/SCP/OT/0397 | J18: Rent - Warehouse - SCPL | L18: PU/26/SCP/OT/0397
A19: 45946 | B19: 256779413128 | C19: Sundry Creditors USD - SCPL | D19: 0 | E19: 45.75 | F19: -178.94701 | G19: Purchase Invoice | H19: Purchase Invoice | I19: PU/26/SCP/OT/0398 | J19: Rent - Warehouse - SCPL | L19: PU/26/SCP/OT/0398
A20: 45946 | B20: 256779414387 | C20: Sundry Creditors USD - SCPL | D20: 0 | E20: 45.75 | F20: -224.69701 | G20: Purchase Invoice | H20: Purchase Invoice | I20: PU/26/SCP/OT/0399 | J20: Rent - Warehouse - SCPL | L20: PU/26/SCP/OT/0399
A21: 45946 | B21: 256779414945 | C21: Sundry Creditors USD - SCPL | D21: 0 | E21: 45.75 | F21: -270.44701 | G21: Purchase Invoice | H21: Purchase Invoice | I21: PU/26/SCP/OT/0400 | J21: Rent - Warehouse - SCPL | L21: PU/26/SCP/OT/0400
A22: 45946 | B22: 256779416055 | C22: Sundry Creditors USD - SCPL | D22: 0 | E22: 45.75 | F22: -316.19701 | G22: Purchase Invoice | H22: Purchase Invoice | I22: PU/26/SCP/OT/0401 | J22: Rent - Warehouse - SCPL | L22: PU/26/SCP/OT/0401
A23: 45954 | C23: Sundry Creditors USD - SCPL | D23: 5813.9535 | E23: 0 | F23: 5497.7565 | G23: Payment Entry | H23: Pay | I23: BP/26/SCP/0466 | J23: 201003540849 - Indusind Bank Limited - SCPL
A24: 46014 | B24: 256779418037 | C24: Sundry Creditors USD - SCPL | D24: 0 | E24: 45.75 | F24: 5452.0065 | G24: Purchase Invoice | H24: Purchase Invoice | I24: PU/26/SCP/OT/0590 | J24: Rent - Warehouse - SCPL | L24: PU/26/SCP/OT/0590
A25: 46014 | B25: 256779413840 | C25: Sundry Creditors USD - SCPL | D25: 0 | E25: 41.14 | F25: 5410.8665 | G25: Purchase Invoice | H25: Purchase Invoice | I25: PU/26/SCP/OT/0592 | J25: Weighment Expense - SCPL | L25: PU/26/SCP/OT/0592
A26: 46014 | B26: 256779413242 | C26: Sundry Creditors USD - SCPL | D26: 0 | E26: 1170.92 | F26: 4239.9465 | G26: Purchase Invoice | H26: Purchase Invoice | I26: PU/26/SCP/OT/0591-1 | J26: Re-Bagging Charges - SCPL | L26: PU/26/SCP/OT/0591-1
A27: 46014 | B27: 256779414742 | C27: Sundry Creditors USD - SCPL | D27: 0 | E27: 325.22 | F27: 3914.7265 | G27: Purchase Invoice | H27: Purchase Invoice | I27: PU/26/SCP/OT/0589-2 | J27: Re-Bagging Charges - SCPL | K27: SCP26/MF/ES/0006 | L27: PU/26/SCP/OT/0589-2
A28: 46014 | B28: 256779417450 | C28: Sundry Creditors USD - SCPL | D28: 0 | E28: 79.57 | F28: 3835.1565 | G28: Purchase Invoice | H28: Purchase Invoice | I28: PU/26/SCP/OT/0593 | J28: Weighment Expense - SCPL | L28: PU/26/SCP/OT/0593
A29: 46015 | B29: 256779418186 | C29: Sundry Creditors USD - SCPL | D29: 0 | E29: 20.27 | F29: 3814.8865 | G29: Purchase Invoice | H29: Purchase Invoice | I29: PU/26/SCP/OT/0595 | J29: Weighment Expense - SCPL | K29: SCP26/MF/ES/0015 | L29: PU/26/SCP/OT/0595
A30: 46015 | B30: 256779418481 | C30: Sundry Creditors USD - SCPL | D30: 0 | E30: 39.77 | F30: 3775.1165 | G30: Purchase Invoice | H30: Purchase Invoice | I30: PU/26/SCP/OT/0596 | J30: Weighment Expense - SCPL | L30: PU/26/SCP/OT/0596
A31: 46015 | B31: 256779413162 | C31: Sundry Creditors USD - SCPL | D31: 0 | E31: 128.6 | F31: 3646.5165 | G31: Purchase Invoice | H31: Purchase Invoice | I31: PU/26/SCP/OT/0597 | J31: Handling Expense - Pallet - SCPL | K31: 025/25-26_IMP/SCPL001/25-26 | L31: PU/26/SCP/OT/0597
A32: 46015 | B32: 256779413171 | C32: Sundry Creditors USD - SCPL | D32: 0 | E32: 110.8 | F32: 3535.7165 | G32: Purchase Invoice | H32: Purchase Invoice | I32: PU/26/SCP/OT/0598 | J32: Handling Expense - Pallet - SCPL | L32: PU/26/SCP/OT/0598
A33: 46015 | B33: 256779413425 | C33: Sundry Creditors USD - SCPL | D33: 0 | E33: 36.6 | F33: 3499.1165 | G33: Purchase Invoice | H33: Purchase Invoice | I33: PU/26/SCP/OT/0599 | J33: Handling Expense - Pallet - SCPL | K33: SCP26/MF/ES/0004 | L33: PU/26/SCP/OT/0599
A34: 46015 | B34: 256779413426 | C34: Sundry Creditors USD - SCPL | D34: 0 | E34: 2.35 | F34: 3496.7665 | G34: Purchase Invoice | H34: Purchase Invoice | I34: PU/26/SCP/OT/0600 | J34: Handling Expense - Pallet - SCPL | K34: SCP26/MF/ES/0005 | L34: PU/26/SCP/OT/0600
A35: 46015 | B35: 256779414757 | C35: Sundry Creditors USD - SCPL | D35: 0 | E35: 115.9 | F35: 3380.8665 | G35: Purchase Invoice | H35: Purchase Invoice | I35: PU/26/SCP/OT/0601 | J35: Handling Expense - Pallet - SCPL,Gate in & Gate Out Expense - SCPL | K35: SCP26/MF/ES/0006 | L35: PU/26/SCP/OT/0601
A36: 46015 | B36: 256779414767 | C36: Sundry Creditors USD - SCPL | D36: 0 | E36: 19.7 | F36: 3361.1665 | G36: Purchase Invoice | H36: Purchase Invoice | I36: PU/26/SCP/OT/0602 | J36: Handling Expense - Pallet - SCPL,Gate in & Gate Out Expense - SCPL | K36: 081/25-26 | L36: PU/26/SCP/OT/0602
A37: 46015 | B37: 256779414967 | C37: Sundry Creditors USD - SCPL | D37: 0 | E37: 212.2 | F37: 3148.9665 | G37: Purchase Invoice | H37: Purchase Invoice | I37: PU/26/SCP/OT/0603 | J37: Handling Expense - Pallet - SCPL | K37: 087/25-26_IMP/SCPL002/25-26_IMP/SCPL003/25-26 | L37: PU/26/SCP/OT/0603
A38: 46015 | B38: 256779415455 | C38: Sundry Creditors USD - SCPL | D38: 0 | E38: 480.4 | F38: 2668.5665 | G38: Purchase Invoice | H38: Purchase Invoice | I38: PU/26/SCP/OT/0604 | J38: Handling Expense - Pallet - SCPL,Gate in & Gate Out Expense - SCPL | L38: PU/26/SCP/OT/0604
A39: 46015 | B39: 256779417583 | C39: Sundry Creditors USD - SCPL | D39: 0 | E39: 273.45 | F39: 2395.1165 | G39: Purchase Invoice | H39: Purchase Invoice | I39: PU/26/SCP/OT/0605 | J39: Handling Expense - Pallet - SCPL,Gate in & Gate Out Expense - SCPL | K39: 168/25-26_IMP/SCPL004/25-26 | L39: PU/26/SCP/OT/0605
A40: 46015 | B40: 256779418907 | C40: Sundry Creditors USD - SCPL | D40: 0 | E40: 110.8 | F40: 2284.3165 | G40: Purchase Invoice | H40: Purchase Invoice | I40: PU/26/SCP/OT/0607 | J40: Handling Expense - Pallet - SCPL | L40: PU/26/SCP/OT/0607
...

Sheet Updated Customer Ledger
A1: Posting Date | B1: Voucher Subtype | C1: Supplier Invoice No | D1: Debit (USD) | E1: Credit (USD) | F1: Balance (USD) | G1: Voucher No | H1: Against Account | I1: `
A2: 2025-02-26 | B2: Purchase Invoice | C2: 246779410050 | D2: 0 | E2: 45.75 | F2: -45.75 | G2: PU/25/SCP/OT/0867 | H2: Rent - Warehouse - SCPL | I2: PU/25/SCP/OT/0867
A3: 2025-02-26 | B3: Purchase Invoice | C3: 246779410304 | D3: 0 | E3: 45.75 | F3: -91.5 | G3: PU/25/SCP/OT/0868 | H3: Rent - Warehouse - SCPL | I3: PU/25/SCP/OT/0868
A4: 2025-02-26 | B4: Purchase Invoice | C4: 246779410118 | D4: 0 | E4: 45.75 | F4: -137.25 | G4: PU/25/SCP/OT/0869 | H4: Rent - Warehouse - SCPL | I4: PU/25/SCP/OT/0869
A5: 2025-02-26 | B5: Purchase Invoice | C5: 246779410161 | D5: 0 | E5: 45.75 | F5: -183 | G5: PU/25/SCP/OT/0870 | H5: Rent - Warehouse - SCPL | I5: PU/25/SCP/OT/0870
A6: 2025-02-26 | B6: Purchase Invoice | C6: 246779410247 | D6: 0 | E6: 45.75 | F6: -228.75 | G6: PU/25/SCP/OT/0872 | H6: Rent - Warehouse - SCPL | I6: PU/25/SCP/OT/0872
A7: 2025-02-26 | B7: Purchase Invoice | C7: 246779410204 | D7: 0 | E7: 45.75 | F7: -274.5 | G7: PU/25/SCP/OT/0871-1 | H7: Rent - Warehouse - SCPL | I7: PU/25/SCP/OT/0871-1
A8: 2025-03-26 | B8: Pay | C8: 246779410050 | D8: 278.55299 | E8: 0 | F8: 4.0529947 | G8: BP/25/SCP/0820 | H8: 650014134028 - IndusInd Bank Limited - SCPL | I8: PU/25/SCP/OT/0867, PU/25/SCP/OT/0868, PU/25/SCP/OT/0869, PU/25/SCP/OT/0870, PU/25/SCP/OT/0871-1, PU/25/SCP/OT/0872
A9: 2025-03-31 | B9: Exchange Rate Revaluation | D9: 4.053 | E9: 4.053 | F9: 4.0529947 | G9: SJ/25/GEA/1247 | H9: Rhenocoll-Werk EK EURO, Welfull Group Co., Ltd., H2 Minerals And More GmbH - EUR, Limited Liability Company VOSTOK - RUB, Exchange Gain/Loss - SCPL, Kaustik Europe B. V., Thomas Brunner Hygiene GmbH - EURO, Ascendas Panvel FTWZ Private Limited, Rhenocoll-Werk Ek EUR, Indulor AG, Zhejiang Luba Traffic Technology Co Ltd | I9: ACC-ERR-2025-00004, ACC-ERR-2025-00004
A10: 2025-09-04 | B10: Purchase Invoice | C10: 256779417374 | D10: 0 | E10: 45.75 | F10: -41.697005 | G10: PU/26/SCP/OT/0351 | H10: Rent - Warehouse - SCPL | I10: PU/26/SCP/OT/0351
A11: 2025-10-16 | B11: Purchase Invoice | C11: 246779413009 | D11: 0 | E11: 45.75 | F11: -87.447005 | G11: PU/26/SCP/OT/0396 | H11: Rent - Warehouse - SCPL | I11: PU/26/SCP/OT/0396
A12: 2025-10-16 | B12: Purchase Invoice | C12: 256779412170 | D12: 0 | E12: 45.75 | F12: -133.19701 | G12: PU/26/SCP/OT/0397 | H12: Rent - Warehouse - SCPL | I12: PU/26/SCP/OT/0397
A13: 2025-10-16 | B13: Purchase Invoice | C13: 256779413128 | D13: 0 | E13: 45.75 | F13: -178.94701 | G13: PU/26/SCP/OT/0398 | H13: Rent - Warehouse - SCPL | I13: PU/26/SCP/OT/0398
A14: 2025-10-16 | B14: Purchase Invoice | C14: 256779414387 | D14: 0 | E14: 45.75 | F14: -224.69701 | G14: PU/26/SCP/OT/0399 | H14: Rent - Warehouse - SCPL | I14: PU/26/SCP/OT/0399
A15: 2025-10-16 | B15: Purchase Invoice | C15: 256779414945 | D15: 0 | E15: 45.75 | F15: -270.44701 | G15: PU/26/SCP/OT/0400 | H15: Rent - Warehouse - SCPL | I15: PU/26/SCP/OT/0400
A16: 2025-10-16 | B16: Purchase Invoice | C16: 256779416055 | D16: 0 | E16: 45.75 | F16: -316.19701 | G16: PU/26/SCP/OT/0401 | H16: Rent - Warehouse - SCPL | I16: PU/26/SCP/OT/0401
A17: 2025-10-24 | B17: Pay | D17: 5813.9535 | E17: 0 | F17: 5497.7565 | G17: BP/26/SCP/0466 | H17: 201003540849 - Indusind Bank Limited - SCPL
A18: 2025-12-23 | B18: Purchase Invoice | C18: 256779418037 | D18: 0 | E18: 45.75 | F18: 5452.0065 | G18: PU/26/SCP/OT/0590 | H18: Rent - Warehouse - SCPL | I18: PU/26/SCP/OT/0590
A19: 2025-12-23 | B19: Purchase Invoice | C19: 256779413840 | D19: 0 | E19: 41.14 | F19: 5410.8665 | G19: PU/26/SCP/OT/0592 | H19: Weighment Expense - SCPL | I19: PU/26/SCP/OT/0592
A20: 2025-12-23 | B20: Purchase Invoice | C20: 256779413242 | D20: 0 | E20: 1170.92 | F20: 4239.9465 | G20: PU/26/SCP/OT/0591-1 | H20: Re-Bagging Charges - SCPL | I20: PU/26/SCP/OT/0591-1
A21: 2025-12-23 | B21: Purchase Invoice | C21: 256779414742 | D21: 0 | E21: 325.22 | F21: 3914.7265 | G21: PU/26/SCP/OT/0589-2 | H21: Re-Bagging Charges - SCPL | I21: PU/26/SCP/OT/0589-2
A22: 2025-12-23 | B22: Purchase Invoice | C22: 256779417450 | D22: 0 | E22: 79.57 | F22: 3835.1565 | G22: PU/26/SCP/OT/0593 | H22: Weighment Expense - SCPL | I22: PU/26/SCP/OT/0593
A23: 2025-12-24 | B23: Purchase Invoice | C23: 256779418186 | D23: 0 | E23: 20.27 | F23: 3814.8865 | G23: PU/26/SCP/OT/0595 | H23: Weighment Expense - SCPL | I23: PU/26/SCP/OT/0595
A24: 2025-12-24 | B24: Purchase Invoice | C24: 256779418481 | D24: 0 | E24: 39.77 | F24: 3775.1165 | G24: PU/26/SCP/OT/0596 | H24: Weighment Expense - SCPL | I24: PU/26/SCP/OT/0596
A25: 2025-12-24 | B25: Purchase Invoice | C25: 256779413162 | D25: 0 | E25: 128.6 | F25: 3646.5165 | G25: PU/26/SCP/OT/0597 | H25: Handling Expense - Pallet - SCPL | I25: PU/26/SCP/OT/0597
A26: 2025-12-24 | B26: Purchase Invoice | C26: 256779413171 | D26: 0 | E26: 110.8 | F26: 3535.7165 | G26: PU/26/SCP/OT/0598 | H26: Handling Expense - Pallet - SCPL | I26: PU/26/SCP/OT/0598
A27: 2025-12-24 | B27: Purchase Invoice | C27: 256779413425 | D27: 0 | E27: 36.6 | F27: 3499.1165 | G27: PU/26/SCP/OT/0599 | H27: Handling Expense - Pallet - SCPL | I27: PU/26/SCP/OT/0599
A28: 2025-12-24 | B28: Purchase Invoice | C28: 256779413426 | D28: 0 | E28: 2.35 | F28: 3496.7665 | G28: PU/26/SCP/OT/0600 | H28: Handling Expense - Pallet - SCPL | I28: PU/26/SCP/OT/0600
A29: 2025-12-24 | B29: Purchase Invoice | C29: 256779414757 | D29: 0 | E29: 115.9 | F29: 3380.8665 | G29: PU/26/SCP/OT/0601 | H29: Handling Expense - Pallet - SCPL,Gate in & Gate Out Expense - SCPL | I29: PU/26/SCP/OT/0601
... A43: 2026-01-01 | B43: Purchase Invoice | C43: 256779418818 | D43: 29 | E43: 1468.91 | F43: -2716.7435 | G43: PU/26/SCP/OT/0628 | H43: Re-Bagging Charges - SCPL | I43: PU/26/SCP/OT/0628, PU/26/SCP/OT/0628
A44: 2026-01-14 | B44: Pay | D44: 5537.098 | E44: 0 | F44: 2820.3545 | G44: BP/26/SCP/0638 | H44: 201003540849 - Indusind Bank Limited - SCPL
A45: 2026-01-16 | B45: Purchase Invoice | C45: 256779440042 | D45: 5 | E45: 50.75 | F45: 2774.6045 | G45: PU/26/SCP/OT/0663 | H45: Rent - Warehouse - SCPL | I45: PU/26/SCP/OT/0663, PU/26/SCP/OT/0663
A46: 2026-01-23 | B46: Purchase Invoice | C46: 256779440333 | D46: 5 | E46: 50.75 | F46: 2728.8545 | G46: PU/26/SCP/OT/0712 | H46: Rent - Warehouse - SCPL | I46: PU/26/SCP/OT/0712, PU/26/SCP/OT/0712
A47: 2026-02-12 | B47: Purchase Invoice | C47: 256779418803 | D47: 5 | E47: 50.75 | F47: 2683.1045 | G47: PU/26/SCP/OT/0826 | H47: Rent - Warehouse - SCPL | I47: PU/26/SCP/OT/0826, PU/26/SCP/OT/0826
A48: 2026-02-12 | B48: Purchase Invoice | C48: 256779440370 | D48: 1 | E48: 60.36 | F48: 2623.7445 | G48: PU/26/SCP/OT/0827-1 | H48: Weighment Expense - SCPL | I48: PU/26/SCP/OT/0827-1, PU/26/SCP/OT/0827-1
A49: 2026-02-13 | B49: Purchase Invoice | C49: 256779440336 | D49: 1 | E49: 70 | F49: 2554.7445 | G49: PU/26/SCP/OT/0829 | H49: Intra SEZ Trf Expenses - SCPL | I49: PU/26/SCP/OT/0829, PU/26/SCP/OT/0829
A50: 2026-02-13 | B50: Purchase Invoice | C50: 256779440256 | D50: 2 | E50: 112.8 | F50: 2443.9445 | G50: PU/26/SCP/OT/0831 | H50: Handling Expense - Pallet - SCPL | I50: PU/26/SCP/OT/0831, PU/26/SCP/OT/0831
A51: 2026-02-13 | B51: Purchase Invoice | C51: 256779440129 | D51: 3 | E51: 169.2 | F51: 2277.7445 | G51: PU/26/SCP/OT/0832 | H51: Handling Expense - Pallet - SCPL | I51: PU/26/SCP/OT/0832, PU/26/SCP/OT/0832
A52: 2026-02-13 | B52: Purchase Invoice | C52: 256779440171 | D52: 4 | E52: 180.4 | F52: 2101.3445 | G52: PU/26/SCP/OT/0833 | H52: Gate in & Gate Out Expense - SCPL,Handling Expense - Pallet - SCPL | I52: PU/26/SCP/OT/0833, PU/26/SCP/OT/0833
A53: 2026-02-13 | B53: Purchase Invoice | C53: 256779440292 | D53: 1 | E53: 40.04 | F53: 2062.3045 | G53: PU/26/SCP/OT/0830-1 | H53: Weighment Expense - SCPL | I53: PU/26/SCP/OT/0830-1, PU/26/SCP/OT/0830-1
...

Sheet Ascendus Data
A2: Document Number | B2: Document Type | C2: Document Date | D2: Document Header Text | E2: Reference | F2: Document Currency Key | G2: Document Currency Value | H2: Company Code Currency Key | I2: Company Code Currency Value | M2: Clearing Document Number | N2: Our Remarks
A3: 1800000001 | B3: DR | C3: 45688 | D3: NA | E3: 246779410001 | F3: USD | G3: 50.75 | H3: INR | I3: 4299.63 | J3: Towards Fixed charges for the month of August2024 | K3: {=VLOOKUP(E3,'Customer Data'!$B$1:$F$58,{3,4},0)} -> #N/A | M3: 1400000000
A4: 1400000001 | B4: DY | C4: 45692 | D4: knock off entry | E4: KNOCK OFF ENTRY | F4: USD | G4: 50.75 | H4: INR | I4: 4379.91 | K4: {=VLOOKUP(E4,'Customer Data'!$B$1:$F$58,{3,4},0)} -> #N/A | M4: 1400000001
A5: 1400000001 | B5: DY | C5: 45692 | D5: knock off entry | E5: KNOCK OFF ENTRY | F5: USD | G5: -50.75 | H5: INR | I5: -4379.91 | K5: {=VLOOKUP(E5,'Customer Data'!$B$1:$F$58,{3,4},0)} -> #N/A | M5: 1400000001
A6: 1800000003 | B6: DR | C6: 45692 | D6: NA | E6: 246779410003 | F6: USD | G6: 50.75 | H6: INR | I6: 4379.91 | J6: Towards Fixed charges for the month of August2024 | K6: {=VLOOKUP(E6,'Customer Data'!$B$1:$F$58,{3,4},0)} -> #N/A
A7: 1800000002 | B7: DR | C7: 45692 | D7: NA | E7: 246779410002 | F7: USD | G7: 50.75 | H7: INR | I7: 4379.91 | J7: Towards Fixed charges for the month of August2024 | K7: {=VLOOKUP(E7,'Customer Data'!$B$1:$F$58,{3,4},0)} -> #N/A | M7: 1400000001
A8: 1400000000 | B8: DY | C8: 45693 | D8: knock off entry | E8: KNOCK OFF ENTRY | F8: USD | G8: 50.75 | H8: INR | I8: 4299.63 | K8: {=VLOOKUP(E8,'Customer Data'!$B$1:$F$58,{3,4},0)} -> #N/A | M8: 1400000000
A9: 1400000000 | B9: DY | C9: 45693 | D9: knock off entry | E9: KNOCK OFF ENTRY | F9: USD | G9: -50.75 | H9: INR | I9: -4299.63 | K9: {=VLOOKUP(E9,'Customer Data'!$B$1:$F$58,{3,4},0)} -> #N/A | M9: 1400000000
A10: 1600000001 | B10: DG | C10: 45693 | D10: NA | E10: 246779420002 | F10: USD | G10: -50.75 | H10: INR | I10: -4299.63 | J10: Credit Note Against Inv. 246779410001 | K10: {=VLOOKUP(E10,'Customer Data'!$B$1:$F$58,{3,4},0)} -> #N/A | M10: 1400000000
A11: 1600000000 | B11: DG | C11: 45693 | D11: NA | E11: 246779420001 | F11: USD | G11: -50.75 | H11: INR | I11: -4379.91 | J11: Credit Against Invoice 246779410002 | K11: {=VLOOKUP(E11,'Customer Data'!$B$1:$F$58,{3,4},0)} -> #N/A | M11: 1400000001
A12: 1800000091 | B12: DR | C12: 45708 | D12: NA | E12: 246779410304 | F12: USD | G12: 50.75 | H12: INR | I12: 4379.91 | J12: Fixed Rental charges for Oct 2024 | K12: {=VLOOKUP(E12,'Customer Data'!$B$1:$F$58,{3,4},0)} -> 0 | L12: 45.75 | M12: 1400000004
A13: 1800000320 | B13: DR | C13: 45708 | D13: NA | E13: 246779410247 | F13: USD | G13: 50.75 | H13: INR | I13: 4379.91 | J13: Fixed Rental charges for Feb 2025 | K13: {=VLOOKUP(E13,'Customer Data'!$B$1:$F$58,{3,4},0)} -> 0 | L13: 45.75 | M13: 1400000004
A14: 1800000277 | B14: DR | C14: 45708 | D14: NA | E14: 246779410204 | F14: USD | G14: 50.75 | H14: INR | I14: 4379.91 | J14: Fixed Rental charges for Jan 2025 | K14: {=VLOOKUP(E14,'Customer Data'!$B$1:$F$58,{3,4},0)} -> 0 | L14: 45.75 | M14: 1400000004
A15: 1800000234 | B15: DR | C15: 45708 | D15: NA | E15: 246779410161 | F15: USD | G15: 50.75 | H15: INR | I15: 4379.91 | J15: Fixed Rental charges for Dec 2024 | K15: {=VLOOKUP(E15,'Customer Data'!$B$1:$F$58,{3,4},0)} -> 0 | L15: 45.75 | M15: 1400000004
A16: 1800000191 | B16: DR | C16: 45708 | D16: NA | E16: 246779410118 | F16: USD | G16: 50.75 | H16: INR | I16: 4379.91 | J16: Fixed Rental charges for Nov 2024 | K16: {=VLOOKUP(E16,'Customer Data'!$B$1:$F$58,{3,4},0)} -> 0 | L16: 45.75 | M16: 1400000004
A17: 1800000028 | B17: DR | C17: 45708 | D17: NA | E17: 246779410073 | F17: USD | G17: 50.75 | H17: INR | I17: 4379.91 | J17: Fixed Rental charges for Aug 2024 | K17: {=VLOOKUP(E17,'Customer Data'!$B$1:$F$58,{3,4},0)} -> #N/A | M17: 1400000789
A18: 1800000122 | B18: DR | C18: 45708 | D18: NA | E18: 246779410050 | F18: USD | G18: 50.75 | H18: INR | I18: 4379.91 | J18: Fixed Rental charges for Sept 2024 | K18: {=VLOOKUP(E18,'Customer Data'!$B$1:$F$58,{3,4},0)} -> 0 | L18: 45.75 | M18: 1400000004
A19: 1800003142 | B19: DR | C19: 45735 | D19: NA | E19: 246779413009 | F19: USD | G19: 50.75 | H19: INR | I19: 4399.58 | J19: Fixed Storage Charges for Mar 2025 | K19: {=VLOOKUP(E19,'Customer Data'!$B$1:$F$58,{3,4},0)} -> 0 | L19: 45.75
A20: 1400000004 | B20: DZ | C20: 45743 | D20: INDBN52025032607043264 | F20: INR | G20: -302.06276 | H20: INR | I20: -26279.46 | J20: INDBN52025032607043264 | K20: {=VLOOKUP(E20,'Customer Data'!$B$1:$F$58,{3,4},0)} -> #N/A | M20: 1400000004 | N20: USD Amount taken from Payt Reco
A21: 1800005400 | B21: DR | C21: 45750 | D21: NA | E21: 256779410292 | F21: USD | G21: 50.75 | H21: INR | I21: 4411.28 | J21: Fixed Rental charges for Feb 2025 | K21: {=VLOOKUP(E21,'Customer Data'!$B$1:$F$58,{3,4},0)} -> #N/A | M21: 1400000789
A22: 1800005359 | B22: DR | C22: 45750 | D22: NA | E22: 256779410251 | F22: USD | G22: 50.75 | H22: INR | I22: 4411.28 | J22: Fixed Rental charges for Jan 2025 | K22: {=VLOOKUP(E22,'Customer Data'!$B$1:$F$58,{3,4},0)} -> #N/A | M22: 1400000789
A23: 1800007279 | B23: DR | C23: 45768 | D23: NA | E23: 256779412170 | F23: USD | G23: 50.75 | H23: INR | I23: 4354.86 | J23: Fixed Storage Charges for April 2025 | K23: {=VLOOKUP(E23,'Customer Data'!$B$1:$F$58,{3,4},0)} -> 0 | L23: 45.75
A24: 1800008368 | B24: DR | C24: 45787 | D24: NA | E24: 256779413251 | F24: USD | G24: 87.01 | H24: INR | I24: 7481.44 | J24: Weighment-16-30 April25, Ex.Rate-85.05 | K24: {=VLOOKUP(E24,'Customer Data'!$B$1:$F$58,{3,4},0)} -> #N/A
A25: 1800008359 | B25: DR | C25: 45787 | D25: NA | E25: 256779413242 | F25: USD | G25: 1194.92 | H25: INR | I25: 102743.64 | J25: VAS - 16-30 April 25, Ex.Rate-85.05 | K25: {=VLOOKUP(E25,'Customer Data'!$B$1:$F$58,{3,4},0)} -> 0 | L25: 1170.92
A26: 1800008288 | B26: DR | C26: 45787 | D26: NA | E26: 256779413171 | F26: USD | G26: 112.8 | H26: INR | I26: 9698.96 | J26: CODC Out chgs - 16 - 30 Apr 25 | K26: {=VLOOKUP(E26,'Customer Data'!$B$1:$F$58,{3,4},0)} -> 0 | L26: 110.8
A27: 1800008279 | B27: DR | C27: 45787 | D27: NA | E27: 256779413162 | F27: USD | G27: 131.6 | H27: INR | I27: 11315.45 | J27: CODC Inbound chgs - 16 - 30 Apr 25 | K27: {=VLOOKUP(E27,'Customer Data'!$B$1:$F$58,{3,4},0)} -> 0 | L27: 128.6
A28: 1800008244 | B28: DR | C28: 45787 | D28: NA | E28: 256779413128 | F28: USD | G28: 50.75 | H28: INR | I28: 4363.67 | J28: Fixed Storage Charges fo MAY 2025 | K28: {=VLOOKUP(E28,'Customer Data'!$B$1:$F$58,{3,4},0)} -> 0 | L28: 45.75
A29: 1600000803 | B29: DG | C29: 45791 | D29: NA | E29: 256779420512 | F29: USD | G29: -50.75 | H29: INR | I29: -4411.28 | J29: Credit note against 256779410251 | K29: {=VLOOKUP(E29,'Customer Data'!$B$1:$F$58,{3,4},0)} -> #N/A | M29: 1400000789
A30: 1600000716 | B30: DG | C30: 45791 | D30: NA | E30: 256779420425 | F30: USD | G30: -50.75 | H30: INR | I30: -4411.28 | J30: Credit note against 256779410292 | K30: {=VLOOKUP(E30,'Customer Data'!$B$1:$F$58,{3,4},0)} -> #N/A | M30: 1400000789
A31: 1800009076 | B31: DR | C31: 45797 | D31: NA | E31: 256779413840 | F31: USD | G31: 42.14 | H31: INR | I31: 3623.35 | J31: Weighment & Misc, 1-15 May 25 | K31: {=VLOOKUP(E31,'Customer Data'!$B$1:$F$58,{3,4},0)} -> 0 | L31: 41.14
A32: 1800009072 | B32: DR | C32: 45797 | D32: NA | E32: 256779413836 | F32: USD | G32: 793.07 | H32: INR | I32: 68191.09 | J32: VAS -1-15 May 25, Ex.rate 85.43 | K32: {=VLOOKUP(E32,'Customer Data'!$B$1:$F$58,{3,4},0)} -> 16 | L32: 793.07
A33: 1800008662 | B33: DR | C33: 45798 | D33: NA | E33: 256779413426 | F33: USD | G33: 2.35 | H33: INR | I33: 202.06 | J33: OutKPI-CODC-1-15-MAY-25-1608594 | K33: {=VLOOKUP(E33,'Customer Data'!$B$1:$F$58,{3,4},0)} -> 0 | L33: 2.35
A34: 1800008661 | B34: DR | C34: 45798 | D34: NA | E34: 256779413425 | F34: USD | G34: 37.6 | H34: INR | I34: 3232.99 | J34: OutKPI-CODC-1-15-MAY-25-1478252 | K34: {=VLOOKUP(E34,'Customer Data'!$B$1:$F$58,{3,4},0)} -> 0 | L34: 36.6
A35: 1600001070 | B35: DG | C35: 45799 | D35: NA | E35: 256779420758 | F35: USD | G35: -50.75 | H35: INR | I35: -4379.91 | J35: Credit Note against 246779410002 | K35: {=VLOOKUP(E35,'Customer Data'!$B$1:$F$58,{3,4},0)} -> #N/A
A36: 1600001069 | B36: DG | C36: 45799 | D36: NA | E36: 256779420757 | F36: USD | G36: -50.75 | H36: INR | I36: -4379.91 | J36: Credit Note against 246779410073 | K36: {=VLOOKUP(E36,'Customer Data'!$B$1:$F$58,{3,4},0)} -> #N/A | M36: 1400000789
A37: 1800009134 | B37: DR | C37: 45805 | D37: NA | E37: 256779413898 | F37: USD | G37: 928.64 | H37: INR | I37: 79847.9 | J37: Storage Chgs - 01 - 31 Apr 25 | K37: {=VLOOKUP(E37,'Customer Data'!$B$1:$F$58,{3,4},0)} -> #N/A
A38: 1800009191 | B38: DR | C38: 45810 | D38: NA | E38: 256779413955 | F38: USD | G38: 50.75 | H38: INR | I38: 4338.66 | J38: Towards Fixed charges for the month of A | K38: {=VLOOKUP(E38,'Customer Data'!$B$1:$F$58,{3,4},0)} -> #N/A
A39: 1800009181 | B39: DR | C39: 45810 | D39: NA | E39: 256779413945 | F39: USD | G39: 50.75 | H39: INR | I39: 4338.66 | J39: Fixed Rental charges for Aug 2024 | K39: {=VLOOKUP(E39,'Customer Data'!$B$1:$F$58,{3,4},0)} -> #N/A
A40: 1800009477 | B40: DR | C40: 45815 | D40: NA | E40: 256779414241 | F40: USD | G40: 632.96 | H40: INR | I40: 54112.24 | J40: Unit storage -1-31 May 25 | K40: {=VLOOKUP(E40,'Customer Data'!$B$1:$F$58,{3,4},0)} -> #N/A
A41: 1800009623 | B41: DR | C41: 45818 | D41: NA | E41: 256779414387 | F41: USD | G41: 50.75 | H41: INR | I41: 4338.66 | J41: Fixed Storage Charges fo JUNE 2025 | K41: {=VLOOKUP(E41,'Customer Data'!$B$1:$F$58,{3,4},0)} -> 0 | L41: 45.75
...

Sheet Invoices not in customers books
A2: Document Number | B2: Document Type | C2: Document Date | D2: Document Header Text | E2: Reference | F2: Document Currency Key | G2: Document Currency Value | H2: Company Code Currency Key | I2: Company Code Currency Value | J2: Remarks | K2: Purchase voucher no | L2: Remarks | M2: Debit | N2: Credit | O2: Updated Ledger Xlooup | P2: TDS | Q2: Rate
A3: 1800014973 | B3: DR | C3: 45981 | D3: NA | E3: 256779419471 | F3: USD | G3: 20.28 | H3: INR | I3: 1784.71 | J3: Weighment-Nov 1-15, 2025 | K3: PU/26/SCP/OT/0834 | M3: {=_xlfn.XLOOKUP(E3,'Updated Customer Ledger'!$C:$C,'Updated Customer Ledger'!$D:$E,,0)} -> 0 | N3: 20.28 | O3: =N3-M3 -> 20.28 | P3: =G3-O3 -> 0 | Q3: =P3/G3 -> 0
A4: 1800000003 | B4: DR | C4: 45692 | D4: NA | E4: 246779410003 | F4: USD | G4: 50.75 | H4: INR | I4: 4379.91 | J4: Towards Fixed charges for the month of August2024 | K4: pending | L4: Fixed Storage for Aug'24 already invoiced (256779413955) | M4: {=_xlfn.XLOOKUP(E4,'Updated Customer Ledger'!$C:$C,'Updated Customer Ledger'!$D:$E,,0)} -> #N/A | O4: =N4-M4 -> #N/A | P4: =G4-O4 -> #N/A | Q4: =P4/G4 -> #N/A
A5: 1800010437 | B5: DR | C5: 45842 | D5: NA | E5: 256779415197 | F5: USD | G5: 492.25 | H5: INR | I5: 42333.83 | J5: Unit Storage - 1-30 June 25 | K5: PU/26/SCP/OT/0929 | M5: {=_xlfn.XLOOKUP(E5,'Updated Customer Ledger'!$C:$C,'Updated Customer Ledger'!$D:$E,,0)} -> 49 | N5: 492.25 | O5: =N5-M5 -> 443.25 | P5: =G5-O5 -> 49 | Q5: =P5/G5 -> 0.099542915
A6: 1800010502 | B6: DR | C6: 45842 | D6: NA | E6: 256779415262 | F6: USD | G6: 476.32 | H6: INR | I6: 40963.84 | J6: VAS - 16-30 June 25 | K6: PU/26/SCP/OT/0840 | M6: {=_xlfn.XLOOKUP(E6,'Updated Customer Ledger'!$C:$C,'Updated Customer Ledger'!$D:$E,,0)} -> 10 | N6: 476.32 | O6: =N6-M6 -> 466.32 | P6: =G6-O6 -> 10 | Q6: =P6/G6 -> 0.02099429
A7: 1800014289 | B7: DR | C7: 45966 | D7: NA | E7: 256779418826 | F7: USD | G7: 60.86 | H7: INR | I7: 5355.89 | J7: WEIGHTMENT-16 -31 Oct 25 | K7: PU/26/SCP/OT/0841 | M7: {=_xlfn.XLOOKUP(E7,'Updated Customer Ledger'!$C:$C,'Updated Customer Ledger'!$D:$E,,0)} -> 1 | N7: 60.86 | O7: =N7-M7 -> 59.86 | P7: =G7-O7 -> 1 | Q7: =P7/G7 -> 0.016431153
A8: 1800014554 | B8: DR | C8: 45966 | D8: NA | E8: 256779418886 | F8: USD | G8: 1457.24 | H8: INR | I8: 128242.06 | J8: Unit Storage - 1-31 Oct 2025 | K8: PU/26/SCP/OT/0924 | M8: {=_xlfn.XLOOKUP(E8,'Updated Customer Ledger'!$C:$C,'Updated Customer Ledger'!$D:$E,,0)} -> 146 | N8: 1457.24 | O8: =N8-M8 -> 1311.24 | P8: =G8-O8 -> 146 | Q8: =P8/G8 -> 0.1001894
A9: 1800009181 | B9: DR | C9: 45810 | D9: NA | E9: 256779413945 | F9: USD | G9: 50.75 | H9: INR | I9: 4338.66 | J9: Fixed Rental charges for Aug 2024 | K9: pending | L9: Fixed Storage for Aug'24 already invoiced (256779413955) | M9: {=_xlfn.XLOOKUP(E9,'Updated Customer Ledger'!$C:$C,'Updated Customer Ledger'!$D:$E,,0)} -> #N/A | O9: =N9-M9 -> #N/A | P9: =G9-O9 -> #N/A | Q9: =P9/G9 -> #N/A
A10: 1800011657 | B10: DR | C10: 45877 | D10: NA | E10: 256779416087 | F10: USD | G10: 916.56 | H10: INR | I10: 78851.77 | J10: Unit Storage - 1-31 July 25 | K10: PU/26/SCP/OT/0928 | M10: {=_xlfn.XLOOKUP(E10,'Updated Customer Ledger'!$C:$C,'Updated Customer Ledger'!$D:$E,,0)} -> 92 | N10: 916.56 | O10: =N10-M10 -> 824.56 | P10: =G10-O10 -> 92 | Q10: =P10/G10 -> 0.10037532
A11: 1800009134 | B11: DR | C11: 45805 | D11: NA | E11: 256779413898 | F11: USD | G11: 928.64 | H11: INR | I11: 79847.9 | J11: Storage Chgs - 01 - 31 Apr 25 | K11: PU/26/SCP/OT/0931 | M11: {=_xlfn.XLOOKUP(E11,'Updated Customer Ledger'!$C:$C,'Updated Customer Ledger'!$D:$E,,0)} -> 93 | N11: 928.64 | O11: =N11-M11 -> 835.64 | P11: =G11-O11 -> 93 | Q11: =P11/G11 -> 0.10014645
A12: 1800009191 | B12: DR | C12: 45810 | D12: NA | E12: 256779413955 | F12: USD | G12: 50.75 | H12: INR | I12: 4338.66 | J12: Towards Fixed charges for the month of August2024 | K12: pending | L12: Fixed Storage for Aug'24 already invoiced (256779413955) | M12: {=_xlfn.XLOOKUP(E12,'Updated Customer Ledger'!$C:$C,'Updated Customer Ledger'!$D:$E,,0)} -> #N/A | O12: =N12-M12 -> #N/A | P12: =G12-O12 -> #N/A | Q12: =P12/G12 -> #N/A
A13: 1800011070 | B13: DR | C13: 45862 | D13: NA | E13: 256779415830 | F13: USD | G13: 50.75 | H13: INR | I13: 4364.53 | J13: Debit Note against 246779420001 | K13: #N/A | L13: Invoices not received | M13: {=_xlfn.XLOOKUP(E13,'Updated Customer Ledger'!$C:$C,'Updated Customer Ledger'!$D:$E,,0)} -> #N/A | O13: =N13-M13 -> #N/A | P13: =G13-O13 -> #N/A | Q13: =P13/G13 -> #N/A
A14: 1800013944 | B14: DR | C14: 45951 | D14: NA | E14: 256779418476 | F14: USD | G14: 950.87 | H14: INR | I14: 83857.96 | J14: VAS -1-15 Oct 2025 | K14: PU/26/SCP/OT/0839 | M14: {=_xlfn.XLOOKUP(E14,'Updated Customer Ledger'!$C:$C,'Updated Customer Ledger'!$D:$E,,0)} -> 19 | N14: 950.87 | O14: =N14-M14 -> 931.87 | P14: =G14-O14 -> 19 | Q14: =P14/G14 -> 0.019981701
A15: 1800014962 | B15: DR | C15: 45981 | D15: NA | E15: 256779419463 | F15: USD | G15: 602.03 | H15: INR | I15: 52980.68 | J15: VAS-Nov 1-15, 2025 | K15: PU/26/SCP/OT/0838 | M15: {=_xlfn.XLOOKUP(E15,'Updated Customer Ledger'!$C:$C,'Updated Customer Ledger'!$D:$E,,0)} -> 12 | N15: 602.03 | O15: =N15-M15 -> 590.03 | P15: =G15-O15 -> 12 | Q15: =P15/G15 -> 0.019932562
A16: 1800015032 | B16: DR | C16: 45981 | D16: NA | E16: 256779419533 | F16: USD | G16: 131.6 | H16: INR | I16: 11581.25 | J16: CODC Inbound chgs - 1-15 Nov 25 | K16: PU/26/SCP/OT/0842 | M16: {=_xlfn.XLOOKUP(E16,'Updated Customer Ledger'!$C:$C,'Updated Customer Ledger'!$D:$E,,0)} -> 3 | N16: 131.6 | O16: =N16-M16 -> 128.6 | P16: =G16-O16 -> 3 | Q16: =P16/G16 -> 0.022796353
A17: 1800015095 | B17: DR | C17: 45981 | D17: NA | E17: 256779419546 | F17: USD | G17: 56.4 | H17: INR | I17: 4963.39 | J17: CODC Out chgs -1-15 Nov 25 | K17: PU/26/SCP/OT/0845 | M17: {=_xlfn.XLOOKUP(E17,'Updated Customer Ledger'!$C:$C,'Updated Customer Ledger'!$D:$E,,0)} -> 1 | N17: 56.4 | O17: =N17-M17 -> 55.4 | P17: =G17-O17 -> 1 | Q17: =P17/G17 -> 0.017730496
A18: 1800011071 | B18: DR | C18: 45862 | D18: NA | E18: 256779415831 | F18: USD | G18: 50.75 | H18: INR | I18: 4364.53 | J18: Debit Note against 246779420002 | K18: #N/A | L18: Invoices not received | M18: {=_xlfn.XLOOKUP(E18,'Updated Customer Ledger'!$C:$C,'Updated Customer Ledger'!$D:$E,,0)} -> #N/A | O18: =N18-M18 -> #N/A | P18: =G18-O18 -> #N/A | Q18: =P18/G18 -> #N/A
A19: 1800016281 | B19: DR | C19: 46028 | D19: 2158342 | E19: 256779440161 | F19: USD | G19: 56.74 | H19: INR | I19: 5148.77 | J19: PORT SSR Chgs Dec 25 | K19: pending | L19: PORT SSR Chgs Dec 25 | M19: {=_xlfn.XLOOKUP(E19,'Updated Customer Ledger'!$C:$C,'Updated Customer Ledger'!$D:$E,,0)} -> #N/A | O19: =N19-M19 -> #N/A | P19: =G19-O19 -> #N/A | Q19: =P19/G19 -> #N/A
A20: 1800014728 | B20: DR | C20: 45966 | D20: 2123630 | E20: 256779419229 | F20: USD | G20: 77.07 | H20: INR | I20: 6782.42 | J20: PORT SSR Chgs Oct 25 | K20: pending | L20: PORT SSR Chgs Oct 25 Not to be booked | M20: {=_xlfn.XLOOKUP(E20,'Updated Customer Ledger'!$C:$C,'Updated Customer Ledger'!$D:$E,,0)} -> #N/A | O20: =N20-M20 -> #N/A | P20: =G20-O20 -> #N/A | Q20: =P20/G20 -> #N/A
A21: 1800011010 | B21: DR | C21: 45857 | D21: NA | E21: 256779415770 | F21: USD | G21: 1425.77 | H21: INR | I21: 122617.18 | J21: VAS - 1-15 July 25 | K21: pending | L21: val diff as per anexure & Inv | M21: {=_xlfn.XLOOKUP(E21,'Updated Customer Ledger'!$C:$C,'Updated Customer Ledger'!$D:$E,,0)} -> 65 | N21: 1425.77 | O21: =N21-M21 -> 1360.77 | P21: =G21-O21 -> 65 | Q21: =P21/G21 -> 0.045589401
A22: 1800012870 | B22: DR | C22: 45918 | D22: NA | E22: 256779417488 | F22: USD | G22: 52.64 | H22: INR | I22: 4606.75 | J22: CY Ground rent Chgs - 01 - 15 Sep 25 | K22: pending | L22: Towards SCOPE Logistics Shipment; not to be invoiced in SCOPE Chemicals | M22: {=_xlfn.XLOOKUP(E22,'Updated Customer Ledger'!$C:$C,'Updated Customer Ledger'!$D:$E,,0)} -> #N/A | O22: =N22-M22 -> #N/A | P22: =G22-O22 -> #N/A | Q22: =P22/G22 -> #N/A
A23: 1800014002 | B23: DR | C23: 45948 | D23: NA | E23: 256779418426 | F23: USD | G23: 124.55 | H23: INR | I23: 10984.16 | J23: CODC LCL Chgs -1-15 Oct 25 | K23: PU/26/SCP/OT/0846 | M23: {=_xlfn.XLOOKUP(E23,'Updated Customer Ledger'!$C:$C,'Updated Customer Ledger'!$D:$E,,0)} -> 2 | N23: 124.55 | O23: =N23-M23 -> 122.55 | P23: =G23-O23 -> 2 | Q23: =P23/G23 -> 0.016057808
A24: 1800014149 | B24: DR | C24: 45948 | D24: NA | E24: 256779418441 | F24: USD | G24: 112.8 | H24: INR | I24: 9947.92 | J24: CODC Out chgs -1-15 Oct 25 | K24: PU/26/SCP/OT/0847 | M24: {=_xlfn.XLOOKUP(E24,'Updated Customer Ledger'!$C:$C,'Updated Customer Ledger'!$D:$E,,0)} -> 2 | N24: 112.8 | O24: =N24-M24 -> 110.8 | P24: =G24-O24 -> 2 | Q24: =P24/G24 -> 0.017730496
A25: 1800009477 | B25: DR | C25: 45815 | D25: NA | E25: 256779414241 | F25: USD | G25: 632.96 | H25: INR | I25: 54112.24 | J25: Unit storage -1-31 May 25 | K25: PU/26/SCP/OT/0930 | M25: {=_xlfn.XLOOKUP(E25,'Updated Customer Ledger'!$C:$C,'Updated Customer Ledger'!$D:$E,,0)} -> 63 | N25: 632.96 | O25: =N25-M25 -> 569.96 | P25: =G25-O25 -> 63 | Q25: =P25/G25 -> 0.099532356
A26: 1800013273 | B26: DR | C26: 45936 | D26: NA | E26: 256779418009 | F26: USD | G26: 1480.75 | H26: INR | I26: 130588.48 | J26: Unit Storage - 1-30 Sept 2025 | K26: PU/26/SCP/OT/0926 | M26: {=_xlfn.XLOOKUP(E26,'Updated Customer Ledger'!$C:$C,'Updated Customer Ledger'!$D:$E,,0)} -> 30 | N26: 1480.75 | O26: =N26-M26 -> 1450.75 | P26: =G26-O26 -> 30 | Q26: =P26/G26 -> 0.020260003
A27: 1800013396 | B27: DR | C27: 45935 | D27: NA | E27: 256779417991 | F27: USD | G27: 184.54 | H27: INR | I27: 16274.72 | J27: CY - CY Grd Rent Chgs - 16 - 30 SEP 25 | K27: pending | L27: Towards SCOPE Logistics Shipment; not to be invoiced in SCOPE Chemicals | M27: {=_xlfn.XLOOKUP(E27,'Updated Customer Ledger'!$C:$C,'Updated Customer Ledger'!$D:$E,,0)} -> #N/A | O27: =N27-M27 -> #N/A | P27: =G27-O27 -> #N/A | Q27: =P27/G27 -> #N/A
A28: 1800012475 | B28: DR | C28: 45906 | D28: NA | E28: 256779417083 | F28: USD | G28: 634.36 | H28: INR | I28: 55515.59 | J28: Unit-Storage-1-31 Aug 25 | K28: PU/26/SCP/OT/0927 | M28: {=_xlfn.XLOOKUP(E28,'Updated Customer Ledger'!$C:$C,'Updated Customer Ledger'!$D:$E,,0)} -> 63 | N28: 634.36 | O28: =N28-M28 -> 571.36 | P28: =G28-O28 -> 63 | Q28: =P28/G28 -> 0.099312693
A29: 1800015688 | B29: DR | C29: 46024 | D29: NA | E29: 256779440021 | F29: USD | G29: 950.6 | H29: INR | I29: 86260.43 | J29: Unit Storage - 1-30 Nov 2025 | K29: PU/26/SCP/OT/0923 | M29: {=_xlfn.XLOOKUP(E29,'Updated Customer Ledger'!$C:$C,'Updated Customer Ledger'!$D:$E,,0)} -> 95 | N29: 950.6 | O29: =N29-M29 -> 855.6 | P29: =G29-O29 -> 95 | Q29: =P29/G29 -> 0.099936882
A30: 1800008368 | B30: DR | C30: 45787 | D30: NA | E30: 256779413251 | F30: USD | G30: 87.01 | H30: INR | I30: 7481.44 | J30: Weighment-16-30 April25, Ex.Rate-85.05 | K30: pending | L30: Why is royalty charged | M30: {=_xlfn.XLOOKUP(E30,'Updated Customer Ledger'!$C:$C,'Updated Customer Ledger'!$D:$E,,0)} -> #N/A | O30: =N30-M30 -> #N/A | P30: =G30-O30 -> #N/A | Q30: =P30/G30 -> #N/A
A31: 1800016318 | B31: DR | C31: 46034 | D31: 2158401 | E31: 256779440171 | F31: USD | G31: 180.4 | H31: INR | I31: 16370.06 | J31: CODC LCL Chgs -16-31 DEC 25 | K31: PU/26/SCP/OT/0833 | M31: {=_xlfn.XLOOKUP(E31,'Updated Customer Ledger'!$C:$C,'Updated Customer Ledger'!$D:$E,,0)} -> 4 | N31: 180.4 | O31: =N31-M31 -> 176.4 | P31: =G31-O31 -> 4 | Q31: =P31/G31 -> 0.022172949
A32: 1800016359 | B32: DR | C32: 46028 | D32: 2158411 | E32: 256779440249 | F32: USD | G32: 1037.05 | H32: INR | I32: 94105.17 | J32: Unit Storage - 1-31 DEC 2025 | K32: PU/26/SCP/OT/0922 | M32: {=_xlfn.XLOOKUP(E32,'Updated Customer Ledger'!$C:$C,'Updated Customer Ledger'!$D:$E,,0)} -> 104 | N32: 1037 | O32: =N32-M32 -> 933 | P32: =G32-O32 -> 104.05 | Q32: =P32/G32 -> 0.10033267
A33: 1800016692 | B33: DR | C33: 46034 | D33: 2158638 | E33: 256779440281 | F33: USD | G33: 933.73 | H33: INR | I33: 84729.59 | J33: VAS-Dec 25 - 16-31 | K33: PU/26/SCP/OT/0837 | M33: {=_xlfn.XLOOKUP(E33,'Updated Customer Ledger'!$C:$C,'Updated Customer Ledger'!$D:$E,,0)} -> 19 | N33: 933.73 | O33: =N33-M33 -> 914.73 | P33: =G33-O33 -> 19 | Q33: =P33/G33 -> 0.020348495
A34: 1800016703 | B34: DR | C34: 46034 | D34: 2158638 | E34: 256779440292 | F34: USD | G34: 40.04 | H34: INR | I34: 3633.36 | J34: Weighment-Dec 25 - 16-31 | K34: PU/26/SCP/OT/0830 | M34: {=_xlfn.XLOOKUP(E34,'Updated Customer Ledger'!$C:$C,'Updated Customer Ledger'!$D:$E,,0)} -> 1 | N34: 40.04 | O34: =N34-M34 -> 39.04 | P34: =G34-O34 -> 1 | Q34: =P34/G34 -> 0.024975025
G35: =SUM(G3:G34)-0.46 -> 14357.35

Sheet Difference in Invoice value
A2: Document Number | B2: Document Type | C2: Reference | D2: Document Currency Value | E2: Company Code Currency Value | F2: Remarks | G2: Credit | H2: Difference | I2: Purchase voucher no | J2: Booking Date | K2: TDS @2% | L2: Net payable
A3: 1800016772 | B3: DR | C3: 256779440359 | D3: 821.64 | E3: 74558.19 | F3: VAS - NOV 25,16-30 | G3: 40.04 | H3: =D3-G3 -> 781.6 | I3: PU/26/SCP/OT/0835 | J3: 46069 | K3: =D3*2% -> 16.4328 | L3: =D3-K3 -> 805.2072
A4: 1800016783 | B4: DR | C4: 256779440370 | D4: 60.36 | E4: 5477.26 | F4: Weighment -NOV 25,16-30 | G4: 63.21 | H4: =D4-G4 -> -2.85 | I4: PU/26/SCP/OT/0827-1 | J4: 46065 | K4: 1 | L4: =D4-K4 -> 59.36 | M4: now corrected
H5: =SUM(H3:H4) -> 778.75
