Workbook

Sheet Summary
A1: Reconciliation of Ledger as on 31st January 2026
A2: Particulars | B2: Amount
A3: Balance as per Scope Chemicals Pvt Ltd | B3: =-'Customer Data'!E389 -> 1489274.5
A4: Add: TDS to be booked in Ascendus books | B4: ='TDS to be recorded '!#REF! -> #REF!
A5: Add: Invoices & CN not recorded in customer books | B5: ='Invoice&DN in Customer''s ledger'!#REF! -> #REF!
A6: Add: Diffrence of invoice value in both Books | B6: ='Diffrence in Invoice value'!M28 -> 0
A7: Add: Knock off entries difference | B7: ='Knock off entries difference'!H1 -> -1093.08
A8: Derived balance | B8: =SUM(B3:B6) -> #REF!
A9: Balance as per Ascent | B9: ='Ascendus Data'!U476 -> 4683369.6
A11: Difference | B11: =B8-B9-B10 -> #REF!

Sheet Payment Reco

Sheet Sheet2
A1: Posting Date | B1: Debit (INR) | C1: Credit (INR) | D1: Balance (INR) | E1: Voucher No | F1: Against Account | G1: Against Voucher | H1: Supplier Invoice No
A2: 45854 | B2: 19430 | C2: 0 | D2: -1612920.6 | E2: SLS26/MF/DN/0006 | F2: Storage Charges - Cargo - SLSIPL | G2: PU/26/SLS/OT/0590 | H2: DN | I2: 246779413705
A3: 45854 | B3: 18611 | C3: 0 | D3: -1594309.6 | E3: SLS26/MF/DN/0008 | F3: Container Scanning Paid - SLSIPL | G3: PU/25/SLS/OT/1821 | H3: DN | I3: 246779413816
A4: 45854 | B4: 31723 | C4: 0 | D4: -1562586.6 | E4: SLS26/MF/DN/0009 | F4: Container Scanning Paid - SLSIPL | G4: PU/25/SLS/OT/1822 | H4: DN | I4: 246779413827
A5: 45854 | B5: 17857 | C5: 0 | D5: -1544729.6 | E5: SLS26/MF/DN/0011 | F5: Container Scanning Paid - SLSIPL | G5: PU/25/SLS/OT/1854 | H5: DN | I5: 246779411339
A6: 45854 | B6: 11798 | C6: 0 | D6: -1532931.6 | E6: SLS26/MF/DN/0013 | F6: Container Scanning Paid - SLSIPL | G6: PU/26/SLS/OT/0283 | H6: DN | I6: 256779413283
A7: 45854 | B7: 20874 | C7: 0 | D7: -1512057.6 | E7: SLS26/MF/DN/0014 | F7: Container Scanning Paid - SLSIPL | G7: PU/25/SLS/OT/1820 | H7: DN | I7: 246779411326
A8: 45854 | B8: 140649 | C8: 0 | D8: -1371408.6 | E8: SLS26/MF/DN/0016 | F8: Storage Charges - Cargo - SLSIPL | G8: PU/26/SLS/OT/0612 | H8: DN | I8: 256779410010
A9: 45854 | B9: 55272 | C9: 0 | D9: -1316136.6 | E9: SLS26/MF/DN/0017 | F9: Storage Charges - Cargo - SLSIPL | G9: PU/26/SLS/OT/0613 | H9: DN | I9: 256779410004
A10: 45854 | B10: 4786 | C10: 0 | D10: -1311350.6 | E10: SLS26/MF/DN/0007-2 | F10: Storage Charges - Cargo - SLSIPL | G10: SLS26/MF/DN/0007-2 | H10: DN | I10: 256779421381
A11: 45854 | B11: 11955 | C11: 0 | D11: -1299395.6 | E11: SLS26/MF/DN/0004-1 | F11: Transportation Charges Paid - SLSIPL | G11: PU/26/SLS/OT/0588 | H11: DN | I11: 246779413845
A12: 45854 | B12: 12467 | C12: 0 | D12: -1450559.6 | E12: SLS26/MF/DN/0018-1 | F12: Storage Charges - Cargo - SLSIPL | G12: SLS26/MF/DN/0018-1 | H12: DN | I12: 256779421383
A13: 45854 | B13: 6084 | C13: 0 | D13: -1444475.6 | E13: SLS26/MF/DN/0002-1 | F13: Scanning Charges - Inbound - SLSIPL | G13: SLS26/MF/DN/0002-1 | H13: DN | I13: 256779421376
... A19: 45869 | B19: 33376 | C19: 0 | D19: -259448.6 | E19: SLS26/MF/DN/0019 | F19: Container Scanning Paid - SLSIPL | G19: PU/25/SLS/OT/1925 | H19: DN | I19: 246779411300
A20: 45869 | B20: 15778 | C20: 0 | D20: -243670.6 | E20: SLS26/MF/DN/0020-1 | F20: Storage Charges - Cargo - SLSIPL | G20: SLS26/MF/DN/0020-1 | H20: DN | I20: 246779410348/256779421380
A21: 45869 | B21: 36410 | C21: 0 | D21: -251862.6 | E21: SLS26/MF/DN/0022-1 | F21: Container Scanning Paid - SLSIPL | G21: SLS26/MF/DN/0022-1 | H21: DN | I21: 246779411278/256779421385
A22: 45869 | B22: 15401 | C22: 0 | D22: -236461.6 | E22: SLS26/MF/DN/0021-1 | F22: Fixed Storage Charges - ODC (Covered) - SLSIPL | G22: SLS26/MF/DN/0021-1 | H22: DN | I22: 256779421382/246779413701

Sheet Customer Data Vlookup
A2: Posting Date | B2: Debit (INR) | C2: Credit (INR) | D2: Balance (INR) | E2: Voucher No | F2: Against Account | G2: Against Voucher | H2: Supplier Invoice No | L2: Row Labels | M2: Sum of Debit (INR) | N2: Sum of Credit (INR) | P2: Row Labels | Q2: Sum of Debit (INR) | R2: Sum of Credit (INR)
A3: 45708 | B3: 0 | C3: 35554.52 | D3: -35554.52 | E3: PU/25/SLS/OT/1560 | F3: Fixed Storage Charges - ODC (Covered) - SLSIPL | G3: PU/25/SLS/OT/1560 | H3: 246779410049 | L3: 25677941807 | M3: 0 | N3: 1972 | P3: 25677941807 | Q3: 0 | R3: 1972
A4: 45708 | B4: 0 | C4: 35554.52 | D4: -71109.04 | E4: PU/25/SLS/OT/1561 | F4: Fixed Storage Charges - ODC (Covered) - SLSIPL | G4: PU/25/SLS/OT/1561 | H4: 246779410303 | L4: 246779410049 | M4: 0 | N4: 35554.52 | P4: 246779410049 | Q4: 0 | R4: 35554.52
A5: 45708 | B5: 0 | C5: 35554.52 | D5: -106663.56 | E5: PU/25/SLS/OT/1562 | F5: Fixed Storage Charges - ODC (Covered) - SLSIPL | G5: PU/25/SLS/OT/1562 | H5: 246779410117 | L5: 246779410072 | M5: 0 | N5: 35477 | P5: 246779410072 | Q5: 0 | R5: 35477
A6: 45708 | B6: 0 | C6: 35554.52 | D6: -142218.08 | E6: PU/25/SLS/OT/1563 | F6: Fixed Storage Charges - ODC (Covered) - SLSIPL | G6: PU/25/SLS/OT/1563 | H6: 246779410160 | L6: 246779410117 | M6: 0 | N6: 35554.52 | P6: 246779410117 | Q6: 0 | R6: 35554.52
A7: 45708 | B7: 0 | C7: 35554.52 | D7: -177772.6 | E7: PU/25/SLS/OT/1564 | F7: Fixed Storage Charges - ODC (Covered) - SLSIPL | G7: PU/25/SLS/OT/1564 | H7: 246779410203 | L7: 246779410160 | M7: 0 | N7: 35554.52 | P7: 246779410160 | Q7: 0 | R7: 35554.52
A8: 45708 | B8: 0 | C8: 35554.52 | D8: -213327.12 | E8: PU/25/SLS/OT/1565 | F8: Fixed Storage Charges - ODC (Covered) - SLSIPL | G8: PU/25/SLS/OT/1565 | H8: 246779410246 | L8: 246779410203 | M8: 0 | N8: 35554.52 | P8: 246779410203 | Q8: 0 | R8: 35554.52
A9: 45719 | B9: 0 | C9: 804 | D9: -214131.12 | E9: PU/25/SLS/OT/1672 | F9: Handling Charges - Outbound (Exp) - SLSIPL | G9: PU/25/SLS/OT/1672 | H9: 246779410613 | L9: 246779410246 | M9: 0 | N9: 35554.52 | P9: 246779410246 | Q9: 0 | R9: 35554.52
A10: 45719 | B10: 0 | C10: 1004 | D10: -215135.12 | E10: PU/25/SLS/OT/1673 | F10: Handling Charges - Outbound (Exp) - SLSIPL | G10: PU/25/SLS/OT/1673 | H10: 246779410612 | L10: 246779410303 | M10: 0 | N10: 35554.52 | P10: 246779410303 | Q10: 0 | R10: 35554.52
A11: 45719 | B11: 0 | C11: 402 | D11: -215537.12 | E11: PU/25/SLS/OT/1674 | F11: Handling Charges - Outbound (Exp) - SLSIPL | G11: PU/25/SLS/OT/1674 | H11: 246779410611 | L11: 246779410327 | M11: 0 | N11: 16480.711 | P11: 246779410327 | Q11: 0 | R11: 16480.711
A12: 45719 | B12: 0 | C12: 201 | D12: -215738.12 | E12: PU/25/SLS/OT/1675 | F12: Handling Charges - Outbound (Exp) - SLSIPL | G12: PU/25/SLS/OT/1675 | H12: 246779410610 | L12: 246779410333 | M12: 0 | N12: 29975.442 | P12: 246779410333 | Q12: 0 | R12: 29975.442
A13: 45719 | B13: 0 | C13: 804 | D13: -216542.12 | E13: PU/25/SLS/OT/1676 | F13: Handling Charges - Outbound (Exp) - SLSIPL | G13: PU/25/SLS/OT/1676 | H13: 246779410608 | L13: 246779410338 | M13: 0 | N13: 13859.78 | P13: 246779410338 | Q13: 0 | R13: 13859.78
A14: 45719 | B14: 0 | C14: 402 | D14: -216944.12 | E14: PU/25/SLS/OT/1677 | F14: Handling Charges - Outbound (Exp) - SLSIPL | G14: PU/25/SLS/OT/1677 | H14: 246779410607 | L14: 246779410339 | M14: 0 | N14: 44681.825 | P14: 246779410339 | Q14: 0 | R14: 44681.825
... A112: 45747 | B112: 0 | C112: 31723 | D112: -2522653.1 | E112: PU/25/SLS/OT/1823 | F112: Container Scanning Paid - SLSIPL | G112: PU/25/SLS/OT/1823 | H112: 246779413753 | L112: 246779411252 | M112: 0 | N112: 1907 | P112: 246779411252 | Q112: 0 | R112: 1907
A113: 45747 | B113: 0 | C113: 191 | D113: -2522844.1 | E113: PU/25/SLS/OT/1824 | F113: Handling Charges - Outbound (Exp) - SLSIPL | G113: PU/25/SLS/OT/1824 | H113: 246779413762 | L113: 246779411278 | P113: 246779411278 | Q113: 0 | R113: 44602
A114: 45747 | B114: 0 | C114: 3064 | D114: -2525908.1 | E114: PU/25/SLS/OT/1825 | F114: Handling Charges - Outbound (Exp) - SLSIPL | G114: PU/25/SLS/OT/1825 | H114: 246779413745 | L114: 246779411300 | M114: 0 | N114: 33376 | P114: 246779411300 | Q114: 33376 | R114: 33376
A115: 45747 | B115: 0 | C115: 3448 | D115: -2529356.1 | E115: PU/25/SLS/OT/1826 | F115: Handling Charges - Outbound (Exp) - SLSIPL | G115: PU/25/SLS/OT/1826 | H115: 246779413734 | L115: 246779411314 | M115: 0 | N115: 8522 | P115: 246779411314 | Q115: 0 | R115: 8522
A116: 45747 | B116: 0 | C116: 6513 | D116: -2535869.1 | E116: PU/25/SLS/OT/1827 | F116: Handling Charges - Outbound (Exp) - SLSIPL | G116: PU/25/SLS/OT/1827 | H116: 246779413736 | L116: 246779411326 | M116: 0 | N116: 20874 | P116: 246779411326 | Q116: 20874 | R116: 20874
A117: 45747 | B117: 0 | C117: 1724 | D117: -2537593.1 | E117: PU/25/SLS/OT/1828 | F117: Handling Charges - Outbound (Exp) - SLSIPL | G117: PU/25/SLS/OT/1828 | H117: 246779413739 | L117: 246779411339 | M117: 0 | N117: 17857 | P117: 246779411339 | Q117: 17857 | R117: 17857
A118: 45747 | B118: 0 | C118: 1149 | D118: -2538742.1 | E118: PU/25/SLS/OT/1829 | F118: Handling Charges - Outbound (Exp) - SLSIPL | G118: PU/25/SLS/OT/1829 | H118: 246779413742 | L118: 246779411448 | M118: 0 | N118: 1161 | P118: 246779411448 | Q118: 0 | R118: 1161
A119: 45747 | B119: 0 | C119: 191 | D119: -2538933.1 | E119: PU/25/SLS/OT/1830 | F119: Handling Charges - Outbound (Exp) - SLSIPL | G119: PU/25/SLS/OT/1830 | H119: 246779413692 | L119: 246779411619 | M119: 0 | N119: 143412 | P119: 246779411619 | Q119: 0 | R119: 143412
A120: 45747 | B120: 0 | C120: 6896 | D120: -2545829.1 | E120: PU/25/SLS/OT/1831 | F120: Handling Charges - Outbound (Exp) - SLSIPL | G120: PU/25/SLS/OT/1831 | H120: 246779413693 | L120: 246779411620 | M120: 0 | N120: 5816 | P120: 246779411620 | Q120: 0 | R120: 5816
A121: 45747 | B121: 0 | C121: 3448 | D121: -2549277.1 | E121: PU/25/SLS/OT/1832 | F121: Handling Charges - Outbound (Exp) - SLSIPL | G121: PU/25/SLS/OT/1832 | H121: 246779413694 | L121: 246779411755 | M121: 0 | N121: 5816 | P121: 246779411755 | Q121: 0 | R121: 5816
A122: 45747 | B122: 0 | C122: 191 | D122: -2549468.1 | E122: PU/25/SLS/OT/1833 | F122: Handling Charges - Outbound (Exp) - SLSIPL | G122: PU/25/SLS/OT/1833 | H122: 246779413695 | L122: 246779411756 | M122: 0 | N122: 4339 | P122: 246779411756 | Q122: 0 | R122: 4339
A123: 45747 | B123: 0 | C123: 382 | D123: -2549850.1 | E123: PU/25/SLS/OT/1834 | F123: Handling Charges - Outbound (Exp) - SLSIPL | G123: PU/25/SLS/OT/1834 | H123: 246779413696 | L123: 246779411757 | M123: 0 | N123: 3110 | P123: 246779411757 | Q123: 0 | R123: 3110
A124: 45747 | B124: 0 | C124: 381 | D124: -2550231.1 | E124: PU/25/SLS/OT/1835 | F124: Handling Charges - Outbound (Exp) - SLSIPL | G124: PU/25/SLS/OT/1835 | H124: 246779410846 | L124: 246779411758 | M124: 0 | N124: 1842 | P124: 246779411758 | Q124: 0 | R124: 1842
A125: 45747 | B125: 0 | C125: 1528 | D125: -2551759.1 | E125: PU/25/SLS/OT/1836 | F125: Handling Charges - Outbound (Exp) - SLSIPL | G125: PU/25/SLS/OT/1836 | H125: 246779410847 | L125: 246779411759 | M125: 0 | N125: 6761 | P125: 246779411759 | Q125: 0 | R125: 6761
... A147: 45747 | B147: 0 | C147: 33376 | D147: -2809572.1 | E147: PU/25/SLS/OT/1925 | F147: Container Scanning Paid - SLSIPL | G147: PU/25/SLS/OT/1925 | H147: 246779411300 | L147: 246779413701 | M147: 0 | N147: 18367 | P147: 246779413701 | Q147: 0 | R147: 18367
A148: 45748 | B148: 0 | C148: 1161 | D148: -2810733.1 | E148: PU/26/SLS/OT/0048 | F148: VOS Activity Charges Paid - SLSIPL | G148: PU/26/SLS/OT/0048 | H148: 246779411448 | L148: 246779413702 | P148: 246779413702 | Q148: 0 | R148: 31577
A149: 45748 | B149: 0 | C149: 1591 | D149: -2812324.1 | E149: PU/26/SLS/OT/0193 | F149: Handling Charges - Outbound (Exp) - SLSIPL | G149: PU/26/SLS/OT/0193 | H149: 246779413689 | L149: 246779413704 | M149: 0 | N149: 13011 | P149: 246779413704 | Q149: 0 | R149: 13011
A150: 45748 | B150: 0 | C150: 574 | D150: -2812898.1 | E150: PU/26/SLS/OT/0194 | F150: Handling Charges - Outbound (Exp) - SLSIPL | G150: PU/26/SLS/OT/0194 | H150: 246779413740 | L150: 246779413705 | M150: 0 | N150: 19429 | P150: 246779413705 | Q150: 19430 | R150: 19429
A151: 45748 | B151: 0 | C151: 574 | D151: -2813472.1 | E151: PU/26/SLS/OT/0195 | F151: Handling Charges - Outbound (Exp) - SLSIPL | G151: PU/26/SLS/OT/0195 | H151: 246779413737 | L151: 246779413733 | M151: 0 | N151: 191 | P151: 246779413733 | Q151: 0 | R151: 191
A152: 45748 | B152: 0 | C152: 6896 | D152: -2820368.1 | E152: PU/26/SLS/OT/0196 | F152: Handling Charges - Outbound (Exp) - SLSIPL | G152: PU/26/SLS/OT/0196 | H152: 246779413735 | L152: 246779413734 | M152: 0 | N152: 3448 | P152: 246779413734 | Q152: 0 | R152: 3448
A153: 45748 | B153: 0 | C153: 191 | D153: -2820559.1 | E153: PU/26/SLS/OT/0197 | F153: Handling Charges - Outbound (Exp) - SLSIPL | G153: PU/26/SLS/OT/0197 | H153: 246779413744 | L153: 246779413735 | M153: 0 | N153: 6896 | P153: 246779413735 | Q153: 0 | R153: 6896
A154: 45748 | B154: 0 | C154: 191 | D154: -2820750.1 | E154: PU/26/SLS/OT/0199 | F154: Handling Charges - Outbound (Exp) - SLSIPL | G154: PU/26/SLS/OT/0199 | H154: 246779413733 | L154: 246779413736 | M154: 0 | N154: 6513 | P154: 246779413736 | Q154: 0 | R154: 6513
A155: 45748 | B155: 0 | C155: 383 | D155: -2821133.1 | E155: PU/26/SLS/OT/0200 | F155: Handling Charges - Outbound (Exp) - SLSIPL | G155: PU/26/SLS/OT/0200 | H155: 246779413743 | L155: 246779413737 | M155: 0 | N155: 574 | P155: 246779413737 | Q155: 0 | R155: 574
A156: 45748 | B156: 0 | C156: 383 | D156: -2821516.1 | E156: PU/26/SLS/OT/0201 | F156: Handling Charges - Outbound (Exp) - SLSIPL | G156: PU/26/SLS/OT/0201 | H156: 246779414680 | L156: 246779413738 | M156: 0 | N156: 3603 | P156: 246779413738 | Q156: 0 | R156: 3603
A157: 45748 | B157: 0 | C157: 6895 | D157: -2828411.1 | E157: PU/26/SLS/OT/0202 | F157: Handling Charges - Outbound (Exp) - SLSIPL | G157: PU/26/SLS/OT/0202 | H157: 246779413741 | L157: 246779413739 | M157: 0 | N157: 1724 | P157: 246779413739 | Q157: 0 | R157: 1724
A158: 45748 | B158: 0 | C158: 846 | D158: -2829257.1 | E158: PU/26/SLS/OT/0191 | F158: Handling Charges - Inbound (Exp) - SLSIPL | G158: PU/26/SLS/OT/0191 | H158: 246779413933 | L158: 246779413740 | M158: 0 | N158: 574 | P158: 246779413740 | Q158: 0 | R158: 574
A159: 45748 | B159: 0 | C159: 3203 | D159: -2832460.1 | E159: PU/26/SLS/OT/0301-1 | F159: Handling Charges - Outbound (Exp) - SLSIPL | G159: PU/26/SLS/OT/0301-1 | H159: 246779410609 | L159: 246779413741 | M159: 0 | N159: 6895 | P159: 246779413741 | Q159: 0 | R159: 6895
...

Sheet Customer Data
A1: Posting Date | B1: Account | C1: Debit (INR) | D1: Credit (INR) | E1: Balance (INR) | F1: Voucher Type | G1: Voucher Subtype | H1: Voucher No | I1: Against Account | J1: Party Type | K1: Party | L1: Against Voucher | M1: Supplier Invoice No
A2: 45708 | B2: Sundry Creditors - SLSIPL | C2: 0 | D2: 35554.52 | E2: -35554.52 | F2: Purchase Invoice | G2: Purchase Invoice | H2: PU/25/SLS/OT/1560 | I2: Fixed Storage Charges - ODC (Covered) - SLSIPL | J2: Supplier | K2: Ascendas Panvel FTWZ Private Limited | L2: PU/25/SLS/OT/1560 | M2: 246779410049
A3: 45708 | B3: Sundry Creditors - SLSIPL | C3: 0 | D3: 35554.52 | E3: -71109.04 | F3: Purchase Invoice | G3: Purchase Invoice | H3: PU/25/SLS/OT/1561 | I3: Fixed Storage Charges - ODC (Covered) - SLSIPL | J3: Supplier | K3: Ascendas Panvel FTWZ Private Limited | L3: PU/25/SLS/OT/1561 | M3: 246779410303
A4: 45708 | B4: Sundry Creditors - SLSIPL | C4: 0 | D4: 35554.52 | E4: -106663.56 | F4: Purchase Invoice | G4: Purchase Invoice | H4: PU/25/SLS/OT/1562 | I4: Fixed Storage Charges - ODC (Covered) - SLSIPL | J4: Supplier | K4: Ascendas Panvel FTWZ Private Limited | L4: PU/25/SLS/OT/1562 | M4: 246779410117
A5: 45708 | B5: Sundry Creditors - SLSIPL | C5: 0 | D5: 35554.52 | E5: -142218.08 | F5: Purchase Invoice | G5: Purchase Invoice | H5: PU/25/SLS/OT/1563 | I5: Fixed Storage Charges - ODC (Covered) - SLSIPL | J5: Supplier | K5: Ascendas Panvel FTWZ Private Limited | L5: PU/25/SLS/OT/1563 | M5: 246779410160
A6: 45708 | B6: Sundry Creditors - SLSIPL | C6: 0 | D6: 35554.52 | E6: -177772.6 | F6: Purchase Invoice | G6: Purchase Invoice | H6: PU/25/SLS/OT/1564 | I6: Fixed Storage Charges - ODC (Covered) - SLSIPL | J6: Supplier | K6: Ascendas Panvel FTWZ Private Limited | L6: PU/25/SLS/OT/1564 | M6: 246779410203
A7: 45708 | B7: Sundry Creditors - SLSIPL | C7: 0 | D7: 35554.52 | E7: -213327.12 | F7: Purchase Invoice | G7: Purchase Invoice | H7: PU/25/SLS/OT/1565 | I7: Fixed Storage Charges - ODC (Covered) - SLSIPL | J7: Supplier | K7: Ascendas Panvel FTWZ Private Limited | L7: PU/25/SLS/OT/1565 | M7: 246779410246
A8: 45719 | B8: Sundry Creditors - SLSIPL | C8: 0 | D8: 804 | E8: -214131.12 | F8: Purchase Invoice | G8: Purchase Invoice | H8: PU/25/SLS/OT/1672 | I8: Handling Charges - Outbound (Exp) - SLSIPL | J8: Supplier | K8: Ascendas Panvel FTWZ Private Limited | L8: PU/25/SLS/OT/1672 | M8: 246779410613
A9: 45719 | B9: Sundry Creditors - SLSIPL | C9: 0 | D9: 1004 | E9: -215135.12 | F9: Purchase Invoice | G9: Purchase Invoice | H9: PU/25/SLS/OT/1673 | I9: Handling Charges - Outbound (Exp) - SLSIPL | J9: Supplier | K9: Ascendas Panvel FTWZ Private Limited | L9: PU/25/SLS/OT/1673 | M9: 246779410612
A10: 45719 | B10: Sundry Creditors - SLSIPL | C10: 0 | D10: 402 | E10: -215537.12 | F10: Purchase Invoice | G10: Purchase Invoice | H10: PU/25/SLS/OT/1674 | I10: Handling Charges - Outbound (Exp) - SLSIPL | J10: Supplier | K10: Ascendas Panvel FTWZ Private Limited | L10: PU/25/SLS/OT/1674 | M10: 246779410611
A11: 45719 | B11: Sundry Creditors - SLSIPL | C11: 0 | D11: 201 | E11: -215738.12 | F11: Purchase Invoice | G11: Purchase Invoice | H11: PU/25/SLS/OT/1675 | I11: Handling Charges - Outbound (Exp) - SLSIPL | J11: Supplier | K11: Ascendas Panvel FTWZ Private Limited | L11: PU/25/SLS/OT/1675 | M11: 246779410610
A12: 45719 | B12: Sundry Creditors - SLSIPL | C12: 0 | D12: 804 | E12: -216542.12 | F12: Purchase Invoice | G12: Purchase Invoice | H12: PU/25/SLS/OT/1676 | I12: Handling Charges - Outbound (Exp) - SLSIPL | J12: Supplier | K12: Ascendas Panvel FTWZ Private Limited | L12: PU/25/SLS/OT/1676 | M12: 246779410608
A13: 45719 | B13: Sundry Creditors - SLSIPL | C13: 0 | D13: 402 | E13: -216944.12 | F13: Purchase Invoice | G13: Purchase Invoice | H13: PU/25/SLS/OT/1677 | I13: Handling Charges - Outbound (Exp) - SLSIPL | J13: Supplier | K13: Ascendas Panvel FTWZ Private Limited | L13: PU/25/SLS/OT/1677 | M13: 246779410607
... A109: 45849 | B109: Sundry Creditors - SLSIPL | C109: 0 | D109: 151725 | E109: -1632350.6 | F109: Purchase Invoice | G109: Purchase Invoice | H109: PU/26/SLS/OT/0415-1 | I109: Storage Charges - Cargo - SLSIPL | J109: Supplier | K109: Ascendas Panvel FTWZ Private Limited | L109: PU/26/SLS/OT/0415-1 | M109: 246779410348
A110: 45937 | B110: Sundry Creditors - SLSIPL | C110: 15778 | D110: 15778 | E110: -757662.6 | F110: Journal Entry | G110: Debit Note | H110: SJ/25/GEA/1104 | J110: Supplier | K110: Ascendas Panvel FTWZ Private Limited | L110: PU/26/SLS/OT/0415-1, SLS26/MF/DN/0020-1 | M110: 246779410348
A111: 45747 | B111: Sundry Creditors - SLSIPL | C111: 0 | D111: 31723 | E111: -2522653.1 | F111: Purchase Invoice | G111: Purchase Invoice | H111: PU/25/SLS/OT/1823 | I111: Container Scanning Paid - SLSIPL | J111: Supplier | K111: Ascendas Panvel FTWZ Private Limited | L111: PU/25/SLS/OT/1823 | M111: 246779413753
A112: 45747 | B112: Sundry Creditors - SLSIPL | C112: 0 | D112: 191 | E112: -2522844.1 | F112: Purchase Invoice | G112: Purchase Invoice | H112: PU/25/SLS/OT/1824 | I112: Handling Charges - Outbound (Exp) - SLSIPL | J112: Supplier | K112: Ascendas Panvel FTWZ Private Limited | L112: PU/25/SLS/OT/1824 | M112: 246779413762
A113: 45747 | B113: Sundry Creditors - SLSIPL | C113: 0 | D113: 3064 | E113: -2525908.1 | F113: Purchase Invoice | G113: Purchase Invoice | H113: PU/25/SLS/OT/1825 | I113: Handling Charges - Outbound (Exp) - SLSIPL | J113: Supplier | K113: Ascendas Panvel FTWZ Private Limited | L113: PU/25/SLS/OT/1825 | M113: 246779413745
A114: 45747 | B114: Sundry Creditors - SLSIPL | C114: 0 | D114: 3448 | E114: -2529356.1 | F114: Purchase Invoice | G114: Purchase Invoice | H114: PU/25/SLS/OT/1826 | I114: Handling Charges - Outbound (Exp) - SLSIPL | J114: Supplier | K114: Ascendas Panvel FTWZ Private Limited | L114: PU/25/SLS/OT/1826 | M114: 246779413734
A115: 45747 | B115: Sundry Creditors - SLSIPL | C115: 0 | D115: 6513 | E115: -2535869.1 | F115: Purchase Invoice | G115: Purchase Invoice | H115: PU/25/SLS/OT/1827 | I115: Handling Charges - Outbound (Exp) - SLSIPL | J115: Supplier | K115: Ascendas Panvel FTWZ Private Limited | L115: PU/25/SLS/OT/1827 | M115: 246779413736
A116: 45747 | B116: Sundry Creditors - SLSIPL | C116: 0 | D116: 1724 | E116: -2537593.1 | F116: Purchase Invoice | G116: Purchase Invoice | H116: PU/25/SLS/OT/1828 | I116: Handling Charges - Outbound (Exp) - SLSIPL | J116: Supplier | K116: Ascendas Panvel FTWZ Private Limited | L116: PU/25/SLS/OT/1828 | M116: 246779413739
A117: 45747 | B117: Sundry Creditors - SLSIPL | C117: 0 | D117: 1149 | E117: -2538742.1 | F117: Purchase Invoice | G117: Purchase Invoice | H117: PU/25/SLS/OT/1829 | I117: Handling Charges - Outbound (Exp) - SLSIPL | J117: Supplier | K117: Ascendas Panvel FTWZ Private Limited | L117: PU/25/SLS/OT/1829 | M117: 246779413742
A118: 45747 | B118: Sundry Creditors - SLSIPL | C118: 0 | D118: 191 | E118: -2538933.1 | F118: Purchase Invoice | G118: Purchase Invoice | H118: PU/25/SLS/OT/1830 | I118: Handling Charges - Outbound (Exp) - SLSIPL | J118: Supplier | K118: Ascendas Panvel FTWZ Private Limited | L118: PU/25/SLS/OT/1830 | M118: 246779413692
A119: 45747 | B119: Sundry Creditors - SLSIPL | C119: 0 | D119: 6896 | E119: -2545829.1 | F119: Purchase Invoice | G119: Purchase Invoice | H119: PU/25/SLS/OT/1831 | I119: Handling Charges - Outbound (Exp) - SLSIPL | J119: Supplier | K119: Ascendas Panvel FTWZ Private Limited | L119: PU/25/SLS/OT/1831 | M119: 246779413693
A120: 45747 | B120: Sundry Creditors - SLSIPL | C120: 0 | D120: 3448 | E120: -2549277.1 | F120: Purchase Invoice | G120: Purchase Invoice | H120: PU/25/SLS/OT/1832 | I120: Handling Charges - Outbound (Exp) - SLSIPL | J120: Supplier | K120: Ascendas Panvel FTWZ Private Limited | L120: PU/25/SLS/OT/1832 | M120: 246779413694
A121: 45747 | B121: Sundry Creditors - SLSIPL | C121: 0 | D121: 191 | E121: -2549468.1 | F121: Purchase Invoice | G121: Purchase Invoice | H121: PU/25/SLS/OT/1833 | I121: Handling Charges - Outbound (Exp) - SLSIPL | J121: Supplier | K121: Ascendas Panvel FTWZ Private Limited | L121: PU/25/SLS/OT/1833 | M121: 246779413695
A122: 45747 | B122: Sundry Creditors - SLSIPL | C122: 0 | D122: 382 | E122: -2549850.1 | F122: Purchase Invoice | G122: Purchase Invoice | H122: PU/25/SLS/OT/1834 | I122: Handling Charges - Outbound (Exp) - SLSIPL | J122: Supplier | K122: Ascendas Panvel FTWZ Private Limited | L122: PU/25/SLS/OT/1834 | M122: 246779413696
... A138: 45748 | B138: Sundry Creditors - SLSIPL | C138: 0 | D138: 59624 | E138: -3015382.1 | F138: Purchase Invoice | G138: Purchase Invoice | H138: PU/26/SLS/OT/0591-1 | I138: Storage Charges - Cargo - SLSIPL | J138: Supplier | K138: Ascendas Panvel FTWZ Private Limited | L138: PU/26/SLS/OT/0591-1 | M138: 246779410360
A139: 45937 | B139: Sundry Creditors - SLSIPL | C139: 4786 | D139: 4786 | E139: -757662.6 | F139: Journal Entry | G139: Debit Note | H139: SJ/25/GEA/1103 | J139: Supplier | K139: Ascendas Panvel FTWZ Private Limited | L139: PU/26/SLS/OT/0591-1, SLS26/MF/DN/0007-2 | M139: 246779410360
A140: 45747 | B140: Sundry Creditors - SLSIPL | C140: 0 | D140: 143412 | E140: -2750354.1 | F140: Purchase Invoice | G140: Purchase Invoice | H140: PU/25/SLS/OT/1857 | I140: VOS Activity Charges Paid - SLSIPL | J140: Supplier | K140: Ascendas Panvel FTWZ Private Limited | L140: PU/25/SLS/OT/1857 | M140: 246779411619
A141: 45747 | B141: Sundry Creditors - SLSIPL | C141: 0 | D141: 5816 | E141: -2756170.1 | F141: Purchase Invoice | G141: Purchase Invoice | H141: PU/25/SLS/OT/1858 | I141: VOS Activity Charges Paid - SLSIPL | J141: Supplier | K141: Ascendas Panvel FTWZ Private Limited | L141: PU/25/SLS/OT/1858 | M141: 246779411620
A142: 45747 | B142: Sundry Creditors - SLSIPL | C142: 0 | D142: 5816 | E142: -2761986.1 | F142: Purchase Invoice | G142: Purchase Invoice | H142: PU/25/SLS/OT/1859 | I142: VOS Activity Charges Paid - SLSIPL | J142: Supplier | K142: Ascendas Panvel FTWZ Private Limited | L142: PU/25/SLS/OT/1859 | M142: 246779411755
A143: 45747 | B143: Sundry Creditors - SLSIPL | C143: 0 | D143: 4339 | E143: -2766325.1 | F143: Purchase Invoice | G143: Purchase Invoice | H143: PU/25/SLS/OT/1860 | I143: VOS Activity Charges Paid - SLSIPL | J143: Supplier | K143: Ascendas Panvel FTWZ Private Limited | L143: PU/25/SLS/OT/1860 | M143: 246779411756
A144: 45747 | B144: Sundry Creditors - SLSIPL | C144: 0 | D144: 6761 | E144: -2773086.1 | F144: Purchase Invoice | G144: Purchase Invoice | H144: PU/25/SLS/OT/1861 | I144: VOS Activity Charges Paid - SLSIPL | J144: Supplier | K144: Ascendas Panvel FTWZ Private Limited | L144: PU/25/SLS/OT/1861 | M144: 246779411759
A145: 45747 | B145: Sundry Creditors - SLSIPL | C145: 0 | D145: 3110 | E145: -2776196.1 | F145: Purchase Invoice | G145: Purchase Invoice | H145: PU/25/SLS/OT/1862 | I145: VOS Activity Charges Paid - SLSIPL | J145: Supplier | K145: Ascendas Panvel FTWZ Private Limited | L145: PU/25/SLS/OT/1862 | M145: 246779411757
A146: 45869 | B146: Sundry Creditors - SLSIPL | C146: 0 | D146: 44602 | E146: -288272.6 | F146: Purchase Invoice | G146: Purchase Invoice | H146: PU/26/SLS/OT/1009-1 | I146: Container Scanning Paid - SLSIPL | J146: Supplier | K146: Ascendas Panvel FTWZ Private Limited | L146: PU/26/SLS/OT/1009-1 | M146: 246779411278
A147: 45748 | B147: Sundry Creditors - SLSIPL | C147: 0 | D147: 1161 | E147: -2810733.1 | F147: Purchase Invoice | G147: Purchase Invoice | H147: PU/26/SLS/OT/0048 | I147: VOS Activity Charges Paid - SLSIPL | J147: Supplier | K147: Ascendas Panvel FTWZ Private Limited | L147: PU/26/SLS/OT/0048 | M147: 246779411448
A148: 45748 | B148: Sundry Creditors - SLSIPL | C148: 0 | D148: 1591 | E148: -2812324.1 | F148: Purchase Invoice | G148: Purchase Invoice | H148: PU/26/SLS/OT/0193 | I148: Handling Charges - Outbound (Exp) - SLSIPL | J148: Supplier | K148: Ascendas Panvel FTWZ Private Limited | L148: PU/26/SLS/OT/0193 | M148: 246779413689
A149: 45748 | B149: Sundry Creditors - SLSIPL | C149: 0 | D149: 574 | E149: -2812898.1 | F149: Purchase Invoice | G149: Purchase Invoice | H149: PU/26/SLS/OT/0194 | I149: Handling Charges - Outbound (Exp) - SLSIPL | J149: Supplier | K149: Ascendas Panvel FTWZ Private Limited | L149: PU/26/SLS/OT/0194 | M149: 246779413740
A150: 45748 | B150: Sundry Creditors - SLSIPL | C150: 0 | D150: 574 | E150: -2813472.1 | F150: Purchase Invoice | G150: Purchase Invoice | H150: PU/26/SLS/OT/0195 | I150: Handling Charges - Outbound (Exp) - SLSIPL | J150: Supplier | K150: Ascendas Panvel FTWZ Private Limited | L150: PU/26/SLS/OT/0195 | M150: 246779413737
...

Sheet Ascendus Data
A1: Cleared Item | B1: Company Code | C1: Customer | D1: Customer Account: Name 1 | E1: Fiscal Year | F1: Posting period | G1: Posting Date | H1: Document Number | I1: Document Type | J1: Document Date | K1: Entry Date | L1: Document Header Text | M1: Reference | N1: G/L Account | O1: G/L Account: Short Text | P1: Special G/L Ind. | Q1: Posting Key | R1: Document Currency Key | S1: Document Currency Value | T1: Company Code Currency Key | U1: Company Code Currency Value | V1: Tax Code | W1: Profit Center | X1: Trading Partner No. | Y1: Assignment | Z1: Item | AA1: Text | AB1: Reference Key 1 | AC1: Reference Key 2 | AD1: Reference Key 3 | AE1: Baseline Payment Dte | AF1: Clearing Date | AG1: Clearing Document | AJ1: Debit | AK1: Credit | AL1: Net Amount | AM1: TDS | AN1: Rate
A2: Selected | B2: 6779 | C2: 100222332 | D2: SCOPE LOGISTICS SERVICES INDIA PVT. | E2: 2025 | F2: 7 | G2: 45854 | H2: 1600001726 | I2: DG | J2: 45854 | K2: 45854 | L2: NA | M2: 256779421358 | N2: 212100 | O2: Trade Debtors (Ctrl) | Q2: 11 | R2: USD | S2: -1793.99 | T2: INR | U2: -154827.9 | V2: O0 | W2: 6779224500 | Y2: NA | Z2: 1 | AA2: Credit Note raised against INV_246779410348 | AE2: 45854 | AF2: 45854 | AG2: 1400000285 | AJ2: {=_xlfn.XLOOKUP(M2,'Customer Data Vlookup'!$L:$L,'Customer Data Vlookup'!$M:$N,,0)} -> #N/A
A3: Selected | B3: 6779 | C3: 100222332 | D3: SCOPE LOGISTICS SERVICES INDIA PVT. | E3: 2025 | F3: 7 | G3: 45854 | H3: 1800010646 | I3: DR | J3: 45854 | K3: 45855 | L3: NA | M3: 256779415406 | N3: 212100 | O3: Trade Debtors (Ctrl) | Q3: 01 | R3: USD | S3: 1793.99 | T3: INR | U3: 154827.9 | V3: O0 | W3: 6779224500 | Y3: NA | Z3: 1 | AA3: Debit note Note raised against CN_256779421358 | AE3: 45854 | AF3: 45854 | AG3: 1400000285 | AJ3: {=_xlfn.XLOOKUP(M3,'Customer Data Vlookup'!$L:$L,'Customer Data Vlookup'!$M:$N,,0)} -> #N/A
A4: Selected | B4: 6779 | C4: 100222332 | D4: SCOPE LOGISTICS SERVICES INDIA PVT. | E4: 2025 | F4: 7 | G4: 45854 | H4: 1600001727 | I4: DG | J4: 45854 | K4: 45854 | L4: NA | M4: 256779421359 | N4: 212100 | O4: Trade Debtors (Ctrl) | Q4: 11 | R4: USD | S4: -705 | T4: INR | U4: -60844.08 | V4: O0 | W4: 6779224500 | Y4: NA | Z4: 1 | AA4: Credit Note raised against INV_246779410360 | AE4: 45854 | AF4: 45854 | AG4: 1400000286 | AJ4: {=_xlfn.XLOOKUP(M4,'Customer Data Vlookup'!$L:$L,'Customer Data Vlookup'!$M:$N,,0)} -> #N/A
A5: Selected | B5: 6779 | C5: 100222332 | D5: SCOPE LOGISTICS SERVICES INDIA PVT. | E5: 2025 | F5: 7 | G5: 45854 | H5: 1800010647 | I5: DR | J5: 45854 | K5: 45855 | L5: NA | M5: 256779415407 | N5: 212100 | O5: Trade Debtors (Ctrl) | Q5: 01 | R5: USD | S5: 705 | T5: INR | U5: 60844.08 | V5: O0 | W5: 6779224500 | Y5: NA | Z5: 1 | AA5: Debit note Note raised against CN_256779421359 | AE5: 45854 | AF5: 45854 | AG5: 1400000286 | AJ5: {=_xlfn.XLOOKUP(M5,'Customer Data Vlookup'!$L:$L,'Customer Data Vlookup'!$M:$N,,0)} -> #N/A
A6: Selected | B6: 6779 | C6: 100222332 | D6: SCOPE LOGISTICS SERVICES INDIA PVT. | E6: 2025 | F6: 7 | G6: 45854 | H6: 1600001728 | I6: DG | J6: 45854 | K6: 45854 | L6: NA | M6: 256779421360 | N6: 212100 | O6: Trade Debtors (Ctrl) | Q6: 11 | R6: USD | S6: -216.2 | T6: INR | U6: -18742.65 | V6: O0 | W6: 6779224500 | Y6: NA | Z6: 1 | AA6: Credit Note raised against INV_246779413701 | AE6: 45854 | AF6: 45854 | AG6: 1400000287 | AJ6: {=_xlfn.XLOOKUP(M6,'Customer Data Vlookup'!$L:$L,'Customer Data Vlookup'!$M:$N,,0)} -> #N/A
A7: Selected | B7: 6779 | C7: 100222332 | D7: SCOPE LOGISTICS SERVICES INDIA PVT. | E7: 2025 | F7: 7 | G7: 45854 | H7: 1800010648 | I7: DR | J7: 45854 | K7: 45855 | L7: NA | M7: 256779415408 | N7: 212100 | O7: Trade Debtors (Ctrl) | Q7: 01 | R7: USD | S7: 216.2 | T7: INR | U7: 18742.65 | V7: O0 | W7: 6779224500 | Y7: NA | Z7: 1 | AA7: Debit note Note raised against CN_256779421360 | AE7: 45854 | AF7: 45854 | AG7: 1400000287 | AJ7: {=_xlfn.XLOOKUP(M7,'Customer Data Vlookup'!$L:$L,'Customer Data Vlookup'!$M:$N,,0)} -> #N/A
A8: Selected | B8: 6779 | C8: 100222332 | D8: SCOPE LOGISTICS SERVICES INDIA PVT. | E8: 2025 | F8: 7 | G8: 45854 | H8: 1600001731 | I8: DG | J8: 45854 | K8: 45854 | L8: NA | M8: 256779421363 | N8: 212100 | O8: Trade Debtors (Ctrl) | Q8: 11 | R8: USD | S8: -1926.06 | T8: INR | U8: -166972.57 | V8: O0 | W8: 6779224500 | Y8: NA | Z8: 1 | AA8: Credit Note raised against INV_246779413796 | AE8: 45854 | AF8: 45854 | AG8: 1400000288 | AJ8: {=_xlfn.XLOOKUP(M8,'Customer Data Vlookup'!$L:$L,'Customer Data Vlookup'!$M:$N,,0)} -> #N/A
A9: Selected | B9: 6779 | C9: 100222332 | D9: SCOPE LOGISTICS SERVICES INDIA PVT. | E9: 2025 | F9: 7 | G9: 45854 | H9: 1800010649 | I9: DR | J9: 45854 | K9: 45855 | L9: NA | M9: 256779415409 | N9: 212100 | O9: Trade Debtors (Ctrl) | Q9: 01 | R9: USD | S9: 1926.06 | T9: INR | U9: 166972.57 | V9: O0 | W9: 6779224500 | Y9: NA | Z9: 1 | AA9: Debit note Note raised against CN_256779421363 | AE9: 45854 | AF9: 45854 | AG9: 1400000288 | AJ9: {=_xlfn.XLOOKUP(M9,'Customer Data Vlookup'!$L:$L,'Customer Data Vlookup'!$M:$N,,0)} -> #N/A
A10: Selected | B10: 6779 | C10: 100222332 | D10: SCOPE LOGISTICS SERVICES INDIA PVT. | E10: 2025 | F10: 7 | G10: 45854 | H10: 1600001734 | I10: DG | J10: 45854 | K10: 45854 | L10: NA | M10: 256779421366 | N10: 212100 | O10: Trade Debtors (Ctrl) | Q10: 11 | R10: USD | S10: -531.9 | T10: INR | U10: -46111.08 | V10: O0 | W10: 6779224500 | Y10: NA | Z10: 1 | AA10: Credit Note raised against INV_246779413845 | AE10: 45854 | AF10: 45854 | AG10: 1400000289 | AJ10: {=_xlfn.XLOOKUP(M10,'Customer Data Vlookup'!$L:$L,'Customer Data Vlookup'!$M:$N,,0)} -> #N/A
A11: Selected | B11: 6779 | C11: 100222332 | D11: SCOPE LOGISTICS SERVICES INDIA PVT. | E11: 2025 | F11: 7 | G11: 45854 | H11: 1800010650 | I11: DR | J11: 45854 | K11: 45855 | L11: NA | M11: 256779415410 | N11: 212100 | O11: Trade Debtors (Ctrl) | Q11: 01 | R11: USD | S11: 531.9 | T11: INR | U11: 46111.08 | V11: O0 | W11: 6779224500 | Y11: NA | Z11: 1 | AA11: Debit note Note raised against CN_256779421366 | AE11: 45854 | AF11: 45854 | AG11: 1400000289 | AJ11: {=_xlfn.XLOOKUP(M11,'Customer Data Vlookup'!$L:$L,'Customer Data Vlookup'!$M:$N,,0)} -> #N/A
A12: Selected | B12: 6779 | C12: 100222332 | D12: SCOPE LOGISTICS SERVICES INDIA PVT. | E12: 2025 | F12: 7 | G12: 45854 | H12: 1600001739 | I12: DG | J12: 45854 | K12: 45854 | L12: NA | M12: 256779421371 | N12: 212100 | O12: Trade Debtors (Ctrl) | Q12: 11 | R12: USD | S12: -525 | T12: INR | U12: -45512.91 | V12: O0 | W12: 6779224500 | Y12: NA | Z12: 1 | AA12: Credit Note raised against INV_246779411278 | AE12: 45854 | AF12: 45854 | AG12: 1400000290 | AJ12: {=_xlfn.XLOOKUP(M12,'Customer Data Vlookup'!$L:$L,'Customer Data Vlookup'!$M:$N,,0)} -> #N/A
A13: Selected | B13: 6779 | C13: 100222332 | D13: SCOPE LOGISTICS SERVICES INDIA PVT. | E13: 2025 | F13: 7 | G13: 45854 | H13: 1800010651 | I13: DR | J13: 45854 | K13: 45855 | L13: NA | M13: 256779415411 | N13: 212100 | O13: Trade Debtors (Ctrl) | Q13: 01 | R13: USD | S13: 525 | T13: INR | U13: 45512.91 | V13: O0 | W13: 6779224500 | Y13: NA | Z13: 1 | AA13: Debit note Note raised against CN_256779421371 | AE13: 45854 | AF13: 45854 | AG13: 1400000290 | AJ13: {=_xlfn.XLOOKUP(M13,'Customer Data Vlookup'!$L:$L,'Customer Data Vlookup'!$M:$N,,0)} -> #N/A
... A35: Selected | B35: 6779 | C35: 100222332 | D35: SCOPE LOGISTICS SERVICES INDIA PVT. | E35: 2025 | F35: 7 | G35: 45854 | H35: 1600001753 | I35: DG | J35: 45854 | K35: 45855 | L35: NA | M35: 256779421385 | N35: 212100 | O35: Trade Debtors (Ctrl) | Q35: 11 | R35: USD | S35: -420 | T35: INR | U35: -36410.33 | V35: O0 | W35: 6779224500 | Y35: NA | Z35: 1 | AA35: Credit note Note raised against INV_246779411278 | AE35: 45854 | AF35: 45976 | AG35: 1400001902 | AJ35: {=_xlfn.XLOOKUP(M35,'Customer Data Vlookup'!$L:$L,'Customer Data Vlookup'!$M:$N,,0)} -> #N/A
A36: Not Selected | B36: 6779 | C36: 100222332 | D36: SCOPE LOGISTICS SERVICES INDIA PVT. | E36: 2025 | F36: 5 | G36: 45797 | H36: 1800008722 | I36: DR | J36: 45797 | K36: 45805 | L36: NA | M36: 256779413486 | N36: 212100 | O36: Trade Debtors (Ctrl) | Q36: 01 | R36: USD | S36: 12.5 | T36: INR | U36: 1074.8 | V36: O0 | W36: 6779224500 | Y36: NA | Z36: 1 | AA36: Outbound chgs - 01 - 15 MAY 25 | AE36: 45797 | AJ36: {=_xlfn.XLOOKUP(M36,'Customer Data Vlookup'!$L:$L,'Customer Data Vlookup'!$M:$N,,0)} -> 0 | AK36: 1054 | AL36: =AK36-AJ36 -> 1054 | AM36: =U36-AL36 -> 20.8
A37: Not Selected | B37: 6779 | C37: 100222332 | D37: SCOPE LOGISTICS SERVICES INDIA PVT. | E37: 2025 | F37: 5 | G37: 45797 | H37: 1800009073 | I37: DR | J37: 45797 | K37: 45805 | L37: NA | M37: 256779413837 | N37: 212100 | O37: Trade Debtors (Ctrl) | Q37: 01 | R37: USD | S37: 144.52 | T37: INR | U37: 12426.36 | V37: O0 | W37: 6779224500 | Z37: 1 | AA37: VAS -1-15 May 25, Ex.rate 85.43 | AE37: 45797 | AJ37: {=_xlfn.XLOOKUP(M37,'Customer Data Vlookup'!$L:$L,'Customer Data Vlookup'!$M:$N,,0)} -> 0 | AK37: 12177 | AL37: =AK37-AJ37 -> 12177 | AM37: =U37-AL37 -> 249.36
A38: Selected | B38: 6779 | C38: 100222332 | D38: SCOPE LOGISTICS SERVICES INDIA PVT. | E38: 2025 | F38: 5 | G38: 45797 | H38: 1800009121 | I38: DR | J38: 45797 | K38: 45805 | L38: NA | M38: 256779413885 | N38: 212100 | O38: Trade Debtors (Ctrl) | Q38: 01 | R38: USD | S38: 111.15 | T38: INR | U38: 9557.09 | V38: O0 | W38: 6779224500 | Y38: NA | Z38: 1 | AA38: Inbound chgs -01-15 MAY 25 | AE38: 45797 | AF38: 45976 | AG38: 1400001901 | AJ38: {=_xlfn.XLOOKUP(M38,'Customer Data Vlookup'!$L:$L,'Customer Data Vlookup'!$M:$N,,0)} -> #N/A
A39: Not Selected | B39: 6779 | C39: 100222332 | D39: SCOPE LOGISTICS SERVICES INDIA PVT. | E39: 2025 | F39: 4 | G39: 45750 | H39: 1800005188 | I39: DR | J39: 45750 | K39: 45752 | L39: NA | M39: 256779410134 | N39: 212100 | O39: Trade Debtors (Ctrl) | Q39: 01 | R39: USD | S39: 7.5 | T39: INR | U39: 651.91 | V39: O0 | Y39: NA | Z39: 1 | AA39: Outbound Handling charges for Mar 25 | AE39: 45750 | AJ39: {=_xlfn.XLOOKUP(M39,'Customer Data Vlookup'!$L:$L,'Customer Data Vlookup'!$M:$N,,0)} -> 0 | AK39: 639 | AL39: =AK39-AJ39 -> 639 | AM39: =U39-AL39 -> 12.91
A40: Not Selected | B40: 6779 | C40: 100222332 | D40: SCOPE LOGISTICS SERVICES INDIA PVT. | E40: 2025 | F40: 4 | G40: 45750 | H40: 1800005189 | I40: DR | J40: 45750 | K40: 45752 | L40: NA | M40: 256779410135 | N40: 212100 | O40: Trade Debtors (Ctrl) | Q40: 01 | R40: USD | S40: 3.75 | T40: INR | U40: 325.96 | V40: O0 | Y40: NA | Z40: 1 | AA40: Loose loading Handling charges for Mar 25 | AE40: 45750 | AJ40: {=_xlfn.XLOOKUP(M40,'Customer Data Vlookup'!$L:$L,'Customer Data Vlookup'!$M:$N,,0)} -> 0 | AK40: 319 | AL40: =AK40-AJ40 -> 319 | AM40: =U40-AL40 -> 6.96
A41: Not Selected | B41: 6779 | C41: 100222332 | D41: SCOPE LOGISTICS SERVICES INDIA PVT. | E41: 2025 | F41: 4 | G41: 45750 | H41: 1800005264 | I41: DR | J41: 45750 | K41: 45752 | L41: NA | M41: 256779410156 | N41: 212100 | O41: Trade Debtors (Ctrl) | Q41: 01 | R41: USD | S41: 58.75 | T41: INR | U41: 5106.66 | V41: O0 | Y41: NA | Z41: 1 | AA41: Inbound Handling charges for Mar 25 | AE41: 45750 | AJ41: {=_xlfn.XLOOKUP(M41,'Customer Data Vlookup'!$L:$L,'Customer Data Vlookup'!$M:$N,,0)} -> 0 | AK41: 4913 | AL41: =AK41-AJ41 -> 4913 | AM41: =U41-AL41 -> 193.66
A42: Not Selected | B42: 6779 | C42: 100222332 | D42: SCOPE LOGISTICS SERVICES INDIA PVT. | E42: 2025 | F42: 4 | G42: 45750 | H42: 1800005265 | I42: DR | J42: 45750 | K42: 45752 | L42: NA | M42: 256779410157 | N42: 212100 | O42: Trade Debtors (Ctrl) | Q42: 01 | R42: USD | S42: 34.48 | T42: INR | U42: 2997.06 | V42: O0 | Y42: NA | Z42: 1 | AA42: MHE Charges for Mar 25 | AE42: 45750 | AJ42: {=_xlfn.XLOOKUP(M42,'Customer Data Vlookup'!$L:$L,'Customer Data Vlookup'!$M:$N,,0)} -> 0 | AK42: 2883 | AL42: =AK42-AJ42 -> 2883 | AM42: =U42-AL42 -> 114.06
A43: Not Selected | B43: 6779 | C43: 100222332 | D43: SCOPE LOGISTICS SERVICES INDIA PVT. | E43: 2025 | F43: 4 | G43: 45750 | H43: 1800005274 | I43: DR | J43: 45750 | K43: 45752 | L43: NA | M43: 256779410166 | N43: 212100 | O43: Trade Debtors (Ctrl) | Q43: 01 | R43: USD | S43: 152.75 | T43: INR | U43: 13277.31 | V43: O0 | Y43: NA | Z43: 1 | AA43: Outbound Handling charges for Mar 25 | AE43: 45750 | AJ43: {=_xlfn.XLOOKUP(M43,'Customer Data Vlookup'!$L:$L,'Customer Data Vlookup'!$M:$N,,0)} -> 0 | AK43: 13011 | AL43: =AK43-AJ43 -> 13011 | AM43: =U43-AL43 -> 266.31
A44: Not Selected | B44: 6779 | C44: 100222332 | D44: SCOPE LOGISTICS SERVICES INDIA PVT. | E44: 2025 | F44: 4 | G44: 45750 | H44: 1800005282 | I44: DR | J44: 45750 | K44: 45752 | L44: NA | M44: 256779410174 | N44: 212100 | O44: Trade Debtors (Ctrl) | Q44: 01 | R44: USD | S44: 72.85 | T44: INR | U44: 6332.25 | V44: O0 | Y44: NA | Z44: 1 | AA44: Outbound Handling charges for Feb 2025 | AE44: 45750 | AJ44: {=_xlfn.XLOOKUP(M44,'Customer Data Vlookup'!$L:$L,'Customer Data Vlookup'!$M:$N,,0)} -> 0 | AK44: 6205 | AL44: =AK44-AJ44 -> 6205 | AM44: =U44-AL44 -> 127.25
A45: Not Selected | B45: 6779 | C45: 100222332 | D45: SCOPE LOGISTICS SERVICES INDIA PVT. | E45: 2025 | F45: 4 | G45: 45750 | H45: 1800005309 | I45: DR | J45: 45750 | K45: 45752 | L45: NA | M45: 256779410201 | N45: 212100 | O45: Trade Debtors (Ctrl) | Q45: 01 | R45: USD | S45: 34.48 | T45: INR | U45: 2997.06 | V45: O0 | Y45: NA | Z45: 1 | AA45: VAS Activity -1 -15 Mar 25, Ex Rate. 87.01 | AE45: 45750 | AJ45: {=_xlfn.XLOOKUP(M45,'Customer Data Vlookup'!$L:$L,'Customer Data Vlookup'!$M:$N,,0)} -> 0 | AK45: 2937 | AL45: =AK45-AJ45 -> 2937 | AM45: =U45-AL45 -> 60.06
A46: Selected | B46: 6779 | C46: 100222332 | D46: SCOPE LOGISTICS SERVICES INDIA PVT. | E46: 2025 | F46: 4 | G46: 45750 | H46: 1800005399 | I46: DR | J46: 45750 | K46: 45752 | L46: NA | M46: 256779410291 | N46: 212100 | O46: Trade Debtors (Ctrl) | Q46: 01 | R46: USD | S46: 456.75 | T46: INR | U46: 39701.54 | V46: O0 | Y46: NA | Z46: 1 | AA46: Fixed Rental charges for Feb 2025 | AE46: 45750 | AF46: 45842 | AG46: 1400000246 | AJ46: {=_xlfn.XLOOKUP(M46,'Customer Data Vlookup'!$L:$L,'Customer Data Vlookup'!$M:$N,,0)} -> #N/A
A47: Selected | B47: 6779 | C47: 100222332 | D47: SCOPE LOGISTICS SERVICES INDIA PVT. | E47: 2025 | F47: 4 | G47: 45750 | H47: 1800005358 | I47: DR | J47: 45750 | K47: 45752 | L47: NA | M47: 256779410250 | N47: 212100 | O47: Trade Debtors (Ctrl) | Q47: 01 | R47: USD | S47: 456.75 | T47: INR | U47: 39701.54 | V47: O0 | Y47: NA | Z47: 1 | AA47: Fixed Rental charges for Jan 2025 | AE47: 45750 | AF47: 45842 | AG47: 1400000247 | AJ47: {=_xlfn.XLOOKUP(M47,'Customer Data Vlookup'!$L:$L,'Customer Data Vlookup'!$M:$N,,0)} -> #N/A
A48: Selected | B48: 6779 | C48: 100222332 | D48: SCOPE LOGISTICS SERVICES INDIA PVT. | E48: 2025 | F48: 4 | G48: 45750 | H48: 1800005058 | I48: DR | J48: 45750 | K48: 45752 | L48: NA | M48: 256779410004 | N48: 212100 | O48: Trade Debtors (Ctrl) | Q48: 01 | R48: USD | S48: 705 | T48: INR | U48: 61279.88 | V48: O0 | Y48: NA | Z48: 1 | AA48: CY Longstanding container Ground Rent charges for | AE48: 45750 | AF48: 45976 | AG48: 1400001901 | AJ48: {=_xlfn.XLOOKUP(M48,'Customer Data Vlookup'!$L:$L,'Customer Data Vlookup'!$M:$N,,0)} -> 0 | AK48: 55272 | AL48: =AK48-AJ48 -> 55272 | AM48: =U48-AL48 -> 6007.88
A49: Selected | B49: 6779 | C49: 100222332 | D49: SCOPE LOGISTICS SERVICES INDIA PVT. | E49: 2025 | F49: 4 | G49: 45750 | H49: 1800005064 | I49: DR | J49: 45750 | K49: 45752 | L49: NA | M49: 256779410010 | N49: 212100 | O49: Trade Debtors (Ctrl) | Q49: 01 | R49: USD | S49: 1793.99 | T49: INR | U49: 155936.88 | V49: O0 | Y49: NA | Z49: 1 | AA49: CY Longstanding container Ground Rent charges for | AE49: 45750 | AF49: 45976 | AG49: 1400001901 | AJ49: {=_xlfn.XLOOKUP(M49,'Customer Data Vlookup'!$L:$L,'Customer Data Vlookup'!$M:$N,,0)} -> 0 | AK49: 140649 | AL49: =AK49-AJ49 -> 140649 | AM49: =U49-AL49 -> 15287.88
A50: Selected | B50: 6779 | C50: 100222332 | D50: SCOPE LOGISTICS SERVICES INDIA PVT. | E50: 2025 | F50: 4 | G50: 45750 | H50: 1800005328 | I50: DR | J50: 45750 | K50: 45752 | L50: NA | M50: 256779410220 | N50: 212100 | O50: Trade Debtors (Ctrl) | Q50: 01 | R50: USD | S50: 1314.12 | T50: INR | U50: 114225.7 | V50: O0 | Y50: NA | Z50: 1 | AA50: CY Longstanding container Ground Rent charges for | AE50: 45750 | AF50: 45976 | AG50: 1400001901 | AJ50: {=_xlfn.XLOOKUP(M50,'Customer Data Vlookup'!$L:$L,'Customer Data Vlookup'!$M:$N,,0)} -> 0 | AK50: 114223 | AL50: =AK50-AJ50 -> 114223 | AM50: =U50-AL50 -> 2.7
A51: Not Selected | B51: 6779 | C51: 100222332 | D51: SCOPE LOGISTICS SERVICES INDIA PVT. | E51: 2025 | F51: 10 | G51: 45950 | H51: 1800013971 | I51: DR | J51: 45950 | K51: 45951 | L51: NA | M51: 256779418614 | N51: 212100 | O51: Trade Debtors (Ctrl) | Q51: 01 | R51: USD | S51: 338.06 | T51: INR | U51: 29813.77 | V51: O0 | W51: 6779224500 | Y51: 2114876 | Z51: 1 | AA51: CY - CY Grd Rent Chgs - 01 - 15 OCT 25 | AE51: 45950 | AJ51: {=_xlfn.XLOOKUP(M51,'Customer Data Vlookup'!$L:$L,'Customer Data Vlookup'!$M:$N,,0)} -> #N/A
A52: Not Selected | B52: 6779 | C52: 100222332 | D52: SCOPE LOGISTICS SERVICES INDIA PVT. | E52: 2025 | F52: 10 | G52: 45950 | H52: 1800014013 | I52: DR | J52: 45950 | K52: 45951 | L52: NA | M52: 256779418620 | N52: 212100 | O52: Trade Debtors (Ctrl) | Q52: 01 | R52: USD | S52: 830.96 | T52: INR | U52: 73283 | V52: O0 | W52: 6779224500 | Y52: 2114877 | Z52: 1 | AA52: CY Ground rent Chgs - 01 - 15 Oct 25 | AE52: 45950 | AJ52: {=_xlfn.XLOOKUP(M52,'Customer Data Vlookup'!$L:$L,'Customer Data Vlookup'!$M:$N,,0)} -> #N/A
A53: Not Selected | B53: 6779 | C53: 100222332 | D53: SCOPE LOGISTICS SERVICES INDIA PVT. | E53: 2025 | F53: 10 | G53: 45950 | H53: 1800013843 | I53: DR | J53: 45950 | K53: 45951 | L53: NA | M53: 256779418661 | N53: 212100 | O53: Trade Debtors (Ctrl) | Q53: 01 | R53: USD | S53: 226.3 | T53: INR | U53: 19957.57 | V53: O0 | W53: 6779224500 | Y53: 2114881 | Z53: 1 | AA53: Inbound chgs - 01 - 15 OCT 25 | AE53: 45950 | AJ53: {=_xlfn.XLOOKUP(M53,'Customer Data Vlookup'!$L:$L,'Customer Data Vlookup'!$M:$N,,0)} -> #N/A
A54: Not Selected | B54: 6779 | C54: 100222332 | D54: SCOPE LOGISTICS SERVICES INDIA PVT. | E54: 2025 | F54: 10 | G54: 45950 | H54: 1800013925 | I54: DR | J54: 45950 | K54: 45951 | L54: NA | M54: 256779418702 | N54: 212100 | O54: Trade Debtors (Ctrl) | Q54: 01 | R54: USD | S54: 182.87 | T54: INR | U54: 16127.45 | V54: O0 | W54: 6779224500 | Y54: 2114883 | Z54: 1 | AA54: Outbound chgs - 01 - 15 Oct 25 | AE54: 45950 | AJ54: {=_xlfn.XLOOKUP(M54,'Customer Data Vlookup'!$L:$L,'Customer Data Vlookup'!$M:$N,,0)} -> #N/A
A55: Not Selected | B55: 6779 | C55: 100222332 | D55: SCOPE LOGISTICS SERVICES INDIA PVT. | E55: 2025 | F55: 4 | G55: 45768 | H55: 1800007270 | I55: DR | J55: 45768 | K55: 45769 | L55: NA | M55: 256779412161 | N55: 212100 | O55: Trade Debtors (Ctrl) | Q55: 01 | R55: USD | S55: 456.75 | T55: INR | U55: 39193.72 | V55: O0 | W55: 6779224500 | Y55: NA | Z55: 1 | AA55: Fixed Storage Charges for April 2025 | AE55: 45768 | AJ55: {=_xlfn.XLOOKUP(M55,'Customer Data Vlookup'!$L:$L,'Customer Data Vlookup'!$M:$N,,0)} -> 0 | AK55: 34962 | AL55: =AK55-AJ55 -> 34962 | AM55: =U55-AL55 -> 4231.72
A56: Not Selected | B56: 6779 | C56: 100222332 | D56: SCOPE LOGISTICS SERVICES INDIA PVT. | E56: 2025 | F56: 7 | G56: 45862 | H56: 1600001816 | I56: DG | J56: 45862 | K56: 45862 | L56: NA | M56: 256779421436 | N56: 212100 | O56: Trade Debtors (Ctrl) | Q56: 11 | R56: USD | S56: -140 | T56: INR | U56: -12037.72 | V56: O0 | W56: 6779224500 | Y56: NA | Z56: 1 | AA56: Credit Note raised against 256779413861 | AE56: 45862 | AJ56: {=_xlfn.XLOOKUP(M56,'Customer Data Vlookup'!$L:$L,'Customer Data Vlookup'!$M:$N,,0)} -> #N/A
A57: Not Selected | B57: 6779 | C57: 100222332 | D57: SCOPE LOGISTICS SERVICES INDIA PVT. | E57: 2025 | F57: 7 | G57: 45862 | H57: 1800011187 | I57: DR | J57: 45862 | K57: 45862 | L57: NA | M57: 256779415939 | N57: 212100 | O57: Trade Debtors (Ctrl) | Q57: 01 | R57: USD | S57: 140 | T57: INR | U57: 12040.09 | V57: O0 | W57: 6779224500 | Y57: NA | Z57: 1 | AA57: Scanning Chgs - 01 - 15 May 25 | AE57: 45862 | AJ57: {=_xlfn.XLOOKUP(M57,'Customer Data Vlookup'!$L:$L,'Customer Data Vlookup'!$M:$N,,0)} -> 0 | AK57: 11782.092 | AL57: =AK57-AJ57 -> 11782.092 | AM57: =U57-AL57 -> 257.9982
A58: Not Selected | B58: 6779 | C58: 100222332 | D58: SCOPE LOGISTICS SERVICES INDIA PVT. | E58: 2025 | F58: 7 | G58: 45862 | H58: 1800011193 | I58: DR | J58: 45862 | K58: 45862 | L58: NA | M58: 256779415945 | N58: 212100 | O58: Trade Debtors (Ctrl) | Q58: 01 | R58: USD | S58: 111.15 | T58: INR | U58: 9558.97 | V58: O0 | W58: 6779224500 | Y58: NA | Z58: 1 | AA58: Inbound chgs -01-15 MAY 25 | AE58: 45862 | AJ58: {=_xlfn.XLOOKUP(M58,'Customer Data Vlookup'!$L:$L,'Customer Data Vlookup'!$M:$N,,0)} -> #N/A | AL58: =AK58-AJ58 -> #N/A | AM58: =U58-AL58 -> #N/A
A59: Selected | B59: 6779 | C59: 100222332 | D59: SCOPE LOGISTICS SERVICES INDIA PVT. | E59: 2025 | F59: 7 | G59: 45862 | H59: 1600001906 | I59: DG | J59: 45862 | K59: 45862 | L59: NA | M59: 256779421526 | N59: 212100 | O59: Trade Debtors (Ctrl) | Q59: 11 | R59: USD | S59: -456.75 | T59: INR | U59: -39280.81 | V59: O0 | W59: 6779224500 | Y59: NA | Z59: 1 | AA59: Credit note raised against 256779414459 | AE59: 45862 | AF59: 45902 | AG59: 1400001112 | AJ59: {=_xlfn.XLOOKUP(M59,'Customer Data Vlookup'!$L:$L,'Customer Data Vlookup'!$M:$N,,0)} -> #N/A
A60: Selected | B60: 6779 | C60: 100222332 | D60: SCOPE LOGISTICS SERVICES INDIA PVT. | E60: 2025 | F60: 7 | G60: 45862 | H60: 1600001923 | I60: DG | J60: 45862 | K60: 45862 | L60: NA | M60: 256779421543 | N60: 212100 | O60: Trade Debtors (Ctrl) | Q60: 11 | R60: USD | S60: -456.75 | T60: INR | U60: -39280.81 | V60: O0 | W60: 6779224500 | Y60: NA | Z60: 1 | AA60: Credit note raised against 256779414476 | AE60: 45862 | AF60: 45902 | AG60: 1400001112 | AJ60: {=_xlfn.XLOOKUP(M60,'Customer Data Vlookup'!$L:$L,'Customer Data Vlookup'!$M:$N,,0)} -> #N/A
A61: Selected | B61: 6779 | C61: 100222332 | D61: SCOPE LOGISTICS SERVICES INDIA PVT. | E61: 2025 | F61: 7 | G61: 45862 | H61: 1600001822 | I61: DG | J61: 45862 | K61: 45862 | L61: NA | M61: 256779421442 | N61: 212100 | O61: Trade Debtors (Ctrl) | Q61: 11 | R61: USD | S61: -111.15 | T61: INR | U61: -9557.09 | V61: O0 | W61: 6779224500 | Y61: NA | Z61: 1 | AA61: Credit Note raised against 256779413885 | AE61: 45862 | AF61: 45976 | AG61: 1400001901 | AJ61: {=_xlfn.XLOOKUP(M61,'Customer Data Vlookup'!$L:$L,'Customer Data Vlookup'!$M:$N,,0)} -> #N/A
...

Sheet Knock off entries difference
H1: =SUM(H3:H31) -> -1093.08
A2: Document Number | B2: Document Type | C2: Document Date | D2: Reference | E2: Document Currency Key | F2: Document Currency Value | G2: Company Code Currency Key | H2: Company Code Currency Value
A3: 1400001112 | B3: DY | C3: 45902 | E3: INR | F3: 79944.34 | G3: INR | H3: 78561.62
A4: 1400001112 | B4: DY | C4: 45902 | E4: INR | F4: -79944.34 | G4: INR | H4: -78095.82
A5: 1400000285 | B5: DY | C5: 45854 | E5: USD | F5: 1793.99 | G5: INR | H5: 154827.9
A6: 1400000285 | B6: DY | C6: 45854 | E6: USD | F6: -1793.99 | G6: INR | H6: -154827.9
A7: 1400000286 | B7: DY | C7: 45854 | E7: USD | F7: 705 | G7: INR | H7: 60844.08
A8: 1400000286 | B8: DY | C8: 45854 | E8: USD | F8: -705 | G8: INR | H8: -60844.08
A9: 1400000287 | B9: DY | C9: 45854 | E9: USD | F9: 216.2 | G9: INR | H9: 18742.65
A10: 1400000287 | B10: DY | C10: 45854 | E10: USD | F10: -216.2 | G10: INR | H10: -18742.65
A11: 1400000288 | B11: DY | C11: 45854 | E11: USD | F11: 1926.06 | G11: INR | H11: 166972.57
A12: 1400000288 | B12: DY | C12: 45854 | E12: USD | F12: -1926.06 | G12: INR | H12: -166972.57
A13: 1400000289 | B13: DY | C13: 45854 | E13: USD | F13: 531.9 | G13: INR | H13: 46111.08
A14: 1400000289 | B14: DY | C14: 45854 | E14: USD | F14: -531.9 | G14: INR | H14: -46111.08
A15: 1400000245 | B15: DY | C15: 45842 | D15: KNOCK OFF ENTRY | E15: USD | F15: 0 | G15: INR | H15: 0
A16: 1400000248 | B16: DY | C16: 45842 | D16: KNOCK OFF ENTRY | E16: USD | F16: 0 | G16: INR | H16: 0
A17: 1400000246 | B17: DY | C17: 45842 | D17: KNOCK OFF ENTRY | E17: USD | F17: 456.75 | G17: INR | H17: 39701.54
A18: 1400000246 | B18: DY | C18: 45842 | D18: KNOCK OFF ENTRY | E18: USD | F18: -456.75 | G18: INR | H18: -39701.54
A19: 1400000247 | B19: DY | C19: 45842 | D19: KNOCK OFF ENTRY | E19: USD | F19: 456.75 | G19: INR | H19: 39701.54
A20: 1400000247 | B20: DY | C20: 45842 | D20: KNOCK OFF ENTRY | E20: USD | F20: -456.75 | G20: INR | H20: -39701.54
A21: 1400000290 | B21: DY | C21: 45854 | D21: KNOCK OFF ENTRY | E21: USD | F21: 525 | G21: INR | H21: 45512.91
A22: 1400000290 | B22: DY | C22: 45854 | D22: KNOCK OFF ENTRY | E22: USD | F22: -525 | G22: INR | H22: -45512.91
A23: 1400001901 | B23: DY | C23: 45976 | D23: KNOCK OFF ENTRY | E23: USD | F23: 3813.11 | G23: INR | H23: 331442.46
A24: 1400001901 | B24: DY | C24: 45976 | D24: KNOCK OFF ENTRY | E24: USD | F24: -3813.11 | G24: INR | H24: -331442.46
A25: 1400001902 | B25: DY | C25: 45976 | D25: KNOCK OFF ENTRY | E25: USD | F25: 1117.66 | G25: INR | H25: 96798.99
A26: 1400001902 | B26: DY | C26: 45976 | D26: KNOCK OFF ENTRY | E26: USD | F26: -182.83 | G26: INR | H26: -16089.66
... A31: 1400001902 | B31: DY | C31: 45976 | D31: KNOCK OFF ENTRY | E31: USD | F31: -137.9 | G31: INR | H31: -12135.67

Sheet Diffrence in Invoice value

Sheet TDS to be recorded 
A2: Document Number | B2: Document Type | C2: Document Date | D2: Reference | E2: Document Currency Key | F2: Document Currency Value | G2: Company Code Currency Key | H2: Company Code Currency Value | I2: Text | J2: Debit | K2: Credit | L2: Net Amount
A3: 1800008722 | B3: DR | C3: 45797 | D3: 256779413486 | E3: USD | F3: 12.5 | G3: INR | H3: 1074.8 | I3: Outbound chgs - 01 - 15 MAY 25 | J3: 0 | K3: 1054 | L3: 1054
A4: 1800009073 | B4: DR | C4: 45797 | D4: 256779413837 | E4: USD | F4: 144.52 | G4: INR | H4: 12426.36 | I4: VAS -1-15 May 25, Ex.rate 85.43 | J4: 0 | K4: 12177 | L4: 12177
A5: 1800005188 | B5: DR | C5: 45750 | D5: 256779410134 | E5: USD | F5: 7.5 | G5: INR | H5: 651.91 | I5: Outbound Handling charges for Mar 25 | J5: 0 | K5: 639 | L5: 639
A6: 1800005189 | B6: DR | C6: 45750 | D6: 256779410135 | E6: USD | F6: 3.75 | G6: INR | H6: 325.96 | I6: Loose loading Handling charges for Mar 25 | J6: 0 | K6: 319 | L6: 319
A7: 1800005264 | B7: DR | C7: 45750 | D7: 256779410156 | E7: USD | F7: 58.75 | G7: INR | H7: 5106.66 | I7: Inbound Handling charges for Mar 25 | J7: 0 | K7: 4913 | L7: 4913
A8: 1800005265 | B8: DR | C8: 45750 | D8: 256779410157 | E8: USD | F8: 34.48 | G8: INR | H8: 2997.06 | I8: MHE Charges for Mar 25 | J8: 0 | K8: 2883 | L8: 2883
A9: 1800005274 | B9: DR | C9: 45750 | D9: 256779410166 | E9: USD | F9: 152.75 | G9: INR | H9: 13277.31 | I9: Outbound Handling charges for Mar 25 | J9: 0 | K9: 13011 | L9: 13011
A10: 1800005282 | B10: DR | C10: 45750 | D10: 256779410174 | E10: USD | F10: 72.85 | G10: INR | H10: 6332.25 | I10: Outbound Handling charges for Feb 2025 | J10: 0 | K10: 6205 | L10: 6205
A11: 1800005309 | B11: DR | C11: 45750 | D11: 256779410201 | E11: USD | F11: 34.48 | G11: INR | H11: 2997.06 | I11: VAS Activity -1 -15 Mar 25, Ex Rate. 87.01 | J11: 0 | K11: 2937 | L11: 2937
A12: 1800005058 | B12: DR | C12: 45750 | D12: 256779410004 | E12: USD | F12: 705 | G12: INR | H12: 61279.88 | I12: CY Longstanding container Ground Rent charges for | J12: 0 | K12: 55272 | L12: 55272
A13: 1800005064 | B13: DR | C13: 45750 | D13: 256779410010 | E13: USD | F13: 1793.99 | G13: INR | H13: 155936.88 | I13: CY Longstanding container Ground Rent charges for | J13: 0 | K13: 140649 | L13: 140649
A14: 1800005328 | B14: DR | C14: 45750 | D14: 256779410220 | E14: USD | F14: 1314.12 | G14: INR | H14: 114225.7 | I14: CY Longstanding container Ground Rent charges for | J14: 0 | K14: 114223 | L14: 114223
... A103: 1800011903 | B103: DR | C103: 45880 | D103: 256779416546 | E103: USD | F103: 282.9 | G103: INR | H103: 24337.92 | I103: CY - CY Grd Rent Chgs - 16 - 15 JUL 25 | J103: 0 | K103: 21929.078 | L103: 21929.078
A104: 1800010208 | B104: DR | C104: 45845 | D104: 256779414968 | E104: USD | F104: 31.58 | G104: INR | H104: 2715.9 | J104: 0 | K104: 2629.9005 | L104: 2629.9005
A105: 1800006916 | B105: DR | C105: 45763 | D105: 256779411807 | E105: USD | F105: 23.5 | G105: INR | H105: 2042.66 | I105: Inbound Handling charges for Dec 2024 | J105: 0 | K105: 2053.9 | L105: 2053.9
A106: 1800006994 | B106: DR | C106: 45763 | D106: 256779411885 | E106: USD | F106: 15 | G106: INR | H106: 1303.83 | I106: Outbound Handling charges for Dec 2024 | J106: 0 | K106: 1256 | L106: 1256
A107: 1800006995 | B107: DR | C107: 45763 | D107: 256779411886 | E107: USD | F107: 5.25 | G107: INR | H107: 456.34 | I107: Loose loading Handling charges for Dec 2024 | J107: 0 | K107: 447 | L107: 447
A108: 1800007174 | B108: DR | C108: 45763 | D108: 256779412065 | E108: USD | F108: 18.88 | G108: INR | H108: 1641.08 | I108: VAS Activity - Feb 25, Ex Rate. 87.40 | J108: 0 | K108: 1584 | L108: 1584
A109: 1800007209 | B109: DR | C109: 45763 | D109: 256779412100 | E109: USD | F109: 252.98 | G109: INR | H109: 21989.48 | I109: VAS Activity - Mar 25, 16-31, Ex Rate. 85.58 | J109: 0 | K109: 21549 | L109: 21549
A110: 1800007226 | B110: DR | C110: 45763 | D110: 256779412117 | E110: USD | F110: 5415.85 | G110: INR | H110: 470755.54 | I110: Storage Charges Mar, 25 | J110: 0 | K110: 417286 | L110: 417286
A111: 1800007026 | B111: DR | C111: 45763 | D111: 256779411917 | E111: USD | F111: 140 | G111: INR | H111: 12169.05 | I111: Scanning charges for 01 to 31 Mar 25 | J111: 0 | K111: 12169 | L111: 12169
A112: 1800001783 | B112: DR | C112: 45730 | D112: 246779411448 | E112: USD | F112: 14.31 | G112: INR | H112: 1240.55 | I112: VAS Activity Charges for the month of August, 24 | J112: 0 | K112: 1161 | L112: 1161
A113: 1800012275 | B113: DR | C113: 45904 | D113: 256779416911 | E113: USD | F113: 40.85 | G113: INR | H113: 3574.96 | I113: CODC LCL Chgs - 16-31 Aug 25 | J113: 0 | K113: 3487.4461 | L113: 3487.4461
A114: 1800012286 | B114: DR | C114: 45904 | D114: 256779416948 | E114: USD | F114: 14.1 | G114: INR | H114: 1233.95 | I114: CODC Out chgs -16-31 Aug 25 | J114: 0 | K114: 1233.9521 | L114: 1233.9521
A115: 1800012460 | B115: DR | C115: 45904 | D115: 256779417160 | E115: USD | F115: 14.25 | G115: INR | H115: 1247.08 | I115: VAS -16-31 Aug 25 | J115: 0 | K115: 1247.0792 | L115: 1247.0792
A116: 1800012493 | B116: DR | C116: 45904 | D116: 256779417166 | E116: USD | F116: 760.25 | G116: INR | H116: 66532.77 | I116: CY - CY Grd Rent Chgs - 01 - 31 AUG 25 | J116: 0 | K116: 59881.68 | L116: 59881.68
... A126: 1800010184 | B126: DR | C126: 45842 | D126: 256779414944 | E126: USD | F126: 456.75 | G126: INR | H126: 39280.81 | I126: Fixed Storage Charges fo JULY 2025 | J126: 0 | K126: 35324.775 | L126: 35324.775
A127: 1800010215 | B127: DR | C127: 45842 | D127: 256779414975 | E127: USD | F127: 54.05 | G127: INR | H127: 4648.34 | J127: 0 | K127: 4562.3355 | L127: 4562.3355
A128: 1800010288 | B128: DR | C128: 45842 | D128: 256779415048 | E128: USD | F128: 6.43 | G128: INR | H128: 552.98 | I128: Bond Stamp Paper Chgs | J128: 0 | K128: 552.9843 | L128: 552.9843
A129: 1800010438 | B129: DR | C129: 45842 | D129: 256779415198 | E129: USD | F129: 3330.8 | G129: INR | H129: 286451.03 | I129: Unit Storage - 1-30 June 25 | J129: 0 | K129: 257812.81 | L129: 257812.81
A130: 1800010503 | B130: DR | C130: 45842 | D130: 256779415263 | E130: USD | F130: 2.34 | G130: INR | H130: 201.24 | I130: VAS - 16-30 June 25 | J130: 0 | K130: 201.2416 | L130: 201.2416
A131: 1800014263 | B131: DR | C131: 45966 | D131: 256779418802 | E131: USD | F131: 456.75 | G131: INR | H131: 40195.55 | I131: Fixed Storage Charges for November 2025 | J131: 4048 | K131: 40195.392 | L131: 36147.392
A132: 1800014282 | B132: DR | C132: 45966 | D132: 256779418819 | E132: USD | F132: 32.74 | G132: INR | H132: 2881.23 | I132: VAS-16 -31 Oct 25 | J132: 0 | K132: 2793.2276 | L132: 2793.2276
A133: 1800014537 | B133: DR | C133: 45966 | D133: 256779418869 | E133: USD | F133: 6685.47 | G133: INR | H133: 588344.02 | I133: Unit Storage - 1-31 Oct 2025 | J133: 0 | K133: 529469.76 | L133: 529469.76
A134: 1800014590 | B134: DR | C134: 45966 | D134: 256779418897 | E134: USD | F134: 108.45 | G134: INR | H134: 9543.97 | I134: CODC LCL Chgs -16-31 Oct 25 | J134: 0 | K134: 9367.9609 | L134: 9367.9609
A135: 1800014641 | B135: DR | C135: 45966 | D135: 256779418906 | E135: USD | F135: 35.25 | G135: INR | H135: 3102.12 | I135: CODC Out chgs -16-31 Oct 25 | J135: 0 | K135: 3014.1161 | L135: 3014.1161
A136: 1800014455 | B136: DR | C136: 45966 | D136: 256779419069 | E136: USD | F136: 337.59 | G136: INR | H136: 29709.06 | I136: CY - CY Grd Rent Chgs - 16 - 31 OCT 25 | J136: 0 | K136: 26716.949 | L136: 26716.949
A137: 1800014633 | B137: DR | C137: 45966 | D137: 256779419076 | E137: USD | F137: 799 | G137: INR | H137: 70314.71 | I137: CY Ground rent Chgs - 16 - 31 Oct 25 | J137: 0 | K137: 63274.437 | L137: 63274.437
A138: 1800014523 | B138: DR | C138: 45966 | D138: 256779419172 | E138: USD | F138: 68.15 | G138: INR | H138: 5997.43 | I138: Outbound chgs - 16 - 31 Oct 25 | J138: 0 | K138: 5909.4276 | L138: 5909.4276
...

Sheet Invoice&DN in Customer's ledger
A2: Document Number | B2: Document Type | C2: Document Date | D2: Reference | E2: Document Currency Key | F2: Document Currency Value | G2: Company Code Currency Key | H2: Company Code Currency Value | I2: Text | J2: Xlookup
