Workbook

Sheet Customer Ledger
A1: Posting Date | B1: Debit (INR) | C1: Credit (INR) | D1: Balance (INR) | E1: Voucher Subtype | F1: Voucher No | G1: Against Account | H1: Against Voucher | I1: Supplier Invoice No | K1: Supplier Invoice No | L1: Sum of Debit (INR) | M1: Sum of Credit (INR) | O1: Supplier Invoice No | P1: Sum of Debit (INR) | Q1: Sum of Credit (INR)
A2: 2025-02-20 | B2: 0 | C2: 35554.52 | D2: -35554.52 | E2: Purchase Invoice | F2: PU/25/SLS/OT/1560 | G2: Fixed Storage Charges - ODC (Covered) - SLSIPL | H2: PU/25/SLS/OT/1560 | I2: 246779410049 | K2: 25677941807 | L2: 0 | M2: 1972 | O2: 25677941807 | P2: 0 | Q2: 1972
A3: 2025-02-20 | B3: 0 | C3: 35554.52 | D3: -71109.04 | E3: Purchase Invoice | F3: PU/25/SLS/OT/1561 | G3: Fixed Storage Charges - ODC (Covered) - SLSIPL | H3: PU/25/SLS/OT/1561 | I3: 246779410303 | K3: 246779410049 | L3: 0 | M3: 35554.52 | O3: 246779410049 | P3: 0 | Q3: 35554.52
A4: 2025-02-20 | B4: 0 | C4: 35554.52 | D4: -106663.56 | E4: Purchase Invoice | F4: PU/25/SLS/OT/1562 | G4: Fixed Storage Charges - ODC (Covered) - SLSIPL | H4: PU/25/SLS/OT/1562 | I4: 246779410117 | K4: 246779410072 | L4: 0 | M4: 35477 | O4: 246779410072 | P4: 0 | Q4: 35477
A5: 2025-02-20 | B5: 0 | C5: 35554.52 | D5: -142218.08 | E5: Purchase Invoice | F5: PU/25/SLS/OT/1563 | G5: Fixed Storage Charges - ODC (Covered) - SLSIPL | H5: PU/25/SLS/OT/1563 | I5: 246779410160 | K5: 246779410117 | L5: 0 | M5: 35554.52 | O5: 246779410117 | P5: 0 | Q5: 35554.52
A6: 2025-02-20 | B6: 0 | C6: 35554.52 | D6: -177772.6 | E6: Purchase Invoice | F6: PU/25/SLS/OT/1564 | G6: Fixed Storage Charges - ODC (Covered) - SLSIPL | H6: PU/25/SLS/OT/1564 | I6: 246779410203 | K6: 246779410160 | L6: 0 | M6: 35554.52 | O6: 246779410160 | P6: 0 | Q6: 35554.52
A7: 2025-02-20 | B7: 0 | C7: 35554.52 | D7: -213327.12 | E7: Purchase Invoice | F7: PU/25/SLS/OT/1565 | G7: Fixed Storage Charges - ODC (Covered) - SLSIPL | H7: PU/25/SLS/OT/1565 | I7: 246779410246 | K7: 246779410203 | L7: 0 | M7: 35554.52 | O7: 246779410203 | P7: 0 | Q7: 35554.52
A8: 2025-03-03 | B8: 0 | C8: 804 | D8: -214131.12 | E8: Purchase Invoice | F8: PU/25/SLS/OT/1672 | G8: Handling Charges - Outbound (Exp) - SLSIPL | H8: PU/25/SLS/OT/1672 | I8: 246779410613 | K8: 246779410246 | L8: 0 | M8: 35554.52 | O8: 246779410246 | P8: 0 | Q8: 35554.52
A9: 2025-03-03 | B9: 0 | C9: 1004 | D9: -215135.12 | E9: Purchase Invoice | F9: PU/25/SLS/OT/1673 | G9: Handling Charges - Outbound (Exp) - SLSIPL | H9: PU/25/SLS/OT/1673 | I9: 246779410612 | K9: 246779410303 | L9: 0 | M9: 35554.52 | O9: 246779410303 | P9: 0 | Q9: 35554.52
A10: 2025-03-03 | B10: 0 | C10: 402 | D10: -215537.12 | E10: Purchase Invoice | F10: PU/25/SLS/OT/1674 | G10: Handling Charges - Outbound (Exp) - SLSIPL | H10: PU/25/SLS/OT/1674 | I10: 246779410611 | K10: 246779410327 | L10: 0 | M10: 16480.711 | O10: 246779410327 | P10: 0 | Q10: 16480.711
A11: 2025-03-03 | B11: 0 | C11: 201 | D11: -215738.12 | E11: Purchase Invoice | F11: PU/25/SLS/OT/1675 | G11: Handling Charges - Outbound (Exp) - SLSIPL | H11: PU/25/SLS/OT/1675 | I11: 246779410610 | K11: 246779410333 | L11: 0 | M11: 29975.442 | O11: 246779410333 | P11: 0 | Q11: 29975.442
A12: 2025-03-03 | B12: 0 | C12: 804 | D12: -216542.12 | E12: Purchase Invoice | F12: PU/25/SLS/OT/1676 | G12: Handling Charges - Outbound (Exp) - SLSIPL | H12: PU/25/SLS/OT/1676 | I12: 246779410608 | K12: 246779410338 | L12: 0 | M12: 13859.78 | O12: 246779410338 | P12: 0 | Q12: 13859.78
A13: 2025-03-03 | B13: 0 | C13: 402 | D13: -216944.12 | E13: Purchase Invoice | F13: PU/25/SLS/OT/1677 | G13: Handling Charges - Outbound (Exp) - SLSIPL | H13: PU/25/SLS/OT/1677 | I13: 246779410607 | K13: 246779410339 | L13: 0 | M13: 44681.825 | O13: 246779410339 | P13: 0 | Q13: 44681.825
... A108: 2025-07-11 | B108: 0 | C108: 151725 | D108: -1632350.6 | E108: Purchase Invoice | F108: PU/26/SLS/OT/0415-1 | G108: Storage Charges - Cargo - SLSIPL | H108: PU/26/SLS/OT/0415-1 | I108: 246779410348 | K108: 246779411249 | L108: 0 | M108: 13737 | O108: 246779411249 | P108: 0 | Q108: 13737
A109: 2025-10-07 | B109: 15778 | C109: 15778 | D109: -757662.6 | E109: Debit Note | F109: SJ/25/GEA/1104 | H109: PU/26/SLS/OT/0415-1, SLS26/MF/DN/0020-1 | I109: Debit Note | K109: 246779411250 | L109: 0 | M109: 1599 | O109: 246779411250 | P109: 0 | Q109: 1599
A110: 2025-04-01 | B110: 0 | C110: 59624 | D110: -3015382.1 | E110: Purchase Invoice | F110: PU/26/SLS/OT/0591-1 | G110: Storage Charges - Cargo - SLSIPL | H110: PU/26/SLS/OT/0591-1 | I110: 246779410360 | K110: 246779411251 | L110: 0 | M110: 1599 | O110: 246779411251 | P110: 0 | Q110: 1599
A111: 2025-03-31 | B111: 0 | C111: 31723 | D111: -2522653.1 | E111: Purchase Invoice | F111: PU/25/SLS/OT/1823 | G111: Container Scanning Paid - SLSIPL | H111: PU/25/SLS/OT/1823 | I111: 246779413753 | K111: 246779411252 | L111: 0 | M111: 1907 | O111: 246779411252 | P111: 0 | Q111: 1907
A112: 2025-03-31 | B112: 0 | C112: 191 | D112: -2522844.1 | E112: Purchase Invoice | F112: PU/25/SLS/OT/1824 | G112: Handling Charges - Outbound (Exp) - SLSIPL | H112: PU/25/SLS/OT/1824 | I112: 246779413762 | K112: 246779411278 | L112: 0 | M112: 44602 | O112: 246779411278 | P112: 0 | Q112: 44602
A113: 2025-03-31 | B113: 0 | C113: 3064 | D113: -2525908.1 | E113: Purchase Invoice | F113: PU/25/SLS/OT/1825 | G113: Handling Charges - Outbound (Exp) - SLSIPL | H113: PU/25/SLS/OT/1825 | I113: 246779413745 | K113: 246779411300 | L113: 0 | M113: 33376 | O113: 246779411300 | P113: 0 | Q113: 33376
A114: 2025-03-31 | B114: 0 | C114: 3448 | D114: -2529356.1 | E114: Purchase Invoice | F114: PU/25/SLS/OT/1826 | G114: Handling Charges - Outbound (Exp) - SLSIPL | H114: PU/25/SLS/OT/1826 | I114: 246779413734 | K114: 246779411314 | L114: 0 | M114: 8522 | O114: 246779411314 | P114: 0 | Q114: 8522
A115: 2025-03-31 | B115: 0 | C115: 6513 | D115: -2535869.1 | E115: Purchase Invoice | F115: PU/25/SLS/OT/1827 | G115: Handling Charges - Outbound (Exp) - SLSIPL | H115: PU/25/SLS/OT/1827 | I115: 246779413736 | K115: 246779411326 | L115: 0 | M115: 20874 | O115: 246779411326 | P115: 0 | Q115: 20874
A116: 2025-03-31 | B116: 0 | C116: 1724 | D116: -2537593.1 | E116: Purchase Invoice | F116: PU/25/SLS/OT/1828 | G116: Handling Charges - Outbound (Exp) - SLSIPL | H116: PU/25/SLS/OT/1828 | I116: 246779413739 | K116: 246779411339 | L116: 0 | M116: 17857 | O116: 246779411339 | P116: 0 | Q116: 17857
A117: 2025-03-31 | B117: 0 | C117: 1149 | D117: -2538742.1 | E117: Purchase Invoice | F117: PU/25/SLS/OT/1829 | G117: Handling Charges - Outbound (Exp) - SLSIPL | H117: PU/25/SLS/OT/1829 | I117: 246779413742 | K117: 246779411448 | L117: 0 | M117: 1161 | O117: 246779411448 | P117: 0 | Q117: 1161
A118: 2025-03-31 | B118: 0 | C118: 191 | D118: -2538933.1 | E118: Purchase Invoice | F118: PU/25/SLS/OT/1830 | G118: Handling Charges - Outbound (Exp) - SLSIPL | H118: PU/25/SLS/OT/1830 | I118: 246779413692 | K118: 246779411619 | L118: 0 | M118: 143412 | O118: 246779411619 | P118: 0 | Q118: 143412
A119: 2025-03-31 | B119: 0 | C119: 6896 | D119: -2545829.1 | E119: Purchase Invoice | F119: PU/25/SLS/OT/1831 | G119: Handling Charges - Outbound (Exp) - SLSIPL | H119: PU/25/SLS/OT/1831 | I119: 246779413693 | K119: 246779411620 | L119: 0 | M119: 5816 | O119: 246779411620 | P119: 0 | Q119: 5816
A120: 2025-03-31 | B120: 0 | C120: 3448 | D120: -2549277.1 | E120: Purchase Invoice | F120: PU/25/SLS/OT/1832 | G120: Handling Charges - Outbound (Exp) - SLSIPL | H120: PU/25/SLS/OT/1832 | I120: 246779413694 | K120: 246779411755 | L120: 0 | M120: 5816 | O120: 246779411755 | P120: 0 | Q120: 5816
A121: 2025-03-31 | B121: 0 | C121: 191 | D121: -2549468.1 | E121: Purchase Invoice | F121: PU/25/SLS/OT/1833 | G121: Handling Charges - Outbound (Exp) - SLSIPL | H121: PU/25/SLS/OT/1833 | I121: 246779413695 | K121: 246779411756 | L121: 0 | M121: 4339 | O121: 246779411756 | P121: 0 | Q121: 4339
... A137: 2025-03-31 | B137: 0 | C137: 994 | D137: -2580563.1 | E137: Purchase Invoice | F137: PU/25/SLS/OT/1853 | G137: Handling Charges - Outbound (Exp) - SLSIPL | H137: PU/25/SLS/OT/1853 | I137: 246779413772 | K137: 246779413629 | L137: 0 | M137: 397 | O137: 246779413629 | P137: 0 | Q137: 397
A138: 2025-10-07 | B138: 4786 | C138: 4786 | D138: -757662.6 | E138: Debit Note | F138: SJ/25/GEA/1103 | H138: PU/26/SLS/OT/0591-1, SLS26/MF/DN/0007-2 | I138: Debit Note | K138: 246779413689 | L138: 0 | M138: 1591 | O138: 246779413689 | P138: 0 | Q138: 1591
A139: 2025-07-31 | B139: 0 | C139: 44602 | D139: -288272.6 | E139: Purchase Invoice | F139: PU/26/SLS/OT/1009-1 | G139: Container Scanning Paid - SLSIPL | H139: PU/26/SLS/OT/1009-1 | I139: 246779411278 | K139: 246779413690 | L139: 0 | M139: 198 | O139: 246779413690 | P139: 0 | Q139: 198
A140: 2025-03-31 | B140: 0 | C140: 143412 | D140: -2750354.1 | E140: Purchase Invoice | F140: PU/25/SLS/OT/1857 | G140: VOS Activity Charges Paid - SLSIPL | H140: PU/25/SLS/OT/1857 | I140: 246779411619 | K140: 246779413691 | L140: 0 | M140: 596 | O140: 246779413691 | P140: 0 | Q140: 596
A141: 2025-03-31 | B141: 0 | C141: 5816 | D141: -2756170.1 | E141: Purchase Invoice | F141: PU/25/SLS/OT/1858 | G141: VOS Activity Charges Paid - SLSIPL | H141: PU/25/SLS/OT/1858 | I141: 246779411620 | K141: 246779413692 | L141: 0 | M141: 191 | O141: 246779413692 | P141: 0 | Q141: 191
A142: 2025-03-31 | B142: 0 | C142: 5816 | D142: -2761986.1 | E142: Purchase Invoice | F142: PU/25/SLS/OT/1859 | G142: VOS Activity Charges Paid - SLSIPL | H142: PU/25/SLS/OT/1859 | I142: 246779411755 | K142: 246779413693 | L142: 0 | M142: 6896 | O142: 246779413693 | P142: 0 | Q142: 6896
A143: 2025-03-31 | B143: 0 | C143: 4339 | D143: -2766325.1 | E143: Purchase Invoice | F143: PU/25/SLS/OT/1860 | G143: VOS Activity Charges Paid - SLSIPL | H143: PU/25/SLS/OT/1860 | I143: 246779411756 | K143: 246779413694 | L143: 0 | M143: 3448 | O143: 246779413694 | P143: 0 | Q143: 3448
A144: 2025-03-31 | B144: 0 | C144: 6761 | D144: -2773086.1 | E144: Purchase Invoice | F144: PU/25/SLS/OT/1861 | G144: VOS Activity Charges Paid - SLSIPL | H144: PU/25/SLS/OT/1861 | I144: 246779411759 | K144: 246779413695 | L144: 0 | M144: 191 | O144: 246779413695 | P144: 0 | Q144: 191
A145: 2025-03-31 | B145: 0 | C145: 3110 | D145: -2776196.1 | E145: Purchase Invoice | F145: PU/25/SLS/OT/1862 | G145: VOS Activity Charges Paid - SLSIPL | H145: PU/25/SLS/OT/1862 | I145: 246779411757 | K145: 246779413696 | L145: 0 | M145: 382 | O145: 246779413696 | P145: 0 | Q145: 382
A146: 2025-10-07 | B146: 36410 | C146: 36410 | D146: -757662.6 | E146: Debit Note | F146: SJ/25/GEA/1105 | H146: PU/26/SLS/OT/1009-1, SLS26/MF/DN/0022-1 | I146: Debit Note | K146: 246779413701 | L146: 0 | M146: 18367 | O146: 246779413701 | P146: 0 | Q146: 18367
A147: 2025-04-01 | B147: 0 | C147: 1161 | D147: -2810733.1 | E147: Purchase Invoice | F147: PU/26/SLS/OT/0048 | G147: VOS Activity Charges Paid - SLSIPL | H147: PU/26/SLS/OT/0048 | I147: 246779411448 | K147: 246779413702 | L147: 0 | M147: 31577 | O147: 246779413702 | P147: 0 | Q147: 31577
A148: 2025-04-01 | B148: 0 | C148: 1591 | D148: -2812324.1 | E148: Purchase Invoice | F148: PU/26/SLS/OT/0193 | G148: Handling Charges - Outbound (Exp) - SLSIPL | H148: PU/26/SLS/OT/0193 | I148: 246779413689 | K148: 246779413704 | L148: 0 | M148: 13011 | O148: 246779413704 | P148: 0 | Q148: 13011
A149: 2025-04-01 | B149: 0 | C149: 574 | D149: -2812898.1 | E149: Purchase Invoice | F149: PU/26/SLS/OT/0194 | G149: Handling Charges - Outbound (Exp) - SLSIPL | H149: PU/26/SLS/OT/0194 | I149: 246779413740 | K149: 246779413705 | L149: 0 | M149: 19429 | O149: 246779413705 | P149: 0 | Q149: 19429
...

Sheet Ascendus Ledger
A1: Company Code | B1: Customer | C1: Customer Account: Name 1 | D1: Fiscal Year | E1: Posting period | F1: Posting Date | G1: Document Number | H1: Document Type | I1: Document Date | J1: Entry Date | K1: Document Header Text | L1: Reference | M1: G/L Account | N1: G/L Account: Short Text | O1: Special G/L Ind. | P1: Posting Key | Q1: Document Currency Key | R1: Document Currency Value | S1: Company Code Currency Key | T1: Company Code Currency Value | U1: Tax Code | V1: Profit Center | W1: Trading Partner No. | X1: Assignment | Y1: Item | Z1: Debit | AA1: Credit | AB1: Net Amount | AC1: TDS | AD1: Rate | AE1: Text | AF1: Reference Key 1 | AG1: Reference Key 2 | AH1: Reference Key 3 | AI1: Baseline Payment Dte | AJ1: Clearing Date | AK1: Clearing Document
A2: 6779 | B2: 100222332 | C2: SCOPE LOGISTICS SERVICES INDIA PVT. | D2: 2025 | E2: 7 | F2: 45854 | G2: 1600001726 | H2: DG | I2: 45854 | J2: 45854 | K2: NA | L2: 256779421358 | M2: 212100 | N2: Trade Debtors (Ctrl) | P2: 11 | Q2: USD | R2: -1793.99 | S2: INR | T2: -154827.9 | U2: O0 | V2: 6779224500 | X2: NA | Y2: 1 | Z2: {=_xlfn.XLOOKUP(L2,'Customer Ledger'!$O:$O,'Customer Ledger'!$P:$Q,,0)} -> #N/A | AE2: Credit Note raised against INV_246779410348 | AI2: 45854 | AJ2: 45854 | AK2: 1400000285
A3: 6779 | B3: 100222332 | C3: SCOPE LOGISTICS SERVICES INDIA PVT. | D3: 2025 | E3: 7 | F3: 45854 | G3: 1800010646 | H3: DR | I3: 45854 | J3: 45855 | K3: NA | L3: 256779415406 | M3: 212100 | N3: Trade Debtors (Ctrl) | P3: 1 | Q3: USD | R3: 1793.99 | S3: INR | T3: 154827.9 | U3: O0 | V3: 6779224500 | X3: NA | Y3: 1 | Z3: {=_xlfn.XLOOKUP(L3,'Customer Ledger'!$O:$O,'Customer Ledger'!$P:$Q,,0)} -> #N/A | AE3: Debit note Note raised against CN_256779421358 | AI3: 45854 | AJ3: 45854 | AK3: 1400000285
A4: 6779 | B4: 100222332 | C4: SCOPE LOGISTICS SERVICES INDIA PVT. | D4: 2025 | E4: 7 | F4: 45854 | G4: 1600001727 | H4: DG | I4: 45854 | J4: 45854 | K4: NA | L4: 256779421359 | M4: 212100 | N4: Trade Debtors (Ctrl) | P4: 11 | Q4: USD | R4: -705 | S4: INR | T4: -60844.08 | U4: O0 | V4: 6779224500 | X4: NA | Y4: 1 | Z4: {=_xlfn.XLOOKUP(L4,'Customer Ledger'!$O:$O,'Customer Ledger'!$P:$Q,,0)} -> #N/A | AE4: Credit Note raised against INV_246779410360 | AI4: 45854 | AJ4: 45854 | AK4: 1400000286
A5: 6779 | B5: 100222332 | C5: SCOPE LOGISTICS SERVICES INDIA PVT. | D5: 2025 | E5: 7 | F5: 45854 | G5: 1800010647 | H5: DR | I5: 45854 | J5: 45855 | K5: NA | L5: 256779415407 | M5: 212100 | N5: Trade Debtors (Ctrl) | P5: 1 | Q5: USD | R5: 705 | S5: INR | T5: 60844.08 | U5: O0 | V5: 6779224500 | X5: NA | Y5: 1 | Z5: {=_xlfn.XLOOKUP(L5,'Customer Ledger'!$O:$O,'Customer Ledger'!$P:$Q,,0)} -> #N/A | AE5: Debit note Note raised against CN_256779421359 | AI5: 45854 | AJ5: 45854 | AK5: 1400000286
A6: 6779 | B6: 100222332 | C6: SCOPE LOGISTICS SERVICES INDIA PVT. | D6: 2025 | E6: 7 | F6: 45854 | G6: 1600001728 | H6: DG | I6: 45854 | J6: 45854 | K6: NA | L6: 256779421360 | M6: 212100 | N6: Trade Debtors (Ctrl) | P6: 11 | Q6: USD | R6: -216.2 | S6: INR | T6: -18742.65 | U6: O0 | V6: 6779224500 | X6: NA | Y6: 1 | Z6: {=_xlfn.XLOOKUP(L6,'Customer Ledger'!$O:$O,'Customer Ledger'!$P:$Q,,0)} -> #N/A | AE6: Credit Note raised against INV_246779413701 | AI6: 45854 | AJ6: 45854 | AK6: 1400000287
A7: 6779 | B7: 100222332 | C7: SCOPE LOGISTICS SERVICES INDIA PVT. | D7: 2025 | E7: 7 | F7: 45854 | G7: 1800010648 | H7: DR | I7: 45854 | J7: 45855 | K7: NA | L7: 256779415408 | M7: 212100 | N7: Trade Debtors (Ctrl) | P7: 1 | Q7: USD | R7: 216.2 | S7: INR | T7: 18742.65 | U7: O0 | V7: 6779224500 | X7: NA | Y7: 1 | Z7: {=_xlfn.XLOOKUP(L7,'Customer Ledger'!$O:$O,'Customer Ledger'!$P:$Q,,0)} -> #N/A | AE7: Debit note Note raised against CN_256779421360 | AI7: 45854 | AJ7: 45854 | AK7: 1400000287
A8: 6779 | B8: 100222332 | C8: SCOPE LOGISTICS SERVICES INDIA PVT. | D8: 2025 | E8: 7 | F8: 45854 | G8: 1600001731 | H8: DG | I8: 45854 | J8: 45854 | K8: NA | L8: 256779421363 | M8: 212100 | N8: Trade Debtors (Ctrl) | P8: 11 | Q8: USD | R8: -1926.06 | S8: INR | T8: -166972.57 | U8: O0 | V8: 6779224500 | X8: NA | Y8: 1 | Z8: {=_xlfn.XLOOKUP(L8,'Customer Ledger'!$O:$O,'Customer Ledger'!$P:$Q,,0)} -> #N/A | AE8: Credit Note raised against INV_246779413796 | AI8: 45854 | AJ8: 45854 | AK8: 1400000288
A9: 6779 | B9: 100222332 | C9: SCOPE LOGISTICS SERVICES INDIA PVT. | D9: 2025 | E9: 7 | F9: 45854 | G9: 1800010649 | H9: DR | I9: 45854 | J9: 45855 | K9: NA | L9: 256779415409 | M9: 212100 | N9: Trade Debtors (Ctrl) | P9: 1 | Q9: USD | R9: 1926.06 | S9: INR | T9: 166972.57 | U9: O0 | V9: 6779224500 | X9: NA | Y9: 1 | Z9: {=_xlfn.XLOOKUP(L9,'Customer Ledger'!$O:$O,'Customer Ledger'!$P:$Q,,0)} -> #N/A | AE9: Debit note Note raised against CN_256779421363 | AI9: 45854 | AJ9: 45854 | AK9: 1400000288
A10: 6779 | B10: 100222332 | C10: SCOPE LOGISTICS SERVICES INDIA PVT. | D10: 2025 | E10: 7 | F10: 45854 | G10: 1600001734 | H10: DG | I10: 45854 | J10: 45854 | K10: NA | L10: 256779421366 | M10: 212100 | N10: Trade Debtors (Ctrl) | P10: 11 | Q10: USD | R10: -531.9 | S10: INR | T10: -46111.08 | U10: O0 | V10: 6779224500 | X10: NA | Y10: 1 | Z10: {=_xlfn.XLOOKUP(L10,'Customer Ledger'!$O:$O,'Customer Ledger'!$P:$Q,,0)} -> #N/A | AE10: Credit Note raised against INV_246779413845 | AI10: 45854 | AJ10: 45854 | AK10: 1400000289
A11: 6779 | B11: 100222332 | C11: SCOPE LOGISTICS SERVICES INDIA PVT. | D11: 2025 | E11: 7 | F11: 45854 | G11: 1800010650 | H11: DR | I11: 45854 | J11: 45855 | K11: NA | L11: 256779415410 | M11: 212100 | N11: Trade Debtors (Ctrl) | P11: 1 | Q11: USD | R11: 531.9 | S11: INR | T11: 46111.08 | U11: O0 | V11: 6779224500 | X11: NA | Y11: 1 | Z11: {=_xlfn.XLOOKUP(L11,'Customer Ledger'!$O:$O,'Customer Ledger'!$P:$Q,,0)} -> #N/A | AE11: Debit note Note raised against CN_256779421366 | AI11: 45854 | AJ11: 45854 | AK11: 1400000289
A12: 6779 | B12: 100222332 | C12: SCOPE LOGISTICS SERVICES INDIA PVT. | D12: 2025 | E12: 7 | F12: 45854 | G12: 1600001739 | H12: DG | I12: 45854 | J12: 45854 | K12: NA | L12: 256779421371 | M12: 212100 | N12: Trade Debtors (Ctrl) | P12: 11 | Q12: USD | R12: -525 | S12: INR | T12: -45512.91 | U12: O0 | V12: 6779224500 | X12: NA | Y12: 1 | Z12: {=_xlfn.XLOOKUP(L12,'Customer Ledger'!$O:$O,'Customer Ledger'!$P:$Q,,0)} -> #N/A | AE12: Credit Note raised against INV_246779411278 | AI12: 45854 | AJ12: 45854 | AK12: 1400000290
A13: 6779 | B13: 100222332 | C13: SCOPE LOGISTICS SERVICES INDIA PVT. | D13: 2025 | E13: 7 | F13: 45854 | G13: 1800010651 | H13: DR | I13: 45854 | J13: 45855 | K13: NA | L13: 256779415411 | M13: 212100 | N13: Trade Debtors (Ctrl) | P13: 1 | Q13: USD | R13: 525 | S13: INR | T13: 45512.91 | U13: O0 | V13: 6779224500 | X13: NA | Y13: 1 | Z13: {=_xlfn.XLOOKUP(L13,'Customer Ledger'!$O:$O,'Customer Ledger'!$P:$Q,,0)} -> #N/A | AE13: Debit note Note raised against CN_256779421371 | AI13: 45854 | AJ13: 45854 | AK13: 1400000290
A14: 6779 | B14: 100222332 | C14: SCOPE LOGISTICS SERVICES INDIA PVT. | D14: 2025 | E14: 7 | F14: 45854 | G14: 1600001729 | H14: DG | I14: 45854 | J14: 45854 | K14: NA | L14: 256779421361 | M14: 212100 | N14: Trade Debtors (Ctrl) | P14: 11 | Q14: USD | R14: -364.25 | S14: INR | T14: -31577.29 | U14: O0 | V14: 6779224500 | X14: NA | Y14: 1 | Z14: {=_xlfn.XLOOKUP(L14,'Customer Ledger'!$O:$O,'Customer Ledger'!$P:$Q,,0)} -> 31577 | AA14: 0 | AB14: =AA14-Z14 -> -31577 | AC14: =T14-AB14 -> -0.29 | AD14: =AC14/T14 -> 9.1838153e-06 | AE14: Credit Note raised against INV_246779413702 | AI14: 45854 | AJ14: 45976 | AK14: 1400001901
A15: 6779 | B15: 100222332 | C15: SCOPE LOGISTICS SERVICES INDIA PVT. | D15: 2025 | E15: 7 | F15: 45854 | G15: 1600001730 | H15: DG | I15: 45854 | J15: 45854 | K15: NA | L15: 256779421362 | M15: 212100 | N15: Trade Debtors (Ctrl) | P15: 11 | Q15: USD | R15: -237.35 | S15: INR | T15: -20576.17 | U15: O0 | V15: 6779224500 | X15: NA | Y15: 1 | Z15: {=_xlfn.XLOOKUP(L15,'Customer Ledger'!$O:$O,'Customer Ledger'!$P:$Q,,0)} -> 19430 | AA15: 0 | AB15: =AA15-Z15 -> -19430 | AC15: =T15-AB15 -> -1146.17 | AD15: =AC15/T15 -> 0.055703758 | AE15: Credit Note raised against INV_246779413705 | AI15: 45854 | AJ15: 45976 | AK15: 1400001901
A16: 6779 | B16: 100222332 | C16: SCOPE LOGISTICS SERVICES INDIA PVT. | D16: 2025 | E16: 7 | F16: 45854 | G16: 1600001732 | H16: DG | I16: 45854 | J16: 45854 | K16: NA | L16: 256779421364 | M16: 212100 | N16: Trade Debtors (Ctrl) | P16: 11 | Q16: USD | R16: -220 | S16: INR | T16: -19072.08 | U16: O0 | V16: 6779224500 | X16: NA | Y16: 1 | Z16: {=_xlfn.XLOOKUP(L16,'Customer Ledger'!$O:$O,'Customer Ledger'!$P:$Q,,0)} -> 18611 | AA16: 0 | AB16: =AA16-Z16 -> -18611 | AC16: =T16-AB16 -> -461.08 | AD16: =AC16/T16 -> 0.024175654 | AE16: Credit Note raised against INV_246779413816 | AI16: 45854 | AJ16: 45976 | AK16: 1400001901
A17: 6779 | B17: 100222332 | C17: SCOPE LOGISTICS SERVICES INDIA PVT. | D17: 2025 | E17: 7 | F17: 45854 | G17: 1600001733 | H17: DG | I17: 45854 | J17: 45854 | K17: NA | L17: 256779421365 | M17: 212100 | N17: Trade Debtors (Ctrl) | P17: 11 | Q17: USD | R17: -375 | S17: INR | T17: -32509.22 | U17: O0 | V17: 6779224500 | X17: NA | Y17: 1 | Z17: {=_xlfn.XLOOKUP(L17,'Customer Ledger'!$O:$O,'Customer Ledger'!$P:$Q,,0)} -> 31723 | AA17: 0 | AB17: =AA17-Z17 -> -31723 | AC17: =T17-AB17 -> -786.22 | AD17: =AC17/T17 -> 0.024184524 | AE17: Credit Note raised against INV_246779413827 | AI17: 45854 | AJ17: 45976 | AK17: 1400001901
A18: 6779 | B18: 100222332 | C18: SCOPE LOGISTICS SERVICES INDIA PVT. | D18: 2025 | E18: 7 | F18: 45854 | G18: 1600001735 | H18: DG | I18: 45854 | J18: 45854 | K18: NA | L18: 256779421367 | M18: 212100 | N18: Trade Debtors (Ctrl) | P18: 11 | Q18: USD | R18: -1314.12 | S18: INR | T18: -114225.7 | U18: O0 | V18: 6779224500 | X18: NA | Y18: 1 | Z18: {=_xlfn.XLOOKUP(L18,'Customer Ledger'!$O:$O,'Customer Ledger'!$P:$Q,,0)} -> 114223 | AA18: 0 | AB18: =AA18-Z18 -> -114223 | AC18: =T18-AB18 -> -2.7 | AD18: =AC18/T18 -> 2.3637413e-05 | AE18: Credit Note raised against INV_256779410220 | AI18: 45854 | AJ18: 45976 | AK18: 1400001901
A19: 6779 | B19: 100222332 | C19: SCOPE LOGISTICS SERVICES INDIA PVT. | D19: 2025 | E19: 7 | F19: 45854 | G19: 1600001736 | H19: DG | I19: 45854 | J19: 45854 | K19: NA | L19: 256779421368 | M19: 212100 | N19: Trade Debtors (Ctrl) | P19: 11 | Q19: USD | R19: -705 | S19: INR | T19: -61279.88 | U19: O0 | V19: 6779224500 | X19: NA | Y19: 1 | Z19: {=_xlfn.XLOOKUP(L19,'Customer Ledger'!$O:$O,'Customer Ledger'!$P:$Q,,0)} -> 55272 | AA19: 0 | AB19: =AA19-Z19 -> -55272 | AC19: =T19-AB19 -> -6007.88 | AD19: =AC19/T19 -> 0.098040009 | AE19: Credit Note raised against INV_256779410004 | AI19: 45854 | AJ19: 45976 | AK19: 1400001901
A20: 6779 | B20: 100222332 | C20: SCOPE LOGISTICS SERVICES INDIA PVT. | D20: 2025 | E20: 7 | F20: 45854 | G20: 1600001737 | H20: DG | I20: 45854 | J20: 45854 | K20: NA | L20: 256779421369 | M20: 212100 | N20: Trade Debtors (Ctrl) | P20: 11 | Q20: USD | R20: -1793.99 | S20: INR | T20: -155936.88 | U20: O0 | V20: 6779224500 | X20: NA | Y20: 1 | Z20: {=_xlfn.XLOOKUP(L20,'Customer Ledger'!$O:$O,'Customer Ledger'!$P:$Q,,0)} -> 140649 | AA20: 0 | AB20: =AA20-Z20 -> -140649 | AC20: =T20-AB20 -> -15287.88 | AD20: =AC20/T20 -> 0.098038899 | AE20: Credit Note raised against INV_256779410010 | AI20: 45854 | AJ20: 45976 | AK20: 1400001901
A21: 6779 | B21: 100222332 | C21: SCOPE LOGISTICS SERVICES INDIA PVT. | D21: 2025 | E21: 7 | F21: 45854 | G21: 1600001738 | H21: DG | I21: 45854 | J21: 45854 | K21: NA | L21: 256779421370 | M21: 212100 | N21: Trade Debtors (Ctrl) | P21: 11 | Q21: USD | R21: -140 | S21: INR | T21: -12169.05 | U21: O0 | V21: 6779224500 | X21: NA | Y21: 1 | Z21: {=_xlfn.XLOOKUP(L21,'Customer Ledger'!$O:$O,'Customer Ledger'!$P:$Q,,0)} -> 12169 | AA21: 0 | AB21: =AA21-Z21 -> -12169 | AC21: =T21-AB21 -> -0.05 | AD21: =AC21/T21 -> 4.1087842e-06 | AE21: Credit Note raised against INV_256779411917 | AI21: 45854 | AJ21: 45976 | AK21: 1400001901
A22: 6779 | B22: 100222332 | C22: SCOPE LOGISTICS SERVICES INDIA PVT. | D22: 2025 | E22: 7 | F22: 45854 | G22: 1600001740 | H22: DG | I22: 45854 | J22: 45854 | K22: NA | L22: 256779421372 | M22: 212100 | N22: Trade Debtors (Ctrl) | P22: 11 | Q22: USD | R22: -385 | S22: INR | T22: -33376.14 | U22: O0 | V22: 6779224500 | X22: NA | Y22: 1 | Z22: {=_xlfn.XLOOKUP(L22,'Customer Ledger'!$O:$O,'Customer Ledger'!$P:$Q,,0)} -> 33376 | AA22: 0 | AB22: =AA22-Z22 -> -33376 | AC22: =T22-AB22 -> -0.14 | AD22: =AC22/T22 -> 4.1946133e-06 | AE22: Credit Note raised against INV_246779411300 | AI22: 45854 | AJ22: 45976 | AK22: 1400001901
A23: 6779 | B23: 100222332 | C23: SCOPE LOGISTICS SERVICES INDIA PVT. | D23: 2025 | E23: 7 | F23: 45854 | G23: 1600001741 | H23: DG | I23: 45854 | J23: 45854 | K23: NA | L23: 256779421373 | M23: 212100 | N23: Trade Debtors (Ctrl) | P23: 11 | Q23: USD | R23: -105 | S23: INR | T23: -9102.58 | U23: O0 | V23: 6779224500 | X23: NA | Y23: 1 | Z23: {=_xlfn.XLOOKUP(L23,'Customer Ledger'!$O:$O,'Customer Ledger'!$P:$Q,,0)} -> 8696 | AA23: 173 | AB23: =AA23-Z23 -> -8523 | AC23: =T23-AB23 -> -579.58 | AD23: =AC23/T23 -> 0.063672058 | AE23: Credit Note raised against INV_246779411314 | AI23: 45854 | AJ23: 45976 | AK23: 1400001901
A24: 6779 | B24: 100222332 | C24: SCOPE LOGISTICS SERVICES INDIA PVT. | D24: 2025 | E24: 7 | F24: 45854 | G24: 1600001742 | H24: DG | I24: 45854 | J24: 45854 | K24: NA | L24: 256779421374 | M24: 212100 | N24: Trade Debtors (Ctrl) | P24: 11 | Q24: USD | R24: -245 | S24: INR | T24: -21239.36 | U24: O0 | V24: 6779224500 | X24: NA | Y24: 1 | Z24: {=_xlfn.XLOOKUP(L24,'Customer Ledger'!$O:$O,'Customer Ledger'!$P:$Q,,0)} -> 20874 | AA24: 0 | AB24: =AA24-Z24 -> -20874 | AC24: =T24-AB24 -> -365.36 | AD24: =AC24/T24 -> 0.017202025 | AE24: Credit Note raised against INV_246779411326 | AI24: 45854 | AJ24: 45976 | AK24: 1400001901
A25: 6779 | B25: 100222332 | C25: SCOPE LOGISTICS SERVICES INDIA PVT. | D25: 2025 | E25: 7 | F25: 45854 | G25: 1600001743 | H25: DG | I25: 45854 | J25: 45854 | K25: NA | L25: 256779421375 | M25: 212100 | N25: Trade Debtors (Ctrl) | P25: 11 | Q25: USD | R25: -220 | S25: INR | T25: -19072.08 | U25: O0 | V25: 6779224500 | X25: NA | Y25: 1 | Z25: {=_xlfn.XLOOKUP(L25,'Customer Ledger'!$O:$O,'Customer Ledger'!$P:$Q,,0)} -> 17857 | AA25: 0 | AB25: =AA25-Z25 -> -17857 | AC25: =T25-AB25 -> -1215.08 | AD25: =AC25/T25 -> 0.063709884 | AE25: Credit Note raised against INV_246779411339 | AI25: 45854 | AJ25: 45976 | AK25: 1400001901
... A27: 6779 | B27: 100222332 | C27: SCOPE LOGISTICS SERVICES INDIA PVT. | D27: 2025 | E27: 7 | F27: 45854 | G27: 1600001745 | H27: DG | I27: 45854 | J27: 45854 | K27: NA | L27: 256779421377 | M27: 212100 | N27: Trade Debtors (Ctrl) | P27: 11 | Q27: USD | R27: -140 | S27: INR | T27: -12037.72 | U27: O0 | V27: 6779224500 | X27: NA | Y27: 1 | Z27: {=_xlfn.XLOOKUP(L27,'Customer Ledger'!$O:$O,'Customer Ledger'!$P:$Q,,0)} -> 11798 | AA27: 0 | AB27: =AA27-Z27 -> -11798 | AC27: =T27-AB27 -> -239.72 | AD27: =AC27/T27 -> 0.01991407 | AE27: Credit Note raised against INV_256779413283 | AI27: 45854 | AJ27: 45976 | AK27: 1400001901
A28: 6779 | B28: 100222332 | C28: SCOPE LOGISTICS SERVICES INDIA PVT. | D28: 2025 | E28: 7 | F28: 45854 | G28: 1600001746 | H28: DG | I28: 45854 | J28: 45854 | K28: NA | L28: 256779421378 | M28: 212100 | N28: Trade Debtors (Ctrl) | P28: 11 | Q28: USD | R28: -140 | S28: INR | T28: -12037.72 | U28: O0 | V28: 6779224500 | X28: NA | Y28: 1 | Z28: {=_xlfn.XLOOKUP(L28,'Customer Ledger'!$O:$O,'Customer Ledger'!$P:$Q,,0)} -> #N/A | AE28: Credit Note raised against INV_256779413861 | AI28: 45854 | AJ28: 45976 | AK28: 1400001901
A29: 6779 | B29: 100222332 | C29: SCOPE LOGISTICS SERVICES INDIA PVT. | D29: 2025 | E29: 7 | F29: 45854 | G29: 1600001747 | H29: DG | I29: 45854 | J29: 45854 | K29: NA | L29: 256779421379 | M29: 212100 | N29: Trade Debtors (Ctrl) | P29: 11 | Q29: USD | R29: -190 | S29: INR | T29: -16243.25 | U29: O0 | V29: 6779224500 | X29: NA | Y29: 1 | Z29: {=_xlfn.XLOOKUP(L29,'Customer Ledger'!$O:$O,'Customer Ledger'!$P:$Q,,0)} -> 17313 | AA29: 330 | AB29: =AA29-Z29 -> -16983 | AC29: =T29-AB29 -> 739.75 | AD29: =AC29/T29 -> -0.045541994 | AE29: Credit Note raised against INV_256779414288 | AI29: 45854 | AJ29: 45976 | AK29: 1400001901
A30: 6779 | B30: 100222332 | C30: SCOPE LOGISTICS SERVICES INDIA PVT. | D30: 2025 | E30: 7 | F30: 45854 | G30: 1600001748 | H30: DG | I30: 45854 | J30: 45855 | K30: NA | L30: 256779421380 | M30: 212100 | N30: Trade Debtors (Ctrl) | P30: 11 | Q30: USD | R30: -182.83 | S30: INR | T30: -15778.9 | U30: O0 | V30: 6779224500 | X30: NA | Y30: 1 | Z30: {=_xlfn.XLOOKUP(L30,'Customer Ledger'!$O:$O,'Customer Ledger'!$P:$Q,,0)} -> 15778 | AA30: 0 | AB30: =AA30-Z30 -> -15778 | AC30: =T30-AB30 -> -0.9 | AD30: =AC30/T30 -> 5.7038197e-05 | AE30: Credit note Note raised against INV_246779410348 | AI30: 45854 | AJ30: 45976 | AK30: 1400001902
A31: 6779 | B31: 100222332 | C31: SCOPE LOGISTICS SERVICES INDIA PVT. | D31: 2025 | E31: 7 | F31: 45854 | G31: 1600001749 | H31: DG | I31: 45854 | J31: 45855 | K31: NA | L31: 256779421381 | M31: 212100 | N31: Trade Debtors (Ctrl) | P31: 11 | Q31: USD | R31: -55.46 | S31: INR | T31: -4786.4 | U31: O0 | V31: 6779224500 | X31: NA | Y31: 1 | Z31: {=_xlfn.XLOOKUP(L31,'Customer Ledger'!$O:$O,'Customer Ledger'!$P:$Q,,0)} -> 4786 | AA31: 0 | AB31: =AA31-Z31 -> -4786 | AC31: =T31-AB31 -> -0.4 | AD31: =AC31/T31 -> 8.3570115e-05 | AE31: Credit note Note raised against INV_246779410360 | AI31: 45854 | AJ31: 45976 | AK31: 1400001902
A32: 6779 | B32: 100222332 | C32: SCOPE LOGISTICS SERVICES INDIA PVT. | D32: 2025 | E32: 7 | F32: 45854 | G32: 1600001750 | H32: DG | I32: 45854 | J32: 45855 | K32: NA | L32: 256779421382 | M32: 212100 | N32: Trade Debtors (Ctrl) | P32: 11 | Q32: USD | R32: -177.66 | S32: INR | T32: -15401.57 | U32: O0 | V32: 6779224500 | X32: NA | Y32: 1 | Z32: {=_xlfn.XLOOKUP(L32,'Customer Ledger'!$O:$O,'Customer Ledger'!$P:$Q,,0)} -> 15401 | AA32: 0 | AB32: =AA32-Z32 -> -15401 | AC32: =T32-AB32 -> -0.57 | AD32: =AC32/T32 -> 3.7009214e-05 | AE32: Credit note Note raised against INV_246779413701 | AI32: 45854 | AJ32: 45976 | AK32: 1400001902
A33: 6779 | B33: 100222332 | C33: SCOPE LOGISTICS SERVICES INDIA PVT. | D33: 2025 | E33: 7 | F33: 45854 | G33: 1600001751 | H33: DG | I33: 45854 | J33: 45855 | K33: NA | L33: 256779421383 | M33: 212100 | N33: Trade Debtors (Ctrl) | P33: 11 | Q33: USD | R33: -143.81 | S33: INR | T33: -12467.07 | U33: O0 | V33: 6779224500 | X33: NA | Y33: 1 | Z33: {=_xlfn.XLOOKUP(L33,'Customer Ledger'!$O:$O,'Customer Ledger'!$P:$Q,,0)} -> 12467 | AA33: 0 | AB33: =AA33-Z33 -> -12467 | AC33: =T33-AB33 -> -0.07 | AD33: =AC33/T33 -> 5.6147916e-06 | AE33: Credit note Note raised against INV_246779413796 | AI33: 45854 | AJ33: 45976 | AK33: 1400001902
A34: 6779 | B34: 100222332 | C34: SCOPE LOGISTICS SERVICES INDIA PVT. | D34: 2025 | E34: 7 | F34: 45854 | G34: 1600001752 | H34: DG | I34: 45854 | J34: 45855 | K34: NA | L34: 256779421384 | M34: 212100 | N34: Trade Debtors (Ctrl) | P34: 11 | Q34: USD | R34: -137.9 | S34: INR | T34: -11954.72 | U34: O0 | V34: 6779224500 | X34: NA | Y34: 1 | Z34: {=_xlfn.XLOOKUP(L34,'Customer Ledger'!$O:$O,'Customer Ledger'!$P:$Q,,0)} -> 11955 | AA34: 0 | AB34: =AA34-Z34 -> -11955 | AC34: =T34-AB34 -> 0.28 | AD34: =AC34/T34 -> -2.3421711e-05 | AE34: Credit note Note raised against INV_246779413845 | AI34: 45854 | AJ34: 45976 | AK34: 1400001902
A35: 6779 | B35: 100222332 | C35: SCOPE LOGISTICS SERVICES INDIA PVT. | D35: 2025 | E35: 7 | F35: 45854 | G35: 1600001753 | H35: DG | I35: 45854 | J35: 45855 | K35: NA | L35: 256779421385 | M35: 212100 | N35: Trade Debtors (Ctrl) | P35: 11 | Q35: USD | R35: -420 | S35: INR | T35: -36410.33 | U35: O0 | V35: 6779224500 | X35: NA | Y35: 1 | Z35: {=_xlfn.XLOOKUP(L35,'Customer Ledger'!$O:$O,'Customer Ledger'!$P:$Q,,0)} -> 36410 | AA35: 0 | AB35: =AA35-Z35 -> -36410 | AC35: =T35-AB35 -> -0.33 | AD35: =AC35/T35 -> 9.063362e-06 | AE35: Credit note Note raised against INV_246779411278 | AI35: 45854 | AJ35: 45976 | AK35: 1400001902
A36: 6779 | B36: 100222332 | C36: SCOPE LOGISTICS SERVICES INDIA PVT. | D36: 2025 | E36: 5 | F36: 45797 | G36: 1800008722 | H36: DR | I36: 45797 | J36: 45805 | K36: NA | L36: 256779413486 | M36: 212100 | N36: Trade Debtors (Ctrl) | P36: 1 | Q36: USD | R36: 12.5 | S36: INR | T36: 1074.8 | U36: O0 | V36: 6779224500 | X36: NA | Y36: 1 | Z36: {=_xlfn.XLOOKUP(L36,'Customer Ledger'!$O:$O,'Customer Ledger'!$P:$Q,,0)} -> 0 | AA36: 1054 | AB36: =AA36-Z36 -> 1054 | AC36: =T36-AB36 -> 20.8 | AD36: =AC36/T36 -> 0.019352438 | AE36: Outbound chgs - 01 - 15 MAY 25 | AI36: 45797
A37: 6779 | B37: 100222332 | C37: SCOPE LOGISTICS SERVICES INDIA PVT. | D37: 2025 | E37: 5 | F37: 45797 | G37: 1800009073 | H37: DR | I37: 45797 | J37: 45805 | K37: NA | L37: 256779413837 | M37: 212100 | N37: Trade Debtors (Ctrl) | P37: 1 | Q37: USD | R37: 144.52 | S37: INR | T37: 12426.36 | U37: O0 | V37: 6779224500 | Y37: 1 | Z37: {=_xlfn.XLOOKUP(L37,'Customer Ledger'!$O:$O,'Customer Ledger'!$P:$Q,,0)} -> 0 | AA37: 12177 | AB37: =AA37-Z37 -> 12177 | AC37: =T37-AB37 -> 249.36 | AD37: =AC37/T37 -> 0.020067019 | AE37: VAS -1-15 May 25, Ex.rate 85.43 | AI37: 45797
A38: 6779 | B38: 100222332 | C38: SCOPE LOGISTICS SERVICES INDIA PVT. | D38: 2025 | E38: 5 | F38: 45797 | G38: 1600001822 | H38: DG | I38: 45862 | J38: 45862 | K38: NA | L38: 256779421442 | M38: 212100 | N38: Trade Debtors (Ctrl) | P38: 11 | Q38: USD | R38: -111.15 | S38: INR | T38: -9557.09 | U38: O0 | V38: 6779224500 | X38: NA | Y38: 1 | Z38: {=_xlfn.XLOOKUP(L38,'Customer Ledger'!$O:$O,'Customer Ledger'!$P:$Q,,0)} -> #N/A | AE38: Credit Note raised against 256779413885 | AI38: 45862 | AJ38: 45976 | AK38: 1400001901
A39: 6779 | B39: 100222332 | C39: SCOPE LOGISTICS SERVICES INDIA PVT. | D39: 2025 | E39: 4 | F39: 45750 | G39: 1800001031 | H39: DR | I39: 45722 | J39: 45722 | K39: NA | L39: 246779410971 | M39: 212100 | N39: Trade Debtors (Ctrl) | P39: 1 | Q39: USD | R39: 1205.2 | S39: INR | T39: 104480.31 | U39: O0 | V39: 6779224500 | X39: NA | Y39: 1 | Z39: {=_xlfn.XLOOKUP(L39,'Customer Ledger'!$O:$O,'Customer Ledger'!$P:$Q,,0)} -> 0 | AA39: 36538 | AB39: =AA39-Z39 -> 36538 | AC39: =T39-AB39 -> 67942.31 | AD39: =AC39/T39 -> 0.65028817 | AE39: Inbound Handling charges for Aug 2024 | AI39: 45722
A40: 6779 | B40: 100222332 | C40: SCOPE LOGISTICS SERVICES INDIA PVT. | D40: 2025 | E40: 4 | F40: 45750 | G40: 1800007792 | H40: DR | I40: 45769 | J40: 45770 | K40: NA | L40: 256779412683 | M40: 212100 | N40: Trade Debtors (Ctrl) | P40: 1 | Q40: USD | R40: 517.64 | S40: INR | T40: 44994.21 | U40: O0 | V40: 6779224500 | X40: NA | Y40: 1 | Z40: {=_xlfn.XLOOKUP(L40,'Customer Ledger'!$O:$O,'Customer Ledger'!$P:$Q,,0)} -> 0 | AA40: 43195 | AB40: =AA40-Z40 -> 43195 | AC40: =T40-AB40 -> 1799.21 | AD40: =AC40/T40 -> 0.03998759 | AE40: Outbound Handling charges for 31 Mar 25 | AI40: 45769
A41: 6779 | B41: 100222332 | C41: SCOPE LOGISTICS SERVICES INDIA PVT. | D41: 2025 | E41: 4 | F41: 45750 | G41: 1800004735 | H41: DR | I41: 45736 | J41: 45737 | K41: NA | L41: 246779414603 | M41: 212100 | N41: Trade Debtors (Ctrl) | P41: 1 | Q41: USD | R41: 412.38 | S41: INR | T41: 35749.74 | U41: O0 | V41: 6779224500 | X41: NA | Y41: 1 | Z41: {=_xlfn.XLOOKUP(L41,'Customer Ledger'!$O:$O,'Customer Ledger'!$P:$Q,,0)} -> 0 | AA41: 34760 | AB41: =AA41-Z41 -> 34760 | AC41: =T41-AB41 -> 989.74 | AD41: =AC41/T41 -> 0.027685236 | AE41: Outbound Handling charges for Oct 2024 | AI41: 45736
...

Sheet TDS 

Sheet Invoices not in customers books
A1: Document Number | B1: Document Type | C1: Document Date | D1: Reference | E1: Document Currency Key | F1: Document Currency Value | G1: Company Code Currency Key | H1: Company Code Currency Value | I1: Text | J1: Clearing Document
A2: 1600002697 | B2: DG | C2: 46027 | D2: 256779422167 | E2: USD | F2: -3.4 | G2: INR | H2: -308.53 | I2: Credit note for Duplicate invoice -256779418492 | K2: =IF(H2<0,H2*-1,H2) -> 308.53
A3: 1800003457 | B3: DR | C3: 45735 | D3: 246779413324 | E3: USD | F3: 4.3 | G3: INR | H3: 372.77 | I3: EOLU8605417-Port SSR Storage Feb 2025. Exch rate - | K3: =IF(H3<0,H3*-1,H3) -> 372.77
A4: 1800016637 | B4: DR | C4: 46028 | D4: 256779440257 | E4: USD | F4: 4.7 | G4: INR | H4: 426.49 | I4: CODC Out chgs -16-31 DEC 25 | K4: =IF(H4<0,H4*-1,H4) -> 426.49
A5: 1800016160 | B5: DR | C5: 46031 | D5: 256779440130 | E5: USD | F5: 16.45 | G5: INR | H5: 1492.72 | I5: CODC Out chgs -1-15 Nov 25 | K5: =IF(H5<0,H5*-1,H5) -> 1492.72
A6: 1800007089 | B6: DR | C6: 45763 | D6: 256779411980 | E6: USD | F6: 17.42 | G6: INR | H6: 1514.18 | I6: BEAU2827340-Port SSR Shifting Mar 2025. Exch rate | K6: =IF(H6<0,H6*-1,H6) -> 1514.18
A7: 1800007088 | B7: DR | C7: 45763 | D7: 256779411979 | E7: USD | F7: 37.56 | G7: INR | H7: 3264.78 | I7: GMCU3054416-Port SSR Shifting Mar 2025. Exch rate | K7: =IF(H7<0,H7*-1,H7) -> 3264.78
A8: 1800003342 | B8: DR | C8: 45735 | D8: 246779413209 | E8: USD | F8: 39.06 | G8: INR | H8: 3386.16 | I8: HMMU6832693-Port SSR Shifting Jan 2025. Exch rate | K8: =IF(H8<0,H8*-1,H8) -> 3386.16
A9: 1800003343 | B9: DR | C9: 45735 | D9: 246779413210 | E9: USD | F9: 39.06 | G9: INR | H9: 3386.16 | I9: KOCU4372804-Port SSR Shifting Jan 2025. Exch rate | K9: =IF(H9<0,H9*-1,H9) -> 3386.16
A10: 1800003345 | B10: DR | C10: 45735 | D10: 246779413212 | E10: USD | F10: 39.06 | G10: INR | H10: 3386.16 | I10: HDMU6860845-Port SSR Shifting Jan 2025. Exch rate | K10: =IF(H10<0,H10*-1,H10) -> 3386.16
A11: 1800015963 | B11: DR | C11: 46027 | D11: 256779440080 | E11: USD | F11: 41.46 | G11: INR | H11: 3762.21 | I11: Outbound chgs - 01 - 15 Dec 25 | K11: =IF(H11<0,H11*-1,H11) -> 3762.21
A12: 1800007087 | B12: DR | C12: 45763 | D12: 256779411978 | E12: USD | F12: 46.85 | G12: INR | H12: 4072.29 | I12: GMCU3054268-Port SSR Shifting Mar 2025. Exch rate | K12: =IF(H12<0,H12*-1,H12) -> 4072.29
A13: 1800016321 | B13: DR | C13: 46034 | D13: 256779440174 | E13: USD | F13: 48.8 | G13: INR | H13: 4428.27 | I13: CODC LCL Chgs -16-31 DEC 25 | K13: =IF(H13<0,H13*-1,H13) -> 4428.27
... A16: 1800003344 | B16: DR | C16: 45735 | D16: 246779413211 | E16: USD | F16: 78.12 | G16: INR | H16: 6772.32 | I16: TCNU8653352-Port SSR Shifting Jan 2025. Exch rate | K16: =IF(H16<0,H16*-1,H16) -> 6772.32
A17: 1600001746 | B17: DG | C17: 45854 | D17: 256779421378 | E17: USD | F17: -140 | G17: INR | H17: -12037.72 | I17: Credit Note raised against INV_256779413861 | J17: 1400001901 | K17: =IF(H17<0,H17*-1,H17) -> 12037.72
A18: 1600001816 | B18: DG | C18: 45862 | D18: 256779421436 | E18: USD | F18: -140 | G18: INR | H18: -12037.72 | I18: Credit Note raised against 256779413861 | K18: =IF(H18<0,H18*-1,H18) -> 12037.72
A19: 1800009097 | B19: DR | C19: 45795 | D19: 256779413861 | E19: USD | F19: 140 | G19: INR | H19: 12037.72 | I19: Scanning Chgs - 01 - 15 May 25 | J19: 1400001901 | K19: =IF(H19<0,H19*-1,H19) -> 12037.72
A20: 1800017152 | B20: DR | C20: 46049 | D20: 256779440445 | E20: USD | F20: 137.14 | G20: INR | H20: 12444.51 | I20: VAS-1-15 Jan 2026 | K20: =IF(H20<0,H20*-1,H20) -> 12444.51
A21: 1800010281 | B21: DR | C21: 45842 | D21: 256779415041 | E21: USD | F21: 155.09 | G21: INR | H21: 13337.84 | I21: PORT SSR Chgs June 25 | K21: =IF(H21<0,H21*-1,H21) -> 13337.84
A22: 1800014729 | B22: DR | C22: 45966 | D22: 256779419230 | E22: USD | F22: 179.58 | G22: INR | H22: 15803.65 | I22: PORT SSR Chgs Oct 25 | K22: =IF(H22<0,H22*-1,H22) -> 15803.65
A23: 1800013925 | B23: DR | C23: 45950 | D23: 256779418702 | E23: USD | F23: 182.87 | G23: INR | H23: 16127.45 | I23: Outbound chgs - 01 - 15 Oct 25 | K23: =IF(H23<0,H23*-1,H23) -> 16127.45
A24: 1800016314 | B24: DR | C24: 46034 | D24: 256779440167 | E24: USD | F24: 188 | G24: INR | H24: 17059.71 | I24: CY Ground rent Chgs - 16 - 31 Dec 25 | K24: =IF(H24<0,H24*-1,H24) -> 17059.71
A25: 1800013843 | B25: DR | C25: 45950 | D25: 256779418661 | E25: USD | F25: 226.3 | G25: INR | H25: 19957.57 | I25: Inbound chgs - 01 - 15 OCT 25 | K25: =IF(H25<0,H25*-1,H25) -> 19957.57
A26: 1800016416 | B26: DR | C26: 46034 | D26: 256779440229 | E26: USD | F26: 308.79 | G26: INR | H26: 28020.57 | I26: Outbound chgs - 16 - 31 Dec 25 | K26: =IF(H26<0,H26*-1,H26) -> 28020.57
A27: 1800013971 | B27: DR | C27: 45950 | D27: 256779418614 | E27: USD | F27: 338.06 | G27: INR | H27: 29813.77 | I27: CY - CY Grd Rent Chgs - 01 - 15 OCT 25 | K27: =IF(H27<0,H27*-1,H27) -> 29813.77
A28: 1800010769 | B28: DR | C28: 45856 | D28: 256779415431 | E28: USD | F28: 358.33 | G28: INR | H28: 30816.62 | I28: PORT SSR Chgs Apr & June 25 | K28: =IF(H28<0,H28*-1,H28) -> 30816.62
A29: 1800015801 | B29: DR | C29: 46027 | D29: 256779440051 | E29: USD | F29: 358.14 | G29: INR | H29: 32498.75 | I29: CY Ground rent Chgs - 01 - 15 Dec 25 | K29: =IF(H29<0,H29*-1,H29) -> 32498.75
A30: 1800016202 | B30: DR | C30: 46028 | D30: 256779440143 | E30: USD | F30: 360.75 | G30: INR | H30: 32735.59 | I30: CY - CY Grd Rent Chgs - 16 - 31 Dec 25 | K30: =IF(H30<0,H30*-1,H30) -> 32735.59
A31: 1800015473 | B31: DR | C31: 45997 | D31: 256779419990 | E31: USD | F31: 429.75 | G31: INR | H31: 38118.89 | I31: PORT SSR Chgs Nov 25 | K31: =IF(H31<0,H31*-1,H31) -> 38118.89
... A43: 1800016345 | B43: DR | C43: 46028 | D43: 256779440235 | E43: USD | F43: 7267.85 | G43: INR | H43: 659507.53 | I43: Unit Storage - 1-31 DEC 2025 | K43: =IF(H43<0,H43*-1,H43) -> 659507.53

Sheet Sheet4
A1: Document Number | B1: Document Type | C1: Document Date | D1: Reference | E1: Document Currency Key | F1: Document Currency Value | G1: Company Code Currency Key | H1: Company Code Currency Value | I1: Text | J1: Clearing Document | L1: `
A2: 1600001737 | B2: DG | C2: 45854 | D2: 256779421369 | E2: USD | F2: -1793.99 | G2: INR | H2: -155936.88 | I2: Credit Note raised against INV_256779410010 | J2: 1400001901 | K2: 256779410010 | L2: #N/A
A3: 1600001736 | B3: DG | C3: 45854 | D3: 256779421368 | E3: USD | F3: -705 | G3: INR | H3: -61279.88 | I3: Credit Note raised against INV_256779410004 | J3: 1400001901 | K3: 256779410004 | L3: #N/A
A4: 1600001753 | B4: DG | C4: 45854 | D4: 256779421385 | E4: USD | F4: -420 | G4: INR | H4: -36410.33 | I4: Credit note Note raised against INV_246779411278 | J4: 1400001902 | K4: 246779411278 | L4: #N/A
A5: 1600001740 | B5: DG | C5: 45854 | D5: 256779421372 | E5: USD | F5: -385 | G5: INR | H5: -33376.14 | I5: Credit Note raised against INV_246779411300 | J5: 1400001901 | K5: 246779411300 | L5: #N/A
A6: 1600001733 | B6: DG | C6: 45854 | D6: 256779421365 | E6: USD | F6: -375 | G6: INR | H6: -32509.22 | I6: Credit Note raised against INV_246779413827 | J6: 1400001901 | K6: 246779413827 | L6: #N/A
A7: 1600001742 | B7: DG | C7: 45854 | D7: 256779421374 | E7: USD | F7: -245 | G7: INR | H7: -21239.36 | I7: Credit Note raised against INV_246779411326 | J7: 1400001901 | K7: 246779411326 | L7: #N/A
A8: 1600001730 | B8: DG | C8: 45854 | D8: 256779421362 | E8: USD | F8: -237.35 | G8: INR | H8: -20576.17 | I8: Credit Note raised against INV_246779413705 | J8: 1400001901 | K8: 246779413705 | L8: #N/A
A9: 1600001732 | B9: DG | C9: 45854 | D9: 256779421364 | E9: USD | F9: -220 | G9: INR | H9: -19072.08 | I9: Credit Note raised against INV_246779413816 | J9: 1400001901 | K9: 246779413816 | L9: #N/A
A10: 1600001743 | B10: DG | C10: 45854 | D10: 256779421375 | E10: USD | F10: -220 | G10: INR | H10: -19072.08 | I10: Credit Note raised against INV_246779411339 | J10: 1400001901 | K10: 246779411339 | L10: #N/A
A11: 1600001748 | B11: DG | C11: 45854 | D11: 256779421380 | E11: USD | F11: -182.83 | G11: INR | H11: -15778.9 | I11: Credit note Note raised against INV_246779410348 | J11: 1400001902 | K11: 246779410348 | L11: #N/A
A12: 1600001750 | B12: DG | C12: 45854 | D12: 256779421382 | E12: USD | F12: -177.66 | G12: INR | H12: -15401.57 | I12: Credit note Note raised against INV_246779413701 | J12: 1400001902 | K12: 246779413701 | L12: #N/A
A13: 1600001745 | B13: DG | C13: 45854 | D13: 256779421377 | E13: USD | F13: -140 | G13: INR | H13: -12037.72 | I13: Credit Note raised against INV_256779413283 | J13: 1400001901 | K13: 256779413283 | L13: #N/A
A14: 1600001816 | B14: DG | C14: 45862 | D14: 256779421436 | E14: USD | F14: -140 | G14: INR | H14: -12037.72 | I14: Credit Note raised against 256779413861 | L14: 12037.72
A15: 1600001752 | B15: DG | C15: 45854 | D15: 256779421384 | E15: USD | F15: -137.9 | G15: INR | H15: -11954.72 | I15: Credit note Note raised against INV_246779413845 | J15: 1400001902 | K15: 246779413845 | L15: #N/A
A16: 1600002697 | B16: DG | C16: 46027 | D16: 256779422167 | E16: USD | F16: -3.4 | G16: INR | H16: -308.53 | I16: Credit note for Duplicate invoice -256779418492 | K16: 256779418492 | L16: #N/A
