Workbook

Sheet Summary
A1: Reconciliation of Ledger as on 31st January 2026
A2: Particulars | B2: Amount In USD
A3: Balance as per SML Limited | B3: 0
A4: Add: TDS entries given by BMAC | B4: 0 | C4: >> Working For Knocking Off Done
A5: Add: TDS entries pending | B5: =-'TDS Ledger'!H55+'Payment Reco'!J11 -> 428.67 | C5: >> Pending Due to Outstanding Payable by customer
A6: Add: Invoices not recorded in customer books | B6: ='Invoice not in customers books'!F4 -> 112.61 | C6: Invoice Booked with Doc No 5100026202 & 5100026207
A7: Add: Diffrence in Payment recorded in both books | B7: ='Payment Reco'!D10 -> 1733.59 | C7: >> Payment Received on 06/03/2026
A8: Add: Exchange gain loss | B8: =-'Customer Ledger'!D55+0.02 -> 9.09
A9: Derived balance | B9: =SUM(B3:B8) -> 2283.96
A10: Balance as per Ascent | B10: ='CL Ledger'!H99 -> 2283.96
B11: 0
A12: Difference | B12: =B9-B10-B11 -> -4.5474735e-13

Sheet Customer Ledger
A1: Account | B1: Reference | C1: Document Date | D1: Amount in Doc. Curr.-USD | E1: Amount in Local Currency-INR | F1: Text | G1: Assignment | H1: Withholding Tax Amt-USD | I1: Withhldg Tax Base Amount-INR | J1: Xlookup | K1: Exchange Rate | L1: TDS in INR
A2: 60000472 | B2: NSMT0824926 | C2: 45931 | D2: 2032.13 | E2: 180144.46 | F2: PAID AGAINST INV.NO. 256779414933/6044/7363 | G2: NSMT0824926 | H2: 0 | I2: 0 | J2: Payment | K2: =E2/D2 -> 88.648098 | L2: =H2*K2 -> 0
A3: 60000472 | B3: 256779414933 | C3: 45842 | D3: -680.4 | E3: -60470.35 | F3: storage charges july 2025 | G3: 256779414933 | H3: -75.6 | I3: -756 | J3: =_xlfn.XLOOKUP('Customer Ledger'!B3,'CL Ledger'!$F:$F,'CL Ledger'!$H:$H,,0) -> 756 | K3: =E3/D3 -> 88.874706 | L3: =H3*K3 -> -6718.9278
A4: 60000472 | B4: 256779416044 | C4: 45870 | D4: -680.4 | E4: -60470.35 | F4: storage charges august 2025 | G4: 256779416044 | H4: -75.6 | I4: -756 | J4: =_xlfn.XLOOKUP('Customer Ledger'!B4,'CL Ledger'!$F:$F,'CL Ledger'!$H:$H,,0) -> 756 | K4: =E4/D4 -> 88.874706 | L4: =H4*K4 -> -6718.9278
A5: 60000472 | B5: 256779417363 | C5: 45904 | D5: -680.4 | E5: -60470.35 | F5: storage charges sept 2025 | G5: 256779417363 | H5: -75.6 | I5: -756 | J5: =_xlfn.XLOOKUP('Customer Ledger'!B5,'CL Ledger'!$F:$F,'CL Ledger'!$H:$H,,0) -> 756 | K5: =E5/D5 -> 88.874706 | L5: =H5*K5 -> -6718.9278
A6: 60000472 | B6: NSMT0548526 | C6: 45869 | D6: 750.97 | E6: 65857.88 | F6: PAID AGAINST INV.NO.5406/5404/02/03/01/399 | G6: NSMT0548526 | H6: 0 | I6: 834.4 | J6: Payment | K6: =E6/D6 -> 87.697085 | L6: =H6*K6 -> 0
A7: 60000472 | B7: NSMT0548526 | C7: 45869 | D7: 7484.4 | E7: 656363.29 | F7: PAID AGAINST INV.NO. | H7: 0 | I7: 8316 | J7: Payment | K7: =E7/D7 -> 87.697516 | L7: =H7*K7 -> 0
A8: 60000472 | B8: 256779415405 | C8: 45854 | D8: -750.97 | E8: -65857.88 | F8: Storage charges for Aug 2024 | G8: 256779415405 | H8: -83.43 | I8: -834.4 | J8: =_xlfn.XLOOKUP('Customer Ledger'!B8,'CL Ledger'!$F:$F,'CL Ledger'!$H:$H,,0) -> 834.4 | K8: =E8/D8 -> 87.697085 | L8: =H8*K8 -> -7316.5678
A9: 60000472 | B9: 256779415404 | C9: 45854 | D9: -680.4 | E9: -59669.39 | F9: WAREHOUSE RENT FOR SEPT 24 | G9: 256779415404 | H9: -75.6 | I9: -756 | J9: =_xlfn.XLOOKUP('Customer Ledger'!B9,'CL Ledger'!$F:$F,'CL Ledger'!$H:$H,,0) -> 756 | K9: =E9/D9 -> 87.697516 | L9: =H9*K9 -> -6629.9322
A10: 60000472 | B10: 256779415402 | C10: 45854 | D10: -680.4 | E10: -59669.39 | F10: Storage charges for Feb 2025 | G10: 256779415402 | H10: -75.6 | I10: -756 | J10: =_xlfn.XLOOKUP('Customer Ledger'!B10,'CL Ledger'!$F:$F,'CL Ledger'!$H:$H,,0) -> 756 | K10: =E10/D10 -> 87.697516 | L10: =H10*K10 -> -6629.9322
A11: 60000472 | B11: 256779415403 | C11: 45854 | D11: -680.4 | E11: -59669.39 | F11: Storage charges for Oct 2024 | G11: 256779415403 | H11: -75.6 | I11: -756 | J11: =_xlfn.XLOOKUP('Customer Ledger'!B11,'CL Ledger'!$F:$F,'CL Ledger'!$H:$H,,0) -> 756 | K11: =E11/D11 -> 87.697516 | L11: =H11*K11 -> -6629.9322
A12: 60000472 | B12: 256779415401 | C12: 45854 | D12: -680.4 | E12: -59669.39 | F12: Storage charges for Jan 2025 | G12: 256779415401 | H12: -75.6 | I12: -756 | J12: =_xlfn.XLOOKUP('Customer Ledger'!B12,'CL Ledger'!$F:$F,'CL Ledger'!$H:$H,,0) -> 756 | K12: =E12/D12 -> 87.697516 | L12: =H12*K12 -> -6629.9322
A13: 60000472 | B13: 256779415400 | C13: 45854 | D13: -680.4 | E13: -59669.39 | F13: WAREHOUSE RENT FOR DEC 2024 | G13: 256779415400 | H13: -75.6 | I13: -756 | J13: =_xlfn.XLOOKUP('Customer Ledger'!B13,'CL Ledger'!$F:$F,'CL Ledger'!$H:$H,,0) -> 756 | K13: =E13/D13 -> 87.697516 | L13: =H13*K13 -> -6629.9322
A14: 60000472 | B14: 256779415399 | C14: 45854 | D14: -680.4 | E14: -59669.39 | F14: Storage charges for Nov 2024 | G14: 256779415399 | H14: -75.6 | I14: -756 | J14: =_xlfn.XLOOKUP('Customer Ledger'!B14,'CL Ledger'!$F:$F,'CL Ledger'!$H:$H,,0) -> 756 | K14: =E14/D14 -> 87.697516 | L14: =H14*K14 -> -6629.9322
A15: 60000472 | B15: 256779415398 | C15: 45854 | D15: -680.4 | E15: -59669.39 | F15: Storage charges for Aug 2024 | G15: 256779415398 | H15: -75.6 | I15: -756 | J15: =_xlfn.XLOOKUP('Customer Ledger'!B15,'CL Ledger'!$F:$F,'CL Ledger'!$H:$H,,0) -> 756 | K15: =E15/D15 -> 87.697516 | L15: =H15*K15 -> -6629.9322
A16: 60000472 | B16: 256779415397 | C16: 45854 | D16: -680.4 | E16: -59669.39 | F16: Storage charges for Mar 2025 | G16: 256779415397 | H16: -75.6 | I16: -756 | J16: =_xlfn.XLOOKUP('Customer Ledger'!B16,'CL Ledger'!$F:$F,'CL Ledger'!$H:$H,,0) -> 756 | K16: =E16/D16 -> 87.697516 | L16: =H16*K16 -> -6629.9322
A17: 60000472 | B17: 256779412157 | C17: 45768 | D17: -680.4 | E17: -59669.39 | F17: Storage charges for April 2025 | G17: 256779412157 | H17: -75.6 | I17: -756 | J17: =_xlfn.XLOOKUP('Customer Ledger'!B17,'CL Ledger'!$F:$F,'CL Ledger'!$H:$H,,0) -> 756 | K17: =E17/D17 -> 87.697516 | L17: =H17*K17 -> -6629.9322
A18: 60000472 | B18: 256779413116 | C18: 45787 | D18: -680.4 | E18: -59669.39 | F18: Storage charges for May 2025 | G18: 256779413116 | H18: -75.6 | I18: -756 | J18: =_xlfn.XLOOKUP('Customer Ledger'!B18,'CL Ledger'!$F:$F,'CL Ledger'!$H:$H,,0) -> 756 | K18: =E18/D18 -> 87.697516 | L18: =H18*K18 -> -6629.9322
A19: 60000472 | B19: 256779414375 | C19: 45818 | D19: -680.4 | E19: -59669.39 | F19: Storage charges for June 2025 | G19: 256779414375 | H19: -75.6 | I19: -756 | J19: =_xlfn.XLOOKUP('Customer Ledger'!B19,'CL Ledger'!$F:$F,'CL Ledger'!$H:$H,,0) -> 756 | K19: =E19/D19 -> 87.697516 | L19: =H19*K19 -> -6629.9322
A20: 60000472 | B20: NSMT0671126 | C20: 45898 | D20: 411.6 | E20: 36049.56 | F20: PAID AGAINST INV.NO.11604/605/606 | H20: 0 | I20: 420 | J20: Payment | K20: =E20/D20 -> 87.583965 | L20: =H20*K20 -> 0
A21: 60000472 | B21: 256779411605 | C21: 45762 | D21: -137.2 | E21: -12016.52 | F21: Handling charges for Aug 2024 | G21: 256779411605 | H21: -2.8 | I21: -140 | J21: =_xlfn.XLOOKUP('Customer Ledger'!B21,'CL Ledger'!$F:$F,'CL Ledger'!$H:$H,,0) -> 140 | K21: =E21/D21 -> 87.583965 | L21: =H21*K21 -> -245.2351
A22: 60000472 | B22: 256779411604 | C22: 45762 | D22: -137.2 | E22: -12016.52 | F22: Handling charges for Aug 2024 | G22: 256779411604 | H22: -2.8 | I22: -140 | J22: =_xlfn.XLOOKUP('Customer Ledger'!B22,'CL Ledger'!$F:$F,'CL Ledger'!$H:$H,,0) -> 140 | K22: =E22/D22 -> 87.583965 | L22: =H22*K22 -> -245.2351
A23: 60000472 | B23: 256779415396 | C23: 45854 | D23: -137.2 | E23: -12016.52 | F23: Handling charges for SEPT 2024 | H23: -2.8 | I23: -140 | J23: =_xlfn.XLOOKUP('Customer Ledger'!B23,'CL Ledger'!$F:$F,'CL Ledger'!$H:$H,,0) -> 140 | K23: =E23/D23 -> 87.583965 | L23: =H23*K23 -> -245.2351
A24: 60000472 | B24: 256779411605 | C24: 45762 | D24: 137.2 | E24: 12016.52 | F24: Handling charges for Aug 2024 | G24: 256779411605 | H24: 2.8 | I24: 140 | J24: =_xlfn.XLOOKUP('Customer Ledger'!B24,'CL Ledger'!$F:$F,'CL Ledger'!$H:$H,,0) -> 140 | K24: =E24/D24 -> 87.583965 | L24: =H24*K24 -> 245.2351
A25: 60000472 | B25: 256779411604 | C25: 45762 | D25: 137.2 | E25: 12016.52 | F25: Handling charges for Aug 2024 | G25: 256779411604 | H25: 2.8 | I25: 140 | J25: =_xlfn.XLOOKUP('Customer Ledger'!B25,'CL Ledger'!$F:$F,'CL Ledger'!$H:$H,,0) -> 140 | K25: =E25/D25 -> 87.583965 | L25: =H25*K25 -> 245.2351
A26: 60000472 | B26: 256779411605 | C26: 45397 | D26: -137.2 | E26: -12016.52 | F26: Handling charges for Aug 2024 | G26: 256779411605 | H26: -2.8 | I26: -140 | J26: =_xlfn.XLOOKUP('Customer Ledger'!B26,'CL Ledger'!$F:$F,'CL Ledger'!$H:$H,,0) -> 140 | K26: =E26/D26 -> 87.583965 | L26: =H26*K26 -> -245.2351
A27: 60000472 | B27: 256779411604 | C27: 45762 | D27: -137.2 | E27: -12016.52 | F27: Handling charges for Aug 2024 | G27: 256779411604 | H27: -2.8 | I27: -140 | J27: =_xlfn.XLOOKUP('Customer Ledger'!B27,'CL Ledger'!$F:$F,'CL Ledger'!$H:$H,,0) -> 140 | K27: =E27/D27 -> 87.583965 | L27: =H27*K27 -> -245.2351
A28: 60000472 | B28: NSMT0818226 | C28: 45931 | D28: 1478.15 | E28: 130858.37 | F28: PAID AGAINST INV.NO. 6818/7208/5049/7246 | H28: 0 | I28: 1508.31 | J28: Payment | K28: =E28/D28 -> 88.528478 | L28: =H28*K28 -> 0
A29: 60000472 | B29: 256779416818 | C29: 45889 | D29: -470.4 | E29: -41294.52 | F29: Transporation charges against inv.no. 25FZ05041 | G29: 256779416818 | H29: -9.6 | I29: -480 | J29: =_xlfn.XLOOKUP('Customer Ledger'!B29,'CL Ledger'!$F:$F,'CL Ledger'!$H:$H,,0) -> 480 | K29: =E29/D29 -> 87.785969 | L29: =H29*K29 -> -842.74531
A30: 60000472 | B30: 256779417208 | C30: 45870 | D30: -62.03 | E30: -5512.89 | F30: emty contenar unloading charges | G30: 256779417208 | H30: -1.26 | I30: -63.29 | J30: =_xlfn.XLOOKUP('Customer Ledger'!B30,'CL Ledger'!$F:$F,'CL Ledger'!$H:$H,,0) -> 63.29 | K30: =E30/D30 -> 88.874577 | L30: =H30*K30 -> -111.98197
A31: 60000472 | B31: 256779415049 | C31: 45842 | D31: -17.19 | E31: -1527.86 | F31: bond stamp paper charges | G31: 256779415049 | H31: -0.35 | I31: -17.54 | J31: =_xlfn.XLOOKUP('Customer Ledger'!B31,'CL Ledger'!$F:$F,'CL Ledger'!$H:$H,,0) -> 17.54 | K31: =E31/D31 -> 88.880745 | L31: =H31*K31 -> -31.108261
A32: 60000472 | B32: 256779417246 | C32: 45904 | D32: -179.87 | E32: -15986.08 | F32: port ssr charges (transpotation charges) | G32: 256779417246 | H32: -3.67 | I32: -183.54 | J32: =_xlfn.XLOOKUP('Customer Ledger'!B32,'CL Ledger'!$F:$F,'CL Ledger'!$H:$H,,0) -> 183.54 | K32: =E32/D32 -> 88.875744 | L32: =H32*K32 -> -326.17398
A33: 60000472 | B33: 256779417329 | C33: 45914 | D33: -86.21 | E33: -7662.32 | F33: outbond charges | G33: 256779417329 | H33: -1.76 | I33: -87.97 | J33: =_xlfn.XLOOKUP('Customer Ledger'!B33,'CL Ledger'!$F:$F,'CL Ledger'!$H:$H,,0) -> 87.97 | K33: =E33/D33 -> 88.879712 | L33: =H33*K33 -> -156.42829
A34: 60000472 | B34: 256779417289 | C34: 45904 | D34: -662.45 | E34: -58874.7 | F34: transporation charges | G34: 256779417289 | H34: -13.52 | I34: -675.97 | J34: =_xlfn.XLOOKUP('Customer Ledger'!B34,'CL Ledger'!$F:$F,'CL Ledger'!$H:$H,,0) -> 675.97 | K34: =E34/D34 -> 88.874179 | L34: =H34*K34 -> -1201.5789
A35: 60000472 | B35: NSMT0881326 | C35: 45946 | D35: 631.98 | E35: 56117.65 | F35: PAID AGAINST INV.NO. 256779417570/7529/7443 | H35: 0 | I35: 644.87 | J35: Payment | K35: =E35/D35 -> 88.79656 | L35: =H35*K35 -> 0
A36: 60000472 | B36: 256779417529 | C36: 45918 | D36: -168.52 | E36: -14969.54 | F36: Loading chargs from 1-15/9/2025 | G36: 256779417529 | H36: -3.43 | I36: -171.95 | J36: =_xlfn.XLOOKUP('Customer Ledger'!B36,'CL Ledger'!$F:$F,'CL Ledger'!$H:$H,,0) -> 171.95 | K36: =E36/D36 -> 88.829456 | L36: =H36*K36 -> -304.68504
A37: 60000472 | B37: 256779417570 | C37: 45918 | D37: -439.04 | E37: -39000.42 | F37: Transaporation charges from 1-15/9/2025 | G37: 256779417570 | H37: -8.96 | I37: -448 | J37: =_xlfn.XLOOKUP('Customer Ledger'!B37,'CL Ledger'!$F:$F,'CL Ledger'!$H:$H,,0) -> 448 | K37: =E37/D37 -> 88.831132 | L37: =H37*K37 -> -795.92694
A38: 60000472 | B38: 256779417443 | C38: 45917 | D38: -24.42 | E38: -2147.69 | F38: MT contenar transport charges | G38: 256779417443 | H38: -0.5 | I38: -24.92 | J38: =_xlfn.XLOOKUP('Customer Ledger'!B38,'CL Ledger'!$F:$F,'CL Ledger'!$H:$H,,0) -> 24.92 | K38: =E38/D38 -> 87.947993 | L38: =H38*K38 -> -43.973997
A39: 60000472 | B39: NSMT1165026 | C39: 46007 | D39: 2754.77 | E39: 247026.06 | F39: PAID AGAINST INV.NO.418013/9135/9234/9203 | H39: 0 | I39: 2943.55 | J39: Payment | K39: =E39/D39 -> 89.672118 | L39: =H39*K39 -> 0
A40: 60000472 | B40: 256779418665 | C40: 45950 | D40: -45.57 | E40: -4063.47 | F40: outbond charges | G40: 256779418665 | H40: -0.93 | I40: -46.5 | J40: =_xlfn.XLOOKUP('Customer Ledger'!B40,'CL Ledger'!$F:$F,'CL Ledger'!$H:$H,,0) -> 46.5 | K40: =E40/D40 -> 89.169849 | L40: =H40*K40 -> -82.927959
...

Sheet CL Ledger
A1: Document Number | B1: Document Type | C1: Document Date | D1: Entry Date | E1: Document Header Text | F1: Reference | G1: Document Currency Key | H1: Document Currency Value | I1: Company Code Currency Key | J1: Company Code Currency Value | K1: TDS | L1: Total Invoice Value | M1: TDS Rate | N1: Text | O1: Clearing Document
A2: 1400001106 | B2: DY | C2: 45902 | D2: 45902 | G2: INR | H2: 132321.66 | I2: INR | J2: 130033.02 | K2: {=_xlfn.XLOOKUP(F2,'Customer Ledger'!$B:$B,'Customer Ledger'!$H:$I,,0)} -> #N/A | O2: 1400001106
A3: 1400001106 | B3: DY | C3: 45902 | D3: 45902 | G3: INR | H3: -132321.66 | I3: INR | J3: -129262.06 | K3: {=_xlfn.XLOOKUP(F3,'Customer Ledger'!$B:$B,'Customer Ledger'!$H:$I,,0)} -> #N/A | O3: 1400001106
A4: 1400001172 | B4: DZ | C4: 45912 | D4: 45912 | E4: 2178269241JS | G4: USD | H4: -140 | I4: INR | J4: -12040.09 | K4: {=_xlfn.XLOOKUP(F4,'Customer Ledger'!$B:$B,'Customer Ledger'!$H:$I,,0)} -> #N/A | N4: 2178269241JS | O4: 1400001172
A5: 1400002219 | B5: DZ | C5: 46009 | D5: 46009 | E5: T54SWIC283727 | G5: USD | H5: -170.89 | I5: INR | J5: -15038.9 | K5: {=_xlfn.XLOOKUP(F5,'Customer Ledger'!$B:$B,'Customer Ledger'!$H:$I,,0)} -> #N/A | N5: T54SWIC283727 | O5: 1400002219
A6: 1400002219 | B6: DZ | C6: 46009 | D6: 46009 | E6: T54SWIC283727 | G6: USD | H6: -2772.66 | I6: INR | J6: -244261.12 | K6: {=_xlfn.XLOOKUP(F6,'Customer Ledger'!$B:$B,'Customer Ledger'!$H:$I,,0)} -> #N/A | N6: T54SWIC283727 | O6: 1400002219
A7: 1400002015 | B7: DZ | C7: 45986 | D7: 45986 | E7: T54SWIC276317 | G7: USD | H7: -1478.14 | I7: INR | J7: -130358.3 | K7: {=_xlfn.XLOOKUP(F7,'Customer Ledger'!$B:$B,'Customer Ledger'!$H:$I,,0)} -> #N/A
A8: 1400002021 | B8: DZ | C8: 45986 | D8: 45986 | E8: T54SWIC276290 | G8: USD | H8: -2032.13 | I8: INR | J8: -179215.11 | K8: {=_xlfn.XLOOKUP(F8,'Customer Ledger'!$B:$B,'Customer Ledger'!$H:$I,,0)} -> #N/A
A9: 1400001171 | B9: DZ | C9: 45912 | D9: 45912 | E9: T54SWIC270284 | G9: USD | H9: -9150.4 | I9: INR | J9: -786398.11 | K9: {=_xlfn.XLOOKUP(F9,'Customer Ledger'!$B:$B,'Customer Ledger'!$H:$I,,0)} -> #N/A | N9: T54SWIC270284 | O9: 1400001171
A10: 1400001172 | B10: DZ | C10: 45912 | D10: 45912 | E10: 2178269241JS | G10: USD | H10: -280 | I10: INR | J10: -24338.1 | K10: {=_xlfn.XLOOKUP(F10,'Customer Ledger'!$B:$B,'Customer Ledger'!$H:$I,,0)} -> #N/A | N10: 2178269241JS | O10: 1400001172
A11: 1400001176 | B11: DZ | C11: 45908 | D11: 45915 | E11: 2178269241JS | G11: USD | H11: 411.6 | I11: INR | J11: 36020.9 | K11: {=_xlfn.XLOOKUP(F11,'Customer Ledger'!$B:$B,'Customer Ledger'!$H:$I,,0)} -> #N/A | O11: 1400001176
A12: 1400001154 | B12: DZ | C12: 45908 | D12: 45908 | E12: 2178269241JS | G12: USD | H12: -411.6 | I12: INR | J12: -36020.9 | K12: {=_xlfn.XLOOKUP(F12,'Customer Ledger'!$B:$B,'Customer Ledger'!$H:$I,,0)} -> #N/A | O12: 1400001176
A13: 1400002224 | B13: DZ | C13: 45887 | D13: 46010 | E13: 2148164212JS | G13: USD | H13: 8235.36 | I13: INR | J13: 708489.01 | K13: {=_xlfn.XLOOKUP(F13,'Customer Ledger'!$B:$B,'Customer Ledger'!$H:$I,,0)} -> #N/A | O13: 1400002224
A14: 1400000846 | B14: DZ | C14: 45887 | D14: 45887 | E14: 2148164212JS | G14: USD | H14: -8235.36 | I14: INR | J14: -708489.01 | K14: {=_xlfn.XLOOKUP(F14,'Customer Ledger'!$B:$B,'Customer Ledger'!$H:$I,,0)} -> #N/A | O14: 1400002224
A15: 1400001579 | B15: DZ | C15: 45960 | D15: 45960 | E15: T54SWIC277677 | G15: USD | H15: -631.97 | I15: INR | J15: -55733.92 | K15: {=_xlfn.XLOOKUP(F15,'Customer Ledger'!$B:$B,'Customer Ledger'!$H:$I,,0)} -> #N/A
A16: 1400002017 | B16: DZ | C16: 45972 | D16: 45986 | E16: T54SWIC276317 | G16: USD | H16: 1478.14 | I16: INR | J16: 130358.3 | K16: {=_xlfn.XLOOKUP(F16,'Customer Ledger'!$B:$B,'Customer Ledger'!$H:$I,,0)} -> #N/A | O16: 1400002017
A17: 1400001621 | B17: DZ | C17: 45972 | D17: 45972 | E17: T54SWIC276317 | G17: USD | H17: -1478.14 | I17: INR | J17: -130358.3 | K17: {=_xlfn.XLOOKUP(F17,'Customer Ledger'!$B:$B,'Customer Ledger'!$H:$I,,0)} -> #N/A | O17: 1400002017
A18: 1400002037 | B18: DZ | C18: 45972 | D18: 45986 | E18: T54SWIC276290 | G18: USD | H18: 2032.13 | I18: INR | J18: 179215.11 | K18: {=_xlfn.XLOOKUP(F18,'Customer Ledger'!$B:$B,'Customer Ledger'!$H:$I,,0)} -> #N/A | O18: 1400002037
A19: 1400001623 | B19: DZ | C19: 45972 | D19: 45972 | E19: T54SWIC276290 | G19: USD | H19: -2032.13 | I19: INR | J19: -179215.11 | K19: {=_xlfn.XLOOKUP(F19,'Customer Ledger'!$B:$B,'Customer Ledger'!$H:$I,,0)} -> #N/A | O19: 1400002037
A20: 1400000194 | B20: DY | C20: 45842 | D20: 45842 | E20: NA | F20: KNOCK OFF ENTRY | G20: USD | H20: 756 | I20: INR | J20: 65712.9 | K20: {=_xlfn.XLOOKUP(F20,'Customer Ledger'!$B:$B,'Customer Ledger'!$H:$I,,0)} -> #N/A | O20: 1400000194
A21: 1400000194 | B21: DY | C21: 45842 | D21: 45842 | E21: NA | F21: KNOCK OFF ENTRY | G21: USD | H21: -756 | I21: INR | J21: -65712.9 | K21: {=_xlfn.XLOOKUP(F21,'Customer Ledger'!$B:$B,'Customer Ledger'!$H:$I,,0)} -> #N/A | O21: 1400000194
A22: 1400000195 | B22: DY | C22: 45842 | D22: 45842 | E22: NA | F22: KNOCK OFF ENTRY | G22: USD | H22: 756 | I22: INR | J22: 65712.9 | K22: {=_xlfn.XLOOKUP(F22,'Customer Ledger'!$B:$B,'Customer Ledger'!$H:$I,,0)} -> #N/A | O22: 1400000195
A23: 1400000195 | B23: DY | C23: 45842 | D23: 45842 | E23: NA | F23: KNOCK OFF ENTRY | G23: USD | H23: -756 | I23: INR | J23: -65712.9 | K23: {=_xlfn.XLOOKUP(F23,'Customer Ledger'!$B:$B,'Customer Ledger'!$H:$I,,0)} -> #N/A | O23: 1400000195
A24: 1400001906 | B24: DY | C24: 45976 | D24: 45976 | E24: NA | F24: KNOCK OFF ENTRY | G24: USD | H24: 0 | I24: INR | J24: -2798.42 | K24: {=_xlfn.XLOOKUP(F24,'Customer Ledger'!$B:$B,'Customer Ledger'!$H:$I,,0)} -> #N/A | O24: 1400001906
A25: 1800000420 | B25: DR | C25: 45719 | D25: 45719 | E25: NA | F25: 246779410382 | G25: USD | H25: 834.4 | I25: INR | J25: 72335.19 | K25: {=_xlfn.XLOOKUP(F25,'Customer Ledger'!$B:$B,'Customer Ledger'!$H:$I,,0)} -> #N/A | N25: Storage Charges for the month of August, 2024 | O25: 1400001906
A26: 1800011335 | B26: DR | C26: 45870 | D26: 45873 | E26: NA | F26: 256779416044 | G26: USD | H26: 756 | I26: INR | J26: 65038.77 | K26: {=_xlfn.XLOOKUP(F26,'Customer Ledger'!$B:$B,'Customer Ledger'!$H:$I,,0)} -> -75.6 | L26: -756 | M26: =(K26/H26)*-1 -> 0.1 | N26: Fixed Storage Charges for August 2025 | P26: -1
A27: 1800009611 | B27: DR | C27: 45818 | D27: 45825 | E27: NA | F27: 256779414375 | G27: USD | H27: 756 | I27: INR | J27: 64631.03 | K27: {=_xlfn.XLOOKUP(F27,'Customer Ledger'!$B:$B,'Customer Ledger'!$H:$I,,0)} -> -75.6 | L27: -756 | M27: =(K27/H27)*-1 -> 0.1 | N27: Fixed Storage Charges fo JUNE 2025 | O27: 1400001171
A28: 1800012789 | B28: DR | C28: 45917 | D28: 45922 | E28: NA | F28: 256779417443 | G28: USD | H28: 24.92 | I28: INR | J28: 2180.86 | K28: {=_xlfn.XLOOKUP(F28,'Customer Ledger'!$B:$B,'Customer Ledger'!$H:$I,,0)} -> -0.5 | L28: -24.92 | M28: =(K28/H28)*-1 -> 0.020064205 | N28: VAS -1-15 Sept-25
A29: 1800006713 | B29: DR | C29: 45762 | D29: 45763 | E29: NA | F29: 256779411604 | G29: USD | H29: 140 | I29: INR | J29: 12169.05 | K29: {=_xlfn.XLOOKUP(F29,'Customer Ledger'!$B:$B,'Customer Ledger'!$H:$I,,0)} -> -2.8 | L29: -140 | M29: =(K29/H29)*-1 -> 0.02 | N29: Outbound Handling Charges Aug 2024 | O29: 1400001172
A30: 1800006714 | B30: DR | C30: 45762 | D30: 45763 | E30: NA | F30: 256779411605 | G30: USD | H30: 140 | I30: INR | J30: 12169.05 | K30: {=_xlfn.XLOOKUP(F30,'Customer Ledger'!$B:$B,'Customer Ledger'!$H:$I,,0)} -> -2.8 | L30: -140 | M30: =(K30/H30)*-1 -> 0.02 | N30: Outbound Handling Charges Aug 2024 | O30: 1400001172
A31: 1800012588 | B31: DR | C31: 45904 | D31: 45909 | E31: NA | F31: 256779417246 | G31: USD | H31: 183.54 | I31: INR | J31: 16062.38 | K31: {=_xlfn.XLOOKUP(F31,'Customer Ledger'!$B:$B,'Customer Ledger'!$H:$I,,0)} -> -3.67 | L31: -183.54 | M31: =(K31/H31)*-1 -> 0.019995641 | N31: PORT SSR Chgs Aug 25
A32: 1800012621 | B32: DR | C32: 45904 | D32: 45909 | E32: NA | F32: 256779417208 | G32: USD | H32: 63.29 | I32: INR | J32: 5538.78 | K32: {=_xlfn.XLOOKUP(F32,'Customer Ledger'!$B:$B,'Customer Ledger'!$H:$I,,0)} -> -1.26 | L32: -63.29 | M32: =(K32/H32)*-1 -> 0.019908358 | N32: Empty Lolo Chgs - 01 - 31 AUG 25
A33: 1800012649 | B33: DR | C33: 45904 | D33: 45909 | E33: NA | F33: 256779417289 | G33: USD | H33: 675.97 | I33: INR | J33: 59157.06 | K33: {=_xlfn.XLOOKUP(F33,'Customer Ledger'!$B:$B,'Customer Ledger'!$H:$I,,0)} -> -13.52 | L33: -675.97 | M33: =(K33/H33)*-1 -> 0.020000888 | N33: Transportation In Chgs - 16 - 31 AUG 25
A34: 1800012689 | B34: DR | C34: 45904 | D34: 45909 | E34: NA | F34: 256779417329 | G34: USD | H34: 87.97 | I34: INR | J34: 7698.64 | K34: {=_xlfn.XLOOKUP(F34,'Customer Ledger'!$B:$B,'Customer Ledger'!$H:$I,,0)} -> -1.76 | L34: -87.97 | M34: =(K34/H34)*-1 -> 0.020006821 | N34: Outbound chgs - 16 - 31 Aug 25
A35: 1800012729 | B35: DR | C35: 45904 | D35: 45909 | E35: NA | F35: 256779417363 | G35: USD | H35: 756 | I35: INR | J35: 66160.83 | K35: {=_xlfn.XLOOKUP(F35,'Customer Ledger'!$B:$B,'Customer Ledger'!$H:$I,,0)} -> -75.6 | L35: -756 | M35: =(K35/H35)*-1 -> 0.1 | N35: Fixed Storage Charges for September 2025
A36: 1800010173 | B36: DR | C36: 45842 | D36: 45847 | E36: NA | F36: 256779414933 | G36: USD | H36: 756 | I36: INR | J36: 65016.51 | K36: {=_xlfn.XLOOKUP(F36,'Customer Ledger'!$B:$B,'Customer Ledger'!$H:$I,,0)} -> -75.6 | L36: -756 | M36: =(K36/H36)*-1 -> 0.1 | N36: Fixed Storage Charges fo JULY 2025
A37: 1800010289 | B37: DR | C37: 45842 | D37: 45847 | E37: NA | F37: 256779415049 | G37: USD | H37: 17.54 | I37: INR | J37: 1508.45 | K37: {=_xlfn.XLOOKUP(F37,'Customer Ledger'!$B:$B,'Customer Ledger'!$H:$I,,0)} -> -0.35 | L37: -17.54 | M37: =(K37/H37)*-1 -> 0.01995439 | N37: Bond Stamp Paper Chgs
A38: 1600001545 | B38: DG | C38: 45842 | D38: 45846 | E38: NA | F38: 256779421177 | G38: USD | H38: -140 | I38: INR | J38: -12040.09 | K38: {=_xlfn.XLOOKUP(F38,'Customer Ledger'!$B:$B,'Customer Ledger'!$H:$I,,0)} -> #N/A | M38: 0 | N38: Credit note against 246779414228 | O38: 1400001906
A39: 1600001546 | B39: DG | C39: 45842 | D39: 45846 | E39: NA | F39: 256779421178 | G39: USD | H39: -756 | I39: INR | J39: -65016.51 | K39: {=_xlfn.XLOOKUP(F39,'Customer Ledger'!$B:$B,'Customer Ledger'!$H:$I,,0)} -> #N/A | M39: 0 | N39: Credit note against 246779412996 | O39: 1400001906
A40: 1600001547 | B40: DG | C40: 45842 | D40: 45846 | E40: NA | F40: 256779421179 | G40: USD | H40: -756 | I40: INR | J40: -65016.51 | K40: {=_xlfn.XLOOKUP(F40,'Customer Ledger'!$B:$B,'Customer Ledger'!$H:$I,,0)} -> #N/A | M40: 0 | N40: Credit note against 246779410019 | O40: 1400001906
...

Sheet Payment Reco
A1: As Per Customer Ledger | G1: As Per CL Ledger | J1: Difference
A2: Account | B2: Reference | C2: Document Date | D2: Amount in Doc. Curr.-USD | E2: Amount in Local Currency-INR | F2: Text | G2: Clearing Document | H2: Document Header Text | I2: Sum of Document Currency Value | J2: TDS | K2: Foreign Exchange Gain/loss | L2: Remarks
A3: 60000472 | B3: NSMT0548526 | C3: 45869 | D3: 7484.4 | E3: 656363.29 | F3: PAID AGAINST INV.NO. | G3: 1400001171 | H3: T54SWIC270284 | I3: -9150.4 | J3: =_xlfn.XLOOKUP(G3,Sheet6!$Q$15:$Q$22,Sheet6!$R$15:$R$22,,0) -> -915.03 | K3: =I3+D3+D4-J3 -> 0 | L3: 2 payments Cleared at once
A4: 60000472 | B4: NSMT0548526 | C4: 45869 | D4: 750.97 | E4: 65857.88 | F4: PAID AGAINST INV.NO.5406/5404/02/03/01/399
A5: 60000472 | B5: NSMT1165026 | C5: 46007 | D5: 2754.77 | E5: 247026.06 | F5: PAID AGAINST INV.NO.418013/9135/9234/9203 | G5: 1400002219 | H5: T54SWIC283727 | I5: -2943.55 | J5: =_xlfn.XLOOKUP(G5,Sheet6!$Q$15:$Q$22,Sheet6!$R$15:$R$22,,0) -> -188.78 | K5: =I5+D5-J5 -> 2.8421709e-13
A6: 60000472 | B6: NSMT0824926 | C6: 45931 | D6: 2032.13 | E6: 180144.46 | F6: PAID AGAINST INV.NO. 256779414933/6044/7363 | G6: Not Yet Cleared | H6: T54SWIC276290 | I6: -2032.13 | K6: =I6+D6-J6 -> 0
A7: 60000472 | B7: NSMT0818226 | C7: 45931 | D7: 1478.15 | E7: 130858.37 | F7: PAID AGAINST INV.NO. 6818/7208/5049/7246 | G7: Not Yet Cleared | H7: T54SWIC276317 | I7: -1478.14 | K7: =I7+D7-J7 -> 0.01
A8: 60000472 | B8: NSMT0881326 | C8: 45946 | D8: 631.98 | E8: 56117.65 | F8: PAID AGAINST INV.NO. 256779417570/7529/7443 | G8: Not Yet Cleared | H8: T54SWIC277677 | I8: -631.97 | K8: =I8+D8-J8 -> 0.01
A9: 60000472 | B9: NSMT0671126 | C9: 45898 | D9: 411.6 | E9: 36049.56 | F9: PAID AGAINST INV.NO.11604/605/606 | G9: 1400001172 | H9: 2178269241JS | I9: -420 | J9: -8.4 | K9: =I9+D9-J9 -> 2.3092639e-14
A10: 60000472 | B10: NSMT1582226 | C10: 46087 | D10: 1733.59 | E10: 157574.99 | F10: PAID AGAINST INV.NO. 256779418402/32/323/9921 | L10: Payment Not in CL ledger
D11: =SUM(D3:D10) -> 17277.59 | I11: =SUM(I3:I10) -> -16656.19 | J11: =SUM(J3:J10) -> -1112.21 | K11: =SUM(K3:K10) -> 0.02

Sheet Sheet6
A1: Document Number | B1: Document Type | C1: Document Date | D1: Entry Date | E1: Document Header Text | F1: Reference | G1: Document Currency Key | H1: Document Currency Value | I1: Company Code Currency Key | J1: Company Code Currency Value | K1: TDS | L1: Total Invoice Value | M1: Net Amount | N1: Text | O1: Clearing Document | Q1: Row Labels | R1: Sum of TDS
A2: 1800000420 | B2: DR | C2: 45719 | D2: 45719 | E2: NA | F2: 246779410382 | G2: USD | H2: 834.4 | I2: INR | J2: 72335.19 | N2: Storage Charges for the month of August, 2024 | O2: 1400001906 | Q2: 1400001172 | R2: -2.8
A3: 1800011335 | B3: DR | C3: 45870 | D3: 45873 | E3: NA | F3: 256779416044 | G3: USD | H3: 756 | I3: INR | J3: 65038.77 | K3: -75.6 | L3: -756 | N3: Fixed Storage Charges for August 2025 | R3: -428.67
A4: 1800009611 | B4: DR | C4: 45818 | D4: 45825 | E4: NA | F4: 256779414375 | G4: USD | H4: 756 | I4: INR | J4: 64631.03 | K4: -75.6 | L4: -756 | N4: Fixed Storage Charges fo JUNE 2025 | O4: 1400001171 | Q4: 1400000194
A5: 1800012789 | B5: DR | C5: 45917 | D5: 45922 | E5: NA | F5: 256779417443 | G5: USD | H5: 24.92 | I5: INR | J5: 2180.86 | K5: -0.5 | L5: -24.92 | N5: VAS -1-15 Sept-25 | Q5: 1400000195
A6: 1800006713 | B6: DR | C6: 45762 | D6: 45763 | E6: NA | F6: 256779411604 | G6: USD | H6: 140 | I6: INR | J6: 12169.05 | K6: -2.8 | L6: -140 | N6: Outbound Handling Charges Aug 2024 | O6: 1400001172 | Q6: 1400001106
A7: 1800006714 | B7: DR | C7: 45762 | D7: 45763 | E7: NA | F7: 256779411605 | G7: USD | H7: 140 | I7: INR | J7: 12169.05 | K7: -2.8 | L7: -140 | N7: Outbound Handling Charges Aug 2024 | O7: 1400001172 | Q7: 1400001171 | R7: -915.03
A8: 1800012588 | B8: DR | C8: 45904 | D8: 45909 | E8: NA | F8: 256779417246 | G8: USD | H8: 183.54 | I8: INR | J8: 16062.38 | K8: -3.67 | L8: -183.54 | N8: PORT SSR Chgs Aug 25 | Q8: 1400001172 | R8: -5.6
A9: 1800012621 | B9: DR | C9: 45904 | D9: 45909 | E9: NA | F9: 256779417208 | G9: USD | H9: 63.29 | I9: INR | J9: 5538.78 | K9: -1.26 | L9: -63.29 | N9: Empty Lolo Chgs - 01 - 31 AUG 25 | Q9: 1400001906
A10: 1800012649 | B10: DR | C10: 45904 | D10: 45909 | E10: NA | F10: 256779417289 | G10: USD | H10: 675.97 | I10: INR | J10: 59157.06 | K10: -13.52 | L10: -675.97 | N10: Transportation In Chgs - 16 - 31 AUG 25 | Q10: 1400002219 | R10: -188.78
A11: 1800012689 | B11: DR | C11: 45904 | D11: 45909 | E11: NA | F11: 256779417329 | G11: USD | H11: 87.97 | I11: INR | J11: 7698.64 | K11: -1.76 | L11: -87.97 | N11: Outbound chgs - 16 - 31 Aug 25 | Q11: Grand Total | R11: -1540.88
A12: 1800012729 | B12: DR | C12: 45904 | D12: 45909 | E12: NA | F12: 256779417363 | G12: USD | H12: 756 | I12: INR | J12: 66160.83 | K12: -75.6 | L12: -756 | N12: Fixed Storage Charges for September 2025
A13: 1800010173 | B13: DR | C13: 45842 | D13: 45847 | E13: NA | F13: 256779414933 | G13: USD | H13: 756 | I13: INR | J13: 65016.51 | K13: -75.6 | L13: -756 | N13: Fixed Storage Charges fo JULY 2025
A14: 1800010289 | B14: DR | C14: 45842 | D14: 45847 | E14: NA | F14: 256779415049 | G14: USD | H14: 17.54 | I14: INR | J14: 1508.45 | K14: -0.35 | L14: -17.54 | N14: Bond Stamp Paper Chgs | Q14: Row Labels | R14: Sum of TDS
A15: 1600001545 | B15: DG | C15: 45842 | D15: 45846 | E15: NA | F15: 256779421177 | G15: USD | H15: -140 | I15: INR | J15: -12040.09 | N15: Credit note against 246779414228 | O15: 1400001906 | Q15: 1400001172 | R15: -2.8
A16: 1600001546 | B16: DG | C16: 45842 | D16: 45846 | E16: NA | F16: 256779421178 | G16: USD | H16: -756 | I16: INR | J16: -65016.51 | N16: Credit note against 246779412996 | O16: 1400001906 | Q16: 1400000194
A17: 1600001547 | B17: DG | C17: 45842 | D17: 45846 | E17: NA | F17: 256779421179 | G17: USD | H17: -756 | I17: INR | J17: -65016.51 | N17: Credit note against 246779410019 | O17: 1400001906 | Q17: 1400000195
A18: 1600001548 | B18: DG | C18: 45842 | D18: 45846 | E18: NA | F18: 256779421180 | G18: USD | H18: -756 | I18: INR | J18: -65016.51 | N18: Credit note against 246779410107 | O18: 1400001906 | Q18: 1400001106
A19: 1600001549 | B19: DG | C19: 45842 | D19: 45846 | E19: NA | F19: 256779421181 | G19: USD | H19: -756 | I19: INR | J19: -65016.51 | N19: Credit note against 246779410150 | O19: 1400001906 | Q19: 1400001171 | R19: -915.03
A20: 1600001550 | B20: DG | C20: 45842 | D20: 45846 | E20: NA | F20: 256779421182 | G20: USD | H20: -756 | I20: INR | J20: -65016.51 | N20: Credit note against 246779410193 | O20: 1400001906 | Q20: 1400001172 | R20: -5.6
A21: 1600001551 | B21: DG | C21: 45842 | D21: 45846 | E21: NA | F21: 256779421183 | G21: USD | H21: -756 | I21: INR | J21: -65016.51 | N21: Credit note against 246779410236 | O21: 1400001906 | Q21: 1400001906
A22: 1600001552 | B22: DG | C22: 45842 | D22: 45846 | E22: NA | F22: 256779421184 | G22: USD | H22: -756 | I22: INR | J22: -65016.51 | N22: Credit note against 246779410293 | O22: 1400001906 | Q22: 1400002219 | R22: -188.78
A23: 1600001553 | B23: DG | C23: 45842 | D23: 45846 | E23: NA | F23: 256779421185 | G23: USD | H23: -756 | I23: INR | J23: -65016.51 | N23: Credit note against 246779410039 | O23: 1400001906
A24: 1600001554 | B24: DG | C24: 45842 | D24: 45846 | E24: NA | F24: 256779421186 | G24: USD | H24: -834.4 | I24: INR | J24: -71758.96 | N24: Credit note against 246779410382 | O24: 1400001906
A25: 1800014733 | B25: DR | C25: 45966 | D25: 45968 | E25: 2123630 | F25: 256779419234 | G25: USD | H25: 170.89 | I25: INR | J25: 15038.9 | K25: -3.42 | L25: -170.89 | N25: PORT SSR Chgs Oct 25 | O25: 1400002219
A26: 1800014253 | B26: DR | C26: 45966 | D26: 45966 | E26: NA | F26: 256779418792 | G26: USD | H26: 756 | I26: INR | J26: 66530.56 | K26: -75.59 | L26: -756 | N26: Fixed Storage Charges for November 2025 | O26: 1400002219
A27: 1800014621 | B27: DR | C27: 45966 | D27: 45967 | E27: NA | F27: 256779419203 | G27: USD | H27: 62.66 | I27: INR | J27: 5514.29 | K27: -1.26 | L27: -62.66 | N27: Empty Lolo Chgs - 01 - 31 OCT 25 | O27: 1400002219
A28: 1800014413 | B28: DR | C28: 45964 | D28: 45967 | E28: NA | F28: 256779419135 | G28: USD | H28: 579 | I28: INR | J28: 50953.96 | K28: -11.58 | L28: -579 | N28: Transportation In Chgs - 16 - 31 OCT 25 | O28: 1400002219
A29: 1600000705 | B29: DG | C29: 45791 | D29: 45793 | E29: NA | F29: 256779420414 | G29: USD | H29: -756 | I29: INR | J29: -65712.9 | N29: Credit note against 256779410281 | O29: 1400000194
A30: 1600000792 | B30: DG | C30: 45791 | D30: 45793 | E30: NA | F30: 256779420501 | G30: USD | H30: -756 | I30: INR | J30: -65712.9 | N30: Credit note against 256779410240 | O30: 1400000195
A31: 1800004360 | B31: DR | C31: 45736 | D31: 45737 | E31: NA | F31: 246779414228 | G31: USD | H31: 140 | I31: INR | J31: 12136.78 | N31: Outbound Handling charges for Sep 2024 | O31: 1400001906
A32: 1800000063 | B32: DR | C32: 45708 | D32: 45708 | E32: NA | F32: 246779410019 | G32: USD | H32: 756 | I32: INR | J32: 65245.57 | N32: Fixed Rental charges for Aug 2024 | O32: 1400001906
A33: 1800000111 | B33: DR | C33: 45708 | D33: 45708 | E33: NA | F33: 246779410039 | G33: USD | H33: 756 | I33: INR | J33: 65245.57 | N33: Fixed Rental charges for Sept 2024 | O33: 1400001906
A34: 1800000144 | B34: DR | C34: 45708 | D34: 45709 | E34: NA | F34: 246779410293 | G34: USD | H34: 756 | I34: INR | J34: 65245.57 | N34: Fixed Rental charges for Oct 2024 | O34: 1400001906
A35: 1800000180 | B35: DR | C35: 45708 | D35: 45708 | E35: NA | F35: 246779410107 | G35: USD | H35: 756 | I35: INR | J35: 65245.57 | N35: Fixed Rental charges for Nov 2024 | O35: 1400001906
A36: 1800000223 | B36: DR | C36: 45708 | D36: 45708 | E36: NA | F36: 246779410150 | G36: USD | H36: 756 | I36: INR | J36: 65245.57 | N36: Fixed Rental charges for Dec 2024 | O36: 1400001906
A37: 1800000266 | B37: DR | C37: 45708 | D37: 45708 | E37: NA | F37: 246779410193 | G37: USD | H37: 756 | I37: INR | J37: 65245.57 | N37: Fixed Rental charges for Jan 2025 | O37: 1400001906
A38: 1800000309 | B38: DR | C38: 45708 | D38: 45708 | E38: NA | F38: 246779410236 | G38: USD | H38: 756 | I38: INR | J38: 65245.57 | N38: Fixed Rental charges for Feb 2025 | O38: 1400001906
A39: 1800012186 | B39: DR | C39: 45889 | D39: 45891 | E39: NA | F39: 256779416818 | G39: USD | H39: 480 | I39: INR | J39: 41294.46 | K39: -9.6 | L39: -480 | N39: Transportation In Chgs - 01 - 15 Aug 25
A40: 1800010637 | B40: DR | C40: 45854 | D40: 45854 | E40: NA | F40: 256779415397 | G40: USD | H40: 756 | I40: INR | J40: 65016.51 | K40: -75.6 | L40: -756 | N40: Fixed Storage Charges for Mar 2025 | O40: 1400001171
...

Sheet Sheet7

Sheet TDS Ledger
A1: Account | B1: Reference | C1: Document Date | D1: Amount in Doc. Curr.-USD | E1: Amount in Local Currency-INR | F1: Text | G1: Assignment | H1: Withholding Tax Amt-USD
A2: 60000472 | B2: NSMT0824926 | C2: 45931 | D2: 2032.13 | E2: 180144.46 | F2: PAID AGAINST INV.NO. 256779414933/6044/7363 | G2: NSMT0824926 | H2: 0
A3: 60000472 | B3: 256779414933 | C3: 45842 | D3: -680.4 | E3: -60470.35 | F3: storage charges july 2025 | G3: 256779414933 | H3: -75.6
A4: 60000472 | B4: 256779416044 | C4: 45870 | D4: -680.4 | E4: -60470.35 | F4: storage charges august 2025 | G4: 256779416044 | H4: -75.6
A5: 60000472 | B5: 256779417363 | C5: 45904 | D5: -680.4 | E5: -60470.35 | F5: storage charges sept 2025 | G5: 256779417363 | H5: -75.6
A6: 60000472 | B6: NSMT0548526 | C6: 45869 | D6: 750.97 | E6: 65857.88 | F6: PAID AGAINST INV.NO.5406/5404/02/03/01/399 | G6: NSMT0548526 | H6: 0
A7: 60000472 | B7: NSMT0548526 | C7: 45869 | D7: 7484.4 | E7: 656363.29 | F7: PAID AGAINST INV.NO. | H7: 0
A8: 60000472 | B8: 256779415405 | C8: 45854 | D8: -750.97 | E8: -65857.88 | F8: Storage charges for Aug 2024 | G8: 256779415405 | H8: -83.43
A9: 60000472 | B9: 256779415404 | C9: 45854 | D9: -680.4 | E9: -59669.39 | F9: WAREHOUSE RENT FOR SEPT 24 | G9: 256779415404 | H9: -75.6
A10: 60000472 | B10: 256779415402 | C10: 45854 | D10: -680.4 | E10: -59669.39 | F10: Storage charges for Feb 2025 | G10: 256779415402 | H10: -75.6
A11: 60000472 | B11: 256779415403 | C11: 45854 | D11: -680.4 | E11: -59669.39 | F11: Storage charges for Oct 2024 | G11: 256779415403 | H11: -75.6
A12: 60000472 | B12: 256779415401 | C12: 45854 | D12: -680.4 | E12: -59669.39 | F12: Storage charges for Jan 2025 | G12: 256779415401 | H12: -75.6
A13: 60000472 | B13: 256779415400 | C13: 45854 | D13: -680.4 | E13: -59669.39 | F13: WAREHOUSE RENT FOR DEC 2024 | G13: 256779415400 | H13: -75.6
A14: 60000472 | B14: 256779415399 | C14: 45854 | D14: -680.4 | E14: -59669.39 | F14: Storage charges for Nov 2024 | G14: 256779415399 | H14: -75.6
A15: 60000472 | B15: 256779415398 | C15: 45854 | D15: -680.4 | E15: -59669.39 | F15: Storage charges for Aug 2024 | G15: 256779415398 | H15: -75.6
A16: 60000472 | B16: 256779415397 | C16: 45854 | D16: -680.4 | E16: -59669.39 | F16: Storage charges for Mar 2025 | G16: 256779415397 | H16: -75.6
A17: 60000472 | B17: 256779412157 | C17: 45768 | D17: -680.4 | E17: -59669.39 | F17: Storage charges for April 2025 | G17: 256779412157 | H17: -75.6
A18: 60000472 | B18: 256779413116 | C18: 45787 | D18: -680.4 | E18: -59669.39 | F18: Storage charges for May 2025 | G18: 256779413116 | H18: -75.6
A19: 60000472 | B19: 256779414375 | C19: 45818 | D19: -680.4 | E19: -59669.39 | F19: Storage charges for June 2025 | G19: 256779414375 | H19: -75.6
A20: 60000472 | B20: NSMT0671126 | C20: 45898 | D20: 411.6 | E20: 36049.56 | F20: PAID AGAINST INV.NO.11604/605/606 | H20: 0
A21: 60000472 | B21: 256779411605 | C21: 45762 | D21: -137.2 | E21: -12016.52 | F21: Handling charges for Aug 2024 | G21: 256779411605 | H21: -2.8
A22: 60000472 | B22: 256779411604 | C22: 45762 | D22: -137.2 | E22: -12016.52 | F22: Handling charges for Aug 2024 | G22: 256779411604 | H22: -2.8
A23: 60000472 | B23: 256779415396 | C23: 45854 | D23: -137.2 | E23: -12016.52 | F23: Handling charges for SEPT 2024 | H23: -2.8
A24: 60000472 | B24: 256779411605 | C24: 45762 | D24: 137.2 | E24: 12016.52 | F24: Handling charges for Aug 2024 | G24: 256779411605 | H24: 2.8
A25: 60000472 | B25: 256779411604 | C25: 45762 | D25: 137.2 | E25: 12016.52 | F25: Handling charges for Aug 2024 | G25: 256779411604 | H25: 2.8
A26: 60000472 | B26: 256779411605 | C26: 45397 | D26: -137.2 | E26: -12016.52 | F26: Handling charges for Aug 2024 | G26: 256779411605 | H26: -2.8
A27: 60000472 | B27: 256779411604 | C27: 45762 | D27: -137.2 | E27: -12016.52 | F27: Handling charges for Aug 2024 | G27: 256779411604 | H27: -2.8
A28: 60000472 | B28: NSMT0818226 | C28: 45931 | D28: 1478.15 | E28: 130858.37 | F28: PAID AGAINST INV.NO. 6818/7208/5049/7246 | H28: 0
A29: 60000472 | B29: 256779416818 | C29: 45889 | D29: -470.4 | E29: -41294.52 | F29: Transporation charges against inv.no. 25FZ05041 | G29: 256779416818 | H29: -9.6
A30: 60000472 | B30: 256779417208 | C30: 45870 | D30: -62.03 | E30: -5512.89 | F30: emty contenar unloading charges | G30: 256779417208 | H30: -1.26
A31: 60000472 | B31: 256779415049 | C31: 45842 | D31: -17.19 | E31: -1527.86 | F31: bond stamp paper charges | G31: 256779415049 | H31: -0.35
A32: 60000472 | B32: 256779417246 | C32: 45904 | D32: -179.87 | E32: -15986.08 | F32: port ssr charges (transpotation charges) | G32: 256779417246 | H32: -3.67
A33: 60000472 | B33: 256779417329 | C33: 45914 | D33: -86.21 | E33: -7662.32 | F33: outbond charges | G33: 256779417329 | H33: -1.76
A34: 60000472 | B34: 256779417289 | C34: 45904 | D34: -662.45 | E34: -58874.7 | F34: transporation charges | G34: 256779417289 | H34: -13.52
A35: 60000472 | B35: NSMT0881326 | C35: 45946 | D35: 631.98 | E35: 56117.65 | F35: PAID AGAINST INV.NO. 256779417570/7529/7443 | H35: 0
A36: 60000472 | B36: 256779417529 | C36: 45918 | D36: -168.52 | E36: -14969.54 | F36: Loading chargs from 1-15/9/2025 | G36: 256779417529 | H36: -3.43
A37: 60000472 | B37: 256779417570 | C37: 45918 | D37: -439.04 | E37: -39000.42 | F37: Transaporation charges from 1-15/9/2025 | G37: 256779417570 | H37: -8.96
A38: 60000472 | B38: 256779417443 | C38: 45917 | D38: -24.42 | E38: -2147.69 | F38: MT contenar transport charges | G38: 256779417443 | H38: -0.5
A39: 60000472 | B39: NSMT1165026 | C39: 46007 | D39: 2754.77 | E39: 247026.06 | F39: PAID AGAINST INV.NO.418013/9135/9234/9203 | H39: 0
A40: 60000472 | B40: 256779418665 | C40: 45950 | D40: -45.57 | E40: -4063.47 | F40: outbond charges | G40: 256779418665 | H40: -0.93
...

Sheet Invoice not in customers books
A1: Document Number | B1: Document Type | C1: Document Date | D1: Reference | E1: Document Currency Key | F1: Document Currency Value | G1: Company Code Currency Key | H1: Company Code Currency Value | I1: Text
A2: 1800012816 | B2: DR | C2: 45918 | D2: 256779417421 | E2: USD | F2: 50 | G2: INR | H2: 4375.72 | I2: Scanning Chgs - 01 - 15 Sep 25
A3: 1800013307 | B3: DR | C3: 45935 | D3: 256779417903 | E3: USD | F3: 62.61 | G3: INR | H3: 5521.62 | I3: Empty Lolo Chgs - 01 - 30 SEP 25
F4: =SUM(F2:F3) -> 112.61
