Workbook

Sheet Sheet2
F1: 5695051 | G1: 4 | H1: 509405 | N1: 0 | O1: 0 | P1: 0
A2: Date | B2: Particulars | C2: Ledger | D2: Invoice | E2: 2 | F2: 3 | G2: 4 | H2: TDS Tagging | I2: Month | J2: Debit Amount (USD) | K2: Credit Amount (USD) | L2: Vch Type | M2: Vch No. | N2: Debit | O2: Credit | P2: TDS
C3: New Ref | D3: 246779410018 | F3: 140899 | G3: Cr | H3: 15655 | P3: 0
C4: New Ref | D4: 246779410038 | F4: 140453 | G4: Cr | H4: 15606 | P4: 0
C5: New Ref | D5: 246779410292 | F5: 140453 | G5: Cr | H5: 15606 | P5: 0
C6: New Ref | D6: 246779410106 | F6: 140453 | G6: Cr | H6: 15606 | P6: 0
C7: New Ref | D7: 246779410149 | F7: 140453 | G7: Cr | H7: 15606 | P7: 0
C8: New Ref | D8: 246779410192 | F8: 140453 | G8: Cr | H8: 15606 | P8: 0
C9: New Ref | D9: 246779410235 | F9: 140453 | G9: Cr | H9: 15606 | P9: 0
C10: New Ref | D10: 246779410321 | F10: 36410 | G10: Cr | H10: 4046 | P10: 0
C11: New Ref | D11: 246779410341 | F11: 35397 | G11: Cr | H11: 3933 | P11: 0
C12: New Ref | D12: 246779410345 | F12: 36577 | G12: Cr | H12: 4064 | P12: 0
C13: New Ref | D13: 246779410357 | F13: 35397 | G13: Cr | H13: 3933 | P13: 0
C14: New Ref | D14: 246779410351 | F14: 36577 | G14: Cr | H14: 4064 | P14: 0
... C171: New Ref | D171: 256779418871 | F171: 84631 | G171: Cr | H171: 9404 | P171: 0

Sheet Invoices and CN not rec
K1: =SUM(K3:K43) -> 1001750.5
A2: Customer Account: Name 1 | B2: Fiscal Year | C2: Posting Date | D2: Document Number | E2: Document Type | F2: Document Date | G2: Reference | H2: Document Currency Key | I2: Document Currency Value | J2: Company Code Currency Key | K2: Company Code Currency Value | L2: Text
A3: SRIKARAM PRESCIENCE PVT. LTD. | B3: 2025 | C3: 45947 | D3: 1600002475 | E3: DG | F3: 45947 | G3: 256779422017 | H3: USD | I3: -156.08 | J3: INR | K3: -13764.82 | L3: Credit note raised against 256779418079
A4: SRIKARAM PRESCIENCE PVT. LTD. | B4: 2025 | C4: 45791 | D4: 1600000605 | E4: DG | F4: 45791 | G4: 256779420314 | H4: USD | I4: -77.2 | J4: INR | K4: -6692.57 | L4: Credit note against 246779412247
A5: SRIKARAM PRESCIENCE PVT. LTD. | B5: 2025 | C5: 45791 | D5: 1600000704 | E5: DG | F5: 45791 | G5: 256779420413 | H5: USD | I5: -1800 | J5: INR | K5: -156459.28 | L5: Credit note against 256779410280
A6: SRIKARAM PRESCIENCE PVT. LTD. | B6: 2025 | C6: 45791 | D6: 1600000791 | E6: DG | F6: 45791 | G6: 256779420500 | H6: USD | I6: -1800 | J6: INR | K6: -156459.28 | L6: Credit note against 256779410239
A7: SRIKARAM PRESCIENCE PVT. LTD. | B7: 2025 | C7: 45873 | D7: 1600002058 | E7: DG | F7: 45873 | G7: 256779421634 | H7: USD | I7: -239.19 | J7: INR | K7: -20570.5 | L7: Credit note raised against 256779415806
A8: SRIKARAM PRESCIENCE PVT. LTD. | B8: 2025 | C8: 45862 | D8: 1600001823 | E8: DG | F8: 45862 | G8: 256779421443 | H8: USD | I8: -29.25 | J8: INR | K8: -2515.02 | L8: Credit Note raised against 256779413888
A9: SRIKARAM PRESCIENCE PVT. LTD. | B9: 2025 | C9: 45799 | D9: 1600001001 | E9: DG | F9: 45799 | G9: 256779420689 | H9: USD | I9: -368.88 | J9: INR | K9: -31978.67 | L9: Credit Note against 246779413091
A10: SRIKARAM PRESCIENCE PVT. LTD. | B10: 2025 | C10: 45799 | D10: 1600001002 | E10: DG | F10: 45799 | G10: 256779420690 | H10: USD | I10: -190.41 | J10: INR | K10: -16550.78 | L10: Credit Note against 256779412933
A11: SRIKARAM PRESCIENCE PVT. LTD. | B11: 2025 | C11: 45735 | D11: 1800003224 | E11: DR | F11: 45735 | G11: 246779413091 | H11: USD | I11: 368.88 | J11: INR | K11: 31978.67 | L11: Port SSR Charges - Shifting for Aug to Dec,24.
A12: SRIKARAM PRESCIENCE PVT. LTD. | B12: 2025 | C12: 45856 | D12: 1800011046 | E12: DR | F12: 45856 | G12: 256779415806 | H12: USD | I12: 239.19 | J12: INR | K12: 20570.5 | L12: LCL chgs - 01 - 15 JUL 25
A13: SRIKARAM PRESCIENCE PVT. LTD. | B13: 2025 | C13: 45999 | D13: 1800015423 | E13: DR | F13: 45999 | G13: 256779419872 | H13: USD | I13: 42.73 | J13: INR | K13: 3790.16 | L13: LCL Chgs - 16 - 30 NOV 25
A14: SRIKARAM PRESCIENCE PVT. LTD. | B14: 2025 | C14: 45797 | D14: 1800009124 | E14: DR | F14: 45797 | G14: 256779413888 | H14: USD | I14: 29.25 | J14: INR | K14: 2515.02 | L14: LCL Chgs - 01-15 MAY 25
... A43: SRIKARAM PRESCIENCE PVT. LTD. | B43: 2026 | C43: 46049 | D43: 1800017154 | E43: DR | F43: 46049 | G43: 256779440447 | H43: USD | I43: 176.58 | J43: INR | K43: 16023.42 | L43: VAS-1-15 Jan 2026

Sheet Sheet1
A1: Customer Account: Name 1 | B1: Fiscal Year | C1: Posting Date | D1: Document Number | E1: Document Type | F1: Document Date | G1: Reference | H1: Document Currency Key | I1: Document Currency Value | J1: Company Code Currency Key | K1: Company Code Currency Value | L1: Text | M1: INOVICE TAGGING | Q1: TDS | R1: Net amount | S1: DZ Tagging | T1: DZ Tagged Amount
A2: SRIKARAM PRESCIENCE PVT. LTD. | B2: 2025 | C2: 45975 | D2: 1400001853 | E2: DY | F2: 45975 | H2: INR | I2: 0 | J2: INR | K2: 0 | M2: =VLOOKUP(G2,Sheet2!$D$3:$H$171,3,) -> #N/A
A3: SRIKARAM PRESCIENCE PVT. LTD. | B3: 2025 | C3: 45758 | D3: 1600000046 | E3: DA | F3: 45758 | H3: INR | I3: 1 | J3: INR | K3: 1 | L3: Overpayment | M3: =VLOOKUP(G3,Sheet2!$D$3:$H$171,3,) -> #N/A
A4: SRIKARAM PRESCIENCE PVT. LTD. | B4: 2025 | C4: 45758 | D4: 1600000046 | E4: DA | F4: 45758 | H4: INR | I4: -1 | J4: INR | K4: -1 | L4: Overpayment | M4: =VLOOKUP(G4,Sheet2!$D$3:$H$171,3,) -> #N/A
A5: SRIKARAM PRESCIENCE PVT. LTD. | B5: 2025 | C5: 45796 | D5: 1400000021 | E5: DZ | F5: 45796 | H5: INR | I5: -285397.37 | J5: INR | K5: -283762.44 | L5: ICICN22025042926352474 | M5: =VLOOKUP(G5,Sheet2!$D$3:$H$171,3,) -> #N/A | S5: =D5 -> 1400000021
A6: SRIKARAM PRESCIENCE PVT. LTD. | B6: 2025 | C6: 45839 | D6: 1400000116 | E6: DZ | F6: 45832 | H6: INR | I6: -500000 | J6: INR | K6: -500000 | M6: =VLOOKUP(G6,Sheet2!$D$3:$H$171,3,) -> #N/A | S6: =D6 -> 1400000116
A7: SRIKARAM PRESCIENCE PVT. LTD. | B7: 2025 | C7: 45839 | D7: 1400000077 | E7: DZ | F7: 45832 | H7: INR | I7: -324702 | J7: INR | K7: -324702 | M7: =VLOOKUP(G7,Sheet2!$D$3:$H$171,3,) -> #N/A | S7: =D7 -> 1400000077
A8: SRIKARAM PRESCIENCE PVT. LTD. | B8: 2025 | C8: 45890 | D8: 1400000887 | E8: DZ | F8: 45890 | H8: INR | I8: -100000 | J8: INR | K8: -100000 | M8: =VLOOKUP(G8,Sheet2!$D$3:$H$171,3,) -> #N/A | S8: =D8 -> 1400000887
A9: SRIKARAM PRESCIENCE PVT. LTD. | B9: 2025 | C9: 45890 | D9: 1400000904 | E9: DZ | F9: 45890 | H9: INR | I9: -700000 | J9: INR | K9: -700000 | M9: =VLOOKUP(G9,Sheet2!$D$3:$H$171,3,) -> #N/A | S9: =D9 -> 1400000904
A10: SRIKARAM PRESCIENCE PVT. LTD. | B10: 2025 | C10: 45890 | D10: 1400000922 | E10: DZ | F10: 45890 | H10: INR | I10: -150000 | J10: INR | K10: -150000 | M10: =VLOOKUP(G10,Sheet2!$D$3:$H$171,3,) -> #N/A | S10: =D10 -> 1400000922
A11: SRIKARAM PRESCIENCE PVT. LTD. | B11: 2025 | C11: 45890 | D11: 1400000941 | E11: DZ | F11: 45890 | H11: INR | I11: -150000 | J11: INR | K11: -150000 | M11: =VLOOKUP(G11,Sheet2!$D$3:$H$171,3,) -> #N/A | S11: =D11 -> 1400000941
A12: SRIKARAM PRESCIENCE PVT. LTD. | B12: 2025 | C12: 45890 | D12: 1400000955 | E12: DZ | F12: 45890 | H12: INR | I12: -150000 | J12: INR | K12: -150000 | M12: =VLOOKUP(G12,Sheet2!$D$3:$H$171,3,) -> #N/A | S12: =D12 -> 1400000955
A13: SRIKARAM PRESCIENCE PVT. LTD. | B13: 2025 | C13: 45890 | D13: 1400000966 | E13: DZ | F13: 45890 | H13: INR | I13: -150000 | J13: INR | K13: -150000 | M13: =VLOOKUP(G13,Sheet2!$D$3:$H$171,3,) -> #N/A | S13: =D13 -> 1400000966
A14: SRIKARAM PRESCIENCE PVT. LTD. | B14: 2025 | C14: 45931 | D14: 1400001257 | E14: DZ | F14: 45931 | H14: INR | I14: -100000 | J14: INR | K14: -100000 | M14: =VLOOKUP(G14,Sheet2!$D$3:$H$171,3,) -> #N/A | S14: =D14 -> 1400001257
A15: SRIKARAM PRESCIENCE PVT. LTD. | B15: 2025 | C15: 45931 | D15: 1400001259 | E15: DZ | F15: 45931 | H15: INR | I15: -100000 | J15: INR | K15: -100000 | M15: =VLOOKUP(G15,Sheet2!$D$3:$H$171,3,) -> #N/A | S15: =D15 -> 1400001259
A16: SRIKARAM PRESCIENCE PVT. LTD. | B16: 2025 | C16: 45931 | D16: 1400001341 | E16: DZ | F16: 45931 | H16: INR | I16: -450000 | J16: INR | K16: -450000 | M16: =VLOOKUP(G16,Sheet2!$D$3:$H$171,3,) -> #N/A | S16: =D16 -> 1400001341
A17: SRIKARAM PRESCIENCE PVT. LTD. | B17: 2025 | C17: 45931 | D17: 1400001345 | E17: DZ | F17: 45931 | H17: INR | I17: -100000 | J17: INR | K17: -100000 | M17: =VLOOKUP(G17,Sheet2!$D$3:$H$171,3,) -> #N/A | S17: =D17 -> 1400001345
... A28: SRIKARAM PRESCIENCE PVT. LTD. | B28: 2025 | C28: 46009 | D28: 1400002218 | E28: DZ | F28: 46009 | H28: INR | I28: -100000 | J28: INR | K28: -100000 | M28: =VLOOKUP(G28,Sheet2!$D$3:$H$171,3,) -> #N/A | S28: =D28 -> 1400002218
A29: SRIKARAM PRESCIENCE PVT. LTD. | B29: 2025 | C29: 45701 | D29: 7000000069 | E29: XC | F29: 45701 | G29: 6779ZP25000105 | H29: INR | I29: -1 | J29: INR | K29: -1 | L29: Overpayment | M29: =VLOOKUP(G29,Sheet2!$D$3:$H$171,3,) -> #N/A
A30: SRIKARAM PRESCIENCE PVT. LTD. | B30: 2025 | C30: 45744 | D30: 7000000196 | E30: XC | F30: 45701 | G30: 6779ZR25000004 | H30: INR | I30: 1 | J30: INR | K30: 1 | L30: Overpayment | M30: =VLOOKUP(G30,Sheet2!$D$3:$H$171,3,) -> #N/A
A31: SRIKARAM PRESCIENCE PVT. LTD. | B31: 2025 | C31: 45861 | D31: 1400000612 | E31: DY | F31: 45861 | G31: KNOCK OFF ENTRY | H31: USD | I31: 0 | J31: INR | K31: 0 | M31: =VLOOKUP(G31,Sheet2!$D$3:$H$171,3,) -> #N/A
A32: SRIKARAM PRESCIENCE PVT. LTD. | B32: 2025 | C32: 45861 | D32: 1400000619 | E32: DY | F32: 45861 | G32: KNOCK OFF ENTRY | H32: USD | I32: 0 | J32: INR | K32: 0 | M32: =VLOOKUP(G32,Sheet2!$D$3:$H$171,3,) -> #N/A
A33: SRIKARAM PRESCIENCE PVT. LTD. | B33: 2025 | C33: 45861 | D33: 1400000621 | E33: DY | F33: 45861 | G33: KNOCK OFF ENTRY | H33: USD | I33: 0 | J33: INR | K33: 0 | M33: =VLOOKUP(G33,Sheet2!$D$3:$H$171,3,) -> #N/A
A34: SRIKARAM PRESCIENCE PVT. LTD. | B34: 2025 | C34: 45707 | D34: 1800000022 | E34: DR | F34: 45707 | G34: 246779410018 | H34: USD | I34: 1800 | J34: INR | K34: 155346.59 | L34: Fixed Rental charges for Aug 2024 | M34: =VLOOKUP(G34,Sheet2!$D$3:$H$171,3,) -> 140899 | N34: =K34-M34 -> 14447.59 | O34: =N34/K34 -> 0.093002299 | Q34: =VLOOKUP(G34,'[1]TDS not in our Books'!$D:$H,5,0) -> 15655 | R34: =K34-Q34 -> 139691.59
A35: SRIKARAM PRESCIENCE PVT. LTD. | B35: 2025 | C35: 45861 | D35: 1400000615 | E35: DY | F35: 45861 | G35: KNOCK OFF ENTRY | H35: USD | I35: 1800 | J35: INR | K35: 156459.28 | M35: =VLOOKUP(G35,Sheet2!$D$3:$H$171,3,) -> #N/A
A36: SRIKARAM PRESCIENCE PVT. LTD. | B36: 2025 | C36: 45861 | D36: 1400000615 | E36: DY | F36: 45861 | G36: KNOCK OFF ENTRY | H36: USD | I36: -1800 | J36: INR | K36: -156459.28 | M36: =VLOOKUP(G36,Sheet2!$D$3:$H$171,3,) -> #N/A
A37: SRIKARAM PRESCIENCE PVT. LTD. | B37: 2025 | C37: 45861 | D37: 1400000617 | E37: DY | F37: 45861 | G37: KNOCK OFF ENTRY | H37: USD | I37: 1800 | J37: INR | K37: 156459.28 | M37: =VLOOKUP(G37,Sheet2!$D$3:$H$171,3,) -> #N/A
A38: SRIKARAM PRESCIENCE PVT. LTD. | B38: 2025 | C38: 45861 | D38: 1400000617 | E38: DY | F38: 45861 | G38: KNOCK OFF ENTRY | H38: USD | I38: -1800 | J38: INR | K38: -156459.28 | M38: =VLOOKUP(G38,Sheet2!$D$3:$H$171,3,) -> #N/A
A39: SRIKARAM PRESCIENCE PVT. LTD. | B39: 2025 | C39: 45708 | D39: 1800000110 | E39: DR | F39: 45708 | G39: 246779410038 | H39: USD | I39: 1800 | J39: INR | K39: 155346.59 | L39: Fixed Rental charges for Sept 2024 | M39: =VLOOKUP(G39,Sheet2!$D$3:$H$171,3,) -> 140453 | N39: =K39-M39 -> 14893.59 | O39: =N39/K39 -> 0.095873299 | Q39: =VLOOKUP(G39,'[1]TDS not in our Books'!$D:$H,5,0) -> 15606 | R39: =K39-Q39 -> 139740.59 | S39: 1400000077
A40: SRIKARAM PRESCIENCE PVT. LTD. | B40: 2025 | C40: 45708 | D40: 1800000179 | E40: DR | F40: 45708 | G40: 246779410106 | H40: USD | I40: 1800 | J40: INR | K40: 155346.59 | L40: Fixed Rental charges for Nov 2024 | M40: =VLOOKUP(G40,Sheet2!$D$3:$H$171,3,) -> 140453 | N40: =K40-M40 -> 14893.59 | O40: =N40/K40 -> 0.095873299 | Q40: =VLOOKUP(G40,'[1]TDS not in our Books'!$D:$H,5,0) -> 15606 | R40: =K40-Q40 -> 139740.59 | S40: =VLOOKUP(D40,[2]Sheet1!$D:$S,16,0) -> 1400000116 | T40: =VLOOKUP(D40,[2]Sheet1!$D:$T,17,0) -> 140453
A41: SRIKARAM PRESCIENCE PVT. LTD. | B41: 2025 | C41: 45708 | D41: 1800000222 | E41: DR | F41: 45708 | G41: 246779410149 | H41: USD | I41: 1800 | J41: INR | K41: 155346.59 | L41: Fixed Rental charges for Dec 2024 | M41: =VLOOKUP(G41,Sheet2!$D$3:$H$171,3,) -> 140453 | N41: =K41-M41 -> 14893.59 | O41: =N41/K41 -> 0.095873299 | Q41: =VLOOKUP(G41,'[1]TDS not in our Books'!$D:$H,5,0) -> 15606 | R41: =K41-Q41 -> 139740.59 | S41: =VLOOKUP(D41,[2]Sheet1!$D:$S,16,0) -> 1400000116 | T41: =VLOOKUP(D41,[2]Sheet1!$D:$T,17,0) -> 140453
A42: SRIKARAM PRESCIENCE PVT. LTD. | B42: 2025 | C42: 45708 | D42: 1800000265 | E42: DR | F42: 45708 | G42: 246779410192 | H42: USD | I42: 1800 | J42: INR | K42: 155346.59 | L42: Fixed Rental charges for Jan 2025 | M42: =VLOOKUP(G42,Sheet2!$D$3:$H$171,3,) -> 140453 | N42: =K42-M42 -> 14893.59 | O42: =N42/K42 -> 0.095873299 | Q42: =VLOOKUP(G42,'[1]TDS not in our Books'!$D:$H,5,0) -> 15606 | R42: =K42-Q42 -> 139740.59 | S42: =VLOOKUP(D42,[2]Sheet1!$D:$S,16,0) -> 1400000116 | T42: =VLOOKUP(D42,[2]Sheet1!$D:$T,17,0) -> 140453
A43: SRIKARAM PRESCIENCE PVT. LTD. | B43: 2025 | C43: 45708 | D43: 1800000308 | E43: DR | F43: 45708 | G43: 246779410235 | H43: USD | I43: 1800 | J43: INR | K43: 155346.59 | L43: Fixed Rental charges for Feb 2025 | M43: =VLOOKUP(G43,Sheet2!$D$3:$H$171,3,) -> 140453 | N43: =K43-M43 -> 14893.59 | O43: =N43/K43 -> 0.095873299 | Q43: =VLOOKUP(G43,'[1]TDS not in our Books'!$D:$H,5,0) -> 15606 | R43: =K43-Q43 -> 139740.59 | S43: =VLOOKUP(D43,[2]Sheet1!$D:$S,16,0) -> 1400000116 | T43: =VLOOKUP(D43,[2]Sheet1!$D:$T,17,0) -> 78641
A44: SRIKARAM PRESCIENCE PVT. LTD. | B44: 2025 | C44: 45708 | D44: 1800000080 | E44: DR | F44: 45708 | G44: 246779410292 | H44: USD | I44: 1800 | J44: INR | K44: 155346.59 | L44: Fixed Rental charges for Oct 2024 | M44: =VLOOKUP(G44,Sheet2!$D$3:$H$171,3,) -> 140453 | N44: =K44-M44 -> 14893.59 | O44: =N44/K44 -> 0.095873299 | Q44: =VLOOKUP(G44,'[1]TDS not in our Books'!$D:$H,5,0) -> 15606 | R44: =K44-Q44 -> 139740.59 | S44: =VLOOKUP(D44,[2]Sheet1!$D:$S,16,0) -> 1400000887 | T44: =VLOOKUP(D44,[2]Sheet1!$D:$T,17,0) -> 38188
A45: SRIKARAM PRESCIENCE PVT. LTD. | B45: 2025 | C45: 45713 | D45: 1800000347 | E45: DR | F45: 45713 | G45: 246779410321 | H45: USD | I45: 465 | J45: INR | K45: 40131.2 | L45: CY Longstanding container Ground Rent charges for | M45: =VLOOKUP(G45,Sheet2!$D$3:$H$171,3,) -> 36410 | N45: =K45-M45 -> 3721.2 | O45: =N45/K45 -> 0.092725859 | Q45: =VLOOKUP(G45,'[1]TDS not in our Books'!$D:$H,5,0) -> 4046 | R45: =K45-Q45 -> 36085.2
A46: SRIKARAM PRESCIENCE PVT. LTD. | B46: 2025 | C46: 45716 | D46: 1800000372 | E46: DR | F46: 45716 | G46: 246779410341 | H46: USD | I46: 450 | J46: INR | K46: 38836.65 | L46: CY Longstanding container Ground Rent charges for | M46: =VLOOKUP(G46,Sheet2!$D$3:$H$171,3,) -> 35397 | N46: =K46-M46 -> 3439.65 | O46: =N46/K46 -> 0.088567114 | Q46: =VLOOKUP(G46,'[1]TDS not in our Books'!$D:$H,5,0) -> 3933 | R46: =K46-Q46 -> 34903.65 | S46: 1400000077
A47: SRIKARAM PRESCIENCE PVT. LTD. | B47: 2025 | C47: 45716 | D47: 1800000388 | E47: DR | F47: 45716 | G47: 246779410357 | H47: USD | I47: 450 | J47: INR | K47: 38836.65 | L47: CY Longstanding container Ground Rent charges for | M47: =VLOOKUP(G47,Sheet2!$D$3:$H$171,3,) -> 35397 | N47: =K47-M47 -> 3439.65 | O47: =N47/K47 -> 0.088567114 | Q47: =VLOOKUP(G47,'[1]TDS not in our Books'!$D:$H,5,0) -> 3933 | R47: =K47-Q47 -> 34903.65 | S47: =VLOOKUP(D47,[2]Sheet1!$D:$S,16,0) -> 1400000904 | T47: =VLOOKUP(D47,[2]Sheet1!$D:$T,17,0) -> 35397
A48: SRIKARAM PRESCIENCE PVT. LTD. | B48: 2025 | C48: 45716 | D48: 1800000376 | E48: DR | F48: 45716 | G48: 246779410345 | H48: USD | I48: 465 | J48: INR | K48: 40131.2 | L48: CY Longstanding container Ground Rent charges for | M48: =VLOOKUP(G48,Sheet2!$D$3:$H$171,3,) -> 36577 | N48: =K48-M48 -> 3554.2 | O48: =N48/K48 -> 0.088564508 | Q48: =VLOOKUP(G48,'[1]TDS not in our Books'!$D:$H,5,0) -> 4064 | R48: =K48-Q48 -> 36067.2 | S48: =VLOOKUP(D48,[2]Sheet1!$D:$S,16,0) -> 1400000904 | T48: =VLOOKUP(D48,[2]Sheet1!$D:$T,17,0) -> 36577
A49: SRIKARAM PRESCIENCE PVT. LTD. | B49: 2025 | C49: 45716 | D49: 1800000382 | E49: DR | F49: 45716 | G49: 246779410351 | H49: USD | I49: 465 | J49: INR | K49: 40131.2 | L49: CY Longstanding container Ground Rent charges for | M49: =VLOOKUP(G49,Sheet2!$D$3:$H$171,3,) -> 36577 | N49: =K49-M49 -> 3554.2 | O49: =N49/K49 -> 0.088564508 | Q49: =VLOOKUP(G49,'[1]TDS not in our Books'!$D:$H,5,0) -> 4064 | R49: =K49-Q49 -> 36067.2 | S49: =VLOOKUP(D49,[2]Sheet1!$D:$S,16,0) -> 1400000904 | T49: =VLOOKUP(D49,[2]Sheet1!$D:$T,17,0) -> 36577
A50: SRIKARAM PRESCIENCE PVT. LTD. | B50: 2025 | C50: 45719 | D50: 1800000403 | E50: DR | F50: 45719 | G50: 246779410365 | H50: USD | I50: 1018.38 | J50: INR | K50: 88284.65 | L50: Storage Charges for the month of August, 2024 | M50: =VLOOKUP(G50,Sheet2!$D$3:$H$171,3,) -> 80043 | N50: =K50-M50 -> 8241.65 | O50: =N50/K50 -> 0.093353148 | Q50: =VLOOKUP(G50,'[1]TDS not in our Books'!$D:$H,5,0) -> 8894 | R50: =K50-Q50 -> 79390.65
...

Sheet DZ
A1: Customer Account: Name 1 | B1: Fiscal Year | C1: Posting Date | D1: Document Number | E1: Document Type | F1: Document Date | G1: Reference | H1: Document Currency Key | I1: Document Currency Value | J1: Company Code Currency Key | K1: Company Code Currency Value | L1: Text | M1: INOVICE TAGGING
A2: SRIKARAM PRESCIENCE PVT. LTD. | B2: 2025 | C2: 45796 | D2: 1400000021 | E2: DZ | F2: 45796 | H2: INR | I2: -285397.37 | J2: INR | K2: -283762.44 | L2: ICICN22025042926352474 | M2: #N/A
A3: SRIKARAM PRESCIENCE PVT. LTD. | B3: 2025 | C3: 45839 | D3: 1400000116 | E3: DZ | F3: 45832 | H3: INR | I3: -500000 | J3: INR | K3: -500000 | M3: #N/A
A4: SRIKARAM PRESCIENCE PVT. LTD. | B4: 2025 | C4: 45839 | D4: 1400000077 | E4: DZ | F4: 45832 | H4: INR | I4: -324702 | J4: INR | K4: -324702 | M4: #N/A
A5: SRIKARAM PRESCIENCE PVT. LTD. | B5: 2025 | C5: 45890 | D5: 1400000887 | E5: DZ | F5: 45890 | H5: INR | I5: -100000 | J5: INR | K5: -100000 | M5: #N/A
A6: SRIKARAM PRESCIENCE PVT. LTD. | B6: 2025 | C6: 45890 | D6: 1400000904 | E6: DZ | F6: 45890 | H6: INR | I6: -700000 | J6: INR | K6: -700000 | M6: #N/A
A7: SRIKARAM PRESCIENCE PVT. LTD. | B7: 2025 | C7: 45890 | D7: 1400000922 | E7: DZ | F7: 45890 | H7: INR | I7: -150000 | J7: INR | K7: -150000 | M7: #N/A
A8: SRIKARAM PRESCIENCE PVT. LTD. | B8: 2025 | C8: 45890 | D8: 1400000941 | E8: DZ | F8: 45890 | H8: INR | I8: -150000 | J8: INR | K8: -150000 | M8: #N/A
A9: SRIKARAM PRESCIENCE PVT. LTD. | B9: 2025 | C9: 45890 | D9: 1400000955 | E9: DZ | F9: 45890 | H9: INR | I9: -150000 | J9: INR | K9: -150000 | M9: #N/A
A10: SRIKARAM PRESCIENCE PVT. LTD. | B10: 2025 | C10: 45890 | D10: 1400000966 | E10: DZ | F10: 45890 | H10: INR | I10: -150000 | J10: INR | K10: -150000 | M10: #N/A
A11: SRIKARAM PRESCIENCE PVT. LTD. | B11: 2025 | C11: 45931 | D11: 1400001257 | E11: DZ | F11: 45931 | H11: INR | I11: -100000 | J11: INR | K11: -100000 | M11: #N/A
A12: SRIKARAM PRESCIENCE PVT. LTD. | B12: 2025 | C12: 45931 | D12: 1400001259 | E12: DZ | F12: 45931 | H12: INR | I12: -100000 | J12: INR | K12: -100000 | M12: #N/A
A13: SRIKARAM PRESCIENCE PVT. LTD. | B13: 2025 | C13: 45931 | D13: 1400001341 | E13: DZ | F13: 45931 | H13: INR | I13: -450000 | J13: INR | K13: -450000 | M13: #N/A
A14: SRIKARAM PRESCIENCE PVT. LTD. | B14: 2025 | C14: 45931 | D14: 1400001345 | E14: DZ | F14: 45931 | H14: INR | I14: -100000 | J14: INR | K14: -100000 | M14: #N/A
... A25: SRIKARAM PRESCIENCE PVT. LTD. | B25: 2026 | C25: 46045 | D25: 1400002521 | E25: DZ | F25: 46045 | H25: INR | I25: -150000 | J25: INR | K25: -150000 | M25: #N/A
A26: SRIKARAM PRESCIENCE PVT. LTD. | B26: 2026 | C26: 46055 | D26: 1400002594 | E26: DZ | F26: 46055 | G26: 2168964 | H26: INR | I26: -200000 | J26: INR | K26: -200000 | M26: #N/A
A27: SRIKARAM PRESCIENCE PVT. LTD. | B27: 2026 | C27: 46055 | D27: 1400002602 | E27: DZ | F27: 46055 | G27: 2168967 | H27: INR | I27: -200000 | J27: INR | K27: -200000 | M27: #N/A
