Workbook

Sheet Summary
A1: Reconciliation of Ledger as on 31st January 2026
A2: Particulars | B2: Amount in USD
A3: Balance as per Scope Chemicals Pvt Ltd | B3: =-'Customer Ledger'!D48 -> -2728.8545
A4: Add: TDS to be booked in Ascendus books | B4: ='TDS To Be Booked'!K43-'Payment Reco'!M6 -> 217
A5: Add: Invoices & CN not recorded in customer books | B5: ='Invoices Not In customer Books'!F39 -> 15591.81 | C5: >> Pending Invoices Booked By Customer & CN Issued By Capital Land
A6: Add: Exchange Gain / Loss | B6: ='Payment Reco'!N6 -> 6.4875302
A7: Derived balance | B7: =SUM(B3:B6) -> 13086.443
A8: Balance as per Ascent | B8: ='Ascendus Ledger'!F119 -> 13086.446
A10: Difference | B10: =B7-B8-B9 -> -0.0027059045

Sheet Payment Reco
A1: As Per Ascendus | J1: As per customer | M1: Difference
A2: Document Number | B2: Document Type | C2: Document Date | D2: Document Currency Key | E2: Document Currency Value | F2: Company Code Currency Key | G2: Company Code Currency Value | H2: Exchange Rate | I2: Converted Value | J2: Posting Date | K2: Debit (USD) | L2: Voucher Type | M2: TDS Booked | N2: Foreign Exchange Gain/Loss
A3: 1400001561 | B3: DZ | C3: 45959 | D3: INR | E3: -500000 | F3: INR | G3: -500000 | H3: =G3/K3 -> -86 | I3: =G3/H3 -> 5813.9535 | J3: 2025-10-24 | K3: 5813.9535 | L3: Payment Entry | M3: =I3-K3 -> 0
A4: 1400000004 | B4: DZ | C4: 45743 | D4: INR | E4: -26397.48 | F4: INR | G4: -26279.46 | H4: 86.543676 | I4: =G4/H4 -> -303.65546 | J4: 2025-03-26 | K4: 278.55299 | L4: Payment Entry | M4: ='TDS To Be Booked'!O43 -> 30 | N4: =K4+M4+I4+1.59 -> 6.4875302
A5: 1400002476 | B5: DZ | C5: 46041 | D5: INR | E5: -500000 | F5: INR | G5: -500000 | H5: =G5/K5 -> -90.300009 | I5: =G5/H5 -> 5537.098 | J5: 2026-01-14 | K5: 5537.098 | L5: Payment Entry | M5: =I5-K5 -> 0
I6: =SUM(I3:I5) -> 11047.396 | K6: =SUM(K3:K5) -> 11629.604 | M6: =SUM(M3:M5) -> 30 | N6: =SUM(N3:N5) -> 6.4875302

Sheet Customer Ledger
A1: Posting Date | B1: Debit (USD) | C1: Credit (USD) | D1: Balance (USD) | E1: Voucher Subtype | F1: Voucher No | G1: Against Account | H1: Against Voucher | I1: Supplier Invoice No
B2: 0 | C2: 0 | D2: 0
A3: 2025-02-26 | B3: 0 | C3: 45.75 | D3: -45.75 | E3: Purchase Invoice | F3: PU/25/SCP/OT/0867 | G3: Rent - Warehouse - SCPL | H3: PU/25/SCP/OT/0867 | I3: 246779410050
A4: 2025-02-26 | B4: 0 | C4: 45.75 | D4: -91.5 | E4: Purchase Invoice | F4: PU/25/SCP/OT/0868 | G4: Rent - Warehouse - SCPL | H4: PU/25/SCP/OT/0868 | I4: 246779410304
A5: 2025-02-26 | B5: 0 | C5: 45.75 | D5: -137.25 | E5: Purchase Invoice | F5: PU/25/SCP/OT/0869 | G5: Rent - Warehouse - SCPL | H5: PU/25/SCP/OT/0869 | I5: 246779410118
A6: 2025-02-26 | B6: 0 | C6: 45.75 | D6: -183 | E6: Purchase Invoice | F6: PU/25/SCP/OT/0870 | G6: Rent - Warehouse - SCPL | H6: PU/25/SCP/OT/0870 | I6: 246779410161
A7: 2025-02-26 | B7: 0 | C7: 45.75 | D7: -228.75 | E7: Purchase Invoice | F7: PU/25/SCP/OT/0872 | G7: Rent - Warehouse - SCPL | H7: PU/25/SCP/OT/0872 | I7: 246779410247
A8: 2025-02-26 | B8: 0 | C8: 45.75 | D8: -274.5 | E8: Purchase Invoice | F8: PU/25/SCP/OT/0871-1 | G8: Rent - Warehouse - SCPL | H8: PU/25/SCP/OT/0871-1 | I8: 246779410204
A9: 2025-03-26 | B9: 278.55299 | C9: 0 | D9: 4.0529947 | E9: Pay | F9: BP/25/SCP/0820 | G9: 650014134028 - IndusInd Bank Limited - SCPL | H9: PU/25/SCP/OT/0867, PU/25/SCP/OT/0868, PU/25/SCP/OT/0869, PU/25/SCP/OT/0870, PU/25/SCP/OT/0871-1, PU/25/SCP/OT/0872
A10: 2025-03-31 | B10: 4.053 | C10: 4.053 | D10: 4.0529947 | E10: Exchange Rate Revaluation | F10: SJ/25/GEA/1247 | G10: Rhenocoll-Werk EK EURO, Welfull Group Co., Ltd., H2 Minerals And More GmbH - EUR, Limited Liability Company VOSTOK - RUB, Exchange Gain/Loss - SCPL, Kaustik Europe B. V., Thomas Brunner Hygiene GmbH - EURO, Ascendas Panvel FTWZ Private Limited, Rhenocoll-Werk Ek EUR, Indulor AG, Zhejiang Luba Traffic Technology Co Ltd | H10: ACC-ERR-2025-00004, ACC-ERR-2025-00004
A11: 2025-09-04 | B11: 0 | C11: 45.75 | D11: -41.697005 | E11: Purchase Invoice | F11: PU/26/SCP/OT/0351 | G11: Rent - Warehouse - SCPL | H11: PU/26/SCP/OT/0351 | I11: 256779417374
A12: 2025-10-16 | B12: 0 | C12: 45.75 | D12: -87.447005 | E12: Purchase Invoice | F12: PU/26/SCP/OT/0396 | G12: Rent - Warehouse - SCPL | H12: PU/26/SCP/OT/0396 | I12: 246779413009
A13: 2025-10-16 | B13: 0 | C13: 45.75 | D13: -133.19701 | E13: Purchase Invoice | F13: PU/26/SCP/OT/0397 | G13: Rent - Warehouse - SCPL | H13: PU/26/SCP/OT/0397 | I13: 256779412170
A14: 2025-10-16 | B14: 0 | C14: 45.75 | D14: -178.94701 | E14: Purchase Invoice | F14: PU/26/SCP/OT/0398 | G14: Rent - Warehouse - SCPL | H14: PU/26/SCP/OT/0398 | I14: 256779413128
A15: 2025-10-16 | B15: 0 | C15: 45.75 | D15: -224.69701 | E15: Purchase Invoice | F15: PU/26/SCP/OT/0399 | G15: Rent - Warehouse - SCPL | H15: PU/26/SCP/OT/0399 | I15: 256779414387
A16: 2025-10-16 | B16: 0 | C16: 45.75 | D16: -270.44701 | E16: Purchase Invoice | F16: PU/26/SCP/OT/0400 | G16: Rent - Warehouse - SCPL | H16: PU/26/SCP/OT/0400 | I16: 256779414945
A17: 2025-10-16 | B17: 0 | C17: 45.75 | D17: -316.19701 | E17: Purchase Invoice | F17: PU/26/SCP/OT/0401 | G17: Rent - Warehouse - SCPL | H17: PU/26/SCP/OT/0401 | I17: 256779416055
A18: 2025-10-24 | B18: 5813.9535 | C18: 0 | D18: 5497.7565 | E18: Pay | F18: BP/26/SCP/0466 | G18: 201003540849 - Indusind Bank Limited - SCPL
A19: 2025-12-23 | B19: 0 | C19: 45.75 | D19: 5452.0065 | E19: Purchase Invoice | F19: PU/26/SCP/OT/0590 | G19: Rent - Warehouse - SCPL | H19: PU/26/SCP/OT/0590 | I19: 256779418037
A20: 2025-12-23 | B20: 0 | C20: 41.14 | D20: 5410.8665 | E20: Purchase Invoice | F20: PU/26/SCP/OT/0592 | G20: Weighment Expense - SCPL | H20: PU/26/SCP/OT/0592 | I20: 256779413840
A21: 2025-12-23 | B21: 0 | C21: 1170.92 | D21: 4239.9465 | E21: Purchase Invoice | F21: PU/26/SCP/OT/0591-1 | G21: Re-Bagging Charges - SCPL | H21: PU/26/SCP/OT/0591-1 | I21: 256779413242
A22: 2025-12-23 | B22: 0 | C22: 325.22 | D22: 3914.7265 | E22: Purchase Invoice | F22: PU/26/SCP/OT/0589-2 | G22: Re-Bagging Charges - SCPL | H22: PU/26/SCP/OT/0589-2 | I22: 256779414742
A23: 2025-12-23 | B23: 0 | C23: 79.57 | D23: 3835.1565 | E23: Purchase Invoice | F23: PU/26/SCP/OT/0593 | G23: Weighment Expense - SCPL | H23: PU/26/SCP/OT/0593 | I23: 256779417450
A24: 2025-12-24 | B24: 0 | C24: 20.27 | D24: 3814.8865 | E24: Purchase Invoice | F24: PU/26/SCP/OT/0595 | G24: Weighment Expense - SCPL | H24: PU/26/SCP/OT/0595 | I24: 256779418186
A25: 2025-12-24 | B25: 0 | C25: 39.77 | D25: 3775.1165 | E25: Purchase Invoice | F25: PU/26/SCP/OT/0596 | G25: Weighment Expense - SCPL | H25: PU/26/SCP/OT/0596 | I25: 256779418481
A26: 2025-12-24 | B26: 0 | C26: 128.6 | D26: 3646.5165 | E26: Purchase Invoice | F26: PU/26/SCP/OT/0597 | G26: Handling Expense - Pallet - SCPL | H26: PU/26/SCP/OT/0597 | I26: 256779413162
A27: 2025-12-24 | B27: 0 | C27: 110.8 | D27: 3535.7165 | E27: Purchase Invoice | F27: PU/26/SCP/OT/0598 | G27: Handling Expense - Pallet - SCPL | H27: PU/26/SCP/OT/0598 | I27: 256779413171
A28: 2025-12-24 | B28: 0 | C28: 36.6 | D28: 3499.1165 | E28: Purchase Invoice | F28: PU/26/SCP/OT/0599 | G28: Handling Expense - Pallet - SCPL | H28: PU/26/SCP/OT/0599 | I28: 256779413425
A29: 2025-12-24 | B29: 0 | C29: 2.35 | D29: 3496.7665 | E29: Purchase Invoice | F29: PU/26/SCP/OT/0600 | G29: Handling Expense - Pallet - SCPL | H29: PU/26/SCP/OT/0600 | I29: 256779413426
A30: 2025-12-24 | B30: 0 | C30: 115.9 | D30: 3380.8665 | E30: Purchase Invoice | F30: PU/26/SCP/OT/0601 | G30: Handling Expense - Pallet - SCPL,Gate in & Gate Out Expense - SCPL | H30: PU/26/SCP/OT/0601 | I30: 256779414757
... A44: 2026-01-01 | B44: 29 | C44: 1468.91 | D44: -2716.7435 | E44: Purchase Invoice | F44: PU/26/SCP/OT/0628 | G44: Re-Bagging Charges - SCPL | H44: PU/26/SCP/OT/0628, PU/26/SCP/OT/0628 | I44: 256779418818
A45: 2026-01-14 | B45: 5537.098 | C45: 0 | D45: 2820.3545 | E45: Pay | F45: BP/26/SCP/0638 | G45: 201003540849 - Indusind Bank Limited - SCPL
A46: 2026-01-16 | B46: 5 | C46: 50.75 | D46: 2774.6045 | E46: Purchase Invoice | F46: PU/26/SCP/OT/0663 | G46: Rent - Warehouse - SCPL | H46: PU/26/SCP/OT/0663, PU/26/SCP/OT/0663 | I46: 256779440042
A47: 2026-01-23 | B47: 5 | C47: 50.75 | D47: 2728.8545 | E47: Purchase Invoice | F47: PU/26/SCP/OT/0712 | G47: Rent - Warehouse - SCPL | H47: PU/26/SCP/OT/0712, PU/26/SCP/OT/0712 | I47: 256779440333
B48: =SUM(B2:B47) -> 11737.657 | C48: =SUM(C2:C47) -> 9008.803 | D48: =B48-C48 -> 2728.8545

Sheet TDS To Be Booked
A1: Document Number | B1: Document Type | C1: Document Date | D1: Reference | E1: Document Currency Key | F1: Document Currency Value | G1: Company Code Currency Value | H1: Debit | I1: Credit | J1: Updated Ledger Xlooup | K1: TDS | L1: Rate | M1: Text | N1: Clearing Document | O1: TDS Booked | P1: TDS To Be booked
A2: 1800000091 | B2: DR | C2: 45708 | D2: 246779410304 | E2: USD | F2: 50.75 | G2: 4379.91 | H2: 0 | I2: 45.75 | J2: 45.75 | K2: 5 | L2: 0.098522167 | M2: Fixed Rental charges for Oct 2024 | N2: 1400000004 | O2: =K2 -> 5
A3: 1800000122 | B3: DR | C3: 45708 | D3: 246779410050 | E3: USD | F3: 50.75 | G3: 4379.91 | H3: 0 | I3: 45.75 | J3: 45.75 | K3: 5 | L3: 0.098522167 | M3: Fixed Rental charges for Sept 2024 | N3: 1400000004 | O3: =K3 -> 5
A4: 1800000191 | B4: DR | C4: 45708 | D4: 246779410118 | E4: USD | F4: 50.75 | G4: 4379.91 | H4: 0 | I4: 45.75 | J4: 45.75 | K4: 5 | L4: 0.098522167 | M4: Fixed Rental charges for Nov 2024 | N4: 1400000004 | O4: =K4 -> 5
A5: 1800000234 | B5: DR | C5: 45708 | D5: 246779410161 | E5: USD | F5: 50.75 | G5: 4379.91 | H5: 0 | I5: 45.75 | J5: 45.75 | K5: 5 | L5: 0.098522167 | M5: Fixed Rental charges for Dec 2024 | N5: 1400000004 | O5: =K5 -> 5
A6: 1800000277 | B6: DR | C6: 45708 | D6: 246779410204 | E6: USD | F6: 50.75 | G6: 4379.91 | H6: 0 | I6: 45.75 | J6: 45.75 | K6: 5 | L6: 0.098522167 | M6: Fixed Rental charges for Jan 2025 | N6: 1400000004 | O6: =K6 -> 5
A7: 1800000320 | B7: DR | C7: 45708 | D7: 246779410247 | E7: USD | F7: 50.75 | G7: 4379.91 | H7: 0 | I7: 45.75 | J7: 45.75 | K7: 5 | L7: 0.098522167 | M7: Fixed Rental charges for Feb 2025 | N7: 1400000004 | O7: =K7 -> 5
A8: 1800003142 | B8: DR | C8: 45735 | D8: 246779413009 | E8: USD | F8: 50.75 | G8: 4399.58 | H8: 0 | I8: 45.75 | J8: 45.75 | K8: 5 | L8: 0.098522167 | M8: Fixed Storage Charges for Mar 2025 | P8: =K8 -> 5
A9: 1800007279 | B9: DR | C9: 45768 | D9: 256779412170 | E9: USD | F9: 50.75 | G9: 4354.86 | H9: 0 | I9: 45.75 | J9: 45.75 | K9: 5 | L9: 0.098522167 | M9: Fixed Storage Charges for April 2025 | P9: =K9 -> 5
A10: 1800008244 | B10: DR | C10: 45787 | D10: 256779413128 | E10: USD | F10: 50.75 | G10: 4363.67 | H10: 0 | I10: 45.75 | J10: 45.75 | K10: 5 | L10: 0.098522167 | M10: Fixed Storage Charges fo MAY 2025 | P10: =K10 -> 5
A11: 1800008279 | B11: DR | C11: 45787 | D11: 256779413162 | E11: USD | F11: 131.6 | G11: 11315.45 | H11: 0 | I11: 128.6 | J11: 128.6 | K11: 3 | L11: 0.022796353 | M11: CODC Inbound chgs - 16 - 30 Apr 25 | P11: =K11 -> 3
A12: 1800008288 | B12: DR | C12: 45787 | D12: 256779413171 | E12: USD | F12: 112.8 | G12: 9698.96 | H12: 0 | I12: 110.8 | J12: 110.8 | K12: 2 | L12: 0.017730496 | M12: CODC Out chgs - 16 - 30 Apr 25 | P12: =K12 -> 2
A13: 1800008359 | B13: DR | C13: 45787 | D13: 256779413242 | E13: USD | F13: 1194.92 | G13: 102743.64 | H13: 0 | I13: 1170.92 | J13: 1170.92 | K13: 24 | L13: 0.020085027 | M13: VAS - 16-30 April 25, Ex.Rate-85.05 | P13: =K13 -> 24
A14: 1800009072 | B14: DR | C14: 45797 | D14: 256779413836 | E14: USD | F14: 793.07 | G14: 68191.09 | H14: 16 | I14: 793.07 | J14: 777.07 | K14: 16 | L14: 0.020174764 | M14: VAS -1-15 May 25, Ex.rate 85.43 | P14: =K14 -> 16
A15: 1800009076 | B15: DR | C15: 45797 | D15: 256779413840 | E15: USD | F15: 42.14 | G15: 3623.35 | H15: 0 | I15: 41.14 | J15: 41.14 | K15: 1 | L15: 0.023730422 | M15: Weighment & Misc, 1-15 May 25 | P15: =K15 -> 1
A16: 1800008661 | B16: DR | C16: 45798 | D16: 256779413425 | E16: USD | F16: 37.6 | G16: 3232.99 | H16: 0 | I16: 36.6 | J16: 36.6 | K16: 1 | L16: 0.026595745 | M16: OutKPI-CODC-1-15-MAY-25-1478252 | P16: =K16 -> 1
A17: 1800008662 | B17: DR | C17: 45798 | D17: 256779413426 | E17: USD | F17: 2.35 | G17: 202.06 | H17: 0 | I17: 2.35 | J17: 2.35 | K17: 0 | L17: 0 | M17: OutKPI-CODC-1-15-MAY-25-1608594 | P17: =K17 -> 0
A18: 1800009623 | B18: DR | C18: 45818 | D18: 256779414387 | E18: USD | F18: 50.75 | G18: 4338.66 | H18: 0 | I18: 45.75 | J18: 45.75 | K18: 5 | L18: 0.098522167 | M18: Fixed Storage Charges fo JUNE 2025 | P18: =K18 -> 5
A19: 1800009993 | B19: DR | C19: 45826 | D19: 256779414757 | E19: USD | F19: 117.9 | G19: 10079.36 | H19: 0 | I19: 115.9 | J19: 115.9 | K19: 2 | L19: 0.016963528 | M19: CODC Out chgs - 01 - 15 Jun 25 | P19: =K19 -> 2
... A22: 1800010185 | B22: DR | C22: 45842 | D22: 256779414945 | E22: USD | F22: 50.75 | G22: 4364.53 | H22: 0 | I22: 45.75 | J22: 45.75 | K22: 5 | L22: 0.098522167 | M22: Fixed Storage Charges fo JULY 2025 | P22: =K22 -> 5
A23: 1800010207 | B23: DR | C23: 45845 | D23: 256779414967 | E23: USD | F23: 216.2 | G23: 18593.34 | H23: 0 | I23: 212.2 | J23: 212.2 | K23: 4 | L23: 0.018501388 | P23: =K23 -> 4
A24: 1800010671 | B24: DR | C24: 45856 | D24: 256779415455 | E24: USD | F24: 490.4 | G24: 42174.73 | H24: 0 | I24: 480.4 | J24: 480.4 | K24: 10 | L24: 0.020391517 | M24: CODC GATE Out chgs - 01 - 15 July 25 | P24: =K24 -> 10
A25: 1800011346 | B25: DR | C25: 45870 | D25: 256779416055 | E25: USD | F25: 50.75 | G25: 4366.03 | H25: 0 | I25: 45.75 | J25: 45.75 | K25: 5 | L25: 0.098522167 | M25: Fixed Storage Charges for August 2025 | P25: =K25 -> 5
A26: 1800012740 | B26: DR | C26: 45904 | D26: 256779417374 | E26: USD | F26: 50.75 | G26: 4441.35 | H26: 0 | I26: 45.75 | J26: 45.75 | K26: 5 | L26: 0.098522167 | M26: Fixed Storage Charges for September 2025 | P26: =K26 -> 5
A27: 1800012787 | B27: DR | C27: 45917 | D27: 256779417441 | E27: USD | F27: 1902.19 | G27: 166468.88 | H27: 38 | I27: 1902.19 | J27: 1864.19 | K27: 38 | L27: 0.019976974 | M27: VAS -1-15 Sept-25 | P27: =K27 -> 38
A28: 1800012796 | B28: DR | C28: 45917 | D28: 256779417450 | E28: USD | F28: 81.57 | G28: 7138.54 | H28: 0 | I28: 79.57 | J28: 79.57 | K28: 2 | L28: 0.024518818 | M28: Weighment -1-15 Sept-25 | P28: =K28 -> 2
A29: 1800012944 | B29: DR | C29: 45918 | D29: 256779417583 | E29: USD | F29: 279.45 | G29: 24455.88 | H29: 0 | I29: 273.45 | J29: 273.45 | K29: 6 | L29: 0.021470746 | M29: CODC LCL Chgs -1-15 Sep 25 | P29: =K29 -> 6
A30: 1800012862 | B30: DR | C30: 45918 | D30: 256779417598 | E30: USD | F30: 150.4 | G30: 13162.16 | H30: 0 | I30: 147.4 | J30: 147.4 | K30: 3 | L30: 0.019946809 | M30: CODC Out chgs -1-15 Sep 25 | P30: =K30 -> 3
A31: 1800013461 | B31: DR | C31: 45935 | D31: 256779418037 | E31: USD | F31: 50.75 | G31: 4475.68 | H31: 0 | I31: 45.75 | J31: 45.75 | K31: 5 | L31: 0.098522167 | M31: Fixed Storage Charges for October 2025 | P31: =K31 -> 5
A32: 1800013746 | B32: DR | C32: 45937 | D32: 256779418167 | E32: USD | F32: 70 | G32: 6173.35 | H32: 0 | I32: 69 | J32: 69 | K32: 1 | L32: 0.014285714 | M32: Intra - SEZ-16-30 Sept 25 | P32: =K32 -> 1
A33: 1800013757 | B33: DR | C33: 45937 | D33: 256779418178 | E33: USD | F33: 472.74 | G33: 41691.3 | H33: 9 | I33: 472.74 | J33: 463.74 | K33: 9 | L33: 0.019037949 | M33: VAS-16-30 Sept 25 | P33: =K33 -> 9
A34: 1800013765 | B34: DR | C34: 45937 | D34: 256779418186 | E34: USD | F34: 20.27 | G34: 1787.63 | H34: 0 | I34: 20.27 | J34: 20.27 | K34: 0 | L34: 0 | M34: Weighment-16-30 Sept 25 | P34: =K34 -> 0
A35: 1800013772 | B35: DR | C35: 45937 | D35: 256779418340 | E35: USD | F35: 76.55 | G35: 6751 | H35: 2 | I35: 76.55 | J35: 74.55 | K35: 2 | L35: 0.026126715 | M35: CODC LCL Chgs -16-30 Sep 25 | P35: =K35 -> 2
... A42: 1800016624 | B42: DR | C42: 46028 | D42: 256779440333 | E42: USD | F42: 50.75 | G42: 4605.21 | H42: 5 | I42: 50.75 | J42: 45.75 | K42: 5 | L42: 0.098522167 | M42: Fixed Storage Charges for January 2026 | P42: =K42 -> 5
K43: =SUM(K2:K42) -> 247 | O43: =SUM(O2:O42) -> 30 | P43: =SUM(P2:P42) -> 217

Sheet Invoices Not In customer Books
A1: Document Number | B1: Document Type | C1: Document Date | D1: Reference | E1: Document Currency Key | F1: Document Currency Value | G1: Company Code Currency Value | H1: Text | I1: Customer Remarks | J1: Debit | K1: Credit | L1: Updated Ledger Xlooup | M1: TDS | N1: Rate | O1: Remarks
A2: 1800009181 | B2: DR | C2: 45810 | D2: 256779413945 | E2: USD | F2: 50.75 | G2: 4338.66 | H2: Fixed Rental charges for Aug 2024 | I2: =_xlfn.XLOOKUP(D2,'[1]Invoices not in customers books'!$E:$E,'[1]Invoices not in customers books'!L:L,,0) -> Fixed Storage for Aug'24 already invoiced (256779413955) | J2: {=_xlfn.XLOOKUP(D2,'[2]Query Report'!$H:$H,'[2]Query Report'!$C:$D,,0)} -> #N/A | O2: CN To Be Passed
A3: 1800009191 | B3: DR | C3: 45810 | D3: 256779413955 | E3: USD | F3: 50.75 | G3: 4338.66 | H3: Towards Fixed charges for the month of A | I3: =_xlfn.XLOOKUP(D3,'[1]Invoices not in customers books'!$E:$E,'[1]Invoices not in customers books'!L:L,,0) -> Fixed Storage for Aug'24 already invoiced (256779413955) | J3: {=_xlfn.XLOOKUP(D3,'[2]Query Report'!$H:$H,'[2]Query Report'!$C:$D,,0)} -> #N/A | O3: To be Booked By Customer
A4: 1800011070 | B4: DR | C4: 45862 | D4: 256779415830 | E4: USD | F4: 50.75 | G4: 4364.53 | H4: Debit Note against 246779420001 | I4: =_xlfn.XLOOKUP(D4,'[1]Invoices not in customers books'!$E:$E,'[1]Invoices not in customers books'!L:L,,0) -> Invoices not received | J4: {=_xlfn.XLOOKUP(D4,'[2]Query Report'!$H:$H,'[2]Query Report'!$C:$D,,0)} -> #N/A | O4: CN To Be Passed
A5: 1800011071 | B5: DR | C5: 45862 | D5: 256779415831 | E5: USD | F5: 50.75 | G5: 4364.53 | H5: Debit Note against 246779420002 | I5: =_xlfn.XLOOKUP(D5,'[1]Invoices not in customers books'!$E:$E,'[1]Invoices not in customers books'!L:L,,0) -> Invoices not received | J5: {=_xlfn.XLOOKUP(D5,'[2]Query Report'!$H:$H,'[2]Query Report'!$C:$D,,0)} -> #N/A | O5: CN To Be Passed
A6: 1800016281 | B6: DR | C6: 46028 | D6: 256779440161 | E6: USD | F6: 56.74 | G6: 5148.77 | H6: PORT SSR Chgs Dec 25 | I6: =_xlfn.XLOOKUP(D6,'[1]Invoices not in customers books'!$E:$E,'[1]Invoices not in customers books'!L:L,,0) -> PORT SSR Chgs Dec 25 | J6: {=_xlfn.XLOOKUP(D6,'[2]Query Report'!$H:$H,'[2]Query Report'!$C:$D,,0)} -> #N/A | O6: To be Booked By Customer
A7: 1800014728 | B7: DR | C7: 45966 | D7: 256779419229 | E7: USD | F7: 77.07 | G7: 6782.42 | H7: PORT SSR Chgs Oct 25 | I7: =_xlfn.XLOOKUP(D7,'[1]Invoices not in customers books'!$E:$E,'[1]Invoices not in customers books'!L:L,,0) -> PORT SSR Chgs Oct 25 Not to be booked | J7: {=_xlfn.XLOOKUP(D7,'[2]Query Report'!$H:$H,'[2]Query Report'!$C:$D,,0)} -> #N/A | O7: To be Booked By Customer
A8: 1800014264 | B8: DR | C8: 45966 | D8: 256779418803 | E8: USD | F8: 50.75 | G8: 4466.17 | H8: Fixed Storage Charges for November 2025 | I8: =_xlfn.XLOOKUP(D8,'[2]Query Report'!$H:$H,'[2]Query Report'!$B:$B,,0) -> PU/26/SCP/OT/0826 | J8: {=_xlfn.XLOOKUP(D8,'[2]Query Report'!$H:$H,'[2]Query Report'!$C:$D,,0)} -> 5 | K8: 50.75 | L8: =K8-J8 -> 45.75 | M8: =F8-L8 -> 5 | N8: =M8/F8 -> 0.098522167 | O8: Invoice Booked
A9: 1800016783 | B9: DR | C9: 46035 | D9: 256779440370 | E9: USD | F9: 60.36 | G9: 5477.26 | H9: Weighment -NOV 25,16-30 | I9: =_xlfn.XLOOKUP(D9,'[2]Query Report'!$H:$H,'[2]Query Report'!$B:$B,,0) -> PU/26/SCP/OT/0827-1 | J9: {=_xlfn.XLOOKUP(D9,'[2]Query Report'!$H:$H,'[2]Query Report'!$C:$D,,0)} -> 1 | K9: 60.36 | L9: =K9-J9 -> 59.36 | M9: =F9-L9 -> 1 | N9: =M9/F9 -> 0.016567263 | O9: Invoice Booked
A10: 1800016749 | B10: DR | C10: 46035 | D10: 256779440336 | E10: USD | F10: 70 | G10: 6352.02 | H10: INTRA -NOV 25,16-30 | I10: =_xlfn.XLOOKUP(D10,'[2]Query Report'!$H:$H,'[2]Query Report'!$B:$B,,0) -> PU/26/SCP/OT/0829 | J10: {=_xlfn.XLOOKUP(D10,'[2]Query Report'!$H:$H,'[2]Query Report'!$C:$D,,0)} -> 1 | K10: 70 | L10: =K10-J10 -> 69 | M10: =F10-L10 -> 1 | N10: =M10/F10 -> 0.014285714 | O10: Invoice Booked
A11: 1800016703 | B11: DR | C11: 46034 | D11: 256779440292 | E11: USD | F11: 40.04 | G11: 3633.36 | H11: Weighment-Dec 25 - 16-31 | I11: =_xlfn.XLOOKUP(D11,'[2]Query Report'!$H:$H,'[2]Query Report'!$B:$B,,0) -> PU/26/SCP/OT/0830-1 | J11: {=_xlfn.XLOOKUP(D11,'[2]Query Report'!$H:$H,'[2]Query Report'!$C:$D,,0)} -> 1 | K11: 40.04 | L11: =K11-J11 -> 39.04 | M11: =F11-L11 -> 1 | N11: =M11/F11 -> 0.024975025 | O11: Invoice Booked
A12: 1800016636 | B12: DR | C12: 46028 | D12: 256779440256 | E12: USD | F12: 112.8 | G12: 10235.83 | H12: CODC Out chgs -16-31 DEC 25 | I12: =_xlfn.XLOOKUP(D12,'[2]Query Report'!$H:$H,'[2]Query Report'!$B:$B,,0) -> PU/26/SCP/OT/0831 | J12: {=_xlfn.XLOOKUP(D12,'[2]Query Report'!$H:$H,'[2]Query Report'!$C:$D,,0)} -> 2 | K12: 112.8 | L12: =K12-J12 -> 110.8 | M12: =F12-L12 -> 2 | N12: =M12/F12 -> 0.017730496 | O12: Invoice Booked
A13: 1800016159 | B13: DR | C13: 46031 | D13: 256779440129 | E13: USD | F13: 169.2 | G13: 15353.74 | H13: CODC Out chgs -1-15 Nov 25 | I13: =_xlfn.XLOOKUP(D13,'[2]Query Report'!$H:$H,'[2]Query Report'!$B:$B,,0) -> PU/26/SCP/OT/0832 | J13: {=_xlfn.XLOOKUP(D13,'[2]Query Report'!$H:$H,'[2]Query Report'!$C:$D,,0)} -> 3 | K13: 169.2 | L13: =K13-J13 -> 166.2 | M13: =F13-L13 -> 3 | N13: =M13/F13 -> 0.017730496 | O13: Invoice Booked
A14: 1800016318 | B14: DR | C14: 46034 | D14: 256779440171 | E14: USD | F14: 180.4 | G14: 16370.06 | H14: CODC LCL Chgs -16-31 DEC 25 | I14: =_xlfn.XLOOKUP(D14,'[2]Query Report'!$H:$H,'[2]Query Report'!$B:$B,,0) -> PU/26/SCP/OT/0833 | J14: {=_xlfn.XLOOKUP(D14,'[2]Query Report'!$H:$H,'[2]Query Report'!$C:$D,,0)} -> 4 | K14: 180.4 | L14: =K14-J14 -> 176.4 | M14: =F14-L14 -> 4 | N14: =M14/F14 -> 0.022172949 | O14: Invoice Booked
A15: 1800014973 | B15: DR | C15: 45981 | D15: 256779419474 | E15: USD | F15: 20.28 | G15: 1784.71 | H15: Weighment-Nov 1-15, 2025 | I15: =_xlfn.XLOOKUP(D15,'[2]Query Report'!$H:$H,'[2]Query Report'!$B:$B,,0) -> PU/26/SCP/OT/0834 | J15: {=_xlfn.XLOOKUP(D15,'[2]Query Report'!$H:$H,'[2]Query Report'!$C:$D,,0)} -> 0 | K15: 20.28 | L15: =K15-J15 -> 20.28 | M15: =F15-L15 -> 0 | N15: =M15/F15 -> 0 | O15: Invoice Booked
A16: 1800016772 | B16: DR | C16: 46035 | D16: 256779440359 | E16: USD | F16: 821.64 | G16: 74558.19 | H16: VAS - NOV 25,16-30 | I16: =_xlfn.XLOOKUP(D16,'[2]Query Report'!$H:$H,'[2]Query Report'!$B:$B,,0) -> PU/26/SCP/OT/0835 | J16: {=_xlfn.XLOOKUP(D16,'[2]Query Report'!$H:$H,'[2]Query Report'!$C:$D,,0)} -> 16 | K16: 821.64 | L16: =K16-J16 -> 805.64 | M16: =F16-L16 -> 16 | N16: =M16/F16 -> 0.019473249 | O16: Invoice Booked
A17: 1800016692 | B17: DR | C17: 46034 | D17: 256779440281 | E17: USD | F17: 933.73 | G17: 84729.59 | H17: VAS-Dec 25 - 16-31 | I17: =_xlfn.XLOOKUP(D17,'[2]Query Report'!$H:$H,'[2]Query Report'!$B:$B,,0) -> PU/26/SCP/OT/0837 | J17: {=_xlfn.XLOOKUP(D17,'[2]Query Report'!$H:$H,'[2]Query Report'!$C:$D,,0)} -> 19 | K17: 933.73 | L17: =K17-J17 -> 914.73 | M17: =F17-L17 -> 19 | N17: =M17/F17 -> 0.020348495 | O17: Invoice Booked
A18: 1800014962 | B18: DR | C18: 45981 | D18: 256779419463 | E18: USD | F18: 602.03 | G18: 52980.68 | H18: VAS-Nov 1-15, 2025 | I18: =_xlfn.XLOOKUP(D18,'[2]Query Report'!$H:$H,'[2]Query Report'!$B:$B,,0) -> PU/26/SCP/OT/0838 | J18: {=_xlfn.XLOOKUP(D18,'[2]Query Report'!$H:$H,'[2]Query Report'!$C:$D,,0)} -> 12 | K18: 602.03 | L18: =K18-J18 -> 590.03 | M18: =F18-L18 -> 12 | N18: =M18/F18 -> 0.019932562 | O18: Invoice Booked
A19: 1800013944 | B19: DR | C19: 45951 | D19: 256779418476 | E19: USD | F19: 950.87 | G19: 83857.96 | H19: VAS -1-15 Oct 2025 | I19: =_xlfn.XLOOKUP(D19,'[2]Query Report'!$H:$H,'[2]Query Report'!$B:$B,,0) -> PU/26/SCP/OT/0839 | J19: {=_xlfn.XLOOKUP(D19,'[2]Query Report'!$H:$H,'[2]Query Report'!$C:$D,,0)} -> 19 | K19: 950.87 | L19: =K19-J19 -> 931.87 | M19: =F19-L19 -> 19 | N19: =M19/F19 -> 0.019981701 | O19: Invoice Booked
... A35: 1800011010 | B35: DR | C35: 45857 | D35: 256779415770 | E35: USD | F35: 1425.77 | G35: 122617.18 | H35: VAS - 1-15 July 25 | I35: =_xlfn.XLOOKUP(D35,'[2]Query Report'!$H:$H,'[2]Query Report'!$B:$B,,0) -> PU/27/SCP/OT/0024 | J35: {=_xlfn.XLOOKUP(D35,'[2]Query Report'!$H:$H,'[2]Query Report'!$C:$D,,0)} -> 65 | K35: 1425.77 | L35: =K35-J35 -> 1360.77 | M35: =F35-L35 -> 65 | N35: =M35/F35 -> 0.045589401 | O35: Invoice Booked
A36: 1800012870 | B36: DR | C36: 45918 | D36: 256779417488 | E36: USD | F36: 52.64 | G36: 4606.75 | H36: CY Ground rent Chgs - 01 - 15 Sep 25 | I36: =_xlfn.XLOOKUP(D36,'[1]Invoices not in customers books'!$E:$E,'[1]Invoices not in customers books'!L:L,,0) -> Towards SCOPE Logistics Shipment; not to be invoiced in SCOPE Chemicals | J36: {=_xlfn.XLOOKUP(D36,'[2]Query Report'!$H:$H,'[2]Query Report'!$C:$D,,0)} -> #N/A | O36: To be Booked in Scope Logistic Ledger
A37: 1800013396 | B37: DR | C37: 45935 | D37: 256779417991 | E37: USD | F37: 184.54 | G37: 16274.72 | H37: CY - CY Grd Rent Chgs - 16 - 30 SEP 25 | I37: =_xlfn.XLOOKUP(D37,'[1]Invoices not in customers books'!$E:$E,'[1]Invoices not in customers books'!L:L,,0) -> Towards SCOPE Logistics Shipment; not to be invoiced in SCOPE Chemicals | J37: {=_xlfn.XLOOKUP(D37,'[2]Query Report'!$H:$H,'[2]Query Report'!$C:$D,,0)} -> #N/A | O37: To be Booked in Scope Logistic Ledger
A38: 1800008368 | B38: DR | C38: 45787 | D38: 256779413251 | E38: USD | F38: 87.01 | G38: 7481.44 | H38: Weighment-16-30 April25, Ex.Rate-85.05 | I38: =_xlfn.XLOOKUP(D38,'[1]Invoices not in customers books'!$E:$E,'[1]Invoices not in customers books'!L:L,,0) -> Why is royalty charged | J38: {=_xlfn.XLOOKUP(D38,'[2]Query Report'!$H:$H,'[2]Query Report'!$C:$D,,0)} -> #N/A | O38: To be Booked By Customer
F39: =SUM(F2:F38) -> 15591.81

Sheet Ascendus Ledger
A1: Document Number | B1: Document Type | C1: Document Date | D1: Reference | E1: Document Currency Key | F1: Document Currency Value | G1: Company Code Currency Value | H1: Debit | I1: Credit | J1: Updated Ledger Xlooup | K1: TDS | L1: Rate | M1: Text | N1: Clearing Document
A2: 1800000001 | B2: DR | C2: 45688 | D2: 246779410001 | E2: USD | F2: 50.75 | G2: 4299.63 | H2: {=_xlfn.XLOOKUP(D2,'Customer Ledger'!$I:$I,'Customer Ledger'!$B:$C,,0)} -> #N/A | M2: Towards Fixed charges for the month of August2024 | N2: 1400000000
A3: 1400000001 | B3: DY | C3: 45692 | D3: KNOCK OFF ENTRY | E3: USD | F3: 50.75 | G3: 4379.91 | H3: {=_xlfn.XLOOKUP(D3,'Customer Ledger'!$I:$I,'Customer Ledger'!$B:$C,,0)} -> #N/A | N3: 1400000001
A4: 1400000001 | B4: DY | C4: 45692 | D4: KNOCK OFF ENTRY | E4: USD | F4: -50.75 | G4: -4379.91 | H4: {=_xlfn.XLOOKUP(D4,'Customer Ledger'!$I:$I,'Customer Ledger'!$B:$C,,0)} -> #N/A | N4: 1400000001
A5: 1800000003 | B5: DR | C5: 45692 | D5: 246779410003 | E5: USD | F5: 50.75 | G5: 4379.91 | H5: {=_xlfn.XLOOKUP(D5,'Customer Ledger'!$I:$I,'Customer Ledger'!$B:$C,,0)} -> #N/A | M5: Towards Fixed charges for the month of August2024
A6: 1800000002 | B6: DR | C6: 45692 | D6: 246779410002 | E6: USD | F6: 50.75 | G6: 4379.91 | H6: {=_xlfn.XLOOKUP(D6,'Customer Ledger'!$I:$I,'Customer Ledger'!$B:$C,,0)} -> #N/A | M6: Towards Fixed charges for the month of August2024 | N6: 1400000001
A7: 1400000000 | B7: DY | C7: 45693 | D7: KNOCK OFF ENTRY | E7: USD | F7: 50.75 | G7: 4299.63 | H7: {=_xlfn.XLOOKUP(D7,'Customer Ledger'!$I:$I,'Customer Ledger'!$B:$C,,0)} -> #N/A | N7: 1400000000
A8: 1400000000 | B8: DY | C8: 45693 | D8: KNOCK OFF ENTRY | E8: USD | F8: -50.75 | G8: -4299.63 | H8: {=_xlfn.XLOOKUP(D8,'Customer Ledger'!$I:$I,'Customer Ledger'!$B:$C,,0)} -> #N/A | N8: 1400000000
A9: 1600000001 | B9: DG | C9: 45693 | D9: 246779420002 | E9: USD | F9: -50.75 | G9: -4299.63 | H9: {=_xlfn.XLOOKUP(D9,'Customer Ledger'!$I:$I,'Customer Ledger'!$B:$C,,0)} -> #N/A | M9: Credit Note Against Inv. 1800000001 | N9: 1400000000
A10: 1600000000 | B10: DG | C10: 45693 | D10: 246779420001 | E10: USD | F10: -50.75 | G10: -4379.91 | H10: {=_xlfn.XLOOKUP(D10,'Customer Ledger'!$I:$I,'Customer Ledger'!$B:$C,,0)} -> #N/A | M10: Credit Against Invoice #1800000002 | N10: 1400000001
A11: 1800000091 | B11: DR | C11: 45708 | D11: 246779410304 | E11: USD | F11: 50.75 | G11: 4379.91 | H11: {=_xlfn.XLOOKUP(D11,'Customer Ledger'!$I:$I,'Customer Ledger'!$B:$C,,0)} -> 0 | I11: 45.75 | J11: =I11-H11 -> 45.75 | K11: =F11-J11 -> 5 | L11: =K11/F11 -> 0.098522167 | M11: Fixed Rental charges for Oct 2024 | N11: 1400000004
A12: 1800000122 | B12: DR | C12: 45708 | D12: 246779410050 | E12: USD | F12: 50.75 | G12: 4379.91 | H12: {=_xlfn.XLOOKUP(D12,'Customer Ledger'!$I:$I,'Customer Ledger'!$B:$C,,0)} -> 0 | I12: 45.75 | J12: =I12-H12 -> 45.75 | K12: =F12-J12 -> 5 | L12: =K12/F12 -> 0.098522167 | M12: Fixed Rental charges for Sept 2024 | N12: 1400000004
A13: 1800000191 | B13: DR | C13: 45708 | D13: 246779410118 | E13: USD | F13: 50.75 | G13: 4379.91 | H13: {=_xlfn.XLOOKUP(D13,'Customer Ledger'!$I:$I,'Customer Ledger'!$B:$C,,0)} -> 0 | I13: 45.75 | J13: =I13-H13 -> 45.75 | K13: =F13-J13 -> 5 | L13: =K13/F13 -> 0.098522167 | M13: Fixed Rental charges for Nov 2024 | N13: 1400000004
A14: 1800000234 | B14: DR | C14: 45708 | D14: 246779410161 | E14: USD | F14: 50.75 | G14: 4379.91 | H14: {=_xlfn.XLOOKUP(D14,'Customer Ledger'!$I:$I,'Customer Ledger'!$B:$C,,0)} -> 0 | I14: 45.75 | J14: =I14-H14 -> 45.75 | K14: =F14-J14 -> 5 | L14: =K14/F14 -> 0.098522167 | M14: Fixed Rental charges for Dec 2024 | N14: 1400000004
A15: 1800000277 | B15: DR | C15: 45708 | D15: 246779410204 | E15: USD | F15: 50.75 | G15: 4379.91 | H15: {=_xlfn.XLOOKUP(D15,'Customer Ledger'!$I:$I,'Customer Ledger'!$B:$C,,0)} -> 0 | I15: 45.75 | J15: =I15-H15 -> 45.75 | K15: =F15-J15 -> 5 | L15: =K15/F15 -> 0.098522167 | M15: Fixed Rental charges for Jan 2025 | N15: 1400000004
A16: 1800000320 | B16: DR | C16: 45708 | D16: 246779410247 | E16: USD | F16: 50.75 | G16: 4379.91 | H16: {=_xlfn.XLOOKUP(D16,'Customer Ledger'!$I:$I,'Customer Ledger'!$B:$C,,0)} -> 0 | I16: 45.75 | J16: =I16-H16 -> 45.75 | K16: =F16-J16 -> 5 | L16: =K16/F16 -> 0.098522167 | M16: Fixed Rental charges for Feb 2025 | N16: 1400000004
A17: 1800000028 | B17: DR | C17: 45708 | D17: 246779410073 | E17: USD | F17: 50.75 | G17: 4379.91 | H17: {=_xlfn.XLOOKUP(D17,'Customer Ledger'!$I:$I,'Customer Ledger'!$B:$C,,0)} -> #N/A | M17: Fixed Rental charges for Aug 2024 | N17: 1400000789
A18: 1800003142 | B18: DR | C18: 45735 | D18: 246779413009 | E18: USD | F18: 50.75 | G18: 4399.58 | H18: {=_xlfn.XLOOKUP(D18,'Customer Ledger'!$I:$I,'Customer Ledger'!$B:$C,,0)} -> 0 | I18: 45.75 | J18: =I18-H18 -> 45.75 | K18: =F18-J18 -> 5 | L18: =K18/F18 -> 0.098522167 | M18: Fixed Storage Charges for Mar 2025
A19: 1400000004 | B19: DZ | C19: 45743 | E19: INR | F19: -302.06276 | G19: -26279.46 | H19: {=_xlfn.XLOOKUP(D19,'Customer Ledger'!$I:$I,'Customer Ledger'!$B:$C,,0)} -> #N/A | M19: INDBN52025032607043264 | N19: 1400000004 | O19: USD Amount taken from Payt Reco
A20: 1800005359 | B20: DR | C20: 45750 | D20: 256779410251 | E20: USD | F20: 50.75 | G20: 4411.28 | H20: {=_xlfn.XLOOKUP(D20,'Customer Ledger'!$I:$I,'Customer Ledger'!$B:$C,,0)} -> #N/A | M20: Fixed Rental charges for Jan 2025 | N20: 1400000789
A21: 1800005400 | B21: DR | C21: 45750 | D21: 256779410292 | E21: USD | F21: 50.75 | G21: 4411.28 | H21: {=_xlfn.XLOOKUP(D21,'Customer Ledger'!$I:$I,'Customer Ledger'!$B:$C,,0)} -> #N/A | M21: Fixed Rental charges for Feb 2025 | N21: 1400000789
A22: 1800007279 | B22: DR | C22: 45768 | D22: 256779412170 | E22: USD | F22: 50.75 | G22: 4354.86 | H22: {=_xlfn.XLOOKUP(D22,'Customer Ledger'!$I:$I,'Customer Ledger'!$B:$C,,0)} -> 0 | I22: 45.75 | J22: =I22-H22 -> 45.75 | K22: =F22-J22 -> 5 | L22: =K22/F22 -> 0.098522167 | M22: Fixed Storage Charges for April 2025
A23: 1800008244 | B23: DR | C23: 45787 | D23: 256779413128 | E23: USD | F23: 50.75 | G23: 4363.67 | H23: {=_xlfn.XLOOKUP(D23,'Customer Ledger'!$I:$I,'Customer Ledger'!$B:$C,,0)} -> 0 | I23: 45.75 | J23: =I23-H23 -> 45.75 | K23: =F23-J23 -> 5 | L23: =K23/F23 -> 0.098522167 | M23: Fixed Storage Charges fo MAY 2025
A24: 1800008279 | B24: DR | C24: 45787 | D24: 256779413162 | E24: USD | F24: 131.6 | G24: 11315.45 | H24: {=_xlfn.XLOOKUP(D24,'Customer Ledger'!$I:$I,'Customer Ledger'!$B:$C,,0)} -> 0 | I24: 128.6 | J24: =I24-H24 -> 128.6 | K24: =F24-J24 -> 3 | L24: =K24/F24 -> 0.022796353 | M24: CODC Inbound chgs - 16 - 30 Apr 25
A25: 1800008288 | B25: DR | C25: 45787 | D25: 256779413171 | E25: USD | F25: 112.8 | G25: 9698.96 | H25: {=_xlfn.XLOOKUP(D25,'Customer Ledger'!$I:$I,'Customer Ledger'!$B:$C,,0)} -> 0 | I25: 110.8 | J25: =I25-H25 -> 110.8 | K25: =F25-J25 -> 2 | L25: =K25/F25 -> 0.017730496 | M25: CODC Out chgs - 16 - 30 Apr 25
A26: 1800008359 | B26: DR | C26: 45787 | D26: 256779413242 | E26: USD | F26: 1194.92 | G26: 102743.64 | H26: {=_xlfn.XLOOKUP(D26,'Customer Ledger'!$I:$I,'Customer Ledger'!$B:$C,,0)} -> 0 | I26: 1170.92 | J26: =I26-H26 -> 1170.92 | K26: =F26-J26 -> 24 | L26: =K26/F26 -> 0.020085027 | M26: VAS - 16-30 April 25, Ex.Rate-85.05
A27: 1800008368 | B27: DR | C27: 45787 | D27: 256779413251 | E27: USD | F27: 87.01 | G27: 7481.44 | H27: {=_xlfn.XLOOKUP(D27,'Customer Ledger'!$I:$I,'Customer Ledger'!$B:$C,,0)} -> #N/A | M27: Weighment-16-30 April25, Ex.Rate-85.05
A28: 1600000716 | B28: DG | C28: 45791 | D28: 256779420425 | E28: USD | F28: -50.75 | G28: -4411.28 | H28: {=_xlfn.XLOOKUP(D28,'Customer Ledger'!$I:$I,'Customer Ledger'!$B:$C,,0)} -> #N/A | M28: Credit note against 256779410292 | N28: 1400000789
A29: 1600000803 | B29: DG | C29: 45791 | D29: 256779420512 | E29: USD | F29: -50.75 | G29: -4411.28 | H29: {=_xlfn.XLOOKUP(D29,'Customer Ledger'!$I:$I,'Customer Ledger'!$B:$C,,0)} -> #N/A | M29: Credit note against 256779410251 | N29: 1400000789
A30: 1800009072 | B30: DR | C30: 45797 | D30: 256779413836 | E30: USD | F30: 793.07 | G30: 68191.09 | H30: {=_xlfn.XLOOKUP(D30,'Customer Ledger'!$I:$I,'Customer Ledger'!$B:$C,,0)} -> 16 | I30: 793.07 | J30: =I30-H30 -> 777.07 | K30: =F30-J30 -> 16 | L30: =K30/F30 -> 0.020174764 | M30: VAS -1-15 May 25, Ex.rate 85.43
A31: 1800009076 | B31: DR | C31: 45797 | D31: 256779413840 | E31: USD | F31: 42.14 | G31: 3623.35 | H31: {=_xlfn.XLOOKUP(D31,'Customer Ledger'!$I:$I,'Customer Ledger'!$B:$C,,0)} -> 0 | I31: 41.14 | J31: =I31-H31 -> 41.14 | K31: =F31-J31 -> 1 | L31: =K31/F31 -> 0.023730422 | M31: Weighment & Misc, 1-15 May 25
A32: 1800008661 | B32: DR | C32: 45798 | D32: 256779413425 | E32: USD | F32: 37.6 | G32: 3232.99 | H32: {=_xlfn.XLOOKUP(D32,'Customer Ledger'!$I:$I,'Customer Ledger'!$B:$C,,0)} -> 0 | I32: 36.6 | J32: =I32-H32 -> 36.6 | K32: =F32-J32 -> 1 | L32: =K32/F32 -> 0.026595745 | M32: OutKPI-CODC-1-15-MAY-25-1478252
A33: 1800008662 | B33: DR | C33: 45798 | D33: 256779413426 | E33: USD | F33: 2.35 | G33: 202.06 | H33: {=_xlfn.XLOOKUP(D33,'Customer Ledger'!$I:$I,'Customer Ledger'!$B:$C,,0)} -> 0 | I33: 2.35 | J33: =I33-H33 -> 2.35 | K33: =F33-J33 -> 0 | L33: =K33/F33 -> 0 | M33: OutKPI-CODC-1-15-MAY-25-1608594
A34: 1600001070 | B34: DG | C34: 45799 | D34: 256779420758 | E34: USD | F34: -50.75 | G34: -4379.91 | H34: {=_xlfn.XLOOKUP(D34,'Customer Ledger'!$I:$I,'Customer Ledger'!$B:$C,,0)} -> #N/A | M34: Credit Note against 246779410002
A35: 1600001069 | B35: DG | C35: 45799 | D35: 256779420757 | E35: USD | F35: -50.75 | G35: -4379.91 | H35: {=_xlfn.XLOOKUP(D35,'Customer Ledger'!$I:$I,'Customer Ledger'!$B:$C,,0)} -> #N/A | M35: Credit Note against 246779410073 | N35: 1400000789
A36: 1800009134 | B36: DR | C36: 45805 | D36: 256779413898 | E36: USD | F36: 928.64 | G36: 79847.9 | H36: {=_xlfn.XLOOKUP(D36,'Customer Ledger'!$I:$I,'Customer Ledger'!$B:$C,,0)} -> #N/A | M36: Storage Chgs - 01 - 31 Apr 25
A37: 1800009181 | B37: DR | C37: 45810 | D37: 256779413945 | E37: USD | F37: 50.75 | G37: 4338.66 | H37: {=_xlfn.XLOOKUP(D37,'Customer Ledger'!$I:$I,'Customer Ledger'!$B:$C,,0)} -> #N/A | M37: Fixed Rental charges for Aug 2024
A38: 1800009191 | B38: DR | C38: 45810 | D38: 256779413955 | E38: USD | F38: 50.75 | G38: 4338.66 | H38: {=_xlfn.XLOOKUP(D38,'Customer Ledger'!$I:$I,'Customer Ledger'!$B:$C,,0)} -> #N/A | M38: Towards Fixed charges for the month of A
A39: 1800009477 | B39: DR | C39: 45815 | D39: 256779414241 | E39: USD | F39: 632.96 | G39: 54112.24 | H39: {=_xlfn.XLOOKUP(D39,'Customer Ledger'!$I:$I,'Customer Ledger'!$B:$C,,0)} -> #N/A | M39: Unit storage -1-31 May 25
A40: 1800009623 | B40: DR | C40: 45818 | D40: 256779414387 | E40: USD | F40: 50.75 | G40: 4338.66 | H40: {=_xlfn.XLOOKUP(D40,'Customer Ledger'!$I:$I,'Customer Ledger'!$B:$C,,0)} -> 0 | I40: 45.75 | J40: =I40-H40 -> 45.75 | K40: =F40-J40 -> 5 | L40: =K40/F40 -> 0.098522167 | M40: Fixed Storage Charges fo JUNE 2025
...

Sheet Invoices not in customers old
G1: =SUBTOTAL(9,G3:G46) -> 15890.1 | H1: ='CN not in customers book'!G15 -> -1532.29 | I1: =G1+H1 -> 14357.81
A2: Document Number | B2: Document Type | C2: Document Date | D2: Document Header Text | E2: Reference | F2: Document Currency Key | G2: Document Currency Value | H2: Company Code Currency Key | I2: Company Code Currency Value
A3: 1800000001 | B3: DR | C3: 45688 | D3: NA | E3: 246779410001 | F3: USD | G3: 50.75 | H3: INR | I3: 4299.63 | J3: Towards Fixed charges for the month of August2024
A4: 1800014973 | B4: DR | C4: 45981 | D4: NA | E4: 256779419474 | F4: USD | G4: 20.28 | H4: INR | I4: 1784.71 | J4: Weighment-Nov 1-15, 2025
A5: 1800000003 | B5: DR | C5: 45692 | D5: NA | E5: 246779410003 | F5: USD | G5: 50.75 | H5: INR | I5: 4379.91 | J5: Towards Fixed charges for the month of August2024
A6: 1800000002 | B6: DR | C6: 45692 | D6: NA | E6: 246779410002 | F6: USD | G6: 50.75 | H6: INR | I6: 4379.91 | J6: Towards Fixed charges for the month of August2024
A7: 1800010437 | B7: DR | C7: 45842 | D7: NA | E7: 256779415197 | F7: USD | G7: 492.25 | H7: INR | I7: 42333.83 | J7: Unit Storage - 1-30 June 25
A8: 1800010502 | B8: DR | C8: 45842 | D8: NA | E8: 256779415262 | F8: USD | G8: 476.32 | H8: INR | I8: 40963.84 | J8: VAS - 16-30 June 25
A9: 1800014289 | B9: DR | C9: 45966 | D9: NA | E9: 256779418826 | F9: USD | G9: 60.86 | H9: INR | I9: 5355.89 | J9: WEIGHTMENT-16 -31 Oct 25
A10: 1800014554 | B10: DR | C10: 45966 | D10: NA | E10: 256779418886 | F10: USD | G10: 1457.24 | H10: INR | I10: 128242.06 | J10: Unit Storage - 1-31 Oct 2025
A11: 1800014728 | B11: DR | C11: 45966 | D11: 2123630 | E11: 256779419229 | F11: USD | G11: 77.07 | H11: INR | I11: 6782.42 | J11: PORT SSR Chgs Oct 25
A12: 1800011657 | B12: DR | C12: 45877 | D12: NA | E12: 256779416087 | F12: USD | G12: 916.56 | H12: INR | I12: 78851.77 | J12: Unit Storage - 1-31 July 25
A13: 1800009134 | B13: DR | C13: 45805 | D13: NA | E13: 256779413898 | F13: USD | G13: 928.64 | H13: INR | I13: 79847.9 | J13: Storage Chgs - 01 - 31 Apr 25
A14: 1800000028 | B14: DR | C14: 45708 | D14: NA | E14: 246779410073 | F14: USD | G14: 50.75 | H14: INR | I14: 4379.91 | J14: Fixed Rental charges for Aug 2024
... A46: 1800016703 | B46: DR | C46: 46034 | D46: 2158638 | E46: 256779440292 | F46: USD | G46: 40.04 | H46: INR | I46: 3633.36 | J46: Weighment-Dec 25 - 16-31

Sheet CN not in customers book
A2: Document Number | B2: Document Type | C2: Document Date | D2: Document Header Text | E2: Reference | F2: Document Currency Key | G2: Document Currency Value | H2: Company Code Currency Key | I2: Company Code Currency Value
A3: 1600000000 | B3: DG | C3: 45693 | D3: NA | E3: 246779420001 | F3: USD | G3: -50.75 | H3: INR | I3: -4379.91 | J3: Credit Against Invoice #1800000002
A4: 1600000716 | B4: DG | C4: 45791 | D4: NA | E4: 256779420425 | F4: USD | G4: -50.75 | H4: INR | I4: -4411.28 | J4: Credit note against 256779410292
A5: 1600000803 | B5: DG | C5: 45791 | D5: NA | E5: 256779420512 | F5: USD | G5: -50.75 | H5: INR | I5: -4411.28 | J5: Credit note against 256779410251
A6: 1600002033 | B6: DG | C6: 45873 | D6: NA | E6: 256779421609 | F6: USD | G6: -83.9 | H6: INR | I6: -7215.46 | J6: Credit note raised against 256779415776
A7: 1600001873 | B7: DG | C7: 45862 | D7: NA | E7: 256779421493 | F7: USD | G7: -50.75 | H7: INR | I7: -4364.53 | J7: Credit note raised against 256779414425
A8: 1600001907 | B8: DG | C8: 45862 | D8: NA | E8: 256779421527 | F8: USD | G8: -50.75 | H8: INR | I8: -4364.53 | J8: Credit note raised against 256779414460
A9: 1600001924 | B9: DG | C9: 45862 | D9: NA | E9: 256779421544 | F9: USD | G9: -50.75 | H9: INR | I9: -4364.53 | J9: Credit note raised against 256779414477
A10: 1600001851 | B10: DG | C10: 45862 | D10: NA | E10: 256779421471 | F10: USD | G10: -50.75 | H10: INR | I10: -4364.53 | J10: Credit note raised against 256779414403
A11: 1600001070 | B11: DG | C11: 45799 | D11: NA | E11: 256779420758 | F11: USD | G11: -50.75 | H11: INR | I11: -4379.91 | J11: Credit Note against 246779410002
A12: 1600001069 | B12: DG | C12: 45799 | D12: NA | E12: 256779420757 | F12: USD | G12: -50.75 | H12: INR | I12: -4379.91 | J12: Credit Note against 246779410073
A13: 1600002696 | B13: DG | C13: 46027 | D13: NA | E13: 256779422166 | F13: USD | G13: -950.87 | H13: INR | I13: -86284.93 | J13: Credit note for Duplicate invoice -256779418491
A14: 1600002701 | B14: DG | C14: 46027 | D14: NA | E14: 256779422171 | F14: USD | G14: -40.77 | H14: INR | I14: -3699.6 | J14: Credit note for Duplicate invoice -256779418496
G15: =SUM(G3:G14) -> -1532.29

Sheet Difference in Invoice old
A1: Document Number | B1: Document Type | C1: Document Date | D1: Reference | E1: Document Currency Key | F1: Document Currency Value | G1: Company Code Currency Key | H1: Company Code Currency Value | K1: Gross Amount | L1: Net Amount | M1: Diffrence In invoice value
A2: 1800016772 | B2: DR | C2: 46035 | D2: 256779440359 | E2: USD | F2: 821.64 | G2: INR | H2: 74558.19 | I2: VAS - NOV 25,16-30 | J2: 1 | K2: 40.04 | L2: 39.04 | M2: =F2-K2 -> 781.6
A3: 1800016783 | B3: DR | C3: 46035 | D3: 256779440370 | E3: USD | F3: 60.36 | G3: INR | H3: 5477.26 | I3: Weighment -NOV 25,16-30 | J3: 1 | K3: 63.21 | L3: =K3-J3 -> 62.21 | M3: =F3-K3 -> -2.85
M4: =SUM(M2:M3) -> 778.75

Sheet Sheet10
A2: As per Customer Data | F2: As per Ascendus Data
A3: Years | B3: Posting Date | C3: TDS and Payment | D3: Purchase | F3: Years | G3: Document Date | H3: CN | I3: Sales | J3: Net Sales | K3: Payment
F4: 2025 | G4: Jan | I4: 50.75 | J4: =SUM(H4:I4) -> 50.75
A5: 2025 | B5: Feb | C5: 0 | D5: 274.5 | F5: 2025 | G5: Feb | H5: -101.5 | I5: 456.75 | J5: =SUM(H5:I5) -> 355.25
A6: 2025 | B6: Mar | C6: -282.60599 | D6: 4.053 | F6: 2025 | G6: Mar | I6: 50.75 | J6: =SUM(H6:I6) -> 50.75 | K6: -302.06276
F7: 2025 | G7: Apr | I7: 152.25 | J7: =SUM(H7:I7) -> 152.25
F8: 2025 | G8: May | H8: -203 | I8: 3380.88 | J8: =SUM(H8:I8) -> 3177.88
F9: 2025 | G9: Jun | I9: 1438.33 | J9: =SUM(H9:I9) -> 1438.33
F10: 2025 | G10: Jul | H10: -203 | I10: 3356.79 | J10: =SUM(H10:I10) -> 3153.79 | K10: 0
F11: 2025 | G11: Aug | H11: -83.9 | I11: 967.31 | J11: =SUM(H11:I11) -> 883.41
A12: 2025 | B12: Sep | C12: 0 | D12: 45.75 | F12: 2025 | G12: Sep | I12: 3151.36 | J12: =SUM(H12:I12) -> 3151.36
A13: 2025 | B13: Oct | C13: -5813.9535 | D13: 274.5 | F13: 2025 | G13: Oct | I13: 4613.83 | J13: =SUM(H13:I13) -> 4613.83 | K13: -5813.9535
F14: 2025 | G14: Nov | I14: 4169.54 | J14: =SUM(H14:I14) -> 4169.54
A15: 2025 | B15: Dec | C15: -2 | D15: 3671.59 | F15: 2026 | G15: Jan | H15: -991.64 | I15: 4534.06 | J15: =SUM(H15:I15) -> 3542.42 | K15: -5537.098
A16: 2026 | B16: Jan | C16: -5639.098 | D16: 4738.41 | H16: =SUM(H4:H15) -> -1583.04 | I16: =SUM(I4:I15) -> 26322.6 | J16: =SUM(H16:I16) -> 24739.56 | K16: =SUM(K4:K15) -> -11653.114 | L16: =SUM(J16:K16) -> 13086.446
A17: 2026 | B17: Feb | C17: -13 | D17: 506
C18: =SUM(C4:C17) -> -11750.657 | D18: =SUM(D4:D17) -> 9514.803 | E18: =SUM(C18:D18) -> -2235.8545
