Workbook

Sheet Invoice Not in Customer Boo (2)
A1: Document Number | B1: Document Type | C1: Document Date | D1: Entry Date | E1: Document Header Text | F1: Reference | G1: Document Currency Key | H1: Document Currency Value | I1: Company Code Currency Key | J1: Company Code Currency Value | K1: Text | L1: Remark | M1: Remarks | N1: Action Points
A2: 1800001617 | B2: DR | C2: 45730 | D2: 45735 | E2: NA | F2: 246779412274 | G2: USD | H2: 100 | I2: INR | J2: 8669.13 | K2: Intra Unit Transfer Charges Month Of August,2024 | L2: We had given 2 invoices against BOE No. 7000274, and we accepted invoice 246779411485. | M2: Credit Note to be passed after verification by billing team | N2: Credit Note to be passed as discussed with CL team
A3: 1800000559 | B3: DR | C3: 45719 | D3: 45719 | E3: NA | F3: 246779410509 | G3: USD | H3: 29.25 | I3: INR | J3: 2535.72 | K3: Outbound Handling for Aug 2024 | L3: you have made an Invoice of Handling Charges 13 Plt instead of 4 Plt. | M3: CRM team will handle | N3: to be accounted by siddhartha
A4: 1800006698 | B4: DR | C4: 45762 | D4: 45763 | E4: NA | F4: 256779411589 | G4: USD | H4: 3.38 | I4: INR | J4: 293.8 | K4: Outbound Handling Charges Aug 2024 | L4: Handling Charges CBM Rate is 2.25 but you have Handling Charges CBM Rate is 3.24 | M4: CRM team will handle | N4: To be discussed with customer that the rate is charged as per agreemant for HAZ goods
A5: 1800001791 | B5: DR | C5: 45730 | D5: 45733 | E5: NA | F5: 246779411456 | G5: USD | H5: 4.77 | I5: INR | J5: 413.52 | K5: VAS Activity Charges for the month of August, 24 | L5: Duplicated invoice | M5: Credit Note to be passed after verification by billing team | N5: Credit Note to be passed as discussed with CL team
A6: 1800012462 | B6: DR | C6: 45904 | D6: 45909 | E6: NA | F6: 256779417162 | G6: USD | H6: 44.74 | I6: INR | J6: 3915.39 | K6: VAS -16-31 Aug 25 | L6: The VAS charges are incorrect. | M6: Invoice to changed by CRM team | N6: Credit Note to be passed as discussed with CL team
A7: 1800014290 | B7: DR | C7: 45966 | D7: 45967 | E7: NA | F7: 256779418827 | G7: USD | H7: 60.86 | I7: INR | J7: 5355.89 | K7: WEIGHTMENT-16 -31 Oct 25 | L7: These specific charges are not included in our existing contract. | N7: Credit Note to be passed as discussed with CL team
A8: 1800004532 | B8: DR | C8: 45736 | D8: 45737 | E8: NA | F8: 246779414400 | G8: USD | H8: 80.95 | I8: INR | J8: 7017.66 | K8: Inbound Handling charges for Nov 2024 | L8: Handling Charges CBM Rate is 2.25 but you have Handling Charges CBM Rate is 3.24 | M8: CRM team will handle | N8: To be discussed with customer that the rate is charged as per agreemant for HAZ goods
A9: 1800004533 | B9: DR | C9: 45736 | D9: 45737 | E9: NA | F9: 246779414401 | G9: USD | H9: 15 | I9: INR | J9: 1300.37 | K9: LCL Movement Charges for Nov 2024 | M9: Amount in Invoice to be verified by biling team | N9: to be accounted by siddhartha
A10: 1800013760 | B10: DR | C10: 45937 | D10: 45939 | E10: NA | F10: 256779418181 | G10: USD | H10: 49.33 | I10: INR | J10: 4350.45 | K10: VAS-16-30 Sept 25 | L10: This is to inform you that MHE charges have already been applied in Invoice Nos. 256779418354 and 256779418342. However, the same MHE charges have been included again in Invoice No. 256779418181. | M10: to be accounted by siddhartha after CBM rate issue is solved | N10: Credit Note to be passed as discussed with CL team
A11: 1800009470 | B11: DR | C11: 45815 | D11: 45817 | E11: NA | F11: 256779414234 | G11: USD | H11: 925.23 | I11: INR | J11: 79098.63 | K11: Unit storage -1-31 May 25 | L11: Credit Note Pending | M11: mail summary will be sent by Siddhartha team ,Credit Note to be passed after verification by billing team | N11: Credit Note to be passed as discussed with CL team | O11: 149 | P11: 22.64
A12: 1800013511 | B12: DR | C12: 45935 | D12: 45940 | E12: NA | F12: 256779418401 | G12: USD | H12: 62.52 | I12: INR | J12: 5513.69 | K12: PORT SSR Chgs Sep 25 | L12: These specific charges are not included in our existing contract. | M12: to be accounted by siddhartha | N12: to be accounted by siddhartha
H13: =SUM(H2:H12) -> 1376.03 | J13: =SUBTOTAL(9,J2:J12) -> 118464.25

Sheet Summary
A1: Reconciliation of Ledger as on 31st January 2026
A2: Particulars | B2: Amount in USD
A3: Balance as per Siddhartha Logistics | B3: ='Customer Data'!F151 -> 5221.593
A4: Add: TDS to be booked in Ascendus books | B4: ='TDS To Be Booked'!L146+'Payment Reco'!H4 -> 2462.8459
A5: Add: Invoices & CN not recorded in customer books | B5: ='Invoice Not in Customer Boo (2)'!H13 -> 1376.03
A6: Less: Difference in Payment recorded in both books | B6: 50
A7: Derived balance | B7: =SUM(B3:B6) -> 9110.4689
A8: Balance as per Ascent | B8: ='Ascendus data working'!F202 -> 8974.5146
A10: Difference | B10: =B7-B8-B9 -> 135.95426

Sheet Payment Reco
A2: As per Customer | D2: As per Ascendus
A3: Payment Date | B3: Particulars | C3: Amount | D3: Particulars | E3: Date | G3: Amount | H3: Diffrence
A4: 45800 | B4: Outgoing payment | C4: 7435.89 | D4: DZ | E4: 45862 | F4: USD | G4: -8262.11 | H4: =C4+G4 -> -826.22
A5: 45856 | B5: Outgoing payment | C5: 4602.99 | D5: DZ | E5: 45891 | F5: USD | G5: -4582.99 | H5: =C5+G5 -> 20
A6: 45945 | B6: Outgoing payment | C6: 4875.15 | D6: DZ | E6: 45955 | F6: USD | G6: -4875.15 | H6: =C6+G6 -> 0
B7: Outgoing payment | C7: 10721.42 | D7: DZ | E7: 46050 | F7: USD | G7: -10691.42 | H7: =C7+G7 -> 30
C8: =SUM(C4:C7) -> 27635.45 | G8: =SUM(G4:G7) -> -28411.67 | H8: =SUM(H4:H7) -> -776.22

Sheet CN Not in Customer Books
A1: Document Number | B1: Document Type | C1: Document Date | D1: Entry Date | E1: Document Header Text | F1: Reference | G1: Document Currency Key | H1: Document Currency Value | I1: Company Code Currency Key | J1: Company Code Currency Value | K1: Text | L1: Text | M1: Vlookup
A2: 1600002686 | B2: DG | C2: 46027 | D2: 46027 | E2: NA | F2: 256779422156 | G2: USD | H2: -59.62 | I2: INR | J2: -5410.11 | K2: Credit note for Duplicate invoice -256779418354 | M2: #N/A | O2: 256779418354 | P2: =VLOOKUP(O2,'Invoice Not in Customer Book'!F:H,3,0) -> #N/A | Q2: =H2+P2 -> #N/A
A3: 1600002687 | B3: DG | C3: 46027 | D3: 46027 | E3: NA | F3: 256779422157 | G3: USD | H3: -49.33 | I3: INR | J3: -4476.36 | K3: Credit note for Duplicate invoice -256779418354 | M3: #N/A | O3: 256779418354 | P3: =VLOOKUP(O3,'Invoice Not in Customer Book'!F:H,3,0) -> #N/A | Q3: =H3+P3 -> #N/A
H4: =SUM(H2:H3) -> -108.95

Sheet Invoice Not in Customer Book
A1: Document Number | B1: Document Type | C1: Document Date | D1: Entry Date | E1: Document Header Text | F1: Reference | G1: Document Currency Key | H1: Document Currency Value | I1: Company Code Currency Key | J1: Company Code Currency Value | K1: Text | L1: Text | M1: Vlookup | O1: Action points
A2: 1800001617 | B2: DR | C2: 45730 | D2: 45735 | E2: NA | F2: 246779412274 | G2: USD | H2: 100 | I2: INR | J2: 8669.13 | K2: Intra Unit Transfer Charges Month Of August,2024 | M2: #N/A | N2: =VLOOKUP(F2,'CN Not in Customer Books'!O:O,1,0) -> #N/A | O2: Credit Note to be passed as discussed with CL team
A3: 1800000559 | B3: DR | C3: 45719 | D3: 45719 | E3: NA | F3: 246779410509 | G3: USD | H3: 29.25 | I3: INR | J3: 2535.72 | K3: Outbound Handling for Aug 2024 | M3: #N/A | N3: =VLOOKUP(F3,'CN Not in Customer Books'!O:O,1,0) -> #N/A | O3: to be accounted by siddhartha
A4: 1800006698 | B4: DR | C4: 45762 | D4: 45763 | E4: NA | F4: 256779411589 | G4: USD | H4: 3.38 | I4: INR | J4: 293.8 | K4: Outbound Handling Charges Aug 2024 | M4: #N/A | N4: =VLOOKUP(F4,'CN Not in Customer Books'!O:O,1,0) -> #N/A | O4: To be discussed with customer that the rate is charged as per agreemant for HAZ goods
A5: 1800012462 | B5: DR | C5: 45904 | D5: 45909 | E5: NA | F5: 256779417162 | G5: USD | H5: 44.74 | I5: INR | J5: 3915.39 | K5: VAS -16-31 Aug 25 | M5: #N/A | N5: =VLOOKUP(F5,'CN Not in Customer Books'!O:O,1,0) -> #N/A | O5: Credit Note to be passed as discussed with CL team
A6: 1800014290 | B6: DR | C6: 45966 | D6: 45967 | E6: NA | F6: 256779418827 | G6: USD | H6: 60.86 | I6: INR | J6: 5355.89 | K6: WEIGHTMENT-16 -31 Oct 25 | M6: #N/A | N6: =VLOOKUP(F6,'CN Not in Customer Books'!O:O,1,0) -> #N/A | O6: Credit Note to be passed as discussed with CL team
A7: 1800004532 | B7: DR | C7: 45736 | D7: 45737 | E7: NA | F7: 246779414400 | G7: USD | H7: 80.95 | I7: INR | J7: 7017.66 | K7: Inbound Handling charges for Nov 2024 | M7: #N/A | N7: =VLOOKUP(F7,'CN Not in Customer Books'!O:O,1,0) -> #N/A | O7: To be discussed with customer that the rate is charged as per agreemant for HAZ goods
A8: 1800004533 | B8: DR | C8: 45736 | D8: 45737 | E8: NA | F8: 246779414401 | G8: USD | H8: 15 | I8: INR | J8: 1300.37 | K8: LCL Movement Charges for Nov 2024 | M8: #N/A | N8: =VLOOKUP(F8,'CN Not in Customer Books'!O:O,1,0) -> #N/A | O8: to be accounted by siddhartha
A9: 1800013760 | B9: DR | C9: 45937 | D9: 45939 | E9: NA | F9: 256779418181 | G9: USD | H9: 49.33 | I9: INR | J9: 4350.45 | K9: VAS-16-30 Sept 25 | M9: #N/A | N9: =VLOOKUP(F9,'CN Not in Customer Books'!O:O,1,0) -> #N/A | O9: Credit Note to be passed as discussed with CL team
A10: 1800009470 | B10: DR | C10: 45815 | D10: 45817 | E10: NA | F10: 256779414234 | G10: USD | H10: 925.23 | I10: INR | J10: 79098.63 | K10: Unit storage -1-31 May 25 | M10: #N/A | N10: =VLOOKUP(F10,'CN Not in Customer Books'!O:O,1,0) -> #N/A | O10: Credit Note to be passed as discussed with CL team
A11: 1800013511 | B11: DR | C11: 45935 | D11: 45940 | E11: NA | F11: 256779418401 | G11: USD | H11: 62.52 | I11: INR | J11: 5513.69 | K11: PORT SSR Chgs Sep 25 | M11: #N/A | N11: =VLOOKUP(F11,'CN Not in Customer Books'!O:O,1,0) -> #N/A | O11: to be accounted by siddhartha
H12: =SUM(H2:H11) -> 1371.26
H13: ='CN Not in Customer Books'!H4 -> -108.95
H14: =SUM(H12:H13) -> 1262.31

Sheet TDS To Be Booked
L1: =SUBTOTAL(9,L2:L136) -> 3468.5859 | M1: =L1*85 -> 294829.8
A2: Document Number | B2: Document Type | C2: Document Date | D2: Reference | E2: Document Currency Key | F2: Document Currency Value | G2: Company Code Currency Key | H2: Company Code Currency Value | I2: Text | J2: Vlookup | K2: Converted Value | L2: TDS Deducted | M2: Rate
A3: 1800000035 | B3: DR | C3: 45708 | D3: 246779410007 | E3: USD | F3: 1190.48 | G3: INR | H3: 102742.78 | I3: Fixed Rental charges for Aug 2024 | J3: 1071.43 | K3: =F3 -> 1190.48 | L3: =F3-J3 -> 119.05 | M3: =L3/F3*100 -> 10.000168
A4: 1800000079 | B4: DR | C4: 45708 | D4: 246779410274 | E4: USD | F4: 1190.48 | G4: INR | H4: 102742.78 | I4: Fixed Rental charges for Oct 2024 | J4: 1071.43 | K4: =F4 -> 1190.48 | L4: =F4-J4 -> 119.05 | M4: =L4/F4*100 -> 10.000168
A5: 1800000099 | B5: DR | C5: 45708 | D5: 246779410027 | E5: USD | F5: 1190.48 | G5: INR | H5: 102742.78 | I5: Fixed Rental charges for Sept 2024 | J5: 1071.43 | K5: =F5 -> 1190.48 | L5: =F5-J5 -> 119.05 | M5: =L5/F5*100 -> 10.000168
A6: 1800000168 | B6: DR | C6: 45708 | D6: 246779410095 | E6: USD | F6: 1190.48 | G6: INR | H6: 102742.78 | I6: Fixed Rental charges for Nov 2024 | J6: 1071.43 | K6: =F6 -> 1190.48 | L6: =F6-J6 -> 119.05 | M6: =L6/F6*100 -> 10.000168
A7: 1800000211 | B7: DR | C7: 45708 | D7: 246779410138 | E7: USD | F7: 1190.48 | G7: INR | H7: 102742.78 | I7: Fixed Rental charges for Dec 2024 | J7: 1071.43 | K7: =F7 -> 1190.48 | L7: =F7-J7 -> 119.05 | M7: =L7/F7*100 -> 10.000168
A8: 1800000254 | B8: DR | C8: 45708 | D8: 246779410181 | E8: USD | F8: 1166.59 | G8: INR | H8: 100680.99 | I8: Fixed Rental charges for Jan 2025 | J8: 1049.93 | K8: =F8 -> 1166.59 | L8: =F8-J8 -> 116.66 | M8: =L8/F8*100 -> 10.000086
A9: 1800000297 | B9: DR | C9: 45708 | D9: 246779410224 | E9: USD | F9: 1143.12 | G9: INR | H9: 98655.44 | I9: Fixed Rental charges for Feb 2025 | J9: 1028.81 | K9: =F9 -> 1143.12 | L9: =F9-J9 -> 114.31 | M9: =L9/F9*100 -> 9.999825
A10: 1800000406 | B10: DR | C10: 45719 | D10: 246779410368 | E10: USD | F10: 356.43 | G10: INR | H10: 30899.37 | I10: Storage Charges for the month of August, 2024 | J10: 320.78 | K10: =F10 -> 356.43 | L10: =F10-J10 -> 35.65 | M10: =L10/F10*100 -> 10.001964
A11: 1800000675 | B11: DR | C11: 45719 | D11: 246779410615 | E11: USD | F11: 9 | G11: INR | H11: 780.22 | I11: Outbound Handling for Sep 2024 | J11: 8.81 | K11: =F11 -> 9 | L11: =F11-J11 -> 0.19 | M11: =L11/F11*100 -> 2.1111111
A12: 1800000432 | B12: DR | C12: 45719 | D12: 246779410394 | E12: USD | F12: 505.86 | G12: INR | H12: 43853.64 | I12: Storage for the month of Sep 2024 Exch Rate 83.79 | J12: 455.27 | K12: =F12 -> 505.86 | L12: =F12-J12 -> 50.59 | M12: =L12/F12*100 -> 10.000791
A13: 1800000456 | B13: DR | C13: 45719 | D13: 246779410418 | E13: USD | F13: 562.6 | G13: INR | H13: 48772.5 | I13: Storage for the month of Oct 2024 | J13: 506.34 | K13: =F13 -> 562.6 | L13: =F13-J13 -> 56.26 | M13: =L13/F13*100 -> 10
A14: 1800000560 | B14: DR | C14: 45719 | D14: 246779410510 | E14: USD | F14: 194.9 | G14: INR | H14: 16896.13 | I14: Outbound Handling for Aug 2024 | J14: 191 | K14: =F14 -> 194.9 | L14: =F14-J14 -> 3.9 | M14: =L14/F14*100 -> 2.0010262
... A73: 1800008041 | B73: DR | C73: 45770 | D73: 256779412932 | E73: USD | F73: 66.86 | G73: INR | H73: 5811.59 | I73: Outbound chgs - 01 - 15 Apr 25 | J73: 65.52 | K73: =F73 -> 66.86 | L73: =F73-J73 -> 1.34 | M73: =L73/F73*100 -> 2.0041879
A74: 1800008258 | B74: DR | C74: 45787 | D74: 256779413142 | E74: INR | F74: 100000 | G74: INR | H74: 100000 | I74: Fixed Storage Charges fo MAY 2025 | J74: 1046.71 | K74: =J74/0.9 -> 1163.0111 | L74: =K74-J74 -> 116.30111 | M74: =L74/K74*100 -> 10
A75: 1800008504 | B75: DR | C75: 45793 | D75: 256779413272 | E75: USD | F75: 25.28 | G75: INR | H75: 2173.67 | I75: Empty Lolo Chgs - 01 - 31 Apr 25 | J75: 24.77 | K75: =F75 -> 25.28 | L75: =F75-J75 -> 0.51 | M75: =L75/F75*100 -> 2.0174051
A76: 1800008597 | B76: DR | C76: 45793 | D76: 256779413361 | E76: USD | F76: 3 | G76: INR | H76: 257.95 | I76: Outbound chgs - 16 - 30 Apr 25 | J76: 2.94 | K76: =F76 -> 3 | L76: =F76-J76 -> 0.06 | M76: =L76/F76*100 -> 2
A77: 1800008726 | B77: DR | C77: 45797 | D77: 256779413490 | E77: USD | F77: 3 | G77: INR | H77: 257.95 | I77: Outbound chgs - 01 - 15 MAY 25 | J77: 2.94 | K77: =F77 -> 3 | L77: =F77-J77 -> 0.06 | M77: =L77/F77*100 -> 2
A78: 1800009129 | B78: DR | C78: 45805 | D78: 256779413893 | E78: USD | F78: 797.57 | G78: INR | H78: 68578.02 | I78: Storage Chgs - 01 - 31 Apr 25 | J78: 717.81 | K78: =F78 -> 797.57 | L78: =F78-J78 -> 79.76 | M78: =L78/F78*100 -> 10.000376
A79: 1800009239 | B79: DR | C79: 45812 | D79: 256779414003 | E79: USD | F79: 807.39 | G79: INR | H79: 69024.4 | I79: Storage- Aug-24, | J79: 726.65 | K79: =F79 -> 807.39 | L79: =F79-J79 -> 80.74 | M79: =L79/F79*100 -> 10.000124
A80: 1800009240 | B80: DR | C80: 45812 | D80: 256779414004 | E80: USD | F80: 808.16 | G80: INR | H80: 69090.23 | I80: Storage- Sept-24, | J80: 727.34 | K80: =F80 -> 808.16 | L80: =F80-J80 -> 80.82 | M80: =L80/F80*100 -> 10.000495
A81: 1800009241 | B81: DR | C81: 45812 | D81: 256779414005 | E81: USD | F81: 805.28 | G81: INR | H81: 68844.02 | I81: Storage - Oct-24, | J81: 724.75 | K81: =F81 -> 805.28 | L81: =F81-J81 -> 80.53 | M81: =L81/F81*100 -> 10.000248
A82: 1800009242 | B82: DR | C82: 45812 | D82: 256779414006 | E82: USD | F82: 801.47 | G82: INR | H82: 68518.3 | I82: Storage- Nov-24, | J82: 721.32 | K82: =F82 -> 801.47 | L82: =F82-J82 -> 80.15 | M82: =L82/F82*100 -> 10.000374
A83: 1800009243 | B83: DR | C83: 45812 | D83: 256779414007 | E83: USD | F83: 790.89 | G83: INR | H83: 67613.8 | I83: Storage- Dec-24, | J83: 711.8 | K83: =F83 -> 790.89 | L83: =F83-J83 -> 79.09 | M83: =L83/F83*100 -> 10.000126
A84: 1800009590 | B84: DR | C84: 45818 | D84: 256779414354 | E84: INR | F84: 100000 | G84: INR | H84: 100000 | I84: Fixed Storage Charges fo JUNE 2025 | J84: 1052.75 | K84: =J84/0.9 -> 1169.7222 | L84: =K84-J84 -> 116.97222 | M84: =L84/K84*100 -> 10
A85: 1800010152 | B85: DR | C85: 45842 | D85: 256779414912 | E85: INR | F85: 100000 | G85: INR | H85: 100000 | I85: Fixed Storage Charges fo JULY 2025 | J85: 1046.5 | K85: =J85/0.9 -> 1162.7778 | L85: =K85-J85 -> 116.27778 | M85: =L85/K85*100 -> 10
A86: 1800010069 | B86: DR | C86: 45842 | D86: 256779414833 | E86: USD | F86: 3 | G86: INR | H86: 258 | I86: Outbound chgs - 01 - 15 Jun 25 | J86: 2.94 | K86: =F86 -> 3 | L86: =F86-J86 -> 0.06 | M86: =L86/F86*100 -> 2
A87: 1800010430 | B87: DR | C87: 45842 | D87: 256779415190 | E87: USD | F87: 690.7 | G87: INR | H87: 59400.66 | I87: Unit Storage - 1-30 June 25 | J87: 621.63 | K87: =F87 -> 690.7 | L87: =F87-J87 -> 69.07 | M87: =L87/F87*100 -> 10
A88: 1800010701 | B88: DR | C88: 45856 | D88: 256779415485 | E88: USD | F88: 17.25 | G88: INR | H88: 1483.51 | I88: LCL chgs - 01 - 15 JUL 25 | J88: 16.9 | K88: =F88 -> 17.25 | L88: =F88-J88 -> 0.35 | M88: =L88/F88*100 -> 2.0289855
A89: 1800010749 | B89: DR | C89: 45856 | D89: 256779415533 | E89: USD | F89: 21.75 | G89: INR | H89: 1870.51 | I89: Outbound chgs - 01 - 15 Jul 25 | J89: 21.31 | K89: =F89 -> 21.75 | L89: =F89-J89 -> 0.44 | M89: =L89/F89*100 -> 2.0229885
A90: 1800011012 | B90: DR | C90: 45857 | D90: 256779415772 | E90: USD | F90: 59.43 | G90: INR | H90: 5111.02 | I90: VAS - 1-15 July 25 | J90: 58.24 | K90: =F90 -> 59.43 | L90: =F90-J90 -> 1.19 | M90: =L90/F90*100 -> 2.0023557
A91: 1800011358 | B91: DR | C91: 45870 | D91: 256779416024 | E91: INR | F91: 100000 | G91: INR | H91: 100000 | I91: Fixed Storage Charges for August 2025 | J91: 1046.14 | K91: =J91/0.9 -> 1162.3778 | L91: =K91-J91 -> 116.23778 | M91: =L91/K91*100 -> 10
A92: 1800011652 | B92: DR | C92: 45877 | D92: 256779416082 | E92: USD | F92: 759.67 | G92: INR | H92: 65354.5 | I92: Unit Storage - 1-31 July 25 | J92: 683.7 | K92: =F92 -> 759.67 | L92: =F92-J92 -> 75.97 | M92: =L92/F92*100 -> 10.000395
A93: 1800011791 | B93: DR | C93: 45877 | D93: 256779416182 | E93: USD | F93: 18 | G93: INR | H93: 1548.54 | I93: LCL chgs - 16 - 31 JUL 25 | J93: 17.64 | K93: =F93 -> 18 | L93: =F93-J93 -> 0.36 | M93: =L93/F93*100 -> 2
A94: 1800011710 | B94: DR | C94: 45877 | D94: 256779416228 | E94: USD | F94: 3 | G94: INR | H94: 258.09 | I94: Outbound chgs - 16 - 31 Jul 25 | J94: 2.94 | K94: =F94 -> 3 | L94: =F94-J94 -> 0.06 | M94: =L94/F94*100 -> 2
A95: 1800011396 | B95: DR | C95: 45877 | D95: 256779416246 | E95: USD | F95: 70.95 | G95: INR | H95: 6103.84 | I95: CODC LCL Chgs - 16 - 31 Jul 25 | J95: 69.54 | K95: =F95 -> 70.95 | L95: =F95-J95 -> 1.41 | M95: =L95/F95*100 -> 1.987315
A96: 1800011407 | B96: DR | C96: 45877 | D96: 256779416257 | E96: USD | F96: 22.87 | G96: INR | H96: 1967.51 | I96: CODC Out chgs - 16 - 31 Jul 25 | J96: 22.42 | K96: =F96 -> 22.87 | L96: =F96-J96 -> 0.45 | M96: =L96/F96*100 -> 1.9676432
A97: 1800011596 | B97: DR | C97: 45877 | D97: 256779416446 | E97: USD | F97: 2.28 | G97: INR | H97: 196.15 | I97: VAS 16-31 July 25 | J97: 2.23 | K97: =F97 -> 2.28 | L97: =F97-J97 -> 0.05 | M97: =L97/F97*100 -> 2.1929825
A98: 1800012069 | B98: DR | C98: 45889 | D98: 256779416604 | E98: USD | F98: 17.31 | G98: INR | H98: 1489.18 | I98: CODC LCL Chgs - 1-15 Aug 25 | J98: 16.96 | K98: =F98 -> 17.31 | L98: =F98-J98 -> 0.35 | M98: =L98/F98*100 -> 2.0219526
...

Sheet Ascendus data working
A1: Document Number | B1: Ref | C1: Document Type | D1: Document Date | E1: Document Currency Key | F1: Document Currency Value | G1: Company Code Currency Key | H1: Company Code Currency Value | I1: Text | K1: Ref | L1: Document Type | M1: Sum of Document Currency Value
A2: 1800000035 | B2: 246779410007 | C2: DR | D2: 45708 | E2: USD | F2: 1190.48 | G2: INR | H2: 102742.78 | I2: Fixed Rental charges for Aug 2024 | K2: 2166093 | L2: DZ | M2: -10691.42
A3: 1800000079 | B3: 246779410274 | C3: DR | D3: 45708 | E3: USD | F3: 1190.48 | G3: INR | H3: 102742.78 | I3: Fixed Rental charges for Oct 2024 | K3: 246779410007 | L3: DR | M3: 1190.48
A4: 1800000099 | B4: 246779410027 | C4: DR | D4: 45708 | E4: USD | F4: 1190.48 | G4: INR | H4: 102742.78 | I4: Fixed Rental charges for Sept 2024 | K4: 246779410027 | L4: DR | M4: 1190.48
A5: 1800000168 | B5: 246779410095 | C5: DR | D5: 45708 | E5: USD | F5: 1190.48 | G5: INR | H5: 102742.78 | I5: Fixed Rental charges for Nov 2024 | K5: 246779410095 | L5: DR | M5: 1190.48
A6: 1800000211 | B6: 246779410138 | C6: DR | D6: 45708 | E6: USD | F6: 1190.48 | G6: INR | H6: 102742.78 | I6: Fixed Rental charges for Dec 2024 | K6: 246779410138 | L6: DR | M6: 1190.48
A7: 1800000254 | B7: 246779410181 | C7: DR | D7: 45708 | E7: USD | F7: 1166.59 | G7: INR | H7: 100680.99 | I7: Fixed Rental charges for Jan 2025 | K7: 246779410181 | L7: DR | M7: 1166.59
A8: 1800000297 | B8: 246779410224 | C8: DR | D8: 45708 | E8: USD | F8: 1143.12 | G8: INR | H8: 98655.44 | I8: Fixed Rental charges for Feb 2025 | K8: 246779410224 | L8: DR | M8: 1143.12
A9: 1800000406 | B9: 246779410368 | C9: DR | D9: 45719 | E9: USD | F9: 356.43 | G9: INR | H9: 30899.37 | I9: Storage Charges for the month of August, 2024 | K9: 246779410274 | L9: DR | M9: 1190.48
A10: 1800000675 | B10: 246779410615 | C10: DR | D10: 45719 | E10: USD | F10: 9 | G10: INR | H10: 780.22 | I10: Outbound Handling for Sep 2024 | K10: 246779410368 | L10: DR | M10: 356.43
A11: 1800000432 | B11: 246779410394 | C11: DR | D11: 45719 | E11: USD | F11: 505.86 | G11: INR | H11: 43853.64 | I11: Storage for the month of Sep 2024 Exch Rate 83.79 | K11: 246779410394 | L11: DR | M11: 505.86
A12: 1800000456 | B12: 246779410418 | C12: DR | D12: 45719 | E12: USD | F12: 562.6 | G12: INR | H12: 48772.5 | I12: Storage for the month of Oct 2024 | K12: 246779410418 | L12: DR | M12: 562.6
A13: 1800000559 | B13: 246779410509 | C13: DR | D13: 45719 | E13: USD | F13: 29.25 | G13: INR | H13: 2535.72 | I13: Outbound Handling for Aug 2024 | K13: 246779410509 | L13: DR | M13: 29.25
... A116: 1800011012 | B116: 256779415772 | C116: DR | D116: 45857 | E116: USD | F116: 59.43 | G116: INR | H116: 5111.02 | I116: VAS - 1-15 July 25 | K116: 256779416446 | L116: DR | M116: 2.28
A117: 1400000797 | C117: DY | D117: 45861 | E117: INR | F117: 198636.61 | G117: INR | H117: 200764.2 | K117: 256779416604 | L117: DR | M117: 17.31
A118: 1400000797 | C118: DY | D118: 45861 | E118: INR | F118: -198636.61 | G118: INR | H118: -200764.2 | K118: 256779416616 | L118: DR | M118: 63.65
A119: 1400000805 | C119: DZ | D119: 45862 | E119: USD | F119: -8262.11 | G119: INR | H119: -713050.33 | I119: 0105357143FC | K119: 256779416847 | L119: DR | M119: 27.83
A120: 1600001882 | B120: 256779421502 | C120: DG | D120: 45862 | E120: USD | F120: -1190.48 | G120: INR | H120: -102382.08 | I120: Credit note raised against 256779414435 | K120: 256779416882 | L120: DR | M120: 12.83
A121: 1800011358 | B121: 256779416024 | C121: DR | D121: 45870 | E121: USD | F121: 1162.7907 | G121: INR | H121: 100000 | I121: Fixed Storage Charges for August 2025 | K121: 256779416912 | L121: DR | M121: 44.96
A122: 1600002012 | B122: 256779421588 | C122: DG | D122: 45873 | E122: USD | F122: -17.25 | G122: INR | H122: -1483.51 | I122: Credit note raised against 256779415490 | K122: 256779416949 | L122: DR | M122: 30.16
A123: 1600002057 | B123: 256779421633 | C123: DG | D123: 45873 | E123: USD | F123: -17.25 | G123: INR | H123: -1483.51 | I123: Credit note raised against 256779415805 | K123: 256779417077 | L123: DR | M123: 565.97
A124: 1600002062 | B124: 256779421638 | C124: DG | D124: 45873 | E124: USD | F124: -17.25 | G124: INR | H124: -1483.51 | I124: Credit note raised against 256779415810 | K124: 256779417136 | L124: DR | M124: 1.71
A125: 1800011652 | B125: 256779416082 | C125: DR | D125: 45877 | E125: USD | F125: 759.67 | G125: INR | H125: 65354.5 | I125: Unit Storage - 1-31 July 25 | K125: 256779417162 | L125: DR | M125: 44.74
A126: 1800011791 | B126: 256779416182 | C126: DR | D126: 45877 | E126: USD | F126: 18 | G126: INR | H126: 1548.54 | I126: LCL chgs - 16 - 31 JUL 25 | K126: 256779417328 | L126: DR | M126: 2.25
A127: 1800011710 | B127: 256779416228 | C127: DR | D127: 45877 | E127: USD | F127: 3 | G127: INR | H127: 258.09 | I127: Outbound chgs - 16 - 31 Jul 25 | K127: 256779417344 | L127: DR | M127: 1142.8571
A128: 1800011396 | B128: 256779416246 | C128: DR | D128: 45877 | E128: USD | F128: 70.95 | G128: INR | H128: 6103.84 | I128: CODC LCL Chgs - 16 - 31 Jul 25 | K128: 256779417528 | L128: DR | M128: 3
A129: 1800011407 | B129: 256779416257 | C129: DR | D129: 45877 | E129: USD | F129: 22.87 | G129: INR | H129: 1967.51 | I129: CODC Out chgs - 16 - 31 Jul 25 | K129: 256779417860 | L129: DR | M129: 50
A130: 1800011596 | B130: 256779416446 | C130: DR | D130: 45877 | E130: USD | F130: 2.28 | G130: INR | H130: 196.15 | I130: VAS 16-31 July 25 | K130: 256779417871 | L130: DR | M130: 1136.3636
A131: 1800012069 | B131: 256779416604 | C131: DR | D131: 45889 | E131: USD | F131: 17.31 | G131: INR | H131: 1489.18 | I131: CODC LCL Chgs - 1-15 Aug 25 | K131: 256779418012 | L131: DR | M131: 480.02
... A134: 1800012220 | B134: 256779416882 | C134: DR | D134: 45889 | E134: USD | F134: 12.83 | G134: INR | H134: 1103.77 | I134: Outbound chgs - 01 - 15 Aug 25 | K134: 256779418354 | L134: DR | M134: 108.95
A135: 1400001003 | C135: DZ | D135: 45891 | E135: USD | F135: -4582.99 | G135: INR | H135: -394140.21 | K135: 256779418401 | L135: DR | M135: 62.52
A136: 1400001107 | C136: DY | D136: 45902 | E136: INR | F136: 104184.06 | G136: INR | H136: 102382.08 | K136: 256779418410 | L136: DR | M136: 480.02
A137: 1400001107 | C137: DY | D137: 45902 | E137: INR | F137: -104184.06 | G137: INR | H137: -101775.06 | K137: 256779418440 | L137: DR | M137: 246.92
A138: 1800012710 | B138: 256779417344 | C138: DR | D138: 45904 | E138: USD | F138: 1142.8571 | G138: INR | H138: 100000 | I138: Fixed Storage Charges for September 2025 | K138: 256779418478 | L138: DR | M138: 27.64
A139: 1800012276 | B139: 256779416912 | C139: DR | D139: 45904 | E139: USD | F139: 44.96 | G139: INR | H139: 3934.64 | I139: CODC LCL Chgs - 16-31 Aug 25 | K139: 256779418493 | L139: DR | M139: 27.64
A140: 1800012287 | B140: 256779416949 | C140: DR | D140: 45904 | E140: USD | F140: 30.16 | G140: INR | H140: 2639.43 | I140: CODC Out chgs -16-31 Aug 25 | K140: 256779418704 | L140: DR | M140: 2.25
A141: 1800012532 | B141: 256779417136 | C141: DR | D141: 45904 | E141: USD | F141: 1.71 | G141: INR | H141: 149.65 | I141: VAS - 16-31 Aug 25 | K141: 256779418773 | L141: DR | M141: 1136.3636
A142: 1800012462 | B142: 256779417162 | C142: DR | D142: 45904 | E142: USD | F142: 44.74 | G142: INR | H142: 3915.39 | I142: VAS -16-31 Aug 25 | K142: 256779418821 | L142: DR | M142: 49.59
A143: 1800012688 | B143: 256779417328 | C143: DR | D143: 45904 | E143: USD | F143: 2.25 | G143: INR | H143: 196.91 | I143: Outbound chgs - 16 - 31 Aug 25 | K143: 256779418827 | L143: DR | M143: 60.86
A144: 1800012469 | B144: 256779417077 | C144: DR | D144: 45906 | E144: USD | F144: 565.97 | G144: INR | H144: 49530.49 | I144: Unit-Storage-1-31 Aug 25 | K144: 256779418870 | L144: DR | M144: 493.91
...

Sheet Ascendus Data
O1: =SUBTOTAL(9,O3:O202) -> 90064.44 | Q1: =SUBTOTAL(9,Q3:Q202) -> -801583.91 | AH1: =SUBTOTAL(9,AH3:AH202) -> -9.15
A2: Customer | B2: Customer Account: Name 1 | C2: Posting Date | D2: Document Number | E2: Document Type | F2: Document Date | G2: Entry Date | H2: Document Header Text | I2: Reference | J2: G/L Account | K2: G/L Account: Short Text | L2: Special G/L Ind. | M2: Posting Key | N2: Document Currency Key | O2: Document Currency Value | P2: Company Code Currency Key | Q2: Company Code Currency Value | T2: Tax Code | U2: Profit Center | V2: Trading Partner No. | W2: Assignment | X2: Item | Y2: Text | Z2: Reference Key 1 | AA2: Reference Key 2 | AB2: Reference Key 3 | AC2: Baseline Payment Dte | AD2: Clearing Date | AE2: Clearing Document | AF2: Text | AG2: Vlookup
A3: 100222345 | B3: SIDDHARTHA LOGISTICS FTWZ PRIVATE | C3: 45902 | D3: 1400001107 | E3: DY | F3: 45902 | G3: 45902 | J3: 212100 | K3: Trade Debtors (Ctrl) | M3: 08 | N3: INR | O3: 104184.06 | P3: INR | Q3: 102382.08 | U3: 6779224500 | X3: 1 | AC3: 45902 | AD3: 45902 | AE3: 1400001107 | AG3: =VLOOKUP(I3,'Customer Data'!$B$2:$F$149,4,0) -> #N/A
A4: 100222345 | B4: SIDDHARTHA LOGISTICS FTWZ PRIVATE | C4: 45902 | D4: 1400001107 | E4: DY | F4: 45902 | G4: 45902 | J4: 212100 | K4: Trade Debtors (Ctrl) | M4: 15 | N4: INR | O4: -104184.06 | P4: INR | Q4: -101775.06 | U4: 6779224500 | X4: 2 | AC4: 45902 | AD4: 45902 | AE4: 1400001107 | AG4: =VLOOKUP(I4,'Customer Data'!$B$2:$F$149,4,0) -> #N/A
A5: 100222345 | B5: SIDDHARTHA LOGISTICS FTWZ PRIVATE | C5: 45861 | D5: 1400000797 | E5: DY | F5: 45861 | G5: 45861 | J5: 212100 | K5: Trade Debtors (Ctrl) | M5: 08 | N5: INR | O5: 198636.61 | P5: INR | Q5: 200764.2 | U5: 6779224500 | X5: 1 | AC5: 45861 | AD5: 45861 | AE5: 1400000797 | AG5: =VLOOKUP(I5,'Customer Data'!$B$2:$F$149,4,0) -> #N/A
A6: 100222345 | B6: SIDDHARTHA LOGISTICS FTWZ PRIVATE | C6: 45861 | D6: 1400000797 | E6: DY | F6: 45861 | G6: 45861 | J6: 212100 | K6: Trade Debtors (Ctrl) | M6: 15 | N6: INR | O6: -198636.61 | P6: INR | Q6: -200764.2 | U6: 6779224500 | X6: 2 | AC6: 45861 | AD6: 45861 | AE6: 1400000797 | AG6: =VLOOKUP(I6,'Customer Data'!$B$2:$F$149,4,0) -> #N/A
A7: 100222345 | B7: SIDDHARTHA LOGISTICS FTWZ PRIVATE | C7: 45891 | D7: 1400001003 | E7: DZ | F7: 45891 | G7: 45891 | H7: 0099542199FC | J7: 212100 | K7: Trade Debtors (Ctrl) | M7: 15 | N7: USD | O7: -4582.99 | P7: INR | Q7: -394140.21 | U7: 6779220000 | X7: 2 | AC7: 45891 | AG7: =VLOOKUP(I7,'Customer Data'!$B$2:$F$149,4,0) -> #N/A
A8: 100222345 | B8: SIDDHARTHA LOGISTICS FTWZ PRIVATE | C8: 45862 | D8: 1400000805 | E8: DZ | F8: 45862 | G8: 45862 | H8: 0105357143FC | J8: 212100 | K8: Trade Debtors (Ctrl) | M8: 15 | N8: USD | O8: -8262.11 | P8: INR | Q8: -713050.33 | U8: 6779224500 | X8: 3 | Y8: 0105357143FC | AC8: 45862 | AD8: 45862 | AE8: 1400000805 | AG8: =VLOOKUP(I8,'Customer Data'!$B$2:$F$149,4,0) -> #N/A
A9: 100222345 | B9: SIDDHARTHA LOGISTICS FTWZ PRIVATE | C9: 45955 | D9: 1400001512 | E9: DZ | F9: 45955 | G9: 45955 | H9: T54SWIC277314 | J9: 212100 | K9: Trade Debtors (Ctrl) | M9: 15 | N9: USD | O9: -4875.15 | P9: INR | Q9: -429943.23 | U9: 6779220000 | X9: 2 | AC9: 45955 | AG9: =VLOOKUP(I9,'Customer Data'!$B$2:$F$149,4,0) -> #N/A
A10: 100222345 | B10: SIDDHARTHA LOGISTICS FTWZ PRIVATE | C10: 45976 | D10: 1400001904 | E10: DY | F10: 45976 | G10: 45976 | H10: NA | I10: KNOCK OFF ENTRY | J10: 212100 | K10: Trade Debtors (Ctrl) | M10: 08 | N10: USD | O10: 0 | P10: INR | Q10: 0 | U10: 6779224500 | X10: 1 | AC10: 45976 | AD10: 45976 | AE10: 1400001904 | AG10: =VLOOKUP(I10,'Customer Data'!$B$2:$F$149,4,0) -> #N/A
A11: 100222345 | B11: SIDDHARTHA LOGISTICS FTWZ PRIVATE | C11: 45976 | D11: 1400001905 | E11: DY | F11: 45976 | G11: 45976 | H11: NA | I11: KNOCK OFF ENTRY | J11: 212100 | K11: Trade Debtors (Ctrl) | M11: 08 | N11: USD | O11: 879.2 | P11: INR | Q11: 77537.33 | U11: 6779224500 | X11: 4 | AC11: 45976 | AD11: 45976 | AE11: 1400001905 | AG11: =VLOOKUP(I11,'Customer Data'!$B$2:$F$149,4,0) -> #N/A
A12: 100222345 | B12: SIDDHARTHA LOGISTICS FTWZ PRIVATE | C12: 45976 | D12: 1400001905 | E12: DY | F12: 45976 | G12: 45976 | H12: NA | I12: KNOCK OFF ENTRY | J12: 212100 | K12: Trade Debtors (Ctrl) | M12: 15 | N12: USD | O12: -111.25 | P12: INR | Q12: -9790.38 | U12: 6779224500 | W12: NA | X12: 1 | AC12: 45976 | AG12: =VLOOKUP(I12,'Customer Data'!$B$2:$F$149,4,0) -> #N/A
A13: 100222345 | B13: SIDDHARTHA LOGISTICS FTWZ PRIVATE | C13: 45976 | D13: 1400001905 | E13: DY | F13: 45976 | G13: 45976 | H13: NA | I13: KNOCK OFF ENTRY | J13: 212100 | K13: Trade Debtors (Ctrl) | M13: 15 | N13: USD | O13: -376.4 | P13: INR | Q13: -33124.48 | U13: 6779224500 | W13: NA | X13: 2 | AC13: 45976 | AG13: =VLOOKUP(I13,'Customer Data'!$B$2:$F$149,4,0) -> #N/A
A14: 100222345 | B14: SIDDHARTHA LOGISTICS FTWZ PRIVATE | C14: 45976 | D14: 1400001905 | E14: DY | F14: 45976 | G14: 45976 | H14: NA | I14: KNOCK OFF ENTRY | J14: 212100 | K14: Trade Debtors (Ctrl) | M14: 15 | N14: USD | O14: -391.55 | P14: INR | Q14: -34457.73 | U14: 6779224500 | W14: NA | X14: 3 | AC14: 45976 | AG14: =VLOOKUP(I14,'Customer Data'!$B$2:$F$149,4,0) -> #N/A
A15: 100222345 | B15: SIDDHARTHA LOGISTICS FTWZ PRIVATE | C15: 45787 | D15: 1800008258 | E15: DR | F15: 45787 | G15: 45791 | H15: NA | I15: 256779413142 | J15: 212100 | K15: Trade Debtors (Ctrl) | M15: 01 | N15: INR | O15: 100000 | P15: INR | Q15: 100000 | T15: O0 | U15: 6779224500 | W15: NA | X15: 1 | Y15: Fixed Storage Charges fo MAY 2025 | AC15: 45787 | AG15: =VLOOKUP(I15,'Customer Data'!$B$2:$F$149,4,0) -> 1046.71
A16: 100222345 | B16: SIDDHARTHA LOGISTICS FTWZ PRIVATE | C16: 45818 | D16: 1800009590 | E16: DR | F16: 45818 | G16: 45825 | H16: NA | I16: 256779414354 | J16: 212100 | K16: Trade Debtors (Ctrl) | M16: 01 | N16: INR | O16: 100000 | P16: INR | Q16: 100000 | T16: O0 | U16: 6779224500 | W16: NA | X16: 1 | Y16: Fixed Storage Charges fo JUNE 2025 | AC16: 45818 | AG16: =VLOOKUP(I16,'Customer Data'!$B$2:$F$149,4,0) -> 1052.75
A17: 100222345 | B17: SIDDHARTHA LOGISTICS FTWZ PRIVATE | C17: 45842 | D17: 1800010152 | E17: DR | F17: 45842 | G17: 45847 | H17: NA | I17: 256779414912 | J17: 212100 | K17: Trade Debtors (Ctrl) | M17: 01 | N17: INR | O17: 100000 | P17: INR | Q17: 100000 | T17: O0 | U17: 6779224500 | W17: NA | X17: 1 | Y17: Fixed Storage Charges fo JULY 2025 | AC17: 45842 | AG17: =VLOOKUP(I17,'Customer Data'!$B$2:$F$149,4,0) -> 1046.5
A18: 100222345 | B18: SIDDHARTHA LOGISTICS FTWZ PRIVATE | C18: 45870 | D18: 1800011358 | E18: DR | F18: 45870 | G18: 45873 | H18: NA | I18: 256779416024 | J18: 212100 | K18: Trade Debtors (Ctrl) | M18: 01 | N18: INR | O18: 100000 | P18: INR | Q18: 100000 | T18: O0 | U18: 6779224500 | W18: NA | X18: 1 | Y18: Fixed Storage Charges for August 2025 | AC18: 45870 | AG18: =VLOOKUP(I18,'Customer Data'!$B$2:$F$149,4,0) -> 1046.14
A19: 100222345 | B19: SIDDHARTHA LOGISTICS FTWZ PRIVATE | C19: 45904 | D19: 1800012710 | E19: DR | F19: 45904 | G19: 45909 | H19: NA | I19: 256779417344 | J19: 212100 | K19: Trade Debtors (Ctrl) | M19: 01 | N19: INR | O19: 100000 | P19: INR | Q19: 100000 | T19: O0 | U19: 6779224500 | W19: 2097261 | X19: 1 | Y19: Fixed Storage Charges for September 2025 | AC19: 45904 | AG19: =VLOOKUP(I19,'Customer Data'!$B$2:$F$149,4,0) -> 1028.4
A20: 100222345 | B20: SIDDHARTHA LOGISTICS FTWZ PRIVATE | C20: 45935 | D20: 1800013251 | E20: DR | F20: 45935 | G20: 45937 | H20: NA | I20: 256779417871 | J20: 212100 | K20: Trade Debtors (Ctrl) | M20: 01 | N20: INR | O20: 100000 | P20: INR | Q20: 100000 | T20: O0 | U20: 6779224500 | W20: 2110507 | X20: 1 | Y20: Fixed Storage Charges for October 2025 | AC20: 45935 | AG20: =VLOOKUP(I20,'Customer Data'!$B$2:$F$149,4,0) -> 1020.52
A21: 100222345 | B21: SIDDHARTHA LOGISTICS FTWZ PRIVATE | C21: 45966 | D21: 1800014233 | E21: DR | F21: 45966 | G21: 45966 | H21: NA | I21: 256779418773 | J21: 212100 | K21: Trade Debtors (Ctrl) | M21: 01 | N21: INR | O21: 100000 | P21: INR | Q21: 100000 | T21: O0 | U21: 6779224500 | W21: 2123158 | X21: 1 | Y21: Fixed Storage Charges for November 2025 | AC21: 45966 | AG21: =VLOOKUP(I21,'Customer Data'!$B$2:$F$149,4,0) -> 1022.69
A22: 100222345 | B22: SIDDHARTHA LOGISTICS FTWZ PRIVATE | C22: 45995 | D22: 1800015482 | E22: DR | F22: 45995 | G22: 46000 | H22: NA | I22: 256779419966 | J22: 212100 | K22: Trade Debtors (Ctrl) | M22: 01 | N22: INR | O22: 100000 | P22: INR | Q22: 100000 | T22: O0 | U22: 6779224500 | W22: 2139804 | X22: 1 | Y22: Fixed Storage Charges for December 2025 | AC22: 45995 | AG22: =VLOOKUP(I22,'Customer Data'!$B$2:$F$149,4,0) -> 1014.65
A23: 100222345 | B23: SIDDHARTHA LOGISTICS FTWZ PRIVATE | C23: 45730 | D23: 1800001820 | E23: DR | F23: 45730 | G23: 45733 | H23: NA | I23: 246779411485 | J23: 212100 | K23: Trade Debtors (Ctrl) | M23: 01 | N23: USD | O23: 100 | P23: INR | Q23: 8669.13 | T23: O0 | U23: 6779224500 | W23: NA | X23: 1 | Y23: Intra Unit Transfer Charges Month Of August,2024 | AC23: 45730 | AG23: =VLOOKUP(I23,'Customer Data'!$B$2:$F$149,4,0) -> 98
A24: 100222345 | B24: SIDDHARTHA LOGISTICS FTWZ PRIVATE | C24: 45730 | D24: 1800001617 | E24: DR | F24: 45730 | G24: 45735 | H24: NA | I24: 246779412274 | J24: 212100 | K24: Trade Debtors (Ctrl) | M24: 01 | N24: USD | O24: 100 | P24: INR | Q24: 8669.13 | T24: O0 | U24: 6779224500 | W24: NA | X24: 1 | Y24: Intra Unit Transfer Charges Month Of August,2024 | AC24: 45730 | AG24: =VLOOKUP(I24,'Customer Data'!$B$2:$F$149,4,0) -> #N/A
A25: 100222345 | B25: SIDDHARTHA LOGISTICS FTWZ PRIVATE | C25: 45720 | D25: 1800000754 | E25: DR | F25: 45720 | G25: 45720 | H25: NA | I25: 246779410694 | J25: 212100 | K25: Trade Debtors (Ctrl) | M25: 01 | N25: USD | O25: 59.36 | P25: INR | Q25: 5145.99 | T25: O0 | U25: 6779224500 | W25: NA | X25: 1 | Y25: Outbound Handling for Oct 2024 | AC25: 45720 | AG25: =VLOOKUP(I25,'Customer Data'!$B$2:$F$149,4,0) -> 58.17
A26: 100222345 | B26: SIDDHARTHA LOGISTICS FTWZ PRIVATE | C26: 45720 | D26: 1800000915 | E26: DR | F26: 45720 | G26: 45721 | H26: NA | I26: 246779410856 | J26: 212100 | K26: Trade Debtors (Ctrl) | M26: 01 | N26: USD | O26: 18.32 | P26: INR | Q26: 1588.18 | T26: O0 | U26: 6779224500 | W26: NA | X26: 1 | Y26: Outbound Handling for Dec 2024 | AC26: 45720 | AG26: =VLOOKUP(I26,'Customer Data'!$B$2:$F$149,4,0) -> 17.95
A27: 100222345 | B27: SIDDHARTHA LOGISTICS FTWZ PRIVATE | C27: 45751 | D27: 1800005899 | E27: DR | F27: 45751 | G27: 45752 | H27: NA | I27: 256779410791 | J27: 212100 | K27: Trade Debtors (Ctrl) | M27: 01 | N27: USD | O27: 441.2 | P27: INR | Q27: 38349.91 | T27: O0 | W27: NA | X27: 1 | Y27: Storage Charges Feb, 25 Exch Rate 87.4 | AC27: 45751 | AG27: =VLOOKUP(I27,'Customer Data'!$B$2:$F$149,4,0) -> 397.08
A28: 100222345 | B28: SIDDHARTHA LOGISTICS FTWZ PRIVATE | C28: 45751 | D28: 1800005916 | E28: DR | F28: 45751 | G28: 45752 | H28: NA | I28: 256779410807 | J28: 212100 | K28: Trade Debtors (Ctrl) | M28: 01 | N28: USD | O28: 742.7 | P28: INR | Q28: 64556.84 | T28: O0 | W28: NA | X28: 1 | Y28: Storage Charges Jan, 25 Exch Rate 86.64 | AC28: 45751 | AG28: =VLOOKUP(I28,'Customer Data'!$B$2:$F$149,4,0) -> 668.43
A29: 100222345 | B29: SIDDHARTHA LOGISTICS FTWZ PRIVATE | C29: 45722 | D29: 1800000948 | E29: DR | F29: 45722 | G29: 45722 | H29: NA | I29: 246779410888 | J29: 212100 | K29: Trade Debtors (Ctrl) | M29: 01 | N29: USD | O29: 446.38 | P29: INR | Q29: 38697.24 | T29: O0 | U29: 6779224500 | W29: NA | X29: 1 | Y29: Storage Charges for the month of December, 2024 Ex | AC29: 45722 | AG29: =VLOOKUP(I29,'Customer Data'!$B$2:$F$149,4,0) -> 401.74
A30: 100222345 | B30: SIDDHARTHA LOGISTICS FTWZ PRIVATE | C30: 45722 | D30: 1800000925 | E30: DR | F30: 45722 | G30: 45722 | H30: NA | I30: 246779410865 | J30: 212100 | K30: Trade Debtors (Ctrl) | M30: 01 | N30: USD | O30: 412.11 | P30: INR | Q30: 35726.34 | T30: O0 | U30: 6779224500 | W30: NA | X30: 1 | Y30: Storage Charges for the month of November, 2024 Ex | AC30: 45722 | AG30: =VLOOKUP(I30,'Customer Data'!$B$2:$F$149,4,0) -> 370.9
A31: 100222345 | B31: SIDDHARTHA LOGISTICS FTWZ PRIVATE | C31: 45722 | D31: 1800001035 | E31: DR | F31: 45722 | G31: 45722 | H31: NA | I31: 246779410975 | J31: 212100 | K31: Trade Debtors (Ctrl) | M31: 01 | N31: USD | O31: 28.91 | P31: INR | Q31: 2506.24 | T31: O0 | U31: 6779224500 | W31: NA | X31: 1 | Y31: Inbound Handling charges for Aug 2024 | AC31: 45722 | AG31: =VLOOKUP(I31,'Customer Data'!$B$2:$F$149,4,0) -> 28.33
A32: 100222345 | B32: SIDDHARTHA LOGISTICS FTWZ PRIVATE | C32: 45722 | D32: 1800001036 | E32: DR | F32: 45722 | G32: 45722 | H32: NA | I32: 246779410976 | J32: 212100 | K32: Trade Debtors (Ctrl) | M32: 01 | N32: USD | O32: 24 | P32: INR | Q32: 2080.59 | T32: O0 | U32: 6779224500 | W32: NA | X32: 1 | Y32: Inbound Handling charges for Aug 2024 | AC32: 45722 | AG32: =VLOOKUP(I32,'Customer Data'!$B$2:$F$149,4,0) -> 23.51
A33: 100222345 | B33: SIDDHARTHA LOGISTICS FTWZ PRIVATE | C33: 45722 | D33: 1800001120 | E33: DR | F33: 45722 | G33: 45723 | H33: NA | I33: 246779411056 | J33: 212100 | K33: Trade Debtors (Ctrl) | M33: 01 | N33: USD | O33: 59.36 | P33: INR | Q33: 5145.99 | T33: O0 | U33: 6779224500 | W33: NA | X33: 1 | Y33: Inbound Handling charges for Sep 2024 | AC33: 45722 | AG33: =VLOOKUP(I33,'Customer Data'!$B$2:$F$149,4,0) -> 58.17
A34: 100222345 | B34: SIDDHARTHA LOGISTICS FTWZ PRIVATE | C34: 45722 | D34: 1800001121 | E34: DR | F34: 45722 | G34: 45723 | H34: NA | I34: 246779411057 | J34: 212100 | K34: Trade Debtors (Ctrl) | M34: 01 | N34: USD | O34: 67.67 | P34: INR | Q34: 5866.4 | T34: O0 | U34: 6779224500 | W34: NA | X34: 1 | Y34: Inbound Handling charges for Sep 2024 | AC34: 45722 | AG34: =VLOOKUP(I34,'Customer Data'!$B$2:$F$149,4,0) -> 66.32
A35: 100222345 | B35: SIDDHARTHA LOGISTICS FTWZ PRIVATE | C35: 45722 | D35: 1800001321 | E35: DR | F35: 45722 | G35: 45723 | H35: NA | I35: 246779411190 | J35: 212100 | K35: Trade Debtors (Ctrl) | M35: 01 | N35: USD | O35: 17.25 | P35: INR | Q35: 1495.42 | T35: O0 | U35: 6779224500 | W35: NA | X35: 1 | Y35: Inbound Handling charges for Nov 2024 | AC35: 45722 | AG35: =VLOOKUP(I35,'Customer Data'!$B$2:$F$149,4,0) -> 16.9
A36: 100222345 | B36: SIDDHARTHA LOGISTICS FTWZ PRIVATE | C36: 45722 | D36: 1800001322 | E36: DR | F36: 45722 | G36: 45723 | H36: NA | I36: 246779411191 | J36: 212100 | K36: Trade Debtors (Ctrl) | M36: 01 | N36: USD | O36: 26.15 | P36: INR | Q36: 2266.98 | T36: O0 | U36: 6779224500 | W36: NA | X36: 1 | Y36: Inbound Handling charges for Nov 2024 | AC36: 45722 | AG36: =VLOOKUP(I36,'Customer Data'!$B$2:$F$149,4,0) -> 25.63
A37: 100222345 | B37: SIDDHARTHA LOGISTICS FTWZ PRIVATE | C37: 45722 | D37: 1800001384 | E37: DR | F37: 45722 | G37: 45723 | H37: NA | I37: 246779411253 | J37: 212100 | K37: Trade Debtors (Ctrl) | M37: 01 | N37: USD | O37: 20 | P37: INR | Q37: 1733.83 | T37: O0 | U37: 6779224500 | W37: NA | X37: 1 | Y37: Inbound Handling charges for Dec 2024 | AC37: 45722 | AG37: =VLOOKUP(I37,'Customer Data'!$B$2:$F$149,4,0) -> 19.6
A38: 100222345 | B38: SIDDHARTHA LOGISTICS FTWZ PRIVATE | C38: 45943 | D38: 1600002430 | E38: DG | F38: 45943 | G38: 45944 | H38: NA | I38: 256779421974 | J38: 212100 | K38: Trade Debtors (Ctrl) | M38: 11 | N38: USD | O38: -435.91 | P38: INR | Q38: -38443.24 | T38: O0 | U38: 6779224500 | W38: 2112576 | X38: 1 | Y38: CN issued against 246779410865 | AC38: 45943 | AG38: =VLOOKUP(I38,'Customer Data'!$B$2:$F$149,4,0) -> -392.32 | AH38: =O38-AG38 -> -43.59 | AI38: =AH38/O38*100 -> 9.9997706
A39: 100222345 | B39: SIDDHARTHA LOGISTICS FTWZ PRIVATE | C39: 45943 | D39: 1600002431 | E39: DG | F39: 45943 | G39: 45944 | H39: NA | I39: 256779421975 | J39: 212100 | K39: Trade Debtors (Ctrl) | M39: 11 | N39: USD | O39: -447.05 | P39: INR | Q39: -39425.68 | T39: O0 | U39: 6779224500 | W39: 2112576 | X39: 1 | Y39: CN issued against 246779410888 | AC39: 45943 | AG39: =VLOOKUP(I39,'Customer Data'!$B$2:$F$149,4,0) -> -402.34 | AH39: =O39-AG39 -> -44.71 | AI39: =AH39/O39*100 -> 10.001118
A40: 100222345 | B40: SIDDHARTHA LOGISTICS FTWZ PRIVATE | C40: 45943 | D40: 1600002438 | E40: DG | F40: 45943 | G40: 45944 | H40: NA | I40: 256779421982 | J40: 212100 | K40: Trade Debtors (Ctrl) | M40: 11 | N40: USD | O40: -480.02 | P40: INR | Q40: -42333.33 | T40: O0 | U40: 6779224500 | W40: 2112591 | X40: 1 | Y40: CN issued against 256779418012 | AC40: 45943 | AD40: 45976 | AE40: 1400001904 | AG40: =VLOOKUP(I40,'Customer Data'!$B$2:$F$149,4,0) -> #N/A
...

Sheet Customer Data
A1: Payment Date | B1: Invoice No | C1: Invoice Dt | D1: Debit (USD) | E1: Credit (USD) | H1: Inv No | I1: Sum of Debit (USD) | J1: Sum of Credit (USD)
B2: 246779410007 | C2: 45708 | E2: 1071.43 | F2: =VLOOKUP(B2,'Ascendus data working'!$B$2:$F$201,5,0) -> 1190.48 | G2: =F2-E2 -> 119.05 | H2: 246779410007 | J2: 1071.43 | K2: =VLOOKUP(H2,'Ascendus data working'!$K$1:$M$189,3,0) -> 1190.48
B3: 246779410138 | C3: 45708 | E3: 1071.43 | F3: =VLOOKUP(B3,'Ascendus data working'!$B$2:$F$201,5,0) -> 1190.48 | G3: =F3-E3 -> 119.05 | H3: 246779410027 | J3: 1071.43 | K3: =VLOOKUP(H3,'Ascendus data working'!$K$1:$M$189,3,0) -> 1190.48
B4: 246779410095 | C4: 45708 | E4: 1071.43 | F4: =VLOOKUP(B4,'Ascendus data working'!$B$2:$F$201,5,0) -> 1190.48 | G4: =F4-E4 -> 119.05 | H4: 246779410095 | J4: 1071.43 | K4: =VLOOKUP(H4,'Ascendus data working'!$K$1:$M$189,3,0) -> 1190.48
B5: 246779410274 | C5: 45708 | E5: 1071.43 | F5: =VLOOKUP(B5,'Ascendus data working'!$B$2:$F$201,5,0) -> 1190.48 | G5: =F5-E5 -> 119.05 | H5: 246779410138 | J5: 1071.43 | K5: =VLOOKUP(H5,'Ascendus data working'!$K$1:$M$189,3,0) -> 1190.48
B6: 246779410027 | C6: 45708 | E6: 1071.43 | F6: =VLOOKUP(B6,'Ascendus data working'!$B$2:$F$201,5,0) -> 1190.48 | G6: =F6-E6 -> 119.05 | H6: 246779410181 | J6: 1049.93 | K6: =VLOOKUP(H6,'Ascendus data working'!$K$1:$M$189,3,0) -> 1166.59
B7: 246779410181 | C7: 45708 | E7: 1049.93 | F7: =VLOOKUP(B7,'Ascendus data working'!$B$2:$F$201,5,0) -> 1166.59 | G7: =F7-E7 -> 116.66 | H7: 246779410224 | J7: 1028.81 | K7: =VLOOKUP(H7,'Ascendus data working'!$K$1:$M$189,3,0) -> 1143.12
B8: 246779410224 | C8: 45708 | E8: 1028.81 | F8: =VLOOKUP(B8,'Ascendus data working'!$B$2:$F$201,5,0) -> 1143.12 | G8: =F8-E8 -> 114.31 | H8: 246779410274 | J8: 1071.43 | K8: =VLOOKUP(H8,'Ascendus data working'!$K$1:$M$189,3,0) -> 1190.48
A9: 45800 | B9: Outgoing payment | C9: 45800 | D9: 7435.89 | F9: =VLOOKUP(B9,'Ascendus data working'!$B$2:$F$201,5,0) -> #N/A | H9: 246779410368 | J9: 320.78 | K9: =VLOOKUP(H9,'Ascendus data working'!$K$1:$M$189,3,0) -> 356.43
B10: 246779410694 | C10: 45720 | E10: 58.17 | F10: =VLOOKUP(B10,'Ascendus data working'!$B$2:$F$201,5,0) -> 59.36 | G10: =F10-E10 -> 1.19 | H10: 246779410394 | J10: 455.27 | K10: =VLOOKUP(H10,'Ascendus data working'!$K$1:$M$189,3,0) -> 505.86
B11: 246779410614 | C11: 45719 | E11: 2.2 | F11: =VLOOKUP(B11,'Ascendus data working'!$B$2:$F$201,5,0) -> 2.25 | G11: =F11-E11 -> 0.05 | H11: 246779410418 | J11: 506.34 | K11: =VLOOKUP(H11,'Ascendus data working'!$K$1:$M$189,3,0) -> 562.6
B12: 246779410615 | C12: 45719 | E12: 8.81 | F12: =VLOOKUP(B12,'Ascendus data working'!$B$2:$F$201,5,0) -> 9 | G12: =F12-E12 -> 0.19 | H12: 246779410510 | J12: 191 | K12: =VLOOKUP(H12,'Ascendus data working'!$K$1:$M$189,3,0) -> 194.9
B13: 246779410975 | C13: 45722 | E13: 28.33 | F13: =VLOOKUP(B13,'Ascendus data working'!$B$2:$F$201,5,0) -> 28.91 | G13: =F13-E13 -> 0.58 | H13: 246779410511 | J13: 13.63 | K13: =VLOOKUP(H13,'Ascendus data working'!$K$1:$M$189,3,0) -> 13.91
B14: 246779410976 | C14: 45722 | E14: 23.51 | F14: =VLOOKUP(B14,'Ascendus data working'!$B$2:$F$201,5,0) -> 24 | G14: =F14-E14 -> 0.49 | H14: 246779410614 | J14: 2.2 | K14: =VLOOKUP(H14,'Ascendus data working'!$K$1:$M$189,3,0) -> 2.25
B15: 246779411190 | C15: 45722 | E15: 16.9 | F15: =VLOOKUP(B15,'Ascendus data working'!$B$2:$F$201,5,0) -> 17.25 | G15: =F15-E15 -> 0.35 | H15: 246779410615 | J15: 8.81 | K15: =VLOOKUP(H15,'Ascendus data working'!$K$1:$M$189,3,0) -> 9
B16: 246779411191 | C16: 45722 | E16: 25.63 | F16: =VLOOKUP(B16,'Ascendus data working'!$B$2:$F$201,5,0) -> 26.15 | G16: =F16-E16 -> 0.52 | H16: 246779410694 | J16: 58.17 | K16: =VLOOKUP(H16,'Ascendus data working'!$K$1:$M$189,3,0) -> 59.36
B17: 246779410511 | C17: 45719 | E17: 13.63 | F17: =VLOOKUP(B17,'Ascendus data working'!$B$2:$F$201,5,0) -> 13.91 | G17: =F17-E17 -> 0.28 | H17: 246779410856 | J17: 17.95 | K17: =VLOOKUP(H17,'Ascendus data working'!$K$1:$M$189,3,0) -> 18.32
B18: 246779412992 | C18: 45735 | E18: 1033.77 | F18: =VLOOKUP(B18,'Ascendus data working'!$B$2:$F$201,5,0) -> 1148.63 | G18: =F18-E18 -> 114.86 | H18: 246779410865 | J18: 370.9 | K18: =VLOOKUP(H18,'Ascendus data working'!$K$1:$M$189,3,0) -> 412.11
B19: 246779410510 | C19: 45719 | E19: 191 | F19: =VLOOKUP(B19,'Ascendus data working'!$B$2:$F$201,5,0) -> 194.9 | G19: =F19-E19 -> 3.9 | H19: 246779410888 | J19: 401.74 | K19: =VLOOKUP(H19,'Ascendus data working'!$K$1:$M$189,3,0) -> 446.38
B20: 246779412240 | C20: 45747 | E20: 2.8 | F20: =VLOOKUP(B20,'Ascendus data working'!$B$2:$F$201,5,0) -> 2.86 | G20: =F20-E20 -> 0.06 | H20: 246779410975 | J20: 28.33 | K20: =VLOOKUP(H20,'Ascendus data working'!$K$1:$M$189,3,0) -> 28.91
B21: 246779411452 | C21: 45747 | E21: 0.93 | F21: =VLOOKUP(B21,'Ascendus data working'!$B$2:$F$201,5,0) -> 0.95 | G21: =F21-E21 -> 0.02 | H21: 246779410976 | J21: 23.51 | K21: =VLOOKUP(H21,'Ascendus data working'!$K$1:$M$189,3,0) -> 24
B22: 246779412242 | C22: 45730 | E22: 4.67 | F22: =VLOOKUP(B22,'Ascendus data working'!$B$2:$F$201,5,0) -> 4.77 | H22: 246779411056 | J22: 58.17 | K22: =VLOOKUP(H22,'Ascendus data working'!$K$1:$M$189,3,0) -> 59.36
B23: 246779412243 | C23: 45730 | E23: 1.87 | F23: =VLOOKUP(B23,'Ascendus data working'!$B$2:$F$201,5,0) -> 1.91 | G23: =F23-E23 -> 0.04 | H23: 246779411057 | J23: 66.32 | K23: =VLOOKUP(H23,'Ascendus data working'!$K$1:$M$189,3,0) -> 67.67
B24: 246779412244 | C24: 45730 | E24: 1.87 | F24: =VLOOKUP(B24,'Ascendus data working'!$B$2:$F$201,5,0) -> 1.91 | G24: =F24-E24 -> 0.04 | H24: 246779411190 | J24: 16.9 | K24: =VLOOKUP(H24,'Ascendus data working'!$K$1:$M$189,3,0) -> 17.25
B25: 246779412245 | C25: 45730 | E25: 4.68 | F25: =VLOOKUP(B25,'Ascendus data working'!$B$2:$F$201,5,0) -> 4.77 | G25: =F25-E25 -> 0.09 | H25: 246779411191 | J25: 25.63 | K25: =VLOOKUP(H25,'Ascendus data working'!$K$1:$M$189,3,0) -> 26.15
B26: 246779411622 | C26: 45733 | E26: 3.74 | F26: =VLOOKUP(B26,'Ascendus data working'!$B$2:$F$201,5,0) -> 3.82 | G26: =F26-E26 -> 0.08 | H26: 246779411253 | J26: 19.6 | K26: =VLOOKUP(H26,'Ascendus data working'!$K$1:$M$189,3,0) -> 20
B27: 246779411623 | C27: 45733 | E27: 1.87 | F27: =VLOOKUP(B27,'Ascendus data working'!$B$2:$F$201,5,0) -> 1.91 | G27: =F27-E27 -> 0.04 | H27: 246779411452 | J27: 0.93 | K27: =VLOOKUP(H27,'Ascendus data working'!$K$1:$M$189,3,0) -> 0.95
B28: 246779410856 | C28: 45748 | E28: 17.95 | F28: =VLOOKUP(B28,'Ascendus data working'!$B$2:$F$201,5,0) -> 18.32 | G28: =F28-E28 -> 0.37 | H28: 246779411485 | J28: 98 | K28: =VLOOKUP(H28,'Ascendus data working'!$K$1:$M$189,3,0) -> 100
B29: 246779411253 | C29: 45748 | E29: 19.6 | F29: =VLOOKUP(B29,'Ascendus data working'!$B$2:$F$201,5,0) -> 20 | G29: =F29-E29 -> 0.4 | H29: 246779411622 | J29: 3.74 | K29: =VLOOKUP(H29,'Ascendus data working'!$K$1:$M$189,3,0) -> 3.82
B30: 246779411056 | C30: 45748 | E30: 58.17 | F30: =VLOOKUP(B30,'Ascendus data working'!$B$2:$F$201,5,0) -> 59.36 | G30: =F30-E30 -> 1.19 | H30: 246779411623 | J30: 1.87 | K30: =VLOOKUP(H30,'Ascendus data working'!$K$1:$M$189,3,0) -> 1.91
B31: 246779411485 | C31: 45748 | E31: 98 | F31: =VLOOKUP(B31,'Ascendus data working'!$B$2:$F$201,5,0) -> 100 | G31: =F31-E31 -> 2 | H31: 246779412240 | J31: 2.8 | K31: =VLOOKUP(H31,'Ascendus data working'!$K$1:$M$189,3,0) -> 2.86
B32: 246779414225 | C32: 45748 | E32: 13.23 | F32: =VLOOKUP(B32,'Ascendus data working'!$B$2:$F$201,5,0) -> 13.5 | G32: =F32-E32 -> 0.27 | H32: 246779412243 | J32: 1.87 | K32: =VLOOKUP(H32,'Ascendus data working'!$K$1:$M$189,3,0) -> 1.91
B33: 246779414607 | C33: 45748 | E33: 2.2 | F33: =VLOOKUP(B33,'Ascendus data working'!$B$2:$F$201,5,0) -> 2.25 | G33: =F33-E33 -> 0.05 | H33: 246779412244 | J33: 1.87 | K33: =VLOOKUP(H33,'Ascendus data working'!$K$1:$M$189,3,0) -> 1.91
B34: 246779414738 | C34: 45748 | E34: 2.2 | F34: =VLOOKUP(B34,'Ascendus data working'!$B$2:$F$201,5,0) -> 2.25 | G34: =F34-E34 -> 0.05 | H34: 246779412245 | J34: 4.68 | K34: =VLOOKUP(H34,'Ascendus data working'!$K$1:$M$189,3,0) -> 4.77
... B68: 256779413490 | C68: 45797 | E68: 2.94 | F68: =VLOOKUP(B68,'Ascendus data working'!$B$2:$F$201,5,0) -> 3 | G68: =F68-E68 -> 0.06 | H68: 256779411891 | J68: 2.2 | K68: =VLOOKUP(H68,'Ascendus data working'!$K$1:$M$189,3,0) -> 2.25
A69: 45856 | B69: Outgoing payment | C69: 45856 | D69: 4602.99 | F69: =VLOOKUP(B69,'Ascendus data working'!$B$2:$F$201,5,0) -> #N/A | H69: 256779412103 | J69: 41.67 | K69: =VLOOKUP(H69,'Ascendus data working'!$K$1:$M$189,3,0) -> 42.53
B70: 256779414354 | C70: 45818 | E70: 1052.75 | F70: =VLOOKUP(B70,'Ascendus data working'!$B$2:$F$201,5,0) -> 1169.5906 | G70: =F70-E70 -> 116.84064 | H70: 256779412113 | J70: 744.73 | K70: =VLOOKUP(H70,'Ascendus data working'!$K$1:$M$189,3,0) -> 827.48
B71: 246779411057 | C71: 45748 | E71: 66.32 | F71: =VLOOKUP(B71,'Ascendus data working'!$B$2:$F$201,5,0) -> 67.67 | G71: =F71-E71 -> 1.35 | H71: 256779412153 | J71: 1048.83 | K71: =VLOOKUP(H71,'Ascendus data working'!$K$1:$M$189,3,0) -> 1165.37
B72: 256779414912 | C72: 45842 | E72: 1046.5 | F72: =VLOOKUP(B72,'Ascendus data working'!$B$2:$F$201,5,0) -> 1162.7907 | G72: =F72-E72 -> 116.2907 | H72: 256779412617 | J72: 376.93 | K72: =VLOOKUP(H72,'Ascendus data working'!$K$1:$M$189,3,0) -> 384.63
B73: 256779415190 | C73: 45842 | E73: 621.63 | F73: =VLOOKUP(B73,'Ascendus data working'!$B$2:$F$201,5,0) -> 690.7 | G73: =F73-E73 -> 69.07 | H73: 256779412660 | J73: 7.34 | K73: =VLOOKUP(H73,'Ascendus data working'!$K$1:$M$189,3,0) -> 7.5
...
